File: SU - Suspension/05 - Essais/Excels essais Optimus/Temoins et tests triangles/Triangles tests/R-R sup/RR sup fr.is_tcyclic_RawData/Specimen_RawData_1.csv
Temps;Déplacement;Charge
(sec);(mm);(N)
0,00000;-59,55590;0,79939
0,00200;-59,55590;0,73569
0,00400;-59,55590;0,67502
0,10400;-59,55345;7,10575
0,20400;-59,54789;49,05030
0,30400;-59,54197;102,04089
0,40400;-59,53647;147,98632
0,50400;-59,53115;194,57435
0,60400;-59,52612;237,28765
0,70400;-59,52104;281,47991
0,80400;-59,51602;322,06485
0,90400;-59,51094;365,36343
1,00400;-59,50604;406,91211
1,10400;-59,50096;450,06238
1,20400;-59,49599;491,57990
1,30400;-59,49091;532,22897
1,40400;-59,48595;573,93424
1,50400;-59,48093;614,84394
1,60400;-59,47602;656,15023
1,70400;-59,47094;695,60762
1,80400;-59,46598;732,20399
1,90400;-59,46096;771,46422
2,00400;-59,45594;810,09055
2,10400;-59,45091;849,66728
2,20400;-59,44589;888,03740
2,30400;-59,44093;924,02678
2,40400;-59,43585;960,70310
2,50400;-59,43100;996,64563
2,60400;-59,42592;1035,16616
2,70400;-59,42102;1070,16042
2,80400;-59,41588;1106,39306
2,90400;-59,41097;1140,13469
3,00400;-59,40613;1173,45145
3,10400;-59,40099;1211,69016
3,20400;-59,39596;1247,35208
3,30400;-59,39094;1280,32118
3,40400;-59,38592;1315,21523
3,50400;-59,38102;1348,34358
3,60400;-59,37600;1381,75720
3,70400;-59,37104;1415,48738
3,80400;-59,36595;1449,66329
3,90400;-59,36105;1482,81232
4,00400;-59,35597;1515,52716
4,10400;-59,35100;1549,35326
4,20400;-59,34598;1580,19047
4,30400;-59,34096;1615,46823
4,40400;-59,33594;1646,22236
4,50400;-59,33098;1677,58577
4,60400;-59,32595;1707,63079
4,70400;-59,32087;1738,85189
4,80400;-59,31591;1769,38977
4,90400;-59,31095;1797,74389
5,00400;-59,30592;1828,22961
5,10400;-59,30084;1858,54789
5,20400;-59,29593;1886,32775
5,30400;-59,29091;1916,87886
5,40400;-59,28595;1944,81499
5,50400;-59,28093;1973,57256
5,60400;-59,27591;2001,28052
5,70400;-59,27089;2030,58608
5,80400;-59,26598;2059,44460
5,90400;-59,26090;2088,43462
6,00400;-59,25600;2115,45154
6,10400;-59,25098;2141,55447
6,20400;-59,24596;2169,04264
6,30400;-59,24099;2195,15711
6,40400;-59,23603;2225,77415
6,50400;-59,23095;2251,83908
6,60400;-59,22598;2277,75257
6,70400;-59,22090;2306,41011
6,80400;-59,21594;2332,57357
6,90400;-59,21086;2361,95736
7,00400;-59,20589;2387,73394
7,10400;-59,20100;2413,52562
7,20400;-59,19591;2442,42121
7,30400;-59,19101;2469,09615
7,40400;-59,18598;2499,43547
7,50400;-59,18102;2526,30506
7,60400;-59,17582;2558,65213
7,70400;-59,17098;2586,96638
7,80400;-59,16596;2615,54960
7,90400;-59,16093;2644,07769
8,00400;-59,15603;2673,30129
8,10400;-59,15107;2702,02477
8,20400;-59,14599;2731,18690
8,30400;-59,14096;2765,89096
8,40400;-59,13600;2795,43437
8,50400;-59,13104;2824,46723
8,60400;-59,12601;2853,84562
8,70400;-59,12105;2884,51985
8,80400;-59,11591;2913,76356
8,90400;-59,11095;2944,10344
9,00400;-59,10587;2972,77775
9,10400;-59,10091;3001,53568
9,20400;-59,09600;3029,45878
9,30400;-59,09092;3058,48289
9,40400;-59,08596;3087,59958
9,50400;-59,08147;3114,82549
9,60400;-59,07591;3147,82262
9,70400;-59,07095;3172,37079
9,80400;-59,06593;3197,22705
9,90400;-59,06091;3224,14748
10,00400;-59,05594;3249,37217
10,10400;-59,05086;3273,09109
10,20400;-59,04596;3297,62436
10,30400;-59,04094;3321,22445
10,40400;-59,03604;3343,01218
10,50400;-59,03089;3371,74200
10,60400;-59,02599;3389,74670
10,70400;-59,02097;3408,92784
10,80400;-59,01600;3425,71773
10,90400;-59,01092;3441,82141
11,00400;-59,00608;3457,27392
11,10400;-59,00094;3472,60535
11,20400;-58,99597;3488,65949
11,30400;-58,99095;3507,00282
11,40400;-58,98593;3529,55088
11,50400;-58,98097;3554,89925
11,60400;-58,97595;3578,95233
11,70400;-58,97092;3606,41442
11,80400;-58,96596;3633,44401
11,90400;-58,96099;3663,02431
12,00400;-58,95591;3692,53531
12,10400;-58,95101;3720,65641
12,20400;-58,94593;3751,35280
12,30400;-58,94097;3777,34862
12,40400;-58,93595;3809,29112
12,50400;-58,93104;3836,58409
12,60400;-58,92596;3868,16524
12,70400;-58,92100;3898,10242
12,80400;-58,91597;3927,79410
12,90400;-58,91095;3960,46303
13,00400;-58,90605;3990,94559
13,10400;-58,90109;4020,52253
13,20400;-58,89601;4051,96883
13,30400;-58,89104;4081,84230
13,40400;-58,88596;4114,20017
13,50400;-58,88100;4147,62385
13,60400;-58,87598;4178,79298
13,70400;-58,87101;4209,62647
13,80400;-58,86599;4239,73724
13,90400;-58,86097;4270,81510
14,00400;-58,85595;4300,56490
14,10400;-58,85093;4333,30759
14,20400;-58,84596;4363,16989
14,30400;-58,84082;4397,36545
14,40400;-58,83592;4427,84987
14,50400;-58,83089;4457,58030
14,60400;-58,82593;4488,86938
14,70400;-58,82091;4518,80135
14,80400;-58,81595;4549,54579
14,90400;-58,81093;4579,26244
15,00400;-58,80602;4606,98083
15,10400;-58,80106;4637,43769
15,20400;-58,79598;4670,02690
15,30400;-58,79090;4699,77893
15,40400;-58,78605;4728,15670
15,50400;-58,78097;4758,62473
15,60400;-58,77595;4787,60824
15,70400;-58,77087;4814,64751
15,80400;-58,76597;4843,38067
15,90400;-58,76088;4874,24880
16,00400;-58,75598;4903,65177
16,10400;-58,75096;4930,01640
16,20400;-58,74593;4957,78807
16,30400;-58,74097;4985,10078
16,40400;-58,73589;5012,56660
16,50400;-58,73093;5042,63155
16,60400;-58,72584;5068,32376
16,70400;-58,72088;5093,05149
16,80400;-58,71592;5119,56550
16,90400;-58,71096;5145,67345
17,00400;-58,70594;5173,74575
17,10400;-58,70097;5197,71799
17,20400;-58,69589;5224,99420
17,30400;-58,69093;5249,02381
17,40400;-58,68590;5274,41800
17,50400;-58,68095;5300,75543
17,60400;-58,67592;5324,10145
17,70400;-58,67096;5348,29125
17,80400;-58,66600;5372,96645
17,90400;-58,66103;5398,04250
18,00400;-58,65601;5421,02344
18,10400;-58,65123;5442,28740
18,20400;-58,64596;5466,90300
18,30400;-58,64107;5487,32504
18,40400;-58,63598;5509,82691
18,50400;-58,63102;5532,02555
18,60400;-58,62600;5556,18890
18,70400;-58,62091;5583,66738
18,80400;-58,61601;5605,14033
18,90400;-58,61087;5628,38726
19,00400;-58,60597;5649,98053
19,10400;-58,60148;5672,28422
19,20400;-58,59592;5697,92762
19,30400;-58,59096;5715,96846
19,40400;-58,58594;5735,11869
19,50400;-58,58092;5754,22682
19,60400;-58,57595;5771,01372
19,70400;-58,57093;5787,31485
19,80400;-58,56597;5801,93102
19,90400;-58,56088;5820,07430
20,00400;-58,55598;5830,76738
20,10400;-58,55096;5842,81944
20,20400;-58,54600;5851,20544
20,30400;-58,54092;5859,23046
20,40400;-58,53601;5867,06623
20,50400;-58,53087;5873,55457
20,60400;-58,52603;5883,29285
20,70400;-58,52094;5889,89966
20,80400;-58,51598;5899,53326
20,90400;-58,51090;5908,77794
21,00400;-58,50588;5918,70695
21,10400;-58,50086;5929,68576
21,20400;-58,49596;5942,03249
21,30400;-58,49093;5956,78501
21,40400;-58,48591;5973,19975
21,50400;-58,48101;5990,06228
21,56600;-58,47784;6000,24052
21,56800;-58,47778;6000,52513
21,66800;-58,47736;5997,03379
21,76800;-58,48185;5955,82426
21,86800;-58,48902;5875,70108
21,96800;-58,49589;5796,81136
22,06800;-58,50200;5729,37541
22,16800;-58,50744;5672,81805
22,26800;-58,51264;5618,54430
22,36800;-58,51778;5566,44127
22,46800;-58,52280;5515,26509
22,56800;-58,52788;5465,94150
22,66800;-58,53279;5416,74383
22,76800;-58,53781;5368,52963
22,86800;-58,54277;5318,97955
22,96800;-58,54785;5268,84906
23,06800;-58,55281;5221,15529
23,16800;-58,55778;5171,56012
23,26800;-58,56274;5123,31314
23,36800;-58,56782;5074,83445
23,46800;-58,57284;5026,91567
23,56800;-58,57781;4979,06506
23,66800;-58,58283;4928,81425
23,76800;-58,58779;4880,63395
23,86800;-58,59287;4833,39094
23,96800;-58,59783;4785,93558
24,06800;-58,60286;4738,90230
24,16800;-58,60776;4690,48359
24,26800;-58,61285;4641,51576
24,36800;-58,61781;4594,68737
24,46800;-58,62289;4545,83094
24,56800;-58,62779;4499,53824
24,66800;-58,63281;4449,36194
24,76800;-58,63783;4401,69945
24,86800;-58,64291;4355,55689
24,96800;-58,64788;4305,96396
25,06800;-58,65278;4261,21540
25,16800;-58,65781;4214,50511
25,26800;-58,66277;4167,71956
25,36800;-58,66779;4118,20635
25,46800;-58,67275;4071,98593
25,56800;-58,67771;4026,53143
25,66800;-58,68280;3978,59514
25,76800;-58,68782;3932,83479
25,86800;-58,69290;3884,15903
25,96800;-58,69786;3837,63537
26,06800;-58,70289;3793,14572
26,16800;-58,70791;3745,45194
26,26800;-58,71287;3699,20284
26,36800;-58,71796;3648,73372
26,46800;-58,72280;3601,60843
26,56800;-58,72782;3555,03336
26,66800;-58,73284;3508,13717
26,76800;-58,73786;3462,00950
26,86800;-58,74282;3415,41320
26,96800;-58,74791;3369,22780
27,06800;-58,75287;3317,79532
27,16800;-58,75789;3270,73596
27,26800;-58,76279;3224,13854
27,36800;-58,76782;3177,66741
27,46800;-58,77278;3134,80459
27,56800;-58,77786;3087,10877
27,66800;-58,78277;3040,25803
27,76800;-58,78785;2991,87861
27,86800;-58,79281;2947,95036
27,96800;-58,79783;2898,99260
28,06800;-58,80286;2853,09479
28,16800;-58,80781;2807,24969
28,26800;-58,81284;2761,43681
28,36800;-58,81780;2717,46926
28,46800;-58,82288;2665,13769
28,56800;-58,82785;2622,04502
28,66800;-58,83287;2576,00825
28,76800;-58,83783;2531,08628
28,86800;-58,84285;2485,03555
28,96800;-58,84782;2439,24074
29,06800;-58,85290;2393,34684
29,16800;-58,85792;2346,45978
29,26800;-58,86288;2301,80919
29,36800;-58,86784;2258,12458
29,46800;-58,87287;2212,50709
29,56800;-58,87783;2168,32981
29,66800;-58,88280;2122,92466
29,76800;-58,88775;2079,10389
29,86800;-58,89272;2034,68557
29,96800;-58,89780;1990,14023
30,06800;-58,90276;1946,39042
30,16800;-58,90778;1900,74444
30,26800;-58,91281;1855,98694
30,36800;-58,91777;1811,50977
30,46800;-58,92285;1768,15912
30,56800;-58,92782;1726,47387
30,66800;-58,93284;1681,63236
30,76800;-58,93786;1635,69096
30,86800;-58,94282;1591,45333
30,96800;-58,94784;1549,76062
31,06800;-58,95281;1508,18797
31,16800;-58,95789;1465,22978
31,26800;-58,96279;1424,55632
31,36800;-58,96787;1381,89336
31,46800;-58,97278;1341,69459
31,56800;-58,97786;1299,77996
31,66800;-58,98270;1257,98630
31,76800;-58,98784;1211,77500
31,86800;-58,99275;1171,20752
31,96800;-58,99783;1130,95064
32,06800;-59,00279;1090,08234
32,16800;-59,00775;1048,88137
32,26800;-59,01271;1009,03669
32,36800;-59,01780;966,84843
32,46800;-59,02270;927,92297
32,56800;-59,02790;883,09497
32,66800;-59,03280;843,36270
32,76800;-59,03777;803,25250
32,86800;-59,04279;763,07985
32,96800;-59,04781;723,47834
33,06800;-59,05284;683,83794
33,16800;-59,05780;645,26359
33,26800;-59,06282;606,70311
33,36800;-59,06784;567,17102
33,46800;-59,07286;528,23992
33,56800;-59,07788;489,88294
33,66800;-59,08285;453,28955
33,76800;-59,08793;414,42118
33,86800;-59,09289;374,39130
33,96800;-59,09786;337,16401
34,06800;-59,10288;299,65269
34,16800;-59,10778;262,69529
34,26800;-59,11274;226,38242
34,36800;-59,11783;190,45864
34,46800;-59,12291;152,92327
34,56800;-59,12787;115,70348
34,66800;-59,13283;80,63522
34,76800;-59,13780;46,24084
34,86800;-59,14282;11,97230
34,90200;-59,14461;0,02709