File: SU - Suspension/05 - Essais/Excels essais Optimus/collage alu carbone 05_02_19/collage7.is_tens_RawData/Specimen_RawData_1.csv
Temps;Déplacement;Charge
(sec);(mm);(N)
0,00000;0,01315;33,67878
0,04000;0,01375;32,91780
0,08000;0,01614;38,09621
0,12000;0,01943;48,96459
0,16000;0,02308;62,70489
0,20000;0,02697;78,18693
0,24000;0,03079;94,51993
0,28000;0,03450;109,49625
0,32000;0,03821;123,58269
0,36000;0,04179;136,79663
0,40000;0,04532;149,21585
0,44000;0,04879;160,57267
0,48000;0,05226;146,01662
0,52000;0,05566;112,50946
0,56000;0,05901;122,91352
0,60000;0,06242;137,07745
0,64000;0,06583;153,45630
0,68000;0,06918;167,10884
0,72000;0,07246;178,33271
0,76000;0,07587;189,29597
0,80000;0,07922;200,77098
0,84000;0,08245;210,51951
0,88000;0,08586;220,91351
0,92000;0,08921;229,82000
0,96000;0,09249;238,83807
1,00000;0,09590;246,37671
1,04000;0,09925;254,43723
1,08000;0,10254;260,17174
1,12000;0,10589;265,65308
1,16000;0,10918;270,27277
1,20000;0,11252;275,11946
1,24000;0,11587;278,95893
1,28000;0,11928;283,14977
1,32000;0,12257;286,91506
1,36000;0,12592;289,25142
1,40000;0,12926;292,57238
1,44000;0,13255;295,29326
1,48000;0,13590;296,52549
1,52000;0,13931;298,04839
1,56000;0,14260;300,92713
1,60000;0,14595;301,70272
1,64000;0,14929;303,00056
1,68000;0,15264;304,81380
1,72000;0,15587;305,98948
1,76000;0,15922;307,64302
1,80000;0,16263;309,14715
1,84000;0,16592;310,32986
1,88000;0,16920;311,70459
1,92000;0,17261;313,13684
1,96000;0,17590;315,38985
2,00000;0,17919;316,05104
2,04000;0,18260;317,91283
2,08000;0,18589;319,69973
2,12000;0,18923;321,23879
2,16000;0,19258;322,94379
2,20000;0,19593;324,84895
2,24000;0,19928;326,50027
2,28000;0,20257;328,11351
2,32000;0,20592;330,76012
2,36000;0,20926;333,12100
2,40000;0,21255;335,19820
2,44000;0,21590;337,35195
2,48000;0,21931;339,57516
2,52000;0,22260;342,31308
2,56000;0,22588;343,54422
2,60000;0,22917;345,81004
2,64000;0,23252;348,05189
2,68000;0,23587;349,57014
2,72000;0,23916;351,47779
2,76000;0,24251;353,86032
2,80000;0,24585;355,59901
2,84000;0,24908;356,72009
2,88000;0,25243;358,58436
2,92000;0,25584;361,32908
2,96000;0,25913;363,21471
3,00000;0,26242;364,38629
3,04000;0,26582;365,36129
3,08000;0,26917;367,54650
3,12000;0,27246;369,27552
3,16000;0,27581;370,16612
3,20000;0,27916;372,40461
3,24000;0,28251;373,66694
3,28000;0,28579;374,93212
3,32000;0,28926;377,34006
3,36000;0,29255;379,10214
3,40000;0,29590;381,08567
3,44000;0,29925;382,77493
3,48000;0,30230;383,95815
3,52000;0,30588;386,59943
3,56000;0,30923;389,24019
3,60000;0,31246;390,45799
3,64000;0,31587;392,22157
3,68000;0,31922;393,43787
3,72000;0,32250;395,38336
3,76000;0,32579;396,78365
3,80000;0,32920;399,34642
3,84000;0,33249;401,09251
3,88000;0,33578;402,88172
3,92000;0,33931;404,73859
3,96000;0,34253;408,03575
4,00000;0,34588;409,18905
4,04000;0,34923;410,86441
4,08000;0,35252;413,20338
4,12000;0,35587;415,45322
4,16000;0,35910;418,27806
4,20000;0,36256;421,05839
4,24000;0,36585;424,21659
4,28000;0,36920;426,25507
4,32000;0,37249;428,70096
4,36000;0,37584;431,40622
4,40000;0,37924;434,90613
4,44000;0,38259;440,14389
4,48000;0,38588;442,20379
4,52000;0,38917;446,04172
4,56000;0,39252;449,77181
4,60000;0,39581;453,58785
4,64000;0,39915;458,47655
4,68000;0,40256;463,76586
4,72000;0,40573;468,60743
4,76000;0,40926;475,67827
4,80000;0,41255;481,01586
4,84000;0,41584;486,20207
4,88000;0,41924;492,25711
4,92000;0,42259;498,62466
4,96000;0,42588;505,07793
5,00000;0,42923;510,50996
5,04000;0,43252;517,20566
5,08000;0,43587;524,50662
5,12000;0,43915;529,79030
5,16000;0,44256;536,84451
5,20000;0,44591;543,28414
5,24000;0,44920;549,21107
5,28000;0,45255;555,03948
5,32000;0,45589;560,91822
5,36000;0,45918;566,21409
5,40000;0,46253;571,75448
5,44000;0,46588;577,27899
5,48000;0,46917;583,01077
5,52000;0,47252;588,33687
5,56000;0,47586;594,08685
5,60000;0,47909;598,83115
5,64000;0,48250;603,71542
5,68000;0,48585;609,13358
5,72000;0,48914;613,99853
5,76000;0,49249;618,70296
5,80000;0,49583;624,51386
5,84000;0,49912;628,08017
5,88000;0,50241;632,54926
5,92000;0,50582;638,12132
5,96000;0,50917;643,20620
6,00000;0,51252;647,72861
6,04000;0,51586;652,95924
6,08000;0,51921;657,18824
6,12000;0,52250;661,63749
6,16000;0,52579;666,72796
6,20000;0,52914;671,79068
6,24000;0,53249;676,91505
6,28000;0,53577;681,59443
6,32000;0,53912;687,02404
6,36000;0,54247;692,54320
6,40000;0,54582;697,52214
6,44000;0,54911;702,64339
6,48000;0,55240;707,35263
6,52000;0,55580;712,15932
6,56000;0,55915;717,78148
6,60000;0,56244;722,49603
6,64000;0,56585;727,45206
6,68000;0,56926;733,90617
6,72000;0,57248;739,02281
6,76000;0,57583;744,40800
6,80000;0,57912;749,43681
6,84000;0,58241;755,26782
6,88000;0,58576;761,22414
6,92000;0,58911;767,34959
6,96000;0,59245;772,76817
7,00000;0,59574;778,52607
7,04000;0,59909;784,14902
7,08000;0,60250;790,27489
7,12000;0,60579;795,46934
7,16000;0,60914;801,85812
7,20000;0,61254;807,95875
7,24000;0,61589;813,83642
7,28000;0,61918;819,46058
7,32000;0,62259;825,40167
7,36000;0,62582;831,95297
7,40000;0,62916;838,12801
7,44000;0,63245;843,28996
7,48000;0,63574;849,43855
7,52000;0,63915;856,50776
7,56000;0,64250;862,37518
7,60000;0,64579;868,85598
7,64000;0,64913;874,81868
7,68000;0,65254;881,55475
7,72000;0,65577;888,22832
7,76000;0,65912;894,47489
7,80000;0,66253;901,62205
7,84000;0,66588;908,34945
7,88000;0,66922;914,67695
7,92000;0,67257;920,61404
7,96000;0,67592;927,59533
8,00000;0,67915;933,29269
8,04000;0,68250;938,79532
8,08000;0,68585;945,86909
8,12000;0,68913;951,95351
8,16000;0,69242;957,34335
8,20000;0,69589;963,57772
8,24000;0,69918;970,72441
8,28000;0,70247;976,91221
8,32000;0,70581;982,53367
8,36000;0,70910;990,41471
8,40000;0,71251;997,61235
8,44000;0,71586;1004,82944
8,48000;0,71915;1011,52007
8,52000;0,72256;1018,64822
8,56000;0,72590;1027,21807
8,60000;0,72913;1034,28299
8,64000;0,73248;1041,60868
8,68000;0,73589;1048,38545
8,72000;0,73912;1055,92515
8,76000;0,74247;1062,75566
8,80000;0,74587;1070,46561
8,84000;0,74916;1078,61981
8,88000;0,75245;1085,74554
8,92000;0,75586;1094,00451
8,96000;0,75921;1103,70182
9,00000;0,76256;1112,82049
9,04000;0,76584;1121,57986
9,08000;0,76919;1130,69490
9,12000;0,77254;1140,55676
9,16000;0,77583;1149,15883
9,20000;0,77918;1158,14442
9,24000;0,78247;1168,50464
9,28000;0,78587;1177,73348
9,32000;0,78916;1187,28969
9,36000;0,79251;1196,87077
9,40000;0,79586;1206,33049
9,44000;0,79921;1215,23198
9,48000;0,80243;1224,71452
9,52000;0,80584;1234,03696
9,56000;0,80919;1244,10922
9,60000;0,81248;1252,11747
9,64000;0,81589;1261,09924
9,68000;0,81924;1270,36162
9,72000;0,82246;1279,71610
9,76000;0,82581;1288,34816
9,80000;0,82916;1298,33436
9,84000;0,83251;1307,90006
9,88000;0,83586;1317,61916
9,92000;0,83921;1327,26179
9,96000;0,84255;1337,69028
10,00000;0,84590;1346,91847
10,04000;0,84913;1355,29367
10,08000;0,85260;1365,23806
10,12000;0,85589;1375,27082
10,16000;0,85923;1384,68891
10,20000;0,86258;1394,02924
10,24000;0,86587;1405,27599
10,28000;0,86916;1413,90646
10,32000;0,87233;1424,16758
10,36000;0,87586;1434,75989
10,40000;0,87920;1444,59847
10,44000;0,88255;1454,44069
10,48000;0,88578;1463,47648
10,52000;0,88925;1473,53541
10,56000;0,89260;1483,50038
10,60000;0,89589;1493,10399
10,64000;0,89923;1503,33550
10,68000;0,90258;1514,25330
10,72000;0,90593;1523,67810
10,76000;0,90916;1532,58517
10,80000;0,91251;1542,03130
10,84000;0,91586;1551,95724
10,88000;0,91914;1561,62996
10,92000;0,92249;1571,55227
10,96000;0,92590;1582,68269
11,00000;0,92919;1592,34535
11,04000;0,93254;1601,64479
11,08000;0,93583;1611,42461
11,12000;0,93917;1621,67046
11,16000;0,94252;1631,19771
11,20000;0,94587;1641,03340
11,24000;0,94922;1650,48651
11,28000;0,95257;1660,38349
11,32000;0,95591;1669,98394
11,36000;0,95914;1678,18870
11,40000;0,96249;1687,48796
11,44000;0,96584;1696,05892
11,48000;0,96901;1706,40536
11,52000;0,97248;1716,69312
11,56000;0,97582;1727,45008
11,60000;0,97911;1737,22561
11,64000;0,98240;1745,96347
11,68000;0,98575;1756,26520
11,72000;0,98910;1765,54695
11,76000;0,99245;1775,14665
11,80000;0,99573;1784,73499
11,84000;0,99926;1796,97033
11,88000;1,00249;1805,69384
11,92000;1,00578;1814,63957
11,96000;1,00919;1823,88257
12,00000;1,01248;1834,76675
12,04000;1,01576;1844,28524
12,08000;1,01917;1854,49813
12,12000;1,02252;1865,16736
12,16000;1,02587;1876,25699
12,20000;1,02916;1885,70824
12,24000;1,03244;1894,81415
12,28000;1,03579;1903,91708
12,32000;1,03908;1912,92223
12,36000;1,04243;1923,79989
12,40000;1,04584;1934,45515
12,44000;1,04919;1944,61104
12,48000;1,05259;1955,40916
12,52000;1,05588;1966,15010
12,56000;1,05923;1975,77868
12,60000;1,06252;1985,73619
12,64000;1,06581;1995,82502
12,68000;1,06922;2006,52927
12,72000;1,07250;2016,92972
12,76000;1,07573;2026,27666
12,80000;1,07920;2037,58366
12,84000;1,08255;2047,75166
12,88000;1,08584;2057,97683
12,92000;1,08913;2067,91349
12,96000;1,09259;2078,10756
13,00000;1,09588;2089,02974
13,04000;1,09917;2097,65714
13,08000;1,10258;2107,93111
13,12000;1,10587;2118,40589
13,16000;1,10921;2127,96815
13,20000;1,11250;2137,36985
13,24000;1,11585;2147,98916
13,28000;1,11920;2157,64772
13,32000;1,12249;2167,45064
13,36000;1,12578;2177,87735
13,40000;1,12912;2187,45470
13,44000;1,13247;2197,65604
13,48000;1,13576;2207,27436
13,52000;1,13911;2217,06629
13,56000;1,14252;2227,80127
13,60000;1,14581;2237,55818
13,64000;1,14909;2247,43467
13,68000;1,15250;2258,34362
13,72000;1,15585;2268,66547
13,76000;1,15908;2278,87351
13,80000;1,16249;2289,31922
13,84000;1,16590;2299,86571
13,88000;1,16906;2309,42816
13,92000;1,17247;2320,61241
13,96000;1,17582;2330,75675
14,00000;1,17905;2341,83986
14,04000;1,18240;2352,32078
14,08000;1,18575;2363,45008
14,12000;1,18909;2374,88616
14,16000;1,19244;2385,65281
14,20000;1,19579;2395,48460
14,24000;1,19908;2405,60696
14,28000;1,20243;2415,61253
14,32000;1,20571;2426,28064
14,36000;1,20912;2436,90200
14,40000;1,21247;2446,65146
14,44000;1,21582;2456,85037
14,48000;1,21917;2467,90648
14,52000;1,22246;2478,14115
14,56000;1,22580;2488,22886
14,60000;1,22903;2497,92784
14,64000;1,23244;2509,15233
14,68000;1,23585;2519,64293
14,72000;1,23920;2530,36916
14,76000;1,24249;2539,64383
14,80000;1,24583;2550,26612
14,84000;1,24918;2560,57922
14,88000;1,25241;2571,40491
14,92000;1,25576;2581,50026
14,96000;1,25917;2593,39642
15,00000;1,26251;2604,07738
15,04000;1,26580;2614,74848
15,08000;1,26921;2625,61534
15,12000;1,27256;2637,41296
15,16000;1,27585;2648,70208
15,20000;1,27908;2658,87883
15,24000;1,28260;2670,21358
15,28000;1,28595;2681,77837
15,32000;1,28924;2691,21472
15,36000;1,29253;2701,34527
15,40000;1,29594;2711,78391
15,44000;1,29929;2722,53398
15,48000;1,30251;2732,82509
15,52000;1,30580;2742,38009
15,56000;1,30915;2753,03666
15,60000;1,31256;2764,21737
15,64000;1,31585;2775,95259
15,68000;1,31926;2786,39663
15,72000;1,32260;2797,26870
15,76000;1,32583;2806,58640
15,80000;1,32930;2817,79245
15,84000;1,33265;2831,33537
15,88000;1,33588;2841,53018
15,92000;1,33917;2851,19843
15,96000;1,34239;2861,71380
16,00000;1,34592;2873,78114
16,04000;1,34915;2884,45782
16,08000;1,35250;2895,11085
16,12000;1,35579;2906,44858
16,16000;1,35919;2917,54939
16,20000;1,36248;2927,82467
16,24000;1,36583;2938,60082
16,28000;1,36924;2951,83398
16,32000;1,37253;2962,23089
16,36000;1,37582;2971,55287
16,40000;1,37922;2983,97541
16,44000;1,38257;2995,00935
16,48000;1,38586;3006,62164
16,52000;1,38921;3016,34632
16,56000;1,39256;3029,01249
16,60000;1,39585;3039,73164
16,64000;1,39907;3049,08566
16,68000;1,40248;3061,58885
16,72000;1,40589;3073,62154
16,76000;1,40918;3084,32523
16,80000;1,41247;3094,36675
16,84000;1,41587;3105,33736
16,88000;1,41916;3116,80995
16,92000;1,42245;3126,93380
16,96000;1,42586;3138,75712
17,00000;1,42921;3150,93622
17,04000;1,43256;3161,24260
17,08000;1,43584;3171,55756
17,12000;1,43919;3183,95086
17,16000;1,44254;3195,91053
17,20000;1,44583;3207,13259
17,24000;1,44912;3217,48704
17,28000;1,45253;3229,81775
17,32000;1,45587;3241,77891
17,36000;1,45910;3253,06579
17,40000;1,46251;3264,01740
17,44000;1,46580;3275,27896
17,48000;1,46915;3286,13520
17,52000;1,47244;3296,53062
17,56000;1,47584;3307,52283
17,60000;1,47919;3319,39124
17,64000;1,48248;3329,65851
17,68000;1,48595;3342,25558
17,72000;1,48930;3354,31397
17,76000;1,49258;3364,53393
17,80000;1,49587;3375,38570
17,84000;1,49928;3386,69419
17,88000;1,50257;3400,60964
17,92000;1,50592;3411,73336
17,96000;1,50927;3422,39365
18,00000;1,51249;3433,31769
18,04000;1,51584;3444,02678
18,08000;1,51919;3454,36186
18,12000;1,52248;3466,62179
18,16000;1,52577;3478,08301
18,20000;1,52924;3491,00232
18,24000;1,53246;3502,71575
18,28000;1,53581;3512,83476
18,32000;1,53916;3523,89663
18,36000;1,54251;3534,39711
18,40000;1,54586;3544,61446
18,44000;1,54903;3555,48151
18,48000;1,55255;3569,07733
18,52000;1,55584;3579,33529
18,56000;1,55913;3589,76014
18,60000;1,56248;3601,06789
18,64000;1,56577;3611,49237
18,68000;1,56906;3621,82558
18,72000;1,57252;3633,52858
18,76000;1,57575;3644,81807
18,80000;1,57910;3655,52716
18,84000;1,58245;3666,09916
18,88000;1,58568;3676,77249
18,92000;1,58909;3686,97792
18,96000;1,59243;3697,54918
19,00000;1,59578;3708,50153
19,04000;1,59913;3720,44593
19,08000;1,60248;3730,59250
19,12000;1,60577;3740,62620
19,16000;1,60911;3751,93991
19,20000;1,61246;3762,36029
19,24000;1,61575;3773,14575
19,28000;1,61910;3783,12394
19,32000;1,62245;3794,75281
19,36000;1,62580;3805,55578
19,40000;1,62908;3815,79734
19,44000;1,63243;3826,45950
19,48000;1,63578;3837,49492
19,52000;1,63907;3847,17174
19,56000;1,64248;3858,26752
19,60000;1,64583;3869,85168
19,64000;1,64905;3879,72295
19,68000;1,65252;3890,40746
19,72000;1,65587;3902,05085
19,76000;1,65910;3911,75300
19,80000;1,66245;3921,53300
19,84000;1,66591;3932,81169
19,88000;1,66914;3942,99291
19,92000;1,67249;3953,19462
19,96000;1,67584;3963,22943
20,00000;1,67913;3973,53806
20,04000;1,68248;3983,12584
20,08000;1,68576;3993,52945
20,12000;1,68911;4004,52539
20,16000;1,69252;4014,98675
20,20000;1,69581;4024,90348
20,24000;1,69910;4035,65243
20,28000;1,70251;4047,28428
20,32000;1,70585;4057,78065
20,36000;1,70920;4068,25580
20,40000;1,71255;4078,34053
20,44000;1,71590;4090,27264
20,48000;1,71925;4099,45026
20,52000;1,72248;4109,44447
20,56000;1,72582;4120,40688
20,60000;1,72917;4130,91779
20,64000;1,73246;4140,25374
20,68000;1,73587;4151,55627
20,72000;1,73922;4162,75114
20,76000;1,74250;4172,89659
20,80000;1,74579;4182,31748
20,84000;1,74914;4193,14355
20,88000;1,75243;4204,48296
20,92000;1,75572;4213,76415
20,96000;1,75913;4225,11324
21,00000;1,76253;4237,03715
21,04000;1,76588;4246,79071
21,08000;1,76917;4256,23246
21,12000;1,77252;4266,43677
21,16000;1,77587;4276,42390
21,20000;1,77916;4287,56140
21,24000;1,78250;4297,90691
21,28000;1,78585;4307,85045
21,32000;1,78914;4319,00099
21,36000;1,79249;4328,17861
21,40000;1,79572;4337,88784
21,44000;1,79913;4348,90650
21,48000;1,80247;4358,77070
21,52000;1,80576;4369,70703
21,56000;1,80917;4380,20416
21,60000;1,81258;4391,62888
21,64000;1,81581;4400,85307
21,68000;1,81921;4410,40657
21,72000;1,82256;4420,68391
21,76000;1,82585;4430,68855
21,80000;1,82914;4439,60391
21,84000;1,83249;4451,52633
21,88000;1,83584;4461,87630
21,92000;1,83912;4471,36536
21,96000;1,84247;4481,61289
22,00000;1,84582;4491,17012
22,04000;1,84911;4500,83092
22,08000;1,85240;4510,31737
22,12000;1,85575;4519,54566
22,16000;1,85915;4530,29573
22,20000;1,86244;4539,00285
22,24000;1,86585;4549,28167
22,28000;1,86914;4558,97897
22,32000;1,87255;4568,54180
22,36000;1,87584;4577,78461
22,40000;1,87912;4587,48415
22,44000;1,88247;4598,10570
22,48000;1,88582;4608,14983
22,52000;1,88911;4616,64498
22,56000;1,89252;4626,49986
22,60000;1,89592;4637,03759
22,64000;1,89909;4646,40930
22,68000;1,90250;4656,54507
22,72000;1,90585;4667,57044
22,76000;1,90914;4677,45587
22,80000;1,91255;4686,78139
22,84000;1,91589;4697,09672
22,88000;1,91918;4706,70909
22,92000;1,92247;4716,50213
22,96000;1,92582;4726,86701
23,00000;1,92917;4736,95025
23,04000;1,93252;4747,19778
23,08000;1,93580;4755,95891
23,12000;1,93921;4766,37818
23,16000;1,94256;4775,74691
23,20000;1,94585;4785,43229
23,24000;1,94914;4795,57477
23,28000;1,95249;4805,69862
23,32000;1,95589;4816,31830
23,36000;1,95924;4826,18213
23,40000;1,96241;4835,72893
23,44000;1,96594;4846,28566
23,48000;1,96929;4856,54771
23,52000;1,97246;4865,27793
23,56000;1,97586;4876,15168
23,60000;1,97921;4886,94049
23,64000;1,98250;4896,35095
23,68000;1,98585;4905,76029
23,72000;1,98926;4916,40978
23,76000;1,99254;4925,95769
23,80000;1,99583;4935,60620
23,84000;1,99924;4945,50355
23,88000;2,00253;4956,31620
23,92000;2,00588;4965,56759
23,96000;2,00923;4974,52170
24,00000;2,01251;4985,40029
24,04000;2,01586;4994,72916
24,08000;2,01915;5004,81538
24,12000;2,02250;5014,90533
24,16000;2,02585;5025,73401
24,20000;2,02920;5035,94428
24,24000;2,03248;5045,48997
24,28000;2,03583;5055,99305
24,32000;2,03918;5067,06350
24,36000;2,04253;5077,61016
24,40000;2,04576;5088,14342
24,44000;2,04917;5099,16693
24,48000;2,05257;5110,49554
24,52000;2,05580;5120,63354
24,56000;2,05915;5130,00451
24,60000;2,06250;5140,90210
24,64000;2,06579;5151,83844
24,68000;2,06908;5160,89685
24,72000;2,07248;5172,04516
24,76000;2,07577;5183,60287
24,80000;2,07912;5192,66985
24,84000;2,08241;5201,86722
24,88000;2,08576;5212,95629
24,92000;2,08910;5223,36736
24,96000;2,09245;5233,57540
25,00000;2,09586;5244,07811
25,04000;2,09921;5256,14545
25,08000;2,10256;5266,26036
25,12000;2,10585;5274,98201
25,16000;2,10919;5285,13044
25,20000;2,11248;5295,32507
25,24000;2,11571;5304,04933
25,28000;2,11918;5315,52806
25,32000;2,12247;5326,62719
25,36000;2,12582;5337,34672
25,40000;2,12904;5346,62977
25,44000;2,13245;5356,44926
25,48000;2,13580;5367,84455
25,52000;2,13909;5377,80635
25,56000;2,14250;5388,42715
25,60000;2,14590;5400,19833
25,64000;2,14919;5411,15068
25,68000;2,15254;5422,30532
25,72000;2,15589;5431,22962
25,76000;2,15912;5441,49205
25,80000;2,16247;5450,33514
25,84000;2,16581;5462,13873
25,88000;2,16916;5474,81515
25,92000;2,17251;5484,58621
25,96000;2,17580;5494,81548
26,00000;2,17915;5505,92579
26,04000;2,18244;5516,64606
26,08000;2,18578;5526,31803
26,12000;2,18901;5537,13962
26,16000;2,19254;5548,49654
26,20000;2,19589;5560,64174
26,24000;2,19924;5570,38411
26,28000;2,20253;5580,43197
26,32000;2,20587;5590,43176
26,36000;2,20922;5600,48446
26,40000;2,21245;5611,06652
26,44000;2,21586;5622,41077
26,48000;2,21927;5636,45847
26,52000;2,22249;5646,26120
26,56000;2,22578;5655,31068
26,60000;2,22913;5666,39602
26,64000;2,23242;5677,43480
26,68000;2,23577;5687,52922
26,72000;2,23912;5699,21732
26,76000;2,24252;5712,20890
26,80000;2,24581;5722,72055
26,84000;2,24916;5732,90251
26,88000;2,25251;5744,37603
26,92000;2,25586;5755,04005
26,96000;2,25915;5765,00259
27,00000;2,26249;5776,51151
27,04000;2,26584;5788,58182
27,08000;2,26919;5799,42949
27,12000;2,27248;5809,42482
27,16000;2,27571;5819,05767
27,20000;2,27918;5830,37511
27,24000;2,28246;5840,03888
27,28000;2,28569;5850,62653
27,32000;2,28916;5862,74453
27,36000;2,29251;5873,41189
27,40000;2,29574;5883,38189
27,44000;2,29915;5894,26793
27,48000;2,30249;5905,77312
27,52000;2,30578;5915,61459
27,56000;2,30913;5926,17132
27,60000;2,31254;5937,33862
27,64000;2,31577;5948,82965
27,68000;2,31911;5958,34032
27,72000;2,32246;5969,87717
27,76000;2,32581;5981,46543
27,80000;2,32910;5990,91835
27,84000;2,33245;6001,52723
27,88000;2,33586;6012,89980
27,92000;2,33914;6023,77504
27,96000;2,34243;6033,88324
28,00000;2,34584;6045,77027
28,04000;2,34919;6056,13329
28,08000;2,35242;6067,60085
28,12000;2,35583;6078,53606
28,16000;2,35911;6089,59012
28,20000;2,36252;6100,57190
28,24000;2,36587;6110,73896
28,28000;2,36916;6122,72583
28,32000;2,37251;6132,85452
28,36000;2,37586;6142,98917
28,40000;2,37914;6153,68225
28,44000;2,38255;6166,34339
28,48000;2,38590;6176,90757
28,52000;2,38913;6186,84143
28,56000;2,39248;6196,85277
28,60000;2,39588;6207,50003
28,64000;2,39899;6218,97765
28,68000;2,40252;6229,82793
28,72000;2,40587;6241,18559
28,76000;2,40922;6251,81645
28,80000;2,41251;6262,65556
28,84000;2,41585;6273,89178
28,88000;2,41920;6284,45968
28,92000;2,42249;6295,58116
28,96000;2,42584;6306,50222
29,00000;2,42925;6318,56322
29,04000;2,43254;6330,56760
29,08000;2,43588;6341,38808
29,12000;2,43923;6351,07160
29,16000;2,44258;6363,88958
29,20000;2,44593;6373,81077
29,24000;2,44916;6384,14770
29,28000;2,45250;6395,88386
29,32000;2,45585;6406,39216
29,36000;2,45920;6417,48905
29,40000;2,46243;6428,18734
29,44000;2,46584;6439,86464
29,48000;2,46919;6451,29383
29,52000;2,47241;6462,11952
29,56000;2,47576;6473,09497
29,60000;2,47917;6485,85111
29,64000;2,48252;6497,99779
29,68000;2,48587;6509,04998
29,72000;2,48922;6520,50003
29,76000;2,49250;6532,42767
29,80000;2,49585;6543,25336
29,84000;2,49908;6553,36827
29,88000;2,50243;6564,39736
29,92000;2,50566;6575,69543
29,96000;2,50913;6588,97460
30,00000;2,51247;6601,05571
30,04000;2,51582;6611,44778
30,08000;2,51917;6622,62365
30,12000;2,52240;6633,44041
30,16000;2,52581;6645,82327
30,20000;2,52916;6658,85881
30,24000;2,53250;6669,42969
30,28000;2,53579;6678,74739
30,32000;2,53920;6690,37700
30,36000;2,54255;6701,98724
30,40000;2,54578;6713,13033
30,44000;2,54912;6724,99463
30,48000;2,55247;6736,27257
30,52000;2,55582;6747,01184
30,56000;2,55893;6757,48736
30,60000;2,56258;6770,35078
30,64000;2,56587;6782,92513
30,68000;2,56915;6791,65572
30,72000;2,57250;6803,20710
30,76000;2,57585;6814,31964
30,80000;2,57920;6824,22966
30,84000;2,58243;6835,32432
30,88000;2,58596;6848,81061
30,92000;2,58930;6859,47910
30,96000;2,59253;6869,90395
31,00000;2,59588;6881,35400
31,04000;2,59923;6893,72644
31,08000;2,60252;6904,30626
31,12000;2,60587;6914,76241
31,16000;2,60915;6926,70047
31,20000;2,61256;6938,85535
31,24000;2,61591;6949,25264
31,28000;2,61914;6960,34580
31,32000;2,62255;6972,05663
31,36000;2,62595;6983,17811
31,40000;2,62918;6994,80772
31,44000;2,63247;7003,84751
31,48000;2,63594;7015,12471
31,52000;2,63917;7026,09494
31,56000;2,64252;7036,35886
31,60000;2,64586;7047,40882
31,64000;2,64921;7060,52259
31,68000;2,65256;7070,39759
31,72000;2,65585;7080,72484
31,76000;2,65920;7092,37903
31,80000;2,66255;7104,39831
31,84000;2,66583;7114,13026
31,88000;2,66918;7124,32861
31,92000;2,67247;7136,08563
31,96000;2,67582;7147,07151
32,00000;2,67911;7158,07304
32,04000;2,68252;7170,21823
32,08000;2,68586;7181,86647
32,12000;2,68921;7192,25779
32,16000;2,69226;7203,64526
32,20000;2,69585;7215,62579
32,24000;2,69920;7227,77545
32,28000;2,70249;7238,02596
32,32000;2,70583;7248,53501
32,36000;2,70918;7260,12364
32,40000;2,71247;7270,24898
32,44000;2,71582;7280,86606
32,48000;2,71917;7292,09855
32,52000;2,72251;7304,58200
32,56000;2,72580;7316,54987
32,60000;2,72915;7327,11703
32,64000;2,73250;7339,49095
32,68000;2,73585;7349,24302
32,72000;2,73914;7359,44882
32,76000;2,74248;7370,15679
32,80000;2,74583;7381,32372
32,84000;2,74918;7394,77277
32,88000;2,75253;7404,97708
32,92000;2,75582;7415,50848
32,96000;2,75917;7425,39167
33,00000;2,76251;7435,51403
33,04000;2,76574;7445,98061
33,08000;2,76915;7456,64537
33,12000;2,77256;7469,52891
33,16000;2,77579;7481,76873
33,20000;2,77919;7491,88736
33,24000;2,78254;7501,57237
33,28000;2,78577;7511,94060
33,32000;2,78918;7521,70607
33,36000;2,79253;7533,26565
33,40000;2,79582;7544,26718
33,44000;2,79899;7555,18079
33,48000;2,80257;7567,71863
33,52000;2,80586;7578,94665
33,56000;2,80921;7588,34407
33,60000;2,81256;7598,46196
33,64000;2,81591;7609,16844
33,68000;2,81919;7619,29452
33,72000;2,82254;7630,23868
33,76000;2,82589;7639,91103
33,80000;2,82918;7650,16377
33,84000;2,83253;7660,89633
33,88000;2,83588;7672,65707
33,92000;2,83916;7683,03424
33,96000;2,84251;7693,04559
34,00000;2,84580;7703,41605
34,04000;2,84915;7714,91230
34,08000;2,85250;7724,92662
34,12000;2,85579;7735,21811
34,16000;2,85907;7746,57726
34,20000;2,86248;7757,86117
34,24000;2,86583;7768,98786
34,28000;2,86912;7779,30841
34,32000;2,87247;7789,27654
34,36000;2,87587;7800,18270
34,40000;2,87916;7810,54720
34,44000;2,88239;7820,14653
34,48000;2,88580;7831,14433
34,52000;2,88915;7842,49976
34,56000;2,89238;7851,64237
34,60000;2,89578;7861,14261
34,64000;2,89913;7873,20659
34,68000;2,90242;7883,32745
34,72000;2,90577;7893,24567
34,76000;2,90918;7904,29488
34,80000;2,91247;7915,08481
34,84000;2,91581;7925,60205
34,88000;2,91916;7935,16561
34,92000;2,92245;7946,31541
34,96000;2,92586;7955,96316
35,00000;2,92915;7965,14452
35,04000;2,93244;7975,79885
35,08000;2,93578;7987,34352
35,12000;2,93913;7997,31165
35,16000;2,94236;8007,35578
35,20000;2,94577;8016,72935
35,24000;2,94912;8027,64893
35,28000;2,95241;8037,47401
35,32000;2,95575;8047,85490
35,36000;2,95916;8058,45857
35,40000;2,96251;8068,29557
35,44000;2,96580;8076,96506
35,48000;2,96921;8087,19397
35,52000;2,97249;8098,12099
35,56000;2,97578;8107,75310
35,60000;2,97919;8117,49026
35,64000;2,98254;8127,82943
35,68000;2,98577;8137,92869
35,72000;2,98912;8147,45277
35,76000;2,99252;8158,98031
35,80000;2,99575;8169,06542
35,84000;2,99916;8179,40906
35,88000;3,00251;8189,84956
35,92000;3,00580;8201,14836
35,96000;3,00915;8210,40198
36,00000;3,01249;8220,15181
36,04000;3,01578;8231,04531
36,08000;3,01919;8240,50605
36,12000;3,02248;8250,12997
36,16000;3,02583;8259,89097
36,20000;3,02917;8270,44398
36,24000;3,03252;8279,72442
36,28000;3,03581;8290,33926
36,32000;3,03916;8298,40228
36,36000;3,04251;8309,31365
36,40000;3,04580;8319,50456
36,44000;3,04908;8327,91179
36,48000;3,05255;8338,46107
36,52000;3,05590;8348,95819
36,56000;3,05919;8358,31463
36,60000;3,06254;8367,37528
36,64000;3,06595;8377,22570
36,68000;3,06917;8386,40630
36,72000;3,07246;8394,96404
36,76000;3,07581;8405,70107
36,80000;3,07916;8416,01714
36,84000;3,08251;8425,62765
36,88000;3,08586;8435,00942
36,92000;3,08920;8445,53187
36,96000;3,09255;8453,96295
37,00000;3,09578;8462,74495
37,04000;3,09913;8472,61548
37,08000;3,10254;8482,67302
37,12000;3,10582;8491,82233
37,16000;3,10917;8500,61029
37,20000;3,11252;8510,19770
37,24000;3,11587;8520,49589
37,28000;3,11910;8529,11323
37,32000;3,12245;8537,68438
37,36000;3,12579;8549,41458
37,40000;3,12920;8558,44319
37,44000;3,13249;8567,72587
37,48000;3,13584;8576,74256
37,52000;3,13925;8586,77030
37,56000;3,14248;8595,19094
37,60000;3,14576;8604,17858
37,64000;3,14923;8615,05717
37,68000;3,15252;8624,47992
37,72000;3,15587;8632,64278
37,76000;3,15922;8641,99772
37,80000;3,16251;8652,06644
37,84000;3,16585;8659,70477
37,88000;3,16914;8669,19905
37,92000;3,17243;8678,48545
37,96000;3,17584;8687,71821
38,00000;3,17913;8695,94291
38,04000;3,18248;8705,29860
38,08000;3,18588;8715,17584
38,12000;3,18923;8724,22978
38,16000;3,19246;8733,42007
38,20000;3,19587;8741,34824
38,24000;3,19922;8751,70827
38,28000;3,20250;8761,37689
38,32000;3,20585;8769,69770
38,36000;3,20920;8779,94075
38,40000;3,21255;8789,05430
38,44000;3,21578;8797,21716
38,48000;3,21919;8806,49760
38,52000;3,22253;8816,17740
38,56000;3,22582;8824,74184
38,60000;3,22917;8833,46498
38,64000;3,23252;8842,38556
38,68000;3,23581;8851,09007
38,72000;3,23916;8860,08143
38,76000;3,24250;8869,13761
38,80000;3,24585;8879,16461
38,84000;3,24920;8887,12183
38,88000;3,25249;8895,17143
38,92000;3,25590;8905,03377
38,96000;3,25918;8913,85525
39,00000;3,26247;8921,29019
39,04000;3,26582;8931,27546
39,08000;3,26923;8941,12140
39,12000;3,27252;8949,01156
39,16000;3,27581;8957,37633
39,20000;3,27915;8964,76582
39,24000;3,28256;8974,55066
39,28000;3,28585;8985,19605
39,32000;3,28902;8992,22940
39,36000;3,29261;9003,67126
39,40000;3,29590;9012,40781
39,44000;3,29924;9020,86571
39,48000;3,30253;9028,01529
39,52000;3,30588;9036,99771
39,56000;3,30923;9046,14553
39,60000;3,31234;9054,29199
39,64000;3,31599;9066,42824
39,68000;3,31921;9075,25271
39,72000;3,32250;9081,98878
39,76000;3,32579;9090,08756
39,80000;3,32914;9099,15566
39,84000;3,33249;9107,93468
39,88000;3,33584;9116,90369
39,92000;3,33918;9128,28073
39,96000;3,34253;9136,20740
40,00000;3,34588;9144,45892
40,04000;3,34917;9153,13512
40,08000;3,35252;9160,80922
40,12000;3,35586;9168,42893
40,16000;3,35915;9175,99425
40,20000;3,36238;9183,95519
40,24000;3,36591;9194,48361
40,28000;3,36920;9203,90934
40,32000;3,37243;9210,94418
40,36000;3,37577;9219,05562
40,40000;3,37918;9228,89784
40,44000;3,38247;9236,61739
40,48000;3,38564;9244,12385
40,52000;3,38923;9253,89677
40,56000;3,39252;9262,62438
40,60000;3,39586;9270,12712
40,64000;3,39921;9277,80420
40,68000;3,40244;9286,08403
40,72000;3,40585;9293,28203
40,76000;3,40914;9301,50598
40,80000;3,41249;9311,25060
40,84000;3,41583;9320,02068
40,88000;3,41912;9328,57245
40,92000;3,42253;9337,03780
40,96000;3,42582;9346,52388
41,00000;3,42917;9353,25474
41,04000;3,43240;9361,88996
41,08000;3,43580;9370,29272
41,12000;3,43915;9378,50475
41,16000;3,44244;9386,16768
41,20000;3,44579;9394,25901
41,24000;3,44914;9403,19151
41,28000;3,45248;9412,21416
41,32000;3,45565;9420,01715
41,36000;3,45918;9430,09704
41,40000;3,46253;9438,54079
41,44000;3,46582;9446,36390
41,48000;3,46911;9453,11263
41,52000;3,47251;9462,47429
41,56000;3,47574;9470,10964
41,60000;3,47909;9476,96045
41,64000;3,48250;9486,11572
41,68000;3,48579;9495,08771
41,72000;3,48914;9502,35203
41,76000;3,49248;9509,66179
41,80000;3,49583;9518,53767
41,84000;3,49918;9525,74462
41,88000;3,50253;9534,02892
41,92000;3,50576;9542,42051
41,96000;3,50916;9550,46788
42,00000;3,51251;9559,26701
42,04000;3,51580;9567,30470
42,08000;3,51915;9575,51822
42,12000;3,52250;9584,98716
42,16000;3,52585;9592,30885
42,20000;3,52907;9598,75286
42,24000;3,53248;9608,57347
42,28000;3,53583;9616,85702
42,32000;3,53912;9624,60041
42,36000;3,54247;9633,44127
42,40000;3,54588;9641,05725
42,44000;3,54910;9648,66504
42,48000;3,55245;9656,59097
42,52000;3,55586;9666,49204
42,56000;3,55915;9674,96037
42,60000;3,56250;9682,04439
42,64000;3,56585;9690,28100
42,68000;3,56913;9698,06463
42,72000;3,57242;9705,06892
42,76000;3,57589;9713,85837
42,80000;3,57918;9722,22760
42,84000;3,58259;9730,09169
42,88000;3,58587;9736,92387
42,92000;3,58916;9745,29758
42,96000;3,59251;9752,08580
43,00000;3,59586;9759,94244
43,04000;3,59915;9767,84304
43,08000;3,60250;9775,93660
43,12000;3,60584;9783,73662
43,16000;3,60913;9791,12387
43,20000;3,61248;9798,67205
43,24000;3,61583;9806,47802
43,28000;3,61912;9814,21769
43,32000;3,62241;9822,10115
43,36000;3,62581;9830,51583
43,40000;3,62922;9838,73308
43,44000;3,63245;9846,05774
43,48000;3,63586;9853,56346
43,52000;3,63921;9862,17260
43,56000;3,64244;9869,62691
43,60000;3,64566;9876,44792
43,64000;3,64919;9885,77232
43,68000;3,65242;9893,81075
43,72000;3,65583;9900,45890
43,76000;3,65912;9908,01156
43,80000;3,66247;9916,14088
43,84000;3,66581;9923,52292
43,88000;3,66910;9931,02640
43,92000;3,67251;9938,44792
43,96000;3,67586;9947,43183
44,00000;3,67927;9955,46654
44,04000;3,68255;9963,29561
44,08000;3,68596;9970,26712
44,12000;3,68925;9978,12375
44,16000;3,69260;9985,48195
44,20000;3,69583;9991,76428
44,24000;3,69918;9999,05914
44,28000;3,70252;10008,60259
44,32000;3,70581;10015,41913
44,36000;3,70922;10023,17294
44,40000;3,71257;10031,48854
44,44000;3,71580;10038,46452
44,48000;3,71915;10044,79676
44,52000;3,72261;10055,53678
44,56000;3,72590;10062,43452
44,60000;3,72919;10068,03736
44,64000;3,73254;10076,03556
44,68000;3,73595;10084,00843
44,72000;3,73929;10091,56778
44,76000;3,74252;10098,77250
44,80000;3,74587;10106,64403
44,84000;3,74922;10114,24512
44,88000;3,75263;10121,13616
44,92000;3,75580;10127,48033
44,96000;3,75920;10136,26456
45,00000;3,76255;10144,33578
45,04000;3,76584;10150,53689
45,08000;3,76913;10157,00176
45,12000;3,77254;10165,79047
45,16000;3,77589;10174,08296
45,20000;3,77917;10180,49568
45,24000;3,78252;10188,08782
45,28000;3,78593;10197,49641
45,32000;3,78916;10204,04473
45,36000;3,79251;10209,96869
45,40000;3,79592;10218,38039
45,44000;3,79914;10226,00755
45,48000;3,80249;10232,09691
45,52000;3,80584;10240,86475
45,56000;3,80913;10249,50966
45,60000;3,81248;10255,63553
45,64000;3,81571;10261,80610
45,68000;3,81911;10269,92723
45,72000;3,82246;10278,11170
45,76000;3,82581;10284,73377
45,80000;3,82910;10291,28209
45,84000;3,83245;10298,44433
45,88000;3,83579;10305,35325
45,92000;3,83908;10311,31223
45,96000;3,84243;10319,05785
46,00000;3,84578;10326,98005
46,04000;3,84913;10333,73326
46,08000;3,85248;10341,23898
46,12000;3,85582;10349,53073
46,16000;3,85917;10356,11704
46,20000;3,86246;10362,31145
46,24000;3,86581;10368,88510
46,28000;3,86922;10376,88851
46,32000;3,87251;10383,23045
46,36000;3,87585;10389,70202
46,40000;3,87926;10397,76281
46,44000;3,88249;10404,84160
46,48000;3,88584;10410,00858
46,52000;3,88919;10417,34368
46,56000;3,89248;10427,06221
46,60000;3,89582;10433,27451
46,64000;3,89923;10439,75353
46,68000;3,90252;10447,86945
46,72000;3,90587;10453,63992
46,76000;3,90922;10460,41325
46,80000;3,91250;10466,85129
46,84000;3,91591;10474,50304
46,88000;3,91920;10482,82161
46,92000;3,92255;10489,50553
46,96000;3,92584;10495,68802
47,00000;3,92919;10502,54479
47,04000;3,93253;10509,26596
47,08000;3,93588;10515,54531
47,12000;3,93923;10521,87234
47,16000;3,94258;10530,63050
47,20000;3,94581;10536,65206
47,24000;3,94916;10542,97760
47,28000;3,95256;10550,65319
47,32000;3,95585;10556,95638
47,36000;3,95920;10563,45105
47,40000;3,96261;10571,31737
47,44000;3,96590;10579,20530
47,48000;3,96924;10586,48229
47,52000;3,97253;10592,41965
47,56000;3,97582;10598,38012
47,60000;3,97917;10603,98519
47,64000;3,98252;10610,38747
47,68000;3,98575;10616,79944
47,72000;3,98915;10624,50334
47,76000;3,99250;10632,65055
47,80000;3,99579;10640,06463
47,84000;3,99920;10646,53099
47,88000;4,00255;10653,65225
47,92000;4,00584;10659,26999
47,96000;4,00918;10665,52028
48,00000;4,01253;10672,07307
48,04000;4,01588;10677,92550
48,08000;4,01911;10683,54398
48,12000;4,02252;10690,85672
48,16000;4,02587;10697,47880
48,20000;4,02909;10702,75977
48,24000;4,03244;10708,98324
48,28000;4,03579;10716,17603
48,32000;4,03908;10722,72435
48,36000;4,04237;10728,48216
48,40000;4,04584;10735,54307
48,44000;4,04906;10741,00435
48,48000;4,05241;10746,42166
48,52000;4,05582;10753,56454
48,56000;4,05911;10760,14489
48,60000;4,06252;10766,09120
48,64000;4,06580;10772,54564
48,68000;4,06915;10779,66318
48,72000;4,07250;10784,68487
48,76000;4,07579;10790,57977
48,80000;4,07914;10796,92468
48,84000;4,08249;10803,19062
48,88000;4,08577;10808,81208
48,92000;4,08912;10814,43876
48,96000;4,09241;10820,48640
49,00000;4,09582;10827,48696
49,04000;4,09917;10833,76557
49,08000;4,10240;10838,01016
49,12000;4,10580;10845,53376
49,16000;4,10921;10852,03141
49,20000;4,11244;10857,49492
49,24000;4,11585;10863,60142
49,28000;4,11926;10870,01562
49,32000;4,12249;10876,05655
49,36000;4,12583;10881,66386
49,40000;4,12924;10887,69734
49,44000;4,13253;10893,88132
49,48000;4,13582;10898,65789
49,52000;4,13917;10904,44028
49,56000;4,14251;10910,41863
49,60000;4,14580;10915,27715
49,64000;4,14915;10920,89787
49,68000;4,15250;10927,57806
49,72000;4,15585;10933,36791
49,76000;4,15920;10937,94033
49,80000;4,16248;10942,80630
49,84000;4,16583;10947,82054
49,88000;4,16918;10953,74078
49,92000;4,17253;10959,60960
49,96000;4,17582;10965,97686
50,00000;4,17923;10971,08871
50,04000;4,18251;10976,59245
50,08000;4,18580;10981,91962
50,12000;4,18921;10987,09777
50,16000;4,19256;10992,58065
50,20000;4,19579;10998,63499
50,24000;4,19914;11004,52766
50,28000;4,20254;11010,61180
50,32000;4,20583;11017,34340
50,36000;4,20918;11021,58949
50,40000;4,21253;11026,49570
50,44000;4,21582;11032,24009
50,48000;4,21911;11036,83338
50,52000;4,22251;11042,39747
50,56000;4,22580;11048,44511
50,60000;4,22909;11054,46145
50,64000;4,23250;11058,82153
50,68000;4,23579;11065,01743
50,72000;4,23913;11069,61966
50,76000;4,24242;11075,09211
50,80000;4,24577;11080,46323
50,84000;4,24912;11086,08916
50,88000;4,25247;11092,17331
50,92000;4,25582;11097,05418
50,96000;4,25910;11101,46120
51,00000;4,26251;11106,77123
51,04000;4,26580;11112,16918
51,08000;4,26909;11117,02695
51,12000;4,27244;11122,55603
51,16000;4,27585;11129,31818
51,20000;4,27907;11134,82788
51,24000;4,28248;11140,26457
51,28000;4,28589;11145,97619
51,32000;4,28912;11151,11336
51,36000;4,29253;11155,38552
51,40000;4,29587;11162,56118
51,44000;4,29916;11168,85692
51,48000;4,30251;11173,13951
51,52000;4,30586;11178,10160
51,56000;4,30921;11184,65960
51,60000;4,31250;11189,15454
51,64000;4,31578;11193,62190
51,68000;4,31913;11199,22772
51,72000;4,32248;11205,16881
51,76000;4,32583;11210,21807
51,80000;4,32918;11216,97202
51,84000;4,33253;11221,91548
51,88000;4,33587;11228,28871
51,92000;4,33922;11232,49009
51,96000;4,34251;11238,87971
52,00000;4,34592;11246,04493
52,04000;4,34933;11251,02565
52,08000;4,35250;11255,18158
52,12000;4,35590;11260,72258
52,16000;4,35925;11267,25823
52,20000;4,36248;11272,28662
52,24000;4,36583;11276,48950
52,28000;4,36918;11283,73146
52,32000;4,37247;11288,77923
52,36000;4,37581;11293,54686
52,40000;4,37922;11299,82546
52,44000;4,38251;11305,89247
52,48000;4,38586;11310,42913
52,52000;4,38915;11315,51564
52,56000;4,39255;11321,80616
52,60000;4,39590;11327,67946
52,64000;4,39925;11333,60416
52,68000;4,40254;11337,40768
52,72000;4,40589;11342,18872
52,76000;4,40924;11347,67309
52,80000;4,41246;11352,30213
52,84000;4,41575;11357,93105
52,88000;4,41916;11364,76025
52,92000;4,42251;11369,66348
52,96000;4,42574;11374,12563
53,00000;4,42915;11379,44683
53,04000;4,43255;11386,49583
53,08000;4,43578;11389,82847
53,12000;4,43913;11393,90618
53,16000;4,44254;11400,39712
53,20000;4,44583;11405,36889
53,24000;4,44906;11409,86159
53,28000;4,45258;11416,19757
53,32000;4,45587;11422,12152
53,36000;4,45916;11425,36700
53,40000;4,46239;11430,89011
53,44000;4,46586;11438,22894
53,48000;4,46914;11442,51972
53,52000;4,47249;11446,25545
53,56000;4,47572;11450,78987
53,60000;4,47913;11457,73754
53,64000;4,48248;11462,40607
53,68000;4,48583;11467,82562
53,72000;4,48911;11472,93821
53,76000;4,49252;11478,27283
53,80000;4,49587;11483,66705
53,84000;4,49922;11489,41144
53,88000;4,50257;11495,50825
53,92000;4,50592;11500,22671
53,96000;4,50908;11504,43628
54,00000;4,51243;11508,56763
54,04000;4,51590;11516,46078
54,08000;4,51919;11520,04600
54,12000;4,52248;11522,94576
54,16000;4,52589;11529,13496
54,20000;4,52911;11533,98901
54,24000;4,53228;11537,64427
54,28000;4,53593;11543,76268
54,32000;4,53922;11549,86918
54,36000;4,54257;11553,39405
54,40000;4,54591;11558,05364
54,44000;4,54920;11561,34233
54,48000;4,55255;11564,18920
54,52000;4,55584;11568,36674
54,56000;4,55925;11572,94810
54,60000;4,56254;11578,20374
54,64000;4,56588;11580,69298
54,68000;4,56917;11584,89957
54,72000;4,57252;11588,05117
54,76000;4,57587;11591,24002
54,80000;4,57922;11593,14513
54,84000;4,58239;11594,22323
54,88000;4,58585;11596,74302
54,92000;4,58926;11592,95216
54,96000;4,59249;11577,08243
55,00000;4,59668;6964,25512
55,02200;4,59931;2318,55176