File: SU - Suspension/05 - Essais/Excels essais Optimus/Temoins et tests triangles/Temoins alu carbone/temoin 3/temoin 3.is_tens_RawData/Specimen_RawData_1.csv
Temps;Déplacement;Charge
(sec);(mm);(N)
0,00000;0,00831;95,01101
0,04000;0,00885;94,84605
0,08000;0,01106;106,02409
0,12000;0,01429;138,47933
0,16000;0,01800;178,16222
0,20000;0,02188;223,69439
0,24000;0,02577;267,56369
0,28000;0,02924;310,65333
0,32000;0,03336;354,52070
0,36000;0,03695;397,88946
0,40000;0,04042;435,94451
0,44000;0,04395;473,67709
0,48000;0,04741;512,25475
0,52000;0,05082;549,16362
0,56000;0,05423;585,45806
0,60000;0,05758;621,28487
0,64000;0,06099;657,80259
0,68000;0,06427;694,06922
0,72000;0,06768;732,39701
0,76000;0,07097;765,83386
0,80000;0,07432;798,78680
0,84000;0,07761;831,61471
0,88000;0,08095;866,36860
0,92000;0,08436;902,42634
0,96000;0,08753;935,78184
1,00000;0,09100;969,42652
1,04000;0,09441;1005,49329
1,08000;0,09770;1040,21635
1,12000;0,10098;1071,22324
1,16000;0,10445;1105,98030
1,20000;0,10768;1140,49781
1,24000;0,11097;1173,19496
1,28000;0,11432;1204,94170
1,32000;0,11767;1241,17369
1,36000;0,12101;1272,61281
1,40000;0,12430;1304,66623
1,44000;0,12765;1337,25340
1,48000;0,13100;1369,91860
1,52000;0,13435;1400,33513
1,56000;0,13764;1432,40215
1,60000;0,14104;1464,16882
1,64000;0,14439;1498,26193
1,68000;0,14768;1529,92262
1,72000;0,15103;1562,74382
1,76000;0,15438;1595,75865
1,80000;0,15772;1628,09063
1,84000;0,16095;1658,49179
1,88000;0,16388;1690,15173
1,92000;0,16777;1726,28537
1,96000;0,17100;1761,01271
2,00000;0,17435;1791,85495
2,04000;0,17769;1824,69971
2,08000;0,18092;1856,44124
2,12000;0,18427;1886,90014
2,16000;0,18762;1917,65819
2,20000;0,19097;1951,81202
2,24000;0,19432;1983,42782
2,28000;0,19760;2014,93017
2,32000;0,20101;2052,11081
2,36000;0,20436;2084,08926
2,40000;0,20771;2114,99725
2,44000;0,21100;2146,10789
2,48000;0,21435;2177,26454
2,52000;0,21763;2208,69947
2,56000;0,22098;2239,19395
2,60000;0,22433;2274,64121
2,64000;0,22762;2305,69392
2,68000;0,23103;2336,20480
2,72000;0,23426;2366,81886
2,76000;0,23760;2398,50283
2,80000;0,24101;2431,38745
2,84000;0,24430;2461,41795
2,88000;0,24753;2490,45026
2,92000;0,25100;2521,73617
2,96000;0,25428;2552,45175
3,00000;0,25757;2580,01965
3,04000;0,26098;2610,05498
3,08000;0,26427;2641,08013
3,12000;0,26756;2669,98615
3,16000;0,27103;2704,11000
3,20000;0,27431;2734,91945
3,24000;0,27766;2763,61443
3,28000;0,28095;2792,06149
3,32000;0,28430;2821,00663
3,36000;0,28765;2849,69006
3,40000;0,29094;2878,15221
3,44000;0,29434;2906,11722
3,48000;0,29769;2938,18209
3,52000;0,30098;2966,31847
3,56000;0,30427;2993,92976
3,60000;0,30762;3021,85435
3,64000;0,31097;3050,00935
3,68000;0,31431;3077,57128
3,72000;0,31766;3104,33265
3,76000;0,32101;3132,65845
3,80000;0,32436;3158,28323
3,84000;0,32759;3185,32586
3,88000;0,33099;3214,27882
3,92000;0,33434;3241,47418
3,96000;0,33757;3266,15833
4,00000;0,34092;3289,80945
4,04000;0,34433;3313,92623
4,08000;0,34762;3338,14882
4,12000;0,35090;3358,82679
4,16000;0,35431;3379,73833
4,20000;0,35766;3402,27857
4,24000;0,36095;3421,40123
4,28000;0,36430;3441,02606
4,32000;0,36765;3462,17342
4,36000;0,37105;3483,07677
4,40000;0,37434;3503,95851
4,44000;0,37769;3524,75569
4,48000;0,38104;3545,91087
4,52000;0,38433;3566,91629
4,56000;0,38768;3587,18187
4,60000;0,39096;3609,11265
4,64000;0,39431;3629,76380
4,68000;0,39760;3648,65884
4,72000;0,40089;3669,77341
4,76000;0,40430;3690,32621
4,80000;0,40764;3709,25590
4,84000;0,41087;3727,05571
4,88000;0,41428;3746,31770
4,92000;0,41769;3766,66002
4,96000;0,42092;3785,53458
5,00000;0,42433;3804,56224
5,04000;0,42773;3825,76771
5,08000;0,43102;3844,60650
5,12000;0,43437;3861,45897
5,16000;0,43766;3879,05426
5,20000;0,44101;3897,51829
5,24000;0,44430;3915,46674
5,28000;0,44758;3934,82819
5,32000;0,45093;3953,61446
5,36000;0,45428;3972,62312
5,40000;0,45763;3991,23766
5,44000;0,46098;4009,96469
5,48000;0,46427;4028,71706
5,52000;0,46761;4047,67953
5,56000;0,47096;4067,38333
5,60000;0,47425;4086,48066
5,64000;0,47766;4106,14125
5,68000;0,48101;4124,36351
5,72000;0,48424;4143,59905
5,76000;0,48764;4161,87234
5,80000;0,49099;4181,38765
5,84000;0,49422;4199,61438
5,88000;0,49757;4218,45578
5,92000;0,50092;4239,06781
5,96000;0,50426;4258,29850
6,00000;0,50761;4276,97711
6,04000;0,51096;4295,04886
6,08000;0,51431;4314,01581
6,12000;0,51760;4331,37640
6,16000;0,52095;4349,68099
6,20000;0,52429;4369,41162
6,24000;0,52764;4388,29288
6,28000;0,53099;4406,91672
6,32000;0,53440;4425,99505
6,36000;0,53775;4444,76120
6,40000;0,54098;4461,31602
6,44000;0,54438;4481,01908
6,48000;0,54767;4498,63784
6,52000;0,55102;4515,98614
6,56000;0,55437;4533,39592
6,60000;0,55772;4550,52033
6,64000;0,56100;4568,77872
6,68000;0,56435;4584,65964
6,72000;0,56746;4601,92561
6,76000;0,57105;4621,39323
6,80000;0,57440;4640,17466
6,84000;0,57769;4655,84807
6,88000;0,58103;4671,33783
6,92000;0,58444;4688,01670
6,96000;0,58767;4703,70725
7,00000;0,59102;4719,17018
7,04000;0,59431;4735,34390
7,08000;0,59772;4752,18035
7,12000;0,60100;4766,96044
7,16000;0,60435;4783,00229
7,20000;0,60770;4800,03543
7,24000;0,61099;4816,86108
7,28000;0,61434;4831,52270
7,32000;0,61757;4848,57112
7,36000;0,62103;4865,17511
7,40000;0,62438;4882,20304
7,44000;0,62773;4896,19896
7,48000;0,63102;4911,13551
7,52000;0,63437;4926,68040
7,56000;0,63765;4940,51576
7,60000;0,64094;4956,37208
7,64000;0,64435;4972,92913
7,68000;0,64770;4987,13478
7,72000;0,65093;5000,52311
7,76000;0,65434;5015,57440
7,80000;0,65768;5031,52944
7,84000;0,66091;5045,33798
7,88000;0,66426;5057,68657
7,92000;0,66767;5073,92250
7,96000;0,67096;5089,16788
8,00000;0,67437;5101,67964
8,04000;0,67765;5114,49166
8,08000;0,68106;5128,97819
8,12000;0,68429;5141,02504
8,16000;0,68758;5152,96087
8,20000;0,69099;5166,44306
8,24000;0,69434;5180,47661
8,28000;0,69762;5192,09392
8,32000;0,70103;5205,47256
8,36000;0,70432;5218,96146
8,40000;0,70767;5232,03872
8,44000;0,71096;5241,80755
8,48000;0,71431;5254,39940
8,52000;0,71765;5266,71559
8,56000;0,72100;5277,23804
8,60000;0,72411;5287,95309
8,64000;0,72770;5300,67906
8,68000;0,73099;5312,13023
8,72000;0,73421;5320,89509
8,76000;0,73762;5330,30219
8,80000;0,74097;5340,12616
8,84000;0,74426;5348,63397
8,88000;0,74749;5357,03711
8,92000;0,75108;5367,38858
8,96000;0,75436;5376,57812
9,00000;0,75765;5381,77676
9,04000;0,76100;5387,59083
9,08000;0,76441;5394,75754
9,12000;0,76776;5399,05764
9,16000;0,77081;5401,59345
9,20000;0,77445;5410,82658
9,24000;0,77774;5414,44011
9,28000;0,78103;5415,71118
9,32000;0,78438;5417,35180
9,36000;0,78767;5419,71661
9,40000;0,79101;5421,28496
9,44000;0,79436;5421,58931
9,48000;0,79753;5421,87802
9,52000;0,80106;5426,24854
9,56000;0,80441;5425,71209
9,60000;0,80770;5423,78388
9,64000;0,81110;5421,97526
9,68000;0,81445;5421,19369
9,72000;0,81774;5418,99055
9,76000;0,82103;5415,35355
9,80000;0,82438;5413,07889
9,84000;0,82767;5409,84906
9,88000;0,83107;5407,61426
9,92000;0,83442;5410,21265
9,96000;0,83771;5405,48563
10,00000;0,84100;5400,29742
10,04000;0,84435;5394,70054
10,08000;0,84776;5391,13246
10,12000;0,85098;5385,20068
10,16000;0,85427;5379,43207
10,20000;0,85768;5376,24285
10,24000;0,86097;5372,88189
10,28000;0,86438;5367,57074
10,32000;0,86772;5361,85727
10,36000;0,87101;5357,93193
10,40000;0,87442;5353,15052
10,44000;0,87771;5348,59486
10,48000;0,88100;5347,92878
10,52000;0,88441;5342,91640
10,56000;0,88769;5338,06272
10,60000;0,89092;5331,26183
10,64000;0,89427;5325,66458
10,68000;0,89768;5319,34872
10,72000;0,90091;5312,92632
10,76000;0,90408;5306,16902
10,80000;0,90772;5304,53138
10,84000;0,91101;5299,32454
10,88000;0,91430;5291,33119
10,92000;0,91771;5284,63200
10,96000;0,92106;5279,89864
11,00000;0,92429;5272,49500
11,04000;0,92763;5265,69150
11,08000;0,93104;5260,66720
11,12000;0,93433;5254,50706
11,16000;0,93768;5246,53681
11,20000;0,94103;5243,44109
11,24000;0,94438;5237,61921
11,28000;0,94766;5233,75906
11,32000;0,95101;5232,42988
11,36000;0,95430;5234,38677
11,40000;0,95765;5237,75518
11,44000;0,96100;5242,85659
11,48000;0,96428;5250,04379
11,52000;0,96751;5257,97792
11,56000;0,97110;5266,74874
11,60000;0,97427;5275,55309
11,64000;0,97768;5284,03111
11,68000;0,98103;5293,75374
11,72000;0,98431;5303,20406
11,76000;0,98760;5311,80315
11,80000;0,99101;5323,74494
11,84000;0,99436;5334,02674
11,88000;0,99765;5342,54462
11,92000;1,00100;5353,67616
11,96000;1,00434;5365,32141
12,00000;1,00757;5375,58831
12,04000;1,01098;5386,28474
12,08000;1,01439;5399,00213
12,12000;1,01768;5409,56780
12,16000;1,02097;5419,88090
12,20000;1,02437;5433,08146
12,24000;1,02766;5444,09230
12,28000;1,03089;5454,14463
12,32000;1,03442;5465,33950
12,36000;1,03771;5477,29470
12,40000;1,04105;5487,24271
12,44000;1,04434;5496,85806
12,48000;1,04769;5508,55137
12,52000;1,05104;5518,55452
12,56000;1,05433;5527,52577
12,60000;1,05768;5537,46819
12,64000;1,06102;5549,69572
12,68000;1,06437;5558,63678
12,72000;1,06760;5567,06600
12,76000;1,07095;5575,82602
12,80000;1,07430;5585,62428
12,84000;1,07765;5594,97774
12,88000;1,08099;5602,84965
12,92000;1,08434;5612,42774
12,96000;1,08769;5622,23904
13,00000;1,09092;5629,61139
13,04000;1,09433;5639,89431
13,08000;1,09768;5649,73243
13,12000;1,10096;5657,52797
13,16000;1,10431;5664,42199
13,20000;1,10766;5672,77595
13,24000;1,11095;5680,47799
13,28000;1,11430;5688,28210
13,32000;1,11759;5695,72188
13,36000;1,12093;5705,08689
13,40000;1,12428;5713,14655
13,44000;1,12757;5721,38280
13,48000;1,13098;5731,30883
13,52000;1,13433;5741,63832
13,56000;1,13767;5751,90671
13,60000;1,14096;5763,20812
13,64000;1,14431;5775,77464
13,68000;1,14766;5790,48023
13,72000;1,15095;5805,54120
13,76000;1,15436;5822,90068
13,80000;1,15764;5839,03901
13,84000;1,16105;5854,77725
13,88000;1,16434;5868,55635
13,92000;1,16763;5884,64886
13,96000;1,17098;5900,23249
14,00000;1,17427;5916,36598
14,04000;1,17761;5932,50319
14,08000;1,18102;5949,55757
14,12000;1,18437;5964,53585
14,16000;1,18766;5978,50569
14,20000;1,19107;5997,36013
14,24000;1,19441;6012,09328
14,28000;1,19770;6024,48210
14,32000;1,20111;6036,06328
14,36000;1,20440;6049,34581
14,40000;1,20775;6060,93034
14,44000;1,21086;6072,91088
14,48000;1,21438;6088,16631
14,52000;1,21773;6100,28394
14,56000;1,22108;6110,73077
14,60000;1,22437;6120,05107
14,64000;1,22772;6129,82586
14,68000;1,23107;6139,94487
14,72000;1,23435;6150,36376
14,76000;1,23764;6158,59814
14,80000;1,24105;6170,76531
14,84000;1,24440;6179,42810
14,88000;1,24769;6186,35491
14,92000;1,25104;6194,81988
14,96000;1,25444;6203,78368
15,00000;1,25767;6210,74177
15,04000;1,26108;6218,36036
15,08000;1,26443;6229,31272
15,12000;1,26766;6236,39226
15,16000;1,27095;6241,74848
15,20000;1,27435;6249,34509
15,24000;1,27764;6258,13156
15,28000;1,28099;6265,41153
15,32000;1,28428;6272,36739
15,36000;1,28763;6280,19497
15,40000;1,29097;6288,28257
15,44000;1,29438;6295,18628
15,48000;1,29761;6301,72119
15,52000;1,30102;6308,61446
15,56000;1,30437;6317,75260
15,60000;1,30766;6325,76346
15,64000;1,31094;6331,74628
15,68000;1,31435;6341,75465
15,72000;1,31764;6351,82932
15,76000;1,32099;6358,66597
15,80000;1,32428;6366,78189
15,84000;1,32769;6375,85446
15,88000;1,33097;6384,11269
15,92000;1,33426;6392,41785
15,96000;1,33767;6403,30762
16,00000;1,34096;6416,43703
16,04000;1,34431;6426,33215
16,08000;1,34766;6439,22463
16,12000;1,35100;6452,65877
16,16000;1,35435;6464,96788
16,20000;1,35764;6477,65473
16,24000;1,36093;6492,94257
16,28000;1,36440;6512,17401
16,32000;1,36768;6526,55736
16,36000;1,37097;6541,22904
16,40000;1,37438;6556,08475
16,44000;1,37767;6571,45604
16,48000;1,38090;6585,32530
16,52000;1,38431;6600,88807
16,56000;1,38765;6619,04514
16,60000;1,39094;6636,53389
16,64000;1,39429;6652,19799
16,68000;1,39782;6672,91582
16,72000;1,40105;6694,40404
16,76000;1,40434;6708,40815
16,80000;1,40768;6723,47248
16,84000;1,41103;6740,31302
16,88000;1,41432;6757,01424
16,92000;1,41767;6773,48003
16,96000;1,42102;6791,74289
17,00000;1,42442;6807,92332
17,04000;1,42771;6824,07245
17,08000;1,43106;6838,73221
17,12000;1,43435;6854,98416
17,16000;1,43770;6871,15267
17,20000;1,44105;6887,53352
17,24000;1,44433;6904,81961
17,28000;1,44768;6923,38571
17,32000;1,45103;6940,10630
17,36000;1,45426;6955,47536
17,40000;1,45761;6971,42780
17,44000;1,46102;6989,23245
17,48000;1,46424;7005,12901
17,52000;1,46759;7022,31154
17,56000;1,47106;7044,19911
17,60000;1,47435;7061,35705
17,64000;1,47764;7077,00551
17,68000;1,48105;7095,98735
17,72000;1,48439;7114,77622
17,76000;1,48762;7131,80602
17,80000;1,49097;7149,39758
17,84000;1,49438;7169,44113
17,88000;1,49761;7187,10050
17,92000;1,50096;7204,30985
17,96000;1,50436;7223,26338
18,00000;1,50759;7241,83246
18,04000;1,51094;7258,59404
18,08000;1,51429;7277,94692
18,12000;1,51764;7298,48891
18,16000;1,52098;7317,38880
18,20000;1,52433;7335,34470
18,24000;1,52762;7354,81903
18,28000;1,53097;7374,58318
18,32000;1,53432;7393,42719
18,36000;1,53761;7410,66858
18,40000;1,54095;7427,55309
18,44000;1,54430;7446,91566
18,48000;1,54753;7463,96556
18,52000;1,55088;7480,76960
18,56000;1,55429;7501,17227
18,60000;1,55758;7519,84119
18,64000;1,56086;7536,18255
18,68000;1,56427;7555,22624
18,72000;1,56768;7575,21614
18,76000;1,57091;7592,57376
18,80000;1,57432;7610,89474
18,84000;1,57773;7630,21782
18,88000;1,58095;7648,86364
18,92000;1,58430;7665,94782
18,96000;1,58771;7685,65610
19,00000;1,59094;7704,84731
19,04000;1,59423;7722,31966
19,08000;1,59763;7742,61430
19,12000;1,60092;7762,24807
19,16000;1,60427;7779,92085
19,20000;1,60762;7798,71196
19,24000;1,61091;7817,50083
19,28000;1,61432;7835,73613
19,32000;1,61760;7855,39746
19,36000;1,62089;7875,64218
19,40000;1,62430;7895,03306
19,44000;1,62771;7914,12443
19,48000;1,63094;7932,86338
19,52000;1,63435;7950,25751
19,56000;1,63757;7969,84285
19,60000;1,64104;7990,39453
19,64000;1,64433;8009,23035
19,68000;1,64768;8027,57069
19,72000;1,65103;8045,24347
19,76000;1,65426;8062,13915
19,80000;1,65766;8080,89226
19,84000;1,66107;8100,37404
19,88000;1,66430;8118,96920
19,92000;1,66765;8137,95105
19,96000;1,67106;8158,26505
20,00000;1,67429;8177,43018
20,04000;1,67763;8193,94812
20,08000;1,68104;8213,77188
20,12000;1,68433;8232,69412
20,16000;1,68768;8250,52112
20,20000;1,69097;8268,14473
20,24000;1,69431;8288,13389
20,28000;1,69766;8307,67304
20,32000;1,70095;8325,05822
20,36000;1,70430;8343,61538
20,40000;1,70759;8363,53749
20,44000;1,71100;8381,86815
20,48000;1,71428;8399,59905
20,52000;1,71757;8417,19359
20,56000;1,72098;8436,91155
20,60000;1,72433;8454,83094
20,64000;1,72762;8473,51551
20,68000;1,73097;8491,47514
20,72000;1,73437;8510,92562
20,76000;1,73754;8528,30932
20,80000;1,74095;8547,56311
20,84000;1,74430;8567,93150
20,88000;1,74759;8586,54529
20,92000;1,75099;8604,47064
20,96000;1,75434;8622,89965
21,00000;1,75763;8640,84661
21,04000;1,76098;8657,20883
21,08000;1,76427;8673,69473
21,12000;1,76762;8694,05046
21,16000;1,77096;8712,26415
21,20000;1,77431;8730,38918
21,24000;1,77760;8748,95379
21,28000;1,78095;8766,68990
21,32000;1,78424;8784,27923
21,36000;1,78759;8802,49068
21,40000;1,79093;8820,74609
21,44000;1,79428;8839,17809
21,48000;1,79763;8857,10493
21,52000;1,80092;8874,39549
21,56000;1,80439;8893,14786
21,60000;1,80768;8910,27749
21,64000;1,81096;8927,38551
21,68000;1,81431;8945,17750
21,72000;1,81766;8963,35915
21,76000;1,82095;8980,40310
21,80000;1,82442;8999,05115
21,84000;1,82776;9019,33312
21,88000;1,83099;9035,75271
21,92000;1,83434;9051,34603
21,96000;1,83769;9069,06426
22,00000;1,84098;9086,88009
22,04000;1,84433;9104,38895
22,08000;1,84767;9121,63854
22,12000;1,85102;9140,89978
22,16000;1,85437;9158,78415
22,20000;1,85772;9174,78204
22,24000;1,86107;9193,77655
22,28000;1,86442;9211,32267
22,32000;1,86776;9227,57462
22,36000;1,87105;9243,22829
22,40000;1,87440;9259,87586
22,44000;1,87775;9276,67469
22,48000;1,88104;9293,52343
22,52000;1,88433;9310,46456
22,56000;1,88767;9327,96970
22,60000;1,89108;9346,06716
22,64000;1,89431;9362,37425
22,68000;1,89772;9380,14537
22,72000;1,90107;9398,31212
22,76000;1,90430;9414,05743
22,80000;1,90764;9430,64690
22,84000;1,91105;9449,07516
22,88000;1,91434;9464,76161
22,92000;1,91763;9480,70884
22,96000;1,92104;9497,68126
23,00000;1,92432;9515,55148
23,04000;1,92761;9530,65827
23,08000;1,93090;9547,07563
23,12000;1,93431;9566,24001
23,16000;1,93766;9582,90324
23,20000;1,94095;9598,13818
23,24000;1,94435;9614,62706
23,28000;1,94764;9632,09048
23,32000;1,95099;9648,64269
23,36000;1,95428;9664,87154
23,40000;1,95769;9684,04561
23,44000;1,96104;9701,76384
23,48000;1,96444;9717,95842
23,52000;1,96767;9732,77315
23,56000;1,97102;9748,55572
23,60000;1,97437;9764,99766
23,64000;1,97760;9780,10669
23,68000;1,98095;9795,46309
23,72000;1,98441;9815,77709
23,76000;1,98764;9830,99192
23,80000;1,99093;9844,77922
23,84000;1,99428;9859,83312
23,88000;1,99763;9875,28414
23,92000;2,00092;9889,44918
23,96000;2,00432;9904,51649
24,00000;2,00767;9924,40730
24,04000;2,01102;9938,52913
24,08000;2,01437;9952,01394
24,12000;2,01772;9965,99942
24,16000;2,02100;9979,83515
24,20000;2,02429;9993,44215
24,24000;2,02764;10006,71387
24,28000;2,03093;10021,70220
24,32000;2,03428;10035,66980
24,36000;2,03739;10049,27009
24,40000;2,04103;10068,46577
24,44000;2,04432;10082,94448
24,48000;2,04767;10094,83635
24,52000;2,05090;10107,20804
24,56000;2,05431;10121,33881
24,60000;2,05772;10134,78786
24,64000;2,06094;10147,75634
24,68000;2,06435;10161,73214
24,72000;2,06776;10175,46132
24,76000;2,07093;10190,98014
24,80000;2,07446;10206,92438
24,84000;2,07780;10225,36308
24,88000;2,08103;10239,07512
24,92000;2,08432;10251,34772
24,96000;2,08767;10264,55835
25,00000;2,09096;10279,25387
25,04000;2,09431;10292,16573
25,08000;2,09759;10306,11098
25,12000;2,10106;10321,15743
25,16000;2,10435;10338,40626
25,20000;2,10764;10350,61851
25,24000;2,11105;10364,69117
25,28000;2,11434;10380,31429
25,32000;2,11768;10394,59929
25,36000;2,12097;10408,40447
25,40000;2,12432;10423,79215
25,44000;2,12773;10441,90004
25,48000;2,13108;10455,54504
25,52000;2,13431;10469,30850
25,56000;2,13771;10483,97794
25,60000;2,14106;10498,92977
25,64000;2,14429;10513,75121
25,68000;2,14746;10527,67932
25,72000;2,15111;10544,45952
25,76000;2,15428;10559,70192
25,80000;2,15762;10572,96544
25,84000;2,16103;10588,73311
25,88000;2,16432;10603,36009
25,92000;2,16755;10617,31130
25,96000;2,17096;10631,16640
26,00000;2,17424;10647,26561
26,04000;2,17765;10662,35453
26,08000;2,18100;10676,83920
26,12000;2,18429;10691,69119
26,16000;2,18764;10705,41814
26,20000;2,19099;10720,31409
26,24000;2,19427;10733,13504
26,28000;2,19756;10746,81133
26,32000;2,20091;10762,11110
26,36000;2,20432;10777,01226
26,40000;2,20761;10792,39622
26,44000;2,21096;10806,75349
26,48000;2,21430;10821,14950
26,52000;2,21753;10835,51124
26,56000;2,22088;10850,37142
26,60000;2,22429;10864,66908
26,64000;2,22752;10878,81476
26,68000;2,23093;10892,11330
26,72000;2,23433;10907,45181
26,76000;2,23756;10921,67422
26,80000;2,24097;10936,99411
26,84000;2,24432;10953,45691
26,88000;2,24767;10967,59215
26,92000;2,25095;10980,49358
26,96000;2,25430;10994,22574
27,00000;2,25765;11010,86065
27,04000;2,26094;11024,50714
27,08000;2,26429;11039,09835
27,12000;2,26764;11056,34794
27,16000;2,27098;11070,39079
27,20000;2,27433;11084,21385
27,24000;2,27762;11097,91547
27,28000;2,28097;11111,31459
27,32000;2,28426;11125,57128
27,36000;2,28761;11139,84510
27,40000;2,29101;11156,58954
27,44000;2,29436;11171,39012
27,48000;2,29771;11185,01648
27,52000;2,30100;11199,18004
27,56000;2,30435;11214,21605
27,60000;2,30775;11228,63144
27,64000;2,31086;11242,34349
27,68000;2,31439;11258,08358
27,72000;2,31774;11273,92203
27,76000;2,32103;11288,09005
27,80000;2,32432;11300,90505
27,84000;2,32772;11315,47466
27,88000;2,33107;11329,54061
27,92000;2,33430;11343,59613
27,96000;2,33771;11356,90659
28,00000;2,34106;11372,98718
28,04000;2,34441;11386,84079
28,08000;2,34769;11400,92388
28,12000;2,35110;11417,94026
28,16000;2,35439;11431,93543
28,20000;2,35774;11445,36510
28,24000;2,36103;11458,43938
28,28000;2,36432;11471,90854
28,32000;2,36766;11485,91191
28,36000;2,37107;11500,88832
28,40000;2,37436;11516,88024
28,44000;2,37771;11530,89777
28,48000;2,38106;11544,16427
28,52000;2,38435;11558,61244
28,56000;2,38763;11576,20549
28,60000;2,39104;11590,25729
28,64000;2,39433;11604,14591
28,68000;2,39768;11617,84306
28,72000;2,40103;11632,73901
28,76000;2,40431;11647,31011
28,80000;2,40760;11660,86718
28,84000;2,41101;11677,28230
28,88000;2,41424;11692,05755
28,92000;2,41765;11704,07161
28,96000;2,42100;11717,05425
29,00000;2,42428;11731,12020
29,04000;2,42763;11744,63257
29,08000;2,43080;11758,37740
29,12000;2,43433;11773,57137
29,16000;2,43762;11787,26479
29,20000;2,44097;11801,22867
29,24000;2,44437;11814,65462
29,28000;2,44766;11827,97998
29,32000;2,45107;11842,42368
29,36000;2,45436;11855,58885
29,40000;2,45765;11869,69355
29,44000;2,46106;11885,83672
29,48000;2,46434;11898,69121
29,52000;2,46763;11912,63720
29,56000;2,47098;11925,49989
29,60000;2,47439;11940,69460
29,64000;2,47762;11954,32171
29,68000;2,48096;11966,29703
29,72000;2,48437;11982,73748
29,76000;2,48766;11996,14182
29,80000;2,49101;12008,10000
29,84000;2,49436;12021,21451
29,88000;2,49771;12035,91973
29,92000;2,50099;12049,25701
29,96000;2,50428;12062,50489
30,00000;2,50769;12077,11697
30,04000;2,51104;12092,27070
30,08000;2,51439;12105,08794
30,12000;2,51768;12119,00860
30,16000;2,52102;12132,91883
30,20000;2,52431;12145,60643
30,24000;2,52766;12158,49966
30,28000;2,53089;12171,20737
30,32000;2,53436;12186,46765
30,36000;2,53771;12200,48517
30,40000;2,54099;12212,24293
30,44000;2,54440;12227,28491
30,48000;2,54775;12242,17936
30,52000;2,55098;12254,72987
30,56000;2,55433;12265,94895
30,60000;2,55767;12281,15112
30,64000;2,56102;12294,01678
30,68000;2,56431;12305,65384
30,72000;2,56778;12323,51661
30,76000;2,57107;12338,16221
30,80000;2,57430;12347,96047
30,84000;2,57764;12359,96112
30,88000;2,58099;12372,92886
30,92000;2,58434;12385,96663
30,96000;2,58763;12398,81516
31,00000;2,59080;12413,90929
31,04000;2,59439;12429,18521
31,08000;2,59767;12443,20050
31,12000;2,60102;12455,80986
31,16000;2,60425;12467,22117
31,20000;2,60766;12481,32437
31,24000;2,61101;12495,97371
31,28000;2,61430;12509,13143
31,32000;2,61770;12522,87477
31,36000;2,62105;12536,92359
31,40000;2,62428;12548,50477
31,44000;2,62763;12560,52107
31,48000;2,63104;12573,85612
31,52000;2,63433;12586,47293
31,56000;2,63767;12599,11656
31,60000;2,64108;12615,92805
31,64000;2,64431;12628,04419
31,68000;2,64760;12638,51821
31,72000;2,65095;12651,36302
31,76000;2,65429;12665,60256
31,80000;2,65758;12678,05248
31,84000;2,66093;12691,60658
31,88000;2,66434;12707,21853
31,92000;2,66769;12722,11224
31,96000;2,67098;12734,30884
32,00000;2,67432;12747,32500
32,04000;2,67761;12761,40958
32,08000;2,68102;12773,96381
32,12000;2,68431;12787,52387
32,16000;2,68742;12800,68755
32,20000;2,69101;12815,69153
32,24000;2,69429;12831,06655
32,28000;2,69758;12843,98884
32,32000;2,70099;12857,08398
32,36000;2,70434;12871,44870
32,40000;2,70757;12884,06253
32,44000;2,71098;12897,80736
32,48000;2,71432;12911,46129
32,52000;2,71749;12924,64137
32,56000;2,72096;12938,01218
32,60000;2,72437;12952,92825
32,64000;2,72766;12965,50632
32,68000;2,73100;12978,24085
32,72000;2,73435;12991,22572
32,76000;2,73764;13005,85717
32,80000;2,74099;13017,99268
32,84000;2,74428;13030,90602
32,88000;2,74763;13044,85500
32,92000;2,75097;13056,77295
32,96000;2,75426;13070,69361
33,00000;2,75761;13084,16426
33,04000;2,76096;13098,03575
33,08000;2,76431;13112,22464
33,12000;2,76766;13124,44210
33,16000;2,77100;13137,45677
33,20000;2,77435;13150,30158
33,24000;2,77764;13162,85282
33,28000;2,78099;13175,42642
33,32000;2,78440;13188,95221
33,36000;2,78769;13201,95645
33,40000;2,79091;13214,19477
33,44000;2,79432;13228,21379
33,48000;2,79767;13242,45930
33,52000;2,80090;13254,08220
33,56000;2,80425;13265,41454
33,60000;2,80765;13279,72710
33,64000;2,81094;13294,41220
33,68000;2,81423;13306,28246
33,72000;2,81764;13320,53691
33,76000;2,82099;13335,69586
33,80000;2,82434;13348,18900
33,84000;2,82768;13360,57633
33,88000;2,83103;13372,96069
33,92000;2,83432;13384,61488
33,96000;2,83767;13397,88288
34,00000;2,84102;13411,12107
34,04000;2,84431;13424,12084
34,08000;2,84765;13436,14310
34,12000;2,85100;13448,69584
34,16000;2,85429;13461,53468
34,20000;2,85758;13474,79820
34,24000;2,86099;13487,73092
34,28000;2,86422;13500,53251
34,32000;2,86762;13513,48013
34,36000;2,87097;13526,79729
34,40000;2,87426;13539,75236
34,44000;2,87767;13551,77462
34,48000;2,88102;13565,21100
34,52000;2,88424;13577,43442
34,56000;2,88759;13588,85318
34,60000;2,89100;13601,64434
34,64000;2,89429;13614,43549
34,68000;2,89758;13626,14036
34,72000;2,90099;13639,59610
34,76000;2,90433;13652,56011
34,80000;2,90762;13664,63453
34,84000;2,91097;13675,99517
34,88000;2,91432;13689,70275
34,92000;2,91767;13702,83365
34,96000;2,92096;13715,37596
35,00000;2,92436;13728,04940
35,04000;2,92765;13740,77201
35,08000;2,93094;13751,74820
35,12000;2,93435;13764,59748
35,16000;2,93764;13777,40502
35,20000;2,94099;13789,05922
35,24000;2,94433;13801,30351
35,28000;2,94768;13814,29583
35,32000;2,95103;13827,49528
35,36000;2,95444;13838,68456
35,40000;2,95767;13850,31492
35,44000;2,96096;13862,51003
35,48000;2,96442;13876,36662
35,52000;2,96771;13888,79716
35,56000;2,97100;13899,59604
35,60000;2,97441;13912,48107
35,64000;2,97770;13924,79390
35,68000;2,98098;13934,61674
35,72000;2,98433;13946,43933
35,76000;2,98768;13959,12766
35,80000;2,99097;13970,29907
35,84000;2,99432;13981,26483
35,88000;2,99773;13993,21705
35,92000;3,00101;14005,29742
35,96000;3,00436;14016,62380
36,00000;3,00759;14028,51790
36,04000;3,01106;14041,68606
36,08000;3,01441;14054,53235
36,12000;3,01770;14065,28950
36,16000;3,02098;14075,38354
36,20000;3,02439;14086,78144
36,24000;3,02774;14098,44458
36,28000;3,03091;14109,09891
36,32000;3,03432;14121,53691
36,36000;3,03766;14134,12839
36,40000;3,04095;14144,95558
36,44000;3,04436;14156,77369
36,48000;3,04771;14169,16549
36,52000;3,05100;14179,98224
36,56000;3,05429;14188,84248
36,60000;3,05769;14199,41783
36,64000;3,06104;14211,16889
36,68000;3,06433;14221,87239
36,72000;3,06768;14230,86375
36,76000;3,07109;14241,54341
36,80000;3,07438;14252,29311
36,84000;3,07766;14260,98794
36,88000;3,08095;14271,08645
36,92000;3,08430;14281,42190
36,96000;3,08765;14291,38929
37,00000;3,09100;14301,20170
37,04000;3,09429;14310,59241
37,08000;3,09763;14320,44506
37,12000;3,10092;14330,15168
37,16000;3,10421;14339,24437
37,20000;3,10762;14349,01506
37,24000;3,11103;14358,80214
37,28000;3,11432;14368,73078
37,32000;3,11772;14377,34812
37,36000;3,12101;14388,51655
37,40000;3,12430;14396,07292
37,44000;3,12765;14404,12998
37,48000;3,13100;14412,87398
37,52000;3,13428;14420,99959
37,56000;3,13745;14427,44881
37,60000;3,14098;14437,41620
37,64000;3,14433;14447,47001
37,68000;3,14762;14453,99672
37,72000;3,15097;14461,47561
37,76000;3,15437;14472,69469
37,80000;3,15766;14480,58635
37,84000;3,16101;14487,30379
37,88000;3,16436;14494,14343
37,92000;3,16771;14503,13926
37,96000;3,17106;14510,50639
38,00000;3,17434;14518,02254
38,04000;3,17769;14530,04181
38,08000;3,18104;14537,35530
38,12000;3,18439;14544,01761
38,16000;3,18762;14551,63956
38,20000;3,19102;14559,55654
38,24000;3,19437;14569,30190
38,28000;3,19742;14576,76888
38,32000;3,20107;14586,94786
38,36000;3,20442;14597,43977
38,40000;3,20771;14604,70259
38,44000;3,21099;14612,07718
38,48000;3,21440;14620,77647
38,52000;3,21775;14628,04377
38,56000;3,22098;14635,66720
38,60000;3,22415;14644,87165
38,64000;3,22780;14656,67337
38,68000;3,23102;14666,51410
38,72000;3,23431;14674,08091
38,76000;3,23766;14682,66398
38,80000;3,24101;14691,36178
38,84000;3,24430;14699,50825
38,88000;3,24765;14707,87823
38,92000;3,25099;14718,54299
38,96000;3,25440;14729,36720
39,00000;3,25775;14737,17690
39,04000;3,26098;14744,88080
39,08000;3,26427;14753,29995
39,12000;3,26779;14765,73944
39,16000;3,27096;14774,65332
39,20000;3,27437;14781,93551
39,24000;3,27772;14791,60339
39,28000;3,28095;14798,55776
39,32000;3,28430;14806,25421
39,36000;3,28764;14815,53912
39,40000;3,29099;14824,02682
39,44000;3,29404;14830,47456
39,48000;3,29769;14842,37462
39,52000;3,30104;14853,49536
39,56000;3,30433;14860,94594
39,60000;3,30767;14869,20565
39,64000;3,31108;14878,55464
39,68000;3,31437;14886,24662
39,72000;3,31760;14894,57488
39,76000;3,32095;14904,90735
39,80000;3,32430;14914,04623
39,84000;3,32758;14921,90808
39,88000;3,33105;14932,53559
39,92000;3,33434;14944,83054
39,96000;3,33769;14952,88610
40,00000;3,34098;14961,06386
40,04000;3,34427;14969,71101
40,08000;3,34761;14978,43862
40,12000;3,35096;14987,03659
40,16000;3,35425;14995,14580
40,20000;3,35766;15003,75569
40,24000;3,36101;15013,77225
40,28000;3,36424;15021,41207
40,32000;3,36758;15028,33664
40,36000;3,37093;15037,65732
40,40000;3,37428;15046,60547
40,44000;3,37757;15054,17824
40,48000;3,38098;15063,65240
40,52000;3,38438;15072,71975
40,56000;3,38767;15080,72466
40,60000;3,39102;15087,43912
40,64000;3,39443;15095,40528
40,68000;3,39772;15103,24627
40,72000;3,40107;15109,94732
40,76000;3,40441;15117,81514
40,80000;3,40770;15125,62633
40,84000;3,41099;15130,80448
40,88000;3,41440;15138,34447
40,92000;3,41763;15144,39881
40,96000;3,42104;15148,66799
41,00000;3,42432;15152,23384
41,04000;3,42767;15155,54339
41,08000;3,43102;15157,21530
41,12000;3,43431;15156,03960
41,16000;3,43772;15153,10705
41,20000;3,44106;15133,62825
41,24000;3,44555;8716,50577
41,25800;3,44812;2591,65782