File: SU - Suspension/05 - Essais/Excels essais Optimus/Test_Rotules_31_01_19/P7_2.is_tens_RawData/Specimen_RawData_1.csv
Temps;Déplacement;Charge
(sec);(mm);(N)
0,00000;-31,99205;59,92291
0,04000;-31,99181;59,65537
0,08000;-31,99073;65,44334
0,12000;-31,98906;76,63001
0,16000;-31,98679;91,20037
0,20000;-31,98446;108,83653
0,24000;-31,98206;126,11349
0,28000;-31,97973;144,09235
0,32000;-31,97758;162,17210
0,36000;-31,97531;179,79450
0,40000;-31,97315;196,40336
0,44000;-31,97100;211,42033
0,48000;-31,96891;228,13780
0,52000;-31,96693;243,17887
0,56000;-31,96490;257,77847
0,60000;-31,96287;270,69419
0,64000;-31,96084;281,91626
0,68000;-31,95880;293,84918
0,72000;-31,95689;303,56806
0,76000;-31,95480;315,37609
0,80000;-31,95276;326,54775
0,84000;-31,95073;337,60641
0,88000;-31,94870;348,76561
0,92000;-31,94679;360,16891
0,96000;-31,94476;370,89444
1,00000;-31,94278;382,65409
1,04000;-31,94075;394,93390
1,08000;-31,93872;406,99807
1,12000;-31,93680;419,64781
1,16000;-31,93483;430,81231
1,20000;-31,93280;443,03467
1,24000;-31,93082;455,34838
1,28000;-31,92879;467,60458
1,32000;-31,92676;479,83411
1,36000;-31,92484;490,48355
1,40000;-31,92281;502,76546
1,44000;-31,92078;515,41529
1,48000;-31,91880;527,62055
1,52000;-31,91677;541,05492
1,56000;-31,91480;552,65739
1,60000;-31,91276;565,01660
1,64000;-31,91079;575,87628
1,68000;-31,90876;589,37930
1,72000;-31,90673;601,66740
1,76000;-31,90482;613,53319
1,80000;-31,90278;625,30637
1,84000;-31,90075;637,28648
1,88000;-31,89878;648,70976
1,92000;-31,89674;659,36288
1,96000;-31,89483;670,90602
2,00000;-31,89286;680,92430
2,04000;-31,89082;691,69449
2,08000;-31,88885;702,97322
2,12000;-31,88676;714,80121
2,16000;-31,88484;726,07896
2,20000;-31,88287;735,91303
2,24000;-31,88084;747,17049
2,28000;-31,87881;757,78388
2,32000;-31,87677;769,40241
2,36000;-31,87474;782,13960
2,40000;-31,87283;791,75765
2,44000;-31,87085;802,06078
2,48000;-31,86882;812,74491
2,52000;-31,86685;824,02155
2,56000;-31,86475;834,98387
2,60000;-31,86290;845,05947
2,64000;-31,86081;855,41401
2,68000;-31,85883;866,37093
2,72000;-31,85680;876,84691
2,76000;-31,85477;887,13039
2,80000;-31,85280;899,17397
2,84000;-31,85077;908,82052
2,88000;-31,84879;919,43517
2,92000;-31,84682;930,58283
2,96000;-31,84479;940,63310
3,00000;-31,84281;951,37935
3,04000;-31,84090;960,51749
3,08000;-31,83887;970,46783
3,12000;-31,83683;980,82535
3,16000;-31,83480;990,73267
3,20000;-31,83277;1001,15174
3,24000;-31,83091;1010,36346
3,28000;-31,82882;1021,50682
3,32000;-31,82679;1030,97958
3,36000;-31,82482;1041,36579
3,40000;-31,82278;1051,39650
3,44000;-31,82087;1060,90279
3,48000;-31,81884;1070,21173
3,52000;-31,81680;1080,30019
3,56000;-31,81483;1090,83010
3,60000;-31,81280;1099,52847
3,64000;-31,81089;1108,81282
3,68000;-31,80885;1117,22928
3,72000;-31,80682;1128,24682
3,76000;-31,80479;1137,07315
3,80000;-31,80269;1146,01543
3,84000;-31,80078;1155,02374
3,88000;-31,79881;1162,88457
3,92000;-31,79678;1171,32710
3,96000;-31,79480;1180,74501
4,00000;-31,79277;1189,65767
4,04000;-31,79074;1197,84018
4,08000;-31,78882;1205,70082
4,12000;-31,78679;1213,86573
4,16000;-31,78482;1221,51235
4,20000;-31,78284;1228,33271
4,24000;-31,78075;1235,70506
4,28000;-31,77890;1240,62644
4,32000;-31,77680;1242,21919
4,36000;-31,77483;1228,63567
4,40000;-31,77280;1208,54182
4,44000;-31,77082;1207,63835
4,48000;-31,76885;1215,48148
4,52000;-31,76682;1222,04246
4,56000;-31,76484;1228,46551
4,60000;-31,76281;1233,47826
4,64000;-31,76084;1237,32220
4,68000;-31,75881;1240,99236
4,72000;-31,75684;1239,34811
4,76000;-31,75480;1235,79968
4,80000;-31,75277;1229,91614
4,84000;-31,75080;1223,26901
4,88000;-31,74876;1219,52575
4,92000;-31,74685;1215,70192
4,96000;-31,74482;1213,68859
5,00000;-31,74278;1213,98829
5,04000;-31,74075;1212,42395
5,08000;-31,73872;1211,44047
5,12000;-31,73687;1211,60578
5,16000;-31,73483;1210,85700
5,20000;-31,73280;1210,83409
5,24000;-31,73077;1207,88720
5,28000;-31,72873;1203,28162
5,32000;-31,72682;1195,80561
5,36000;-31,72485;1185,34090
5,40000;-31,72275;1172,75231
5,44000;-31,72078;1156,01122
5,48000;-31,71875;1139,88956
5,52000;-31,71671;1124,55776
5,56000;-31,71480;1108,81804
5,60000;-31,71277;1096,63559
5,64000;-31,71080;1083,90525
5,68000;-31,70877;1071,69086
5,72000;-31,70673;1060,89236
5,76000;-31,70482;1048,25180
5,80000;-31,70279;1038,88577
5,84000;-31,70075;1030,01539
5,88000;-31,69878;1021,46436
5,92000;-31,69675;1013,46625
5,96000;-31,69483;1005,76915
6,00000;-31,69274;998,76747
6,04000;-31,69077;992,61282
6,08000;-31,68879;985,81715
6,12000;-31,68676;980,66479
6,16000;-31,68485;974,89851
6,20000;-31,68281;969,14750
6,24000;-31,68078;963,52790
6,28000;-31,67881;958,75347
6,32000;-31,67678;955,13836
6,36000;-31,67480;950,61213
6,40000;-31,67283;945,53540
6,44000;-31,67086;942,41323
6,48000;-31,66883;938,78945
6,52000;-31,66685;935,05625
6,56000;-31,66482;931,61641
6,60000;-31,66291;927,18750
6,64000;-31,66081;923,83353
6,68000;-31,65878;922,38626
6,72000;-31,65675;918,19726
6,76000;-31,65477;914,32538
6,80000;-31,65286;909,68153
6,84000;-31,65083;906,83000
6,88000;-31,64880;904,00409
6,92000;-31,64682;900,74763
6,96000;-31,64473;898,44530
7,00000;-31,64288;893,28988
7,04000;-31,64084;889,53264
7,08000;-31,63881;888,77445
7,12000;-31,63678;886,45630
7,16000;-31,63480;882,38511
7,20000;-31,63283;879,28362
7,24000;-31,63086;875,83279
7,28000;-31,62882;875,68620
7,32000;-31,62679;873,79897
7,36000;-31,62476;870,53869
7,40000;-31,62279;869,58772
7,44000;-31,62081;865,12221
7,48000;-31,61884;863,08625
7,52000;-31,61681;861,03566
7,56000;-31,61483;859,79654
7,60000;-31,61280;857,81980
7,64000;-31,61083;854,78891
7,68000;-31,60880;850,30906
7,72000;-31,60676;848,56283
7,76000;-31,60479;845,23195
7,80000;-31,60276;841,92855
7,84000;-31,60084;839,03400
7,88000;-31,59875;835,66299
7,92000;-31,59678;834,26712
7,96000;-31,59480;831,36521
8,00000;-31,59283;830,03268
8,04000;-31,59086;827,95341
8,08000;-31,58882;824,90677
8,12000;-31,58679;824,12940
8,16000;-31,58482;821,70935
8,20000;-31,58279;818,82142
8,24000;-31,58082;816,87300
8,28000;-31,57884;812,96712
8,32000;-31,57675;812,13638
8,36000;-31,57472;810,69404
8,40000;-31,57274;808,38893
8,44000;-31,57071;806,24642
8,48000;-31,56880;804,24668
8,52000;-31,56676;803,15471
8,56000;-31,56473;801,22873
8,60000;-31,56270;799,36497
8,64000;-31,56067;797,12523
8,68000;-31,55881;794,08512
8,72000;-31,55678;793,69089
8,76000;-31,55469;794,64167
8,80000;-31,55271;792,89181
8,84000;-31,55068;789,26664
8,88000;-31,54883;785,79085
8,92000;-31,54679;782,70454
8,96000;-31,54482;782,43865
9,00000;-31,54279;781,77862
9,04000;-31,54075;779,67132
9,08000;-31,53884;777,69822
9,12000;-31,53681;774,18252
9,16000;-31,53478;773,72449
9,20000;-31,53280;771,47894
9,24000;-31,53071;770,89742
9,28000;-31,52874;769,03361
9,32000;-31,52677;765,86423
9,36000;-31,52479;763,35436
9,40000;-31,52276;762,03956
9,44000;-31,52073;760,47815
9,48000;-31,51875;760,40383
9,52000;-31,51678;758,32172
9,56000;-31,51475;757,09145
9,60000;-31,51277;755,23797
9,64000;-31,51074;753,64397
9,68000;-31,50871;751,56377
9,72000;-31,50679;750,33945
9,76000;-31,50476;749,58401
9,80000;-31,50273;749,46894
9,84000;-31,50076;747,70157
9,88000;-31,49872;745,80456
9,92000;-31,49681;745,51031
9,96000;-31,49478;743,93409
10,00000;-31,49281;744,30322
10,04000;-31,49077;741,46814
10,08000;-31,48874;740,03236
10,12000;-31,48683;739,13797
10,16000;-31,48479;735,57417
10,20000;-31,48282;735,12704
10,24000;-31,48079;734,94976
10,28000;-31,47875;733,23925
10,32000;-31,47672;731,99463
10,36000;-31,47481;727,31790
10,40000;-31,47278;725,62406
10,44000;-31,47074;724,29203
10,48000;-31,46871;723,22469
10,52000;-31,46668;721,46030
10,56000;-31,46476;717,76770
10,60000;-31,46279;715,89923
10,64000;-31,46076;714,17633
10,68000;-31,45878;713,07216
10,72000;-31,45675;712,76762
10,76000;-31,45484;711,01398
10,80000;-31,45280;707,68748
10,84000;-31,45083;707,04003
10,88000;-31,44886;705,05678
10,92000;-31,44677;705,85762
10,96000;-31,44479;704,65514
11,00000;-31,44288;701,27314
11,04000;-31,44073;701,48036
11,08000;-31,43876;698,11898
11,12000;-31,43678;695,87040
11,16000;-31,43475;695,95268
11,20000;-31,43284;693,54936
11,24000;-31,43080;692,56783
11,28000;-31,42877;691,22263
11,32000;-31,42680;690,03701
11,36000;-31,42476;689,46783
11,40000;-31,42285;687,79588
11,44000;-31,42076;687,08952
11,48000;-31,41873;685,74608
11,52000;-31,41669;683,56683
11,56000;-31,41472;681,56859
11,60000;-31,41287;680,44462
11,64000;-31,41077;679,22031
11,68000;-31,40874;680,13095
11,72000;-31,40677;681,10931
11,76000;-31,40473;676,52683
11,80000;-31,40288;674,66302
11,84000;-31,40085;672,39418
11,88000;-31,39882;672,91488
11,92000;-31,39678;672,52461
11,96000;-31,39475;670,66718
12,00000;-31,39284;669,42866
12,04000;-31,39086;665,63562
12,08000;-31,38883;665,42216
12,12000;-31,38686;663,70699
12,16000;-31,38470;664,33954
12,20000;-31,38279;666,13802
12,24000;-31,38088;659,63091
12,28000;-31,37885;659,46192
12,32000;-31,37681;660,02156
12,36000;-31,37478;658,81675
12,40000;-31,37269;658,99026
12,44000;-31,37083;656,42060
12,48000;-31,36874;655,32681
12,52000;-31,36677;656,33291
12,56000;-31,36473;654,16857
12,60000;-31,36276;653,67031
12,64000;-31,36085;652,43100
12,68000;-31,35881;650,41413
12,72000;-31,35678;650,81026
12,76000;-31,35481;649,82940
12,80000;-31,35296;649,81282
12,84000;-31,35075;654,80648
12,88000;-31,34871;648,53956
12,92000;-31,34674;645,96720
12,96000;-31,34477;643,86064
13,00000;-31,34273;642,45542
13,04000;-31,34082;642,01052
13,08000;-31,33885;640,26816
13,12000;-31,33681;640,82909
13,16000;-31,33478;639,11220
13,20000;-31,33281;637,03265
13,24000;-31,33077;636,39549
13,28000;-31,32886;635,17294
13,32000;-31,32677;634,16017
13,36000;-31,32468;634,71473
13,40000;-31,32276;633,55551
13,44000;-31,32067;632,19517
13,48000;-31,31882;629,25522
13,52000;-31,31678;627,00920
13,56000;-31,31481;626,83919
13,60000;-31,31296;625,69142
13,64000;-31,31068;628,46588
13,68000;-31,30883;625,54916
13,72000;-31,30674;622,60088
13,76000;-31,30477;623,29783
13,80000;-31,30273;623,82892
13,84000;-31,30070;625,01747
13,88000;-31,29873;624,15334
13,92000;-31,29682;621,83994
13,96000;-31,29478;621,37390
14,00000;-31,29287;621,15649
14,04000;-31,29072;624,38846
14,08000;-31,28874;620,95858
14,12000;-31,28683;616,93648
14,16000;-31,28480;616,47827
14,20000;-31,28282;615,30857
14,24000;-31,28079;613,93119
14,28000;-31,27876;614,54764
14,32000;-31,27684;613,22432
14,36000;-31,27481;611,18677
14,40000;-31,27284;609,84925
14,44000;-31,27080;607,78167
14,48000;-31,26877;607,30171
14,52000;-31,26692;606,49086
14,56000;-31,26489;604,60148
14,60000;-31,26286;606,29104
14,64000;-31,26082;604,58011
14,68000;-31,25879;603,10615
14,72000;-31,25688;603,43463
14,76000;-31,25472;604,07040
14,80000;-31,25269;605,15506
14,84000;-31,25072;600,54185
14,88000;-31,24868;597,86299
14,92000;-31,24677;595,31531
14,96000;-31,24480;593,35926
15,00000;-31,24282;593,83023
15,04000;-31,24079;593,24736
15,08000;-31,23876;592,40758
15,12000;-31,23678;590,78666
15,16000;-31,23481;590,65218
15,20000;-31,23284;590,10503
15,24000;-31,23081;590,05776
15,28000;-31,22877;590,44631
15,32000;-31,22668;589,95853
15,36000;-31,22483;587,45653
15,40000;-31,22303;586,64996
15,44000;-31,22076;588,55345
15,48000;-31,21879;588,13733
15,52000;-31,21675;585,29433
15,56000;-31,21484;584,57255
15,60000;-31,21281;581,72368
15,64000;-31,21084;581,90613
15,68000;-31,20880;580,65029
15,72000;-31,20677;580,55478
15,76000;-31,20480;580,90184
15,80000;-31,20282;578,77717
15,84000;-31,20079;578,71263
15,88000;-31,19882;577,91136
15,92000;-31,19678;577,84417
15,96000;-31,19481;577,66181
16,00000;-31,19284;575,97840
16,04000;-31,19081;575,48564
16,08000;-31,18878;575,60345
16,12000;-31,18680;575,32140
16,16000;-31,18477;574,42868
16,20000;-31,18285;574,23017
16,24000;-31,18076;573,07458
16,28000;-31,17891;572,39425
16,32000;-31,17676;572,67100
16,36000;-31,17478;570,05375
16,40000;-31,17287;569,36294
16,44000;-31,17084;568,61034
16,48000;-31,16886;567,00320
16,52000;-31,16683;565,84510
16,56000;-31,16486;564,94717
16,60000;-31,16288;566,09237
16,64000;-31,16085;564,97818
16,68000;-31,15882;565,34554
16,72000;-31,15685;564,60439
16,76000;-31,15481;562,83684
16,80000;-31,15290;562,47981
16,84000;-31,15087;563,98869
16,88000;-31,14890;561,78183
16,92000;-31,14680;560,73000
16,96000;-31,14483;559,33683
17,00000;-31,14280;558,77892
17,04000;-31,14094;556,66352
17,08000;-31,13885;556,97202
17,12000;-31,13676;559,24319
17,16000;-31,13478;557,68238
17,20000;-31,13269;557,10282
17,24000;-31,13084;556,21569
17,28000;-31,12874;554,55850
17,32000;-31,12677;554,54294
17,36000;-31,12486;554,42415
17,40000;-31,12271;556,08046
17,44000;-31,12085;553,44161
17,48000;-31,11882;550,42291
17,52000;-31,11685;550,54887
17,56000;-31,11487;549,67012
17,60000;-31,11284;550,01290
17,64000;-31,11087;550,36545
17,68000;-31,10884;547,40263
17,72000;-31,10680;546,68132
17,76000;-31,10483;545,39898
17,80000;-31,10286;543,63664
17,84000;-31,10088;543,88978
17,88000;-31,09891;542,62346
17,92000;-31,09682;542,42839
17,96000;-31,09484;541,47434
18,00000;-31,09287;540,21222
18,04000;-31,09078;540,13594
18,08000;-31,08881;539,91373
18,12000;-31,08677;539,40420
18,16000;-31,08474;537,68633
18,20000;-31,08271;537,50426
18,24000;-31,08073;536,82737
18,28000;-31,07882;535,53488
18,32000;-31,07679;534,55313
18,36000;-31,07482;535,67500
18,40000;-31,07278;534,36402
18,44000;-31,07075;534,29683
18,48000;-31,06884;532,62901
18,52000;-31,06687;532,17812
18,56000;-31,06477;532,95647
18,60000;-31,06274;533,12960
18,64000;-31,06077;531,92801
18,68000;-31,05879;531,07208
18,72000;-31,05682;529,46964
18,76000;-31,05479;528,32034
18,80000;-31,05275;528,06963
18,84000;-31,05072;526,97253
18,88000;-31,04875;526,33970
18,92000;-31,04683;524,39501
18,96000;-31,04480;523,25940
19,00000;-31,04283;523,90839
19,04000;-31,04092;523,10098
19,08000;-31,03870;524,13316
19,12000;-31,03679;521,43754
19,16000;-31,03470;519,62729
19,20000;-31,03272;518,49834
19,24000;-31,03075;517,77945
19,28000;-31,02872;517,70029
19,32000;-31,02680;517,27090
19,36000;-31,02477;515,76900
19,40000;-31,02274;516,44505
19,44000;-31,02076;515,84109
19,48000;-31,01879;515,29189
19,52000;-31,01682;515,65855
19,56000;-31,01485;515,15773
19,60000;-31,01281;515,72253
19,64000;-31,01078;516,15075
19,68000;-31,00881;515,90977
19,72000;-31,00672;517,40799
19,76000;-31,00480;514,15563
19,80000;-31,00277;514,54687
19,84000;-31,00074;513,81472
19,88000;-30,99876;512,73447
19,92000;-30,99673;511,77093
19,96000;-30,99488;511,15486
20,00000;-30,99279;510,50941
20,04000;-30,99075;512,39757
20,08000;-30,98872;509,10763
20,12000;-30,98669;507,09848
20,16000;-30,98483;504,42941
20,20000;-30,98280;503,63624
20,24000;-30,98077;503,23494
20,28000;-30,97873;503,29985
20,32000;-30,97670;502,19619
20,36000;-30,97479;499,72981
20,40000;-30,97282;498,61656
20,44000;-30,97096;500,10937
20,48000;-30,96875;501,21238
20,52000;-30,96672;498,49590
20,56000;-30,96480;496,21793
20,60000;-30,96283;494,73685
20,64000;-30,96080;494,34979
20,68000;-30,95882;493,73158
20,72000;-30,95679;493,17270
20,76000;-30,95482;493,45512
20,80000;-30,95284;491,54791
20,84000;-30,95087;491,19461
20,88000;-30,94884;491,64039
20,92000;-30,94686;491,38721
20,96000;-30,94471;492,33851
21,00000;-30,94280;492,82140
21,04000;-30,94077;490,35512
21,08000;-30,93873;489,41942
21,12000;-30,93676;488,59408
21,16000;-30,93473;487,98965
21,20000;-30,93282;487,88730
21,24000;-30,93078;487,35621
21,28000;-30,92875;487,18434
21,32000;-30,92678;486,19919
21,36000;-30,92475;484,53994
21,40000;-30,92283;484,62879
21,44000;-30,92080;484,49538
21,48000;-30,91871;483,87707
21,52000;-30,91673;481,38788
21,56000;-30,91470;479,55737
21,60000;-30,91279;479,12048
21,64000;-30,91087;477,62529
21,68000;-30,90884;478,64718
21,72000;-30,90681;478,33519
21,76000;-30,90478;476,87339
21,80000;-30,90274;475,04804
21,84000;-30,90089;472,70940
21,88000;-30,89885;473,39480
21,92000;-30,89676;472,68919
21,96000;-30,89473;472,19819
22,00000;-30,89270;471,13379
22,04000;-30,89084;468,08757
22,08000;-30,88875;467,06260
22,12000;-30,88678;467,68049
22,16000;-30,88480;466,49226
22,20000;-30,88271;466,83270
22,24000;-30,88086;466,52155
22,28000;-30,87877;465,25309
22,32000;-30,87679;465,92811
22,36000;-30,87482;465,02529
22,40000;-30,87273;465,82841
22,44000;-30,87075;468,16971
22,48000;-30,86872;464,93341
22,52000;-30,86675;464,36368
22,56000;-30,86478;463,61978
22,60000;-30,86274;463,72162
22,64000;-30,86077;464,50635
22,68000;-30,85885;462,18666
22,72000;-30,85676;462,31132
22,76000;-30,85479;461,03690
22,80000;-30,85276;460,26041
22,84000;-30,85078;460,03778
22,88000;-30,84887;458,51977
22,92000;-30,84678;458,50137
22,96000;-30,84474;458,98817
23,00000;-30,84271;458,02151
23,04000;-30,84074;456,56227
23,08000;-30,83883;456,56194
23,12000;-30,83691;454,98908
23,16000;-30,83476;456,61964
23,20000;-30,83273;454,95490
23,24000;-30,83070;453,75829
23,28000;-30,82884;451,89685
23,32000;-30,82681;450,52124
23,36000;-30,82478;451,39515
23,40000;-30,82274;451,46830
23,44000;-30,82065;450,59742
23,48000;-30,81898;449,69264
23,52000;-30,81664;449,78145
23,56000;-30,81473;447,93217
23,60000;-30,81276;446,53183
23,64000;-30,81072;446,60452
23,68000;-30,80875;446,54044
23,72000;-30,80678;444,53749
23,76000;-30,80481;444,35565
23,80000;-30,80277;445,22164
23,84000;-30,80074;445,08846
23,88000;-30,79871;445,17540
23,92000;-30,79679;443,65828
23,96000;-30,79476;442,64519
24,00000;-30,79279;442,17901
24,04000;-30,79081;440,71958
24,08000;-30,78902;440,26733
24,12000;-30,78675;441,62562
24,16000;-30,78478;440,10654
24,20000;-30,78280;436,47266
24,24000;-30,78077;435,55899
24,28000;-30,77874;435,40075
24,32000;-30,77682;435,10809
24,36000;-30,77479;433,92512
24,40000;-30,77282;433,90989
24,44000;-30,77079;433,27208
24,48000;-30,76881;432,77554
24,52000;-30,76684;432,49722
24,56000;-30,76487;430,57292
24,60000;-30,76301;431,74708
24,64000;-30,76074;433,22453
24,68000;-30,75877;429,85347
24,72000;-30,75680;428,68410
24,76000;-30,75482;427,55790
24,80000;-30,75273;427,59911
24,84000;-30,75076;427,27855
24,88000;-30,74873;426,35249
24,92000;-30,74669;425,89502
24,96000;-30,74484;424,95327
25,00000;-30,74280;423,81240
25,04000;-30,74083;422,82161
25,08000;-30,73886;422,34170
25,12000;-30,73683;422,23148
25,16000;-30,73491;420,33442
25,20000;-30,73288;419,00217
25,24000;-30,73085;419,22033
25,28000;-30,72893;418,98242
25,32000;-30,72672;421,60633
25,36000;-30,72481;417,60174
25,40000;-30,72283;414,13642
25,44000;-30,72080;414,84684
25,48000;-30,71883;413,54988
25,52000;-30,71686;411,84025
25,56000;-30,71482;412,23168
25,60000;-30,71291;409,88876
25,64000;-30,71082;409,06719
25,68000;-30,70878;409,14160
25,72000;-30,70681;407,61945
25,76000;-30,70472;407,63705
25,80000;-30,70280;409,55297
25,84000;-30,70077;406,31825
25,88000;-30,69874;406,01236
25,92000;-30,69677;405,14702
25,96000;-30,69479;404,35921
26,00000;-30,69288;404,58986
26,04000;-30,69085;402,42835
26,08000;-30,68881;401,80637
26,12000;-30,68684;401,84902
26,16000;-30,68481;401,26364
26,20000;-30,68308;401,47929
26,24000;-30,68074;403,72149
26,28000;-30,67877;401,25186
26,32000;-30,67680;399,06064
26,36000;-30,67476;397,72885
26,40000;-30,67279;396,86249
26,44000;-30,67088;395,18569
26,48000;-30,66885;395,95305
26,52000;-30,66681;395,83435
26,56000;-30,66478;395,15919
26,60000;-30,66281;394,49311
26,64000;-30,66095;392,12373
26,68000;-30,65874;393,58488
26,72000;-30,65677;393,19647
26,76000;-30,65467;391,05206
26,80000;-30,65264;389,89941
26,84000;-30,65079;388,14656
26,88000;-30,64870;387,48491
26,92000;-30,64678;385,98015
26,96000;-30,64475;385,44589
27,00000;-30,64272;385,71891
27,04000;-30,64080;383,35156
27,08000;-30,63877;382,38978
27,12000;-30,63680;381,98885
27,16000;-30,63482;382,59544
27,20000;-30,63273;382,32305
27,24000;-30,63082;381,74167
27,28000;-30,62879;380,27468
27,32000;-30,62675;380,45121
27,36000;-30,62478;379,26154
27,40000;-30,62275;377,92416
27,44000;-30,62077;377,62660
27,48000;-30,61880;374,99287
27,52000;-30,61677;374,76954
27,56000;-30,61479;372,95176
27,60000;-30,61270;371,94812
27,64000;-30,61073;370,72760
27,68000;-30,60882;368,90160
27,72000;-30,60672;368,42767
27,76000;-30,60469;368,00525
27,80000;-30,60272;367,44517
27,84000;-30,60075;365,63808
27,88000;-30,59883;364,87363
27,92000;-30,59680;365,43882
27,96000;-30,59477;365,08394
28,00000;-30,59279;363,36628
28,04000;-30,59076;360,89115
28,08000;-30,58885;361,13563
28,12000;-30,58681;360,93232
28,16000;-30,58478;360,72589
28,20000;-30,58275;359,35878
28,24000;-30,58071;357,18386
28,28000;-30,57880;356,50947
28,32000;-30,57689;354,62768
28,36000;-30,57486;354,49979
28,40000;-30,57288;353,34665
28,44000;-30,57085;353,19808
28,48000;-30,56882;352,74364
28,52000;-30,56690;350,45310
28,56000;-30,56487;350,91632
28,60000;-30,56284;351,74834
28,64000;-30,56081;350,75180
28,68000;-30,55871;349,65831
28,72000;-30,55680;347,63643
28,76000;-30,55477;346,49696
28,80000;-30,55279;346,02906
28,84000;-30,55082;345,86464
28,88000;-30,54873;344,97685
28,92000;-30,54681;343,88341
28,96000;-30,54484;341,59878
29,00000;-30,54281;341,26171
29,04000;-30,54084;340,38778
29,08000;-30,53880;339,67593
29,12000;-30,53677;338,59531
29,16000;-30,53480;337,39591
29,20000;-30,53276;336,76582
29,24000;-30,53079;335,70025
29,28000;-30,52882;334,72150
29,32000;-30,52684;335,41587
29,36000;-30,52487;333,91661
29,40000;-30,52284;333,66135
29,44000;-30,52087;331,69892
29,48000;-30,51889;330,36864
29,52000;-30,51680;330,76790
29,56000;-30,51489;330,00032
29,60000;-30,51285;329,38928
29,64000;-30,51082;329,64165
29,68000;-30,50879;327,38734
29,72000;-30,50676;326,61723
29,76000;-30,50484;325,28043
29,80000;-30,50281;325,47996
29,84000;-30,50078;325,02585
29,88000;-30,49880;323,67290
29,92000;-30,49677;322,64134
29,96000;-30,49486;322,68483
30,00000;-30,49288;321,07451
30,04000;-30,49085;322,10082
30,08000;-30,48876;322,25247
30,12000;-30,48673;320,76980
30,16000;-30,48475;320,35790
30,20000;-30,48284;318,65055
30,24000;-30,48081;319,29219
30,28000;-30,47877;318,89386
30,32000;-30,47680;317,69148
30,36000;-30,47471;316,99215
30,40000;-30,47286;313,83394
30,44000;-30,47082;313,39629
30,48000;-30,46885;312,39232
30,52000;-30,46682;311,90021
30,56000;-30,46472;311,86040
30,60000;-30,46287;310,46700
30,64000;-30,46078;309,06876
30,68000;-30,45880;307,92963
30,72000;-30,45683;307,39002
30,76000;-30,45474;307,56136
30,80000;-30,45283;306,71482
30,84000;-30,45079;304,35685
30,88000;-30,44876;304,98437
30,92000;-30,44679;304,26886
30,96000;-30,44481;304,54095
31,00000;-30,44284;304,43170
31,04000;-30,44081;302,48913
31,08000;-30,43877;303,19979
31,12000;-30,43680;302,08579
31,16000;-30,43477;300,85358
31,20000;-30,43274;300,73547
31,24000;-30,43076;299,62852
31,28000;-30,42873;299,92550
31,32000;-30,42670;299,04083
31,36000;-30,42466;298,05424
31,40000;-30,42269;297,85940
31,44000;-30,42084;296,53271
31,48000;-30,41875;297,35654
31,52000;-30,41677;296,85930
31,56000;-30,41474;295,96549
31,60000;-30,41271;294,58012
31,64000;-30,41080;292,85219
31,68000;-30,40876;291,28648
31,72000;-30,40673;292,15061
31,76000;-30,40476;290,55802
31,80000;-30,40266;289,88500
31,84000;-30,40081;288,45845
31,88000;-30,39884;286,94568
31,92000;-30,39686;287,38426
31,96000;-30,39483;287,27639
32,00000;-30,39280;286,41294
32,04000;-30,39083;285,65098
32,08000;-30,38885;283,14970
32,12000;-30,38682;283,63254
32,16000;-30,38478;282,82041
32,20000;-30,38275;282,67140
32,24000;-30,38072;283,82086
32,28000;-30,37875;281,41129
32,32000;-30,37677;280,57718
32,36000;-30,37480;280,06313
32,40000;-30,37277;279,64222
32,44000;-30,37073;280,06246
32,48000;-30,36882;278,97067
32,52000;-30,36679;277,98109
32,56000;-30,36476;277,87837
32,60000;-30,36278;276,72665
32,64000;-30,36087;276,82146
32,68000;-30,35878;276,79212
32,72000;-30,35674;276,58998
32,76000;-30,35477;275,51353
32,80000;-30,35280;274,75893
32,84000;-30,35076;273,96742
32,88000;-30,34885;273,43824
32,92000;-30,34688;272,96471
32,96000;-30,34485;273,34664
33,00000;-30,34275;271,87401
33,04000;-30,34078;270,61601
33,08000;-30,33881;270,37221
33,12000;-30,33683;269,03898
33,16000;-30,33480;268,95476
33,20000;-30,33277;267,92423
33,24000;-30,33074;267,10227
33,28000;-30,32870;266,84734
33,32000;-30,32685;264,99324
33,36000;-30,32482;264,07710
33,40000;-30,32272;264,94854
33,44000;-30,32075;263,65947
33,48000;-30,31872;263,42792
33,52000;-30,31681;262,22186
33,56000;-30,31477;260,81225
33,60000;-30,31280;261,71464
33,64000;-30,31077;260,44177
33,68000;-30,30873;260,35579
33,72000;-30,30682;259,48137
33,76000;-30,30485;258,55030
33,80000;-30,30281;258,30434
33,84000;-30,30084;257,85386
33,88000;-30,29881;258,21102
33,92000;-30,29677;257,92036
33,96000;-30,29486;256,57455
34,00000;-30,29283;256,24081
34,04000;-30,29079;255,05801
34,08000;-30,28882;254,32950
34,12000;-30,28679;255,30558
34,16000;-30,28488;254,24182
34,20000;-30,28278;254,16459
34,24000;-30,28081;254,33206
34,28000;-30,27884;252,74793
34,32000;-30,27681;252,91347
34,36000;-30,27489;251,69537
34,40000;-30,27280;251,15579
34,44000;-30,27077;250,14812
34,48000;-30,26873;249,73599
34,52000;-30,26670;249,46679
34,56000;-30,26491;248,38019