File: SU - Suspension/05 - Essais/Excels essais Optimus/Test_Rotules_31_01_19/P7_4.is_tens_RawData/Specimen_RawData_1.csv
Temps;Déplacement;Charge
(sec);(mm);(N)
0,00000;0,09441;19,25223
0,04000;0,09453;19,07048
0,08000;0,09483;20,07382
0,12000;0,09602;22,32306
0,16000;0,09782;27,53471
0,20000;0,09973;33,60702
0,24000;0,10194;40,63617
0,28000;0,10409;48,45837
0,32000;0,10637;56,48471
0,36000;0,10852;65,04832
0,40000;0,11055;72,55364
0,44000;0,11270;80,96463
0,48000;0,11480;88,52918
0,52000;0,11689;97,16043
0,56000;0,11892;105,39250
0,60000;0,12089;112,52069
0,64000;0,12299;120,98819
0,68000;0,12502;127,87930
0,72000;0,12699;135,54498
0,76000;0,12903;142,78241
0,80000;0,13094;150,22859
0,84000;0,13297;157,66880
0,88000;0,13500;165,15478
0,92000;0,13704;170,53752
0,96000;0,13907;176,72647
1,00000;0,14098;181,68644
1,04000;0,14302;185,98896
1,08000;0,14505;189,72073
1,12000;0,14708;194,64673
1,16000;0,14906;197,07491
1,20000;0,15103;199,94695
1,24000;0,15294;202,85505
1,28000;0,15503;204,31341
1,32000;0,15701;206,17330
1,36000;0,15904;208,78511
1,40000;0,16101;210,05967
1,44000;0,16299;211,50948
1,48000;0,16502;214,44382
1,52000;0,16705;217,69656
1,56000;0,16902;222,16185
1,60000;0,17106;226,32652
1,64000;0,17291;231,39750
1,68000;0,17494;236,61880
1,72000;0,17698;241,67690
1,76000;0,17895;245,24615
1,80000;0,18098;248,66157
1,84000;0,18290;252,10560
1,88000;0,18493;254,67807
1,92000;0,18696;256,96557
1,96000;0,18899;257,25903
2,00000;0,19109;255,98153
2,04000;0,19306;251,25169
2,08000;0,19497;238,37881
2,12000;0,19701;175,78134
2,16000;0,19898;174,04970
2,20000;0,20101;193,22267
2,24000;0,20305;203,39498
2,28000;0,20496;210,78216
2,32000;0,20699;218,65931
2,36000;0,20902;226,82201
2,40000;0,21100;235,79139
2,44000;0,21303;244,51781
2,48000;0,21494;253,48945
2,52000;0,21704;262,20323
2,56000;0,21901;269,84042
2,60000;0,22098;277,52090
2,64000;0,22301;284,78762
2,68000;0,22493;290,23793
2,72000;0,22696;296,36351
2,76000;0,22893;302,04458
2,80000;0,23097;305,87444
2,84000;0,23300;311,73890
2,88000;0,23497;316,53803
2,92000;0,23695;322,26674
2,96000;0,23904;327,93612
3,00000;0,24101;333,43898
3,04000;0,24304;339,86222
3,08000;0,24502;345,11201
3,12000;0,24693;351,52552
3,16000;0,24902;358,48003
3,20000;0,25100;364,67277
3,24000;0,25297;371,63305
3,28000;0,25506;379,60722
3,32000;0,25692;386,63661
3,36000;0,25895;394,63025
3,40000;0,26104;403,00987
3,44000;0,26301;411,96761
3,48000;0,26511;420,46169
3,52000;0,26696;429,35153
3,56000;0,26899;438,22513
3,60000;0,27103;446,82515
3,64000;0,27306;456,57954
3,68000;0,27509;466,16034
3,72000;0,27700;475,92442
3,76000;0,27898;484,37458
3,80000;0,28101;493,62378
3,84000;0,28298;503,77455
3,88000;0,28502;513,42612
3,92000;0,28705;524,37158
3,96000;0,28896;533,59955
4,00000;0,29106;543,24619
4,04000;0,29303;553,94536
4,08000;0,29500;565,03704
4,12000;0,29709;575,39823
4,16000;0,29895;584,84883
4,20000;0,30104;594,29929
4,24000;0,30301;603,99547
4,28000;0,30499;613,93431
4,32000;0,30702;624,23735
4,36000;0,30893;634,42355
4,40000;0,31102;644,50880
4,44000;0,31300;654,14263
4,48000;0,31503;664,20082
4,52000;0,31706;674,16281
4,56000;0,31904;683,61494
4,60000;0,32107;693,13189
4,64000;0,32310;703,58934
4,68000;0,32508;712,91788
4,72000;0,32717;722,04107
4,76000;0,32902;730,97437
4,80000;0,33099;739,74738
4,84000;0,33303;750,43431
4,88000;0,33506;759,64611
4,92000;0,33709;768,76921
4,96000;0,33907;778,49897
5,00000;0,34104;785,63737
5,04000;0,34307;794,63832
5,08000;0,34510;802,36616
5,12000;0,34708;811,04161
5,16000;0,34911;819,25839
5,20000;0,35096;826,69612
5,24000;0,35300;834,70531
5,28000;0,35497;843,20577
5,32000;0,35700;851,96281
5,36000;0,35904;860,85703
5,40000;0,36095;867,70309
5,44000;0,36304;875,62148
5,48000;0,36501;882,77757
5,52000;0,36705;891,04138
5,56000;0,36908;897,34336
5,60000;0,37105;905,43143
5,64000;0,37309;911,94874
5,68000;0,37506;918,50283
5,72000;0,37703;924,66827
5,76000;0,37907;930,95694
5,80000;0,38104;936,80751
5,84000;0,38301;941,27208
5,88000;0,38504;946,23938
5,92000;0,38708;950,15746
5,96000;0,38905;954,27949
6,00000;0,39108;958,20427
6,04000;0,39300;962,22945
6,08000;0,39509;965,25652
6,12000;0,39706;969,09758
6,16000;0,39904;971,45615
6,20000;0,40107;974,51601
6,24000;0,40292;976,30238
6,28000;0,40501;978,91884
6,32000;0,40699;982,38438
6,36000;0,40902;984,41476
6,40000;0,41105;985,45654
6,44000;0,41297;986,24378
6,48000;0,41494;986,28337
6,52000;0,41703;984,57048
6,56000;0,41906;979,90157
6,60000;0,42110;972,58184
6,64000;0,42301;964,18904
6,68000;0,42492;954,82627
6,72000;0,42702;949,70167
6,76000;0,42905;944,25566
6,80000;0,43108;937,18478
6,84000;0,43306;929,40461
6,88000;0,43503;921,97480
6,92000;0,43706;916,37960
6,96000;0,43909;910,81336
7,00000;0,44107;904,11538
7,04000;0,44316;897,28646
7,08000;0,44501;890,72855
7,12000;0,44705;884,85675
7,16000;0,44902;879,50779
7,20000;0,45105;875,30967
7,24000;0,45308;869,23558
7,28000;0,45500;862,94226
7,32000;0,45703;855,66854
7,36000;0,45900;851,57277
7,40000;0,46104;845,81040
7,44000;0,46301;841,14922
7,48000;0,46498;836,88255
7,52000;0,46702;829,98658
7,56000;0,46905;826,79829
7,60000;0,47102;822,29674
7,64000;0,47299;818,01210
7,68000;0,47503;816,65562
7,72000;0,47694;812,67292
7,76000;0,47903;810,55826
7,80000;0,48107;807,39921
7,84000;0,48310;805,14438
7,88000;0,48507;802,50688
7,92000;0,48687;800,25122
7,96000;0,48902;799,18057
8,00000;0,49105;797,18726
8,04000;0,49308;794,01759
8,08000;0,49506;792,58550
8,12000;0,49691;791,09482
8,16000;0,49900;788,78393
8,20000;0,50104;788,76745
8,24000;0,50301;786,20166
8,28000;0,50510;784,02758
8,32000;0,50701;781,32777
8,36000;0,50887;778,54735
8,40000;0,51108;779,20868
8,44000;0,51299;776,89546
8,48000;0,51509;772,86982
8,52000;0,51706;769,45177
8,56000;0,51897;766,60621
8,60000;0,52101;765,38431
8,64000;0,52304;764,10226
8,68000;0,52507;761,89106
8,72000;0,52710;758,97910
8,76000;0,52902;753,81789
8,80000;0,53111;751,46994
8,84000;0,53278;748,35732
8,88000;0,53518;748,85567
8,92000;0,53715;746,58631
8,96000;0,53900;741,70423
9,00000;0,54109;738,86611
9,04000;0,54307;737,53935
9,08000;0,54504;735,97794
9,12000;0,54713;734,99363
9,16000;0,54899;734,01532
9,20000;0,55102;731,75998
9,24000;0,55305;731,84399
9,28000;0,55503;730,00309
9,32000;0,55706;728,18482
9,36000;0,55897;726,36227
9,40000;0,56083;724,11997
9,44000;0,56304;726,93517
9,48000;0,56507;723,97669
9,52000;0,56710;719,76087
9,56000;0,56908;718,03769
9,60000;0,57105;716,36015
9,64000;0,57308;716,42585
9,68000;0,57512;715,24521
9,72000;0,57715;714,10062
9,76000;0,57912;711,99099
9,80000;0,58097;708,01396
9,84000;0,58301;707,43402
9,88000;0,58498;707,48543
9,92000;0,58701;706,91654
9,96000;0,58905;705,79476
10,00000;0,59096;703,77761
10,04000;0,59299;700,58582
10,08000;0,59508;702,75157
10,12000;0,59712;703,28442
10,16000;0,59915;698,14171
10,20000;0,60106;695,00040
10,24000;0,60304;692,48192
10,28000;0,60501;691,45090
10,32000;0,60704;690,01652
10,36000;0,60902;689,52520
10,40000;0,61105;687,67667
10,44000;0,61296;684,74384
10,48000;0,61499;684,65080
10,52000;0,61703;683,76837
10,56000;0,61906;682,38010
10,60000;0,62109;682,76431
10,64000;0,62289;679,88201
10,68000;0,62510;679,99149
10,72000;0,62707;679,03353
10,76000;0,62905;676,25185
10,80000;0,63108;674,82311
10,84000;0,63299;673,66343
10,88000;0,63502;671,80716
10,92000;0,63700;671,42006
10,96000;0,63903;671,26220
11,00000;0,64106;669,47974
11,04000;0,64298;669,08668
11,08000;0,64501;667,18371
11,12000;0,64704;667,77305
11,16000;0,64907;665,79124
11,20000;0,65105;663,70950
11,24000;0,65302;662,82395
11,28000;0,65464;660,96648
11,32000;0,65715;666,11753
11,36000;0,65906;660,52657
11,40000;0,66109;655,89761
11,44000;0,66307;655,46446
11,48000;0,66498;653,20246
11,52000;0,66701;652,77736
11,56000;0,66904;652,65652
11,60000;0,67108;651,09823
11,64000;0,67311;650,53292
11,68000;0,67496;647,14109
11,72000;0,67700;646,27226
11,76000;0,67903;646,10997
11,80000;0,68106;645,53837
11,84000;0,68304;642,81542
11,88000;0,68495;642,38138
11,92000;0,68704;640,87012
11,96000;0,68901;641,55506
12,00000;0,69093;639,31057
12,04000;0,69314;641,58333
12,08000;0,69499;637,96709
12,12000;0,69703;634,25736
12,16000;0,69900;634,79403
12,20000;0,70103;634,36590
12,24000;0,70306;632,95197
12,28000;0,70498;633,12538
12,32000;0,70695;630,42310
12,36000;0,70904;630,87107
12,40000;0,71108;630,66590
12,44000;0,71305;627,69311
12,48000;0,71508;627,20045
12,52000;0,71700;625,17473
12,56000;0,71909;625,32066
12,60000;0,72106;624,55758
12,64000;0,72303;623,37625
12,68000;0,72507;622,57163
12,72000;0,72692;620,84594
12,76000;0,72907;621,37689
12,80000;0,73105;620,43052
12,84000;0,73302;619,53729
12,88000;0,73511;618,28084
12,92000;0,73697;618,15381
12,96000;0,73900;616,87357
13,00000;0,74103;618,26371
13,04000;0,74306;617,08754
13,08000;0,74510;615,69302
13,12000;0,74695;613,07573
13,16000;0,74892;612,90944
13,20000;0,75102;613,82423
13,24000;0,75299;613,56747
13,28000;0,75508;612,43451
13,32000;0,75705;611,61071
13,36000;0,75903;609,15346
13,40000;0,76106;610,14048
13,44000;0,76309;611,05476
13,48000;0,76513;610,43203
13,52000;0,76716;609,84101
13,56000;0,76901;606,97282
13,60000;0,77105;606,44029
13,64000;0,77296;606,18911
13,68000;0,77505;605,64745
13,72000;0,77702;604,72013
13,76000;0,77900;603,34452
13,80000;0,78103;601,32197
13,84000;0,78300;599,86259
13,88000;0,78498;599,39148
13,92000;0,78707;600,03642
13,96000;0,78898;597,75948
14,00000;0,79101;595,28523
14,04000;0,79299;594,13183
14,08000;0,79502;593,35828
14,12000;0,79705;592,80968
14,16000;0,79903;593,14584
14,20000;0,80100;590,42955
14,24000;0,80303;590,54531
14,28000;0,80507;589,75569
14,32000;0,80710;589,52537
14,36000;0,80907;591,10713
14,40000;0,81104;588,18413
14,44000;0,81308;587,65793
14,48000;0,81511;587,38943
14,52000;0,81708;586,37750
14,56000;0,81912;585,33740
14,60000;0,82097;583,98163
14,64000;0,82300;583,44305
14,68000;0,82504;584,62140
14,72000;0,82707;583,93190
14,76000;0,82904;582,59810
14,80000;0,83095;582,34073
14,84000;0,83299;581,02580
14,88000;0,83502;582,78162
14,92000;0,83705;580,80330
14,96000;0,83909;579,67026
15,00000;0,84100;578,91603
15,04000;0,84297;577,11801
15,08000;0,84500;577,91565
15,12000;0,84704;577,43629
15,16000;0,84907;576,79396
15,20000;0,85104;575,82934
15,24000;0,85296;573,86877
15,28000;0,85499;574,07659
15,32000;0,85702;573,98835
15,36000;0,85906;573,40879
15,40000;0,86109;573,36208
15,44000;0,86300;571,13781
15,48000;0,86503;569,89645
15,52000;0,86707;569,36899
15,56000;0,86910;569,89202
15,60000;0,87113;568,43120
15,64000;0,87305;566,64487
15,68000;0,87508;565,62098
15,72000;0,87705;565,87532
15,76000;0,87903;565,13478
15,80000;0,88100;565,81390
15,84000;0,88297;567,02239
15,88000;0,88500;564,52439
15,92000;0,88704;564,63787
15,96000;0,88901;564,08602
16,00000;0,89104;563,65933
16,04000;0,89302;563,09812
16,08000;0,89499;562,80787
16,12000;0,89702;563,27623
16,16000;0,89905;562,70808
16,20000;0,90103;561,18965
16,24000;0,90300;561,21284
16,28000;0,90491;560,34597
16,32000;0,90701;560,17805
16,36000;0,90898;560,90192
16,40000;0,91101;559,20361
16,44000;0,91305;558,38465
16,48000;0,91496;557,35335
16,52000;0,91705;557,30995
16,56000;0,91908;555,91525
16,60000;0,92106;555,06802
16,64000;0,92315;554,44706
16,68000;0,92500;553,98648
16,72000;0,92704;551,47270
16,76000;0,92901;552,58316
16,80000;0,93098;552,61389
16,84000;0,93302;551,58339
16,88000;0,93499;551,62893
16,92000;0,93690;550,10305
16,96000;0,93899;551,73752
17,00000;0,94103;551,14864
17,04000;0,94306;550,43525
17,08000;0,94503;550,25406
17,12000;0,94701;548,52404
17,16000;0,94904;547,81297
17,20000;0,95095;547,07085
17,24000;0,95298;547,51583
17,28000;0,95502;550,15427
17,32000;0,95693;546,34637
17,36000;0,95902;546,62675
17,40000;0,96106;546,23862
17,44000;0,96303;545,91373
17,48000;0,96512;546,46232
17,52000;0,96698;546,16607
17,56000;0,96913;545,72127
17,60000;0,97110;545,70776
17,64000;0,97307;545,27158
17,68000;0,97517;545,07856
17,72000;0,97702;544,01797
17,76000;0,97905;543,01322
17,80000;0,98103;543,50803
17,84000;0,98306;541,79630
17,88000;0,98515;541,89954
17,92000;0,98706;539,91918
17,96000;0,98886;537,92228
18,00000;0,99113;539,55126
18,04000;0,99310;537,53001
18,08000;0,99514;536,92507
18,12000;0,99705;535,46699
18,16000;0,99896;533,31507
18,20000;1,00100;532,79153
18,24000;1,00303;532,89663
18,28000;1,00506;532,51851
18,32000;1,00709;532,18477
18,36000;1,00901;530,01973
18,40000;1,01098;529,70126
18,44000;1,01301;529,34927
18,48000;1,01505;529,84846
18,52000;1,01714;530,58635
18,56000;1,01899;528,22758
18,60000;1,02103;526,76490
18,64000;1,02300;526,70008
18,68000;1,02503;527,11666
18,72000;1,02706;527,24974
18,76000;1,02898;527,37226
18,80000;1,03107;525,87502
18,84000;1,03304;524,96162
18,88000;1,03502;524,53689
18,92000;1,03705;524,77564
18,96000;1,03902;524,70015
19,00000;1,04111;524,37005
19,04000;1,04309;522,20421
19,08000;1,04512;521,58185
19,12000;1,04703;521,82646
19,16000;1,04907;521,09710
19,20000;1,05104;520,58348
19,24000;1,05307;520,51586
19,28000;1,05511;520,37067
19,32000;1,05708;518,75021
19,36000;1,05911;518,61438
19,40000;1,06096;516,72528
19,44000;1,06306;516,16933
19,48000;1,06509;515,34064
19,52000;1,06706;513,39772
19,56000;1,06910;512,07771
19,60000;1,07095;511,29684
19,64000;1,07292;509,88495
19,68000;1,07507;511,62243
19,72000;1,07711;509,78702
19,76000;1,07914;507,31134
19,80000;1,08099;506,25056
19,84000;1,08303;504,85367
19,88000;1,08506;505,02722
19,92000;1,08709;504,63798
19,96000;1,08913;503,95583
20,00000;1,09104;502,57957
20,04000;1,09301;500,81951
20,08000;1,09504;502,07898
20,12000;1,09702;502,40895
20,16000;1,09893;502,08159
20,20000;1,10108;503,59624
20,24000;1,10300;500,43371
20,28000;1,10503;500,39934
20,32000;1,10700;499,60990
20,36000;1,10904;499,24552
20,40000;1,11101;499,00152
20,44000;1,11292;497,29040
20,48000;1,11501;495,43222
20,52000;1,11699;495,28121
20,56000;1,11902;494,29559
20,60000;1,12099;493,84809
20,64000;1,12297;494,45662
20,68000;1,12476;493,19523
20,72000;1,12709;496,32941
20,76000;1,12901;492,91523
20,80000;1,13104;490,27624
20,84000;1,13295;491,53804
20,88000;1,13498;490,72010
20,92000;1,13702;490,05053
20,96000;1,13905;489,86059
21,00000;1,14108;488,12819
21,04000;1,14306;487,58797
21,08000;1,14497;486,54880
21,12000;1,14706;486,55714
21,16000;1,14915;488,75129
21,20000;1,15113;485,62186
21,24000;1,15310;485,12188
21,28000;1,15495;483,79027
21,32000;1,15699;483,61099
21,36000;1,15902;484,87149
21,40000;1,16099;484,51582
21,44000;1,16309;484,16425
21,48000;1,16500;482,33881
21,52000;1,16703;481,48204
21,56000;1,16900;481,75207
21,60000;1,17104;481,90854
21,64000;1,17283;481,79002
21,68000;1,17504;483,21877
21,72000;1,17702;479,91197
21,76000;1,17905;479,58079
21,80000;1,18102;478,67922
21,84000;1,18299;477,87381
21,88000;1,18497;476,80880
21,92000;1,18700;475,31603
21,96000;1,18903;476,30654
22,00000;1,19101;475,19850
22,04000;1,19304;474,27844
22,08000;1,19507;475,32390
22,12000;1,19705;474,00147
22,16000;1,19908;474,22494
22,20000;1,20105;471,89849
22,24000;1,20308;471,92178
22,28000;1,20512;471,53020
22,32000;1,20691;469,79189
22,36000;1,20906;471,38096
22,40000;1,21104;471,07264
22,44000;1,21307;468,81405
22,48000;1,21510;467,68244
22,52000;1,21696;466,79461
22,56000;1,21905;466,64514
22,60000;1,22108;467,33604
22,64000;1,22311;466,17081
22,68000;1,22509;465,29383
22,72000;1,22700;465,23190
22,76000;1,22897;464,53318
22,80000;1,23101;465,18235
22,84000;1,23304;465,76080
22,88000;1,23489;464,92266
22,92000;1,23704;464,42952
22,96000;1,23902;462,64306
23,00000;1,24105;463,26257
23,04000;1,24308;461,79704
23,08000;1,24512;462,94332
23,12000;1,24709;461,59965
23,16000;1,24900;459,94311
23,20000;1,25104;460,44788
23,24000;1,25307;460,56537
23,28000;1,25504;459,71195
23,32000;1,25707;459,73849
23,36000;1,25899;458,01755
23,40000;1,26102;457,36125
23,44000;1,26299;456,97954
23,48000;1,26509;458,16856
23,52000;1,26712;459,59209
23,56000;1,26903;456,27207
23,60000;1,27101;455,27690
23,64000;1,27304;455,33516
23,68000;1,27501;454,78866
23,72000;1,27704;454,96183
23,76000;1,27902;454,63503
23,80000;1,28093;452,37322
23,84000;1,28296;452,51949
23,88000;1,28500;451,61983
23,92000;1,28697;451,49177
23,96000;1,28906;451,59375
24,00000;1,29103;449,88957
24,04000;1,29307;450,09996
24,08000;1,29504;447,61109
24,12000;1,29707;447,73524
24,16000;1,29905;447,45989
24,20000;1,30096;446,26691
24,24000;1,30305;446,26119
24,28000;1,30503;446,43944
24,32000;1,30706;446,37928
24,36000;1,30909;445,96596
24,40000;1,31094;445,44251
24,44000;1,31304;445,54337
24,48000;1,31501;446,12172
24,52000;1,31704;445,02742
24,56000;1,31908;443,75896
24,60000;1,32099;443,44594
24,64000;1,32296;442,65022
24,68000;1,32494;443,05893
24,72000;1,32697;443,20947
24,76000;1,32900;442,66847
24,80000;1,33097;441,60224
24,84000;1,33295;439,96531
24,88000;1,33498;440,42510
24,92000;1,33701;441,19665
24,96000;1,33905;440,60494
25,00000;1,34108;440,50626
25,04000;1,34299;438,70313
25,08000;1,34502;438,12632
25,12000;1,34700;438,18136
25,16000;1,34897;437,71993
25,20000;1,35100;437,59285
25,24000;1,35292;436,84333
25,28000;1,35501;435,62306
25,32000;1,35698;435,39153
25,36000;1,35896;435,03707
25,40000;1,36105;434,62170
25,44000;1,36296;433,29592
25,48000;1,36499;430,84803
25,52000;1,36703;431,26172
25,56000;1,36900;429,87638
25,60000;1,37097;428,90259
25,64000;1,37295;428,91321
25,68000;1,37492;428,58329
25,72000;1,37701;429,00960
25,76000;1,37898;428,69346
25,80000;1,38096;427,72852
25,84000;1,38299;429,52229
25,88000;1,38496;428,28815
25,92000;1,38706;428,89132
25,96000;1,38909;428,57928
26,00000;1,39106;427,24423
26,04000;1,39310;426,69880
26,08000;1,39495;425,51598
26,12000;1,39704;425,81605
26,16000;1,39907;427,25913
26,20000;1,40105;425,39430
26,24000;1,40308;424,61888
26,28000;1,40493;424,11108
26,32000;1,40703;423,57887
26,36000;1,40900;423,72337
26,40000;1,41103;423,38083
26,44000;1,41312;422,88522
26,48000;1,41504;421,95031
26,52000;1,41707;420,22127
26,56000;1,41904;419,89167
26,60000;1,42108;420,51827
26,64000;1,42311;420,62756
26,68000;1,42508;419,85908
26,72000;1,42706;417,43219
26,76000;1,42903;417,51065
26,80000;1,43106;416,59456
26,84000;1,43309;416,11823
26,88000;1,43507;416,39153
26,92000;1,43704;414,55934
26,96000;1,43907;414,74961
27,00000;1,44105;413,77065
27,04000;1,44308;412,47327
27,08000;1,44511;414,33689
27,12000;1,44703;413,21418
27,16000;1,44906;412,43266
27,20000;1,45103;412,08789
27,24000;1,45306;411,15740
27,28000;1,45510;412,45776
27,32000;1,45701;411,53780
27,36000;1,45904;410,95689
27,40000;1,46102;411,69850
27,44000;1,46305;410,10897
27,48000;1,46508;410,27223
27,52000;1,46705;409,31003
27,56000;1,46903;407,78737
27,60000;1,47106;408,62826
27,64000;1,47309;407,97754
27,68000;1,47507;406,74573
27,72000;1,47704;406,08798
27,76000;1,47901;406,25986
27,80000;1,48105;406,02982
27,84000;1,48308;405,54539
27,88000;1,48511;405,30949
27,92000;1,48708;404,48941
27,96000;1,48900;404,29621
28,00000;1,49103;403,96107
28,04000;1,49306;403,63153
28,08000;1,49510;403,90724
28,12000;1,49713;402,91925
28,16000;1,49898;401,70145
28,20000;1,50096;401,43728
28,24000;1,50299;401,10513
28,28000;1,50502;401,05972
28,32000;1,50705;400,36538
28,36000;1,50903;399,37957
28,40000;1,51100;397,85276
28,44000;1,51303;397,59404
28,48000;1,51501;399,32709
28,52000;1,51710;398,53458
28,56000;1,51907;397,89826
28,60000;1,52098;396,70411
28,64000;1,52302;396,58956
28,68000;1,52487;396,17349
28,72000;1,52708;396,66397
28,76000;1,52906;396,81727
28,80000;1,53097;394,45241
28,84000;1,53306;394,73600
28,88000;1,53504;393,86810
28,92000;1,53701;393,42195
28,96000;1,53904;393,41105
29,00000;1,54095;392,87489
29,04000;1,54305;392,62706
29,08000;1,54502;391,90054
29,12000;1,54699;391,29592
29,16000;1,54903;390,84349
29,20000;1,55094;391,16791
29,24000;1,55291;389,57426
29,28000;1,55495;390,58907
29,32000;1,55704;390,50474
29,36000;1,55901;388,92352
29,40000;1,56098;389,32993
29,44000;1,56296;388,03560
29,48000;1,56505;389,14152
29,52000;1,56702;387,93280
29,56000;1,56906;386,35980
29,60000;1,57103;386,11174
29,64000;1,57294;386,13761
29,68000;1,57503;385,92303
29,72000;1,57701;385,83651
29,76000;1,57910;385,04479
29,80000;1,58113;385,42864
29,84000;1,58299;383,46625
29,88000;1,58502;383,14133
29,92000;1,58705;382,92396
29,96000;1,58909;383,59435
30,00000;1,59112;383,97487
30,04000;1,59303;382,73982
30,08000;1,59500;381,75092
30,12000;1,59698;382,42296
30,16000;1,59901;382,69791
30,20000;1,60104;383,13130
30,24000;1,60296;382,06214
30,28000;1,60499;381,09727
30,32000;1,60702;381,55920
30,36000;1,60899;380,95529
30,40000;1,61103;380,53701
30,44000;1,61306;381,22674
30,48000;1,61497;379,14000
30,52000;1,61707;379,69702
30,56000;1,61910;378,53762
30,60000;1,62107;378,19864
30,64000;1,62305;377,77980
30,68000;1,62502;377,80311
30,72000;1,62711;377,68446
30,76000;1,62908;376,68042
30,80000;1,63112;375,70817
30,84000;1,63315;375,81795
30,88000;1,63500;373,50832
30,92000;1,63710;373,67642
30,96000;1,63907;374,03195
31,00000;1,64116;373,37842
31,04000;1,64313;371,69338
31,08000;1,64499;370,79530
31,12000;1,64702;370,43160
31,16000;1,64905;371,81971
31,20000;1,65109;371,04331
31,24000;1,65312;371,01291
31,28000;1,65503;369,75525
31,32000;1,65701;369,00053
31,36000;1,65904;369,41017
31,40000;1,66101;370,51230
31,44000;1,66304;369,93797
31,48000;1,66508;370,50245
31,52000;1,66699;368,40062
31,56000;1,66902;368,64504
31,60000;1,67100;368,29142
31,64000;1,67309;368,53361
31,68000;1,67512;368,78842
31,72000;1,67704;367,22384
31,76000;1,67907;366,63322
31,80000;1,68104;367,18065
31,84000;1,68307;367,65458
31,88000;1,68517;368,37810
31,92000;1,68702;367,03469
31,96000;1,68911;365,23095
32,00000;1,69103;364,92115
32,04000;1,69306;364,07784
32,08000;1,69509;364,36138
32,12000;1,69706;364,91666
32,16000;1,69904;363,27750
32,20000;1,70107;363,23152
32,24000;1,70310;362,68316
32,28000;1,70508;362,11899
32,32000;1,70705;361,41064
32,36000;1,70902;360,50435
32,40000;1,71100;359,98586
32,44000;1,71303;359,33987
32,48000;1,71500;358,25912
32,52000;1,71691;357,91195
32,56000;1,71907;359,56721
32,60000;1,72110;358,11339
32,64000;1,72307;355,98150
32,68000;1,72511;355,94227
32,72000;1,72714;354,81867
32,76000;1,72899;354,50128
32,80000;1,73103;353,66144
32,84000;1,73300;354,58892
32,88000;1,73497;354,64058
32,92000;1,73706;354,83777
32,96000;1,73898;353,90391
33,00000;1,74101;353,57079
33,04000;1,74304;354,28305
33,08000;1,74508;354,17669
33,12000;1,74711;352,62117
33,16000;1,74908;354,42931
33,20000;1,75111;354,25259
33,24000;1,75309;351,94000
33,28000;1,75506;350,75755
33,32000;1,75703;351,48871
33,36000;1,75901;351,39776
33,40000;1,76098;350,15703
33,44000;1,76301;350,05750
33,48000;1,76505;350,70814
33,52000;1,76702;350,15533
33,56000;1,76911;350,02772
33,60000;1,77096;349,36871
33,64000;1,77306;348,35301
33,68000;1,77509;347,49212
33,72000;1,77706;347,52653
33,76000;1,77910;346,80185
33,80000;1,78071;345,79949
33,84000;1,78310;346,13158
33,88000;1,78502;345,43322
33,92000;1,78705;343,10685
33,96000;1,78908;342,74401
34,00000;1,79099;343,05837
34,04000;1,79303;342,40223
34,08000;1,79506;342,01243
34,12000;1,79709;342,42105
34,16000;1,79907;341,34092
34,20000;1,80104;340,86630
34,24000;1,80295;340,08287
34,28000;1,80504;340,89661
34,32000;1,80708;340,14215
34,36000;1,80905;339,76957
34,40000;1,81102;338,97830
34,44000;1,81294;338,34341
34,48000;1,81485;338,44670
34,52000;1,81712;341,13061
34,56000;1,81910;339,13371
34,60000;1,82113;338,71976
34,64000;1,82298;337,04492
34,68000;1,82501;336,98445
34,72000;1,82699;336,89297
34,76000;1,82902;336,88808
34,80000;1,83105;335,69299
34,84000;1,83297;335,40560
34,88000;1,83500;334,39251
34,92000;1,83697;334,66760
34,96000;1,83901;334,99950
35,00000;1,84104;334,93883
35,04000;1,84301;334,79992
35,08000;1,84504;333,39832
35,12000;1,84702;332,85550
35,16000;1,84905;333,00780
35,20000;1,85108;331,50907
35,24000;1,85306;331,63221
35,28000;1,85503;330,40284
35,32000;1,85706;330,31788
35,36000;1,85903;329,05957
35,40000;1,86107;329,50228
35,44000;1,86304;329,53180
35,48000;1,86513;331,19451
35,52000;1,86711;328,02871
35,56000;1,86914;327,11029
35,60000;1,87111;326,59003
35,64000;1,87303;326,38041
35,68000;1,87494;326,09666
35,72000;1,87703;326,65746
35,76000;1,87900;325,92181
35,80000;1,88104;325,71268
35,84000;1,88307;325,14320
35,88000;1,88498;325,63501
35,92000;1,88696;323,94379
35,96000;1,88899;325,39058
36,00000;1,89108;324,31139
36,04000;1,89311;324,25008
36,08000;1,89503;322,57356
36,12000;1,89694;321,98015
36,16000;1,89897;322,58267
36,20000;1,90107;323,97269
36,24000;1,90304;320,33895
36,28000;1,90501;319,60441
36,32000;1,90699;318,44673
36,36000;1,90902;319,33784
36,40000;1,91105;318,72010
36,44000;1,91308;318,11108
36,48000;1,91512;318,17302
36,52000;1,91703;317,58088
36,56000;1,91906;316,79985
36,60000;1,92104;317,65860
36,64000;1,92301;317,26467
36,68000;1,92510;316,94663
36,72000;1,92696;315,56671
36,76000;1,92899;314,70784
36,80000;1,93102;314,09005
36,84000;1,93299;313,85494
36,88000;1,93503;313,27426
36,92000;1,93700;313,93890
36,96000;1,93897;311,32794
37,00000;1,94101;311,51397
37,04000;1,94298;310,80528
37,08000;1,94501;310,83266
37,12000;1,94699;310,45205
37,16000;1,94890;309,95260
37,20000;1,95093;309,56226
37,24000;1,95296;309,05239
37,28000;1,95500;309,21940
37,32000;1,95703;310,02651
37,36000;1,95894;308,98142
37,40000;1,96104;308,79453
37,44000;1,96307;308,34612
37,48000;1,96510;307,82428
37,52000;1,96707;306,34583
37,56000;1,96899;306,81668
37,60000;1,97102;305,36908
37,64000;1,97305;305,20128
37,68000;1,97503;303,72448
37,72000;1,97706;302,69157
37,76000;1,97897;302,31399
37,80000;1,98095;302,66067
37,84000;1,98298;302,14228
37,88000;1,98507;302,52459
37,92000;1,98704;301,51773
37,96000;1,98902;301,64220
38,00000;1,99093;299,68251
38,04000;1,99296;300,12883
38,08000;1,99500;300,99778
38,12000;1,99703;301,50043
38,16000;1,99906;300,75407
38,20000;2,00097;299,30382
38,24000;2,00301;299,46726
38,28000;2,00504;301,05873
38,32000;2,00701;298,56004
38,36000;2,00905;298,60847
38,40000;2,01096;297,24154
38,44000;2,01305;296,48745
38,48000;2,01509;294,84921
38,52000;2,01706;295,79082
38,56000;2,01909;295,76775
38,60000;2,02100;295,02132
38,64000;2,02304;293,62342
38,68000;2,02507;294,87628
38,72000;2,02704;293,84464
38,76000;2,02908;293,82173
38,80000;2,03105;293,73521
38,84000;2,03302;292,89310
38,88000;2,03505;293,19141
38,92000;2,03703;292,13689
38,96000;2,03906;290,74820
39,00000;2,04103;290,80298
39,04000;2,04295;289,00376
39,08000;2,04504;290,38463
39,12000;2,04701;289,20299
39,16000;2,04899;288,78052
39,20000;2,05102;289,12220
39,24000;2,05293;287,52070
39,28000;2,05502;287,45166
39,32000;2,05706;287,52652
39,36000;2,05903;287,26382
39,40000;2,06106;287,76894
39,44000;2,06292;285,82490
39,48000;2,06501;286,40169
39,52000;2,06698;286,54081
39,56000;2,06908;286,56637
39,60000;2,07111;286,10795
39,64000;2,07296;285,48939
39,68000;2,07499;284,49984
39,72000;2,07697;286,07608
39,76000;2,07906;285,32080
39,80000;2,08109;285,24983
39,84000;2,08301;284,77150
39,88000;2,08504;284,00384
39,92000;2,08701;283,05640
39,96000;2,08904;284,12458
40,00000;2,09108;284,28512
40,04000;2,09305;283,18590
40,08000;2,09502;281,36089
40,12000;2,09706;282,70078
40,16000;2,09903;281,67847
40,20000;2,10106;282,46818
40,24000;2,10310;282,05751
40,28000;2,10501;281,50934
40,32000;2,10704;280,51320
40,36000;2,10907;280,76631
40,40000;2,11111;279,65400
40,44000;2,11314;280,20418
40,48000;2,11505;279,16494
40,52000;2,11709;278,06058
40,56000;2,11906;278,56913
40,60000;2,12109;277,89816
40,64000;2,12307;277,38237
40,68000;2,12504;278,02587
40,72000;2,12701;276,29198
40,76000;2,12904;277,53601
40,80000;2,13090;276,14278
40,84000;2,13311;277,22798
40,88000;2,13508;276,68795
40,92000;2,13700;274,84936
40,96000;2,13903;275,19236
41,00000;2,14106;276,23149
41,04000;2,14309;275,20387
41,08000;2,14507;275,38587
41,12000;2,14692;273,90688
41,16000;2,14901;274,55874
41,20000;2,15099;274,47713
41,24000;2,15302;274,52721
41,28000;2,15487;274,03438
41,32000;2,15709;275,34650
41,36000;2,15906;272,41902
41,40000;2,16103;272,82543
41,44000;2,16306;272,76564
41,48000;2,16516;272,75179
41,52000;2,16701;272,59139
41,56000;2,16904;271,66842
41,60000;2,17096;272,54394
41,64000;2,17299;272,59362
41,68000;2,17508;271,94240
41,72000;2,17700;271,69879
41,76000;2,17903;271,14504
41,80000;2,18100;271,91639
41,84000;2,18309;271,50416
41,88000;2,18507;269,89928
41,92000;2,18704;269,33700
41,96000;2,18901;269,23502
42,00000;2,19105;268,56821
42,04000;2,19308;267,98395
42,08000;2,19505;267,68288
42,12000;2,19702;268,12204
42,16000;2,19894;266,80923
42,20000;2,20103;267,31999
42,24000;2,20300;266,19232
42,28000;2,20504;265,83257
42,32000;2,20707;265,50749
42,36000;2,20898;265,72524
42,40000;2,21108;265,34582
42,44000;2,21305;265,04400
42,48000;2,21508;264,05612
42,52000;2,21711;263,69193
42,56000;2,21897;263,54708
42,60000;2,22100;263,29029
42,64000;2,22303;264,17740
42,68000;2,22507;262,93551
42,72000;2,22704;262,40002
42,76000;2,22901;262,11543
42,80000;2,23099;260,66920
42,84000;2,23302;261,03340
42,88000;2,23505;261,65030
42,92000;2,23714;261,06474
42,96000;2,23912;261,25880
43,00000;2,24097;259,41159
43,04000;2,24300;260,15849
43,08000;2,24504;260,47123
43,12000;2,24707;260,75460
43,16000;2,24910;260,99517
43,20000;2,25101;259,61478
43,24000;2,25305;258,51298
43,28000;2,25502;258,27882
43,32000;2,25699;257,86555
43,36000;2,25909;258,08145
43,40000;2,26100;258,18308
43,44000;2,26303;257,04147
43,48000;2,26501;256,73313
43,52000;2,26698;255,88693
43,56000;2,26901;255,10548
43,60000;2,27098;256,28603
43,64000;2,27296;255,35130
43,68000;2,27505;255,66404
43,72000;2,27702;254,48573
43,76000;2,27906;253,35322
43,80000;2,28097;253,81634
43,84000;2,28300;253,34533
43,88000;2,28503;253,46647
43,92000;2,28707;251,93647
43,96000;2,28910;251,86576
44,00000;2,29107;252,24127
44,04000;2,29299;251,28087
44,08000;2,29508;251,62010
44,12000;2,29711;251,89079
44,16000;2,29915;251,95947
44,20000;2,30118;250,80557
44,24000;2,30297;248,97580
44,28000;2,30506;249,88400
44,32000;2,30704;249,49363
44,36000;2,30907;249,90686
44,40000;2,31116;249,02700
44,44000;2,31302;248,46175
44,48000;2,31505;247,98668
44,52000;2,31702;248,45186
44,56000;2,31905;247,77835
44,60000;2,32109;248,22115
44,64000;2,32306;247,59609
44,68000;2,32503;246,75496
44,72000;2,32701;246,44067
44,76000;2,32904;246,65543
44,80000;2,33107;245,76201
44,84000;2,33311;247,09140
44,88000;2,33502;243,94109
44,92000;2,33705;243,11799
44,96000;2,33908;243,61445
45,00000;2,34106;243,32339
45,04000;2,34309;243,21182
45,08000;2,34500;243,24849
45,12000;2,34710;243,05321
45,16000;2,34907;242,85265
45,20000;2,35104;242,22634
45,24000;2,35308;242,16517
45,28000;2,35499;241,03452
45,32000;2,35702;241,04372
45,36000;2,35905;240,46360
45,40000;2,36103;240,20756
45,44000;2,36306;239,18047
45,48000;2,36503;239,37763
45,52000;2,36695;238,34312
45,56000;2,36910;241,38570
45,60000;2,37107;238,06116
45,63000;2,37257;238,01019