File: SU - Suspension/05 - Essais/Excels essais Optimus/Collage_alu_alu_31_01_19/collage5.is_tens_RawData/Specimen_RawData_1.csv
Temps;Déplacement;Charge
(sec);(mm);(N)
0,00000;-28,71193;57,20460
0,04000;-28,71146;57,61253
0,08000;-28,70936;64,40018
0,12000;-28,70613;83,07132
0,16000;-28,70249;107,86975
0,20000;-28,69854;134,54155
0,24000;-28,69466;160,96442
0,28000;-28,69095;184,72131
0,32000;-28,68724;205,65728
0,36000;-28,68365;225,27825
0,40000;-28,68013;243,75410
0,44000;-28,67654;262,05336
0,48000;-28,67307;280,09010
0,52000;-28,66972;296,94850
0,56000;-28,66632;313,51477
0,60000;-28,66291;329,43080
0,64000;-28,65962;344,86970
0,68000;-28,65615;360,65807
0,72000;-28,65280;376,19707
0,76000;-28,64952;391,40973
0,80000;-28,64617;407,21786
0,84000;-28,64276;422,27092
0,88000;-28,63953;436,07596
0,92000;-28,63618;450,20026
0,96000;-28,63283;463,68204
1,00000;-28,62955;476,37066
1,04000;-28,62614;488,55394
1,08000;-28,62279;498,33152
1,12000;-28,61944;507,38165
1,16000;-28,61615;513,15823
1,20000;-28,61280;519,15725
1,24000;-28,60951;523,61679
1,28000;-28,60617;525,56484
1,32000;-28,60282;527,72183
1,36000;-28,59947;528,30991
1,40000;-28,59612;528,37934
1,44000;-28,59277;528,76128
1,48000;-28,58943;527,99312
1,52000;-28,58614;525,70803
1,56000;-28,58285;524,12427
1,60000;-28,57938;523,23882
1,64000;-28,57615;521,39563
1,68000;-28,57280;519,05778
1,72000;-28,56946;518,26392
1,76000;-28,56611;517,11160
1,80000;-28,56276;514,30431
1,84000;-28,55947;511,62690
1,88000;-28,55606;511,32040
1,92000;-28,55271;510,73567
1,96000;-28,54943;517,95105
2,00000;-28,54614;526,99023
2,04000;-28,54279;536,49093
2,08000;-28,53944;543,57499
2,12000;-28,53615;550,30319
2,16000;-28,53280;557,66297
2,20000;-28,52946;564,26795
2,24000;-28,52617;570,33426
2,28000;-28,52288;576,31610
2,32000;-28,51953;581,69346
2,36000;-28,51612;587,91931
2,40000;-28,51289;592,88680
2,44000;-28,50949;598,39040
2,48000;-28,50608;603,65158
2,52000;-28,50279;607,70335
2,56000;-28,49944;611,56512
2,60000;-28,49609;614,86079
2,64000;-28,49281;618,97133
2,68000;-28,48946;622,20641
2,72000;-28,48611;626,97455
2,76000;-28,48282;635,82072
2,80000;-28,47947;645,52999
2,84000;-28,47618;656,99480
2,88000;-28,47284;671,10322
2,92000;-28,46949;685,23758
2,96000;-28,46620;700,70508
3,00000;-28,46285;716,49635
3,04000;-28,45950;732,35221
3,08000;-28,45610;748,49888
3,12000;-28,45281;763,59003
3,16000;-28,44952;778,37603
3,20000;-28,44611;794,23105
3,24000;-28,44282;808,63694
3,28000;-28,43953;823,47486
3,32000;-28,43619;839,71601
3,36000;-28,43284;853,92082
3,40000;-28,42961;869,16173
3,44000;-28,42620;885,13130
3,48000;-28,42279;900,85212
3,52000;-28,41956;916,06090
3,56000;-28,41622;931,18446
3,60000;-28,41281;947,31627
3,64000;-28,40952;963,29562
3,68000;-28,40617;977,58258
3,72000;-28,40276;993,40705
3,76000;-28,39942;1010,07242
3,80000;-28,39613;1024,29967
3,84000;-28,39284;1039,60056
3,88000;-28,38955;1055,97693
3,92000;-28,38620;1071,39256
3,96000;-28,38291;1087,01568
4,00000;-28,37951;1102,81836
4,04000;-28,37616;1117,06797
4,08000;-28,37281;1132,33058
4,12000;-28,36958;1147,22596
4,16000;-28,36617;1162,91521
4,20000;-28,36282;1178,79668
4,24000;-28,35942;1193,42469
4,28000;-28,35619;1208,29567
4,32000;-28,35278;1223,62729
4,36000;-28,34943;1238,82741
4,40000;-28,34620;1252,64507
4,44000;-28,34285;1267,35475
4,48000;-28,33951;1283,49736
4,52000;-28,33616;1298,21375
4,56000;-28,33287;1312,34508
4,60000;-28,32946;1327,45942
4,64000;-28,32617;1342,01227
4,68000;-28,32283;1356,21531
4,72000;-28,31948;1371,62777
4,76000;-28,31619;1386,96972
4,80000;-28,31278;1400,97784
4,84000;-28,30949;1416,21595
4,88000;-28,30608;1431,28037
4,92000;-28,30280;1446,02619
4,96000;-28,29939;1460,53769
5,00000;-28,29610;1474,49840
5,04000;-28,29281;1489,40105
5,08000;-28,28946;1504,96960
5,12000;-28,28611;1518,68919
5,16000;-28,28283;1532,70485
5,20000;-28,27942;1546,54514
5,24000;-28,27607;1559,13560
5,28000;-28,27284;1570,48889
5,32000;-28,26949;1581,40808
5,36000;-28,26608;1592,89930
5,40000;-28,26279;1602,83223
5,44000;-28,25951;1611,28584
5,48000;-28,25610;1620,39977
5,52000;-28,25281;1629,66456
5,56000;-28,24952;1637,24590
5,60000;-28,24618;1645,34114
5,64000;-28,24289;1654,58210
5,68000;-28,23948;1661,55398
5,72000;-28,23619;1669,03846
5,76000;-28,23284;1677,29184
5,80000;-28,22943;1684,70796
5,84000;-28,22615;1691,50233
5,88000;-28,22286;1697,93162
5,92000;-28,21951;1705,18290
5,96000;-28,21616;1712,66384
6,00000;-28,21281;1717,98076
6,04000;-28,20958;1725,04019
6,08000;-28,20611;1734,01907
6,12000;-28,20283;1740,04845
6,16000;-28,19954;1745,74163
6,20000;-28,19613;1752,36035
6,24000;-28,19278;1759,02303
6,28000;-28,18961;1764,12202
6,32000;-28,18614;1770,73069
6,36000;-28,18274;1778,74472
6,40000;-28,17945;1784,70984
6,44000;-28,17616;1790,32832
6,48000;-28,17275;1796,62295
6,52000;-28,16940;1806,15019
6,56000;-28,16606;1810,25621
6,60000;-28,16283;1815,71059
6,64000;-28,15948;1821,84782
6,68000;-28,15613;1826,44837
6,72000;-28,15290;1832,37679
6,76000;-28,14949;1839,28944
6,80000;-28,14615;1845,24115
6,84000;-28,14280;1850,66089
6,88000;-28,13957;1855,46335
6,92000;-28,13610;1865,41844
6,96000;-28,13275;1870,22462
7,00000;-28,12941;1875,02038
7,04000;-28,12612;1880,67816
7,08000;-28,12271;1886,75486
7,12000;-28,11936;1892,27145
7,16000;-28,11613;1897,48053
7,20000;-28,11278;1902,84122
7,24000;-28,10938;1910,18544
7,28000;-28,10615;1917,21413
7,32000;-28,10286;1921,51256
7,36000;-28,09945;1928,10297
7,40000;-28,09616;1935,06870
7,44000;-28,09287;1940,16583
7,48000;-28,08953;1947,48193
7,52000;-28,08618;1954,20291
7,56000;-28,08289;1960,22745
7,60000;-28,07954;1966,79384
7,64000;-28,07613;1976,74222
7,68000;-28,07278;1987,56102
7,72000;-28,06938;1996,49855
7,76000;-28,06615;2006,19604
7,80000;-28,06280;2016,01721
7,84000;-28,05945;2026,71289
7,88000;-28,05616;2036,50258
7,92000;-28,05276;2049,33397
7,96000;-28,04941;2063,21571
8,00000;-28,04612;2071,10420
8,04000;-28,04289;2079,48666
8,08000;-28,03954;2089,86066
8,12000;-28,03613;2099,98153
8,16000;-28,03290;2108,78681
8,20000;-28,02944;2119,14331
8,24000;-28,02609;2129,92262
8,28000;-28,02292;2137,53525
8,32000;-28,01951;2145,03556
8,36000;-28,01616;2153,93919
8,40000;-28,01287;2162,02661
8,44000;-28,00959;2169,06071
8,48000;-28,00624;2178,01314
8,52000;-28,00283;2189,15977
8,56000;-27,99948;2197,15144
8,60000;-27,99626;2204,45171
8,64000;-27,99285;2213,11618
8,68000;-27,98956;2220,35926
8,72000;-27,98621;2227,91564
8,76000;-27,98286;2236,36199
8,80000;-27,97969;2244,68745
8,84000;-27,97610;2254,44790
8,88000;-27,97288;2263,22580
8,92000;-27,96953;2270,25896
8,96000;-27,96618;2279,82663
9,00000;-27,96283;2290,18759
9,04000;-27,95954;2302,40822
9,08000;-27,95614;2316,17112
9,12000;-27,95279;2330,04540
9,16000;-27,94956;2342,63744
9,20000;-27,94615;2355,64094
9,24000;-27,94280;2368,47848
9,28000;-27,93951;2380,56798
9,32000;-27,93617;2391,42124
9,36000;-27,93276;2405,79005
9,40000;-27,92947;2419,07761
9,44000;-27,92618;2431,87509
9,48000;-27,92277;2445,29881
9,52000;-27,91942;2459,87810
9,56000;-27,91620;2471,39949
9,60000;-27,91285;2484,93198
9,64000;-27,90944;2499,15719
9,68000;-27,90615;2512,67795
9,72000;-27,90286;2525,98561
9,76000;-27,89946;2541,67244
9,80000;-27,89617;2556,59409
9,84000;-27,89288;2571,46619
9,88000;-27,88947;2586,00879
9,92000;-27,88618;2603,31649
9,96000;-27,88283;2618,44788
10,00000;-27,87967;2633,12515
10,04000;-27,87620;2650,24174
10,08000;-27,87285;2668,20379
10,12000;-27,86950;2683,05391
10,16000;-27,86627;2699,57557
10,20000;-27,86286;2716,10618
10,24000;-27,85952;2733,67185
10,28000;-27,85617;2750,87096
10,32000;-27,85282;2765,52290
10,36000;-27,84947;2781,19668
10,40000;-27,84618;2798,46638
10,44000;-27,84289;2814,15209
10,48000;-27,83955;2831,08354
10,52000;-27,83620;2848,45028
10,56000;-27,83291;2863,76551
10,60000;-27,82956;2879,90179
10,64000;-27,82615;2897,28716
10,68000;-27,82286;2912,72923
10,72000;-27,81958;2929,11772
10,76000;-27,81623;2945,89978
10,80000;-27,81288;2962,64812
10,84000;-27,80953;2978,26026
10,88000;-27,80624;2995,22653
10,92000;-27,80290;3011,54871
10,96000;-27,79949;3029,27997
11,00000;-27,79620;3045,41457
11,04000;-27,79291;3061,67286
11,08000;-27,78950;3078,89022
11,12000;-27,78615;3096,86251
11,16000;-27,78287;3113,03940
11,20000;-27,77946;3131,60233
11,24000;-27,77611;3148,65261
11,28000;-27,77282;3164,60542
11,32000;-27,76953;3180,11492
11,36000;-27,76618;3195,95262
11,40000;-27,76290;3213,53041
11,44000;-27,75973;3229,80061
11,48000;-27,75608;3249,75140
11,52000;-27,75279;3267,04867
11,56000;-27,74944;3283,16912
11,60000;-27,74622;3299,02284
11,64000;-27,74275;3316,60584
11,68000;-27,73940;3334,08676
11,72000;-27,73641;3350,08614
11,76000;-27,73264;3369,26430
11,80000;-27,72935;3387,71082
11,84000;-27,72606;3403,75267
11,88000;-27,72296;3419,75577
11,92000;-27,71943;3439,05017
11,96000;-27,71614;3457,41138
12,00000;-27,71273;3474,40913
12,04000;-27,70950;3490,63426
12,08000;-27,70616;3507,64133
12,12000;-27,70275;3527,27287
12,16000;-27,69946;3547,46431
12,20000;-27,69611;3563,13400
12,24000;-27,69276;3580,63169
12,28000;-27,68941;3598,12155
12,32000;-27,68613;3614,33215
12,36000;-27,68278;3631,57094
12,40000;-27,67937;3651,41369
12,44000;-27,67620;3667,77144
12,48000;-27,67279;3688,38608
12,52000;-27,66944;3707,29975
12,56000;-27,66616;3722,92586
12,60000;-27,66287;3739,67774
12,64000;-27,65946;3758,57092
12,68000;-27,65617;3777,83701
12,72000;-27,65282;3795,55337
12,76000;-27,64954;3813,46121
12,80000;-27,64625;3832,17633
12,84000;-27,64284;3852,09769
12,88000;-27,63943;3870,52186
12,92000;-27,63620;3888,29783
12,96000;-27,63279;3905,78285
13,00000;-27,62945;3926,49584
13,04000;-27,62622;3943,16949
13,08000;-27,62287;3960,98644
13,12000;-27,61946;3981,47888
13,16000;-27,61623;3998,82421
13,20000;-27,61282;4016,44111
13,24000;-27,60948;4036,87097
13,28000;-27,60613;4055,38157
13,32000;-27,60290;4071,30346
13,36000;-27,59955;4089,48511
13,40000;-27,59614;4107,98900
13,44000;-27,59286;4126,07864
13,48000;-27,58945;4143,21460
13,52000;-27,58610;4163,68134
13,56000;-27,58281;4181,48004
13,60000;-27,57946;4198,01436
13,64000;-27,57618;4215,37757
13,68000;-27,57289;4234,36910
13,72000;-27,56948;4252,67294
13,76000;-27,56619;4271,49385
13,80000;-27,56278;4290,95328
13,84000;-27,55949;4311,51763
13,88000;-27,55614;4327,80609
13,92000;-27,55292;4345,28440
13,96000;-27,54951;4363,57670
14,00000;-27,54616;4381,93530
14,04000;-27,54287;4399,52090
14,08000;-27,53952;4417,49468
14,12000;-27,53611;4436,72910
14,16000;-27,53283;4454,39108
14,20000;-27,52948;4471,04760
14,24000;-27,52595;4490,51745
14,28000;-27,52278;4511,66108
14,32000;-27,51949;4528,38019
14,36000;-27,51614;4545,77953
14,40000;-27,51280;4563,87177
14,44000;-27,50951;4580,19339
14,48000;-27,50616;4598,38472
14,52000;-27,50281;4615,89992
14,56000;-27,49946;4637,22758
14,60000;-27,49612;4654,94171
14,64000;-27,49283;4671,86533
14,68000;-27,48954;4688,93722
14,72000;-27,48625;4705,62726
14,76000;-27,48278;4723,79886
14,80000;-27,47979;4742,40892
14,84000;-27,47614;4761,81209
14,88000;-27,47280;4780,63114
14,92000;-27,46957;4797,46275
14,96000;-27,46616;4814,87028
15,00000;-27,46281;4833,66214
15,04000;-27,45952;4850,61593
15,08000;-27,45617;4867,26798
15,12000;-27,45277;4886,47558
15,16000;-27,44948;4906,63722
15,20000;-27,44619;4922,96889
15,24000;-27,44290;4939,26741
15,28000;-27,43955;4956,77479
15,32000;-27,43626;4973,06176
15,36000;-27,43292;4991,53584
15,40000;-27,42951;5011,27467
15,44000;-27,42622;5028,92733
15,48000;-27,42293;5045,30035
15,52000;-27,41953;5062,46351
15,56000;-27,41618;5081,50756
15,60000;-27,41283;5098,73070
15,64000;-27,40948;5114,10348
15,68000;-27,40619;5132,33058
15,72000;-27,40284;5150,55992
15,76000;-27,39955;5166,72283
15,80000;-27,39627;5183,22699
15,84000;-27,39286;5200,35177
15,88000;-27,38951;5217,24224
15,92000;-27,38628;5233,33549
15,96000;-27,38293;5250,66815
16,00000;-27,37953;5268,71867
16,04000;-27,37630;5284,21625
16,08000;-27,37295;5300,21675
16,12000;-27,36954;5318,03146
16,16000;-27,36625;5335,15103
16,20000;-27,36290;5350,98836
16,24000;-27,35950;5368,06919
16,28000;-27,35615;5385,51398
16,32000;-27,35286;5400,89048
16,36000;-27,34951;5417,25345
16,40000;-27,34610;5434,60511
16,44000;-27,34287;5450,94013
16,48000;-27,33953;5466,66943
16,52000;-27,33612;5483,36916
16,56000;-27,33289;5500,28495
16,60000;-27,32954;5515,85369
16,64000;-27,32619;5532,01362
16,68000;-27,32285;5549,54857
16,72000;-27,31950;5566,26767
16,76000;-27,31615;5582,46747
16,80000;-27,31280;5600,39319
16,84000;-27,30945;5617,37232
16,88000;-27,30610;5632,74659
16,92000;-27,30282;5648,10485
16,96000;-27,29947;5664,14818
17,00000;-27,29618;5679,81154
17,04000;-27,29283;5696,39392
17,08000;-27,28948;5711,80247
17,12000;-27,28613;5729,34747
17,16000;-27,28285;5744,49375
17,20000;-27,27956;5758,85288
17,24000;-27,27615;5775,44458
17,28000;-27,27286;5791,70547
17,32000;-27,26957;5806,74522
17,36000;-27,26617;5824,38447
17,40000;-27,26276;5840,43376
17,44000;-27,25953;5856,34410
17,48000;-27,25612;5870,51101
17,52000;-27,25277;5887,36609
17,56000;-27,24942;5903,14306
17,60000;-27,24614;5918,72893
17,64000;-27,24285;5933,79736
17,68000;-27,23950;5951,56141
17,72000;-27,23615;5968,29019
17,76000;-27,23280;5984,36855
17,80000;-27,22951;6000,54078
17,84000;-27,22617;6016,69401
17,88000;-27,22282;6031,73599
17,92000;-27,21959;6047,96112
17,96000;-27,21618;6064,33749
18,00000;-27,21283;6081,51443
18,04000;-27,20954;6098,52858
18,08000;-27,20620;6113,63687
18,12000;-27,20285;6130,25092
18,16000;-27,19950;6146,60457
18,20000;-27,19627;6161,46885
18,24000;-27,19286;6177,76848
18,28000;-27,18952;6194,61797
18,32000;-27,18623;6210,48659
18,36000;-27,18282;6226,93971
18,40000;-27,17947;6243,49751
18,44000;-27,17618;6258,20905
18,48000;-27,17289;6273,86793
18,52000;-27,16949;6289,63783
18,56000;-27,16620;6306,70264
18,60000;-27,16285;6321,90853
18,64000;-27,15950;6337,86693
18,68000;-27,15615;6353,48186
18,72000;-27,15286;6369,18023
18,76000;-27,14952;6385,00825
18,80000;-27,14623;6400,79826
18,84000;-27,14288;6416,66129
18,88000;-27,13953;6433,47800
18,92000;-27,13618;6449,13912
18,96000;-27,13284;6464,90455
19,00000;-27,12943;6482,38584
19,04000;-27,12620;6499,46928
19,08000;-27,12285;6514,13873
19,12000;-27,11950;6531,18789
19,16000;-27,11615;6547,05539
19,20000;-27,11286;6561,86640
19,24000;-27,10952;6577,83523
19,28000;-27,10611;6594,57371
19,32000;-27,10288;6609,25880
19,36000;-27,09953;6625,32970
19,40000;-27,09618;6642,56066
19,44000;-27,09283;6657,43053
19,48000;-27,08955;6673,00150
19,52000;-27,08614;6689,00385
19,56000;-27,08279;6704,84677
19,60000;-27,07950;6720,26649
19,64000;-27,07615;6735,77711
19,68000;-27,07280;6752,76592
19,72000;-27,06946;6767,95840
19,76000;-27,06611;6782,84168
19,80000;-27,06282;6798,39179
19,84000;-27,05941;6813,70273
19,88000;-27,05612;6829,25805
19,92000;-27,05284;6843,72708
19,96000;-27,04949;6860,03938
20,00000;-27,04608;6876,31518
20,04000;-27,04279;6890,85498
20,08000;-27,03950;6905,10571
20,12000;-27,03615;6921,53797
20,16000;-27,03281;6937,44346
20,20000;-27,02952;6950,43579
20,24000;-27,02617;6966,31819
20,28000;-27,02282;6983,44484
20,32000;-27,01947;6997,81775
20,36000;-27,01618;7011,73767
20,40000;-27,01284;7027,55153
20,44000;-27,00943;7040,97748
20,48000;-27,00620;7050,99702
20,52000;-27,00291;7066,45399
20,56000;-26,99956;7085,38219
20,60000;-26,99616;7103,99374
20,64000;-26,99281;7118,27949
20,68000;-26,98958;7132,34544
20,72000;-26,98617;7146,70345
20,76000;-26,98282;7164,72194
20,80000;-26,97953;7179,76317
20,84000;-26,97613;7195,08305
20,88000;-26,97272;7212,39969
20,92000;-26,96949;7227,86188
20,96000;-26,96626;7241,23046
21,00000;-26,96273;7261,25389
21,04000;-26,95944;7275,53964
21,08000;-26,95621;7288,94323
21,12000;-26,95287;7305,30992
21,16000;-26,94946;7322,87690
21,20000;-26,94641;7336,29391
21,24000;-26,94282;7354,01064
21,28000;-26,93948;7369,79246
21,32000;-26,93624;7382,63801
21,36000;-26,93290;7397,77312
21,40000;-26,92955;7414,71574
21,44000;-26,92620;7429,84489
21,48000;-26,92285;7445,31602
21,52000;-26,91951;7461,87195
21,56000;-26,91628;7477,66420
21,60000;-26,91275;7496,34281
21,64000;-26,90946;7511,87503
21,68000;-26,90617;7525,95440
21,72000;-26,90282;7541,01127
21,76000;-26,89953;7556,69475
21,80000;-26,89625;7573,24770
21,84000;-26,89290;7589,64345
21,88000;-26,88955;7606,81927
21,92000;-26,88620;7622,83802
21,96000;-26,88315;7637,69597
22,00000;-26,87945;7657,28951
22,04000;-26,87616;7674,32973
22,08000;-26,87281;7688,62739
22,12000;-26,86952;7704,08884
22,16000;-26,86611;7720,90331
22,20000;-26,86288;7735,55934
22,24000;-26,85960;7751,87090
22,28000;-26,85607;7773,85831
22,32000;-26,85284;7788,45251
22,36000;-26,84949;7802,42980
22,40000;-26,84620;7818,04249
22,44000;-26,84291;7833,96661
22,48000;-26,83957;7849,06149
22,52000;-26,83634;7864,66748
22,56000;-26,83281;7883,00261
22,60000;-26,82946;7900,40493
22,64000;-26,82617;7914,89854
22,68000;-26,82288;7930,73475
22,72000;-26,81948;7945,75810
22,76000;-26,81619;7961,27543
22,80000;-26,81290;7977,23979
22,84000;-26,80943;7993,20340
22,88000;-26,80614;8011,81570
22,92000;-26,80280;8025,48155
22,96000;-26,79957;8039,62126
23,00000;-26,79616;8055,77785
23,04000;-26,79281;8071,93294
23,08000;-26,78958;8085,62264
23,12000;-26,78617;8102,21508
23,16000;-26,78277;8119,53917
23,20000;-26,77948;8133,03143
23,24000;-26,77613;8145,82780
23,28000;-26,77278;8161,01208
23,32000;-26,76949;8175,69867
23,36000;-26,76620;8188,83628
23,40000;-26,76286;8202,67200
23,44000;-26,75951;8218,97462
23,48000;-26,75622;8231,47818
23,52000;-26,75287;8245,87643
23,56000;-26,74952;8261,08754
23,60000;-26,74618;8275,18478
23,64000;-26,74289;8288,48258
23,68000;-26,73960;8301,91895
23,72000;-26,73619;8315,77554
23,76000;-26,73296;8330,05011
23,80000;-26,72955;8344,56906
23,84000;-26,72621;8357,76180
23,88000;-26,72280;8372,57877
23,92000;-26,71957;8385,70222
23,96000;-26,71622;8399,74657
24,00000;-26,71287;8415,20578
24,04000;-26,70952;8429,02362
24,08000;-26,70630;8441,94815
24,12000;-26,70283;8457,46845
24,16000;-26,69942;8474,52581
24,20000;-26,69625;8486,06974
24,24000;-26,69284;8500,38454
24,28000;-26,68943;8514,99289
24,32000;-26,68615;8528,02098
24,36000;-26,68316;8540,56403
24,40000;-26,67939;8556,51572
24,44000;-26,67616;8571,44371
24,48000;-26,67287;8583,62839
24,52000;-26,66953;8596,00902
24,56000;-26,66624;8610,74701
24,60000;-26,66283;8624,54027
24,64000;-26,65954;8636,90004
24,68000;-26,65625;8651,62089
24,72000;-26,65284;8664,18630
24,76000;-26,64962;8677,70687
24,80000;-26,64615;8692,99844
24,84000;-26,64280;8708,45392
24,88000;-26,63939;8720,94482
24,92000;-26,63610;8733,35227
24,96000;-26,63282;8746,16951
25,00000;-26,62941;8759,60663
25,04000;-26,62612;8772,41939
25,08000;-26,62289;8784,82908
25,12000;-26,61948;8800,14002
25,16000;-26,61613;8813,92285
25,20000;-26,61285;8826,35787
25,24000;-26,60950;8839,32859
25,28000;-26,60609;8854,42123
25,32000;-26,60280;8867,85984
25,36000;-26,59951;8880,38129
25,40000;-26,59616;8894,68640
25,44000;-26,59281;8909,43632
25,48000;-26,58947;8922,42640
25,52000;-26,58606;8936,69575
25,56000;-26,58271;8951,92921
25,60000;-26,57942;8963,53498
25,64000;-26,57613;8975,20855
25,68000;-26,57284;8987,35151
25,72000;-26,56950;9000,75287
25,76000;-26,56621;9014,81956
25,80000;-26,56280;9029,21557
25,84000;-26,55951;9042,29581
25,88000;-26,55610;9055,55934
25,92000;-26,55282;9068,22681
25,96000;-26,54977;9078,77833
26,00000;-26,54612;9095,49519
26,04000;-26,54271;9108,31168
26,08000;-26,53948;9119,87796
26,12000;-26,53607;9132,02912
26,16000;-26,53273;9145,94308
26,20000;-26,52950;9159,20585
26,24000;-26,52615;9171,59468
26,28000;-26,52280;9186,37216
26,32000;-26,51952;9199,10595
26,36000;-26,51616;9210,61635
26,40000;-26,51282;9222,28247
26,44000;-26,50953;9234,93728
26,48000;-26,50618;9248,23955
26,52000;-26,50295;9260,07554
26,56000;-26,49960;9275,08548
26,60000;-26,49626;9287,05782
26,64000;-26,49291;9299,34606
26,68000;-26,48956;9312,02918
26,72000;-26,48621;9324,84195
26,76000;-26,48280;9338,60019
26,80000;-26,47951;9350,36987
26,84000;-26,47617;9365,33511
26,88000;-26,47282;9377,49967
26,92000;-26,46947;9388,76048
26,96000;-26,46618;9399,67111
27,00000;-26,46277;9413,37720
27,04000;-26,45943;9426,70554
27,08000;-26,45620;9437,99317
27,12000;-26,45285;9450,08323
27,16000;-26,44944;9464,51053
27,20000;-26,44615;9475,93451
27,24000;-26,44280;9486,90847
27,28000;-26,43946;9498,89868
27,32000;-26,43617;9512,16966
27,36000;-26,43282;9523,70167
27,40000;-26,42959;9535,28211
27,44000;-26,42612;9550,76218
27,48000;-26,42277;9563,15100
27,52000;-26,41943;9574,35742
27,56000;-26,41608;9586,67547
27,60000;-26,41273;9598,94806
27,64000;-26,40944;9610,62238
27,68000;-26,40615;9621,71182
27,72000;-26,40286;9632,48834
27,76000;-26,39940;9645,27056
27,80000;-26,39617;9657,83969
27,84000;-26,39282;9669,64886
27,88000;-26,38941;9683,46894
27,92000;-26,38606;9695,68714
27,96000;-26,38283;9705,92946
28,00000;-26,37967;9716,61732
28,04000;-26,37602;9733,05404
28,08000;-26,37279;9745,00179
28,12000;-26,36944;9756,14190
28,16000;-26,36603;9768,44653
28,20000;-26,36275;9779,72001
28,24000;-26,35946;9789,40874
28,28000;-26,35611;9802,25876
28,32000;-26,35282;9818,85418
28,36000;-26,34947;9828,86106
28,40000;-26,34612;9839,73518
28,44000;-26,34283;9851,67921
28,48000;-26,33943;9862,57568
28,52000;-26,33614;9875,19175
28,56000;-26,33285;9885,68813
28,60000;-26,32956;9896,02432
28,64000;-26,32663;9907,84839
28,68000;-26,32281;9922,81511
28,72000;-26,31952;9936,41689
28,76000;-26,31611;9947,49516
28,80000;-26,31282;9957,77771
28,84000;-26,30947;9968,30165
28,88000;-26,30619;9978,94108
28,92000;-26,30278;9990,92609
28,96000;-26,29949;10002,03341
29,00000;-26,29632;10012,50520
29,04000;-26,29273;10026,63597
29,08000;-26,28956;10037,05859
29,12000;-26,28621;10046,21536
29,16000;-26,28287;10056,92109
29,20000;-26,27958;10069,53046
29,24000;-26,27623;10081,46033
29,28000;-26,27288;10092,86046
29,32000;-26,26971;10105,43779
29,36000;-26,26613;10118,35262
29,40000;-26,26278;10130,08803
29,44000;-26,25949;10140,81165
29,48000;-26,25614;10150,10327
29,52000;-26,25279;10160,72556
29,56000;-26,24950;10171,10050
29,60000;-26,24622;10180,68939
29,64000;-26,24287;10191,40556
29,68000;-26,23958;10201,01979
29,72000;-26,23617;10214,03670
29,76000;-26,23288;10225,63800
29,80000;-26,22953;10237,25867
29,84000;-26,22619;10247,08822
29,88000;-26,22284;10258,07559
29,92000;-26,21949;10268,13090
29,96000;-26,21626;10278,09680
30,00000;-26,21285;10290,07286
30,04000;-26,20945;10301,69576
30,08000;-26,20616;10311,09020
30,12000;-26,20281;10321,54337
30,16000;-26,19940;10331,12556
30,20000;-26,19611;10341,35073
30,24000;-26,19276;10351,46490
30,28000;-26,18948;10362,28687
30,32000;-26,18613;10372,26394
30,36000;-26,18284;10381,09958
30,40000;-26,17949;10391,32625
30,44000;-26,17614;10402,46114
30,48000;-26,17279;10412,36296
30,52000;-26,16951;10422,21487
30,56000;-26,16616;10432,37150
30,60000;-26,16281;10442,43872
30,64000;-26,15946;10452,47465
30,68000;-26,15617;10462,23491
30,72000;-26,15283;10473,37428
30,76000;-26,14942;10484,57623
30,80000;-26,14613;10494,18226
30,84000;-26,14284;10503,48058
30,88000;-26,13949;10514,23550
30,92000;-26,13614;10525,79433
30,96000;-26,13291;10535,09638
31,00000;-26,12957;10544,16150
31,04000;-26,12616;10553,51198
31,08000;-26,12293;10564,71542
31,12000;-26,11958;10572,98928
31,16000;-26,11617;10584,38495
31,20000;-26,11289;10595,86778
31,24000;-26,10954;10603,78179
31,28000;-26,10619;10612,31047
31,32000;-26,10284;10622,42463
31,36000;-26,09949;10632,72357
31,40000;-26,09615;10642,78409
31,44000;-26,09286;10652,97872
31,48000;-26,08951;10661,60649
31,52000;-26,08616;10670,68502
31,56000;-26,08281;10680,38642
31,60000;-26,07952;10689,76000
31,64000;-26,07618;10699,28631
31,68000;-26,07282;10709,30958
31,72000;-26,06960;10718,42238
31,76000;-26,06619;10728,92621
31,80000;-26,06284;10738,57769
31,84000;-26,05955;10748,69409
31,88000;-26,05621;10758,13100
31,92000;-26,05286;10768,10583
31,96000;-26,04963;10776,44825
32,00000;-26,04622;10786,14742
32,04000;-26,04281;10797,05656
32,08000;-26,03958;10806,87493
32,12000;-26,03617;10815,55262
32,16000;-26,03283;10825,17505
32,20000;-26,02954;10835,05899
32,24000;-26,02625;10842,46635
32,28000;-26,02284;10851,80491
32,32000;-26,01949;10863,17822
32,36000;-26,01621;10871,29936
32,40000;-26,01286;10880,22962
32,44000;-26,00951;10889,68515
32,48000;-26,00616;10898,93207
32,52000;-26,00287;10907,80124
32,56000;-25,99952;10917,76788
32,60000;-25,99624;10927,13922
32,64000;-25,99283;10938,39407
32,68000;-25,98948;10946,77746
32,72000;-25,98613;10956,48557
32,76000;-25,98278;10965,55069
32,80000;-25,97943;10974,31704
32,84000;-25,97615;10982,65424
32,88000;-25,97280;10993,66471
32,92000;-25,96939;11003,08523
32,96000;-25,96616;11012,22411
33,00000;-25,96281;11020,71404
33,04000;-25,95941;11030,44227
33,08000;-25,95618;11039,15498
33,12000;-25,95283;11045,88583
33,16000;-25,94948;11057,04382
33,20000;-25,94619;11066,33171
33,24000;-25,94291;11074,58770
33,28000;-25,93950;11084,03057
33,32000;-25,93609;11095,09468
33,36000;-25,93280;11103,55332
33,40000;-25,92945;11112,28764
33,44000;-25,92610;11122,76316
33,48000;-25,92275;11132,40197
33,52000;-25,91941;11141,02751
33,56000;-25,91612;11148,77090
33,60000;-25,91283;11156,65361
33,64000;-25,90942;11167,71773
33,68000;-25,90607;11175,84407
33,72000;-25,90291;11182,50564
33,76000;-25,89950;11191,44261
33,80000;-25,89609;11202,04031
33,84000;-25,89292;11210,76569
33,88000;-25,88951;11220,19589
33,92000;-25,88610;11230,36221
33,96000;-25,88287;11238,44013
34,00000;-25,87953;11245,67166
34,04000;-25,87612;11255,61520
34,08000;-25,87277;11265,28159
34,12000;-25,86948;11273,13077
34,16000;-25,86613;11280,98890
34,20000;-25,86279;11290,21496
34,24000;-25,85950;11296,53603
34,28000;-25,85621;11304,97381
34,32000;-25,85286;11315,00900
34,36000;-25,84951;11323,79696
34,40000;-25,84616;11333,28304
34,44000;-25,84282;11342,57466
34,48000;-25,83947;11352,20230
34,52000;-25,83618;11359,97027
34,56000;-25,83283;11367,97294
34,60000;-25,82948;11377,14162
34,64000;-25,82614;11386,24325
34,68000;-25,82273;11394,40238
34,72000;-25,81956;11401,88500
34,76000;-25,81609;11411,07157
34,80000;-25,81280;11420,26186
34,84000;-25,80957;11428,03952
34,88000;-25,80610;11438,46735
34,92000;-25,80276;11447,50118
34,96000;-25,79947;11454,25215
35,00000;-25,79618;11461,86218
35,04000;-25,79283;11470,42885
35,08000;-25,78948;11480,43722
35,12000;-25,78619;11488,17912
35,16000;-25,78279;11496,95888
35,20000;-25,77944;11509,31418
35,24000;-25,77609;11515,91092
35,28000;-25,77280;11523,20877
35,32000;-25,76946;11531,37684
35,36000;-25,76611;11541,21161
35,40000;-25,76276;11549,97051
35,44000;-25,75953;11558,78678
35,48000;-25,75606;11570,57285
35,52000;-25,75277;11579,26396
35,56000;-25,74942;11587,27184
35,60000;-25,74631;11595,97263
35,64000;-25,74279;11607,92708
35,68000;-25,73938;11617,90341
35,72000;-25,73621;11626,17207
35,76000;-25,73280;11635,53596
35,80000;-25,72946;11646,51886
35,84000;-25,72617;11655,82538
35,88000;-25,72288;11663,13887
35,92000;-25,71935;11673,79171
35,96000;-25,71612;11685,24995
36,00000;-25,71283;11693,12075
36,04000;-25,70949;11702,23653
36,08000;-25,70614;11713,19932
36,12000;-25,70279;11723,60554
36,16000;-25,69950;11732,88897
36,20000;-25,69621;11742,77961
36,24000;-25,69280;11752,30816
36,28000;-25,68952;11760,52392
36,32000;-25,68641;11769,73879
36,36000;-25,68276;11783,26681
36,40000;-25,67947;11792,28723
36,44000;-25,67612;11799,81902
36,48000;-25,67283;11808,41029
36,52000;-25,66949;11818,26219
36,56000;-25,66614;11827,27590
36,60000;-25,66285;11836,23746
36,64000;-25,65962;11846,19591
36,68000;-25,65603;11859,13235
36,72000;-25,65286;11866,87648
36,76000;-25,64945;11874,22797
36,80000;-25,64611;11882,86915
36,84000;-25,64288;11891,68468
36,88000;-25,63953;11900,49946
36,92000;-25,63618;11910,16287
36,96000;-25,63284;11920,26883
37,00000;-25,62955;11929,09777
37,04000;-25,62620;11939,55317
37,08000;-25,62285;11950,07414
37,12000;-25,61956;11958,01944
37,16000;-25,61627;11966,20762
37,20000;-25,61287;11981,31293
37,24000;-25,60952;11988,58246
37,28000;-25,60623;11996,96213
37,32000;-25,60288;12005,43419
37,36000;-25,59953;12014,95752
37,40000;-25,59618;12023,96452
37,44000;-25,59290;12032,78005
37,48000;-25,58955;12041,83176
37,52000;-25,58620;12051,74550
37,56000;-25,58285;12061,76504
37,60000;-25,57956;12070,31831
37,64000;-25,57616;12079,64048
37,68000;-25,57281;12088,65941
37,72000;-25,56964;12096,84759
37,76000;-25,56623;12104,74819
37,80000;-25,56282;12115,07022
37,84000;-25,55959;12123,46032
37,88000;-25,55625;12131,60381
37,92000;-25,55278;12142,24845
37,96000;-25,54949;12151,79637
38,00000;-25,54626;12159,15680
38,04000;-25,54285;12168,69578
38,08000;-25,53944;12179,85153
38,12000;-25,53622;12187,75287
38,16000;-25,53281;12197,07876
38,20000;-25,52946;12207,09905
38,24000;-25,52617;12215,50852
38,28000;-25,52288;12222,85479
38,32000;-25,51947;12233,13957
38,36000;-25,51618;12242,90729
38,40000;-25,51290;12250,71847
38,44000;-25,50949;12259,88865
38,48000;-25,50620;12269,51703
38,52000;-25,50285;12278,01144
38,56000;-25,49950;12287,71359
38,60000;-25,49622;12299,87890
38,64000;-25,49281;12308,41205
38,68000;-25,48940;12316,91688
38,72000;-25,48617;12325,05515
38,76000;-25,48282;12332,02890
38,80000;-25,47947;12341,66026
38,84000;-25,47619;12349,90060
38,88000;-25,47284;12357,29605
38,92000;-25,46949;12367,34614
38,96000;-25,46614;12376,36805
39,00000;-25,46286;12383,42449
39,04000;-25,45950;12392,76230
39,08000;-25,45616;12401,59422
39,12000;-25,45293;12409,97091
39,16000;-25,44952;12419,22230
39,20000;-25,44611;12428,92742
39,24000;-25,44282;12436,91444
39,28000;-25,43948;12445,51167
39,32000;-25,43613;12454,78541
39,36000;-25,43278;12463,08237
39,40000;-25,42949;12471,63266
39,44000;-25,42614;12479,65246
39,48000;-25,42285;12489,62879
39,52000;-25,41945;12497,55695
39,56000;-25,41616;12506,18696
39,60000;-25,41293;12515,36608
39,64000;-25,40946;12526,50321
39,68000;-25,40617;12534,51258
39,72000;-25,40294;12541,39245
39,76000;-25,39954;12550,65650
39,80000;-25,39619;12560,74458
39,84000;-25,39284;12568,84336
39,88000;-25,38943;12577,39365
39,92000;-25,38608;12589,22815
39,96000;-25,38274;12597,04530
40,00000;-25,37951;12602,01633
40,04000;-25,37616;12610,54873
40,08000;-25,37281;12620,03928
40,12000;-25,36952;12627,85494
40,16000;-25,36611;12638,25148
40,20000;-25,36277;12649,68663
40,24000;-25,35948;12656,64995
40,28000;-25,35619;12664,22570
40,32000;-25,35284;12672,36620
40,36000;-25,34949;12682,15626
40,40000;-25,34609;12690,68122
40,44000;-25,34280;12697,49552
40,48000;-25,33939;12709,50586
40,52000;-25,33604;12717,79239
40,56000;-25,33275;12724,37125
40,60000;-25,32946;12732,82915
40,64000;-25,32612;12742,50895
40,68000;-25,32271;12751,12182
40,72000;-25,31948;12758,05980
40,76000;-25,31613;12764,88006
40,80000;-25,31272;12777,51476
40,84000;-25,30943;12784,74480
40,88000;-25,30615;12790,42959
40,92000;-25,30280;12799,47311
40,96000;-25,29945;12808,03382
41,00000;-25,29610;12816,64371
41,04000;-25,29275;12824,33867
41,08000;-25,28935;12834,97065
41,12000;-25,28606;12842,03082
41,16000;-25,28277;12848,93006
41,20000;-25,27942;12858,83039
41,24000;-25,27607;12867,94394
41,28000;-25,27272;12876,99938
41,32000;-25,26944;12883,87328
41,36000;-25,26615;12892,06296
41,40000;-25,26274;12900,30777
41,44000;-25,25945;12907,53931
41,48000;-25,25616;12914,39235
41,52000;-25,25275;12923,83075
41,56000;-25,24941;12932,39444
41,60000;-25,24618;12938,19696
41,64000;-25,24283;12945,60581
41,68000;-25,23942;12956,09623
41,72000;-25,23619;12962,36664
41,76000;-25,23284;12968,68920
41,80000;-25,22949;12978,57463
41,84000;-25,22615;12987,82080
41,88000;-25,22292;12994,11505
41,92000;-25,21945;13002,54315
41,96000;-25,21616;13011,37656
42,00000;-25,21281;13016,54130
42,04000;-25,20953;13023,03523
42,08000;-25,20612;13030,77191
42,12000;-25,20283;13039,06888
42,16000;-25,19960;13046,52393
42,20000;-25,19607;13057,49565
42,24000;-25,19278;13064,78530
42,28000;-25,18950;13071,28221
42,32000;-25,18615;13078,05926
42,36000;-25,18322;13084,97339
42,40000;-25,17945;13095,97343
42,44000;-25,17610;13103,72502
42,48000;-25,17287;13109,44557
42,52000;-25,16947;13116,84102
42,56000;-25,16612;13124,13663
42,60000;-25,16289;13130,27591
42,64000;-25,15948;13136,17826
42,68000;-25,15613;13145,08766
42,72000;-25,15279;13152,10462
42,76000;-25,14944;13159,60586
42,80000;-25,14609;13173,08545
42,84000;-25,14280;13178,56014
42,88000;-25,13951;13182,84422
42,92000;-25,13616;13188,49027
42,96000;-25,13282;13195,81419
43,00000;-25,12953;13202,36325
43,04000;-25,12648;13207,79771
43,08000;-25,12277;13219,36250
43,12000;-25,11948;13226,88162
43,16000;-25,11613;13231,36389
43,20000;-25,11279;13237,58513
43,24000;-25,10950;13244,31449
43,28000;-25,10615;13251,16009
43,32000;-25,10274;13258,37523
43,36000;-25,09945;13263,84991
43,40000;-25,09610;13272,25268
43,44000;-25,09276;13277,22967
43,48000;-25,08953;13281,74919
43,52000;-25,08618;13286,82452
43,56000;-25,08283;13293,33931
43,60000;-25,07954;13299,12394
43,64000;-25,07631;13304,07709
43,68000;-25,07273;13312,16395
43,72000;-25,06950;13318,35091
43,76000;-25,06621;13320,65463
43,80000;-25,06280;13325,46026
43,84000;-25,05945;13332,00037
43,88000;-25,05611;13335,73759
43,92000;-25,05282;13338,72527
43,96000;-25,04941;13341,65633
44,00000;-25,04612;13345,59917
44,04000;-25,04283;13345,77501
44,08000;-25,03949;13345,98362
44,12000;-25,03613;13347,13846
44,16000;-25,03285;13344,55162
44,20000;-25,02950;13341,17949
44,24000;-25,02615;13338,11134
44,28000;-25,02280;13329,71752
44,32000;-25,01963;13318,96186
44,36000;-25,01611;13306,06937
44,40000;-25,01282;13283,64462
44,44000;-25,00941;13244,70490
44,48000;-25,00618;13169,88319
44,52000;-25,00212;9493,82856
44,54400;-24,99895;2389,33209