File: SU - Suspension/05 - Essais/Excels essais Optimus/Collage_alu_alu_31_01_19/collage1.is_tens_RawData/Specimen_RawData_1.csv
Temps;Déplacement;Charge
(sec);(mm);(N)
0,00000;-32,70958;52,80232
0,04000;-32,70904;53,19424
0,08000;-32,70671;59,72839
0,12000;-32,70336;73,73271
0,16000;-32,69971;90,14651
0,20000;-32,69583;108,03964
0,24000;-32,69188;126,18583
0,28000;-32,68818;145,41360
0,32000;-32,68447;165,30040
0,36000;-32,68088;185,19419
0,40000;-32,67735;204,65038
0,44000;-32,67389;225,33771
0,48000;-32,67042;246,19058
0,52000;-32,66695;266,77789
0,56000;-32,66354;286,27007
0,60000;-32,66025;306,14727
0,64000;-32,65691;324,64780
0,68000;-32,65350;342,00628
0,72000;-32,65021;359,84467
0,76000;-32,64686;379,21255
0,80000;-32,64345;397,59530
0,84000;-32,64016;416,07092
0,88000;-32,63688;433,46556
0,92000;-32,63347;450,04906
0,96000;-32,63012;466,48448
1,00000;-32,62689;481,01447
1,04000;-32,62342;494,07976
1,08000;-32,62008;505,32604
1,12000;-32,61679;512,37065
1,16000;-32,61344;518,50826
1,20000;-32,61009;523,09991
1,24000;-32,60674;528,04439
1,28000;-32,60345;532,46380
1,32000;-32,60011;537,74104
1,36000;-32,59676;543,09024
1,40000;-32,59341;548,70532
1,44000;-32,59006;554,38899
1,48000;-32,58671;560,68092
1,52000;-32,58343;567,83073
1,56000;-32,58008;575,29910
1,60000;-32,57673;581,67465
1,64000;-32,57338;588,26269
1,68000;-32,57009;595,29431
1,72000;-32,56668;601,10921
1,76000;-32,56334;607,11312
1,80000;-32,55999;614,00160
1,84000;-32,55664;620,77260
1,88000;-32,55341;625,88113
1,92000;-32,55006;631,19051
1,96000;-32,54677;639,02866
2,00000;-32,54343;644,70423
2,04000;-32,54008;650,02842
2,08000;-32,53673;654,26524
2,12000;-32,53344;658,01716
2,16000;-32,53009;660,69821
2,20000;-32,52675;662,67001
2,24000;-32,52340;663,25339
2,28000;-32,52005;662,47759
2,32000;-32,51670;663,45972
2,36000;-32,51335;665,71347
2,40000;-32,50994;669,82568
2,44000;-32,50672;674,51438
2,48000;-32,50337;677,89475
2,52000;-32,50002;686,29901
2,56000;-32,49667;698,43121
2,60000;-32,49338;709,72326
2,64000;-32,49015;722,34501
2,68000;-32,48668;735,69454
2,72000;-32,48340;746,53164
2,76000;-32,48011;757,94952
2,80000;-32,47676;771,00340
2,84000;-32,47335;783,53928
2,88000;-32,47018;796,48150
2,92000;-32,46672;811,56902
2,96000;-32,46337;825,73751
3,00000;-32,46008;840,34326
3,04000;-32,45673;853,99905
3,08000;-32,45332;871,78303
3,12000;-32,45004;885,65433
3,16000;-32,44675;899,48298
3,20000;-32,44340;914,54089
3,24000;-32,44005;931,03880
3,28000;-32,43676;945,31467
3,32000;-32,43347;959,63562
3,36000;-32,43006;976,17712
3,40000;-32,42672;993,39178
3,44000;-32,42343;1007,36748
3,48000;-32,42008;1021,87619
3,52000;-32,41679;1038,60609
3,56000;-32,41344;1055,10717
3,60000;-32,41016;1070,53686
3,64000;-32,40687;1085,40105
3,68000;-32,40340;1102,75820
3,72000;-32,40005;1119,13476
3,76000;-32,39682;1133,04155
3,80000;-32,39341;1148,47478
3,84000;-32,39012;1164,25101
3,88000;-32,38684;1178,64655
3,92000;-32,38355;1192,41923
3,96000;-32,38008;1208,17591
4,00000;-32,37679;1224,46427
4,04000;-32,37344;1238,45804
4,08000;-32,37010;1253,63143
4,12000;-32,36675;1268,91444
4,16000;-32,36346;1282,45810
4,20000;-32,36011;1296,32251
4,24000;-32,35682;1310,93860
4,28000;-32,35335;1328,81831
4,32000;-32,35007;1341,57119
4,36000;-32,34672;1354,68263
4,40000;-32,34337;1368,79263
4,44000;-32,34008;1382,59763
4,48000;-32,33673;1395,98772
4,52000;-32,33344;1408,91112
4,56000;-32,33003;1423,58029
4,60000;-32,32675;1437,75772
4,64000;-32,32382;1450,72779
4,68000;-32,31999;1466,60227
4,72000;-32,31664;1480,09863
4,76000;-32,31342;1491,63986
4,80000;-32,31007;1504,07543
4,84000;-32,30672;1517,57868
4,88000;-32,30349;1530,91149
4,92000;-32,30014;1543,83890
4,96000;-32,29703;1557,53698
5,00000;-32,29339;1572,66147
5,04000;-32,29004;1585,07470
5,08000;-32,28669;1597,46762
5,12000;-32,28340;1609,15777
5,16000;-32,28005;1622,07615
5,20000;-32,27676;1635,02824
5,24000;-32,27341;1645,80904
5,28000;-32,27007;1656,88787
5,32000;-32,26672;1670,84374
5,36000;-32,26337;1681,22761
5,40000;-32,26008;1692,22225
5,44000;-32,25680;1703,24389
5,48000;-32,25345;1713,72611
5,52000;-32,25040;1724,21690
5,56000;-32,24675;1736,42803
5,60000;-32,24340;1746,57442
5,64000;-32,24012;1756,59414
5,68000;-32,23676;1767,61206
5,72000;-32,23342;1777,25386
5,76000;-32,23013;1786,28825
5,80000;-32,22684;1795,85405
5,84000;-32,22343;1809,08926
5,88000;-32,22020;1817,77626
5,92000;-32,21685;1827,43371
5,96000;-32,21345;1838,92995
6,00000;-32,21016;1849,58801
6,04000;-32,20687;1859,11916
6,08000;-32,20346;1870,14863
6,12000;-32,20018;1881,66685
6,16000;-32,19683;1890,24527
6,20000;-32,19354;1900,15361
6,24000;-32,19013;1911,51835
6,28000;-32,18678;1922,15722
6,32000;-32,18349;1931,83329
6,36000;-32,18014;1941,69991
6,40000;-32,17686;1950,66538
6,44000;-32,17351;1959,91956
6,48000;-32,17016;1969,43134
6,52000;-32,16687;1978,09972
6,56000;-32,16346;1988,85929
6,60000;-32,16011;1998,23454
6,64000;-32,15689;2006,78539
6,68000;-32,15354;2015,95742
6,72000;-32,15013;2024,72433
6,76000;-32,14684;2033,17963
6,80000;-32,14343;2040,85819
6,84000;-32,14003;2050,75424
6,88000;-32,13680;2058,52687
6,92000;-32,13345;2065,36371
6,96000;-32,13010;2073,85365
7,00000;-32,12675;2082,80273
7,04000;-32,12346;2088,10959
7,08000;-32,12011;2097,22482
7,12000;-32,11677;2105,43443
7,16000;-32,11342;2112,01832
7,20000;-32,11013;2118,72719
7,24000;-32,10678;2126,24054
7,28000;-32,10349;2131,66885
7,32000;-32,10015;2137,26796
7,36000;-32,09680;2145,33210
7,40000;-32,09339;2153,07046
7,44000;-32,09004;2158,35907
7,48000;-32,08669;2164,69113
7,52000;-32,08347;2171,61588
7,56000;-32,08006;2178,28788
7,60000;-32,07671;2186,59062
7,64000;-32,07342;2194,79259
7,68000;-32,07001;2202,91503
7,72000;-32,06672;2210,36188
7,76000;-32,06343;2218,48786
7,80000;-32,06009;2226,36983
7,84000;-32,05674;2235,33046
7,88000;-32,05345;2243,84274
7,92000;-32,05010;2253,20552
7,96000;-32,04669;2263,13360
8,00000;-32,04335;2271,31937
8,04000;-32,04012;2278,55295
8,08000;-32,03677;2287,65607
8,12000;-32,03336;2296,91900
8,16000;-32,03013;2304,76148
8,20000;-32,02684;2312,46669
8,24000;-32,02344;2321,86690
8,28000;-32,02015;2329,90421
8,32000;-32,01680;2336,95377
8,36000;-32,01345;2345,94028
8,40000;-32,01010;2352,95743
8,44000;-32,00681;2360,52983
8,48000;-32,00352;2367,78911
8,52000;-32,00018;2375,96799
8,56000;-31,99677;2383,78383
8,60000;-31,99348;2391,09099
8,64000;-31,99013;2398,68555
8,68000;-31,98679;2406,28067
8,72000;-31,98344;2413,76143
8,76000;-31,98021;2419,64553
8,80000;-31,97686;2427,80503
8,84000;-31,97351;2435,68607
8,88000;-31,97016;2443,96981
8,92000;-31,96682;2451,28591
8,96000;-31,96341;2458,92555
9,00000;-31,96000;2466,77846
9,04000;-31,95683;2472,56104
9,08000;-31,95342;2481,53117
9,12000;-31,95007;2490,40797
9,16000;-31,94673;2497,48081
9,20000;-31,94344;2504,95430
9,24000;-31,94003;2511,77326
9,28000;-31,93674;2520,44778
9,32000;-31,93345;2526,19553
9,36000;-31,93011;2533,77706
9,40000;-31,92682;2541,81791
9,44000;-31,92341;2549,30537
9,48000;-31,92012;2556,45420
9,52000;-31,91677;2564,41925
9,56000;-31,91337;2571,49413
9,60000;-31,91008;2578,42001
9,64000;-31,90679;2585,91529
9,68000;-31,90338;2593,16247
9,72000;-31,89997;2600,54469
9,76000;-31,89674;2607,22023
9,80000;-31,89339;2613,58395
9,84000;-31,88998;2622,66137
9,88000;-31,88670;2628,93979
9,92000;-31,88347;2634,52977
9,96000;-31,88012;2643,28495
10,00000;-31,87677;2651,90359
10,04000;-31,87342;2659,76936
10,08000;-31,87008;2667,70571
10,12000;-31,86667;2676,47691
10,16000;-31,86338;2684,75320
10,20000;-31,86009;2692,84714
10,24000;-31,85668;2702,55320
10,28000;-31,85334;2710,97552
10,32000;-31,84999;2718,64124
10,36000;-31,84670;2725,78336
10,40000;-31,84335;2735,22623
10,44000;-31,84000;2743,33116
10,48000;-31,83677;2751,32824
10,52000;-31,83348;2760,43098
10,56000;-31,83014;2769,39906
10,60000;-31,82673;2778,31126
10,64000;-31,82344;2787,35962
10,68000;-31,82009;2795,81882
10,72000;-31,81674;2804,97950
10,76000;-31,81346;2813,27665
10,80000;-31,81017;2820,79000
10,84000;-31,80676;2831,69728
10,88000;-31,80341;2840,30288
10,92000;-31,80018;2848,41247
10,96000;-31,79671;2858,10325
11,00000;-31,79337;2866,88041
11,04000;-31,79014;2875,71605
11,08000;-31,78685;2884,26653
11,12000;-31,78338;2895,66275
11,16000;-31,78015;2903,41172
11,20000;-31,77686;2911,35404
11,24000;-31,77346;2920,08258
11,28000;-31,77017;2929,57984
11,32000;-31,76682;2938,67476
11,36000;-31,76365;2946,76945
11,40000;-31,76012;2957,73093
11,44000;-31,75678;2967,14362
11,48000;-31,75349;2974,74097
11,52000;-31,75020;2982,53186
11,56000;-31,74685;2991,67633
11,60000;-31,74344;3001,45447
11,64000;-31,74021;3009,64024
11,68000;-31,73681;3017,01035
11,72000;-31,73346;3029,58898
11,76000;-31,73011;3038,45722
11,80000;-31,72682;3045,15827
11,84000;-31,72353;3052,85566
11,88000;-31,72006;3063,06984
11,92000;-31,71677;3069,45685
11,96000;-31,71349;3078,27760
12,00000;-31,71002;3086,85005
12,04000;-31,70673;3094,70706
12,08000;-31,70344;3101,49714
12,12000;-31,70016;3109,10717
12,16000;-31,69675;3120,53449
12,20000;-31,69346;3126,01291
12,24000;-31,69011;3133,80212
12,28000;-31,68676;3143,04307
12,32000;-31,68341;3151,17054
12,36000;-31,68006;3158,84948
12,40000;-31,67678;3168,03716
12,44000;-31,67343;3177,59588
12,48000;-31,67008;3184,11738
12,52000;-31,66679;3191,46328
12,56000;-31,66338;3199,43540
12,60000;-31,66003;3208,90695
12,64000;-31,65675;3216,43762
12,68000;-31,65340;3222,73709
12,72000;-31,65011;3232,12668
12,76000;-31,64664;3241,25737
12,80000;-31,64342;3250,21148
12,84000;-31,64001;3257,98392
12,88000;-31,63672;3265,74035
12,92000;-31,63343;3272,05695
12,96000;-31,63008;3279,41105
13,00000;-31,62673;3287,59328
13,04000;-31,62344;3295,37801
13,08000;-31,62039;3303,86050
13,12000;-31,61663;3317,11099
13,16000;-31,61340;3326,29383
13,20000;-31,61011;3332,81010
13,24000;-31,60676;3342,30922
13,28000;-31,60347;3351,77146
13,32000;-31,60013;3359,71080
13,36000;-31,59684;3369,31944
13,40000;-31,59343;3378,77162
13,44000;-31,59014;3390,54912
13,48000;-31,58679;3398,41433
13,52000;-31,58357;3407,09612
13,56000;-31,58016;3415,51900
13,60000;-31,57681;3426,41436
13,64000;-31,57346;3434,42969
13,68000;-31,57011;3441,91976
13,72000;-31,56676;3452,68808
13,76000;-31,56342;3462,64467
13,80000;-31,56019;3469,64523
13,84000;-31,55678;3480,16731
13,88000;-31,55343;3490,11496
13,92000;-31,55014;3496,73070
13,96000;-31,54685;3505,18338
14,00000;-31,54345;3515,81499
14,04000;-31,54022;3524,63126
14,08000;-31,53687;3532,93270
14,12000;-31,53352;3543,80868
14,16000;-31,53017;3552,80377
14,20000;-31,52682;3560,29607
14,24000;-31,52348;3568,66345
14,28000;-31,52013;3579,38930
14,32000;-31,51672;3588,30132
14,36000;-31,51343;3596,84043
14,40000;-31,51014;3605,15788
14,44000;-31,50674;3613,89481
14,48000;-31,50345;3622,14670
14,52000;-31,50016;3630,10392
14,56000;-31,49681;3639,68387
14,60000;-31,49346;3649,09358
14,64000;-31,49017;3657,72769
14,68000;-31,48683;3666,00119
14,72000;-31,48342;3674,87073
14,76000;-31,48025;3684,17911
14,80000;-31,47672;3694,15581
14,84000;-31,47343;3703,57931
14,88000;-31,47003;3711,69597
14,92000;-31,46674;3717,61322
14,96000;-31,46345;3726,36467
15,00000;-31,46004;3735,74272
15,04000;-31,45675;3743,56359
15,08000;-31,45346;3751,85683
15,12000;-31,45006;3760,68689
15,16000;-31,44682;3768,58190
15,20000;-31,44348;3776,03546
15,24000;-31,44013;3784,05452
15,28000;-31,43678;3793,73468
15,32000;-31,43349;3800,52105
15,36000;-31,43009;3808,63696
15,40000;-31,42674;3819,03537
15,44000;-31,42339;3826,29149
15,48000;-31,42010;3833,33787
15,52000;-31,41675;3840,44796
15,56000;-31,41341;3848,05091
15,60000;-31,41006;3855,83527
15,64000;-31,40677;3862,39290
15,68000;-31,40342;3870,44363
15,72000;-31,40007;3879,29529
15,76000;-31,39672;3885,91774
15,80000;-31,39349;3891,57981
15,84000;-31,39009;3901,50622
15,88000;-31,38668;3909,00820
15,92000;-31,38351;3915,50213
15,96000;-31,38016;3922,14507
16,00000;-31,37675;3931,04143
16,04000;-31,37347;3938,49276
16,08000;-31,37006;3945,21877
16,12000;-31,36671;3954,51449
16,16000;-31,36342;3960,71337
16,20000;-31,36007;3967,23598
16,24000;-31,35673;3974,34942
16,28000;-31,35344;3981,50235
16,32000;-31,35015;3988,79237
16,36000;-31,34680;3997,34303
16,40000;-31,34345;4005,61318
16,44000;-31,34004;4012,97435
16,48000;-31,33675;4019,08308
16,52000;-31,33346;4025,45296
16,56000;-31,33012;4035,22812
16,60000;-31,32671;4041,69820
16,64000;-31,32342;4048,39739
16,68000;-31,32007;4054,57094
16,72000;-31,31672;4063,33096
16,76000;-31,31338;4072,16251
16,80000;-31,31015;4079,64028
16,84000;-31,30680;4087,43806
16,88000;-31,30339;4095,83487
16,92000;-31,30010;4103,90012
16,96000;-31,29676;4111,01393
17,00000;-31,29335;4120,05261
17,04000;-31,29006;4130,95243
17,08000;-31,28671;4137,20608
17,12000;-31,28342;4143,71975
17,16000;-31,28013;4152,79157
17,20000;-31,27678;4160,22316
17,24000;-31,27344;4168,22433
17,28000;-31,27015;4176,35143
17,32000;-31,26674;4185,86433
17,36000;-31,26339;4194,77038
17,40000;-31,26016;4202,03768
17,44000;-31,25676;4209,99713
17,48000;-31,25341;4217,23910
17,52000;-31,25012;4225,01042
17,56000;-31,24677;4232,27102
17,60000;-31,24336;4241,98024
17,64000;-31,24001;4249,51054
17,68000;-31,23685;4255,09624
17,72000;-31,23344;4263,17379
17,76000;-31,23009;4272,25307
17,80000;-31,22680;4277,76501
17,84000;-31,22345;4285,70956
17,88000;-31,22004;4295,45306
17,92000;-31,21682;4303,37302
17,96000;-31,21353;4309,54210
18,00000;-31,21006;4317,98212
18,04000;-31,20677;4328,15515
18,08000;-31,20342;4334,94933
18,12000;-31,20014;4341,75879
18,16000;-31,19673;4350,69464
18,20000;-31,19338;4357,97982
18,24000;-31,19009;4365,96051
18,28000;-31,18680;4373,80672
18,32000;-31,18339;4382,14689
18,36000;-31,18010;4389,12883
18,40000;-31,17676;4397,27269
18,44000;-31,17341;4407,40883
18,48000;-31,17006;4414,34272
18,52000;-31,16677;4422,54730
18,56000;-31,16348;4430,75076
18,60000;-31,16007;4440,65966
18,64000;-31,15673;4453,70413
18,68000;-31,15350;4460,05613
18,72000;-31,15009;4468,79119
18,76000;-31,14674;4478,12602
18,80000;-31,14345;4487,35803
18,84000;-31,14010;4496,07149
18,88000;-31,13670;4506,00348
18,92000;-31,13341;4516,39481
18,96000;-31,13036;4525,33588
19,00000;-31,12665;4537,41029
19,04000;-31,12342;4549,04325
19,08000;-31,12008;4556,08405
19,12000;-31,11673;4564,68128
19,16000;-31,11344;4574,90981
19,20000;-31,11009;4584,26476
19,24000;-31,10680;4594,25934
19,28000;-31,10345;4606,70181
19,32000;-31,10005;4620,73721
19,36000;-31,09676;4631,94959
19,40000;-31,09347;4643,57138
19,44000;-31,09012;4655,79405
19,48000;-31,08677;4669,39956
19,52000;-31,08342;4683,42528
19,56000;-31,08014;4693,70410
19,60000;-31,07673;4704,93175
19,64000;-31,07338;4719,63622
19,68000;-31,07015;4729,45459
19,72000;-31,06680;4741,17324
19,76000;-31,06346;4753,88765
19,80000;-31,06017;4765,02627
19,84000;-31,05694;4776,87716
19,88000;-31,05347;4791,14801
19,92000;-31,05012;4806,38668
19,96000;-31,04677;4816,86369
20,00000;-31,04343;4829,05060
20,04000;-31,04014;4842,01126
20,08000;-31,03679;4854,45000
20,12000;-31,03344;4866,40036
20,16000;-31,03003;4880,29681
20,20000;-31,02674;4894,17985
20,24000;-31,02340;4905,79084
20,28000;-31,02011;4919,84338
20,32000;-31,01676;4933,45857
20,36000;-31,01341;4947,00298
20,40000;-31,01012;4960,91321
20,44000;-31,00678;4974,31196
20,48000;-31,00343;4987,18619
20,52000;-31,00014;5000,85093
20,56000;-30,99679;5016,88346
20,60000;-30,99344;5030,50648
20,64000;-30,99009;5043,50215
20,68000;-30,98681;5056,52241
20,72000;-30,98346;5070,62525
20,76000;-30,98011;5084,42298
20,80000;-30,97676;5096,89264
20,84000;-30,97341;5111,50323
20,88000;-30,97006;5125,09048
20,92000;-30,96678;5139,21939
20,96000;-30,96343;5152,13385
21,00000;-30,96014;5166,19012
21,04000;-30,95679;5180,57346
21,08000;-30,95344;5193,12769
21,12000;-30,95015;5206,94144
21,16000;-30,94681;5221,61275
21,20000;-30,94346;5234,94072
21,24000;-30,94017;5248,37188
21,28000;-30,93682;5262,69116
21,32000;-30,93347;5277,11399
21,36000;-30,93013;5290,95866
21,40000;-30,92684;5304,82531
21,44000;-30,92349;5319,64898
21,48000;-30,92014;5335,81786
21,52000;-30,91679;5351,84555
21,56000;-30,91356;5368,22900
21,60000;-30,91016;5385,80120
21,64000;-30,90681;5404,00930
21,68000;-30,90358;5419,54525
21,72000;-30,90017;5438,30507
21,76000;-30,89670;5457,52905
21,80000;-30,89347;5474,92355
21,84000;-30,89018;5490,81601
21,88000;-30,88678;5508,01866
21,92000;-30,88349;5525,74135
21,96000;-30,88020;5543,03974
22,00000;-30,87685;5561,98247
22,04000;-30,87350;5580,47704
22,08000;-30,87016;5598,04700
22,12000;-30,86681;5614,98590
22,16000;-30,86352;5631,90579
22,20000;-30,86017;5649,17997
22,24000;-30,85682;5667,82393
22,28000;-30,85347;5685,96758
22,32000;-30,85013;5703,73535
22,36000;-30,84678;5721,45730
22,40000;-30,84343;5737,21230
22,44000;-30,84014;5754,05397
22,48000;-30,83679;5771,92418
22,52000;-30,83345;5790,10546
22,56000;-30,83016;5805,87648
22,60000;-30,82681;5823,37119
22,64000;-30,82346;5841,36136
22,68000;-30,82017;5857,86439
22,72000;-30,81682;5874,90946
22,76000;-30,81342;5893,39621
22,80000;-30,81019;5910,07732
22,84000;-30,80678;5926,54943
22,88000;-30,80343;5944,91437
22,92000;-30,80014;5962,89597
22,96000;-30,79674;5978,79067
23,00000;-30,79345;5996,42806
23,04000;-30,79010;6014,86191
23,08000;-30,78681;6030,63330
23,12000;-30,78346;6048,01066
23,16000;-30,78011;6066,50263
23,20000;-30,77677;6083,93811
23,24000;-30,77348;6100,35919
23,28000;-30,77007;6118,28528
23,32000;-30,76678;6135,25622
23,36000;-30,76343;6152,05690
23,40000;-30,76014;6168,24664
23,44000;-30,75673;6187,50341
23,48000;-30,75339;6205,07263
23,52000;-30,75004;6220,44988
23,56000;-30,74675;6238,17667
23,60000;-30,74334;6254,50313
23,64000;-30,74005;6271,56943
23,68000;-30,73683;6287,35647
23,72000;-30,73348;6305,16261
23,76000;-30,73013;6322,90468
23,80000;-30,72684;6339,35183
23,84000;-30,72349;6354,57188
23,88000;-30,72008;6373,55447
23,92000;-30,71680;6391,60126
23,96000;-30,71351;6406,35267
24,00000;-30,71016;6425,15048
24,04000;-30,70675;6443,69647
24,08000;-30,70340;6460,78736
24,12000;-30,70012;6478,10102
24,16000;-30,69671;6496,16718
24,20000;-30,69336;6515,35466
24,24000;-30,69013;6531,46952
24,28000;-30,68678;6548,57010
24,32000;-30,68349;6565,99402
24,36000;-30,68015;6583,50810
24,40000;-30,67686;6600,49692
24,44000;-30,67351;6619,00640
24,48000;-30,67016;6636,87065
24,52000;-30,66675;6654,63582
24,56000;-30,66352;6671,42868
24,60000;-30,66011;6688,93605
24,64000;-30,65677;6708,39176
24,68000;-30,65348;6726,23366
24,72000;-30,65013;6741,85306
24,76000;-30,64678;6760,62554
24,80000;-30,64343;6778,33185
24,84000;-30,64014;6793,45801
24,88000;-30,63680;6810,65693
24,92000;-30,63345;6829,56651
24,96000;-30,63010;6845,39229
25,00000;-30,62681;6861,26351
25,04000;-30,62353;6879,86165
25,08000;-30,62012;6896,99948
25,12000;-30,61683;6913,63290
25,16000;-30,61348;6929,49668
25,20000;-30,61013;6946,81406
25,24000;-30,60678;6963,54657
25,28000;-30,60349;6979,48113
25,32000;-30,60009;6996,14286
25,36000;-30,59674;7015,02413
25,40000;-30,59345;7030,28440
25,44000;-30,59016;7046,16234
25,48000;-30,58675;7063,45066
25,52000;-30,58335;7080,46332
25,56000;-30,58018;7096,61320
25,60000;-30,57677;7114,77473
25,64000;-30,57342;7132,27615
25,68000;-30,57013;7148,21219
25,72000;-30,56685;7164,60571
25,76000;-30,56332;7183,16138
25,80000;-30,56009;7199,51764
25,84000;-30,55674;7214,69149
25,88000;-30,55345;7230,26097
25,92000;-30,55010;7247,76313
25,96000;-30,54699;7263,53973
26,00000;-30,54341;7281,83612
26,04000;-30,54006;7298,87038
26,08000;-30,53671;7313,75813
26,12000;-30,53336;7329,29930
26,16000;-30,53013;7345,15041
26,20000;-30,52673;7363,97952
26,24000;-30,52344;7377,76533
26,28000;-30,52009;7392,90118
26,32000;-30,51680;7408,86778
26,36000;-30,51345;7425,34399
26,40000;-30,51004;7439,80259
26,44000;-30,50681;7455,28862
26,48000;-30,50341;7470,60254
26,52000;-30,50006;7487,18306
26,56000;-30,49683;7501,58429
26,60000;-30,49348;7517,77738
26,64000;-30,49013;7533,73429
26,68000;-30,48679;7549,61893
26,72000;-30,48350;7563,30267
26,76000;-30,48009;7580,31309
26,80000;-30,47680;7596,12098
26,84000;-30,47345;7609,51266
26,88000;-30,47040;7625,64614
26,92000;-30,46670;7643,24591
26,96000;-30,46347;7658,68798
27,00000;-30,46012;7672,45814
27,04000;-30,45683;7687,26096
27,08000;-30,45348;7702,20235
27,12000;-30,45013;7717,46337
27,16000;-30,44685;7732,27289
27,20000;-30,44362;7748,77295
27,24000;-30,44003;7767,70934
27,28000;-30,43674;7781,93474
27,32000;-30,43351;7794,99933
27,36000;-30,43011;7809,76042
27,40000;-30,42676;7823,52090
27,44000;-30,42353;7837,18154
27,48000;-30,42012;7852,30324
27,52000;-30,41671;7868,47919
27,56000;-30,41354;7881,65629
27,60000;-30,41014;7895,37802
27,64000;-30,40673;7911,63966
27,68000;-30,40350;7925,93807
27,72000;-30,40021;7938,30231
27,76000;-30,39674;7954,12958
27,80000;-30,39345;7970,00006
27,84000;-30,39011;7981,77645
27,88000;-30,38682;7995,52724
27,92000;-30,38347;8010,23543
27,96000;-30,38012;8022,48865
28,00000;-30,37677;8036,26850
28,04000;-30,37343;8049,68849
28,08000;-30,37008;8063,62480
28,12000;-30,36673;8077,75781
28,16000;-30,36338;8091,56820
28,20000;-30,36003;8105,99178
28,24000;-30,35669;8119,37377
28,28000;-30,35345;8132,38993
28,32000;-30,35011;8145,64228
28,36000;-30,34676;8160,14558
28,40000;-30,34341;8172,78251
28,44000;-30,34018;8185,76440
28,48000;-30,33677;8198,14280
28,52000;-30,33343;8211,42495
28,56000;-30,33020;8223,46732
28,60000;-30,32679;8236,35682
28,64000;-30,32344;8251,14027
28,68000;-30,32009;8264,15494
28,72000;-30,31681;8274,82566
28,76000;-30,31340;8289,51597
28,80000;-30,31005;8302,11639
28,84000;-30,30682;8312,80723
28,88000;-30,30347;8325,36295
28,92000;-30,30006;8339,93480
28,96000;-30,29683;8350,86703
29,00000;-30,29355;8361,80151
29,04000;-30,29014;8375,52324
29,08000;-30,28691;8387,67216
29,12000;-30,28350;8400,02224
29,16000;-30,28015;8413,66425
29,20000;-30,27686;8425,27226
29,24000;-30,27346;8437,48748
29,28000;-30,27011;8448,26475
29,32000;-30,26688;8458,59423
29,36000;-30,26347;8471,35037
29,40000;-30,26013;8484,04169
29,44000;-30,25689;8494,30263
29,48000;-30,25349;8506,64601
29,52000;-30,25008;8518,92531
29,56000;-30,24691;8529,74951
29,60000;-30,24350;8539,56118
29,64000;-30,24015;8551,61026
29,68000;-30,23693;8562,29216
29,72000;-30,23358;8573,60065
29,76000;-30,23017;8586,57658
29,80000;-30,22682;8598,87972
29,84000;-30,22347;8608,61912
29,88000;-30,22013;8617,93607
29,92000;-30,21678;8629,13281
29,96000;-30,21349;8638,86550
30,00000;-30,21020;8648,55573
30,04000;-30,20673;8659,53863
30,08000;-30,20350;8670,57890
30,12000;-30,20009;8679,95098
30,16000;-30,19675;8689,32158
30,20000;-30,19346;8700,85880
30,24000;-30,19011;8710,10274
30,28000;-30,18676;8718,58895
30,32000;-30,18353;8727,59968
30,36000;-30,18007;8738,49988
30,40000;-30,17672;8749,11770
30,44000;-30,17343;8757,18892
30,48000;-30,17002;8766,06107
30,52000;-30,16667;8775,43911
30,56000;-30,16345;8783,50511
30,60000;-30,16010;8790,78358
30,64000;-30,15675;8800,84783
30,68000;-30,15334;8809,91891
30,72000;-30,15005;8821,81525
30,76000;-30,14670;8830,92061
30,80000;-30,14336;8839,93059
30,84000;-30,14012;8847,22024
30,88000;-30,13702;8855,68783
30,92000;-30,13337;8868,33891
30,96000;-30,13002;8877,05535
31,00000;-30,12673;8883,04338
31,04000;-30,12339;8889,96944
31,08000;-30,12004;8898,10324
31,12000;-30,11675;8904,81323
31,16000;-30,11340;8913,29497
31,20000;-30,11011;8922,39958
31,24000;-30,10676;8927,12325
31,28000;-30,10336;8932,11812
31,32000;-30,10013;8936,86116
31,36000;-30,09672;8941,46785
31,40000;-30,09331;8947,78743
31,44000;-30,09008;8948,67033
31,48000;-30,08673;8949,47872
31,52000;-30,08339;8950,59705
31,56000;-30,08010;8949,09427
31,60000;-30,07681;8945,92330
31,64000;-30,07334;8943,15392
31,68000;-30,07005;8935,81808
31,72000;-30,06682;8922,45770
31,76000;-30,06342;8909,43930
31,80000;-30,06007;8888,68496
31,84000;-30,05678;8854,59781
31,88000;-30,05349;8810,21097
31,92000;-30,05002;8749,36357
31,96000;-30,04668;8656,01003
32,00000;-30,04339;8501,76662
32,04000;-30,03938;4780,26867
32,05800;-30,03735;1695,08811