File: SU - Suspension/05 - Essais/Excels essais Optimus/Temoins et tests triangles/Triangles tests/F-R sup/FR sup rr.is_tcyclic_RawData/Specimen_RawData_1.csv
Temps;Déplacement;Charge
(sec);(mm);(N)
0,00000;40,67610;0,04071
0,00200;40,67610;0,02025
0,00400;40,67610;0,00438
0,10400;40,67712;0,51444
0,20400;40,68185;0,53227
0,30400;40,68860;1,81095
0,40400;40,69488;2,04972
0,50400;40,70062;1,53023
0,60400;40,70588;2,31974
0,70400;40,71102;3,25246
0,80400;40,71604;5,26272
0,90400;40,72113;9,12322
1,00400;40,72597;42,59048
1,10400;40,73111;95,25694
1,20400;40,73602;145,72927
1,30400;40,74104;198,40735
1,40400;40,74606;252,28702
1,50400;40,75102;305,57618
1,60400;40,75598;358,31791
1,70400;40,76101;410,32261
1,80400;40,76603;461,43639
1,90400;40,77111;513,63106
2,00400;40,77607;566,58178
2,10400;40,78109;616,65750
2,20400;40,78612;666,46333
2,30400;40,79108;714,79101
2,40400;40,79611;763,32036
2,50400;40,80107;809,95560
2,60400;40,80609;856,14165
2,70400;40,81105;900,14366
2,80400;40,81613;946,63622
2,90400;40,82109;989,08748
3,00400;40,82612;1034,15083
3,10400;40,83108;1077,30506
3,20400;40,83616;1121,35354
3,30400;40,84113;1162,94436
3,40400;40,84609;1205,17546
3,50400;40,85099;1245,13609
3,60400;40,85613;1289,16362
3,70400;40,86104;1331,67626
3,80400;40,86612;1372,58396
3,90400;40,87102;1410,94932
4,00400;40,87604;1450,95168
4,10400;40,88101;1489,30242
4,20400;40,88621;1530,86511
4,30400;40,89111;1566,78483
4,40400;40,89607;1604,65576
4,50400;40,90103;1641,12560
4,60400;40,90600;1676,21169
4,70400;40,91114;1713,33235
4,80400;40,91610;1752,59467
4,90400;40,92106;1785,66203
5,00400;40,92609;1818,55094
5,10400;40,93105;1849,24286
5,20400;40,93613;1882,31952
5,30400;40,94109;1913,63785
5,40400;40,94605;1946,65957
5,50400;40,95108;1975,60042
5,60400;40,95604;2003,20967
5,70400;40,96112;2031,59954
5,80400;40,96603;2055,53118
5,90400;40,97105;2081,71178
6,00400;40,97601;2102,95077
6,10400;40,98109;2125,22335
6,20400;40,98605;2151,60903
6,30400;40,99108;2189,28792
6,40400;40,99604;2235,62364
6,50400;41,00112;2278,67533
6,60400;41,00608;2324,35744
6,70400;41,01111;2367,71256
6,80400;41,01613;2409,62338
6,90400;41,02115;2452,72163
7,00400;41,02618;2494,49071
7,10400;41,03108;2537,52042
7,20400;41,03616;2580,16884
7,30400;41,04112;2620,27606
7,40400;41,04620;2666,80568
7,50400;41,05110;2705,78265
7,60400;41,05619;2746,63679
7,70400;41,06115;2785,92538
7,80400;41,06617;2824,60302
7,90400;41,07107;2865,63225
8,00400;41,07610;2904,00274
8,10400;41,08106;2941,70491
8,20400;41,08614;2983,54644
8,30400;41,09105;3017,65818
8,40400;41,09607;3053,24160
8,50400;41,10097;3088,61230
8,60400;41,10611;3125,99763
8,70400;41,11101;3159,37921
8,80400;41,11615;3195,50596
8,90400;41,12100;3230,99010
9,00400;41,12608;3262,96352
9,10400;41,13105;3293,83314
9,20400;41,13607;3322,64192
9,30400;41,14115;3357,24168
9,40400;41,14605;3387,16172
9,50400;41,15107;3416,69209
9,60400;41,15610;3442,98184
9,70400;41,16112;3468,87261
9,80400;41,16620;3496,33396
9,90400;41,17116;3517,29058
10,00400;41,17607;3535,77435
10,10400;41,18109;3551,24250
10,20400;41,18605;3562,71788
10,30400;41,19107;3564,88302
10,40400;41,19609;3550,12491
10,50400;41,20112;3495,20259
10,58400;41,20506;3219,25730
10,60000;41,20590;2941,48251
10,62400;41,20721;2683,81350
10,72400;41,21230;2684,50696
10,82400;41,21720;2716,14324
10,92400;41,22222;2754,47425
11,02400;41,22712;2791,01133
11,12400;41,23209;2830,45638
11,22400;41,23705;2870,12737
11,32400;41,24207;2908,94639
11,42400;41,24703;2950,60668
11,52400;41,25206;2990,52447
11,62400;41,25702;3032,31999
11,72400;41,26210;3075,11818
11,82400;41,26707;3114,74986
11,92400;41,27209;3157,31317
12,02400;41,27705;3199,15153
12,12400;41,28207;3241,08228
12,22400;41,28709;3283,67092
12,32400;41,29205;3322,84495
12,42400;41,29714;3366,72030
12,52400;41,30204;3405,26886
12,62400;41,30718;3448,89835
12,72400;41,31209;3488,91765
12,82400;41,31711;3528,11590
12,92400;41,32207;3566,22078
13,02400;41,32709;3605,23276
13,12400;41,33206;3644,30249
13,22400;41,33708;3681,28754
13,32400;41,34198;3718,50729
13,42400;41,34700;3756,10068
13,52400;41,35197;3793,85576
13,62400;41,35711;3832,97876
13,72400;41,36201;3868,60743
13,82400;41,36709;3904,79676
13,92400;41,37194;3940,50032
14,02400;41,37708;3977,64482
14,12400;41,38198;4014,59187
14,22400;41,38712;4051,81907
14,32400;41,39214;4088,87975
14,42400;41,39705;4123,71419
14,52400;41,40207;4159,51610
14,62400;41,40709;4195,70878
14,72400;41,41212;4232,57612
14,82400;41,41707;4267,86244
14,92400;41,42210;4302,86303
15,02400;41,42706;4338,75099
15,12400;41,43209;4375,23425
15,22400;41,43717;4411,68956
15,32400;41,44219;4447,01985
15,42400;41,44709;4480,99263
15,52400;41,45217;4519,87535
15,62400;41,45714;4553,72185
15,72400;41,46216;4589,71150
15,82400;41,46706;4624,03037
15,92400;41,47208;4660,98562
16,02400;41,47699;4697,05872
16,12400;41,48213;4732,64083
16,22400;41,48709;4768,30043
16,32400;41,49211;4802,03554
16,42400;41,49707;4841,08366
16,52400;41,50216;4875,90581
16,62400;41,50706;4909,23487
16,72400;41,51214;4942,93571
16,82400;41,51704;4976,34821
16,92400;41,52207;5011,00905
17,02400;41,52709;5045,46352
17,12400;41,53211;5079,50373
17,22400;41,53714;5114,09007
17,32400;41,54210;5144,16173
17,42400;41,54718;5180,10892
17,52400;41,55214;5211,86665
17,62400;41,55716;5245,72395
17,72400;41,56206;5277,06631
17,82400;41,56709;5310,56225
17,92400;41,57205;5342,42056
18,02400;41,57708;5375,69188
18,12400;41,58203;5407,69100
18,22400;41,58706;5439,53776
18,32400;41,59202;5471,54807
18,42400;41,59710;5503,52745
18,52400;41,60207;5536,29957
18,62400;41,60715;5567,58419
18,72400;41,61199;5597,75680
18,82400;41,61713;5630,18918
18,92400;41,62204;5660,98429
19,02400;41,62712;5693,55898
19,12400;41,63208;5725,06301
19,22400;41,63704;5753,71310
19,32400;41,64218;5786,72215
19,42400;41,64715;5815,70566
19,52400;41,65223;5850,59002
19,62400;41,65713;5879,59029
19,72400;41,66216;5908,82786
19,82400;41,66712;5938,99935
19,92400;41,67202;5967,72134
20,02200;41,67704;6000,60001
20,02400;41,67710;6001,21878
20,12400;41,67746;5999,10431
20,22400;41,67316;5951,70520
20,32400;41,66598;5849,25935
20,42400;41,65905;5754,43730
20,52400;41,65295;5670,44653
20,62400;41,64745;5596,42836
20,72400;41,64224;5529,99750
20,82400;41,63710;5464,32398
20,92400;41,63202;5396,57660
21,02400;41,62706;5332,40736
21,12400;41,62210;5268,15802
21,22400;41,61707;5205,83056
21,32400;41,61205;5143,96690
21,42400;41,60709;5080,13926
21,52400;41,60207;5016,98554
21,62400;41,59710;4955,77306
21,72400;41,59202;4895,57013
21,82400;41,58700;4832,30166
21,92400;41,58197;4769,27459
22,02400;41,57702;4708,89360
22,12400;41,57199;4647,52167
22,22400;41,56697;4584,52925
22,32400;41,56201;4522,63877
22,42400;41,55698;4460,82540
22,52400;41,55202;4401,42639
22,62400;41,54700;4338,13594
22,72400;41,54204;4278,41246
22,82400;41,53695;4216,42549
22,92400;41,53206;4156,53251
23,02400;41,52697;4096,65555
23,12400;41,52201;4037,75275
23,22400;41,51704;3977,22460
23,32400;41,51202;3917,26121
23,42400;41,50706;3857,48371
23,52400;41,50204;3797,18244
23,62400;41,49701;3737,16056
23,72400;41,49205;3676,87941
23,82400;41,48703;3616,46339
23,92400;41,48207;3558,53550
24,02400;41,47699;3498,75502
24,12400;41,47202;3437,44121
24,22400;41,46700;3377,27256
24,32400;41,46198;3316,29291
24,42400;41,45707;3260,60280
24,52400;41,45199;3200,24267
24,62400;41,44703;3140,27444
24,72400;41,44195;3078,80696
24,82400;41,43705;3022,87471
24,92400;41,43196;2965,30966
25,02400;41,42700;2904,26072
25,12400;41,42198;2845,42851
25,22400;41,41702;2786,90718
25,32400;41,41205;2730,04193
25,42400;41,40703;2672,54394
25,52400;41,40201;2616,35259
25,62400;41,39699;2557,50287
25,72400;41,39202;2498,70140
25,82400;41,38706;2443,08114
25,92400;41,38210;2385,84839
26,02400;41,37702;2327,13800
26,12400;41,37200;2270,98335
26,22400;41,36709;2213,62915
26,32400;41,36201;2158,22123
26,42400;41,35699;2100,81805
26,52400;41,35203;2047,03137
26,62400;41,34695;1989,64775
26,72400;41,34204;1933,92765
26,82400;41,33702;1879,46130
26,92400;41,33200;1824,70419
27,02400;41,32697;1771,02275
27,12400;41,32207;1718,03515
27,22400;41,31705;1665,82763
27,32400;41,31209;1612,02569
27,42400;41,30701;1559,31702
27,52400;41,30198;1508,84800
27,62400;41,29696;1457,85194
27,72400;41,29205;1417,80134
27,82400;41,28703;1385,92925
27,92400;41,28207;1358,97314
28,02400;41,27705;1326,97430
28,12400;41,27209;1292,14665
28,22400;41,26707;1257,60855
28,32400;41,26204;1219,27578
28,42400;41,25708;1186,31022
28,52400;41,25200;1149,83544
28,62400;41,24703;1115,87159
28,72400;41,24201;1078,75112
28,82400;41,23705;1044,49615
28,92400;41,23203;1011,08970
29,02400;41,22701;977,31585
29,12400;41,22198;942,14780
29,22400;41,21708;904,27315
29,32400;41,21200;864,92263
29,42400;41,20698;828,23327
29,52400;41,20196;788,62673
29,62400;41,19699;751,48232
29,72400;41,19197;713,51402
29,82400;41,18701;675,19802
29,92400;41,18205;637,85529
30,02400;41,17696;600,39260
30,12400;41,17206;563,43512
30,22400;41,16704;527,40849
30,32400;41,16207;490,52192
30,42400;41,15699;453,65337
30,52400;41,15197;418,12542
30,62400;41,14695;379,71605
30,72400;41,14192;341,59955
30,82400;41,13703;305,88657
30,92400;41,13194;270,11447
31,02400;41,12692;233,59305
31,12400;41,12201;199,80602
31,22400;41,11705;163,29926
31,32400;41,11203;128,15158
31,42400;41,10695;92,46743
31,52400;41,10199;56,22793
31,62400;41,09702;23,57157
31,71600;41,09248;0,37676