File: SU - Suspension/05 - Essais/Excels essais Optimus/Collage_alu_alu_31_01_19/collage10.is_tens_RawData/Specimen_RawData_1.csv
Temps;Déplacement;Charge
(sec);(mm);(N)
0,00000;-27,06342;68,77854
0,04000;-27,06294;68,28933
0,08000;-27,06079;76,88599
0,12000;-27,05756;99,31824
0,16000;-27,05385;129,54099
0,20000;-27,05002;161,78879
0,24000;-27,04608;194,49069
0,28000;-27,04237;224,00657
0,32000;-27,03866;250,71451
0,36000;-27,03502;276,10909
0,40000;-27,03149;298,96465
0,44000;-27,02802;319,02478
0,48000;-27,02450;340,76637
0,52000;-27,02109;361,26210
0,56000;-27,01774;378,08171
0,60000;-27,01433;394,82415
0,64000;-27,01098;409,27534
0,68000;-27,00764;419,19216
0,72000;-27,00429;427,02225
0,76000;-27,00094;432,39715
0,80000;-26,99759;435,37198
0,84000;-26,99424;436,64803
0,88000;-26,99089;440,15804
0,92000;-26,98761;447,99619
0,96000;-26,98426;456,33437
1,00000;-26,98091;464,21071
1,04000;-26,97756;472,37985
1,08000;-26,97415;481,37102
1,12000;-26,97081;489,19269
1,16000;-26,96757;495,63837
1,20000;-26,96423;504,39597
1,24000;-26,96082;512,55953
1,28000;-26,95759;519,22929
1,32000;-26,95424;525,20782
1,36000;-26,95084;533,27503
1,40000;-26,94755;539,95135
1,44000;-26,94462;546,30889
1,48000;-26,94073;556,70170
1,52000;-26,93756;563,33072
1,56000;-26,93421;569,25747
1,60000;-26,93092;576,85343
1,64000;-26,92758;585,01884
1,68000;-26,92423;592,88177
1,72000;-26,92082;599,58682
1,76000;-26,91753;607,25007
1,80000;-26,91418;613,12551
1,84000;-26,91089;619,36071
1,88000;-26,90743;626,34982
1,92000;-26,90414;634,24977
1,96000;-26,90085;639,59672
2,00000;-26,89756;644,16793
2,04000;-26,89421;649,91890
2,08000;-26,89093;655,21733
2,12000;-26,88758;659,92665
2,16000;-26,88429;665,84577
2,20000;-26,88100;672,26049
2,24000;-26,87741;679,92737
2,28000;-26,87418;684,64917
2,32000;-26,87090;687,94265
2,36000;-26,86749;691,86576
2,40000;-26,86420;696,00116
2,44000;-26,86085;698,21486
2,48000;-26,85750;702,43045
2,52000;-26,85410;707,89196
2,56000;-26,85081;708,71287
2,60000;-26,84752;710,05435
2,64000;-26,84423;712,94359
2,68000;-26,84088;715,15944
2,72000;-26,83759;717,78027
2,76000;-26,83419;720,61867
2,80000;-26,83084;721,76494
2,84000;-26,82761;723,24905
2,88000;-26,82414;724,56361
2,92000;-26,82085;723,68123
2,96000;-26,81750;726,42532
3,00000;-26,81416;734,84783
3,04000;-26,81093;746,57872
3,08000;-26,80746;759,18362
3,12000;-26,80411;770,19744
3,16000;-26,80094;781,94700
3,20000;-26,79753;793,85461
3,24000;-26,79419;804,85065
3,28000;-26,79096;816,01050
3,32000;-26,78761;827,46483
3,36000;-26,78414;841,14131
3,40000;-26,78085;853,38773
3,44000;-26,77751;864,71485
3,48000;-26,77422;876,21370
3,52000;-26,77087;889,09362
3,56000;-26,76758;901,01352
3,60000;-26,76423;913,01808
3,64000;-26,76088;926,91826
3,68000;-26,75754;939,98583
3,72000;-26,75425;953,28242
3,76000;-26,75090;967,31223
3,80000;-26,74755;980,71201
3,84000;-26,74426;993,60170
3,88000;-26,74091;1006,76408
3,92000;-26,73763;1019,43323
3,96000;-26,73428;1033,23320
4,00000;-26,73093;1046,00517
4,04000;-26,72764;1059,41854
4,08000;-26,72423;1072,72007
4,12000;-26,72094;1084,68896
4,16000;-26,71765;1098,41116
4,20000;-26,71425;1111,08748
4,24000;-26,71090;1125,06580
4,28000;-26,70767;1137,93137
4,32000;-26,70426;1152,10852
4,36000;-26,70092;1166,79566
4,40000;-26,69763;1179,43045
4,44000;-26,69422;1192,21229
4,48000;-26,69087;1206,81962
4,52000;-26,68752;1221,37554
4,56000;-26,68423;1234,36050
4,60000;-26,68089;1247,96927
4,64000;-26,67754;1265,81984
4,68000;-26,67419;1278,74855
4,72000;-26,67096;1292,99173
4,76000;-26,66755;1307,41606
4,80000;-26,66421;1323,26791
4,84000;-26,66097;1338,09075
4,88000;-26,65757;1352,44578
4,92000;-26,65428;1367,56189
4,96000;-26,65093;1383,22217
5,00000;-26,64752;1398,79500
5,04000;-26,64424;1415,99905
5,08000;-26,64089;1431,64098
5,12000;-26,63748;1446,91700
5,16000;-26,63419;1461,63255
5,20000;-26,63084;1476,63746
5,24000;-26,62743;1492,73779
5,28000;-26,62426;1507,88622
5,32000;-26,62086;1523,50646
5,36000;-26,61751;1540,16092
5,40000;-26,61422;1555,78116
5,44000;-26,61093;1570,81354
5,48000;-26,60753;1586,44971
5,52000;-26,60417;1602,84210
5,56000;-26,60089;1616,79778
5,60000;-26,59760;1631,91929
5,64000;-26,59413;1648,54676
5,68000;-26,59084;1663,86515
5,72000;-26,58749;1677,20616
5,76000;-26,58409;1692,67878
5,80000;-26,58080;1706,36959
5,84000;-26,57745;1719,53402
5,88000;-26,57422;1732,37398
5,92000;-26,57093;1747,34145
5,96000;-26,56764;1760,35445
6,00000;-26,56424;1774,13691
6,04000;-26,56095;1788,07937
6,08000;-26,55754;1800,62652
6,12000;-26,55419;1814,33856
6,16000;-26,55102;1824,87294
6,20000;-26,54755;1837,80864
6,24000;-26,54421;1853,67931
6,28000;-26,54092;1863,93373
6,32000;-26,53757;1873,69175
6,36000;-26,53416;1886,44566
6,40000;-26,53087;1898,75271
6,44000;-26,52758;1909,55773
6,48000;-26,52424;1921,38553
6,52000;-26,52089;1933,45193
6,56000;-26,51754;1944,03920
6,60000;-26,51443;1953,77339
6,64000;-26,51084;1966,54033
6,68000;-26,50756;1977,14120
6,72000;-26,50427;1987,49043
6,76000;-26,50098;1996,42554
6,80000;-26,49763;2006,88280
6,84000;-26,49428;2017,43413
6,88000;-26,49099;2027,25288
6,92000;-26,48759;2038,62973
6,96000;-26,48418;2049,41276
7,00000;-26,48089;2058,05935
7,04000;-26,47766;2066,20917
7,08000;-26,47431;2075,86307
7,12000;-26,47084;2085,00680
7,16000;-26,46761;2092,49612
7,20000;-26,46421;2099,86009
7,24000;-26,46086;2107,91081
7,28000;-26,45757;2115,54896
7,32000;-26,45434;2120,67850
7,36000;-26,45088;2128,87712
7,40000;-26,44753;2135,83261
7,44000;-26,44418;2141,04336
7,48000;-26,44089;2146,49979
7,52000;-26,43754;2152,50403
7,56000;-26,43419;2158,62915
7,60000;-26,43091;2163,67617
7,64000;-26,42750;2171,05448
7,68000;-26,42415;2177,56033
7,72000;-26,42080;2181,84199
7,76000;-26,41751;2186,57386
7,80000;-26,41411;2192,21674
7,84000;-26,41082;2197,38614
7,88000;-26,40747;2202,16606
7,92000;-26,40424;2206,62095
7,96000;-26,40083;2212,45233
8,00000;-26,39748;2218,64451
8,04000;-26,39432;2223,08058
8,08000;-26,39085;2229,44561
8,12000;-26,38744;2235,33958
8,16000;-26,38421;2240,67867
8,20000;-26,38092;2244,15474
8,24000;-26,37745;2250,70994
8,28000;-26,37416;2258,70442
8,32000;-26,37088;2261,78411
8,36000;-26,36747;2266,79519
8,40000;-26,36412;2272,35649
8,44000;-26,36083;2276,93431
8,48000;-26,35772;2280,25466
8,52000;-26,35407;2288,47675
8,56000;-26,35085;2294,54897
8,60000;-26,34750;2298,96605
8,64000;-26,34421;2304,42341
8,68000;-26,34092;2308,42177
8,72000;-26,33752;2314,39415
8,76000;-26,33417;2318,42622
8,80000;-26,33094;2323,37248
8,84000;-26,32765;2329,04274
8,88000;-26,32418;2338,33902
8,92000;-26,32095;2343,12322
8,96000;-26,31754;2348,43902
9,00000;-26,31420;2353,57750
9,04000;-26,31091;2358,27565
9,08000;-26,30756;2364,36743
9,12000;-26,30415;2370,31635
9,16000;-26,30092;2375,62582
9,20000;-26,29776;2379,65658
9,24000;-26,29417;2387,48398
9,28000;-26,29094;2391,73416
9,32000;-26,28759;2394,05017
9,36000;-26,28424;2399,64593
9,40000;-26,28095;2405,83085
9,44000;-26,27760;2410,43568
9,48000;-26,27432;2415,37504
9,52000;-26,27109;2420,91604
9,56000;-26,26756;2427,95385
9,60000;-26,26421;2432,88651
9,64000;-26,26086;2437,55523
9,68000;-26,25758;2441,43456
9,72000;-26,25417;2447,34585
9,76000;-26,25088;2452,55698
9,80000;-26,24771;2457,07966
9,84000;-26,24418;2463,98728
9,88000;-26,24084;2469,49736
9,92000;-26,23761;2474,38177
9,96000;-26,23426;2480,03714
10,00000;-26,23091;2485,97637
10,04000;-26,22768;2490,99843
10,08000;-26,22427;2496,38818
10,12000;-26,22087;2504,31728
10,16000;-26,21764;2508,64029
10,20000;-26,21423;2514,18911
10,24000;-26,21082;2520,12350
10,28000;-26,20753;2526,21807
10,32000;-26,20424;2530,94956
10,36000;-26,20084;2536,67254
10,40000;-26,19749;2542,52758
10,44000;-26,19420;2547,29893
10,48000;-26,19091;2551,33789
10,52000;-26,18750;2557,77836
10,56000;-26,18421;2562,67767
10,60000;-26,18087;2568,83763
10,64000;-26,17758;2573,97201
10,68000;-26,17423;2579,97643
10,72000;-26,17088;2585,72027
10,76000;-26,16753;2590,77754
10,80000;-26,16424;2597,17982
10,84000;-26,16083;2601,83010
10,88000;-26,15755;2607,28560
10,92000;-26,15426;2612,74166
10,96000;-26,15085;2619,16742
11,00000;-26,14750;2625,46148
11,04000;-26,14428;2630,23619
11,08000;-26,14087;2636,95549
11,12000;-26,13752;2642,87144
11,16000;-26,13423;2648,43237
11,20000;-26,13094;2652,12897
11,24000;-26,12759;2658,06541
11,28000;-26,12425;2664,30937
11,32000;-26,12102;2668,68100
11,36000;-26,11761;2675,58508
11,40000;-26,11420;2682,05162
11,44000;-26,11091;2687,65166
11,48000;-26,10762;2691,32424
11,52000;-26,10422;2697,68704
11,56000;-26,10093;2703,78720
11,60000;-26,09758;2710,13193
11,64000;-26,09423;2715,97300
11,68000;-26,09094;2721,13793
11,72000;-26,08760;2726,83930
11,76000;-26,08425;2731,46480
11,80000;-26,08096;2738,04013
11,84000;-26,07761;2744,26639
11,88000;-26,07426;2750,12814
11,92000;-26,07097;2756,97969
11,96000;-26,06756;2761,67784
12,00000;-26,06428;2768,25391
12,04000;-26,06093;2774,31868
12,08000;-26,05758;2779,94350
12,12000;-26,05423;2786,07868
12,16000;-26,05094;2791,81004
12,20000;-26,04765;2798,36431
12,24000;-26,04425;2805,15682
12,28000;-26,04090;2811,60846
12,32000;-26,03761;2816,73092
12,36000;-26,03426;2823,29004
12,40000;-26,03085;2830,49643
12,44000;-26,02763;2836,38332
12,48000;-26,02428;2842,02918
12,52000;-26,02087;2848,38509
12,56000;-26,01758;2855,45886
12,60000;-26,01429;2861,45918
12,64000;-26,01088;2867,92610
12,68000;-26,00760;2873,61518
12,72000;-26,00425;2878,55864
12,76000;-26,00090;2883,83793
12,80000;-25,99767;2890,83160
12,84000;-25,99426;2897,87333
12,88000;-25,99092;2905,06408
12,92000;-25,98757;2911,43190
12,96000;-25,98416;2916,79502
13,00000;-25,98081;2923,81570
13,04000;-25,97764;2928,55203
13,08000;-25,97417;2935,43264
13,12000;-25,97083;2942,70683
13,16000;-25,96754;2949,12793
13,20000;-25,96419;2954,31744
13,24000;-25,96078;2960,89221
13,28000;-25,95749;2968,27573
13,32000;-25,95426;2973,30469
13,36000;-25,95091;2980,13315
13,40000;-25,94757;2988,17400
13,44000;-25,94428;2994,56734
13,48000;-25,94093;2999,81274
13,52000;-25,93752;3007,66844
13,56000;-25,93417;3015,03353
13,60000;-25,93089;3020,48083
13,64000;-25,92748;3027,55963
13,68000;-25,92419;3035,71597
13,72000;-25,92084;3042,78266
13,76000;-25,91749;3049,74318
13,80000;-25,91426;3056,11491
13,84000;-25,91086;3065,43149
13,88000;-25,90745;3074,90993
13,92000;-25,90428;3082,80364
13,96000;-25,90093;3090,64500
14,00000;-25,89752;3100,09457
14,04000;-25,89423;3108,88682
14,08000;-25,89089;3117,93126
14,12000;-25,88754;3127,47173
14,16000;-25,88419;3135,36450
14,20000;-25,88090;3143,12391
14,24000;-25,87755;3151,67829
14,28000;-25,87415;3160,64097
14,32000;-25,87086;3167,79576
14,36000;-25,86757;3175,27205
14,40000;-25,86410;3183,40622
14,44000;-25,86087;3190,89778
14,48000;-25,85758;3197,15329
14,52000;-25,85423;3205,91405
14,56000;-25,85095;3214,90057
14,60000;-25,84760;3222,98557
14,64000;-25,84425;3230,24876
14,68000;-25,84090;3239,21219
14,72000;-25,83755;3247,36647
14,76000;-25,83427;3253,99116
14,80000;-25,83098;3262,47029
14,84000;-25,82751;3270,96879
14,88000;-25,82416;3277,84419
14,92000;-25,82099;3284,38058
14,96000;-25,81747;3293,00463
15,00000;-25,81418;3301,01624
15,04000;-25,81089;3307,20022
15,08000;-25,80760;3313,84949
15,12000;-25,80413;3322,97124
15,16000;-25,80084;3332,00991
15,20000;-25,79755;3337,14671
15,24000;-25,79421;3344,37042
15,28000;-25,79086;3352,86148
15,32000;-25,78757;3360,71141
15,36000;-25,78434;3370,96862
15,40000;-25,78075;3385,07816
15,44000;-25,77753;3396,77967
15,48000;-25,77418;3407,48504
15,52000;-25,77083;3419,00066
15,56000;-25,76748;3431,15292
15,60000;-25,76419;3443,30296
15,64000;-25,76084;3454,36931
15,68000;-25,75750;3466,63110
15,72000;-25,75415;3481,39592
15,76000;-25,75086;3490,15146
15,80000;-25,74763;3500,48877
15,84000;-25,74428;3510,68489
15,88000;-25,74082;3523,25402
15,92000;-25,73759;3533,35515
15,96000;-25,73424;3544,35891
16,00000;-25,73077;3558,49750
16,04000;-25,72748;3569,01474
16,08000;-25,72419;3577,83698
16,12000;-25,72085;3588,65857
16,16000;-25,71750;3599,61353
16,20000;-25,71421;3608,80159
16,24000;-25,71092;3620,21998
16,28000;-25,70745;3634,26097
16,32000;-25,70416;3644,81695
16,36000;-25,70088;3654,45837
16,40000;-25,69753;3664,60979
16,44000;-25,69418;3675,24363
16,48000;-25,69089;3685,78732
16,52000;-25,68754;3695,33971
16,56000;-25,68425;3706,66385
16,60000;-25,68078;3721,46815
16,64000;-25,67750;3731,73356
16,68000;-25,67427;3741,66034
16,72000;-25,67086;3752,51360
16,76000;-25,66751;3763,24207
16,80000;-25,66428;3775,24532
16,84000;-25,66094;3785,32037
16,88000;-25,65741;3799,06483
16,92000;-25,65424;3811,78185
16,96000;-25,65089;3820,34406
17,00000;-25,64760;3830,63443
17,04000;-25,64426;3840,54706
17,08000;-25,64097;3850,87542
17,12000;-25,63756;3862,59481
17,16000;-25,63421;3875,16841
17,20000;-25,63098;3886,12263
17,24000;-25,62757;3897,50376
17,28000;-25,62416;3911,26834
17,32000;-25,62094;3920,44522
17,36000;-25,61759;3930,54187
17,40000;-25,61424;3941,92897
17,44000;-25,61095;3954,33232
17,48000;-25,60760;3964,08513
17,52000;-25,60431;3974,33490
17,56000;-25,60103;3987,56303
17,60000;-25,59756;3999,74734
17,64000;-25,59427;4010,82039
17,68000;-25,59098;4021,24450
17,72000;-25,58758;4031,87871
17,76000;-25,58429;4042,95176
17,80000;-25,58094;4052,85135
17,84000;-25,57759;4063,22218
17,88000;-25,57424;4073,76289
17,92000;-25,57095;4083,78467
17,96000;-25,56767;4092,79130
18,00000;-25,56426;4103,89267
18,04000;-25,56091;4114,03961
18,08000;-25,55768;4122,18347
18,12000;-25,55427;4133,28893
18,16000;-25,55087;4142,63606
18,20000;-25,54763;4150,67896
18,24000;-25,54429;4159,09328
18,28000;-25,54082;4169,70961
18,32000;-25,53759;4178,44169
18,36000;-25,53424;4186,10796
18,40000;-25,53090;4196,16774
18,44000;-25,52754;4204,40398
18,48000;-25,52432;4211,31849
18,52000;-25,52091;4219,91460
18,56000;-25,51762;4227,73585
18,60000;-25,51421;4235,55933
18,64000;-25,51099;4241,60659
18,68000;-25,50758;4250,54803
18,72000;-25,50423;4255,66286
18,76000;-25,50094;4262,75171
18,80000;-25,49759;4270,35354
18,84000;-25,49424;4276,89701
18,88000;-25,49083;4282,43615
18,92000;-25,48755;4287,50031
18,96000;-25,48420;4290,36170
19,00000;-25,48085;4295,19340
19,04000;-25,47750;4298,07194
19,08000;-25,47421;4300,91992
19,12000;-25,47086;4304,94845
19,16000;-25,46746;4307,36467
19,20000;-25,46423;4307,28756
19,24000;-25,46088;4307,03387
19,28000;-25,45753;4307,60719
19,32000;-25,45424;4307,14563
19,36000;-25,45096;4304,67315
19,40000;-25,44755;4303,54290
19,44000;-25,44420;4301,36248
19,48000;-25,44091;4296,92417
19,52000;-25,43750;4292,59725
19,56000;-25,43421;4287,93170
19,60000;-25,43081;4280,00763
19,64000;-25,42758;4272,31193
19,68000;-25,42417;4265,12770
19,72000;-25,42082;4255,06756
19,76000;-25,41753;4244,67176
19,80000;-25,41431;4238,73253
19,84000;-25,41090;4252,70796
19,88000;-25,40749;4275,63749
19,92000;-25,40426;4297,62527
19,96000;-25,40091;4318,45337
20,00000;-25,39756;4338,96631
20,04000;-25,39422;4358,53004
20,08000;-25,39093;4375,21040
20,12000;-25,38746;4395,64437
20,16000;-25,38411;4412,48082
20,20000;-25,38094;4427,71390
20,24000;-25,37759;4442,54316
20,28000;-25,37425;4458,59693
20,32000;-25,37096;4474,32511
20,36000;-25,36755;4490,60537
20,40000;-25,36414;4508,48639
20,44000;-25,36091;4522,79225
20,48000;-25,35750;4537,29071
20,52000;-25,35440;4550,71069
20,56000;-25,35087;4569,00299
20,60000;-25,34752;4583,00039
20,64000;-25,34417;4596,40734
20,68000;-25,34088;4610,65695
20,72000;-25,33748;4625,80621
20,76000;-25,33413;4641,27362
20,80000;-25,33084;4656,89451
20,84000;-25,32749;4670,16250
20,88000;-25,32414;4685,02901
20,92000;-25,32079;4700,11309
20,96000;-25,31769;4712,78429
21,00000;-25,31410;4729,16998
21,04000;-25,31081;4744,09871
21,08000;-25,30758;4755,70634
21,12000;-25,30423;4769,53015
21,16000;-25,30082;4784,34898
21,20000;-25,29754;4798,64590
21,24000;-25,29431;4811,16772
21,28000;-25,29072;4826,74018
21,32000;-25,28749;4841,00580
21,36000;-25,28420;4852,63877
21,40000;-25,28091;4867,17187
21,44000;-25,27751;4883,32100
21,48000;-25,27410;4897,18914
21,52000;-25,27081;4910,69891
21,56000;-25,26752;4925,48607
21,60000;-25,26417;4940,17974
21,64000;-25,26082;4954,31349
21,68000;-25,25760;4967,18660
21,72000;-25,25419;4981,70704
21,76000;-25,25078;4997,41323
21,80000;-25,24749;5011,31192
21,84000;-25,24426;5023,97232
21,88000;-25,24080;5040,28425
21,92000;-25,23751;5055,14145
21,96000;-25,23428;5067,09591
22,00000;-25,23099;5083,02301
22,04000;-25,22746;5099,53909
22,08000;-25,22423;5113,12224
22,12000;-25,22094;5127,62778
22,16000;-25,21748;5142,95176
22,20000;-25,21425;5156,90111
22,24000;-25,21096;5169,83271
22,28000;-25,20755;5183,42964
22,32000;-25,20426;5200,33427
22,36000;-25,20092;5213,81684
22,40000;-25,19757;5228,25271
22,44000;-25,19428;5244,00771
22,48000;-25,19093;5258,98598
22,52000;-25,18758;5272,50171
22,56000;-25,18429;5286,40971
22,60000;-25,18089;5300,91152
22,64000;-25,17760;5315,57426
22,68000;-25,17443;5329,35448
22,72000;-25,17084;5347,88258
22,76000;-25,16755;5361,24147
22,80000;-25,16421;5374,33177
22,84000;-25,16092;5387,55059
22,88000;-25,15757;5402,75611
22,92000;-25,15422;5417,49746
22,96000;-25,15093;5431,72769
23,00000;-25,14758;5446,09949
23,04000;-25,14418;5464,72296
23,08000;-25,14089;5477,17996
23,12000;-25,13760;5490,41517
23,16000;-25,13419;5504,37830
23,20000;-25,13096;5518,70950
23,24000;-25,12767;5533,05261
23,28000;-25,12421;5550,28990
23,32000;-25,12092;5566,90656
23,36000;-25,11757;5580,13916
23,40000;-25,11422;5593,90858
23,44000;-25,11087;5608,57505
23,48000;-25,10753;5622,66186
23,52000;-25,10417;5637,73997
23,56000;-25,10083;5653,46554
23,60000;-25,09754;5669,17770
23,64000;-25,09419;5681,75055
23,68000;-25,09090;5695,64290
23,72000;-25,08756;5708,84161
23,76000;-25,08415;5725,55065
23,80000;-25,08086;5739,76561
23,84000;-25,07775;5754,13853
23,88000;-25,07416;5770,79095
23,92000;-25,07087;5786,24308
23,96000;-25,06759;5798,87405
24,00000;-25,06424;5812,90498
24,04000;-25,06083;5829,74143
24,08000;-25,05754;5844,16166
24,12000;-25,05419;5859,19730
24,16000;-25,05096;5873,52663
24,20000;-25,04749;5889,62771
24,24000;-25,04421;5903,69329
24,28000;-25,04092;5918,06099
24,32000;-25,03757;5933,26651
24,36000;-25,03422;5947,32687
24,40000;-25,03094;5960,66937
24,44000;-25,02759;5976,54618
24,48000;-25,02424;5990,85614
24,52000;-25,02095;6005,32852
24,56000;-25,01760;6019,79047
24,60000;-25,01425;6035,60023
24,64000;-25,01091;6049,74702
24,68000;-25,00762;6063,39835
24,72000;-25,00427;6076,63766
24,76000;-25,00092;6091,21881
24,80000;-24,99757;6105,06237
24,84000;-24,99428;6117,92170
24,88000;-24,99094;6132,98714
24,92000;-24,98753;6148,03582
24,96000;-24,98436;6161,01958
25,00000;-24,98095;6174,76031
25,04000;-24,97760;6189,90026
25,08000;-24,97431;6203,10158
25,12000;-24,97102;6215,95308
25,16000;-24,96756;6230,57447
25,20000;-24,96427;6244,24778
25,24000;-24,96098;6256,26594
25,28000;-24,95763;6270,70591
25,32000;-24,95429;6285,73373
25,36000;-24,95100;6298,64410
25,40000;-24,94759;6312,72346
25,44000;-24,94424;6328,71687
25,48000;-24,94089;6341,88429
25,52000;-24,93760;6354,98241
25,56000;-24,93426;6368,38749
25,60000;-24,93091;6381,63537
25,64000;-24,92762;6396,02914
25,68000;-24,92427;6409,15930
25,72000;-24,92092;6423,60151
25,76000;-24,91751;6438,53694
25,80000;-24,91417;6451,73788
25,84000;-24,91094;6463,09108
25,88000;-24,90759;6477,36937
25,92000;-24,90424;6492,26531
25,96000;-24,90095;6505,48115
26,00000;-24,89754;6519,75423
26,04000;-24,89420;6533,37389
26,08000;-24,89097;6547,02559
26,12000;-24,88756;6559,63421
26,16000;-24,88415;6573,79925
26,20000;-24,88092;6587,67819
26,24000;-24,87757;6601,54223
26,28000;-24,87417;6616,76303
26,32000;-24,87088;6631,21119
26,36000;-24,86753;6643,43610
26,40000;-24,86418;6657,02373
26,44000;-24,86083;6671,79078
26,48000;-24,85749;6684,34501
26,52000;-24,85420;6697,89240
26,56000;-24,85085;6712,55365
26,60000;-24,84756;6727,45705
26,64000;-24,84421;6741,47457
26,68000;-24,84086;6755,05251
26,72000;-24,83757;6769,27865
26,76000;-24,83417;6783,37291
26,80000;-24,83082;6797,15425
26,84000;-24,82759;6809,99830
26,88000;-24,82418;6823,49503
26,92000;-24,82077;6837,51106
26,96000;-24,81755;6851,70367
27,00000;-24,81420;6864,24971
27,04000;-24,81079;6879,95777
27,08000;-24,80762;6892,58501
27,12000;-24,80427;6905,81724
27,16000;-24,80092;6920,55896
27,20000;-24,79764;6935,42063
27,24000;-24,79429;6948,50981
27,28000;-24,79088;6962,95947
27,32000;-24,78753;6977,10365
27,36000;-24,78424;6989,75399
27,40000;-24,78089;7003,58152
27,44000;-24,77755;7018,23160
27,48000;-24,77420;7032,48903
27,52000;-24,77085;7046,54232
27,56000;-24,76750;7060,76398
27,60000;-24,76415;7074,96479
27,64000;-24,76086;7088,07334
27,68000;-24,75758;7101,80998
27,72000;-24,75429;7116,84003
27,76000;-24,75094;7130,36656
27,80000;-24,74759;7144,62399
27,84000;-24,74430;7158,53870
27,88000;-24,74084;7172,61508
27,92000;-24,73755;7188,04076
27,96000;-24,73432;7200,43257
28,00000;-24,73091;7215,14001
28,04000;-24,72750;7230,60295
28,08000;-24,72421;7244,22410
28,12000;-24,72093;7256,06754
28,16000;-24,71752;7271,93803
28,20000;-24,71423;7285,72458
28,24000;-24,71088;7298,13352
28,28000;-24,70759;7311,33744
28,32000;-24,70424;7327,03283
28,36000;-24,70090;7339,94618
28,40000;-24,69761;7352,99289
28,44000;-24,69420;7367,39039
28,48000;-24,69085;7381,88773
28,52000;-24,68756;7395,04918
28,56000;-24,68421;7407,77403
28,60000;-24,68087;7422,28627
28,64000;-24,67752;7435,81802
28,68000;-24,67411;7448,92359
28,72000;-24,67082;7460,65229
28,76000;-24,66747;7474,63256
28,80000;-24,66412;7488,39900
28,84000;-24,66090;7500,85935
28,88000;-24,65755;7515,02663
28,92000;-24,65420;7529,13207
28,96000;-24,65091;7541,66692
29,00000;-24,64756;7553,91642
29,04000;-24,64416;7568,61344
29,08000;-24,64087;7583,28140
29,12000;-24,63758;7594,84693
29,16000;-24,63423;7608,38911
29,20000;-24,63088;7623,62704
29,24000;-24,62753;7637,16847
29,28000;-24,62419;7649,20637
29,32000;-24,62090;7662,16666
29,36000;-24,61749;7676,70423
29,40000;-24,61420;7689,27038
29,44000;-24,61103;7701,10637
29,48000;-24,60751;7718,13840
29,52000;-24,60422;7731,66567
29,56000;-24,60093;7741,54440
29,60000;-24,59764;7753,95036
29,64000;-24,59423;7767,63335
29,68000;-24,59088;7781,57711
29,72000;-24,58765;7794,56571
29,76000;-24,58425;7808,68232
29,80000;-24,58078;7824,86722
29,84000;-24,57761;7836,00211
29,88000;-24,57426;7846,32489
29,92000;-24,57085;7859,21887
29,96000;-24,56757;7872,77594
30,00000;-24,56428;7883,69551
30,04000;-24,56087;7900,69103
30,08000;-24,55758;7912,95320
30,12000;-24,55423;7925,18035
30,16000;-24,55089;7937,75767
30,20000;-24,54760;7950,44675
30,24000;-24,54425;7962,37141
30,28000;-24,54084;7976,73613
30,32000;-24,53755;7994,54376
30,36000;-24,53420;8004,94775
30,40000;-24,53092;8016,46784
30,44000;-24,52757;8029,69709
30,48000;-24,52428;8040,53843
30,52000;-24,52093;8052,51673
30,56000;-24,51794;8065,42411
30,60000;-24,51423;8080,85874
30,64000;-24,51089;8095,45070
30,68000;-24,50754;8107,29861
30,72000;-24,50431;8119,58686
30,76000;-24,50090;8132,58067
30,80000;-24,49755;8145,35841
30,84000;-24,49426;8156,91128
30,88000;-24,49109;8169,03114
30,92000;-24,48745;8185,43211
30,96000;-24,48422;8199,65228
31,00000;-24,48087;8209,69939
31,04000;-24,47752;8222,65372
31,08000;-24,47417;8235,64827
31,12000;-24,47088;8247,20338
31,16000;-24,46754;8260,65168
31,20000;-24,46413;8276,63839
31,24000;-24,46084;8291,54775
31,28000;-24,45755;8301,84892
31,32000;-24,45420;8314,36217
31,36000;-24,45086;8326,86871
31,40000;-24,44757;8338,37092
31,44000;-24,44422;8351,79463
31,48000;-24,44093;8366,41267
31,52000;-24,43752;8379,84309
31,56000;-24,43417;8392,52397
31,60000;-24,43095;8406,61079
31,64000;-24,42754;8419,36246
31,68000;-24,42419;8431,94127
31,72000;-24,42114;8444,01568
31,76000;-24,41755;8460,31755
31,80000;-24,41420;8474,21587
31,84000;-24,41092;8486,19044
31,88000;-24,40763;8497,44976
31,92000;-24,40422;8509,98536
31,96000;-24,40093;8522,61707
32,00000;-24,39758;8534,16026
32,04000;-24,39418;8547,66071
32,08000;-24,39089;8560,67538
32,12000;-24,38760;8572,22229
32,16000;-24,38419;8585,13191
32,20000;-24,38084;8597,64889
32,24000;-24,37755;8609,49457
32,28000;-24,37427;8621,56525
32,32000;-24,37092;8633,50853
32,36000;-24,36757;8646,64465
32,40000;-24,36428;8658,39273
32,44000;-24,36093;8671,36419
32,48000;-24,35758;8683,81336
32,52000;-24,35424;8694,84991
32,56000;-24,35089;8706,73731
32,60000;-24,34760;8719,16786
32,64000;-24,34419;8731,04557
32,68000;-24,34096;8743,10434
32,72000;-24,33756;8756,59436
32,76000;-24,33421;8769,96890
32,80000;-24,33086;8781,32135
32,84000;-24,32763;8792,15896
32,88000;-24,32428;8804,69605
32,92000;-24,32087;8818,74338
32,96000;-24,31777;8829,69275
33,00000;-24,31424;8842,40419
33,04000;-24,31089;8855,51125
33,08000;-24,30754;8867,48880
33,12000;-24,30431;8877,65586
33,16000;-24,30090;8889,84278
33,20000;-24,29756;8902,68460
33,24000;-24,29427;8914,15477
33,28000;-24,29110;8924,25254
33,32000;-24,28751;8939,38988
33,36000;-24,28422;8950,40631
33,40000;-24,28088;8961,66340
33,44000;-24,27759;8972,42650
33,48000;-24,27430;8985,12378
33,52000;-24,27089;8995,93309
33,56000;-24,26760;9007,29820
33,60000;-24,26431;9018,66779
33,64000;-24,26091;9031,30099
33,68000;-24,25768;9042,35765
33,72000;-24,25433;9055,16967
33,76000;-24,25092;9067,44525
33,80000;-24,24751;9079,60385
33,84000;-24,24434;9090,79760
33,88000;-24,24088;9101,96081
33,92000;-24,23753;9114,60221
33,96000;-24,23418;9125,70506
34,00000;-24,23089;9135,71343
34,04000;-24,22748;9148,50086
34,08000;-24,22420;9161,16312
34,12000;-24,22091;9170,93977
34,16000;-24,21750;9182,54256
34,20000;-24,21415;9195,65707
34,24000;-24,21086;9205,66395
34,28000;-24,20757;9216,82194
34,32000;-24,20416;9229,33072
34,36000;-24,20088;9241,41929
34,40000;-24,19753;9252,32470
34,44000;-24,19412;9263,37391
34,48000;-24,19083;9274,36575
34,52000;-24,18748;9286,34182
34,56000;-24,18414;9296,68173
34,60000;-24,18091;9305,82210
34,64000;-24,17756;9316,85045
34,68000;-24,17409;9330,99166
34,72000;-24,17086;9344,32447
34,76000;-24,16752;9354,00277
34,80000;-24,16417;9364,41496
34,84000;-24,16088;9374,80405
34,88000;-24,15759;9382,54893
34,92000;-24,15424;9393,70766
34,96000;-24,15089;9403,76446
35,00000;-24,14773;9412,39297
35,04000;-24,14414;9427,39099
35,08000;-24,14079;9438,31354
35,12000;-24,13756;9446,08301
35,16000;-24,13421;9455,26361
35,20000;-24,13086;9466,24428
35,24000;-24,12757;9476,37558
35,28000;-24,12423;9484,81038
35,32000;-24,12106;9494,91784
35,36000;-24,11747;9507,44450
35,40000;-24,11418;9516,91866
35,44000;-24,11083;9524,00640
35,48000;-24,10760;9532,61852
35,52000;-24,10420;9541,77976
35,56000;-24,10091;9550,01339
35,60000;-24,09762;9558,20754
35,64000;-24,09421;9567,78228
35,68000;-24,09086;9575,99878
35,72000;-24,08764;9583,26310
35,76000;-24,08423;9593,96511
35,80000;-24,08088;9602,67484
35,84000;-24,07759;9607,91633
35,88000;-24,07430;9614,19344
35,92000;-24,07084;9622,28402
35,96000;-24,06755;9626,95032
36,00000;-24,06420;9627,69389
36,04000;-24,06091;9626,53160
36,08000;-24,05750;9619,74114
36,12000;-24,05421;9602,31200
36,16000;-24,05087;9568,83952
36,20000;-24,04751;9467,69342
36,24000;-24,04345;5194,77986
36,25600;-24,04154;1764,73595