File: SU - Suspension/05 - Essais/Excels essais Optimus/Test_Rotules_31_01_19/M7_4.is_tens_RawData/Specimen_RawData_1.csv
Temps;Déplacement;Charge
(sec);(mm);(N)
0,00000;6,17081;21,17080
0,04000;6,17093;20,75401
0,08000;6,17141;21,41102
0,12000;6,17249;23,04869
0,16000;6,17380;23,17382
0,20000;6,17506;22,89210
0,24000;6,17643;22,61821
0,28000;6,17799;22,56415
0,32000;6,17942;22,88745
0,36000;6,18086;22,99725
0,40000;6,18229;23,06671
0,44000;6,18373;23,29892
0,48000;6,18504;23,11131
0,52000;6,18624;22,71002
0,56000;6,18767;22,74535
0,60000;6,18905;22,33502
0,64000;6,19042;23,44393
0,68000;6,19174;23,00582
0,72000;6,19306;22,82550
0,76000;6,19449;22,43733
0,80000;6,19569;22,85300
0,84000;6,19694;22,39801
0,88000;6,19838;23,13286
0,92000;6,19975;22,86162
0,96000;6,20107;24,14237
1,00000;6,20238;23,76358
1,04000;6,20376;22,60847
1,08000;6,20513;23,28152
1,12000;6,20639;22,32528
1,16000;6,20764;22,00906
1,20000;6,20914;23,17563
1,24000;6,21045;22,75269
1,28000;6,21177;23,14204
1,32000;6,21308;22,57294
1,36000;6,21446;23,16929
1,40000;6,21584;23,20768
1,44000;6,21703;22,60758
1,48000;6,21841;22,78866
1,52000;6,21984;23,20959
1,56000;6,22116;22,81451
1,60000;6,22247;23,30928
1,64000;6,22379;22,53933
1,68000;6,22516;23,47517
1,72000;6,22648;23,34299
1,76000;6,22767;23,70563
1,80000;6,22905;22,67398
1,84000;6,23048;22,78139
1,88000;6,23180;23,45402
1,92000;6,23311;23,31552
1,96000;6,23449;22,80785
2,00000;6,23586;23,13359
2,04000;6,23712;22,78631
2,08000;6,23838;23,46709
2,12000;6,23975;22,60758
2,16000;6,24113;23,78461
2,20000;6,24244;22,79527
2,24000;6,24382;23,01625
2,28000;6,24513;23,08992
2,32000;6,24651;23,76431
2,36000;6,24776;23,16097
2,40000;6,24902;23,08279
2,44000;6,25045;22,75796
2,48000;6,25177;23,43781
2,52000;6,25314;22,83735
2,56000;6,25452;23,14841
2,60000;6,25583;23,50438
2,64000;6,25715;22,55404
2,68000;6,25847;22,97695
2,72000;6,25966;23,22704
2,76000;6,26110;23,53246
2,80000;6,26241;23,62055
2,84000;6,26379;23,21862
2,88000;6,26516;23,42876
2,92000;6,26648;23,23512
2,96000;6,26785;23,81110
3,00000;6,26905;23,23490
3,04000;6,27030;23,17032
3,08000;6,27174;23,56718
3,12000;6,27311;23,19147
3,16000;6,27449;22,93700
3,20000;6,27580;23,30343
3,24000;6,27718;22,44478
3,28000;6,27855;22,58038
3,32000;6,27975;22,89785
3,36000;6,28101;23,13244
3,40000;6,28238;23,35548
3,44000;6,28376;22,91114
3,48000;6,28513;23,09469
3,52000;6,28645;22,77749
3,56000;6,28776;23,17874
3,60000;6,28914;23,32590
3,64000;6,29039;22,75154
3,68000;6,29171;22,72322
3,72000;6,29314;23,46856
3,76000;6,29446;23,50622
3,80000;6,29583;23,13722
3,84000;6,29715;23,32674
3,88000;6,29852;23,79587
3,92000;6,29990;22,90897
3,96000;6,30110;23,06845
4,00000;6,30247;23,46692
4,04000;6,30379;23,62640
4,08000;6,30510;23,58402
4,12000;6,30648;23,37005
4,16000;6,30779;23,26864
4,20000;6,30905;22,90336
4,24000;6,31048;23,53738
4,28000;6,31168;23,72051
4,32000;6,31305;23,17658
4,36000;6,31443;23,77433
4,40000;6,31574;23,65343
4,44000;6,31712;22,90267
4,48000;6,31843;23,59306
4,52000;6,31981;23,17641
4,56000;6,32112;23,48291
4,60000;6,32232;23,01015
4,64000;6,32375;23,45434
4,68000;6,32513;23,82013
4,72000;6,32651;23,94450
4,76000;6,32782;23,38351
4,80000;6,32914;24,03533
4,84000;6,33051;22,85246
4,88000;6,33171;22,59752
4,92000;6,33296;23,18662
4,96000;6,33440;23,56480
5,00000;6,33577;23,38525
5,04000;6,33709;23,09031
5,08000;6,33846;23,04031
5,12000;6,33984;23,34059
5,16000;6,34121;22,97367
5,20000;6,34235;23,23806
5,24000;6,34372;22,81721
5,28000;6,34516;22,95945
5,32000;6,34653;22,64025
5,36000;6,34785;22,74731
5,40000;6,34923;22,48625
5,44000;6,35054;22,17304
5,48000;6,35186;23,19154
5,52000;6,35305;22,64749
5,56000;6,35437;23,27726
5,60000;6,35580;23,57332
5,64000;6,35712;23,37822
5,68000;6,35849;23,32801
5,72000;6,35981;23,18897
5,76000;6,36118;22,72344
5,80000;6,36244;23,05821
5,84000;6,36369;22,91330
5,88000;6,36507;23,94423
5,92000;6,36644;24,11669
5,96000;6,36776;23,16780
6,00000;6,36914;22,60511
6,04000;6,37045;22,97757
6,08000;6,37183;23,36246
6,12000;6,37308;22,51950
6,16000;6,37434;23,04808
6,20000;6,37577;23,79790
6,24000;6,37709;23,27931
6,28000;6,37846;23,12725
6,32000;6,37978;23,25045
6,36000;6,38109;22,77622
6,40000;6,38247;23,36461
6,44000;6,38372;23,17605
6,48000;6,38504;22,79091
6,52000;6,38647;22,81956
6,56000;6,38779;22,36411
6,60000;6,38911;23,03059
6,64000;6,39042;23,22481
6,68000;6,39180;22,74148
6,72000;6,39317;22,86548
6,76000;6,39437;22,36021
6,80000;6,39574;22,15062
6,84000;6,39712;23,13291
6,88000;6,39849;22,69717
6,92000;6,39981;22,79500
6,96000;6,40112;23,36552
7,00000;6,40250;23,48702
7,04000;6,40381;22,50684
7,08000;6,40501;22,69981
7,12000;6,40638;22,07536
7,16000;6,40782;22,32398
7,20000;6,40919;22,31734
7,24000;6,41051;22,42938
7,28000;6,41183;22,45525
7,32000;6,41326;22,43665
7,36000;6,41446;22,45063
7,40000;6,41571;22,46005
7,44000;6,41709;22,51259
7,48000;6,41846;22,23489
7,52000;6,41984;22,54682
7,56000;6,42115;22,83055
7,60000;6,42253;22,85344
7,64000;6,42390;22,57223
7,68000;6,42510;22,90796
7,72000;6,42629;22,61610
7,76000;6,42773;22,44233
7,80000;6,42910;23,10865
7,84000;6,43042;22,53282
7,88000;6,43179;22,45168
7,92000;6,43311;22,89751
7,96000;6,43454;22,60284
8,00000;6,43574;22,25384
8,04000;6,43700;22,36242
8,08000;6,43843;22,55017
8,12000;6,43981;22,85253
8,16000;6,44112;22,93967
8,20000;6,44250;23,25481
8,24000;6,44381;22,27506
8,28000;6,44519;22,53945
8,32000;6,44644;22,49053
8,36000;6,44770;22,08432
8,40000;6,44913;22,05127
8,44000;6,45045;22,62502
8,48000;6,45176;21,89091
8,52000;6,45314;22,36871
8,56000;6,45451;22,38866
8,60000;6,45589;21,76338
8,64000;6,45709;21,83203
8,68000;6,45846;22,54442
8,72000;6,45984;22,10488
8,76000;6,46115;22,28028
8,80000;6,46247;22,63055
8,84000;6,46384;22,80109
8,88000;6,46504;21,73089
8,92000;6,46659;22,03398
8,96000;6,46773;21,72036
9,00000;6,46910;22,08045
9,04000;6,47048;21,98494
9,08000;6,47179;22,02581
9,12000;6,47311;22,33463
9,16000;6,47442;21,47776
9,20000;6,47580;21,91147
9,24000;6,47712;22,29666
9,28000;6,47831;22,27900
9,32000;6,47969;21,04503
9,36000;6,48112;21,12296
9,40000;6,48250;21,81905
9,44000;6,48381;22,70067
9,48000;6,48519;21,82571
9,52000;6,48650;21,64297
9,56000;6,48782;22,12827
9,60000;6,48907;21,59768
9,64000;6,49045;21,74186
9,68000;6,49176;22,03452
9,72000;6,49314;22,36036
9,76000;6,49445;21,86023
9,80000;6,49583;21,60165
9,84000;6,49720;21,47688
9,88000;6,49846;20,89209
9,92000;6,49966;21,56950
9,96000;6,50085;21,36708
10,00000;6,50253;21,42916
10,04000;6,50384;20,92225
10,08000;6,50522;20,76471
10,12000;6,50653;21,31447
10,16000;6,50791;21,13295
10,20000;6,50916;20,82663
10,24000;6,51042;21,13369
10,28000;6,51185;20,96184
10,32000;6,51311;21,10516
10,36000;6,51448;21,37548
10,40000;6,51580;21,18635
10,44000;6,51717;21,14556
10,48000;6,51849;21,01534
10,52000;6,51974;21,04518
10,56000;6,52106;20,90450
10,60000;6,52244;21,96191
10,64000;6,52375;21,32607
10,68000;6,52513;21,43649
10,72000;6,52650;21,29527
10,76000;6,52782;21,39927
10,80000;6,52919;21,26934
10,84000;6,53045;21,09199
10,88000;6,53170;20,97406
10,92000;6,53308;22,04143
10,96000;6,53439;21,49911
11,00000;6,53577;21,27343
11,04000;6,53708;21,33376
11,08000;6,53846;21,40554
11,12000;6,53983;21,04366
11,16000;6,54103;20,95203
11,20000;6,54241;20,99443
11,24000;6,54378;21,03333
11,28000;6,54510;20,72304
11,32000;6,54647;20,67748
11,36000;6,54779;20,77727
11,40000;6,54916;20,67997
11,44000;6,55048;20,53389
11,48000;6,55173;20,93665
11,52000;6,55311;21,56301
11,56000;6,55448;21,42966
11,60000;6,55580;20,83446
11,64000;6,55717;20,76131
11,68000;6,55849;21,32012
11,72000;6,55986;21,31356
11,76000;6,56112;21,29657
11,80000;6,56237;21,69321
11,84000;6,56375;21,28513
11,88000;6,56489;21,16860
11,92000;6,56656;21,84336
11,96000;6,56782;21,22628
12,00000;6,56919;21,20417
12,04000;6,57051;21,65815
12,08000;6,57170;20,58775
12,12000;6,57302;21,51317
12,16000;6,57445;21,22488
12,20000;6,57583;21,68070
12,24000;6,57714;20,97430
12,28000;6,57846;21,05275
12,32000;6,57983;20,85718
12,36000;6,58121;20,37389
12,40000;6,58240;20,23547
12,44000;6,58366;20,90255
12,48000;6,58504;20,66541
12,52000;6,58641;20,04715
12,56000;6,58773;20,30556
12,60000;6,58910;20,13005
12,64000;6,59048;20,97264
12,68000;6,59179;21,00498
12,72000;6,59299;19,85969
12,76000;6,59436;20,18058
12,80000;6,59574;20,84775
12,84000;6,59711;20,20959
12,88000;6,59843;20,30400
12,92000;6,59956;20,46534
12,96000;6,60130;20,76023
13,00000;6,60255;19,59501
13,04000;6,60375;19,49179
13,08000;6,60512;19,75681
13,12000;6,60644;20,39135
13,16000;6,60776;20,00156
13,20000;6,60913;19,96058
13,24000;6,61045;20,64252
13,28000;6,61182;19,93304
13,32000;6,61308;20,27998
13,36000;6,61433;19,89891
13,40000;6,61577;19,66167
13,44000;6,61708;19,15694
13,48000;6,61846;19,36908
13,52000;6,61977;19,19665
13,56000;6,62115;20,17228
13,60000;6,62252;19,41535
13,64000;6,62378;19,46924
13,68000;6,62503;19,40460
13,72000;6,62647;19,90043
13,76000;6,62779;20,42065
13,80000;6,62916;19,52364
13,84000;6,63042;19,81606
13,88000;6,63173;20,35688
13,92000;6,63275;19,89156
13,96000;6,63442;19,45788
14,00000;6,63568;19,82304
14,04000;6,63705;19,77444
14,08000;6,63837;19,63738
14,12000;6,63974;19,15667
14,16000;6,64106;19,28151
14,20000;6,64243;19,41014
14,24000;6,64381;19,58355
14,28000;6,64500;19,24747
14,32000;6,64638;19,50846
14,36000;6,64781;19,08285
14,40000;6,64913;18,82270
14,44000;6,65050;19,36249
14,48000;6,65176;19,15491
14,52000;6,65314;19,07397
14,56000;6,65451;18,37377
14,60000;6,65571;18,72818
14,64000;6,65702;18,63784
14,68000;6,65846;19,43349
14,72000;6,65977;19,89288
14,76000;6,66115;19,78151
14,80000;6,66246;19,40850
14,84000;6,66384;19,44774
14,88000;6,66515;19,00133
14,92000;6,66635;18,74994
14,96000;6,66743;18,64388
15,00000;6,66922;19,80629
15,04000;6,67053;18,17649
15,08000;6,67185;18,34737
15,12000;6,67322;18,51192
15,16000;6,67454;18,92049
15,20000;6,67580;18,34627
15,24000;6,67705;19,12927
15,28000;6,67849;18,45282
15,32000;6,67974;18,69050
15,36000;6,68106;18,05331
15,40000;6,68243;19,56276
15,44000;6,68381;18,68095
15,48000;6,68518;17,94508
15,52000;6,68638;17,81375
15,56000;6,68763;18,30091
15,60000;6,68913;18,41867
15,64000;6,69044;18,54487
15,68000;6,69176;19,29350
15,72000;6,69313;18,61497
15,76000;6,69445;18,17044
15,80000;6,69583;18,25669
15,84000;6,69708;17,68642
15,88000;6,69840;17,59955
15,92000;6,69983;17,89964
15,96000;6,70115;18,17507
16,00000;6,70246;17,61520
16,04000;6,70378;17,24020
16,08000;6,70515;17,34557
16,12000;6,70653;16,96362
16,16000;6,70772;17,08050
16,20000;6,70904;16,97716
16,24000;6,71041;17,21324
16,28000;6,71173;16,83036
16,32000;6,71310;17,05274
16,36000;6,71448;16,85061
16,40000;6,71580;16,62032
16,44000;6,71717;16,55829
16,48000;6,71837;15,98028
16,52000;6,71974;15,55954
16,56000;6,72118;15,77675
16,60000;6,72249;16,31353
16,64000;6,72387;15,78358
16,68000;6,72518;14,99955
16,72000;6,72650;15,19412
16,76000;6,72781;15,23327
16,80000;6,72907;15,25545
16,84000;6,73044;14,68329
16,88000;6,73182;15,46367
16,92000;6,73313;15,67185
16,96000;6,73445;15,38280
17,00000;6,73582;14,90635
17,04000;6,73714;14,85298
17,08000;6,73846;14,38426
17,12000;6,73971;14,37992
17,16000;6,74109;14,05257
17,20000;6,74246;13,88574
17,24000;6,74384;14,20057
17,28000;6,74521;13,60172
17,32000;6,74653;13,10578
17,36000;6,74784;13,25899
17,40000;6,74910;13,24156
17,44000;6,75035;12,27266
17,48000;6,75179;12,56535
17,52000;6,75310;12,08997
17,56000;6,75442;12,49768
17,60000;6,75579;12,37458
17,64000;6,75717;11,68097
17,68000;6,75848;10,85324
17,72000;6,75974;10,92989
17,76000;6,76100;10,34750
17,80000;6,76237;10,57822
17,84000;6,76375;10,03283
17,88000;6,76512;9,14563
17,92000;6,76644;9,24865
17,96000;6,76781;8,11915
18,00000;6,76919;8,09924
18,04000;6,77044;7,04593
18,08000;6,77170;6,65017
18,12000;6,77307;6,37968
18,16000;6,77439;6,20777
18,20000;6,77576;5,71332
18,24000;6,77714;5,29019
18,28000;6,77845;4,80504
18,32000;6,77983;4,15593
18,36000;6,78102;3,29672
18,40000;6,78240;3,38818
18,44000;6,78378;3,54316
18,48000;6,78515;2,24049
18,52000;6,78653;1,71972
18,56000;6,78784;1,96122
18,60000;6,78922;1,83317
18,64000;6,79047;2,07695
18,68000;6,79173;2,16991
18,72000;6,79316;1,78847
18,76000;6,79448;2,40768
18,80000;6,79579;1,98379
18,84000;6,79717;0,54142
18,88000;6,79848;1,58727
18,92000;6,79980;1,17858
18,96000;6,80105;1,74788
19,00000;6,80231;1,19998
19,04000;6,80375;0,46288
19,08000;6,80506;1,37591
19,12000;6,80644;1,40537
19,16000;6,80775;1,32350
19,20000;6,80907;0,90198
19,24000;6,81044;0,77264
19,28000;6,81170;0,14412
19,32000;6,81295;0,81622
19,36000;6,81439;0,80716
19,40000;6,81576;0,98111
19,44000;6,81714;0,94644
19,48000;6,81845;0,31457
19,52000;6,81983;0,29971
19,56000;6,82114;0,41654
19,60000;6,82240;0,91314
19,64000;6,82365;0,73004
19,68000;6,82515;0,27336
19,72000;6,82647;0,73143
19,76000;6,82778;0,19311
19,80000;6,82910;0,98030
19,84000;6,83041;0,35915
19,88000;6,83179;0,61189
19,92000;6,83298;0,66976
19,96000;6,83430;0,02658
20,00000;6,83579;0,48835
20,04000;6,83717;0,43882
20,08000;6,83848;1,10279
20,12000;6,83986;0,40388
20,16000;6,84123;0,19955
20,20000;6,84255;0,29033
20,24000;6,84368;0,62075
20,28000;6,84506;0,18476
20,32000;6,84643;0,62875
20,36000;6,84781;1,20316
20,40000;6,84913;0,97300
20,44000;6,85044;0,27510
20,48000;6,85188;0,49963
20,52000;6,85313;0,34417
20,56000;6,85433;0,22381
20,60000;6,85570;0,95474
20,64000;6,85708;0,68259
20,68000;6,85839;0,40555
20,72000;6,85977;0,49966
20,76000;6,86108;0,68254
20,80000;6,86252;0,91270
20,84000;6,86377;0,39345
20,88000;6,86497;0,88753
20,92000;6,86646;0,38821
20,96000;6,86778;0,18567
21,00000;6,86910;0,59705
21,04000;6,87047;-0,07478
21,08000;6,87185;0,61453
21,12000;6,87322;0,27518
21,16000;6,87442;0,06357
21,20000;6,87573;0,68068
21,24000;6,87717;0,60706
21,28000;6,87848;0,86097
21,32000;6,87980;0,80939
21,36000;6,88111;0,65189
21,40000;6,88243;0,05838
21,44000;6,88380;0,80804
21,48000;6,88506;0,73582
21,52000;6,88643;0,10654
21,56000;6,88787;1,02809
21,60000;6,88918;0,15604
21,64000;6,89050;0,02024
21,68000;6,89187;0,47471
21,72000;6,89325;0,60601
21,76000;6,89457;0,23843
21,80000;6,89576;0,53327
21,84000;6,89714;1,12693
21,88000;6,89851;0,85505
21,92000;6,89983;0,29205
21,96000;6,90114;0,61916
22,00000;6,90252;0,76578
22,04000;6,90389;0,02905
22,08000;6,90515;-0,49901
22,12000;6,90640;0,30840
22,16000;6,90766;0,17379
22,20000;6,90909;0,33322
22,24000;6,91041;0,44849
22,28000;6,91178;0,59247
22,32000;6,91316;1,12707
22,36000;6,91442;0,43816
22,40000;6,91585;0,97883
22,44000;6,91705;0,34527
22,48000;6,91842;0,62611
22,52000;6,91980;-0,04366
22,56000;6,92117;0,36983
22,60000;6,92255;0,70174
22,64000;6,92386;0,52877
22,68000;6,92518;0,26869
22,72000;6,92649;0,64124
22,76000;6,92769;0,98047
22,80000;6,92906;0,08502
22,84000;6,93038;0,73870
22,88000;6,93175;0,82337
22,92000;6,93313;0,47530
22,96000;6,93450;0,52176
23,00000;6,93588;0,11435
23,04000;6,93714;0,73993
23,08000;6,93839;0,58882
23,12000;6,93977;0,35891
23,16000;6,94108;0,06673
23,20000;6,94258;0,49733
23,24000;6,94389;-0,22094
23,28000;6,94521;-0,33789
23,32000;6,94652;-0,19354
23,36000;6,94778;0,52412
23,40000;6,94909;0,85891
23,44000;6,95047;0,57722
23,48000;6,95178;0,71535
23,52000;6,95310;0,43720
23,56000;6,95441;0,62503
23,60000;6,95579;0,80498
23,64000;6,95717;0,25508
23,68000;6,95842;0,23752
23,72000;6,95974;0,93128
23,76000;6,96111;0,81049
23,80000;6,96243;0,74250
23,84000;6,96380;0,98174
23,88000;6,96512;-0,11040
23,92000;6,96643;0,71929
23,96000;6,96781;0,69596
24,00000;6,96906;0,01431
24,04000;6,97044;0,46749
24,08000;6,97181;0,47079
24,12000;6,97313;0,87789
24,16000;6,97444;0,82351
24,20000;6,97582;0,65125
24,24000;6,97713;0,77682
24,28000;6,97845;0,19314
24,32000;6,97971;0,36052
24,36000;6,98108;0,39595
24,40000;6,98246;1,08949
24,44000;6,98383;0,61098
24,48000;6,98521;0,41563
24,52000;6,98652;0,21253
24,56000;6,98790;0,14180
24,60000;6,98915;-0,30014
24,64000;6,99035;0,01821
24,68000;6,99178;0,67512
24,72000;6,99304;0,88073
24,76000;6,99447;0,43377
24,80000;6,99585;-0,11030
24,84000;6,99716;1,00299
24,88000;6,99854;0,96997
24,92000;6,99973;-0,08795
24,96000;7,00099;0,08025
25,00000;7,00243;0,69243
25,04000;7,00380;0,22442
25,08000;7,00512;1,20341
25,12000;7,00649;0,89270
25,16000;7,00787;0,07486
25,20000;7,00918;-0,52002
25,24000;7,01038;0,49403
25,28000;7,01175;0,67113
25,32000;7,01313;0,77379
25,36000;7,01444;0,71721
25,40000;7,01582;0,59558
25,44000;7,01713;0,93537
25,48000;7,01851;1,08521
25,52000;7,01982;-0,21695
25,56000;7,02102;0,51555
25,60000;7,02240;0,54573
25,64000;7,02377;0,12720
25,68000;7,02509;0,05023
25,72000;7,02640;0,42944
25,76000;7,02778;0,64457
25,80000;7,02915;0,45593
25,84000;7,03047;0,18623
25,88000;7,03172;1,00358
25,92000;7,03310;0,54874
25,96000;7,03447;1,22630
26,00000;7,03579;1,26608
26,04000;7,03716;0,64873
26,08000;7,03848;1,37763
26,12000;7,03979;0,68029
26,16000;7,04105;0,42276
26,20000;7,04237;0,93493
26,24000;7,04380;0,05809
26,28000;7,04512;0,78544
26,32000;7,04643;0,98277
26,36000;7,04775;0,51944
26,40000;7,04906;0,50994
26,44000;7,05044;0,85446
26,48000;7,05169;1,23413
26,52000;7,05301;0,18273
26,56000;7,05444;0,17597
26,60000;7,05582;0,66271
26,64000;7,05719;0,35531
26,68000;7,05851;0,41213
26,72000;7,05982;0,45336
26,76000;7,06120;0,57783
26,80000;7,06239;0,14451
26,84000;7,06365;0,16696
26,88000;7,06509;0,50353
26,92000;7,06646;1,13745
26,96000;7,06783;-0,24175
27,00000;7,06915;-0,02956
27,04000;7,07047;1,01058
27,08000;7,07184;0,41216
27,12000;7,07304;0,87931
27,16000;7,07435;0,81159
27,20000;7,07573;0,45505
27,24000;7,07710;-0,00170
27,28000;7,07848;0,84232
27,32000;7,07979;0,74103
27,36000;7,08117;0,60890
27,40000;7,08254;1,12913
27,44000;7,08374;0,58966
27,48000;7,08506;0,90690
27,52000;7,08649;0,42440
27,56000;7,08780;0,38283
27,60000;7,08912;0,29628
27,64000;7,09050;0,81631
27,68000;7,09187;0,50712
27,72000;7,09319;0,38079
27,76000;7,09438;0,27780
27,80000;7,09576;0,58003
27,84000;7,09713;0,32622
27,88000;7,09845;0,86628
27,92000;7,09982;1,06168
27,96000;7,10114;0,61595
28,00000;7,10257;-0,15410
28,04000;7,10383;-0,08398
28,08000;7,10508;0,50020
28,12000;7,10628;0,18628
28,16000;7,10789;0,05968
28,20000;7,10915;-0,34932
28,24000;7,11047;0,09594
28,28000;7,11184;0,51863
28,32000;7,11322;-0,03176
28,36000;7,11441;0,49381
28,40000;7,11573;0,44535
28,44000;7,11710;0,56907
28,48000;7,11842;0,84574
28,52000;7,11973;0,75092
28,56000;7,12111;0,14539
28,60000;7,12248;1,07943
28,64000;7,12386;0,61801
28,68000;7,12511;0,28083
28,72000;7,12637;0,39644
28,76000;7,12786;0,80611
28,80000;7,12918;0,80170
28,84000;7,13049;0,75775
28,88000;7,13181;0,05990
28,92000;7,13319;-0,07975
28,96000;7,13450;0,11966
29,00000;7,13570;0,54551
29,04000;7,13683;0,26357
29,08000;7,13851;-0,22946
29,12000;7,13982;0,17962
29,16000;7,14114;0,79396
29,20000;7,14251;0,55842
29,24000;7,14389;0,63128
29,28000;7,14514;0,24624
29,32000;7,14640;0,87064
29,36000;7,14777;0,62609
29,40000;7,14915;0,48937
29,44000;7,15046;0,62574
29,48000;7,15184;0,47929
29,52000;7,15316;0,66215
29,56000;7,15453;0,16422
29,60000;7,15585;-0,19898
29,64000;7,15698;0,52000
29,68000;7,15836;0,66318
29,72000;7,15979;0,21150
29,76000;7,16099;0,91072
29,80000;7,16248;0,86415
29,84000;7,16386;0,05243
29,88000;7,16517;0,78192
29,92000;7,16643;0,54037
29,96000;7,16768;0,47126
30,00000;7,16912;1,43891
30,04000;7,17049;0,45799
30,08000;7,17181;0,89696
30,12000;7,17318;0,18359
30,16000;7,17456;0,32005
30,20000;7,17588;0,68773
30,24000;7,17713;0,83064
30,28000;7,17839;0,51146
30,32000;7,17982;0,50649
30,36000;7,18108;0,55477
30,40000;7,18245;0,61798
30,44000;7,18377;1,04280
30,48000;7,18496;0,84569
30,52000;7,18652;0,15066
30,56000;7,18771;0,49437
30,60000;7,18903;0,75697
30,64000;7,19040;0,94213
30,68000;7,19172;-0,24371
30,72000;7,19309;0,69243
30,76000;7,19447;0,60985
30,80000;7,19584;0,71388
30,84000;7,19716;0,86266
30,88000;7,19842;0,04663
30,92000;7,19973;0,71995
30,96000;7,20111;0,25194
31,00000;7,20242;0,96921
31,04000;7,20380;-0,06097
31,08000;7,20511;1,05301
31,12000;7,20643;0,54997
31,16000;7,20780;0,21982
31,20000;7,20900;0,39157
31,24000;7,21031;0,19201
31,28000;7,21175;0,56037
31,32000;7,21306;0,23449
31,36000;7,21438;1,07323
31,40000;7,21575;0,12784
31,44000;7,21713;0,39017
31,48000;7,21844;0,34245
31,52000;7,21964;0,13964
31,56000;7,22114;-0,04141
31,60000;7,22251;0,53315
31,64000;7,22389;0,31589
31,68000;7,22520;-0,20008
31,72000;7,22652;-0,18622
31,76000;7,22783;1,51101
31,80000;7,22909;0,19877
31,84000;7,23034;0,10534
31,88000;7,23178;-0,38563
31,92000;7,23309;0,40623
31,96000;7,23441;0,43453
32,00000;7,23578;0,99310
32,04000;7,23710;1,06391
32,08000;7,23847;0,81132
32,12000;7,23973;1,07262
32,16000;7,24099;1,40387
32,20000;7,24242;0,59007
32,24000;7,24374;0,27557
32,28000;7,24511;0,11261
32,32000;7,24649;0,65855
32,36000;7,24780;0,16740
32,40000;7,24918;0,16026
32,44000;7,25037;0,58471
32,48000;7,25169;0,60270
32,52000;7,25306;0,06972
32,56000;7,25438;0,10253
32,60000;7,25581;0,25912
32,64000;7,25707;0,92972
32,68000;7,25844;0,57394
32,72000;7,25976;0,78755
32,76000;7,26102;1,17117
32,80000;7,26239;0,05283
32,84000;7,26377;0,45047
32,88000;7,26508;0,89238
32,92000;7,26646;0,48088
32,96000;7,26777;0,37460
33,00000;7,26915;1,38862
33,04000;7,27052;-0,07524
33,08000;7,27172;0,71471
33,12000;7,27309;0,64756
33,16000;7,27447;0,51932
33,20000;7,27578;-0,07375
33,24000;7,27710;0,62393
33,28000;7,27847;0,77435
33,32000;7,27985;0,61774
33,36000;7,28116;0,17622
33,40000;7,28236;1,20057
33,44000;7,28374;0,60645
33,48000;7,28511;0,74681
33,52000;7,28649;0,33606
33,56000;7,28780;0,91535
33,60000;7,28912;0,28568
33,64000;7,29049;0,33048
33,68000;7,29175;0,66428
33,72000;7,29300;0,77416
33,76000;7,29444;0,13303
33,80000;7,29581;0,69708
33,84000;7,29713;1,10714
33,88000;7,29844;0,32713
33,92000;7,29982;0,98838
33,96000;7,30119;0,83473
34,00000;7,30239;0,69615
34,04000;7,30365;0,28345
34,08000;7,30514;1,13415
34,12000;7,30640;0,70810
34,16000;7,30777;0,23713
34,20000;7,30909;0,73256
34,24000;7,31046;0,82513
34,28000;7,31184;0,09356
34,32000;7,31303;0,83132
34,36000;7,31441;0,54990
34,40000;7,31584;0,98488
34,44000;7,31716;-0,05776
34,48000;7,31853;0,94039
34,52000;7,31985;-0,05960
34,56000;7,32116;0,44232
34,60000;7,32254;0,51775
34,64000;7,32373;1,08773
34,68000;7,32505;0,59051
34,72000;7,32648;0,18173
34,76000;7,32780;0,63722
34,80000;7,32912;0,96074
34,84000;7,33049;0,22976
34,88000;7,33187;-0,11370
34,92000;7,33318;0,20516
34,96000;7,33438;0,24842
35,00000;7,33575;0,98196
35,04000;7,33713;0,66942
35,08000;7,33844;0,32240
35,12000;7,33982;1,32599
35,16000;7,34119;0,65652
35,20000;7,34251;-0,02003
35,24000;7,34382;0,00242
35,28000;7,34502;0,70014
35,32000;7,34645;0,31224
35,36000;7,34777;1,03294
35,40000;7,34909;0,33584
35,44000;7,35046;0,46614
35,48000;7,35178;0,51246
35,52000;7,35315;0,31550
35,56000;7,35447;0,77362
35,60000;7,35566;1,21122
35,64000;7,35710;0,53790
35,68000;7,35841;-0,05037
35,72000;7,35979;1,04829
35,76000;7,36116;0,90012
35,80000;7,36248;0,57115
35,84000;7,36385;1,32102
35,88000;7,36517;1,14766
35,92000;7,36642;1,16167
35,96000;7,36780;0,59220
36,00000;7,36911;0,68531
36,04000;7,37049;0,81754
36,08000;7,37181;0,51102
36,12000;7,37318;-0,11189
36,16000;7,37450;0,57399
36,20000;7,37575;0,61103
36,24000;7,37701;0,54735
36,28000;7,37844;0,14547
36,32000;7,37982;0,85495
36,36000;7,38113;0,32120
36,40000;7,38251;0,70225
36,44000;7,38382;0,10850
36,48000;7,38520;1,06425
36,52000;7,38645;-0,09292
36,56000;7,38777;0,61717
36,60000;7,38914;0,93288
36,64000;7,39052;0,19522
36,68000;7,39184;0,42712
36,72000;7,39315;-0,04594
36,76000;7,39447;0,29236
36,80000;7,39584;0,56458
36,84000;7,39704;0,43571
36,88000;7,39835;0,40229
36,92000;7,39979;0,42805
36,96000;7,40110;1,23783
37,00000;7,40248;1,23007
37,04000;7,40379;0,36466
37,08000;7,40517;1,05514
37,12000;7,40648;1,03171
37,16000;7,40768;-0,09478
37,20000;7,40905;0,58300
37,24000;7,41049;0,73374
37,28000;7,41180;0,81482
37,32000;7,41318;0,58202
37,36000;7,41455;0,51569
37,40000;7,41587;0,46923
37,44000;7,41713;0,07511
37,48000;7,41838;0,47111
37,52000;7,41976;0,45042
37,56000;7,42113;0,81678
37,60000;7,42245;0,99984
37,64000;7,42382;0,63005
37,68000;7,42514;1,04988
37,72000;7,42651;0,40435
37,76000;7,42777;0,42202
37,80000;7,42902;1,05233
37,84000;7,43040;0,81700
37,88000;7,43171;0,65561
37,92000;7,43309;0,82760
37,96000;7,43440;0,51785
38,00000;7,43578;0,81335
38,04000;7,43716;0,56801
38,08000;7,43841;0,00927
38,12000;7,43967;0,17301
38,16000;7,44116;0,78094
38,20000;7,44248;0,17827
38,24000;7,44385;0,26259
38,28000;7,44517;1,26469
38,32000;7,44648;0,39744
38,36000;7,44780;0,24538
38,40000;7,44905;0,90942
38,44000;7,45043;0,25772
38,48000;7,45180;0,32152
38,52000;7,45312;0,53596
38,56000;7,45449;0,15504
38,60000;7,45581;0,09969
38,64000;7,45712;1,06244
38,68000;7,45850;0,05811
38,72000;7,45970;-0,43193
38,76000;7,46107;0,33244
38,80000;7,46245;0,55971
38,84000;7,46376;0,08098
38,88000;7,46514;0,08580
38,92000;7,46645;1,02576
38,96000;7,46783;1,03032
39,00000;7,46914;-0,11534
39,04000;7,47034;0,73547
39,08000;7,47177;0,71672
39,12000;7,47315;0,73684
39,16000;7,47446;0,09978
39,20000;7,47578;0,58273
39,24000;7,47715;1,44018
39,28000;7,47847;1,01874
39,32000;7,47973;1,32276
39,36000;7,48098;1,05693
39,40000;7,48242;0,11746
39,44000;7,48373;0,13866
39,48000;7,48511;0,80407
39,52000;7,48642;0,27158
39,56000;7,48774;0,79244
39,60000;7,48911;0,92389
39,64000;7,49043;0,78407
39,68000;7,49174;0,64305
39,72000;7,49312;0,90925
39,76000;7,49449;0,35467
39,80000;7,49587;1,01668
39,84000;7,49718;-0,00008
39,88000;7,49856;-0,10656
39,92000;7,49993;0,30553
39,96000;7,50107;0,60021
40,00000;7,50233;0,56363
40,04000;7,50376;0,55545
40,08000;7,50514;0,52035
40,12000;7,50645;0,67152
40,16000;7,50783;1,26043
40,20000;7,50920;0,17531
40,24000;7,51052;0,30154
40,28000;7,51171;0,64888
40,32000;7,51309;0,44731
40,36000;7,51446;0,85590
40,40000;7,51578;-0,07199
40,44000;7,51715;0,54799
40,48000;7,51847;0,84841
40,52000;7,51990;0,54096
40,56000;7,52122;0,29763
40,60000;7,52242;-0,34511
40,64000;7,52373;0,21701
40,68000;7,52511;0,61450
40,72000;7,52642;0,85110
40,76000;7,52774;0,84751
40,80000;7,52905;0,39502
40,84000;7,53049;0,26742
40,88000;7,53174;0,17896
40,92000;7,53294;0,18471
40,96000;7,53437;0,24193
41,00000;7,53581;0,94926
41,04000;7,53712;0,48203
41,08000;7,53844;1,19922
41,12000;7,53981;1,23014
41,16000;7,54119;1,35983
41,20000;7,54238;0,44075
41,24000;7,54376;0,59051
41,28000;7,54519;0,76108
41,32000;7,54651;0,35881
41,36000;7,54783;0,16924
41,40000;7,54914;0,76123
41,44000;7,55052;0,57472
41,48000;7,55189;0,83176
41,52000;7,55309;0,33085
41,56000;7,55440;0,49846
41,60000;7,55584;0,23500
41,64000;7,55709;0,58549
41,68000;7,55847;0,72360
41,72000;7,55984;0,64944
41,76000;7,56122;0,71985
41,80000;7,56253;0,45892
41,84000;7,56373;0,32818
41,88000;7,56504;-0,29855
41,92000;7,56648;0,46869
41,96000;7,56780;0,75357
42,00000;7,56917;1,04684
42,04000;7,57049;0,45052
42,08000;7,57186;0,51080
42,12000;7,57312;0,24237
42,16000;7,57437;0,86004
42,20000;7,57569;0,49824
42,24000;7,57706;0,56799
42,28000;7,57844;0,59717
42,32000;7,57975;0,27141
42,36000;7,58107;0,04830
42,40000;7,58244;0,84971
42,44000;7,58376;0,36356
42,48000;7,58501;0,20161
42,52000;7,58639;0,51785
42,56000;7,58776;1,18514
42,60000;7,58914;0,66031
42,64000;7,59046;0,74235
42,68000;7,59183;0,30267
42,72000;7,59321;-0,27691
42,76000;7,59446;0,39651
42,80000;7,59572;0,38094
42,84000;7,59709;0,53949
42,88000;7,59847;0,32896
42,92000;7,59978;0,23307
42,96000;7,60116;1,03673
43,00000;7,60247;0,88362
43,04000;7,60385;0,08020
43,08000;7,60510;0,58510
43,12000;7,60636;0,83499
43,16000;7,60779;0,49427
43,20000;7,60917;0,72135
43,24000;7,61048;0,06120
43,28000;7,61186;-0,09679
43,32000;7,61318;0,29606
43,36000;7,61455;-0,01014
43,40000;7,61581;-0,29355
43,44000;7,61712;0,25260
43,48000;7,61850;0,67094
43,52000;7,61981;0,33203
43,56000;7,62113;0,51944
43,60000;7,62244;0,75773
43,64000;7,62376;0,87446
43,68000;7,62513;1,23930
43,72000;7,62639;0,93334
43,76000;7,62770;0,31161
43,80000;7,62908;0,26418
43,84000;7,63045;0,43843
43,88000;7,63177;0,52115
43,92000;7,63315;0,50338
43,96000;7,63452;0,40604
44,00000;7,63584;0,20631
44,04000;7,63703;0,47961
44,08000;7,63835;0,26350
44,12000;7,63978;0,49376
44,16000;7,64110;0,56319
44,20000;7,64247;0,07004
44,24000;7,64379;0,75156
44,28000;7,64516;0,73662
44,32000;7,64648;0,41453
44,36000;7,64767;0,84826
44,40000;7,64905;0,27180
44,44000;7,65042;0,77673
44,48000;7,65180;0,93831
44,52000;7,65317;0,29339
44,56000;7,65449;0,26622
44,60000;7,65587;0,44717
44,64000;7,65712;0,46550
44,68000;7,65838;0,93711
44,72000;7,65981;0,87402
44,76000;7,66113;0,46080
44,80000;7,66250;0,81911
44,84000;7,66382;0,35744
44,88000;7,66519;-0,35919
44,92000;7,66657;0,26306
44,96000;7,66776;0,05919
45,00000;7,66902;0,81891
45,04000;7,67045;0,53440
45,08000;7,67177;1,42145
45,12000;7,67291;0,80182
45,16000;7,67452;0,63279
45,20000;7,67583;0,61328
45,24000;7,67721;-0,00429
45,28000;7,67841;0,35296
45,32000;7,67972;0,47691
45,36000;7,68110;0,39649
45,40000;7,68241;0,53690
45,44000;7,68379;0,77729
45,48000;7,68510;0,11939
45,52000;7,68648;0,65715
45,56000;7,68779;0,59051
45,60000;7,68905;0,59950
45,64000;7,69036;0,57528
45,68000;7,69180;1,29867
45,72000;7,69311;1,09529
45,76000;7,69443;0,45321
45,80000;7,69580;0,87206
45,84000;7,69700;0,68357
45,88000;7,69850;0,65862
45,92000;7,69975;0,37813
45,96000;7,70113;0,54906
46,00000;7,70250;0,22954
46,04000;7,70382;0,63299
46,08000;7,70519;0,47968
46,12000;7,70651;0,94908
46,16000;7,70788;0,76848
46,20000;7,70914;0,48291
46,24000;7,71033;0,25094
46,28000;7,71177;0,49314
46,32000;7,71314;0,04372
46,36000;7,71452;0,50198
46,40000;7,71583;0,79345
46,44000;7,71715;0,23040
46,48000;7,71852;0,01010
46,52000;7,71978;0,79208
46,56000;7,72092;0,72392
46,60000;7,72247;0,41615
46,64000;7,72385;0,55976
46,68000;7,72516;0,47285
46,72000;7,72648;0,46323
46,76000;7,72779;0,33298
46,80000;7,72917;0,47035
46,84000;7,73042;0,47444
46,88000;7,73168;0,42973
46,92000;7,73305;0,13788
46,96000;7,73443;0,98191
47,00000;7,73574;1,19770
47,04000;7,73712;0,23625
47,08000;7,73849;0,27601
47,12000;7,73987;1,01849
47,16000;7,74106;-0,03512
47,20000;7,74232;0,86011
47,24000;7,74382;0,61776
47,28000;7,74519;0,57979
47,32000;7,74651;0,14339
47,36000;7,74782;0,10845
47,40000;7,74920;0,41475
47,44000;7,75051;1,14245
47,48000;7,75165;0,31114
47,52000;7,75302;0,02837
47,56000;7,75446;0,46215
47,60000;7,75577;1,14073
47,64000;7,75709;0,74147
47,68000;7,75840;0,79528
47,72000;7,75978;1,48413
47,76000;7,76109;0,89321
47,80000;7,76235;0,45471
47,84000;7,76373;0,37849
47,88000;7,76510;0,88922
47,92000;7,76642;1,03428
47,96000;7,76779;0,66856
48,00000;7,76917;0,90798
48,04000;7,77054;0,16762
48,08000;7,77168;-0,16074
48,12000;7,77317;0,21407
48,16000;7,77455;0,16158
48,20000;7,77580;0,03251
48,24000;7,77712;0,42036
48,28000;7,77843;0,93868
48,32000;7,77981;0,81986
48,36000;7,78118;0,44413
48,40000;7,78238;0,74909
48,44000;7,78364;-0,19690
48,48000;7,78507;0,26076
48,52000;7,78645;0,70191
48,56000;7,78776;0,49976
48,60000;7,78914;0,07028
48,64000;7,79051;1,05321
48,68000;7,79189;0,84471
48,69000;7,79219;0,65806