File: SU - Suspension/05 - Essais/Excels essais Optimus/Collage_alu_alu_31_01_19/collage2.is_tens_RawData/Specimen_RawData_1.csv
Temps;Déplacement;Charge
(sec);(mm);(N)
0,00000;-37,17891;53,92181
0,06000;-37,17753;55,57497
0,12000;-37,17293;79,58698
0,18000;-37,16731;115,55882
0,24000;-37,16139;154,42558
0,30000;-37,15583;190,38302
0,36000;-37,15039;226,95973
0,42000;-37,14513;261,48574
0,48000;-37,13986;296,72333
0,54000;-37,13484;330,96706
0,60000;-37,12976;364,66981
0,66000;-37,12474;398,11162
0,72000;-37,11966;431,62000
0,78000;-37,11469;463,00418
0,84000;-37,10961;490,22310
0,90000;-37,10471;510,02922
0,96000;-37,09963;524,06518
1,02000;-37,09466;536,54625
1,08000;-37,08964;548,13670
1,14000;-37,08474;559,73497
1,20000;-37,07965;571,75122
1,26000;-37,07469;582,18013
1,32000;-37,06961;593,52503
1,38000;-37,06471;604,34896
1,44000;-37,05957;613,86544
1,50000;-37,05466;623,46202
1,56000;-37,04964;631,69179
1,62000;-37,04468;641,36740
1,68000;-37,03966;651,29516
1,74000;-37,03463;660,48526
1,80000;-37,02967;667,99759
1,86000;-37,02459;676,25428
1,92000;-37,01963;683,50569
1,98000;-37,01460;690,51692
2,04000;-37,00970;697,18179
2,10000;-37,00462;702,13960
2,16000;-36,99966;707,60311
2,22000;-36,99458;712,17655
2,28000;-36,98967;715,51315
2,34000;-36,98465;717,33035
2,40000;-36,97969;718,76827
2,46000;-36,97461;720,40074
2,52000;-36,96964;720,97746
2,58000;-36,96468;720,25475
2,64000;-36,95966;728,01979
2,70000;-36,95464;749,92073
2,76000;-36,94961;775,45145
2,82000;-36,94465;798,26145
2,88000;-36,93969;820,30389
2,94000;-36,93460;842,87329
3,00000;-36,92964;863,79359
3,06000;-36,92462;883,06414
3,12000;-36,91966;901,89558
3,18000;-36,91475;921,46546
3,24000;-36,90967;941,02668
3,30000;-36,90477;960,40089
3,36000;-36,89969;981,49795
3,42000;-36,89473;1001,08199
3,48000;-36,88971;1020,57783
3,54000;-36,88468;1040,33118
3,60000;-36,87972;1061,06335
3,66000;-36,87470;1081,29587
3,72000;-36,86973;1099,76092
3,78000;-36,86471;1119,76238
3,84000;-36,85969;1138,12983
3,90000;-36,85473;1158,62163
3,96000;-36,84970;1176,43997
4,02000;-36,84474;1195,24002
4,08000;-36,83966;1213,84375
4,14000;-36,83476;1232,73125
4,20000;-36,82968;1250,26675
4,26000;-36,82471;1269,02806
4,32000;-36,81969;1285,98604
4,38000;-36,81467;1304,11042
4,44000;-36,80976;1320,56875
4,50000;-36,80468;1337,87561
4,56000;-36,79972;1353,05068
4,62000;-36,79470;1369,73113
4,68000;-36,78974;1384,54838
4,74000;-36,78465;1399,66644
4,80000;-36,77963;1415,73464
4,86000;-36,77467;1430,76871
4,92000;-36,76965;1445,70861
4,98000;-36,76474;1459,71011
5,04000;-36,75978;1475,50954
5,10000;-36,75476;1490,93196
5,16000;-36,74980;1505,46739
5,22000;-36,74465;1519,97795
5,28000;-36,73975;1533,69932
5,34000;-36,73467;1550,01003
5,40000;-36,72965;1563,57232
5,46000;-36,72463;1575,75291
5,52000;-36,71960;1590,04144
5,58000;-36,71464;1601,26220
5,64000;-36,70968;1614,69169
5,70000;-36,70465;1626,20842
5,76000;-36,69957;1638,65257
5,82000;-36,69461;1649,37861
5,88000;-36,68959;1661,82909
5,94000;-36,68462;1672,55756
6,00000;-36,67960;1681,71693
6,06000;-36,67458;1690,21226
6,12000;-36,66956;1699,95278
6,18000;-36,66472;1705,35464
6,24000;-36,65958;1714,10162
6,30000;-36,65479;1720,25431
6,36000;-36,64959;1728,05414
6,42000;-36,64463;1732,12700
6,48000;-36,63966;1736,72829
6,54000;-36,63464;1741,53727
6,60000;-36,62962;1744,41766
6,66000;-36,62460;1748,18654
6,72000;-36,61964;1751,02111
6,78000;-36,61467;1753,82625
6,84000;-36,60959;1756,66343
6,90000;-36,60463;1758,72017
6,96000;-36,59961;1759,63435
7,02000;-36,59470;1759,64609
7,08000;-36,58962;1759,56599
7,14000;-36,58466;1759,06867
7,20000;-36,57963;1758,80622
7,26000;-36,57467;1758,54266
7,32000;-36,56971;1757,75699
7,38000;-36,56457;1757,22577
7,44000;-36,55973;1754,29191
7,50000;-36,55464;1754,22430
7,56000;-36,54968;1751,41059
7,62000;-36,54508;1749,92196
7,68000;-36,53958;1751,21240
7,74000;-36,53467;1746,40715
7,80000;-36,52965;1743,86296
7,86000;-36,52469;1741,25861
7,92000;-36,51973;1738,50395
7,98000;-36,51464;1736,16167
8,04000;-36,50974;1733,49958
8,10000;-36,50460;1734,72036
8,16000;-36,49970;1730,01867
8,22000;-36,49468;1727,40519
8,28000;-36,48971;1724,99157
8,34000;-36,48469;1721,84408
8,40000;-36,47961;1721,18563
8,46000;-36,47470;1718,54440
8,52000;-36,46962;1717,38621
8,58000;-36,46460;1715,35350
8,64000;-36,45970;1712,86352
8,70000;-36,45462;1710,44674
8,76000;-36,44965;1707,25659
8,82000;-36,44445;1707,32141
8,88000;-36,43955;1704,43263
8,94000;-36,43465;1699,71325
9,00000;-36,42962;1695,94903
9,06000;-36,42472;1693,07962
9,12000;-36,41958;1692,80954
9,18000;-36,41468;1691,09702
9,24000;-36,40965;1686,87534
9,30000;-36,40475;1682,78515
9,36000;-36,39967;1682,28839
9,42000;-36,39471;1679,77978
9,48000;-36,38957;1678,41595
9,54000;-36,38472;1675,54226
9,60000;-36,37976;1672,43555
9,66000;-36,37474;1669,98561
9,72000;-36,36971;1667,56213
9,78000;-36,36469;1670,19647
9,84000;-36,35973;1678,14288
9,90000;-36,35471;1690,21040
9,96000;-36,34968;1704,31025
10,02000;-36,34472;1719,41333
10,08000;-36,33964;1734,62816
10,14000;-36,33462;1749,79195
10,20000;-36,32978;1763,05715
10,26000;-36,32469;1778,12874
10,32000;-36,31979;1792,45342
10,38000;-36,31471;1807,71481
10,44000;-36,30974;1821,58649
10,50000;-36,30466;1834,96177
10,56000;-36,29964;1850,04175
10,62000;-36,29468;1863,66625
10,68000;-36,28966;1878,42511
10,74000;-36,28470;1890,71409
10,80000;-36,27967;1905,84026
10,86000;-36,27471;1917,88282
10,92000;-36,26975;1930,71682
10,98000;-36,26466;1942,85959
11,04000;-36,25970;1957,59665
11,10000;-36,25462;1969,72452
11,16000;-36,24965;1980,52526
11,22000;-36,24463;1992,01256
11,28000;-36,23961;2003,00887
11,34000;-36,23465;2013,35512
11,40000;-36,22963;2025,58953
11,46000;-36,22467;2035,39468
11,52000;-36,21964;2047,66020
11,58000;-36,21480;2057,35788
11,64000;-36,20960;2069,59490
11,70000;-36,20469;2080,55153
11,76000;-36,19967;2091,04605
11,82000;-36,19465;2101,96804
11,88000;-36,18969;2112,00509
11,94000;-36,18467;2123,16308
12,00000;-36,17964;2134,95269
12,06000;-36,17462;2145,42896
12,12000;-36,16960;2158,52596
12,18000;-36,16470;2168,93945
12,24000;-36,15961;2180,34256
12,30000;-36,15471;2191,51378
12,36000;-36,14963;2201,85556
12,42000;-36,14467;2213,92438
12,48000;-36,13970;2223,87910
12,54000;-36,13468;2235,15294
12,60000;-36,12972;2245,97733
12,66000;-36,12464;2259,40309
12,72000;-36,11968;2269,70240
12,78000;-36,11465;2282,83629
12,84000;-36,10963;2293,79367
12,90000;-36,10461;2302,57679
12,96000;-36,09959;2314,05329
13,02000;-36,09468;2324,33099
13,08000;-36,08960;2338,18050
13,14000;-36,08458;2348,53905
13,20000;-36,07967;2359,49904
13,26000;-36,07483;2377,30425
13,32000;-36,06957;2396,85718
13,38000;-36,06455;2413,03071
13,44000;-36,05959;2429,47675
13,50000;-36,05457;2446,97221
13,56000;-36,04954;2465,61896
13,62000;-36,04464;2482,31348
13,68000;-36,03968;2499,83743
13,74000;-36,03459;2515,47154
13,80000;-36,02969;2530,64688
13,86000;-36,02455;2545,72015
13,92000;-36,01971;2560,38941
13,98000;-36,01456;2575,96727
14,04000;-36,00960;2590,27407
14,10000;-36,00464;2604,31021
14,16000;-35,99968;2619,56789
14,22000;-35,99471;2631,86563
14,28000;-35,98963;2647,98775
14,34000;-35,98473;2661,85254
14,40000;-35,97965;2678,16912
14,46000;-35,97474;2690,84740
14,52000;-35,96972;2704,16215
14,58000;-35,96470;2719,18606
14,64000;-35,95962;2733,67446
14,70000;-35,95466;2749,03718
14,76000;-35,94969;2762,29437
14,82000;-35,94467;2775,76540
14,88000;-35,93965;2790,69785
14,94000;-35,93475;2803,17198
15,00000;-35,92966;2821,99495
15,06000;-35,92470;2833,60202
15,12000;-35,91968;2845,99308
15,18000;-35,91471;2860,19742
15,24000;-35,90969;2873,93481
15,30000;-35,90461;2890,64776
15,36000;-35,89965;2903,20497
15,42000;-35,89469;2916,35636
15,48000;-35,88973;2929,46566
15,54000;-35,88464;2946,02793
15,60000;-35,87968;2960,81975
15,66000;-35,87472;2973,62320
15,72000;-35,86964;2987,87206
15,78000;-35,86467;3001,46509
15,84000;-35,85959;3017,02898
15,90000;-35,85463;3031,36408
15,96000;-35,84967;3044,83641
16,02000;-35,84458;3059,94563
16,08000;-35,83968;3072,64719
16,14000;-35,83460;3089,47824
16,20000;-35,82970;3101,27065
16,26000;-35,82455;3117,76046
16,32000;-35,81965;3132,34851
16,38000;-35,81469;3145,61166
16,44000;-35,80966;3159,05772
16,50000;-35,80470;3173,04246
16,56000;-35,79962;3188,01813
16,62000;-35,79472;3201,77600
16,68000;-35,78970;3217,30450
16,74000;-35,78468;3230,20108
16,80000;-35,77977;3243,83862
16,86000;-35,77469;3258,72637
16,92000;-35,76973;3271,16325
16,98000;-35,76471;3284,81272
17,04000;-35,75974;3297,96001
17,10000;-35,75472;3311,16952
17,16000;-35,74964;3325,94253
17,22000;-35,74473;3338,26356
17,28000;-35,73965;3353,14013
17,34000;-35,73469;3365,00853
17,40000;-35,72961;3378,88040
17,46000;-35,72471;3391,30498
17,52000;-35,71969;3405,12060
17,58000;-35,71466;3419,00848
17,64000;-35,70970;3431,42860
17,70000;-35,70467;3446,81926
17,76000;-35,69971;3458,76105
17,82000;-35,69475;3471,39090
17,88000;-35,68973;3486,71265
17,94000;-35,68477;3506,57217
18,00000;-35,67962;3529,41304
18,06000;-35,67472;3550,59355
18,12000;-35,66970;3571,25886
18,18000;-35,66474;3594,11463
18,24000;-35,65972;3615,51009
18,30000;-35,65469;3637,71431
18,36000;-35,64973;3656,30127
18,42000;-35,64470;3679,43496
18,48000;-35,63974;3700,23213
18,54000;-35,63460;3722,87706
18,60000;-35,62964;3745,17031
18,66000;-35,62456;3764,78694
18,72000;-35,61960;3784,61294
18,78000;-35,61469;3806,26284
18,84000;-35,60967;3827,20977
18,90000;-35,60465;3848,68197
18,96000;-35,59968;3867,86014
19,02000;-35,59466;3888,98887
19,08000;-35,58976;3907,95246
19,14000;-35,58468;3929,96296
19,20000;-35,57965;3949,84037
19,26000;-35,57457;3971,26898
19,32000;-35,56967;3991,26820
19,38000;-35,56465;4010,83454
19,44000;-35,55969;4030,90343
19,50000;-35,55466;4052,47808
19,56000;-35,54964;4075,06190
19,62000;-35,54468;4096,47934
19,68000;-35,53972;4119,54299
19,74000;-35,53469;4141,08410
19,80000;-35,52961;4164,97886
19,86000;-35,52459;4187,36935
19,92000;-35,51969;4209,29492
19,98000;-35,51473;4232,07097
20,04000;-35,50970;4254,22043
20,10000;-35,50468;4275,29924
20,16000;-35,49966;4299,22827
20,22000;-35,49475;4320,30000
20,28000;-35,48967;4345,94825
20,34000;-35,48471;4365,85024
20,40000;-35,47969;4387,48971
20,46000;-35,47466;4411,32970
20,52000;-35,46964;4433,17294
20,58000;-35,46468;4454,92975
20,64000;-35,45972;4476,36358
20,70000;-35,45464;4499,16609
20,76000;-35,44968;4521,83820
20,82000;-35,44471;4543,58906
20,88000;-35,43963;4566,74062
20,94000;-35,43467;4587,68792
21,00000;-35,42959;4609,37060
21,06000;-35,42474;4631,23322
21,12000;-35,41966;4653,47841
21,18000;-35,41470;4676,50108
21,24000;-35,40967;4696,73350
21,30000;-35,40465;4720,67036
21,36000;-35,39975;4741,18739
21,42000;-35,39467;4764,91451
21,48000;-35,38965;4787,81126
21,54000;-35,38468;4808,09696
21,60000;-35,37960;4831,49067
21,66000;-35,37470;4855,59404
21,72000;-35,36962;4883,78927
21,78000;-35,36465;4908,32515
21,84000;-35,35969;4932,86066
21,90000;-35,35461;4959,77737
21,96000;-35,34971;4984,68801
22,02000;-35,34456;5014,29848
22,08000;-35,33972;5038,80754
22,14000;-35,33470;5064,24643
22,20000;-35,32974;5090,38530
22,26000;-35,32495;5115,13241
22,32000;-35,31969;5145,80719
22,38000;-35,31473;5169,90758
22,44000;-35,30971;5195,26564
22,50000;-35,30468;5220,21279
22,56000;-35,29960;5251,20273
22,62000;-35,29464;5277,26598
22,68000;-35,28968;5302,29099
22,74000;-35,28472;5327,40206
22,80000;-35,27975;5354,53819
22,86000;-35,27467;5384,41986
22,92000;-35,26965;5411,98403
22,98000;-35,26474;5437,44303
23,04000;-35,25972;5465,16106
23,10000;-35,25476;5490,74225
23,16000;-35,24956;5520,69657
23,22000;-35,24465;5547,75819
23,28000;-35,23963;5573,90712
23,34000;-35,23473;5601,03171
23,40000;-35,22977;5628,50982
23,46000;-35,22463;5661,91524
23,52000;-35,21972;5686,15571
23,58000;-35,21470;5712,40522
23,64000;-35,20974;5739,92617
23,70000;-35,20483;5766,51655
23,76000;-35,19963;5797,17793
23,82000;-35,19467;5823,73068
23,88000;-35,18959;5852,15315
23,94000;-35,18469;5879,14065
24,00000;-35,17960;5908,42552
24,06000;-35,17470;5937,81285
24,12000;-35,16974;5963,19847
24,18000;-35,16466;5991,66192
24,24000;-35,15969;6018,31712
24,30000;-35,15461;6046,67068
24,36000;-35,14977;6073,48159
24,42000;-35,14463;6101,95883
24,48000;-35,13966;6129,64667
24,54000;-35,13470;6155,57991
24,60000;-35,12968;6182,98687
24,66000;-35,12472;6209,53739
24,72000;-35,11970;6236,06704
24,78000;-35,11474;6263,42222
24,84000;-35,10971;6289,94480
24,90000;-35,10463;6317,41360
24,96000;-35,09972;6343,99727
25,02000;-35,09464;6370,50644
25,08000;-35,08974;6398,32690
25,14000;-35,08466;6426,77918
25,20000;-35,07976;6452,01653
25,26000;-35,07467;6475,78090
25,32000;-35,06971;6498,70336
25,38000;-35,06469;6527,26591
25,44000;-35,05973;6554,63859
25,50000;-35,05477;6578,85000
25,56000;-35,04974;6604,15068
25,62000;-35,04472;6629,74045
25,68000;-35,03975;6655,44644
25,74000;-35,03467;6681,66801
25,80000;-35,02965;6706,01353
25,86000;-35,02469;6731,04450
25,92000;-35,01979;6755,58224
25,98000;-35,01477;6782,11674
26,04000;-35,00968;6807,46213
26,10000;-35,00478;6830,30933
26,16000;-34,99964;6856,70525
26,22000;-34,99473;6880,54189
26,28000;-34,98965;6906,64724
26,34000;-34,98469;6930,71857
26,40000;-34,97967;6954,31605
26,46000;-34,97465;6980,21650
26,52000;-34,96968;7003,10916
26,58000;-34,96472;7028,93957
26,64000;-34,95964;7053,69860
26,70000;-34,95468;7077,83699
26,76000;-34,94959;7102,28309
26,82000;-34,94469;7124,77192
26,88000;-34,93967;7147,43063
26,94000;-34,93459;7174,35777
27,00000;-34,92957;7197,45159
27,06000;-34,92460;7221,27557
27,12000;-34,91964;7243,41124
27,18000;-34,91456;7268,14866
27,24000;-34,90971;7289,97439
27,30000;-34,90451;7318,85657
27,36000;-34,89967;7338,92843
27,42000;-34,89465;7362,64214
27,48000;-34,88969;7385,67486
27,54000;-34,88466;7409,10396
27,60000;-34,87958;7433,24831
27,66000;-34,87462;7458,65330
27,72000;-34,86971;7479,00531
27,78000;-34,86463;7503,04088
27,84000;-34,85967;7525,21604
27,90000;-34,85459;7548,85972
27,96000;-34,84975;7570,75921
28,02000;-34,84466;7594,93485
28,08000;-34,83976;7617,15993
28,14000;-34,83474;7639,15703
28,20000;-34,82972;7663,93691
28,26000;-34,82481;7684,68231
28,32000;-34,81973;7710,20800
28,38000;-34,81465;7730,69859
28,44000;-34,80969;7752,11751
28,50000;-34,80466;7775,67402
28,56000;-34,79976;7795,92842
28,62000;-34,79468;7820,81336
28,68000;-34,78972;7842,49380
28,74000;-34,78470;7864,23907
28,80000;-34,77967;7886,74727
28,86000;-34,77477;7906,34528
28,92000;-34,76963;7930,64758
28,98000;-34,76478;7951,50995
29,04000;-34,75958;7976,31219
29,10000;-34,75462;7995,94596
29,16000;-34,74978;8018,31707
29,22000;-34,74463;8044,65488
29,28000;-34,73961;8064,51514
29,34000;-34,73465;8085,39912
29,40000;-34,72963;8106,28757
29,46000;-34,72467;8126,42202
29,52000;-34,71965;8149,59109
29,58000;-34,71462;8171,70888
29,64000;-34,70960;8195,32126
29,70000;-34,70464;8213,71377
29,76000;-34,69967;8234,11718
29,82000;-34,69471;8255,16582
29,88000;-34,68957;8278,08604
29,94000;-34,68467;8298,45145
30,00000;-34,67971;8317,00340
30,06000;-34,67468;8339,09661
30,12000;-34,66972;8360,83591
30,18000;-34,66493;8380,51736
30,24000;-34,65967;8403,09188
30,30000;-34,65465;8422,45668
30,36000;-34,64969;8442,92939
30,42000;-34,64472;8463,12642
30,48000;-34,63988;8483,80774
30,54000;-34,63462;8507,19437
30,60000;-34,62966;8525,06831
30,66000;-34,62470;8545,48365
30,72000;-34,61974;8564,43420
30,78000;-34,61472;8583,82508
30,84000;-34,60969;8605,74096
30,90000;-34,60467;8626,37460
30,96000;-34,59970;8644,50037
31,02000;-34,59474;8664,09764
31,08000;-34,58978;8683,96163
31,14000;-34,58470;8703,48737
31,20000;-34,57967;8726,31520
31,26000;-34,57471;8744,28600
31,32000;-34,56975;8763,68955
31,38000;-34,56473;8783,17282
31,44000;-34,55977;8801,72700
31,50000;-34,55468;8821,55299
31,56000;-34,54972;8840,23458
31,62000;-34,54470;8861,00903
31,68000;-34,53962;8881,51973
31,74000;-34,53465;8901,14829
31,80000;-34,52957;8922,00097
31,86000;-34,52467;8940,88224
31,92000;-34,51959;8961,20816
31,98000;-34,51469;8978,81240
32,04000;-34,50966;8999,54736
32,10000;-34,50470;9018,65140
32,16000;-34,49968;9036,11630
32,22000;-34,49466;9057,04871
32,28000;-34,48963;9075,66175
32,34000;-34,48461;9096,43322
32,40000;-34,47959;9113,67685
32,46000;-34,47468;9131,21998
32,52000;-34,46966;9149,86134
32,58000;-34,46470;9169,98982
32,64000;-34,45968;9188,32496
32,70000;-34,45472;9207,10936
32,76000;-34,44970;9225,68738
32,82000;-34,44467;9245,96116
32,88000;-34,43971;9264,07054
32,94000;-34,43469;9283,78478
33,00000;-34,42972;9301,04107
33,06000;-34,42464;9320,40289
33,12000;-34,41974;9337,27771
33,18000;-34,41466;9358,03652
33,24000;-34,40975;9375,86948
33,30000;-34,40473;9395,05845
33,36000;-34,39971;9412,38776
33,42000;-34,39475;9429,25438
33,48000;-34,38973;9448,57746
33,54000;-34,38476;9467,30301
33,60000;-34,37974;9485,13225
33,66000;-34,37472;9502,79906
33,72000;-34,36975;9521,20125
33,78000;-34,36467;9540,20098
33,84000;-34,35977;9558,74398
33,90000;-34,35469;9577,21695
33,96000;-34,34973;9594,90910
34,02000;-34,34464;9611,78243
34,08000;-34,33968;9632,63512
34,14000;-34,33466;9648,34690
34,20000;-34,32964;9667,52023
34,26000;-34,32468;9683,50694
34,32000;-34,31959;9703,53931
34,38000;-34,31463;9720,97740
34,44000;-34,30961;9738,63900
34,50000;-34,30458;9755,89901
34,56000;-34,29962;9772,71348
34,62000;-34,29466;9790,47790
34,68000;-34,28958;9809,44261
34,74000;-34,28462;9824,87723
34,80000;-34,27959;9844,31133
34,86000;-34,27469;9859,68411
34,92000;-34,26967;9877,02534
34,98000;-34,26471;9893,92996
35,04000;-34,25962;9911,35687
35,10000;-34,25466;9928,44701
35,16000;-34,24964;9943,44130
35,22000;-34,24468;9961,88372
35,28000;-34,23965;9977,63723
35,34000;-34,23463;9995,40314
35,40000;-34,22967;10010,77592
35,46000;-34,22471;10027,81242
35,52000;-34,21969;10044,10088
35,58000;-34,21466;10059,75232
35,64000;-34,20964;10076,55635
35,70000;-34,20467;10092,39703
35,76000;-34,19959;10108,42100
35,82000;-34,19463;10125,46793
35,88000;-34,18967;10140,12620
35,94000;-34,18465;10159,03577
36,00000;-34,17975;10172,71057
36,06000;-34,17466;10190,69627
36,12000;-34,16970;10205,86118
36,18000;-34,16462;10222,40222
36,24000;-34,15965;10238,76071
36,30000;-34,15481;10253,33479
36,36000;-34,14961;10272,42318
36,42000;-34,14459;10286,39972
36,48000;-34,13968;10300,01938
36,54000;-34,13466;10316,09178
36,60000;-34,12970;10331,59047
36,66000;-34,12462;10348,89519
36,72000;-34,11978;10361,89869
36,78000;-34,11463;10378,43302
36,84000;-34,10967;10394,80269
36,90000;-34,10471;10408,94762
36,96000;-34,09963;10427,54129
37,02000;-34,09460;10440,52169
37,08000;-34,08982;10454,91546
37,14000;-34,08468;10472,43699
37,20000;-34,07966;10485,90615
37,26000;-34,07469;10500,94217
37,32000;-34,06973;10514,95150
37,38000;-34,06471;10530,43082
37,44000;-34,05969;10545,42810
37,50000;-34,05461;10561,43492
37,56000;-34,04964;10577,43952
37,62000;-34,04468;10590,86770
37,68000;-34,03966;10605,04690
37,74000;-34,03469;10618,97725
37,80000;-34,02961;10635,33500
37,86000;-34,02471;10652,20460
37,92000;-34,01969;10664,35352
37,98000;-34,01473;10678,92909
38,04000;-34,00970;10691,71503
38,10000;-34,00468;10709,41389
38,16000;-33,99966;10722,68561
38,22000;-33,99470;10740,46716
38,28000;-33,98967;10753,31122
38,34000;-33,98471;10767,90765
38,40000;-33,97969;10781,71656
38,46000;-33,97478;10796,61697
38,52000;-33,96964;10811,28493
38,58000;-33,96468;10825,89626
38,64000;-33,95972;10838,68146
38,70000;-33,95464;10853,90374
38,76000;-33,94968;10867,76629
38,82000;-33,94459;10883,85209
38,88000;-33,93969;10894,80519
38,94000;-33,93461;10910,09900
39,00000;-33,92976;10923,27088
39,06000;-33,92468;10938,35682
39,12000;-33,91972;10952,38999
39,18000;-33,91476;10965,41882
39,24000;-33,90973;10981,37572
39,30000;-33,90477;10994,52600
39,36000;-33,89975;11010,28547
39,42000;-33,89473;11023,26363
39,48000;-33,88977;11038,34361
39,54000;-33,88468;11052,65915
39,60000;-33,87972;11066,19462
39,66000;-33,87464;11079,81801
39,72000;-33,86968;11093,82883
39,78000;-33,86465;11108,96468
39,84000;-33,85963;11122,42192
39,90000;-33,85467;11133,45325
39,96000;-33,84959;11148,56601
40,02000;-33,84468;11160,81104
40,08000;-33,83966;11175,94093
40,14000;-33,83470;11188,06973
40,20000;-33,82968;11203,04018
40,26000;-33,82471;11216,01611
40,32000;-33,81963;11230,57231
40,38000;-33,81467;11244,60325
40,44000;-33,80965;11257,60078
40,50000;-33,80468;11271,32475
40,56000;-33,79972;11284,41766
40,62000;-33,79464;11298,86433
40,68000;-33,78968;11312,98468
40,74000;-33,78478;11324,86090
40,80000;-33,77969;11339,29938
40,86000;-33,77479;11351,94302
40,92000;-33,76959;11365,68785
40,98000;-33,76462;11381,11129
41,04000;-33,75961;11392,77518
41,10000;-33,75464;11407,09519
41,16000;-33,74968;11417,53718
41,22000;-33,74466;11431,59568
41,28000;-33,73975;11445,36138
41,34000;-33,73467;11459,40870
41,40000;-33,72971;11472,06351
41,46000;-33,72481;11483,33922
41,52000;-33,71967;11500,20733
41,58000;-33,71464;11511,33776
41,64000;-33,70968;11523,22814
41,70000;-33,70460;11537,62415
41,76000;-33,69969;11549,84236
41,82000;-33,69467;11562,99412
41,88000;-33,68989;11574,68930
41,94000;-33,68463;11589,54576
42,00000;-33,67967;11600,39902
42,06000;-33,67464;11611,57712
42,12000;-33,66962;11626,08117
42,18000;-33,66460;11638,31577
42,24000;-33,65958;11651,64411
42,30000;-33,65461;11664,80482
42,36000;-33,64965;11675,85477
42,42000;-33,64463;11687,46278
42,48000;-33,63966;11698,60959
42,54000;-33,63458;11713,95108
42,60000;-33,62968;11724,33570
42,66000;-33,62466;11736,55465
42,72000;-33,61964;11749,07163
42,78000;-33,61468;11759,77811
42,84000;-33,60959;11773,57212
42,90000;-33,60469;11783,82635
42,96000;-33,59961;11798,22236
43,02000;-33,59471;11809,70743
43,08000;-33,58962;11821,66636
43,14000;-33,58466;11833,23860
43,20000;-33,57982;11843,82066
43,26000;-33,57467;11857,05289
43,32000;-33,56965;11867,00091
43,38000;-33,56469;11879,54843
43,44000;-33,55961;11892,55789
43,50000;-33,55470;11901,91358
43,56000;-33,54962;11914,91932
43,62000;-33,54472;11925,90743
43,68000;-33,53958;11942,72861
43,74000;-33,53467;11949,82454
43,80000;-33,52971;11960,09070
43,86000;-33,52469;11972,77755
43,92000;-33,52003;11982,84179
43,98000;-33,51471;11999,24275
44,04000;-33,50968;12007,15825
44,10000;-33,50472;12017,88560
44,16000;-33,49976;12028,19347
44,22000;-33,49468;12042,87857
44,28000;-33,48965;12054,03656
44,34000;-33,48469;12064,49792
44,40000;-33,47967;12074,57930
44,46000;-33,47489;12086,22605
44,52000;-33,46962;12099,10512
44,58000;-33,46466;12108,20973
44,64000;-33,45976;12116,59610
44,70000;-33,45468;12130,57563
44,76000;-33,44966;12142,03462
44,82000;-33,44457;12154,98447
44,88000;-33,43961;12165,36164
44,94000;-33,43459;12174,60558
45,00000;-33,42963;12184,94698
45,06000;-33,42466;12195,10064
45,12000;-33,41958;12208,35820
45,18000;-33,41462;12218,15199
45,24000;-33,40965;12229,01866
45,30000;-33,40463;12239,16933
45,36000;-33,39967;12249,18216
45,42000;-33,39465;12259,62564
45,48000;-33,38969;12270,29338
45,54000;-33,38461;12282,85730
45,60000;-33,37964;12293,61221
45,66000;-33,37462;12302,93959
45,72000;-33,36960;12313,13497
45,78000;-33,36469;12322,70449
45,84000;-33,35967;12333,89974
45,90000;-33,35471;12341,96797
45,96000;-33,34963;12354,31284
46,02000;-33,34473;12364,59240
46,08000;-33,33964;12374,48081
46,14000;-33,33468;12384,47875
46,20000;-33,32972;12393,58783
46,26000;-33,32470;12404,61320
46,32000;-33,31973;12415,14683
46,38000;-33,31471;12424,81843
46,44000;-33,30975;12434,33878
46,50000;-33,30478;12443,52981
46,56000;-33,29970;12453,96137
46,62000;-33,29480;12463,62627
46,68000;-33,28972;12475,16870
46,74000;-33,28476;12484,86489
46,80000;-33,27968;12492,17764
46,86000;-33,27471;12504,33773
46,92000;-33,26969;12514,31853
46,98000;-33,26467;12525,14422
47,04000;-33,25970;12532,78852
47,10000;-33,25468;12543,15972
47,16000;-33,24972;12553,23738
47,22000;-33,24470;12564,40580
47,28000;-33,23967;12574,47302
47,34000;-33,23465;12583,70429
47,40000;-33,22969;12592,92066
47,46000;-33,22461;12602,66155
47,52000;-33,21965;12611,53817
47,58000;-33,21462;12622,67232
47,64000;-33,20966;12630,80388
47,70000;-33,20464;12641,51931
47,76000;-33,19968;12649,37818
47,82000;-33,19465;12660,01910
47,88000;-33,18969;12669,15947
47,94000;-33,18467;12678,03013
48,00000;-33,17971;12687,94835
48,06000;-33,17468;12695,47045
48,12000;-33,16972;12706,19631
48,18000;-33,16470;12715,18469
48,24000;-33,15962;12726,84038
48,30000;-33,15466;12734,34609
48,36000;-33,14969;12743,90221
48,42000;-33,14467;12753,65502
48,48000;-33,13964;12763,20070
48,54000;-33,13462;12772,06391
48,60000;-33,12966;12780,86752
48,66000;-33,12476;12789,99150
48,72000;-33,11968;12801,29403
48,78000;-33,11472;12809,93074
48,84000;-33,10957;12820,99485
48,90000;-33,10467;12829,82677
48,96000;-33,09959;12842,09043
49,02000;-33,09462;12850,11172
49,08000;-33,08960;12859,70360
49,14000;-33,08464;12871,17749
49,20000;-33,07974;12877,84278
49,26000;-33,07471;12888,85474
49,32000;-33,06975;12898,45407
49,38000;-33,06473;12909,02942
49,44000;-33,05965;12918,43802
49,50000;-33,05475;12926,95254
49,56000;-33,04960;12937,17027
49,62000;-33,04464;12946,03199
49,68000;-33,03962;12954,24998
49,74000;-33,03465;12964,50049
49,80000;-33,02969;12971,84825
49,86000;-33,02461;12984,70944
49,92000;-33,01965;12992,37311
49,98000;-33,01469;13001,36000
50,04000;-33,00960;13010,06228
50,10000;-33,00464;13018,07314
50,16000;-32,99956;13028,86456
50,22000;-32,99460;13034,44505
50,28000;-32,98958;13046,84579
50,34000;-32,98467;13053,46489
50,40000;-32,97977;13061,73801
50,46000;-32,97463;13072,60990
50,52000;-32,96972;13076,87759
50,58000;-32,96464;13087,31288
50,64000;-32,95974;13094,47885
50,70000;-32,95460;13106,61435
50,76000;-32,94964;13114,48365
50,82000;-32,94461;13120,91798
50,88000;-32,93965;13129,73052
50,94000;-32,93493;13136,15888
51,00000;-32,92967;13149,61612
51,06000;-32,92470;13154,58864
51,12000;-32,91974;13160,12144
51,18000;-32,91466;13169,21413
51,24000;-32,90963;13180,42725
51,30000;-32,90461;13187,14172
51,36000;-32,89959;13195,41782
51,42000;-32,89475;13201,45428
51,48000;-32,88961;13212,57800
51,54000;-32,88465;13217,61310
51,60000;-32,87962;13226,27664
51,66000;-32,87472;13233,71232
51,72000;-32,86958;13243,02852
51,78000;-32,86467;13249,29744
51,84000;-32,85959;13258,88187
51,90000;-32,85463;13267,59607
51,96000;-32,84967;13273,93204
52,02000;-32,84465;13281,29768
52,08000;-32,83998;13288,66035
52,14000;-32,83466;13301,51707
52,20000;-32,82964;13307,90967
52,26000;-32,82468;13313,44992
52,32000;-32,81965;13321,76775
52,38000;-32,81481;13328,88007
52,44000;-32,80961;13338,94432
52,50000;-32,80470;13345,88230
52,56000;-32,79968;13352,55057
52,62000;-32,79472;13360,44371
52,68000;-32,78976;13365,99886
52,74000;-32,78462;13378,21484
52,80000;-32,77971;13382,15321
52,86000;-32,77463;13390,29968
52,92000;-32,76967;13397,03798
52,98000;-32,76465;13404,17862
53,04000;-32,75963;13410,97057
53,10000;-32,75460;13418,85179
53,16000;-32,74964;13426,90736
53,22000;-32,74468;13432,74415
53,28000;-32,73971;13440,46295
53,34000;-32,73469;13448,61388
53,40000;-32,72967;13457,99863
53,46000;-32,72459;13465,06178
53,52000;-32,71969;13472,35590
53,58000;-32,71461;13480,38316
53,64000;-32,70970;13486,78768
53,70000;-32,70468;13494,50648
53,76000;-32,69977;13500,47588
53,82000;-32,69475;13507,42429
53,88000;-32,68973;13517,03852
53,94000;-32,68471;13520,65653
54,00000;-32,67969;13532,02462
54,06000;-32,67478;13536,88389
54,12000;-32,66970;13545,80522
54,18000;-32,66468;13552,81770
54,24000;-32,65978;13559,10003
54,30000;-32,65469;13569,21494
54,36000;-32,64973;13575,19627
54,42000;-32,64477;13583,16094
54,48000;-32,63969;13592,97335
54,54000;-32,63472;13599,41214
54,60000;-32,62970;13609,64477
54,66000;-32,62474;13618,85667
54,72000;-32,61966;13630,35738
54,78000;-32,61476;13638,07321
54,84000;-32,60967;13648,38630
54,90000;-32,60471;13657,21673
54,96000;-32,59969;13668,76513
55,02000;-32,59473;13680,37164
55,08000;-32,58970;13690,92762
55,14000;-32,58468;13702,69209
55,20000;-32,57972;13713,52673
55,26000;-32,57476;13724,63107
55,32000;-32,56967;13737,39839
55,38000;-32,56465;13749,86917
55,44000;-32,55963;13762,33399
55,50000;-32,55461;13772,43400
55,56000;-32,54964;13782,52059
55,62000;-32,54462;13797,41877
55,68000;-32,53966;13811,47057
55,74000;-32,53458;13823,80575
55,80000;-32,52973;13832,50356
55,86000;-32,52459;13848,07378
55,92000;-32,51963;13859,17962
55,98000;-32,51461;13871,20634
56,04000;-32,50958;13883,98260
56,10000;-32,50468;13895,33728
56,16000;-32,49960;13910,88665
56,22000;-32,49458;13921,66018
56,28000;-32,48967;13932,98507
56,34000;-32,48465;13945,09524
56,40000;-32,47969;13958,63444
56,46000;-32,47461;13969,71643
56,52000;-32,46970;13982,22744
56,58000;-32,46456;13996,25540
56,64000;-32,45972;14008,52650
56,70000;-32,45464;14021,11202
56,76000;-32,44968;14035,83437
56,82000;-32,44472;14046,15939
56,88000;-32,43969;14060,94283
56,94000;-32,43473;14071,16503
57,00000;-32,42965;14085,11847
57,06000;-32,42462;14098,60998
57,12000;-32,41966;14109,03335
57,18000;-32,41464;14121,80960
57,24000;-32,40974;14132,26426
57,30000;-32,40471;14146,84057
57,36000;-32,39963;14160,77465
57,42000;-32,39467;14171,71508
57,48000;-32,38965;14186,49107
57,54000;-32,38474;14195,63740
57,60000;-32,37960;14211,25233
57,66000;-32,37464;14225,01355
57,72000;-32,36962;14238,58255
57,78000;-32,36465;14251,53613
57,84000;-32,35969;14261,53034
57,90000;-32,35455;14280,35945
57,96000;-32,34959;14290,89904
58,02000;-32,34463;14303,82580
58,08000;-32,33966;14314,66639
58,14000;-32,33470;14325,41311
58,20000;-32,32962;14338,12380
58,26000;-32,32495;14349,58726
58,32000;-32,31958;14367,45822
58,38000;-32,31467;14375,38862
58,44000;-32,30971;14384,67652
58,50000;-32,30468;14398,10097
58,56000;-32,29990;14410,89809
58,62000;-32,29464;14426,90790
58,68000;-32,28962;14436,39398
58,74000;-32,28460;14447,04384
58,80000;-32,27964;14458,09752
58,86000;-32,27455;14469,22570
58,92000;-32,26971;14478,30647
58,98000;-32,26469;14487,69718
59,04000;-32,25972;14496,49483
59,10000;-32,25470;14503,30615
59,16000;-32,24962;14512,53146
59,22000;-32,24466;14518,22072
59,28000;-32,23975;14521,26205
59,34000;-32,23461;14524,67442
59,40000;-32,22971;14527,12119
59,46000;-32,22463;14530,21169
59,52000;-32,21978;14534,62690
59,58000;-32,21470;14535,49862
59,64000;-32,20974;14539,13152
59,70000;-32,20472;14534,93088
59,76000;-32,19970;14532,38577
59,82000;-32,19479;14520,60193
59,88000;-32,18965;14500,59712
59,94000;-32,18469;14431,41699
59,98200;-32,17925;2780,05954