File: SU - Suspension/05 - Essais/Excels essais Optimus/collage alu carbone 05_02_19/collage8.is_tens_RawData/Specimen_RawData_1.csv
Temps;Déplacement;Charge
(sec);(mm);(N)
0,00000;0,07617;30,39078
0,04000;0,07647;30,28862
0,08000;0,07773;31,06749
0,12000;0,08036;40,73385
0,16000;0,08365;54,37811
0,20000;0,08735;71,29277
0,24000;0,09118;90,76857
0,28000;0,09483;108,72780
0,32000;0,09853;125,55949
0,36000;0,10218;142,71577
0,40000;0,10571;107,51251
0,44000;0,10918;65,58065
0,48000;0,11258;86,15292
0,52000;0,11605;103,71848
0,56000;0,11946;119,96988
0,60000;0,12281;137,62738
0,64000;0,12622;154,46960
0,68000;0,12950;170,58825
0,72000;0,13285;186,61543
0,76000;0,13620;203,46146
0,80000;0,13961;218,88274
0,84000;0,14290;233,59181
0,88000;0,14625;248,66846
0,92000;0,14965;264,70157
0,96000;0,15294;281,15010
1,00000;0,15623;296,07774
1,04000;0,15958;312,41092
1,08000;0,16299;328,43393
1,12000;0,16621;343,69910
1,16000;0,16962;359,96544
1,20000;0,17303;376,85398
1,24000;0,17626;393,11326
1,28000;0,17961;407,53898
1,32000;0,18296;423,04546
1,36000;0,18624;438,97661
1,40000;0,18953;454,26022
1,44000;0,19300;470,23259
1,48000;0,19629;487,10685
1,52000;0,19958;501,65276
1,56000;0,20287;517,53325
1,60000;0,20621;533,13221
1,64000;0,20962;548,80218
1,68000;0,21291;563,24252
1,72000;0,21626;578,03779
1,76000;0,21961;592,21056
1,80000;0,22296;606,61407
1,84000;0,22624;619,58586
1,88000;0,22959;632,80780
1,92000;0,23300;646,26853
1,96000;0,23629;658,26196
2,00000;0,23958;669,56398
2,04000;0,24298;681,18996
2,08000;0,24627;692,15186
2,12000;0,24956;702,40130
2,16000;0,25285;712,60305
2,20000;0,25626;722,87521
2,24000;0,25955;731,40399
2,28000;0,26289;738,87217
2,32000;0,26624;745,33108
2,36000;0,26953;753,01160
2,40000;0,27288;757,39082
2,44000;0,27623;760,63541
2,48000;0,27958;763,42192
2,52000;0,28292;763,39492
2,56000;0,28621;763,60763
2,60000;0,28962;762,83319
2,64000;0,29297;760,46097
2,68000;0,29632;757,02835
2,72000;0,29961;754,52835
2,76000;0,30289;749,72892
2,80000;0,30630;746,93649
2,84000;0,30959;741,90348
2,88000;0,31288;738,14210
2,92000;0,31623;734,66045
2,96000;0,31957;730,95481
3,00000;0,32286;727,76182
3,04000;0,32621;723,67922
3,08000;0,32956;723,20504
3,12000;0,33291;730,49492
3,16000;0,33602;744,35617
3,20000;0,33972;763,32539
3,24000;0,34295;780,95798
3,28000;0,34630;796,36350
3,32000;0,34959;813,50552
3,36000;0,35288;829,60967
3,40000;0,35623;845,35386
3,44000;0,35945;861,93550
3,48000;0,36286;879,36241
3,52000;0,36621;895,86005
3,56000;0,36956;911,40158
3,60000;0,37285;925,67010
3,64000;0,37620;941,30151
3,68000;0,37960;957,08165
3,72000;0,38289;972,23334
3,76000;0,38630;985,51065
3,80000;0,38959;1000,85884
3,84000;0,39294;1014,04432
3,88000;0,39622;1027,57253
3,92000;0,39957;1040,12443
3,96000;0,40298;1054,52957
4,00000;0,40621;1067,30973
4,04000;0,40956;1080,10573
4,08000;0,41297;1094,33858
4,12000;0,41625;1106,23650
4,16000;0,41960;1116,85516
4,20000;0,42295;1129,13307
4,24000;0,42624;1140,18163
4,28000;0,42959;1150,47935
4,32000;0,43294;1161,40312
4,36000;0,43622;1172,05381
4,40000;0,43957;1181,83810
4,44000;0,44292;1192,11255
4,48000;0,44627;1203,81303
4,52000;0,44962;1212,70008
4,56000;0,45291;1221,44194
4,60000;0,45631;1231,00504
4,64000;0,45960;1240,05377
4,68000;0,46289;1247,94161
4,72000;0,46624;1256,65702
4,76000;0,46959;1266,50734
4,80000;0,47288;1275,31206
4,84000;0,47622;1283,73411
4,88000;0,47951;1291,31759
4,92000;0,48286;1300,30094
4,96000;0,48621;1308,37625
5,00000;0,48950;1316,48146
5,04000;0,49284;1324,13507
5,08000;0,49625;1332,63674
5,12000;0,49954;1340,56676
5,16000;0,50283;1347,86954
5,20000;0,50624;1356,84926
5,24000;0,50959;1365,87601
5,28000;0,51287;1372,50442
5,32000;0,51622;1381,18370
5,36000;0,51957;1390,05659
5,40000;0,52286;1397,17562
5,44000;0,52615;1405,61815
5,48000;0,52956;1414,95410
5,52000;0,53284;1423,59762
5,56000;0,53613;1431,69677
5,60000;0,53954;1440,20803
5,64000;0,54289;1449,10906
5,68000;0,54624;1457,70712
5,72000;0,54953;1465,20277
5,76000;0,55281;1473,17443
5,80000;0,55622;1481,35033
5,84000;0,55957;1489,96599
5,88000;0,56280;1498,43125
5,92000;0,56627;1506,96486
5,96000;0,56961;1516,09518
6,00000;0,57284;1525,36994
6,04000;0,57619;1532,33912
6,08000;0,57954;1541,78217
6,12000;0,58283;1550,66941
6,16000;0,58618;1559,72913
6,20000;0,58952;1569,60301
6,24000;0,59287;1578,46920
6,28000;0,59616;1587,38717
6,32000;0,59951;1595,60721
6,36000;0,60286;1605,29967
6,40000;0,60621;1614,34393
6,44000;0,60955;1623,79127
6,48000;0,61290;1633,06128
6,52000;0,61625;1642,33781
6,56000;0,61960;1651,07418
6,60000;0,62295;1660,62769
6,64000;0,62624;1669,99158
6,68000;0,62958;1679,15374
6,72000;0,63287;1688,44927
6,76000;0,63616;1697,66434
6,80000;0,63951;1706,69388
6,84000;0,64286;1715,97768
6,88000;0,64620;1725,34194
6,92000;0,64955;1733,53814
6,96000;0,65290;1742,26053
7,00000;0,65613;1751,58717
7,04000;0,65954;1759,71463
7,08000;0,66295;1769,87145
7,12000;0,66623;1778,20791
7,16000;0,66964;1785,90231
7,20000;0,67299;1794,83052
7,24000;0,67628;1801,96650
7,28000;0,67957;1808,82253
7,32000;0,68286;1816,90156
7,36000;0,68626;1826,02089
7,40000;0,68955;1832,45186
7,44000;0,69284;1838,79770
7,48000;0,69631;1847,14235
7,52000;0,69960;1853,71693
7,56000;0,70289;1860,19205
7,60000;0,70623;1866,81282
7,64000;0,70952;1874,20882
7,68000;0,71293;1881,17344
7,72000;0,71628;1887,11174
7,76000;0,71957;1892,92077
7,80000;0,72297;1899,54247
7,84000;0,72626;1905,86504
7,88000;0,72955;1910,74815
7,92000;0,73290;1916,96826
7,96000;0,73625;1923,58624
8,00000;0,73948;1928,36206
8,04000;0,74288;1933,87326
8,08000;0,74629;1940,84533
8,12000;0,74952;1945,57328
8,16000;0,75287;1949,87264
8,20000;0,75628;1956,04712
8,24000;0,75963;1961,98672
8,28000;0,76297;1966,61372
8,32000;0,76626;1970,18944
8,36000;0,76961;1973,81284
8,40000;0,77296;1977,42265
8,44000;0,77625;1981,28577
8,48000;0,77960;1984,20603
8,52000;0,78294;1989,45049
8,56000;0,78623;1992,45363
8,60000;0,78958;1994,94157
8,64000;0,79293;1998,74602
8,68000;0,79628;2002,18763
8,72000;0,79962;2005,14514
8,76000;0,80285;2008,58489
8,80000;0,80626;2012,41616
8,84000;0,80967;2015,63593
8,88000;0,81290;2018,60201
8,92000;0,81631;2021,31700
8,96000;0,81965;2025,06762
9,00000;0,82288;2027,98247
9,04000;0,82623;2030,84759
9,08000;0,82958;2035,37848
9,12000;0,83293;2038,39093
9,16000;0,83628;2041,73904
9,20000;0,83968;2045,06628
9,24000;0,84297;2049,51689
9,28000;0,84632;2051,85339
9,32000;0,84955;2054,21876
9,36000;0,85302;2057,25133
9,40000;0,85631;2060,92875
9,44000;0,85959;2063,43979
9,48000;0,86300;2067,57355
9,52000;0,86629;2071,54583
9,56000;0,86958;2074,48788
9,60000;0,87299;2077,32935
9,64000;0,87627;2082,92361
9,68000;0,87962;2086,23149
9,72000;0,88297;2089,57903
9,76000;0,88620;2092,37467
9,80000;0,88967;2095,73563
9,84000;0,89296;2099,98041
9,88000;0,89618;2103,69304
9,92000;0,89971;2107,41945
9,96000;0,90306;2112,54992
10,00000;0,90629;2114,58243
10,04000;0,90958;2116,10571
10,08000;0,91293;2118,57967
10,12000;0,91627;2122,07828
10,16000;0,91956;2124,44104
10,20000;0,92291;2126,93736
10,24000;0,92632;2132,50276
10,28000;0,92961;2133,80959
10,32000;0,93290;2135,71861
10,36000;0,93624;2139,55119
10,40000;0,93959;2143,58233
10,44000;0,94294;2145,15794
10,48000;0,94629;2147,72820
10,52000;0,94958;2150,66206
10,56000;0,95292;2154,85729
10,60000;0,95627;2156,94904
10,64000;0,95944;2158,66435
10,68000;0,96291;2162,67463
10,72000;0,96626;2165,30878
10,76000;0,96949;2168,28957
10,80000;0,97283;2171,36778
10,84000;0,97624;2176,50626
10,88000;0,97953;2180,12780
10,92000;0,98282;2183,81416
10,96000;0,98617;2189,06570
11,00000;0,98952;2193,74411
11,04000;0,99286;2196,79773
11,08000;0,99615;2202,46539
11,12000;0,99962;2210,65283
11,16000;1,00291;2215,21631
11,20000;1,00620;2219,96009
11,24000;1,00961;2225,93751
11,28000;1,01283;2231,03948
11,32000;1,01618;2236,45419
11,36000;1,01953;2243,13382
11,40000;1,02294;2250,32941
11,44000;1,02623;2258,14804
11,48000;1,02957;2262,38780
11,52000;1,03280;2268,25923
11,56000;1,03621;2275,00200
11,60000;1,03950;2280,97755
11,64000;1,04285;2287,29080
11,68000;1,04626;2294,69836
11,72000;1,04954;2301,83918
11,76000;1,05295;2310,27268
11,80000;1,05624;2317,95274
11,84000;1,05965;2323,55855
11,88000;1,06288;2331,35782
11,92000;1,06623;2338,62326
11,96000;1,06963;2346,32678
12,00000;1,07292;2353,26607
12,04000;1,07615;2359,62477
12,08000;1,07962;2368,62358
12,12000;1,08291;2376,33232
12,16000;1,08620;2382,80687
12,20000;1,08954;2390,48135
12,24000;1,09301;2399,16481
12,28000;1,09630;2406,14396
12,32000;1,09959;2413,24734
12,36000;1,10294;2421,17736
12,40000;1,10628;2429,16755
12,44000;1,10963;2435,92206
12,48000;1,11292;2443,12547
12,52000;1,11627;2450,89121
12,56000;1,11962;2458,56866
12,60000;1,12285;2465,18049
12,64000;1,12619;2473,21203
12,68000;1,12954;2481,71333
12,72000;1,13289;2488,15212
12,76000;1,13618;2495,41570
12,80000;1,13953;2504,10400
12,84000;1,14294;2513,01695
12,88000;1,14622;2521,39196
12,92000;1,14951;2530,05438
12,96000;1,15292;2539,68686
13,00000;1,15621;2548,32841
13,04000;1,15950;2557,61277
13,08000;1,16291;2567,42146
13,12000;1,16631;2578,70909
13,16000;1,16948;2588,51144
13,20000;1,17289;2599,77747
13,24000;1,17624;2612,06012
13,28000;1,17929;2623,57742
13,32000;1,18282;2637,07433
13,36000;1,18622;2651,00617
13,40000;1,18951;2663,96906
13,44000;1,19286;2677,47026
13,48000;1,19615;2689,62439
13,52000;1,19950;2702,90766
13,56000;1,20285;2715,58799
13,60000;1,20613;2728,89733
13,64000;1,20948;2743,03257
13,68000;1,21289;2756,88171
13,72000;1,21618;2770,36149
13,76000;1,21953;2784,35126
13,80000;1,22287;2799,01810
13,84000;1,22622;2812,53234
13,88000;1,22945;2826,84825
13,92000;1,23286;2841,76450
13,96000;1,23621;2856,86310
14,00000;1,23956;2871,11420
14,04000;1,24284;2885,24404
14,08000;1,24619;2899,99172
14,12000;1,24960;2914,75933
14,16000;1,25283;2928,88302
14,20000;1,25618;2944,21986
14,24000;1,25959;2959,51273
14,28000;1,26287;2973,90111
14,32000;1,26616;2988,70970
14,36000;1,26963;3004,22646
14,40000;1,27292;3019,75105
14,44000;1,27621;3034,24895
14,48000;1,27955;3049,17712
14,52000;1,28296;3066,79830
14,56000;1,28631;3081,99730
14,60000;1,28966;3096,54847
14,64000;1,29295;3112,13713
14,68000;1,29630;3126,27107
14,72000;1,29964;3141,63603
14,76000;1,30293;3156,40122
14,80000;1,30622;3171,14517
14,84000;1,30957;3187,31219
14,88000;1,31298;3204,13299
14,92000;1,31627;3221,28274
14,96000;1,31961;3237,46428
15,00000;1,32296;3253,16079
15,04000;1,32619;3268,64757
15,08000;1,32966;3284,55083
15,12000;1,33301;3302,23367
15,16000;1,33630;3316,32718
15,20000;1,33958;3329,89283
15,24000;1,34293;3346,07773
15,28000;1,34628;3363,85369
15,32000;1,34957;3378,61367
15,36000;1,35292;3393,42095
15,40000;1,35621;3410,18662
15,44000;1,35955;3426,46018
15,48000;1,36290;3440,47993
15,52000;1,36625;3456,47670
15,56000;1,36960;3474,02170
15,60000;1,37289;3488,71052
15,64000;1,37617;3503,92647
15,68000;1,37958;3519,50675
15,72000;1,38293;3534,46379
15,76000;1,38622;3549,94945
15,80000;1,38963;3564,96312
15,84000;1,39298;3581,59207
15,88000;1,39620;3596,45896
15,92000;1,39949;3610,76295
15,96000;1,40290;3627,70781
16,00000;1,40625;3645,12093
16,04000;1,40954;3659,57841
16,08000;1,41289;3674,55110
16,12000;1,41623;3691,02135
16,16000;1,41958;3706,53160
16,20000;1,42281;3721,24612
16,24000;1,42622;3736,81746
16,28000;1,42957;3753,27356
16,32000;1,43292;3768,49174
16,36000;1,43626;3783,03602
16,40000;1,43955;3799,17808
16,44000;1,44296;3815,22998
16,48000;1,44619;3830,58377
16,52000;1,44948;3846,00498
16,56000;1,45288;3862,98224
16,60000;1,45629;3878,84192
16,64000;1,45946;3893,25842
16,68000;1,46287;3907,89993
16,72000;1,46622;3923,36585
16,76000;1,46951;3938,26179
16,80000;1,47279;3952,40299
16,84000;1,47626;3968,76298
16,88000;1,47961;3985,25670
16,92000;1,48278;3999,38487
16,96000;1,48631;4017,15189
17,00000;1,48966;4032,90838
17,04000;1,49294;4047,71045
17,08000;1,49623;4062,72002
17,12000;1,49964;4078,39939
17,16000;1,50299;4095,99990
17,20000;1,50628;4110,82990
17,24000;1,50962;4126,53238
17,28000;1,51291;4140,99284
17,32000;1,51620;4155,84669
17,36000;1,51961;4171,44038
17,40000;1,52284;4187,79366
17,44000;1,52625;4203,31396
17,48000;1,52965;4222,76966
17,52000;1,53288;4238,51795
17,56000;1,53623;4253,14046
17,60000;1,53958;4268,63842
17,64000;1,54287;4283,96873
17,68000;1,54628;4299,88354
17,72000;1,54950;4314,94340
17,76000;1,55291;4333,68608
17,80000;1,55620;4349,10320
17,84000;1,55955;4364,64176
17,88000;1,56290;4379,73589
17,92000;1,56619;4394,58713
17,96000;1,56947;4410,85100
18,00000;1,57288;4428,50739
18,04000;1,57617;4445,56512
18,08000;1,57952;4460,86153
18,12000;1,58287;4476,30621
18,16000;1,58610;4492,18489
18,20000;1,58944;4507,32522
18,24000;1,59285;4523,33130
18,28000;1,59614;4539,48379
18,32000;1,59955;4556,17569
18,36000;1,60278;4571,79211
18,40000;1,60618;4588,30670
18,44000;1,60953;4605,46352
18,48000;1,61288;4621,05758
18,52000;1,61611;4636,02506
18,56000;1,61952;4652,70281
18,60000;1,62287;4669,19988
18,64000;1,62615;4685,11842
18,68000;1,62950;4699,58298
18,72000;1,63285;4715,83195
18,76000;1,63614;4731,98444
18,80000;1,63943;4746,29067
18,84000;1,64290;4762,10713
18,88000;1,64624;4779,85106
18,92000;1,64947;4794,40279
18,96000;1,65288;4809,86498
19,00000;1,65623;4826,22758
19,04000;1,65952;4840,97935
19,08000;1,66287;4857,08043
19,12000;1,66633;4873,53653
19,16000;1,66956;4889,63798
19,20000;1,67291;4904,26272
19,24000;1,67626;4919,24919
19,28000;1,67955;4934,27627
19,32000;1,68289;4948,99340
19,36000;1,68618;4963,35849
19,40000;1,68953;4979,08071
19,44000;1,69288;4994,37787
19,48000;1,69623;5009,88178
19,52000;1,69952;5025,34844
19,56000;1,70292;5041,57208
19,60000;1,70627;5057,08978
19,64000;1,70956;5072,50652
19,68000;1,71297;5088,55768
19,72000;1,71632;5104,59617
19,76000;1,71961;5119,58562
19,80000;1,72289;5134,13735
19,84000;1,72624;5149,23669
19,88000;1,72959;5165,28264
19,92000;1,73282;5180,16405
19,96000;1,73623;5195,10061
20,00000;1,73964;5211,73365
20,04000;1,74286;5226,74993
20,08000;1,74621;5240,21126
20,12000;1,74956;5255,64812
20,16000;1,75279;5271,03208
20,20000;1,75614;5285,10772
20,24000;1,75954;5301,41219
20,28000;1,76289;5318,20618
20,32000;1,76630;5332,26132
20,36000;1,76959;5345,71782
20,40000;1,77288;5360,58173
20,44000;1,77623;5375,75707
20,48000;1,77957;5390,26335
20,52000;1,78286;5405,99674
20,56000;1,78621;5421,54051
20,60000;1,78956;5436,21741
20,64000;1,79285;5450,45249
20,68000;1,79614;5464,71179
20,72000;1,79954;5479,69230
20,76000;1,80283;5495,64026
20,80000;1,80612;5511,19521
20,84000;1,80959;5526,94388
20,88000;1,81300;5541,45873
20,92000;1,81623;5554,72113
20,96000;1,81963;5569,38611
21,00000;1,82298;5584,58418
21,04000;1,82621;5598,67322
21,08000;1,82950;5612,00380
21,12000;1,83291;5627,79792
21,16000;1,83620;5642,93265
21,20000;1,83954;5656,94608
21,24000;1,84289;5672,16016
21,28000;1,84618;5686,78863
21,32000;1,84953;5701,16378
21,36000;1,85282;5716,17037
21,40000;1,85616;5730,74184
21,44000;1,85951;5744,97208
21,48000;1,86286;5759,92838
21,52000;1,86621;5774,22753
21,56000;1,86956;5787,84868
21,60000;1,87291;5802,48088
21,64000;1,87619;5816,62282
21,68000;1,87948;5830,02865
21,72000;1,88289;5844,86052
21,76000;1,88624;5859,77398
21,80000;1,88953;5873,66335
21,84000;1,89294;5888,76978
21,88000;1,89628;5903,25855
21,92000;1,89945;5916,97544
21,96000;1,90286;5931,30663
22,00000;1,90627;5947,22964
22,04000;1,90950;5961,83576
22,08000;1,91290;5974,86980
22,12000;1,91631;5990,69856
22,16000;1,91954;6005,00591
22,20000;1,92283;6018,57714
22,24000;1,92624;6033,66569
22,28000;1,92953;6048,10603
22,32000;1,93293;6062,32658
22,36000;1,93622;6075,96599
22,40000;1,93957;6091,29183
22,44000;1,94292;6105,71653
22,48000;1,94621;6119,99035
22,52000;1,94956;6133,47255
22,56000;1,95290;6148,60840
22,60000;1,95631;6163,11543
22,64000;1,95960;6176,91763
22,68000;1,96289;6190,49557
22,72000;1,96636;6204,65539
22,76000;1,96965;6218,19124
22,80000;1,97287;6231,91111
22,84000;1,97622;6246,68486
22,88000;1,97963;6261,89113
22,92000;1,98286;6274,86557
22,96000;1,98627;6289,23029
23,00000;1,98967;6304,41755
23,04000;1,99290;6318,86050
23,08000;1,99625;6333,40180
23,12000;1,99960;6347,22859
23,16000;2,00295;6361,61715
23,20000;2,00624;6374,98796
23,24000;2,00958;6388,27011
23,28000;2,01293;6402,89336
23,32000;2,01628;6415,17341
23,36000;2,01957;6428,92271
23,40000;2,02286;6443,07658
23,44000;2,02621;6457,73336
23,48000;2,02955;6470,10878
23,52000;2,03290;6483,82977
23,56000;2,03619;6498,10806
23,60000;2,03960;6512,25597
23,64000;2,04295;6525,26394
23,68000;2,04618;6539,66591
23,72000;2,04958;6554,59836
23,76000;2,05299;6569,18809
23,80000;2,05622;6582,37338
23,84000;2,05951;6594,82405
23,88000;2,06292;6608,42583
23,92000;2,06615;6622,53723
23,96000;2,06943;6634,48349
24,00000;2,07290;6648,64257
24,04000;2,07619;6664,46313
24,08000;2,07954;6674,96622
24,12000;2,08283;6687,69553
24,16000;2,08617;6701,34425
24,20000;2,08952;6714,12125
24,24000;2,09287;6727,70664
24,28000;2,09628;6742,16673
24,32000;2,09963;6757,14388
24,36000;2,10292;6768,82118
24,40000;2,10620;6781,04833
24,44000;2,10961;6793,65173
24,48000;2,11290;6805,97723
24,52000;2,11595;6818,33997
24,56000;2,11960;6831,70557
24,60000;2,12289;6844,97803
24,64000;2,12623;6858,30861
24,68000;2,12946;6870,60282
24,72000;2,13287;6883,58769
24,76000;2,13622;6898,40913
24,80000;2,13951;6910,30473
24,84000;2,14292;6923,56825
24,88000;2,14632;6937,26912
24,92000;2,14961;6951,72325
24,96000;2,15296;6963,42289
25,00000;2,15631;6974,96980
25,04000;2,15954;6987,36310
25,08000;2,16288;6999,76310
25,12000;2,16623;7013,02588
25,16000;2,16958;7027,36825
25,20000;2,17293;7039,92918
25,24000;2,17622;7051,61616
25,28000;2,17957;7064,47661
25,32000;2,18285;7077,08299
25,36000;2,18620;7089,81454
25,40000;2,18925;7102,46190
25,44000;2,19296;7117,05759
25,48000;2,19631;7131,54376
25,52000;2,19966;7143,82380
25,56000;2,20294;7155,87959
25,60000;2,20623;7167,99647
25,64000;2,20964;7180,82413
25,68000;2,21287;7193,85967
25,72000;2,21634;7208,73475
25,76000;2,21963;7223,05402
25,80000;2,22285;7234,46831
25,84000;2,22620;7246,25513
25,88000;2,22955;7258,47930
25,92000;2,23284;7271,14901
25,96000;2,23619;7283,23981
26,00000;2,23953;7296,19637
26,04000;2,24288;7310,76375
26,08000;2,24611;7322,55206
26,12000;2,24964;7337,30718
26,16000;2,25287;7351,87232
26,20000;2,25622;7362,45066
26,24000;2,25950;7375,78645
26,28000;2,26285;7389,33012
26,32000;2,26626;7402,76799
26,36000;2,26961;7416,69163
26,40000;2,27284;7428,71463
26,44000;2,27619;7440,21162
26,48000;2,27953;7453,76647
26,52000;2,28288;7465,84907
26,56000;2,28611;7477,44516
26,60000;2,28958;7491,54463
26,64000;2,29287;7503,68237
26,68000;2,29616;7516,06002
26,72000;2,29950;7529,17752
26,76000;2,30291;7541,84127
26,80000;2,30614;7555,12714
26,84000;2,30949;7568,56874
26,88000;2,31296;7582,15338
26,92000;2,31613;7596,31768
26,96000;2,31947;7607,66119
27,00000;2,32288;7622,04379
27,04000;2,32617;7636,07770
27,08000;2,32952;7647,43462
27,12000;2,33287;7660,62960
27,16000;2,33621;7674,69183
27,20000;2,33950;7687,42263
27,24000;2,34285;7700,07670
27,28000;2,34620;7714,92273
27,32000;2,34955;7727,06941
27,36000;2,35290;7740,02299
27,40000;2,35624;7754,16419
27,44000;2,35953;7767,21239
27,48000;2,36288;7779,88061
27,52000;2,36623;7792,20015
27,56000;2,36952;7804,82143
27,60000;2,37293;7818,41874
27,64000;2,37627;7831,66140
27,68000;2,37950;7845,16633
27,72000;2,38291;7857,00753
27,76000;2,38632;7870,48340
27,80000;2,38955;7882,13760
27,84000;2,39290;7894,01755
27,88000;2,39630;7907,47851
27,92000;2,39953;7921,65920
27,96000;2,40288;7933,18972
28,00000;2,40623;7945,77301
28,04000;2,40958;7960,03640
28,08000;2,41286;7971,59299
28,12000;2,41621;7984,60320
28,16000;2,41956;7998,20200
28,20000;2,42291;8008,51211
28,24000;2,42620;8020,69530
28,28000;2,42961;8035,99060
28,32000;2,43295;8048,07767
28,36000;2,43624;8059,78179
28,40000;2,43965;8071,38085
28,44000;2,44294;8084,84107
28,48000;2,44635;8096,30975
28,52000;2,44958;8108,26197
28,56000;2,45286;8121,25504
28,60000;2,45621;8133,91954
28,64000;2,45962;8146,16531
28,68000;2,46285;8157,84559
28,72000;2,46626;8169,82538
28,76000;2,46960;8183,82055
28,80000;2,47283;8195,01579
28,84000;2,47618;8205,96516
28,88000;2,47959;8219,52969
28,92000;2,48288;8232,81333
28,96000;2,48623;8244,09649
29,00000;2,48957;8255,79986
29,04000;2,49292;8267,59264
29,08000;2,49621;8277,64794
29,12000;2,49950;8288,84766
29,16000;2,50285;8299,92816
29,20000;2,50608;8311,69859
29,24000;2,50954;8325,46055
29,28000;2,51289;8337,17585
29,32000;2,51618;8348,55512
29,36000;2,51953;8359,10514
29,40000;2,52282;8370,35701
29,44000;2,52611;8382,43589
29,48000;2,52951;8394,27263
29,52000;2,53292;8405,10055
29,56000;2,53621;8416,73389
29,60000;2,53962;8429,63755
29,64000;2,54297;8441,59797
29,68000;2,54620;8451,99600
29,72000;2,54954;8462,50877
29,76000;2,55289;8474,12944
29,80000;2,55618;8484,72416
29,84000;2,55953;8494,50156
29,88000;2,56300;8506,89635
29,92000;2,56622;8520,71717
29,96000;2,56957;8530,20400
30,00000;2,57292;8540,97903
30,04000;2,57621;8551,84123
30,08000;2,57962;8561,87716
30,12000;2,58285;8571,99207
30,16000;2,58631;8584,85028
30,20000;2,58966;8596,07086
30,24000;2,59295;8605,34683
30,28000;2,59630;8616,44521
30,32000;2,59965;8628,95474
30,36000;2,60294;8637,93492
30,40000;2,60628;8648,35531
30,44000;2,60957;8659,90520
30,48000;2,61298;8671,38803
30,52000;2,61633;8680,42409
30,56000;2,61956;8691,09482
30,60000;2,62296;8701,79385
30,64000;2,62637;8713,47785
30,68000;2,62960;8722,74190
30,72000;2,63289;8732,69439
30,76000;2,63630;8744,04088
30,80000;2,63959;8754,39942
30,84000;2,64287;8764,79447
30,88000;2,64628;8775,37653
30,92000;2,64963;8788,48210
30,96000;2,65292;8797,57702
31,00000;2,65627;8807,39912
31,04000;2,65962;8818,85812
31,08000;2,66290;8828,68096
31,12000;2,66625;8838,41664
31,16000;2,66954;8847,79617
31,20000;2,67289;8858,60845
31,24000;2,67618;8868,26143
31,28000;2,67953;8878,43668
31,32000;2,68293;8889,89642
31,36000;2,68622;8900,75788
31,40000;2,68957;8910,08377
31,44000;2,69274;8920,02508
31,48000;2,69627;8932,77898
31,52000;2,69962;8944,27598
31,56000;2,70290;8953,09001
31,60000;2,70625;8963,59384
31,64000;2,70960;8974,40687
31,68000;2,71283;8984,59032
31,72000;2,71618;8993,15998
31,76000;2,71953;9004,52510
31,80000;2,72287;9018,60967
31,84000;2,72622;9027,87000
31,88000;2,72951;9037,21601
31,92000;2,73286;9049,36939
31,96000;2,73621;9059,77190
32,00000;2,73955;9069,37718
32,04000;2,74272;9079,36767
32,08000;2,74625;9091,99193
32,12000;2,74960;9102,48682
32,16000;2,75289;9111,96321
32,20000;2,75624;9121,62885
32,24000;2,75958;9132,66316
32,28000;2,76293;9142,17979
32,32000;2,76616;9151,51387
32,36000;2,76939;9163,41469
32,40000;2,77298;9175,42502
32,44000;2,77621;9186,26785
32,48000;2,77955;9196,32837
32,52000;2,78296;9205,91727
32,56000;2,78619;9215,41899
32,60000;2,78954;9225,42661
32,64000;2,79295;9235,67563
32,68000;2,79618;9246,45811
32,72000;2,79946;9256,20720
32,76000;2,80299;9268,16016
32,80000;2,80628;9279,14307
32,84000;2,80957;9287,82672
32,88000;2,81298;9297,23009
32,92000;2,81626;9308,59298
32,96000;2,81961;9317,86448
33,00000;2,82296;9327,86390
33,04000;2,82625;9338,15017
33,08000;2,82954;9348,08627
33,12000;2,83295;9359,33515
33,16000;2,83629;9369,16396
33,20000;2,83958;9379,12166
33,24000;2,84293;9389,48989
33,28000;2,84622;9399,84471
33,32000;2,84957;9410,56758
33,36000;2,85286;9420,55881
33,40000;2,85620;9430,36303
33,44000;2,85949;9441,16786
33,48000;2,86290;9451,95258
33,52000;2,86625;9461,70092
33,56000;2,86954;9470,87035
33,60000;2,87289;9481,42856
33,64000;2,87623;9492,28182
33,68000;2,87952;9501,28958
33,72000;2,88281;9509,45690
33,76000;2,88622;9520,66779
33,80000;2,88951;9530,31182
33,84000;2,89280;9539,50360
33,88000;2,89614;9549,89493
33,92000;2,89955;9560,97469
33,96000;2,90284;9570,97784
34,00000;2,90613;9580,59281
34,04000;2,90960;9592,14792
34,08000;2,91288;9602,59736
34,12000;2,91623;9612,01862
34,16000;2,91958;9621,81315
34,20000;2,92293;9632,10166
34,24000;2,92622;9642,40506
34,28000;2,92957;9651,65868
34,32000;2,93279;9662,12600
34,36000;2,93620;9671,98238
34,40000;2,93955;9681,41481
34,44000;2,94278;9690,65353
34,48000;2,94619;9700,28043
34,52000;2,94953;9711,12624
34,56000;2,95282;9720,52440
34,60000;2,95617;9730,01570
34,64000;2,95958;9741,34132
34,68000;2,96287;9750,35802
34,72000;2,96622;9758,46127
34,76000;2,96962;9768,47038
34,80000;2,97291;9779,01369
34,84000;2,97620;9788,72702
34,88000;2,97955;9799,03638
34,92000;2,98290;9809,89635
34,96000;2,98619;9820,19305
35,00000;2,98953;9829,65678
35,04000;2,99294;9841,50320
35,08000;2,99617;9851,16363
35,12000;2,99952;9861,81051
35,16000;3,00293;9872,58777
35,20000;3,00622;9883,65486
35,24000;3,00956;9893,20576
35,28000;3,01291;9903,30726
35,32000;3,01620;9912,98631
35,36000;3,01955;9922,88962
35,40000;3,02290;9933,93511
35,44000;3,02619;9944,05672
35,48000;3,02959;9954,78854
35,52000;3,03294;9965,13069
35,56000;3,03623;9975,85356
35,60000;3,03958;9985,49312
35,64000;3,04293;9995,88966
35,68000;3,04615;10006,35922
35,72000;3,04950;10015,14494
35,76000;3,05291;10027,22308
35,80000;3,05632;10038,14861
35,84000;3,05961;10047,05727
35,88000;3,06296;10057,14759
35,92000;3,06630;10067,55605
35,96000;3,06953;10076,53996
36,00000;3,07288;10086,31065
36,04000;3,07623;10097,61244
36,08000;3,07958;10108,73616
36,12000;3,08287;10117,83481
36,16000;3,08627;10128,42432
36,20000;3,08962;10138,38053
36,24000;3,09297;10148,73683
36,28000;3,09620;10158,45165
36,32000;3,09955;10168,80199
36,36000;3,10290;10179,65749
36,40000;3,10624;10189,28513
36,44000;3,10953;10200,58915
36,48000;3,11294;10210,51705
36,52000;3,11629;10221,43736
36,56000;3,11952;10231,10673
36,60000;3,12286;10241,18885
36,64000;3,12621;10252,70075
36,68000;3,12956;10263,47876
36,72000;3,13291;10272,83669
36,76000;3,13626;10282,81972
36,80000;3,13961;10294,03880
36,84000;3,14289;10302,84837
36,88000;3,14618;10312,22418
36,92000;3,14959;10323,33896
36,96000;3,15294;10333,86588
37,00000;3,15623;10342,63372
37,04000;3,15964;10351,78006
37,08000;3,16292;10362,36659
37,12000;3,16621;10371,57774
37,16000;3,16956;10380,76356
37,20000;3,17285;10390,94329
37,24000;3,17626;10401,67585
37,28000;3,17955;10410,84826
37,32000;3,18283;10420,82086
37,36000;3,18630;10431,53256
37,40000;3,18965;10441,42693
37,44000;3,19282;10451,07022
37,48000;3,19623;10460,40729
37,52000;3,19963;10471,62935
37,56000;3,20292;10481,29350
37,60000;3,20627;10490,32360
37,64000;3,20962;10500,26342
37,68000;3,21291;10510,25540
37,72000;3,21620;10519,18045
37,76000;3,21960;10528,67696
37,80000;3,22295;10539,20239
37,84000;3,22624;10548,39939
37,88000;3,22953;10557,70218
37,92000;3,23294;10568,34161
37,96000;3,23623;10576,94927
38,00000;3,23951;10586,27963
38,04000;3,24298;10596,15090
38,08000;3,24627;10606,70912
38,12000;3,24962;10615,68037
38,16000;3,25297;10624,76635
38,20000;3,25626;10635,54212
38,24000;3,25960;10645,01703
38,28000;3,26289;10654,61934
38,32000;3,26624;10664,62025
38,36000;3,26959;10675,34536
38,40000;3,27294;10684,13258
38,44000;3,27617;10692,67094
38,48000;3,27951;10701,86347
38,52000;3,28292;10713,00283
38,56000;3,28621;10722,85101
38,60000;3,28950;10731,30742
38,64000;3,29297;10743,33340
38,68000;3,29631;10752,55871
38,72000;3,29966;10760,78564
38,76000;3,30295;10769,28675
38,80000;3,30636;10778,48077
38,84000;3,30959;10788,82441
38,88000;3,31276;10797,06624
38,92000;3,31634;10808,43732
38,96000;3,31957;10818,69751
39,00000;3,32292;10825,56620
39,04000;3,32621;10834,73340
39,08000;3,32956;10845,08374
39,12000;3,33291;10854,66966
39,16000;3,33601;10863,66251
39,20000;3,33960;10875,15131
39,24000;3,34295;10885,73858
39,28000;3,34630;10895,54802
39,32000;3,34959;10904,31437
39,36000;3,35293;10912,32374
39,40000;3,35628;10920,97014
39,44000;3,35951;10929,05402
39,48000;3,36286;10937,28468
39,52000;3,36627;10947,77957
39,56000;3,36956;10956,68450
39,60000;3,37261;10964,54114
39,64000;3,37625;10975,66336
39,68000;3,37960;10986,61348
39,72000;3,38289;10993,59989
39,76000;3,38624;11002,28652
39,80000;3,38959;11011,26149
39,84000;3,39287;11020,90925
39,88000;3,39622;11027,96346
39,92000;3,39945;11037,83995
39,96000;3,40292;11049,33470
40,00000;3,40627;11057,98408
40,04000;3,40962;11066,30936
40,08000;3,41290;11076,14636
40,12000;3,41625;11084,48878
40,16000;3,41954;11093,73122
40,20000;3,42283;11102,80976
40,24000;3,42618;11111,52470
40,28000;3,42958;11120,61217
40,32000;3,43281;11131,34548
40,36000;3,43622;11139,87789
40,40000;3,43957;11149,05477
40,44000;3,44280;11156,38390
40,48000;3,44621;11164,81870
40,52000;3,44955;11174,87624
40,56000;3,45284;11183,35798
40,60000;3,45613;11192,02450
40,64000;3,45960;11201,72217
40,68000;3,46289;11212,14256
40,72000;3,46618;11219,60431
40,76000;3,46952;11228,18366
40,80000;3,47287;11236,71308
40,84000;3,47616;11245,87730
40,88000;3,47945;11254,62502
40,92000;3,48292;11263,50686
40,96000;3,48621;11274,40110
41,00000;3,48955;11282,41196
41,04000;3,49290;11291,20067
41,08000;3,49625;11300,70165
41,12000;3,49960;11309,64905
41,16000;3,50289;11317,18978
41,20000;3,50618;11325,57541
41,24000;3,50958;11334,71802
41,28000;3,51293;11343,38006
41,32000;3,51616;11351,89086
41,36000;3,51957;11361,92903
41,40000;3,52292;11369,98311
41,44000;3,52620;11378,98564
41,48000;3,52949;11386,09722
41,52000;3,53290;11394,65198
41,56000;3,53625;11404,20064
41,60000;3,53954;11411,66389
41,64000;3,54289;11421,00319
41,68000;3,54629;11430,27321
41,72000;3,54952;11437,83554
41,76000;3,55287;11445,69889
41,80000;3,55628;11456,95299
41,84000;3,55957;11466,02705
41,88000;3,56286;11473,94627
41,92000;3,56626;11482,28794
41,96000;3,56955;11491,80457
42,00000;3,57290;11499,60086
42,04000;3,57631;11510,10916
42,08000;3,57960;11518,60505
42,12000;3,58294;11526,68819
42,16000;3,58623;11534,83316
42,20000;3,58952;11542,59890
42,24000;3,59293;11550,59636
42,28000;3,59622;11559,34185
42,32000;3,59951;11568,18643
42,36000;3,60286;11575,68768
42,40000;3,60620;11583,59274
42,44000;3,60949;11592,63849
42,48000;3,61284;11599,90951
42,52000;3,61619;11608,23554
42,56000;3,61948;11616,39541
42,60000;3,62282;11624,51506
42,64000;3,62623;11634,08533
42,68000;3,62964;11642,33238
42,72000;3,63281;11649,24353
42,76000;3,63622;11657,53901
42,80000;3,63963;11667,23296
42,84000;3,64285;11674,54869
42,88000;3,64614;11681,40993
42,92000;3,64961;11691,73941
42,96000;3,65284;11700,16006
43,00000;3,65619;11707,43927
43,04000;3,65954;11714,29008
43,08000;3,66282;11723,52061
43,12000;3,66623;11731,02185
43,16000;3,66952;11738,43667
43,20000;3,67287;11746,88190
43,24000;3,67628;11756,16682
43,28000;3,67951;11764,06667
43,32000;3,68297;11772,91870
43,36000;3,68638;11781,05101
43,40000;3,68967;11788,50159
43,44000;3,69296;11794,98583
43,48000;3,69625;11801,69955
43,52000;3,69959;11810,17086
43,56000;3,70270;11818,40003
43,60000;3,70623;11827,27665
43,64000;3,70958;11836,15625
43,68000;3,71299;11844,30793
43,72000;3,71622;11851,44186
43,76000;3,71950;11857,30100
43,80000;3,72297;11867,79514
43,84000;3,72626;11875,16674
43,88000;3,72961;11881,43343
43,92000;3,73290;11888,37290
43,96000;3,73636;11898,67705
44,00000;3,73965;11905,18513
44,04000;3,74300;11912,29746
44,08000;3,74629;11919,77113
44,12000;3,74964;11926,74935
44,16000;3,75299;11934,62163
44,20000;3,75627;11940,96282
44,24000;3,75962;11949,71800
44,28000;3,76297;11956,47195
44,32000;3,76626;11962,31991
44,36000;3,76955;11968,05015
44,40000;3,77296;11976,05208
44,44000;3,77630;11983,45870
44,48000;3,77959;11989,00640
44,52000;3,78294;11995,62177
44,56000;3,78635;12004,34044
44,60000;3,78958;12009,03356
44,64000;3,79287;12014,04706
44,68000;3,79627;12021,29722
44,72000;3,79956;12025,94042
44,76000;3,80285;12030,02557
44,80000;3,80626;12037,42325
44,84000;3,80955;12042,47400
44,88000;3,81290;12046,63143
44,92000;3,81618;12050,40738
44,96000;3,81953;12056,03033
45,00000;3,82288;12061,22264
45,04000;3,82623;12064,69312
45,08000;3,82952;12068,35508
45,12000;3,83287;12073,72323
45,16000;3,83615;12075,98150
45,20000;3,83944;12079,09659
45,24000;3,84285;12082,68702
45,28000;3,84620;12087,66997
45,32000;3,84949;12091,56066
45,36000;3,85289;12094,36134
45,40000;3,85624;12099,27723
45,44000;3,85959;12102,62626
45,48000;3,86288;12104,48071
45,52000;3,86623;12106,87980
45,56000;3,86964;12110,32122
45,60000;3,87286;12111,63923
45,64000;3,87633;12114,17541
45,68000;3,87968;12118,07504
45,72000;3,88291;12119,72013
45,76000;3,88626;12120,01964
45,80000;3,88949;12121,64462
45,84000;3,89295;12124,75672
45,88000;3,89630;12125,86462
45,92000;3,89965;12125,18439
45,96000;3,90294;12125,06741
46,00000;3,90629;12123,02446
46,04000;3,90963;12121,02622
46,08000;3,91292;12118,34773
46,12000;3,91627;12113,48549
46,16000;3,91968;12110,32942
46,20000;3,92291;12099,95970
46,24000;3,92626;12083,51105
46,28000;3,92966;12060,68546
46,32000;3,93295;12020,96641
46,36000;3,93624;11940,78028
46,40000;3,93941;11552,23846
46,43400;3,94419;2379,31684