File: SU - Suspension/05 - Essais/Excels essais Optimus/collage alu carbone 05_02_19/collage4.is_tens_RawData/Specimen_RawData_1.csv
Temps;Déplacement;Charge
(sec);(mm);(N)
0,00000;0,01632;53,86533
0,04000;0,01686;53,53980
0,08000;0,01907;59,78565
0,12000;0,02224;73,69378
0,16000;0,02595;87,60730
0,20000;0,02972;103,39271
0,24000;0,03348;117,06789
0,28000;0,03731;131,69026
0,32000;0,04096;145,93067
0,36000;0,04448;159,75056
0,40000;0,04807;174,27396
0,44000;0,05148;111,99798
0,48000;0,05489;91,74685
0,52000;0,05829;99,44361
0,56000;0,06176;116,95308
0,60000;0,06505;133,25516
0,64000;0,06846;143,42200
0,68000;0,07181;158,79093
0,72000;0,07510;173,29366
0,76000;0,07844;184,76314
0,80000;0,08179;198,31376
0,84000;0,08508;212,68879
0,88000;0,08849;226,56941
0,92000;0,09184;241,64831
0,96000;0,09513;258,12676
1,00000;0,09847;274,83108
1,04000;0,10182;291,94006
1,08000;0,10517;308,62261
1,12000;0,10846;326,13894
1,16000;0,11187;343,80923
1,20000;0,11521;362,29156
1,24000;0,11850;379,26461
1,28000;0,12185;397,54533
1,32000;0,12526;415,65849
1,36000;0,12855;434,31390
1,40000;0,13190;452,48293
1,44000;0,13530;471,21109
1,48000;0,13853;489,55795
1,52000;0,14182;507,47418
1,56000;0,14523;524,87771
1,60000;0,14846;542,52753
1,64000;0,15187;558,43019
1,68000;0,15515;574,60531
1,72000;0,15850;589,62042
1,76000;0,16185;604,15827
1,80000;0,16520;617,11455
1,84000;0,16849;629,22933
1,88000;0,17183;640,34802
1,92000;0,17524;650,60658
1,96000;0,17847;660,68228
2,00000;0,18188;670,37037
2,04000;0,18529;681,34931
2,08000;0,18858;692,04876
2,12000;0,19180;700,77125
2,16000;0,19515;711,90600
2,20000;0,19856;722,61947
2,24000;0,20179;732,92856
2,28000;0,20514;743,88105
2,32000;0,20855;755,28510
2,36000;0,21177;764,05550
2,40000;0,21512;773,96277
2,44000;0,21853;784,75801
2,48000;0,22182;795,01858
2,52000;0,22511;805,19849
2,56000;0,22846;816,77958
2,60000;0,23180;828,34773
2,64000;0,23509;839,04630
2,68000;0,23844;849,77401
2,72000;0,24173;861,92945
2,76000;0,24514;873,74179
2,80000;0,24837;886,01215
2,84000;0,25171;898,36484
2,88000;0,25506;911,24047
2,92000;0,25841;923,74068
2,96000;0,26176;937,87741
3,00000;0,26511;951,79388
3,04000;0,26845;966,21653
3,08000;0,27180;979,67498
3,12000;0,27509;994,35262
3,16000;0,27850;1008,20698
3,20000;0,28185;1022,88350
3,24000;0,28514;1035,75019
3,28000;0,28854;1050,05791
3,32000;0,29189;1064,93104
3,36000;0,29518;1078,86158
3,40000;0,29847;1091,37231
3,44000;0,30182;1106,16954
3,48000;0,30511;1120,22571
3,52000;0,30845;1133,11186
3,56000;0,31186;1147,26359
3,60000;0,31515;1161,00051
3,64000;0,31850;1173,79893
3,68000;0,32179;1186,58179
3,72000;0,32514;1201,01310
3,76000;0,32848;1214,13879
3,80000;0,33177;1227,31347
3,84000;0,33518;1241,02356
3,88000;0,33859;1255,01454
3,92000;0,34188;1267,77450
3,96000;0,34522;1280,47690
4,00000;0,34851;1293,77274
4,04000;0,35180;1308,57676
4,08000;0,35515;1322,20192
4,12000;0,35844;1334,66143
4,16000;0,36185;1348,95211
4,20000;0,36519;1363,13085
4,24000;0,36842;1377,86549
4,28000;0,37183;1391,09055
4,32000;0,37518;1406,15348
4,36000;0,37853;1420,28052
4,40000;0,38188;1433,12411
4,44000;0,38516;1447,05763
4,48000;0,38851;1460,53927
4,52000;0,39186;1473,67725
4,56000;0,39515;1486,88182
4,60000;0,39844;1499,95238
4,64000;0,40185;1512,62982
4,68000;0,40513;1526,72734
4,72000;0,40848;1539,65922
4,76000;0,41183;1553,40275
4,80000;0,41518;1566,85114
4,84000;0,41847;1579,68570
4,88000;0,42176;1592,56551
4,92000;0,42516;1605,95514
4,96000;0,42851;1618,43840
5,00000;0,43180;1630,01493
5,04000;0,43521;1642,95547
5,08000;0,43856;1655,54956
5,12000;0,44178;1667,12049
5,16000;0,44513;1679,61512
5,20000;0,44854;1692,61284
5,24000;0,45183;1705,87096
5,28000;0,45518;1718,43804
5,32000;0,45859;1732,03889
5,36000;0,46187;1744,84998
5,40000;0,46516;1757,71229
5,44000;0,46851;1770,30973
5,48000;0,47186;1784,04935
5,52000;0,47521;1795,94923
5,56000;0,47850;1807,94671
5,60000;0,48190;1820,73731
5,64000;0,48519;1832,91938
5,68000;0,48842;1843,80710
5,72000;0,49189;1857,94197
5,76000;0,49518;1871,60317
5,80000;0,49852;1882,95469
5,84000;0,50181;1893,98825
5,88000;0,50510;1906,22248
5,92000;0,50857;1919,65476
5,96000;0,51186;1931,78710
6,00000;0,51515;1943,87659
6,04000;0,51861;1956,26877
6,08000;0,52196;1970,11828
6,12000;0,52519;1980,70891
6,16000;0,52848;1991,79668
6,20000;0,53183;2003,51607
6,24000;0,53512;2015,74806
6,28000;0,53822;2027,59746
6,32000;0,54187;2040,83771
6,36000;0,54516;2053,25019
6,40000;0,54845;2063,08514
6,44000;0,55174;2074,44150
6,48000;0,55509;2086,21453
6,52000;0,55843;2097,01136
6,56000;0,56184;2108,95948
6,60000;0,56513;2120,16031
6,64000;0,56854;2131,29520
6,68000;0,57183;2142,37440
6,72000;0,57517;2153,87493
6,76000;0,57840;2163,83059
6,80000;0,58181;2175,25959
6,84000;0,58516;2185,14372
6,88000;0,58839;2194,82966
6,92000;0,59180;2206,41010
6,96000;0,59514;2217,65395
7,00000;0,59837;2227,80630
7,04000;0,60172;2237,60772
7,08000;0,60513;2248,57964
7,12000;0,60836;2257,92490
7,16000;0,61171;2266,62941
7,20000;0,61523;2276,99541
7,24000;0,61846;2288,18059
7,28000;0,62181;2296,88417
7,32000;0,62510;2306,00815
7,36000;0,62845;2315,68255
7,40000;0,63180;2324,72233
7,44000;0,63508;2333,79323
7,48000;0,63855;2343,93682
7,52000;0,64184;2353,44991
7,56000;0,64513;2361,89924
7,60000;0,64848;2370,41749
7,64000;0,65177;2379,56736
7,68000;0,65511;2388,61144
7,72000;0,65834;2396,75716
7,76000;0,66181;2407,01959
7,80000;0,66516;2417,15759
7,84000;0,66851;2425,61977
7,88000;0,67179;2434,44685
7,92000;0,67514;2442,84328
7,96000;0,67831;2451,92312
8,00000;0,68178;2461,76906
8,04000;0,68519;2471,45779
8,08000;0,68854;2480,66671
8,12000;0,69176;2489,53588
8,16000;0,69511;2497,58512
8,20000;0,69846;2507,85127
8,24000;0,70175;2517,31593
8,28000;0,70510;2525,41676
8,32000;0,70851;2535,21185
8,36000;0,71185;2545,21240
8,40000;0,71514;2553,93535
8,44000;0,71849;2563,49873
8,48000;0,72184;2573,10458
8,52000;0,72519;2582,28928
8,56000;0,72853;2591,46616
8,60000;0,73182;2600,99620
8,64000;0,73517;2610,04269
8,68000;0,73846;2620,13245
8,72000;0,74175;2629,45835
8,76000;0,74510;2640,36413
8,80000;0,74844;2652,33833
8,84000;0,75179;2664,67333
8,88000;0,75508;2677,46057
8,92000;0,75849;2692,36304
8,96000;0,76184;2707,01963
9,00000;0,76507;2721,36834
9,04000;0,76841;2735,51699
9,08000;0,77182;2750,33992
9,12000;0,77505;2764,90264
9,16000;0,77846;2778,37999
9,20000;0,78187;2794,73867
9,24000;0,78516;2808,82604
9,28000;0,78838;2822,28999
9,32000;0,79179;2837,43236
9,36000;0,79508;2852,50619
9,40000;0,79831;2866,37302
9,44000;0,80172;2882,56276
9,48000;0,80513;2898,14249
9,52000;0,80841;2913,22470
9,56000;0,81176;2926,87565
9,60000;0,81511;2941,46277
9,64000;0,81840;2956,00463
9,68000;0,82175;2970,87785
9,72000;0,82509;2985,03824
9,76000;0,82838;3001,12516
9,80000;0,83179;3015,42059
9,84000;0,83514;3029,74880
9,88000;0,83843;3044,60544
9,92000;0,84178;3059,18790
9,96000;0,84506;3073,17134
10,00000;0,84835;3087,28684
10,04000;0,85176;3102,53408
10,08000;0,85517;3117,07612
10,12000;0,85840;3130,79953
10,16000;0,86175;3144,98991
10,20000;0,86515;3159,78676
10,24000;0,86844;3174,77360
10,28000;0,87173;3188,79262
10,32000;0,87514;3203,82640
10,36000;0,87843;3219,55867
10,40000;0,88178;3233,86192
10,44000;0,88506;3248,38459
10,48000;0,88853;3264,51771
10,52000;0,89188;3279,59806
10,56000;0,89511;3293,60850
10,60000;0,89852;3307,60032
10,64000;0,90175;3323,52519
10,68000;0,90527;3338,18533
10,72000;0,90856;3352,75121
10,76000;0,91191;3367,41395
10,80000;0,91526;3381,27501
10,84000;0,91855;3396,06628
10,88000;0,92177;3409,43076
10,92000;0,92512;3423,13349
10,96000;0,92847;3437,74669
11,00000;0,93182;3453,47300
11,04000;0,93523;3468,95158
11,08000;0,93858;3483,62625
11,12000;0,94186;3497,66500
11,16000;0,94509;3511,24145
11,20000;0,94856;3526,93647
11,24000;0,95191;3542,04550
11,28000;0,95514;3554,54609
11,32000;0,95849;3567,31191
11,36000;0,96189;3582,51520
11,40000;0,96518;3597,04532
11,44000;0,96847;3610,70596
11,48000;0,97182;3625,57732
11,52000;0,97511;3640,18232
11,56000;0,97845;3652,98763
11,60000;0,98168;3665,69161
11,64000;0,98515;3680,65052
11,68000;0,98850;3694,51120
11,72000;0,99179;3706,96671
11,76000;0,99508;3719,98101
11,80000;0,99848;3733,23075
11,84000;1,00189;3745,87700
11,88000;1,00500;3758,19504
11,92000;1,00853;3771,15645
11,96000;1,01188;3784,88861
12,00000;1,01505;3795,64799
12,04000;1,01839;3808,86234
12,08000;1,02186;3822,28680
12,12000;1,02515;3834,72368
12,16000;1,02844;3844,99095
12,20000;1,03179;3856,55127
12,24000;1,03514;3869,57638
12,28000;1,03848;3879,80901
12,32000;1,04171;3890,45663
12,36000;1,04518;3902,02180
12,40000;1,04853;3912,59715
12,44000;1,05182;3922,16034
12,48000;1,05516;3932,97486
12,52000;1,05851;3943,36246
12,56000;1,06180;3953,30004
12,60000;1,06515;3962,23068
12,64000;1,06844;3973,39240
12,68000;1,07185;3984,04114
12,72000;1,07519;3993,16959
12,76000;1,07842;4003,47561
12,80000;1,08183;4013,58940
12,84000;1,08518;4022,82588
12,88000;1,08841;4032,97469
12,92000;1,09182;4042,12885
12,96000;1,09522;4052,43076
13,00000;1,09845;4061,96527
13,04000;1,10186;4071,54225
13,08000;1,10527;4082,84739
13,12000;1,10856;4093,51364
13,16000;1,11185;4101,31924
13,20000;1,11519;4110,88057
13,24000;1,11860;4122,52918
13,28000;1,12189;4132,22350
13,32000;1,12518;4141,39964
13,36000;1,12853;4150,17381
13,40000;1,13182;4158,83660
13,44000;1,13516;4167,57017
13,48000;1,13851;4176,51422
13,52000;1,14168;4184,90544
13,56000;1,14521;4195,68904
13,60000;1,14856;4202,80807
13,64000;1,15178;4209,59555
13,68000;1,15519;4216,43555
13,72000;1,15854;4222,40384
13,76000;1,16177;4227,96421
13,80000;1,16530;4234,56095
13,84000;1,16853;4241,17334
13,88000;1,17175;4245,55615
13,92000;1,17510;4249,62305
13,96000;1,17845;4254,30015
14,00000;1,18174;4259,05585
14,04000;1,18509;4263,74301
14,08000;1,18850;4268,63842
14,12000;1,19178;4275,58534
14,16000;1,19507;4279,68837
14,20000;1,19836;4284,90117
14,24000;1,20171;4290,54461
14,28000;1,20500;4294,58693
14,32000;1,20841;4299,92639
14,36000;1,21175;4306,70157
14,40000;1,21516;4314,68934
14,44000;1,21845;4320,84911
14,48000;1,22180;4327,25772
14,52000;1,22509;4334,48069
14,56000;1,22843;4341,88657
14,60000;1,23184;4349,55321
14,64000;1,23507;4357,80808
14,68000;1,23842;4366,49956
14,72000;1,24183;4375,06996
14,76000;1,24506;4384,33848
14,80000;1,24840;4392,06511
14,84000;1,25181;4402,14835
14,88000;1,25504;4411,15797
14,92000;1,25833;4420,46300
14,96000;1,26186;4431,91640
15,00000;1,26515;4442,26861
15,04000;1,26843;4450,28767
15,08000;1,27184;4460,99713
15,12000;1,27513;4472,49152
15,16000;1,27842;4481,85541
15,20000;1,28183;4492,79547
15,24000;1,28518;4504,01120
15,28000;1,28852;4513,92233
15,32000;1,29181;4524,92535
15,36000;1,29516;4535,43626
15,40000;1,29845;4545,42525
15,44000;1,30174;4555,08828
15,48000;1,30514;4565,92888
15,52000;1,30849;4576,34255
15,56000;1,31184;4587,20699
15,60000;1,31513;4598,72000
15,64000;1,31842;4609,15901
15,68000;1,32183;4620,62098
15,72000;1,32517;4631,93469
15,76000;1,32846;4642,72425
15,80000;1,33187;4653,03659
15,84000;1,33522;4664,42034
15,88000;1,33845;4674,35569
15,92000;1,34180;4684,04964
15,96000;1,34514;4696,03688
16,00000;1,34843;4706,67593
16,04000;1,35178;4716,38031
16,08000;1,35519;4727,88177
16,12000;1,35848;4739,75390
16,16000;1,36177;4748,74675
16,20000;1,36511;4758,80913
16,24000;1,36846;4769,67879
16,28000;1,37169;4779,84138
16,32000;1,37510;4789,82069
16,36000;1,37851;4801,80383
16,40000;1,38185;4813,33397
16,44000;1,38520;4822,25604
16,48000;1,38849;4832,07069
16,52000;1,39184;4843,05359
16,56000;1,39513;4852,83993
16,60000;1,39848;4863,79974
16,64000;1,40182;4874,99796
16,68000;1,40517;4884,66658
16,72000;1,40846;4894,31396
16,76000;1,41175;4905,29314
16,80000;1,41510;4914,26289
16,84000;1,41839;4924,92020
16,88000;1,42173;4935,71945
16,92000;1,42508;4945,86863
16,96000;1,42855;4957,21437
17,00000;1,43178;4967,13631
17,04000;1,43513;4975,92315
17,08000;1,43854;4985,67671
17,12000;1,44188;4996,19544
17,16000;1,44511;5006,51859
17,20000;1,44846;5017,35881
17,24000;1,45181;5029,12849
17,28000;1,45510;5040,59196
17,32000;1,45845;5052,98786
17,36000;1,46179;5066,54307
17,40000;1,46508;5079,41991
17,44000;1,46843;5092,52697
17,48000;1,47178;5105,91045
17,52000;1,47507;5119,74134
17,56000;1,47847;5134,03416
17,60000;1,48182;5147,76446
17,64000;1,48511;5162,22380
17,68000;1,48846;5177,17339
17,72000;1,49181;5192,39269
17,76000;1,49510;5206,02651
17,80000;1,49844;5220,81330
17,84000;1,50179;5237,21911
17,88000;1,50508;5252,21974
17,92000;1,50843;5267,17454
17,96000;1,51184;5283,02453
18,00000;1,51513;5299,08799
18,04000;1,51841;5313,26346
18,08000;1,52176;5328,87541
18,12000;1,52517;5344,87478
18,16000;1,52846;5359,96333
18,20000;1,53187;5375,26906
18,24000;1,53521;5391,99784
18,28000;1,53844;5407,38143
18,32000;1,54179;5422,59812
18,36000;1,54514;5437,69486
18,40000;1,54849;5454,13233
18,44000;1,55178;5469,86200
18,48000;1,55518;5484,69536
18,52000;1,55847;5501,03970
18,56000;1,56182;5516,53244
18,60000;1,56517;5530,64048
18,64000;1,56840;5546,35786
18,68000;1,57181;5563,01400
18,72000;1,57521;5578,28993
18,76000;1,57844;5592,92808
18,80000;1,58185;5607,92908
18,84000;1,58520;5624,13633
18,88000;1,58849;5640,04481
18,92000;1,59178;5654,18117
18,96000;1,59518;5670,75945
19,00000;1,59853;5687,34035
19,04000;1,60182;5701,95988
19,08000;1,60523;5717,94882
19,12000;1,60858;5734,47198
19,16000;1,61186;5748,82068
19,20000;1,61515;5763,28188
19,24000;1,61850;5779,43437
19,28000;1,62185;5794,67639
19,32000;1,62520;5809,11711
19,36000;1,62849;5823,63345
19,40000;1,63183;5838,37740
19,44000;1,63518;5853,32140
19,48000;1,63847;5868,88082
19,52000;1,64176;5884,14818
19,56000;1,64511;5898,68240
19,60000;1,64846;5913,82645
19,64000;1,65174;5929,05432
19,68000;1,65515;5943,86645
19,72000;1,65850;5959,46833
19,76000;1,66173;5974,37285
19,80000;1,66514;5989,09222
19,84000;1,66855;6004,80437
19,88000;1,67183;6020,39210
19,92000;1,67512;6034,49270
19,96000;1,67841;6048,56126
20,00000;1,68182;6064,97601
20,04000;1,68505;6078,90524
20,08000;1,68840;6093,30200
20,12000;1,69180;6110,74567
20,16000;1,69509;6124,61865
20,20000;1,69838;6138,55235
20,24000;1,70173;6152,62650
20,28000;1,70508;6168,12482
20,32000;1,70842;6182,68028
20,36000;1,71177;6197,32663
20,40000;1,71518;6214,31321
20,44000;1,71853;6229,66960
20,48000;1,72188;6242,89475
20,52000;1,72511;6258,22842
20,56000;1,72851;6271,80412
20,60000;1,73180;6286,49369
20,64000;1,73485;6301,66754
20,68000;1,73850;6317,49481
20,72000;1,74179;6333,59551
20,76000;1,74508;6348,74776
20,80000;1,74842;6362,99476
20,84000;1,75177;6378,10081
20,88000;1,75506;6392,91331
20,92000;1,75847;6409,62720
20,96000;1,76182;6424,75858
21,00000;1,76517;6439,89369
21,04000;1,76851;6454,78442
21,08000;1,77180;6469,67739
21,12000;1,77521;6485,06284
21,16000;1,77844;6500,40582
21,20000;1,78179;6515,55881
21,24000;1,78513;6530,26775
21,28000;1,78842;6546,39676
21,32000;1,79177;6561,73378
21,36000;1,79512;6577,06186
21,40000;1,79841;6592,09415
21,44000;1,80176;6607,68747
21,48000;1,80510;6621,54332
21,52000;1,80839;6637,10088
21,56000;1,81186;6654,13365
21,60000;1,81521;6668,20556
21,64000;1,81850;6682,76921
21,68000;1,82179;6696,54757
21,72000;1,82519;6711,25576
21,76000;1,82848;6726,03920
21,80000;1,83177;6740,59838
21,84000;1,83530;6756,45173
21,88000;1,83853;6773,72888
21,92000;1,84176;6786,69736
21,96000;1,84510;6799,96461
22,00000;1,84851;6814,36583
22,04000;1,85174;6828,72087
22,08000;1,85509;6842,90156
22,12000;1,85850;6858,80780
22,16000;1,86178;6874,14929
22,20000;1,86501;6887,46646
22,24000;1,86854;6904,06486
22,28000;1,87177;6919,81837
22,32000;1,87518;6932,62890
22,36000;1,87847;6946,67622
22,40000;1,88181;6962,66964
22,44000;1,88516;6977,84722
22,48000;1,88851;6991,97575
22,52000;1,89168;7005,85246
22,56000;1,89509;7019,69936
22,60000;1,89844;7034,03354
22,64000;1,90172;7047,20542
22,68000;1,90513;7061,00389
22,72000;1,90848;7077,30949
22,76000;1,91171;7091,19439
22,80000;1,91506;7104,40353
22,84000;1,91847;7118,73770
22,88000;1,92181;7133,24100
22,92000;1,92504;7146,86438
22,96000;1,92845;7161,44964
23,00000;1,93186;7177,21581
23,04000;1,93503;7191,26165
23,08000;1,93838;7205,01244
23,12000;1,94184;7219,13278
23,16000;1,94507;7234,04139
23,20000;1,94842;7247,13281
23,24000;1,95183;7261,86782
23,28000;1,95512;7275,82350
23,32000;1,95840;7290,03474
23,36000;1,96181;7305,87617
23,40000;1,96510;7320,53071
23,44000;1,96845;7334,38954
23,48000;1,97180;7348,77810
23,52000;1,97509;7363,87298
23,56000;1,97849;7378,81139
23,60000;1,98178;7393,47935
23,64000;1,98507;7406,90976
23,68000;1,98848;7421,49130
23,72000;1,99183;7435,54905
23,76000;1,99512;7451,26754
23,80000;1,99846;7465,48995
23,84000;2,00187;7479,96047
23,88000;2,00516;7493,89827
23,92000;2,00845;7507,11262
23,96000;2,01180;7520,92153
24,00000;2,01520;7536,08346
24,04000;2,01849;7550,88776
24,08000;2,02178;7565,51996
24,12000;2,02519;7579,87648
24,16000;2,02848;7594,23748
24,20000;2,03177;7607,15678
24,24000;2,03517;7621,15046
24,28000;2,03846;7636,53293
24,32000;2,04175;7649,54090
24,36000;2,04516;7664,09934
24,40000;2,04851;7679,16366
24,44000;2,05186;7693,71390
24,48000;2,05514;7707,30227
24,52000;2,05855;7721,34885
24,56000;2,06184;7735,54072
24,60000;2,06519;7749,62828
24,64000;2,06848;7763,42824
24,68000;2,07183;7777,65736
24,72000;2,07511;7791,16675
24,76000;2,07846;7805,89879
24,80000;2,08175;7819,24576
24,84000;2,08516;7833,69169
24,88000;2,08851;7847,67643
24,92000;2,09174;7861,85190
24,96000;2,09514;7875,58109
25,00000;2,09855;7890,66553
25,04000;2,10184;7904,97661
25,08000;2,10519;7918,67450
25,12000;2,10854;7932,78143
25,16000;2,11182;7947,31304
25,20000;2,11511;7960,20627
25,24000;2,11840;7973,32227
25,28000;2,12169;7987,04401
25,32000;2,12510;8001,13305
25,36000;2,12845;8017,01695
25,40000;2,13173;8030,96443
25,44000;2,13508;8044,45222
25,48000;2,13837;8057,67849
25,52000;2,14166;8070,30126
25,56000;2,14507;8086,55173
25,60000;2,14848;8100,28166
25,64000;2,15176;8112,66527
25,68000;2,15511;8125,29325
25,72000;2,15852;8139,44563
25,76000;2,16181;8154,05250
25,80000;2,16510;8167,62224
25,84000;2,16845;8182,93393
25,88000;2,17185;8196,66609
25,92000;2,17514;8209,86405
25,96000;2,17849;8223,09852
26,00000;2,18184;8238,50110
26,04000;2,18519;8252,65497
26,08000;2,18847;8264,87094
26,12000;2,19188;8278,43174
26,16000;2,19511;8291,25792
26,20000;2,19846;8304,68684
26,24000;2,20187;8318,04872
26,28000;2,20522;8333,25908
26,32000;2,20856;8346,02788
26,36000;2,21179;8358,08516
26,40000;2,21520;8372,46776
26,44000;2,21855;8386,61492
26,48000;2,22184;8400,11910
26,52000;2,22513;8412,82010
26,56000;2,22853;8427,10510
26,60000;2,23188;8441,22767
26,64000;2,23517;8454,66182
26,68000;2,23852;8467,83072
26,72000;2,24193;8482,12466
26,76000;2,24522;8495,52006
26,80000;2,24850;8506,77937
26,84000;2,25185;8519,56606
26,88000;2,25520;8534,40091
26,92000;2,25849;8546,28980
26,96000;2,26178;8559,28734
27,00000;2,26524;8573,89122
27,04000;2,26853;8587,71279
27,08000;2,27182;8600,95546
27,12000;2,27517;8613,59388
27,16000;2,27852;8627,43929
27,20000;2,28181;8638,81186
27,24000;2,28515;8651,93903
27,28000;2,28844;8664,76595
27,32000;2,29179;8677,86556
27,36000;2,29508;8689,77457
27,40000;2,29849;8703,95303
27,44000;2,30184;8717,74852
27,48000;2,30512;8730,79151
27,52000;2,30841;8743,29582
27,56000;2,31176;8756,76945
27,60000;2,31517;8772,74275
27,64000;2,31846;8786,30430
27,68000;2,32181;8798,44278
27,72000;2,32515;8812,12056
27,76000;2,32850;8824,60624
27,80000;2,33179;8836,14793
27,84000;2,33490;8849,13057
27,88000;2,33855;8863,77320
27,92000;2,34177;8877,01884
27,96000;2,34506;8887,63368
28,00000;2,34847;8900,71839
28,04000;2,35182;8913,49614
28,08000;2,35511;8924,87764
28,12000;2,35840;8937,75225
28,16000;2,36180;8952,50738
28,20000;2,36515;8964,43948
28,24000;2,36850;8977,11962
28,28000;2,37179;8989,95623
28,32000;2,37514;9002,13569
28,36000;2,37849;9014,70780
28,40000;2,38177;9027,13314
28,44000;2,38512;9040,25137
28,48000;2,38847;9055,31645
28,52000;2,39176;9068,35273
28,56000;2,39511;9080,10006
28,60000;2,39846;9092,07836
28,64000;2,40180;9104,11403
28,68000;2,40509;9115,77344
28,72000;2,40844;9128,80674
28,76000;2,41185;9141,96521
28,80000;2,41514;9155,57593
28,84000;2,41849;9167,81351
28,88000;2,42189;9179,59362
28,92000;2,42512;9192,23726
28,96000;2,42847;9203,84452
29,00000;2,43194;9216,91582
29,04000;2,43517;9229,97892
29,08000;2,43851;9241,31647
29,12000;2,44186;9253,05486
29,16000;2,44509;9264,41774
29,20000;2,44850;9277,04945
29,24000;2,45185;9290,01644
29,28000;2,45514;9302,78823
29,32000;2,45848;9314,84029
29,36000;2,46183;9326,49150
29,40000;2,46512;9339,15451
29,44000;2,46847;9350,91078
29,48000;2,47176;9363,18487
29,52000;2,47505;9375,35837
29,56000;2,47845;9388,12345
29,60000;2,48180;9400,85948
29,64000;2,48515;9413,18572
29,68000;2,48844;9425,13421
29,72000;2,49185;9437,49845
29,76000;2,49513;9449,89994
29,80000;2,49842;9460,92233
29,84000;2,50177;9471,95292
29,88000;2,50518;9484,18453
29,92000;2,50841;9495,90579
29,96000;2,51170;9506,67411
30,00000;2,51510;9519,03760
30,04000;2,51839;9532,13945
30,08000;2,52174;9542,85711
30,12000;2,52509;9554,53664
30,16000;2,52844;9567,28607
30,20000;2,53185;9578,28686
30,24000;2,53513;9590,86195
30,28000;2,53842;9601,90371
30,32000;2,54183;9613,75087
30,36000;2,54512;9625,67702
30,40000;2,54841;9636,87450
30,44000;2,55176;9648,67696
30,48000;2,55510;9660,22685
30,52000;2,55839;9671,27159
30,56000;2,56168;9681,93710
30,60000;2,56509;9694,44215
30,64000;2,56844;9705,56438
30,68000;2,57173;9716,51375
30,72000;2,57513;9728,04204
30,76000;2,57854;9740,04865
30,80000;2,58177;9750,56291
30,84000;2,58512;9760,99148
30,88000;2,58853;9772,26123
30,92000;2,59175;9784,09573
30,96000;2,59510;9794,48631
31,00000;2,59851;9806,60468
31,04000;2,60180;9817,84910
31,08000;2,60509;9828,58464
31,12000;2,60844;9839,66738
31,16000;2,61178;9850,78365
31,20000;2,61507;9861,63914
31,24000;2,61842;9874,30662
31,28000;2,62177;9886,08897
31,32000;2,62512;9897,63588
31,36000;2,62847;9908,39750
31,40000;2,63181;9919,11367
31,44000;2,63510;9929,44986
31,48000;2,63845;9940,13622
31,52000;2,64180;9951,72262
31,56000;2,64515;9962,68913
31,60000;2,64850;9974,29714
31,64000;2,65184;9984,59682
31,68000;2,65513;9995,39495
31,72000;2,65848;10006,90237
31,76000;2,66183;10018,13933
31,80000;2,66506;10028,03817
31,84000;2,66846;10038,45185
31,88000;2,67187;10050,79746
31,92000;2,67516;10061,75801
31,96000;2,67851;10071,86845
32,00000;2,68192;10082,54215
32,04000;2,68515;10093,60477
32,08000;2,68843;10102,63935
32,12000;2,69178;10113,53359
32,16000;2,69513;10124,95607
32,20000;2,69848;10135,35783
32,24000;2,70183;10145,25741
32,28000;2,70518;10157,03902
32,32000;2,70852;10167,56222
32,36000;2,71181;10176,95591
32,40000;2,71516;10187,14607
32,44000;2,71845;10198,20869
32,48000;2,72186;10209,70792
32,52000;2,72520;10220,44122
32,56000;2,72849;10231,18347
32,60000;2,73190;10242,21629
32,64000;2,73519;10252,47648
32,68000;2,73842;10261,10351
32,72000;2,74177;10273,06840
32,76000;2,74517;10284,75389
32,80000;2,74846;10294,81962
32,84000;2,75181;10304,74529
32,88000;2,75522;10315,73340
32,92000;2,75845;10326,51961
32,96000;2,76180;10334,99315
33,00000;2,76514;10346,48716
33,04000;2,76843;10357,38885
33,08000;2,77184;10366,90027
33,12000;2,77513;10375,61148
33,16000;2,77848;10387,10997
33,20000;2,78183;10397,26213
33,24000;2,78511;10406,91584
33,28000;2,78840;10416,98009
33,32000;2,79175;10428,03824
33,36000;2,79510;10438,33941
33,40000;2,79845;10447,97897
33,44000;2,80180;10458,20639
33,48000;2,80520;10469,62515
33,52000;2,80855;10478,09049
33,56000;2,81178;10487,31059
33,60000;2,81519;10497,63188
33,64000;2,81854;10508,01277
33,68000;2,82183;10518,41751
33,72000;2,82517;10527,35522
33,76000;2,82858;10537,04917
33,80000;2,83181;10546,67458
33,84000;2,83516;10555,94534
33,88000;2,83857;10566,64735
33,92000;2,84179;10576,35918
33,96000;2,84514;10585,48391
34,00000;2,84849;10594,84109
34,04000;2,85178;10604,47320
34,08000;2,85513;10613,55472
34,12000;2,85842;10622,66231
34,16000;2,86182;10633,70407
34,20000;2,86523;10643,88976
34,24000;2,86852;10652,79543
34,28000;2,87187;10663,10108
34,32000;2,87522;10673,35457
34,36000;2,87851;10682,32059
34,40000;2,88179;10691,23223
34,44000;2,88520;10701,42314
34,48000;2,88855;10711,84874
34,52000;2,89190;10720,03692
34,56000;2,89513;10728,93664
34,60000;2,89847;10738,19473
34,64000;2,90188;10748,55477
34,68000;2,90511;10758,10939
34,72000;2,90852;10766,74834
34,76000;2,91193;10778,70652
34,80000;2,91522;10787,21210
34,84000;2,91850;10795,01361
34,88000;2,92185;10803,79561
34,92000;2,92520;10812,93598
34,96000;2,92849;10822,25069
35,00000;2,93190;10831,35083
35,04000;2,93519;10843,53030
35,08000;2,93847;10851,50018
35,12000;2,94182;10860,04078
35,16000;2,94511;10868,43684
35,20000;2,94846;10878,07268
35,24000;2,95175;10888,10340
35,28000;2,95516;10898,42692
35,32000;2,95850;10908,17526
35,36000;2,96185;10917,96234
35,40000;2,96520;10926,28390
35,44000;2,96849;10934,74030
35,48000;2,97190;10943,33753
35,52000;2,97518;10952,72899
35,56000;2,97829;10960,03875
35,60000;2,98188;10969,92865
35,64000;2,98523;10980,46452
35,68000;2,98846;10988,84344
35,72000;2,99175;10997,30805
35,76000;2,99515;11007,31567
35,80000;2,99844;11015,72067
35,84000;3,00179;11023,73749
35,88000;3,00502;11033,33458
35,92000;3,00849;11043,96880
35,96000;3,01184;11052,35294
36,00000;3,01512;11060,48375
36,04000;3,01847;11070,69924
36,08000;3,02176;11078,31672
36,12000;3,02511;11087,30510
36,16000;3,02828;11096,35681
36,20000;3,03187;11107,21305
36,24000;3,03515;11116,43910
36,28000;3,03850;11124,47008
36,32000;3,04173;11132,60761
36,36000;3,04508;11141,07147
36,40000;3,04843;11149,91605
36,44000;3,05172;11158,70848
36,48000;3,05500;11168,21244
36,52000;3,05853;11178,53150
36,56000;3,06176;11187,05496
36,60000;3,06511;11195,00324
36,64000;3,06846;11203,81132
36,68000;3,07168;11212,27890
36,72000;3,07497;11219,97237
36,76000;3,07850;11230,65352
36,80000;3,08179;11239,50183
36,84000;3,08508;11247,31451
36,88000;3,08843;11256,37665
36,92000;3,09177;11266,13021
36,96000;3,09506;11274,44655
37,00000;3,09829;11282,52894
37,04000;3,10182;11292,22214
37,08000;3,10511;11301,46682
37,12000;3,10846;11309,54102
37,16000;3,11180;11318,41466
37,20000;3,11515;11327,00816
37,24000;3,11844;11335,43923
37,28000;3,12179;11342,90472
37,32000;3,12508;11351,05565
37,36000;3,12849;11360,56185
37,40000;3,13177;11368,82901
37,44000;3,13512;11377,17441
37,48000;3,13847;11387,26771
37,52000;3,14182;11394,76821
37,56000;3,14505;11403,29540
37,60000;3,14845;11410,21252
37,64000;3,15186;11419,55927
37,68000;3,15509;11427,86592
37,72000;3,15844;11435,32544
37,76000;3,16185;11445,39788
37,80000;3,16514;11453,65462
37,84000;3,16842;11461,56788
37,88000;3,17183;11470,72837
37,92000;3,17512;11480,55419
37,96000;3,17847;11488,82210
38,00000;3,18182;11496,87171
38,04000;3,18517;11505,34749
38,08000;3,18851;11513,78900
38,12000;3,19186;11522,59558
38,16000;3,19521;11532,57564
38,20000;3,19850;11539,87572
38,24000;3,20185;11547,95885
38,28000;3,20519;11555,36771
38,32000;3,20848;11563,89490
38,36000;3,21183;11572,58824
38,40000;3,21518;11580,64604
38,44000;3,21841;11588,18454
38,48000;3,22182;11596,22669
38,52000;3,22516;11605,03253
38,56000;3,22839;11612,41233
38,60000;3,23180;11620,41575
38,64000;3,23509;11628,65385
38,68000;3,23832;11636,69154
38,72000;3,24179;11645,72537
38,76000;3,24513;11654,79720
38,80000;3,24842;11662,38785
38,84000;3,25177;11669,81012
38,88000;3,25518;11679,20604
38,92000;3,25853;11687,54920
38,96000;3,26170;11694,67196
39,00000;3,26510;11702,53307
39,04000;3,26845;11712,32685
39,08000;3,27180;11719,52337
39,12000;3,27509;11728,42905
39,16000;3,27850;11736,06068
39,20000;3,28179;11744,51560
39,24000;3,28513;11752,00269
39,28000;3,28842;11759,85485
39,32000;3,29177;11768,61003
39,36000;3,29518;11776,64697
39,40000;3,29853;11784,89029
39,44000;3,30187;11794,84650
39,48000;3,30522;11802,17266
39,52000;3,30857;11809,77672
39,56000;3,31180;11817,34726
39,60000;3,31515;11823,78083
39,64000;3,31850;11831,97871
39,68000;3,32178;11840,15200
39,72000;3,32513;11849,20371
39,76000;3,32854;11857,88065
39,80000;3,33183;11866,04649
39,84000;3,33506;11872,42121
39,88000;3,33853;11880,86867
39,92000;3,34187;11891,21380
39,96000;3,34522;11897,55946
40,00000;3,34851;11904,15472
40,04000;3,35192;11912,86445
40,08000;3,35527;11921,44752
40,12000;3,35850;11928,71183
40,16000;3,36190;11936,98272
40,20000;3,36519;11944,99806
40,24000;3,36854;11951,58735
40,28000;3,37189;11959,87538
40,32000;3,37518;11966,13610
40,36000;3,37858;11975,63112
40,40000;3,38187;11982,78219
40,44000;3,38510;11989,35062
40,48000;3,38845;11996,26252
40,52000;3,39186;12005,05868
40,56000;3,39515;12012,09053
40,60000;3,39849;12019,76836
40,64000;3,40190;12028,73364
40,68000;3,40519;12037,34651
40,72000;3,40848;12043,18032
40,76000;3,41183;12049,97376
40,80000;3,41518;12058,51585
40,84000;3,41846;12064,33699
40,88000;3,42181;12071,63632
40,92000;3,42516;12081,19690
40,96000;3,42851;12087,92552
41,00000;3,43174;12094,69289
41,04000;3,43515;12103,23125
41,08000;3,43849;12110,89343
41,12000;3,44178;12118,40436
41,16000;3,44513;12124,44082
41,20000;3,44848;12132,21550
41,24000;3,45177;12139,53495
41,28000;3,45512;12146,25910
41,32000;3,45834;12153,27606
41,36000;3,46181;12161,76301
41,40000;3,46516;12170,31851
41,44000;3,46839;12177,08737
41,48000;3,47180;12185,07290
41,52000;3,47514;12192,28283
41,56000;3,47843;12199,38397
41,60000;3,48172;12205,10155
41,64000;3,48519;12213,28378
41,68000;3,48848;12220,56895
41,72000;3,49171;12226,61138
41,76000;3,49517;12235,78006
41,80000;3,49852;12243,50855
41,84000;3,50181;12250,83545
41,88000;3,50516;12258,31434
41,92000;3,50857;12266,93988
41,96000;3,51186;12277,20380
42,00000;3,51520;12285,72950
42,04000;3,51855;12293,24937
42,08000;3,52184;12301,61637
42,12000;3,52519;12310,20316
42,16000;3,52860;12318,33845
42,20000;3,53159;12326,33516
42,24000;3,53523;12337,05357
42,28000;3,53858;12347,17742
42,32000;3,54175;12354,09081
42,36000;3,54516;12361,80738
42,40000;3,54851;12370,36809
42,44000;3,55179;12378,83866
42,48000;3,55496;12386,02027
42,52000;3,55855;12395,30593
42,56000;3,56178;12405,40072
42,60000;3,56513;12412,29326
42,64000;3,56848;12421,73091
42,68000;3,57182;12430,35346
42,72000;3,57517;12438,32931
42,76000;3,57840;12446,55326
42,80000;3,58187;12457,52722
42,84000;3,58522;12465,30190
42,88000;3,58851;12473,46550
42,92000;3,59191;12481,10160
42,96000;3,59514;12489,13929
43,00000;3,59849;12497,03392
43,04000;3,60184;12505,37634
43,08000;3,60513;12513,13239
43,12000;3,60848;12522,86583
43,16000;3,61188;12531,45933
43,20000;3,61499;12539,93958
43,24000;3,61858;12549,68494
43,28000;3,62187;12557,96999
43,32000;3,62510;12564,36110
43,36000;3,62850;12571,54495
43,40000;3,63185;12580,62422
43,44000;3,63508;12587,36402
43,48000;3,63849;12595,26610
43,52000;3,64184;12603,87301
43,56000;3,64507;12611,85557
43,60000;3,64841;12618,72351
43,64000;3,65176;12628,21406
43,68000;3,65511;12636,52444
43,72000;3,65834;12643,11224
43,76000;3,66181;12651,13354
43,80000;3,66510;12661,33189
43,84000;3,66838;12668,88529
43,88000;3,67173;12677,53541
43,92000;3,67514;12686,06335
43,96000;3,67843;12694,14574
44,00000;3,68178;12702,75861
44,04000;3,68519;12711,11816
44,08000;3,68841;12719,34062
44,12000;3,69182;12727,78213
44,16000;3,69511;12735,07178
44,20000;3,69840;12743,11244
44,24000;3,70175;12750,49299
44,28000;3,70509;12758,65436
44,32000;3,70832;12766,36273
44,36000;3,71179;12775,35707
44,40000;3,71514;12783,53333
44,44000;3,71837;12790,97050
44,48000;3,72178;12798,26164
44,52000;3,72518;12807,29473
44,56000;3,72847;12814,44132
44,60000;3,73176;12820,79667
44,64000;3,73517;12828,66597
44,68000;3,73852;12837,79144
44,72000;3,74181;12845,11238
44,76000;3,74515;12853,47790
44,80000;3,74856;12861,38296
44,84000;3,75185;12867,86348
44,88000;3,75514;12874,99368
44,92000;3,75849;12883,61847
44,96000;3,76178;12891,20317
45,00000;3,76512;12898,08750
45,04000;3,76847;12906,40831
45,08000;3,77182;12915,95548
45,12000;3,77517;12923,46418
45,16000;3,77846;12930,09520
45,20000;3,78180;12937,18070
45,24000;3,78515;12945,50896
45,28000;3,78850;12953,80741
45,32000;3,79179;12962,62741
45,36000;3,79520;12970,97802
45,40000;3,79855;12980,56841
45,44000;3,80183;12988,33340
45,48000;3,80518;12996,13714
45,52000;3,80853;13004,18526
45,56000;3,81182;13012,39729
45,60000;3,81511;13020,94012
45,64000;3,81852;13028,49948
45,68000;3,82186;13037,12875
45,72000;3,82515;13045,23200
45,76000;3,82850;13050,87805
45,80000;3,83185;13059,61609
45,84000;3,83514;13066,82974
45,88000;3,83843;13073,25810
45,92000;3,84177;13081,72047
45,96000;3,84512;13088,98926
46,00000;3,84847;13097,12827
46,04000;3,85182;13103,73247
46,08000;3,85505;13111,53620
46,12000;3,85846;13119,43680
46,16000;3,86180;13126,32114
46,20000;3,86503;13133,92371
46,24000;3,86844;13142,16256
46,28000;3,87179;13149,33896
46,32000;3,87508;13156,93706
46,36000;3,87842;13163,51295
46,40000;3,88177;13171,24069
46,44000;3,88506;13177,20860
46,48000;3,88841;13184,68601
46,52000;3,89176;13193,12602
46,56000;3,89511;13201,40064
46,60000;3,89845;13208,42206
46,64000;3,90186;13216,38972
46,68000;3,90521;13225,04580
46,72000;3,90844;13231,08971
46,76000;3,91185;13238,90537
46,80000;3,91519;13247,71941
46,84000;3,91848;13254,72444
46,88000;3,92183;13262,04389
46,92000;3,92524;13269,99217
46,96000;3,92847;13276,68726
47,00000;3,93182;13282,70435
47,04000;3,93516;13290,63028
47,08000;3,93839;13298,94811
47,12000;3,94186;13306,26458
47,16000;3,94515;13313,66301
47,20000;3,94850;13321,26111
47,24000;3,95191;13329,22280
47,28000;3,95519;13335,88958
47,32000;3,95848;13343,16880
47,36000;3,96189;13351,10664
47,40000;3,96530;13358,72710
47,44000;3,96859;13365,71574
47,48000;3,97188;13370,99373
47,52000;3,97528;13378,25060
47,56000;3,97857;13385,30332
47,60000;3,98174;13391,18332
47,64000;3,98515;13398,41932
47,68000;3,98856;13405,79540
47,72000;3,99179;13412,92113
47,76000;3,99513;13419,63261
47,80000;3,99854;13427,34098
47,84000;4,00183;13434,12548
47,88000;4,00512;13440,41079
47,92000;4,00853;13447,43222
47,96000;4,01187;13454,74422
48,00000;4,01522;13461,79992
48,04000;4,01857;13467,81701
48,08000;4,02186;13474,00099
48,12000;4,02521;13481,41879
48,16000;4,02850;13486,46730
48,20000;4,03172;13493,07299
48,24000;4,03513;13500,58615
48,28000;4,03848;13508,00246
48,32000;4,04177;13514,10747
48,36000;4,04506;13519,89955
48,40000;4,04847;13526,37410
48,44000;4,05181;13533,38659
48,48000;4,05504;13539,04605
48,52000;4,05851;13546,42212
48,56000;4,06186;13553,54935
48,60000;4,06515;13558,46971
48,64000;4,06856;13565,01132
48,68000;4,07190;13573,67635
48,72000;4,07513;13578,39108
48,76000;4,07830;13583,69291
48,80000;4,08189;13590,57873
48,84000;4,08518;13598,32734
48,88000;4,08847;13602,02134
48,92000;4,09181;13606,97150
48,96000;4,09510;13614,43102
49,00000;4,09845;13620,09645
49,04000;4,10174;13624,98552
49,08000;4,10515;13631,47348
49,12000;4,10849;13638,57239
49,16000;4,11184;13643,41080
49,20000;4,11513;13648,64260
49,24000;4,11848;13653,18894
49,28000;4,12183;13658,23299
49,32000;4,12512;13663,79261
49,36000;4,12852;13668,60420
49,40000;4,13187;13675,98474
49,44000;4,13516;13679,79050
49,48000;4,13845;13683,14177
49,52000;4,14180;13687,25002
49,56000;4,14521;13691,35380
49,60000;4,14849;13697,75832
49,64000;4,15184;13702,23910
49,68000;4,15525;13705,80941
49,72000;4,15854;13710,11734
49,76000;4,16189;13714,53851
49,80000;4,16529;13717,89873
49,84000;4,16852;13722,08446
49,88000;4,17187;13724,48057
49,92000;4,17522;13727,14341
49,96000;4,17845;13729,94632
50,00000;4,18186;13733,31845
50,04000;4,18514;13734,63720
50,08000;4,18843;13736,99903
50,12000;4,19184;13739,26848
50,16000;4,19519;13739,58886
50,20000;4,19836;13739,83473
50,24000;4,20189;13739,72148
50,28000;4,20517;13740,10593
50,32000;4,20846;13736,80532
50,36000;4,21181;13730,37845
50,40000;4,21516;13722,39739
50,44000;4,21851;13709,60325
50,48000;4,22174;13687,23214
50,52000;4,22520;13643,75651
50,56000;4,22837;13273,28086
50,59400;4,23334;2374,79303