File: SU - Suspension/05 - Essais/Excels essais Optimus/Temoins et tests triangles/Triangles tests/R-R inf/RR inf rr.is_tcyclic_RawData/Specimen_RawData_1.csv
Temps;Déplacement;Charge
(sec);(mm);(N)
0,00000;-191,95992;0,97221
0,00200;-191,95992;0,92515
0,00400;-191,95992;0,88770
0,10400;-191,95773;1,63047
0,20400;-191,95186;2,52211
0,30400;-191,94588;15,33808
0,40400;-191,94044;64,32255
0,50400;-191,93517;113,93263
0,60400;-191,93016;161,14282
0,70400;-191,92507;209,00581
0,80400;-191,92012;256,03557
0,90400;-191,91498;305,71409
1,00400;-191,91001;353,97978
1,10400;-191,90500;407,41744
1,20400;-191,90002;455,86401
1,30400;-191,89501;505,60106
1,40400;-191,89004;553,49078
1,50400;-191,88503;600,01635
1,60400;-191,88000;649,90944
1,70400;-191,87510;697,29709
1,80400;-191,86996;753,33486
1,90400;-191,86506;799,54574
2,00400;-191,85996;849,72475
2,10400;-191,85500;899,29560
2,20400;-191,84997;947,93895
2,30400;-191,84502;996,41271
2,40400;-191,83999;1042,37068
2,50400;-191,83503;1089,40396
2,60400;-191,83006;1135,73698
2,70400;-191,82511;1181,90441
2,80400;-191,82002;1229,12247
2,90400;-191,81512;1272,88820
3,00400;-191,80993;1331,01605
3,10400;-191,80508;1373,38834
3,20400;-191,80000;1419,78040
3,30400;-191,79503;1464,25329
3,40400;-191,79001;1510,27180
3,50400;-191,78512;1555,74530
3,60400;-191,78009;1599,27960
3,70400;-191,77506;1649,66024
3,80400;-191,77005;1694,07502
3,90400;-191,76507;1741,44004
4,00400;-191,76006;1787,16499
4,10400;-191,75498;1831,77013
4,20400;-191,74995;1878,77864
4,30400;-191,74499;1924,12492
4,40400;-191,74004;1970,41612
4,50400;-191,73501;2015,43756
4,60400;-191,73006;2060,54915
4,70400;-191,72495;2106,92044
4,80400;-191,72005;2151,78952
4,90400;-191,71497;2195,63618
5,00400;-191,71001;2239,86283
5,10400;-191,70504;2283,40887
5,20400;-191,70009;2326,95974
5,30400;-191,69500;2373,01439
5,40400;-191,69005;2415,01294
5,50400;-191,68502;2457,61145
5,60400;-191,68006;2501,96736
5,70400;-191,67498;2544,65267
5,80400;-191,67008;2588,71093
5,90400;-191,66499;2632,32905
6,00400;-191,66002;2678,79274
6,10400;-191,65501;2722,04690
6,20400;-191,65004;2766,43652
6,30400;-191,64503;2811,79566
6,40400;-191,64005;2855,74477
6,50400;-191,63499;2903,81480
6,60400;-191,63001;2948,04424
6,70400;-191,62506;2991,90469
6,80400;-191,62003;3035,45501
6,90400;-191,61513;3075,68461
7,00400;-191,60993;3123,11035
7,10400;-191,60504;3167,24330
7,20400;-191,60001;3211,07432
7,30400;-191,59505;3252,46230
7,40400;-191,58995;3293,55672
7,50400;-191,58499;3337,22755
7,60400;-191,57996;3377,86227
7,70400;-191,57501;3416,53675
7,80400;-191,56998;3457,04146
7,90400;-191,56519;3492,22608
8,00400;-191,56005;3531,75290
8,10400;-191,55527;3567,87629
8,20400;-191,55001;3604,11704
8,30400;-191,54506;3636,76101
8,40400;-191,54003;3667,00366
8,50400;-191,53507;3698,20371
8,60400;-191,53005;3728,17330
8,70400;-191,52496;3757,54423
8,80400;-191,52001;3780,16718
8,90400;-191,51498;3805,01039
9,00400;-191,50997;3824,94144
9,10400;-191,50488;3841,20718
9,20400;-191,49991;3848,58474
9,30400;-191,49495;3853,88955
9,40400;-191,49000;3854,67894
9,50400;-191,48497;3852,79618
9,60400;-191,47994;3846,20056
9,70400;-191,47487;3842,59410
9,80400;-191,46996;3828,98003
9,90400;-191,46487;3815,25122
10,00400;-191,45990;3798,68597
10,10400;-191,45494;3780,55274
10,20400;-191,44991;3772,63911
10,30400;-191,44490;3794,25064
10,40400;-191,44000;3820,92930
10,50400;-191,43498;3851,81010
10,60400;-191,43008;3888,39804
10,70400;-191,42494;3925,28623
10,80400;-191,42004;3961,77620
10,90400;-191,41490;4002,62028
11,00400;-191,40998;4039,75844
11,10400;-191,40497;4077,06015
11,20400;-191,40000;4113,70397
11,30400;-191,39504;4149,74280
11,40400;-191,38996;4191,98461
11,50400;-191,38506;4226,79819
11,60400;-191,37997;4266,24715
11,70400;-191,37507;4300,20727
11,80400;-191,36999;4337,53096
11,90400;-191,36498;4374,57785
12,00400;-191,35995;4411,41874
12,10400;-191,35492;4449,80636
12,20400;-191,34996;4484,29100
12,30400;-191,34507;4519,39218
12,40400;-191,33998;4555,56139
12,50400;-191,33495;4596,80147
12,60400;-191,33000;4633,33130
12,70400;-191,32508;4666,01253
12,80400;-191,31999;4702,63474
12,90400;-191,31504;4737,27919
13,00400;-191,30995;4774,27095
13,10400;-191,30506;4812,93537
13,20400;-191,30003;4846,31509
13,30400;-191,29507;4881,16853
13,40400;-191,29004;4916,05699
13,50400;-191,28509;4951,61563
13,60400;-191,28000;4986,90344
13,70400;-191,27497;5020,95856
13,80400;-191,26996;5055,42271
13,90400;-191,26499;5087,96051
14,00400;-191,25998;5121,70270
14,10400;-191,25495;5152,91765
14,20400;-191,24994;5187,50921
14,30400;-191,24486;5222,55450
14,40400;-191,24001;5254,12187
14,50400;-191,23493;5288,39491
14,60400;-191,23003;5318,46471
14,70400;-191,22513;5353,41501
14,80400;-191,21999;5389,72542
14,90400;-191,21502;5422,61414
15,00400;-191,21006;5455,50883
15,10400;-191,20503;5488,96417
15,20400;-191,20008;5520,98192
15,30400;-191,19505;5553,40312
15,40400;-191,19002;5590,74953
15,50400;-191,18505;5621,33119
15,60400;-191,18009;5655,24846
15,70400;-191,17501;5688,76602
15,80400;-191,17011;5719,88635
15,90400;-191,16502;5750,85990
16,00400;-191,16007;5785,33448
16,10400;-191,15504;5815,65276
16,20400;-191,14995;5848,25575
16,30400;-191,14500;5878,41570
16,40400;-191,13997;5911,89004
16,50400;-191,13502;5941,73074
16,60400;-191,12987;5975,33025
16,69600;-191,12539;6000,60709
16,69800;-191,12527;6001,23480
16,79800;-191,12492;6003,38727
16,89800;-191,12928;5959,12449
16,99800;-191,13651;5863,30295
17,09800;-191,14345;5770,37372
17,19800;-191,14949;5690,35634
17,29800;-191,15493;5619,00176
17,39800;-191,16024;5553,16918
17,49800;-191,16532;5492,00997
17,59800;-191,17029;5430,48866
17,69800;-191,17530;5367,17623
17,79800;-191,18033;5307,15026
17,89800;-191,18542;5245,46914
17,99800;-191,19034;5186,31861
18,09800;-191,19529;5128,71109
18,19800;-191,20025;5068,35952
18,29800;-191,20533;5007,53634
18,39800;-191,21036;4946,43003
18,49800;-191,21537;4887,64010
18,59800;-191,22034;4828,77679
18,69800;-191,22535;4768,81862
18,79800;-191,23038;4711,24947
18,89800;-191,23547;4651,96297
18,99800;-191,24031;4595,63248
19,09800;-191,24532;4537,38123
19,19800;-191,25029;4478,44937
19,29800;-191,25544;4418,81530
19,39800;-191,26039;4359,61932
19,49800;-191,26542;4303,82378
19,59800;-191,27037;4247,71383
19,69800;-191,27540;4189,15786
19,79800;-191,28041;4132,40381
19,89800;-191,28539;4075,38787
19,99800;-191,29034;4019,09277
20,09800;-191,29531;3960,11658
20,19800;-191,30033;3902,83316
20,29800;-191,30535;3845,89657
20,39800;-191,31031;3789,25614
20,49800;-191,31534;3731,19153
20,59800;-191,32031;3673,78891
20,69800;-191,32540;3617,18647
20,79800;-191,33048;3559,13527
20,89800;-191,33538;3503,29541
20,99800;-191,34039;3445,81157
21,09800;-191,34531;3391,10829
21,19800;-191,35045;3333,88671
21,29800;-191,35535;3277,60614
21,39800;-191,36030;3225,33585
21,49800;-191,36533;3169,21957
21,59800;-191,37042;3111,39803
21,69800;-191,37537;3056,90952
21,79800;-191,38040;3000,46857
21,89800;-191,38535;2946,61410
21,99800;-191,39038;2890,58816
22,09800;-191,39523;2835,95007
22,19800;-191,40037;2775,23920
22,29800;-191,40532;2721,97668
22,39800;-191,41028;2669,88445
22,49800;-191,41536;2614,22563
22,59800;-191,42039;2560,84781
22,69800;-191,42540;2502,45500
22,79800;-191,43037;2448,64039
22,89800;-191,43546;2394,93940
22,99800;-191,44041;2335,70151
23,09800;-191,44544;2283,46493
23,19800;-191,45040;2231,60908
23,29800;-191,45543;2177,85574
23,39800;-191,45984;2126,01312
23,49800;-191,46554;2067,48638
23,59800;-191,47038;2016,92060
23,69800;-191,47540;1962,47976
23,79800;-191,48031;1909,99508
23,89800;-191,48538;1855,16868
23,99800;-191,49035;1804,22720
24,09800;-191,49536;1750,92071
24,19800;-191,50034;1698,72474
24,29800;-191,50518;1647,46232
24,39800;-191,51038;1593,23793
24,49800;-191,51533;1544,11672
24,59800;-191,52030;1490,59333
24,69800;-191,52531;1440,39411
24,79800;-191,53029;1390,24016
24,89800;-191,53537;1340,25849
24,99800;-191,54044;1285,21919
25,09800;-191,54541;1234,96605
25,19800;-191,55037;1186,48959
25,29800;-191,55540;1136,89899
25,39800;-191,56041;1088,46668
25,49800;-191,56538;1039,61434
25,59800;-191,57039;990,37448
25,69800;-191,57531;944,87369
25,79800;-191,58045;890,91854
25,89800;-191,58542;844,65528
25,99800;-191,59051;797,42298
26,09800;-191,59541;751,46114
26,19800;-191,60049;704,03931
26,29800;-191,60544;656,92910
26,39800;-191,61040;610,68474
26,49800;-191,61537;565,28533
26,59800;-191,62033;519,86971
26,69800;-191,62536;475,06383
26,79800;-191,63031;429,81971
26,89800;-191,63528;387,14358
26,99800;-191,64035;343,01179
27,09800;-191,64527;300,04182
27,19800;-191,65028;256,38405
27,29800;-191,65531;213,01941
27,39800;-191,66039;173,29294
27,49800;-191,66535;133,10612
27,59800;-191,67043;91,13567
27,69800;-191,67533;51,33451
27,79800;-191,68036;14,66195
27,84600;-191,68269;0,35867