File: SU - Suspension/05 - Essais/Excels essais Optimus/Test_Rotules_31_01_19/P7_1.is_tens_RawData/Specimen_RawData_1.csv
Temps;Déplacement;Charge
(sec);(mm);(N)
0,00000;71,23571;25,61123
0,04000;71,23619;26,54431
0,08000;71,23834;34,08416
0,12000;71,24175;39,81726
0,16000;71,24539;43,84021
0,20000;71,24928;48,75780
0,24000;71,25323;57,20370
0,28000;71,25699;65,16675
0,32000;71,26070;75,79830
0,36000;71,26441;85,98602
0,40000;71,26793;95,13501
0,44000;71,27141;102,72877
0,48000;71,27487;110,29844
0,52000;71,27828;116,16986
0,56000;71,28169;118,83046
0,60000;71,28504;120,72379
0,64000;71,28845;119,94814
0,68000;71,29179;117,41739
0,72000;71,29514;114,91205
0,76000;71,29843;113,20935
0,80000;71,30184;111,14656
0,84000;71,30519;107,70081
0,88000;71,30841;105,18876
0,92000;71,31189;101,43595
0,96000;71,31523;99,24757
1,00000;71,31846;95,24023
1,04000;71,32181;92,71697
1,08000;71,32521;90,56541
1,12000;71,32851;87,59716
1,16000;71,33179;85,10319
1,20000;71,33520;83,06047
1,24000;71,33855;80,63735
1,28000;71,34184;78,62553
1,32000;71,34513;76,14727
1,36000;71,34853;74,97589
1,40000;71,35182;73,31548
1,44000;71,35517;71,49233
1,48000;71,35852;69,81317
1,52000;71,36181;67,89091
1,56000;71,36521;67,06649
1,60000;71,36850;66,56005
1,64000;71,37179;65,16822
1,68000;71,37520;64,66599
1,72000;71,37849;64,31310
1,76000;71,38178;65,95254
1,80000;71,38518;66,95926
1,84000;71,38859;69,43213
1,88000;71,39176;71,21523
1,92000;71,39511;72,79112
1,96000;71,39852;75,32696
2,00000;71,40187;76,32207
2,04000;71,40515;77,28453
2,08000;71,40850;78,53484
2,12000;71,41185;79,24248
2,16000;71,41514;79,88451
2,20000;71,41843;80,71025
2,24000;71,42177;80,54603
2,28000;71,42513;80,41372
2,32000;71,42847;79,96755
2,36000;71,43188;80,13467
2,40000;71,43517;79,03208
2,44000;71,43851;77,85741
2,48000;71,44181;78,38864
2,52000;71,44521;78,09445
2,56000;71,44850;77,99217
2,60000;71,45185;78,28306
2,64000;71,45514;79,17702
2,68000;71,45849;79,37714
2,72000;71,46177;79,85846
2,76000;71,46506;80,37749
2,80000;71,46847;81,07636
2,84000;71,47188;82,18419
2,88000;71,47504;82,31557
2,92000;71,47846;83,81624
2,96000;71,48186;84,84832
3,00000;71,48515;86,64705
3,04000;71,48838;88,77717
3,08000;71,49197;91,05061
3,12000;71,49532;92,73676
3,16000;71,49860;93,27033
3,20000;71,50189;94,47207
3,24000;71,50524;96,24289
3,28000;71,50853;96,37950
3,32000;71,51182;97,10124
3,36000;71,51517;98,51333
3,40000;71,51851;99,39313
3,44000;71,52181;102,07748
3,48000;71,52521;104,62659
3,52000;71,52844;107,13364
3,56000;71,53179;108,76878
3,60000;71,53519;112,95723
3,64000;71,53837;116,98018
3,68000;71,54195;123,27593
3,72000;71,54524;127,94283
3,76000;71,54847;134,88668
3,80000;71,55181;142,27763
3,84000;71,55517;149,20724
3,88000;71,55845;156,28055
3,92000;71,56180;163,44637
3,96000;71,56521;171,39943
4,00000;71,56850;178,66680
4,04000;71,57179;186,12581
4,08000;71,57513;193,71546
4,12000;71,57848;202,95726
4,16000;71,58177;211,83332
4,20000;71,58512;221,75899
4,24000;71,58841;234,04472
4,28000;71,59194;247,26179
4,32000;71,59516;259,24311
4,36000;71,59845;271,67259
4,40000;71,60180;284,96783
4,44000;71,60515;298,94249
4,48000;71,60844;311,99881
4,52000;71,61179;326,55676
4,56000;71,61526;342,62878
4,60000;71,61848;358,33402
4,64000;71,62171;372,28190
4,68000;71,62512;388,13339
4,72000;71,62841;403,65523
4,76000;71,63169;419,24007
4,80000;71,63511;434,91134
4,84000;71,63845;451,10108
4,88000;71,64174;468,00561
4,92000;71,64515;484,89966
4,96000;71,64849;503,09906
5,00000;71,65179;519,15892
5,04000;71,65513;535,75761
5,08000;71,65843;553,02684
5,12000;71,66183;571,80380
5,16000;71,66512;588,93226
5,20000;71,66835;605,40601
5,24000;71,67181;622,76865
5,28000;71,67510;641,23399
5,32000;71,67845;660,17564
5,36000;71,68180;677,09233
5,40000;71,68515;694,86224
5,44000;71,68849;711,82526
5,48000;71,69178;728,89780
5,52000;71,69513;747,19177
5,56000;71,69848;764,69346
5,60000;71,70183;781,71864
5,64000;71,70500;798,61907
5,68000;71,70852;817,12184
5,72000;71,71188;834,66265
5,76000;71,71510;851,14688
5,80000;71,71839;867,08022
5,84000;71,72180;882,50954
5,88000;71,72509;899,10738
5,92000;71,72838;914,04300
5,96000;71,73178;930,26366
6,00000;71,73519;945,42671
6,04000;71,73836;959,47003
6,08000;71,74177;974,16518
6,12000;71,74518;987,90992
6,16000;71,74841;999,28817
6,20000;71,75169;1011,42600
6,24000;71,75516;1023,13878
6,28000;71,75845;1030,49269
6,32000;71,76173;1036,13585
6,36000;71,76515;1038,94277
6,40000;71,76837;1041,34372
6,44000;71,77179;1040,92192
6,48000;71,77513;1040,49640
6,52000;71,77842;1036,00444
6,56000;71,78177;1023,99401
6,60000;71,78518;1010,85370
6,64000;71,78840;996,25094
6,68000;71,79169;984,96899
6,72000;71,79510;978,48577
6,76000;71,79833;971,58439
6,80000;71,80168;965,37070
6,84000;71,80514;959,67585
6,88000;71,80844;952,29913
6,92000;71,81172;943,84812
6,96000;71,81514;940,31598
7,00000;71,81848;932,88403
7,04000;71,82171;923,14119
7,08000;71,82512;918,99736
7,12000;71,82852;914,27919
7,16000;71,83175;907,30358
7,20000;71,83516;902,51770
7,24000;71,83851;898,72545
7,28000;71,84180;894,69058
7,32000;71,84509;890,69791
7,36000;71,84849;885,61559
7,40000;71,85178;879,85750
7,44000;71,85513;872,63742
7,48000;71,85842;867,01531
7,52000;71,86177;863,15135
7,56000;71,86517;860,57810
7,60000;71,86846;858,73054
7,64000;71,87163;856,23963
7,68000;71,87522;856,76033
7,72000;71,87857;853,31844
7,76000;71,88180;847,39523
7,80000;71,88521;843,31222
7,84000;71,88849;839,85319
7,88000;71,89184;835,45595
7,92000;71,89513;832,18366
7,96000;71,89848;830,00269
8,00000;71,90183;827,51494
8,04000;71,90493;823,25311
8,08000;71,90858;822,66815
8,12000;71,91187;816,98475
8,16000;71,91522;812,26742
8,20000;71,91838;808,08867
8,24000;71,92186;804,31625
8,28000;71,92520;801,77169
8,32000;71,92855;796,24709
8,36000;71,93196;793,49689
8,40000;71,93524;792,84254
8,44000;71,93860;788,35767
8,48000;71,94182;785,34987
8,52000;71,94518;784,49398
8,56000;71,94852;783,15940
8,60000;71,95187;780,00007
8,64000;71,95510;775,88391
8,68000;71,95850;776,78878
8,72000;71,96185;775,95273
8,76000;71,96514;773,71057
8,80000;71,96849;772,15377
8,84000;71,97184;772,51093
8,88000;71,97525;770,28642
8,92000;71,97853;767,55802
8,96000;71,98188;766,53329
9,00000;71,98529;763,78775
9,04000;71,98852;758,32009
9,08000;71,99181;755,57455
9,12000;71,99522;755,85591
9,16000;71,99851;752,79758
9,20000;72,00179;748,73553
9,24000;72,00514;746,73835
9,28000;72,00849;748,64076
9,32000;72,01184;748,45958
9,36000;72,01513;747,85161
9,40000;72,01848;748,74396
9,44000;72,02188;747,60681
9,48000;72,02523;745,25257
9,52000;72,02846;745,08558
9,56000;72,03186;744,87850
9,60000;72,03522;744,11747
9,64000;72,03844;741,79037
9,68000;72,04180;738,92181
9,72000;72,04520;738,61578
9,76000;72,04849;736,46279
9,80000;72,05184;732,79659
9,84000;72,05518;732,78379
9,88000;72,05848;729,65277
9,92000;72,06176;726,09284
9,96000;72,06511;723,99704
10,00000;72,06858;723,59373
10,04000;72,07181;719,40855
10,08000;72,07503;717,50721
10,12000;72,07857;719,13493
10,16000;72,08179;716,25668
10,20000;72,08514;713,84497
10,24000;72,08849;713,85042
10,28000;72,09183;713,73880
10,32000;72,09531;713,02471
10,36000;72,09853;713,81624
10,40000;72,10182;709,92676
10,44000;72,10517;708,44246
10,48000;72,10846;706,16384
10,52000;72,11175;706,41423
10,56000;72,11515;705,02413
10,60000;72,11850;705,31489
10,64000;72,12179;703,13243
10,68000;72,12520;701,27654
10,72000;72,12855;700,54806
10,76000;72,13184;694,48412
10,80000;72,13518;691,15218
10,84000;72,13853;689,44055
10,88000;72,14188;687,16803
10,92000;72,14510;685,50301
10,96000;72,14858;687,37417
11,00000;72,15186;686,52774
11,04000;72,15516;682,55933
11,08000;72,15850;683,02276
11,12000;72,16185;682,88073
11,16000;72,16514;682,42559
11,20000;72,16854;681,19657
11,24000;72,17184;681,54586
11,28000;72,17519;680,04038
11,32000;72,17853;680,85035
11,36000;72,18182;678,07683
11,40000;72,18511;677,63878
11,44000;72,18852;678,08884
11,48000;72,19187;676,32701
11,52000;72,19509;673,47665
11,56000;72,19851;672,29583
11,60000;72,20185;669,88254
11,64000;72,20519;666,97802
11,68000;72,20831;664,72949
11,72000;72,21195;665,01074
11,76000;72,21525;661,83261
11,80000;72,21853;659,28507
11,84000;72,22182;659,01373
11,88000;72,22517;660,33215
11,92000;72,22846;659,26793
11,96000;72,23156;658,93242
12,00000;72,23521;662,60537
12,04000;72,23850;658,96562
12,08000;72,24179;656,55266
12,12000;72,24514;656,84202
12,16000;72,24842;656,88128
12,20000;72,25178;655,33048
12,24000;72,25500;654,92820
12,28000;72,25853;655,05179
12,32000;72,26182;651,49292
12,36000;72,26516;649,18958
12,40000;72,26840;648,44065
12,44000;72,27174;647,38719
12,48000;72,27509;645,41576
12,52000;72,27838;644,51844
12,56000;72,28173;643,63200
12,60000;72,28514;642,31236
12,64000;72,28842;641,26700
12,68000;72,29171;640,17754
12,72000;72,29507;640,68106
12,76000;72,29841;640,23822
12,80000;72,30170;638,38363
12,84000;72,30510;639,10028
12,88000;72,30857;638,31029
12,92000;72,31181;635,98086
12,96000;72,31509;636,03567
13,00000;72,31850;636,29784
13,04000;72,32173;634,09205
13,08000;72,32502;632,06227
13,12000;72,32849;633,56892
13,16000;72,33177;632,60598
13,20000;72,33512;630,12601
13,24000;72,33841;628,37866
13,28000;72,34176;628,09591
13,32000;72,34510;625,72565
13,36000;72,34839;623,50379
13,40000;72,35174;622,57065
13,44000;72,35515;620,40403
13,48000;72,35856;618,62008
13,52000;72,36178;617,69960
13,56000;72,36514;616,63445
13,60000;72,36848;617,30710
13,64000;72,37177;617,68717
13,68000;72,37512;617,13122
13,72000;72,37853;616,14234
13,76000;72,38188;615,05982
13,80000;72,38504;613,14763
13,84000;72,38845;613,86330
13,88000;72,39186;613,93003
13,92000;72,39503;612,52196
13,96000;72,39850;611,90394
14,00000;72,40191;612,52480
14,04000;72,40519;609,68017
14,08000;72,40854;608,45907
14,12000;72,41189;608,24482
14,16000;72,41518;606,18506
14,20000;72,41853;603,35840
14,24000;72,42181;601,25496
14,28000;72,42517;599,92480
14,32000;72,42851;598,71087
14,36000;72,43186;597,75016
14,40000;72,43515;596,61986
14,44000;72,43849;596,25460
14,48000;72,44191;595,98065
14,52000;72,44513;595,17492
14,56000;72,44848;594,92751
14,60000;72,45189;597,19332
14,64000;72,45518;595,27275
14,68000;72,45853;594,10864
14,72000;72,46187;593,51237
14,76000;72,46516;593,02347
14,80000;72,46839;591,07644
14,84000;72,47180;591,53554
14,88000;72,47515;590,36617
14,92000;72,47844;587,75907
14,96000;72,48178;587,64950
15,00000;72,48519;585,58397
15,04000;72,48848;582,25915
15,08000;72,49177;581,38659
15,12000;72,49506;580,95749
15,16000;72,49847;578,42718
15,20000;72,50182;576,70674
15,24000;72,50516;575,18911
15,28000;72,50845;575,58604
15,32000;72,51186;574,94645
15,36000;72,51509;573,74034
15,40000;72,51843;574,39492
15,44000;72,52179;573,10518
15,48000;72,52513;572,48753
15,52000;72,52848;571,01790
15,56000;72,53183;571,02395
15,60000;72,53517;570,52793
15,64000;72,53847;568,84540
15,68000;72,54181;568,75013
15,72000;72,54516;568,17736
15,76000;72,54851;566,09684
15,80000;72,55179;563,06915
15,84000;72,55509;562,51544
15,88000;72,55855;562,19501
15,92000;72,56178;560,64539
15,96000;72,56507;559,27024
16,00000;72,56848;559,70838
16,04000;72,57177;557,37854
16,08000;72,57511;555,67650
16,12000;72,57852;555,90668
16,16000;72,58188;555,76074
16,20000;72,58522;554,75747
16,24000;72,58851;553,00891
16,28000;72,59186;553,72035
16,32000;72,59520;552,54726
16,36000;72,59856;550,67828
16,40000;72,60184;549,73210
16,44000;72,60519;548,01106
16,48000;72,60854;548,01889
16,52000;72,61183;547,84673
16,56000;72,61518;546,44085
16,60000;72,61852;546,17431
16,64000;72,62193;546,82679
16,68000;72,62516;544,39651
16,72000;72,62851;544,02277
16,76000;72,63192;543,81196
16,80000;72,63515;542,04157
16,84000;72,63849;541,26284
16,88000;72,64196;540,83429
16,92000;72,64525;538,26049
16,96000;72,64853;535,72794
17,00000;72,65183;534,81739
17,04000;72,65517;533,99410
17,08000;72,65847;533,22073
17,12000;72,66169;531,67590
17,16000;72,66515;533,43014
17,20000;72,66851;530,37195
17,24000;72,67185;529,20915
17,28000;72,67508;529,47886
17,32000;72,67843;528,99988
17,36000;72,68184;528,46144
17,40000;72,68513;527,68989
17,44000;72,68853;527,78115
17,48000;72,69194;528,47322
17,52000;72,69518;525,81499
17,56000;72,69846;523,71500
17,60000;72,70181;525,53150
17,64000;72,70522;526,09881
17,68000;72,70844;521,81743
17,72000;72,71179;521,89692
17,76000;72,71514;520,67195
17,80000;72,71843;519,00567
17,84000;72,72148;517,89014
17,88000;72,72519;517,55463
17,92000;72,72842;515,35415
17,96000;72,73182;514,33304
18,00000;72,73517;514,07041
18,04000;72,73846;511,34326
18,08000;72,74181;511,57642
18,12000;72,74515;511,26657
18,16000;72,74851;509,84719
18,20000;72,75185;510,60114
18,24000;72,75514;507,67795
18,28000;72,75843;507,67404
18,32000;72,76183;507,66785
18,36000;72,76519;506,94933
18,40000;72,76841;505,35300
18,44000;72,77177;504,38731
18,48000;72,77511;503,45552
18,52000;72,77846;502,39111
18,56000;72,78163;500,31198
18,60000;72,78528;502,32881
18,64000;72,78857;497,73306
18,68000;72,79185;494,32856
18,72000;72,79514;494,02849
18,76000;72,79849;491,97217
18,80000;72,80178;492,03150
18,84000;72,80518;492,47486
18,88000;72,80860;493,59710
18,92000;72,81188;491,01757
18,96000;72,81517;489,28927
19,00000;72,81846;488,92498
19,04000;72,82180;488,01657
19,08000;72,82516;487,14513
19,12000;72,82844;486,84496
19,16000;72,83191;487,95491
19,20000;72,83520;486,65223
19,24000;72,83849;483,13295
19,28000;72,84184;482,48740
19,32000;72,84518;481,67426
19,36000;72,84847;480,33851
19,40000;72,85182;479,52863
19,44000;72,85523;478,91717
19,48000;72,85858;477,19418
19,52000;72,86187;473,13874
19,56000;72,86515;471,24368
19,60000;72,86844;471,55959
19,64000;72,87179;470,62850
19,68000;72,87507;468,08771
19,72000;72,87843;468,20715
19,76000;72,88189;467,76757
19,80000;72,88513;466,24439
19,84000;72,88841;465,62711
19,88000;72,89176;464,71958
19,92000;72,89511;464,96177
19,96000;72,89839;462,29721
20,00000;72,90174;462,94336
20,04000;72,90510;462,55044
20,08000;72,90838;461,00756
20,12000;72,91173;460,14646
20,16000;72,91508;460,23480
20,20000;72,91842;458,12493
20,24000;72,92171;457,01046
20,28000;72,92512;455,50372
20,32000;72,92848;454,61180
20,36000;72,93182;452,45332
20,40000;72,93511;451,11473
20,44000;72,93840;448,96966
20,48000;72,94174;446,10118
20,52000;72,94509;444,30215
20,56000;72,94832;442,55997
20,60000;72,95173;441,53975
20,64000;72,95514;441,14674
20,68000;72,95831;438,94988
20,72000;72,96177;439,53941
20,76000;72,96518;437,88743
20,80000;72,96841;436,42907
20,84000;72,97176;436,80132
20,88000;72,97517;437,47607
20,92000;72,97845;435,98250
20,96000;72,98180;434,40624
21,00000;72,98497;433,97280
21,04000;72,98850;434,14976
21,08000;72,99179;431,15402
21,12000;72,99508;430,72822
21,16000;72,99843;429,19903
21,20000;73,00183;426,55207
21,24000;73,00518;424,50838
21,28000;73,00847;421,94193
21,32000;73,01182;421,21354
21,36000;73,01517;420,12455
21,40000;73,01846;419,18848
21,44000;73,02186;419,23225
21,48000;73,02521;417,18050
21,52000;73,02850;415,47185
21,56000;73,03178;413,52697
21,60000;73,03520;414,76097
21,64000;73,03854;413,90103
21,68000;73,04178;412,74205
21,72000;73,04518;413,03779
21,76000;73,04852;411,70456
21,80000;73,05182;410,25337
21,84000;73,05516;408,90602
21,88000;73,05852;409,20619
21,92000;73,06180;406,87281
21,96000;73,06515;406,14577
22,00000;73,06850;405,95406
22,04000;73,07184;404,19456
22,08000;73,07525;403,14533
22,12000;73,07854;401,80613
22,16000;73,08189;401,34685
22,20000;73,08524;400,15015
22,24000;73,08859;397,95279
22,28000;73,09181;396,46239
22,32000;73,09516;397,21089
22,36000;73,09839;395,33121
22,40000;73,10187;395,46615
22,44000;73,10515;392,92742
22,48000;73,10850;392,19698
22,52000;73,11185;391,45732
22,56000;73,11508;391,98124
22,60000;73,11848;393,22465
22,64000;73,12189;392,52806
22,68000;73,12512;392,27651
22,72000;73,12859;392,63433
22,76000;73,13188;391,79879
22,80000;73,13516;389,54867
22,84000;73,13845;388,36822
22,88000;73,14180;388,12780
22,92000;73,14514;386,58895
22,96000;73,14844;384,86812
23,00000;73,15172;383,28557
23,04000;73,15514;383,48879
23,08000;73,15848;382,72357
23,12000;73,16183;379,82562
23,16000;73,16518;378,99057
23,20000;73,16852;378,13017
23,24000;73,17182;375,80414
23,28000;73,17510;374,43792
23,32000;73,17857;375,88004
23,36000;73,18186;374,33186
23,40000;73,18520;374,91024
23,44000;73,18849;375,47303
23,48000;73,19191;376,72704
23,52000;73,19525;375,62619
23,56000;73,19842;374,53212
23,60000;73,20177;374,76295
23,64000;73,20523;373,40487
23,68000;73,20847;371,75748
23,72000;73,21175;369,67795
23,76000;73,21523;369,17157
23,80000;73,21845;367,47809
23,84000;73,22180;365,78334
23,88000;73,22515;365,44611
23,92000;73,22849;364,82774
23,96000;73,23178;363,36672
24,00000;73,23513;362,84749
24,04000;73,23854;362,93210
24,08000;73,24183;361,28224
24,12000;73,24518;359,44923
24,16000;73,24852;359,36572
24,20000;73,25181;359,52895
24,24000;73,25516;358,57565
24,28000;73,25851;358,96034
24,32000;73,26174;358,81398
24,36000;73,26526;359,00821
24,40000;73,26856;357,10656
24,44000;73,27178;356,10606
24,48000;73,27519;356,42860
24,52000;73,27854;355,36201
24,56000;73,28176;352,49970
24,60000;73,28518;352,17947
24,64000;73,28858;353,32569
24,68000;73,29181;349,38843
24,72000;73,29516;348,44761
24,76000;73,29851;348,13189
24,80000;73,30186;347,08551
24,84000;73,30514;346,17125
24,88000;73,30849;346,31144
24,92000;73,31185;345,36715
24,96000;73,31519;344,30916
25,00000;73,31830;343,69642
25,04000;73,32183;344,70882
25,08000;73,32517;342,82268
25,12000;73,32853;342,16230
25,16000;73,33181;341,25517
25,20000;73,33516;340,17025
25,24000;73,33851;339,55155
25,28000;73,34180;338,72246
25,32000;73,34514;337,70753
25,36000;73,34855;338,15030
25,40000;73,35184;335,82125
25,44000;73,35519;334,24282
25,48000;73,35854;334,66911
25,52000;73,36188;333,58783
25,56000;73,36512;331,75074
25,60000;73,36846;330,85318
25,64000;73,37181;330,53779
25,68000;73,37510;330,63779
25,72000;73,37844;330,40559
25,76000;73,38180;328,72835
25,80000;73,38508;328,08920
25,84000;73,38849;328,32155
25,88000;73,39172;327,17260
25,92000;73,39512;326,98007
25,96000;73,39848;327,55530
26,00000;73,40183;325,37293
26,04000;73,40517;324,73507
26,08000;73,40852;323,97816
26,12000;73,41181;323,17529
26,16000;73,41516;323,52970
26,20000;73,41851;323,49725
26,24000;73,42179;320,59494
26,28000;73,42515;319,16790
26,32000;73,42843;318,47507
26,36000;73,43184;318,51153
26,40000;73,43519;316,83201
26,44000;73,43818;315,68347
26,48000;73,44183;316,65431
26,52000;73,44511;314,43306
26,56000;73,44840;314,14398
26,60000;73,45175;313,81454
26,64000;73,45521;314,37348
26,68000;73,45851;312,60638
26,72000;73,46179;311,79944
26,76000;73,46514;312,31362
26,80000;73,46849;313,24213
26,84000;73,47178;311,20318
26,88000;73,47513;310,30762
26,92000;73,47853;310,30141
26,96000;73,48182;309,16450
27,00000;73,48511;307,47089
27,04000;73,48846;307,29487
27,08000;73,49174;306,39425
27,12000;73,49510;304,98318
27,16000;73,49845;303,94013
27,20000;73,50179;302,43667
27,24000;73,50514;300,92443
27,28000;73,50849;300,62634
27,32000;73,51178;299,02265
27,36000;73,51513;298,86866
27,40000;73,51853;298,21694
27,44000;73,52177;298,87324
27,48000;73,52511;298,16648
27,52000;73,52852;298,80775
27,56000;73,53175;297,42408
27,60000;73,53503;295,84747
27,64000;73,53845;297,88103
27,68000;73,54173;296,12717
27,72000;73,54508;294,44546
27,76000;73,54849;296,31068
27,80000;73,55189;295,61641
27,84000;73,55513;293,88638
27,88000;73,55847;294,17626
27,92000;73,56182;294,07856
27,96000;73,56511;292,13496
28,00000;73,56852;291,28590
28,04000;73,57187;290,74240
28,08000;73,57515;288,44329
28,12000;73,57850;287,76147
28,16000;73,58185;286,46595
28,20000;73,58508;285,94716
28,24000;73,58849;286,38863
28,28000;73,59184;285,67535
28,32000;73,59506;285,44860
28,36000;73,59853;286,39915
28,40000;73,60182;285,73519
28,44000;73,60504;285,50657
28,48000;73,60846;286,15224
28,52000;73,61181;284,41325
28,56000;73,61503;284,45839
28,60000;73,61844;283,64856
28,64000;73,62185;284,27679
28,68000;73,62508;282,18427
28,72000;73,62849;282,15400
28,76000;73,63183;281,64976
28,80000;73,63518;279,93934
28,84000;73,63847;278,57888
28,88000;73,64176;277,35927
28,92000;73,64511;276,62583
28,96000;73,64851;274,71634
29,00000;73,65181;274,65185
29,04000;73,65515;273,57067
29,08000;73,65850;274,28677
29,12000;73,66179;273,41172
29,16000;73,66508;273,65512
29,20000;73,66843;273,65331
29,24000;73,67183;272,76201
29,28000;73,67518;272,44114
29,32000;73,67853;272,54915
29,36000;73,68188;272,68303
29,40000;73,68523;270,62886
29,44000;73,68845;270,30373
29,48000;73,69186;269,79963
29,52000;73,69522;269,42682
29,56000;73,69850;268,83802
29,60000;73,70185;268,86137
29,64000;73,70526;268,52204
29,68000;73,70854;267,10525
29,72000;73,71177;265,60321
29,76000;73,71512;265,70994
29,80000;73,71847;264,36155
29,84000;73,72182;263,01667
29,88000;73,72511;262,12630
29,92000;73,72852;261,95836
29,96000;73,73192;261,89068
30,00000;73,73515;260,51090
30,04000;73,73850;260,70888
30,08000;73,74191;260,48324
30,12000;73,74526;259,41506
30,16000;73,74854;258,76826
30,20000;73,75183;258,60392
30,24000;73,75518;257,92678
30,28000;73,75853;256,89988
30,32000;73,76175;256,48281
30,36000;73,76511;257,53104
30,40000;73,76851;257,64264
30,44000;73,77181;256,48482
30,48000;73,77509;256,65341
30,52000;73,77849;255,92619
30,56000;73,78185;254,37351
30,60000;73,78513;252,14439
30,64000;73,78854;252,84672
30,68000;73,79189;251,51102
30,72000;73,79518;250,43448
30,76000;73,79853;249,11193
30,80000;73,80188;248,79121
30,84000;73,80516;247,66587
30,88000;73,80845;247,36256
30,92000;73,81186;246,90435
30,96000;73,81509;245,49216
31,00000;73,81844;244,73099
31,04000;73,82178;243,68600
31,08000;73,82508;243,75543
31,12000;73,82842;243,02094
31,16000;73,83177;243,88651
31,20000;73,83506;242,96064
31,24000;73,83847;242,03069
31,28000;73,84182;241,54212
31,32000;73,84510;241,89609
31,36000;73,84845;242,60618
31,40000;73,85180;240,84891
31,44000;73,85503;239,84441
31,48000;73,85831;239,02073
31,52000;73,86185;239,12981
31,56000;73,86507;235,11851
31,60000;73,86842;233,64644
31,64000;73,87177;234,94724
31,68000;73,87511;233,50825
31,72000;73,87847;231,97893
31,76000;73,88175;232,69181
31,80000;73,88517;231,75252
31,84000;73,88851;231,71394
31,88000;73,89185;231,43836
31,92000;73,89527;231,87308
31,96000;73,89856;230,83051
32,00000;73,90184;230,71540
32,04000;73,90519;230,74502
32,08000;73,90848;230,66341
32,12000;73,91189;231,57727
32,16000;73,91518;231,84072
32,20000;73,91840;230,01579
32,24000;73,92182;231,83061
32,28000;73,92516;230,14382
32,32000;73,92815;229,42484
32,36000;73,93192;230,50325
32,40000;73,93526;227,65892
32,44000;73,93850;226,69544
32,48000;73,94184;225,04369
32,52000;73,94519;224,33884
32,56000;73,94848;223,91139
32,60000;73,95183;223,86021
32,64000;73,95506;224,54329
32,68000;73,95858;225,98624
32,72000;73,96187;224,88006
32,76000;73,96516;224,73107
32,80000;73,96845;225,68342
32,84000;73,97180;225,14595
32,88000;73,97515;224,52085
32,92000;73,97849;223,47907
32,96000;73,98190;225,14109
33,00000;73,98519;224,47081
33,04000;73,98847;222,58160
33,08000;73,99177;224,51237
33,12000;73,99512;223,92212
33,16000;73,99847;223,68038
33,20000;74,00175;223,07723
33,24000;74,00516;222,33492
33,28000;74,00851;220,86964
33,32000;74,01173;219,99914
33,36000;74,01521;219,56067
33,40000;74,01850;218,06215
33,44000;74,02178;216,07373
33,48000;74,02513;215,72211
33,52000;74,02848;216,52377
33,56000;74,03182;216,67727
33,60000;74,03494;216,09336
33,64000;74,03852;217,59816
33,68000;74,04182;216,98668
33,72000;74,04510;215,48851
33,76000;74,04839;216,23403
33,80000;74,05186;215,77200
33,84000;74,05508;215,64153
33,88000;74,05843;215,99275
33,92000;74,06178;215,41917
33,96000;74,06507;215,27791
34,00000;74,06842;214,04556
34,04000;74,07182;213,24176
34,08000;74,07511;212,05568
34,12000;74,07846;211,35989
34,16000;74,08181;211,42496
34,20000;74,08504;208,94073
34,24000;74,08845;208,40578
34,24400;74,08875;208,22762