File: SU - Suspension/05 - Essais/Excels essais Optimus/Test_Rotules_31_01_19/P7.is_tens_RawData/Specimen_RawData_1.csv
Temps;Déplacement;Charge
(sec);(mm);(N)
0,00000;-34,50153;27,46479
0,06000;-34,50129;27,15932
0,12000;-34,49980;30,94912
0,18000;-34,49699;42,18931
0,24000;-34,49382;58,72229
0,30000;-34,49053;76,14773
0,36000;-34,48730;96,78203
0,42000;-34,48407;117,26503
0,48000;-34,48097;137,66825
0,54000;-34,47792;159,69169
0,60000;-34,47487;180,18003
0,66000;-34,47199;200,65485
0,72000;-34,46889;221,03649
0,78000;-34,46590;241,76426
0,84000;-34,46291;260,99766
0,90000;-34,45992;280,48877
0,96000;-34,45687;300,49460
1,02000;-34,45382;318,37667
1,08000;-34,45101;335,68256
1,14000;-34,44784;353,52884
1,20000;-34,44485;369,97152
1,26000;-34,44186;385,32522
1,32000;-34,43893;401,18783
1,38000;-34,43582;416,08778
1,44000;-34,43277;431,12510
1,50000;-34,42990;445,14509
1,56000;-34,42692;459,39516
1,62000;-34,42381;473,71811
1,68000;-34,42082;485,86042
1,74000;-34,41783;497,33417
1,80000;-34,41484;510,02637
1,86000;-34,41179;522,11522
1,92000;-34,40886;533,63182
1,98000;-34,40581;544,46780
2,04000;-34,40270;556,89174
2,10000;-34,39977;568,20288
2,16000;-34,39678;575,64764
2,22000;-34,39379;582,10143
2,28000;-34,39080;584,48743
2,34000;-34,38787;581,86045
2,40000;-34,38482;573,45163
2,46000;-34,38177;560,79053
2,52000;-34,37879;550,45742
2,58000;-34,37609;543,29159
2,64000;-34,37275;540,40086
2,70000;-34,36970;533,59033
2,76000;-34,36683;529,62010
2,82000;-34,36378;529,27951
2,88000;-34,36079;527,10548
2,94000;-34,35786;524,54988
3,00000;-34,35493;522,20286
3,06000;-34,35182;521,38506
3,12000;-34,34877;519,20749
3,18000;-34,34590;515,34935
3,24000;-34,34285;515,64956
3,30000;-34,33974;514,49011
3,36000;-34,33675;512,36795
3,42000;-34,33376;509,10190
3,48000;-34,33077;506,98910
3,54000;-34,32772;505,48855
3,60000;-34,32479;502,32885
3,66000;-34,32180;500,49983
3,72000;-34,31875;499,18485
3,78000;-34,31576;498,85577
3,84000;-34,31278;497,16523
3,90000;-34,30973;496,80094
3,96000;-34,30698;495,62100
4,02000;-34,30387;496,69407
4,08000;-34,30088;495,82156
4,14000;-34,29783;496,13784
4,20000;-34,29484;497,22176
4,26000;-34,29185;497,67951
4,32000;-34,28880;499,98309
4,38000;-34,28575;498,31104
4,44000;-34,28288;497,41245
4,50000;-34,27989;498,10559
4,56000;-34,27678;499,45628
4,62000;-34,27385;498,89213
4,68000;-34,27080;497,63508
4,74000;-34,26776;497,72849
4,80000;-34,26471;498,00444
4,86000;-34,26184;493,91934
4,92000;-34,25885;494,69927
4,98000;-34,25586;492,59076
5,04000;-34,25287;492,12049
5,10000;-34,24988;489,22822
5,16000;-34,24689;488,71171
5,22000;-34,24378;487,84814
5,28000;-34,24085;484,40336
5,34000;-34,23786;483,95256
5,40000;-34,23481;483,87405
5,46000;-34,23194;482,80498
5,52000;-34,22883;482,68777
5,58000;-34,22590;481,64348
5,64000;-34,22285;481,99468
5,70000;-34,21986;482,52018
5,76000;-34,21681;483,68862
5,82000;-34,21376;483,44699
5,88000;-34,21089;483,07655
5,94000;-34,20785;483,52713
6,00000;-34,20485;481,91380
6,06000;-34,20181;480,07313
6,12000;-34,19888;478,28993
6,18000;-34,19577;478,56956
6,24000;-34,19272;477,43148
6,30000;-34,18991;476,00735
6,36000;-34,18686;475,46830
6,42000;-34,18387;474,83672
6,48000;-34,18082;474,37213
6,54000;-34,17789;472,34730
6,60000;-34,17484;472,96751
6,66000;-34,17179;473,77814
6,72000;-34,16887;470,54626
6,78000;-34,16581;470,58403
6,84000;-34,16283;468,94760
6,90000;-34,15983;469,81149
6,96000;-34,15685;467,05082
7,02000;-34,15385;467,29725
7,08000;-34,15075;467,41441
7,14000;-34,14782;466,83908
7,20000;-34,14477;466,78842
7,26000;-34,14178;465,19842
7,32000;-34,13879;465,36340
7,38000;-34,13586;464,77574
7,44000;-34,13281;465,03083
7,50000;-34,12982;463,66844
7,56000;-34,12689;463,92581
7,62000;-34,12378;463,78542
7,68000;-34,12079;463,16013
7,74000;-34,11780;462,45381
7,80000;-34,11487;462,24892
7,86000;-34,11188;462,85926
7,92000;-34,10883;463,80549
7,98000;-34,10590;462,83845
8,04000;-34,10280;463,11649
8,10000;-34,09975;463,16916
8,16000;-34,09670;462,56850
8,22000;-34,09377;460,94712
8,28000;-34,09078;461,47914
8,34000;-34,08773;461,72435
8,40000;-34,08486;460,25268
8,46000;-34,08187;460,40816
8,52000;-34,07888;460,42595
8,58000;-34,07583;461,42973
8,64000;-34,07284;459,11428
8,70000;-34,06985;459,12880
8,76000;-34,06680;458,98249
8,82000;-34,06387;458,00721
8,88000;-34,06082;458,76009
8,94000;-34,05783;457,23813
9,00000;-34,05484;457,68428
9,06000;-34,05179;458,05159
9,12000;-34,04875;459,77472
9,18000;-34,04575;459,18049
9,24000;-34,04283;458,22416
9,30000;-34,03977;459,12317
9,36000;-34,03679;458,33392
9,42000;-34,03386;457,76335
9,48000;-34,03087;457,73224
9,54000;-34,02788;456,32804
9,60000;-34,02483;455,91923
9,66000;-34,02190;453,60350
9,72000;-34,01885;453,65524
9,78000;-34,01580;453,10017
9,84000;-34,01287;451,50830
9,90000;-34,00982;451,02448
9,96000;-34,00689;451,76954
10,02000;-34,00379;451,37382
10,08000;-34,00079;448,42744
10,14000;-33,99781;447,56792
10,20000;-33,99475;448,06623
10,26000;-33,99183;447,67288
10,32000;-33,98884;447,10659
10,38000;-33,98585;446,44801
10,44000;-33,98286;446,41858
10,50000;-33,97993;446,11827
10,56000;-33,97688;446,49052
10,62000;-33,97389;446,10114
10,68000;-33,97090;446,11036
10,74000;-33,96779;445,38914
10,80000;-33,96480;444,60339
10,86000;-33,96181;445,18081
10,92000;-33,95882;443,76138
10,98000;-33,95577;443,68631
11,04000;-33,95278;442,11480
11,10000;-33,94991;440,84485
11,16000;-33,94680;441,67615
11,22000;-33,94376;441,15167
11,28000;-33,94071;441,11600
11,34000;-33,93784;439,35198
11,40000;-33,93479;440,77723
11,46000;-33,93174;439,91297
11,52000;-33,92887;439,10970
11,58000;-33,92582;438,99212
11,64000;-33,92277;439,09382
11,70000;-33,91978;438,68362
11,76000;-33,91679;437,64785
11,82000;-33,91380;436,59145
11,88000;-33,91075;436,86884
11,94000;-33,90782;436,40714
12,00000;-33,90477;435,98507
12,06000;-33,90178;435,32178
12,12000;-33,89879;435,10729
12,18000;-33,89580;434,53230
12,24000;-33,89275;434,38785
12,30000;-33,88977;432,41200
12,36000;-33,88683;432,47500
12,42000;-33,88379;431,53451
12,48000;-33,88080;429,19684
12,54000;-33,87775;427,47562
12,60000;-33,87482;427,26351
12,66000;-33,87177;426,56725
12,72000;-33,86878;426,28762
12,78000;-33,86585;424,62749
12,84000;-33,86280;425,35774
12,90000;-33,85975;425,39211
12,96000;-33,85676;425,53199
13,02000;-33,85383;423,05659
13,08000;-33,85084;423,53412
13,14000;-33,84779;423,83983
13,20000;-33,84487;422,12778
13,26000;-33,84187;421,59474
13,32000;-33,83894;421,51422
13,38000;-33,83578;422,01513
13,44000;-33,83279;419,93828
13,50000;-33,82980;419,82546
13,56000;-33,82681;419,63994
13,62000;-33,82388;419,46792
13,68000;-33,82083;419,46322
13,74000;-33,81784;417,77636
13,80000;-33,81485;417,56527
13,86000;-33,81180;416,32853
13,92000;-33,80875;414,97517
13,98000;-33,80576;413,79076
14,04000;-33,80301;411,96295
14,10000;-33,79978;414,10183
14,16000;-33,79679;410,98217
14,22000;-33,79386;410,44629
14,28000;-33,79081;410,32960
14,34000;-33,78782;409,87879
14,40000;-33,78478;409,55697
14,46000;-33,78190;408,28865
14,52000;-33,77886;408,89974
14,58000;-33,77574;410,30347
14,64000;-33,77282;407,19798
14,70000;-33,76983;406,64040
14,76000;-33,76678;406,66838
14,82000;-33,76373;406,08593
14,88000;-33,76086;404,82469
14,94000;-33,75781;404,27274
15,00000;-33,75482;403,25890
15,06000;-33,75189;402,45098
15,12000;-33,74884;401,34010
15,18000;-33,74585;400,52067
15,24000;-33,74268;404,37486
15,30000;-33,73981;399,38004
15,36000;-33,73682;400,49050
15,42000;-33,73383;398,81947
15,48000;-33,73090;397,88964
15,54000;-33,72779;397,32964
15,60000;-33,72487;395,59943
15,66000;-33,72176;395,93214
15,72000;-33,71883;394,07741
15,78000;-33,71578;394,54005
15,84000;-33,71267;394,50224
15,90000;-33,70986;392,32937
15,96000;-33,70687;391,95563
16,02000;-33,70382;391,95758
16,08000;-33,70083;390,49333
16,14000;-33,69796;388,93283
16,20000;-33,69479;390,30742
16,26000;-33,69168;391,68843
16,32000;-33,68881;389,71568
16,38000;-33,68583;388,75616
16,44000;-33,68283;388,92676
16,50000;-33,67979;389,92041
16,56000;-33,67685;387,88174
16,62000;-33,67387;387,72775
16,68000;-33,67076;387,91823
16,74000;-33,66777;386,43498
16,80000;-33,66478;385,68983
16,86000;-33,66179;385,57348
16,92000;-33,65880;384,29901
16,98000;-33,65587;383,52462
17,04000;-33,65282;383,15945
17,10000;-33,64989;382,38913
17,16000;-33,64684;383,27882
17,22000;-33,64385;381,39073
17,28000;-33,64080;381,14360
17,34000;-33,63781;381,57206
17,40000;-33,63488;379,50445
17,46000;-33,63183;379,96306
17,52000;-33,62878;378,77520
17,58000;-33,62591;377,40187
17,64000;-33,62286;378,71429
17,70000;-33,61976;378,43715
17,76000;-33,61677;379,41728
17,82000;-33,61384;377,28276
17,88000;-33,61084;377,38464
17,94000;-33,60780;377,15412
18,00000;-33,60493;375,16796
18,06000;-33,60188;376,34545
18,12000;-33,59889;375,92396
18,18000;-33,59584;374,90241
18,24000;-33,59291;374,16273
18,30000;-33,58992;373,47395
18,36000;-33,58687;373,33444
18,42000;-33,58394;372,19482
18,48000;-33,58089;371,38925
18,54000;-33,57784;371,09640
18,60000;-33,57479;371,70728
18,66000;-33,57180;369,62803
18,72000;-33,56882;369,74109
18,78000;-33,56582;368,68071
18,84000;-33,56290;367,43351
18,90000;-33,55985;367,03830
18,96000;-33,55698;366,30265
19,02000;-33,55387;366,88026
19,08000;-33,55082;365,36038
19,14000;-33,54777;364,79924
19,20000;-33,54478;364,17048
19,26000;-33,54191;363,50577
19,32000;-33,53886;364,19251
19,38000;-33,53587;363,43008
19,44000;-33,53282;364,95572
19,50000;-33,52983;363,04158
19,56000;-33,52684;362,89988
19,62000;-33,52373;362,73247
19,68000;-33,52087;361,01819
19,74000;-33,51782;361,89251
19,80000;-33,51483;361,26052
19,86000;-33,51184;360,69509
19,92000;-33,50873;360,98612
19,98000;-33,50580;359,98989
20,04000;-33,50275;360,38689
20,10000;-33,49976;359,34404
20,16000;-33,49677;358,22890
20,22000;-33,49378;357,50377
20,28000;-33,49079;357,40281
20,34000;-33,48774;354,73872
20,40000;-33,48481;354,73628
20,46000;-33,48176;354,50701
20,52000;-33,47883;353,43256
20,58000;-33,47578;353,25380
20,64000;-33,47280;351,99740
20,70000;-33,46980;352,17300
20,76000;-33,46676;351,93453
20,82000;-33,46376;350,62020
20,88000;-33,46072;350,45813
20,94000;-33,45790;349,16657
21,00000;-33,45480;350,25571
21,06000;-33,45175;349,23896
21,12000;-33,44882;348,89139
21,18000;-33,44583;347,90225
21,24000;-33,44278;348,32899
21,30000;-33,43973;347,73871
21,36000;-33,43686;346,43211
21,42000;-33,43387;346,45181
21,48000;-33,43082;346,24322
21,54000;-33,42789;344,86093
21,60000;-33,42478;344,31806
21,66000;-33,42180;344,12870
21,72000;-33,41874;343,53524
21,78000;-33,41582;342,27204
21,84000;-33,41282;341,63853
21,90000;-33,40984;340,63666
21,96000;-33,40690;340,83070
22,02000;-33,40386;339,84915
22,08000;-33,40075;340,11093
22,14000;-33,39776;340,20827
22,20000;-33,39477;338,37545
22,26000;-33,39178;339,10684
22,32000;-33,38879;338,04576
22,38000;-33,38592;337,12033
22,44000;-33,38281;338,29794
22,50000;-33,37982;337,42008
22,56000;-33,37677;336,58401
22,62000;-33,37372;338,05268
22,68000;-33,37073;337,11744
22,74000;-33,36774;336,04789
22,80000;-33,36487;335,36325
22,86000;-33,36188;335,15438
22,92000;-33,35883;334,27437
22,98000;-33,35585;333,86825
23,04000;-33,35285;332,83993
23,10000;-33,34987;332,50765
23,16000;-33,34699;331,74311
23,22000;-33,34383;332,64006
23,28000;-33,34078;331,48278
23,34000;-33,33779;331,35531
23,40000;-33,33480;331,18178
23,46000;-33,33181;330,28885
23,52000;-33,32876;329,82472
23,58000;-33,32577;328,85447
23,64000;-33,32284;328,93557
23,70000;-33,31979;328,79859
23,76000;-33,31680;328,68795
23,82000;-33,31381;330,56305
23,88000;-33,31076;328,39808
23,94000;-33,30777;327,95209
24,00000;-33,30478;327,09457
24,06000;-33,30192;326,22074
24,12000;-33,29881;327,33434
24,18000;-33,29576;326,09738
24,24000;-33,29283;325,40581
24,30000;-33,28984;325,39514
24,36000;-33,28673;324,46058
24,42000;-33,28368;324,75223
24,48000;-33,28075;322,99270
24,54000;-33,27782;322,93645
24,60000;-33,27477;323,14651
24,66000;-33,27184;322,42080
24,72000;-33,26879;321,89975
24,78000;-33,26586;322,52327
24,84000;-33,26281;321,91835
24,90000;-33,25982;321,43204
24,96000;-33,25684;321,07106
25,02000;-33,25384;321,29204
25,08000;-33,25086;321,65973
25,14000;-33,24781;320,18970
25,20000;-33,24482;319,36092
25,26000;-33,24177;319,75955
25,32000;-33,23884;318,52713
25,38000;-33,23585;319,64995
25,44000;-33,23274;318,93614
25,50000;-33,22981;319,36557
25,56000;-33,22676;319,41996
25,62000;-33,22377;318,61376
25,68000;-33,22078;318,01995
25,74000;-33,21815;317,81935
25,80000;-33,21474;319,87191
25,86000;-33,21175;317,39164
25,92000;-33,20888;317,77308
25,98000;-33,20583;317,47164
26,04000;-33,20284;316,82893
26,10000;-33,19979;316,50164
26,16000;-33,19687;314,99490
26,22000;-33,19382;316,02380
26,28000;-33,19083;315,41947
26,34000;-33,18778;316,14287
26,40000;-33,18485;313,08462
26,46000;-33,18186;313,42378
26,52000;-33,17881;313,78872
26,58000;-33,17582;312,38364
26,64000;-33,17277;312,32976
26,70000;-33,16978;312,60019
26,76000;-33,16685;312,07108
26,82000;-33,16380;312,15565
26,88000;-33,16081;310,81298
26,94000;-33,15782;310,32637
27,00000;-33,15483;310,00725
27,06000;-33,15184;309,76110
27,12000;-33,14879;308,42593
27,18000;-33,14593;308,99907
27,24000;-33,14287;307,83731
27,30000;-33,13983;308,39953
27,36000;-33,13684;307,62176
27,42000;-33,13385;306,68506
27,48000;-33,13098;306,44662
27,54000;-33,12781;306,91025
27,60000;-33,12494;304,58535
27,66000;-33,12183;305,94133
27,72000;-33,11878;305,80140
27,78000;-33,11579;305,84957
27,84000;-33,11280;304,53340
27,90000;-33,10981;303,80224
27,96000;-33,10682;304,41089
28,02000;-33,10383;304,11347
28,08000;-33,10084;302,57185
28,14000;-33,09785;302,43283
28,20000;-33,09480;302,81760
28,26000;-33,09182;302,21366
28,32000;-33,08882;302,29103
28,38000;-33,08578;302,69264
28,44000;-33,08321;302,46794
28,50000;-33,07980;304,71946
28,56000;-33,07681;301,95224
28,62000;-33,07388;301,31633
28,68000;-33,07077;301,92104
28,74000;-33,06778;301,17207
28,80000;-33,06473;301,76470
28,86000;-33,06186;301,17717
28,92000;-33,05881;301,53035
28,98000;-33,05576;300,13286
29,04000;-33,05283;299,14801
29,10000;-33,04984;299,36482
29,16000;-33,04679;299,12926
29,22000;-33,04374;299,31655
29,28000;-33,04087;297,57975
29,34000;-33,03789;297,32992
29,40000;-33,03483;298,14378
29,46000;-33,03185;297,00773
29,52000;-33,02885;295,06227
29,58000;-33,02587;296,27925
29,64000;-33,02276;296,42570
29,70000;-33,01989;295,00893
29,76000;-33,01684;295,41056
29,82000;-33,01385;295,85368
29,88000;-33,01086;295,46525
29,94000;-33,00781;295,24197
30,00000;-33,00482;296,16274
30,06000;-33,00183;295,53233
30,12000;-32,99884;296,28957
30,18000;-32,99585;295,66861
30,24000;-32,99287;295,50730
30,30000;-32,98993;294,74183
30,36000;-32,98689;295,04758
30,42000;-32,98383;294,09144
30,48000;-32,98079;292,69231
30,54000;-32,97792;291,91317
30,60000;-32,97481;292,82714
30,66000;-32,97182;292,24721
30,72000;-32,96889;291,03879
30,78000;-32,96590;290,12633
30,84000;-32,96285;290,17632
30,90000;-32,95980;289,62919
30,96000;-32,95687;287,66408
31,02000;-32,95382;288,69361
31,08000;-32,95077;288,52595
31,14000;-32,94784;288,42699
31,20000;-32,94479;287,86601
31,26000;-32,94180;287,62568
31,32000;-32,93881;288,68127
31,38000;-32,93588;287,36636
31,44000;-32,93290;288,60744
31,50000;-32,92984;288,94437
31,56000;-32,92686;288,54834
31,62000;-32,92386;287,89083
31,68000;-32,92088;288,48252
31,74000;-32,91783;288,56571
31,80000;-32,91490;287,15087
31,86000;-32,91185;287,13706
31,92000;-32,90886;285,77994
31,98000;-32,90593;285,22110
32,04000;-32,90282;285,11398
32,10000;-32,89983;283,67646
32,16000;-32,89678;284,14319
32,22000;-32,89385;282,19193
32,28000;-32,89080;282,42681
32,34000;-32,88775;281,03332
32,40000;-32,88488;280,72342
32,46000;-32,88183;281,69227
32,52000;-32,87884;280,82791
32,58000;-32,87579;280,95888
32,64000;-32,87286;280,43706
32,70000;-32,86981;280,72379
32,76000;-32,86677;280,75711
32,82000;-32,86390;279,91785
32,88000;-32,86085;279,59647
32,94000;-32,85786;279,98057
33,00000;-32,85481;280,13778
33,06000;-32,85182;278,18189
33,12000;-32,84883;278,25776
33,18000;-32,84572;278,64925
33,24000;-32,84279;277,03869
33,30000;-32,83980;277,58435
33,36000;-32,83681;278,07087
33,42000;-32,83382;278,12717
33,48000;-32,83083;276,73941
33,54000;-32,82779;276,16560
33,60000;-32,82479;275,80291
33,66000;-32,82187;275,82627
33,72000;-32,81882;274,95204
33,78000;-32,81577;275,15881
33,84000;-32,81284;274,19499
33,90000;-32,80979;274,40896
33,96000;-32,80680;274,66882
34,02000;-32,80369;273,47950
34,08000;-32,80082;272,91391
34,14000;-32,79777;273,67615
34,20000;-32,79472;273,42809
34,26000;-32,79179;272,78513
34,32000;-32,78886;271,28302
34,38000;-32,78581;272,48566
34,44000;-32,78276;270,95017
34,50000;-32,77984;270,90237
34,56000;-32,77678;270,61491
34,62000;-32,77380;271,39608
34,68000;-32,77080;272,01541
34,74000;-32,76782;269,70068
34,80000;-32,76482;270,76909
34,86000;-32,76178;270,72458
34,92000;-32,75885;269,29704
34,98000;-32,75580;269,90853
35,04000;-32,75281;267,87061
35,10000;-32,74982;268,49164
35,16000;-32,74683;267,47335
35,22000;-32,74378;268,10246
35,28000;-32,74079;267,23852
35,34000;-32,73786;267,25642
35,40000;-32,73481;267,17584
35,46000;-32,73176;266,50957
35,52000;-32,72883;266,22342
35,58000;-32,72578;265,36335
35,64000;-32,72279;265,55974
35,70000;-32,71975;265,36819
35,76000;-32,71687;263,31602
35,82000;-32,71383;265,07743
35,88000;-32,71078;264,18862
35,94000;-32,70785;263,81810
36,00000;-32,70480;263,23150
36,06000;-32,70181;262,90230
36,12000;-32,69876;263,02908
36,18000;-32,69583;261,83554
36,24000;-32,69284;262,17962
36,30000;-32,68985;262,24083
36,36000;-32,68692;260,96210
36,42000;-32,68387;260,72806
36,48000;-32,68082;261,32069
36,54000;-32,67777;261,56257
36,60000;-32,67484;260,63053
36,66000;-32,67185;261,23994
36,72000;-32,66887;260,10659
36,78000;-32,66587;261,30658
36,84000;-32,66283;260,08941
36,90000;-32,65983;258,73224
36,96000;-32,65691;259,30523
37,02000;-32,65386;258,10988
37,08000;-32,65087;257,33116
37,14000;-32,64788;257,17188
37,20000;-32,64495;257,22054
37,26000;-32,64184;257,06454
37,32000;-32,63879;256,64628
37,38000;-32,63580;256,18395
37,44000;-32,63293;255,75545
37,50000;-32,62988;256,09443
37,56000;-32,62677;254,81107
37,62000;-32,62384;254,87291
37,68000;-32,62109;255,22520
37,74000;-32,61768;255,26125
37,80000;-32,61470;254,43574
37,86000;-32,61176;253,63786
37,92000;-32,60884;253,36733
37,98000;-32,60578;253,52456
38,04000;-32,60286;252,72295
38,10000;-32,59981;252,59368
38,16000;-32,59694;252,40062
38,22000;-32,59377;252,37217
38,28000;-32,59078;251,00573
38,34000;-32,58779;250,91805
38,40000;-32,58480;250,79146
38,46000;-32,58181;251,18128
38,52000;-32,57882;250,55844
38,58000;-32,57577;250,49886
38,64000;-32,57278;250,24961
38,70000;-32,56973;250,66901
38,76000;-32,56668;250,22896
38,82000;-32,56369;249,18248
38,88000;-32,56083;248,56345
38,94000;-32,55783;249,01805
39,00000;-32,55485;248,90034
39,06000;-32,55186;247,27983
39,12000;-32,54917;247,49576
39,18000;-32,54576;249,14022
39,24000;-32,54271;246,49443
39,30000;-32,53990;246,00932
39,36000;-32,53685;246,32213
39,42000;-32,53386;246,28129
39,48000;-32,53087;245,74271
39,54000;-32,52788;244,70109
39,60000;-32,52483;245,24317
39,66000;-32,52178;245,33984
39,72000;-32,51885;244,06898
39,78000;-32,51574;245,30124
39,84000;-32,51275;243,32209
39,90000;-32,50983;243,30039
39,96000;-32,50677;243,33731
40,02000;-32,50379;242,34669
40,08000;-32,50079;242,86851
40,14000;-32,49787;242,01446
40,20000;-32,49482;242,06794
40,26000;-32,49183;240,84032
40,32000;-32,48884;241,58603
40,38000;-32,48573;242,85442
40,44000;-32,48280;240,51159
40,50000;-32,47981;240,77669
40,56000;-32,47688;240,02786
40,62000;-32,47383;240,52020
40,68000;-32,47078;240,01913
40,74000;-32,46785;239,35013
40,80000;-32,46486;238,73546
40,86000;-32,46181;239,48865
40,92000;-32,45876;238,86855
40,98000;-32,45589;237,28772
41,04000;-32,45302;238,20587
41,10000;-32,44974;239,38410
41,16000;-32,44686;238,33865
41,22000;-32,44382;237,76777
41,28000;-32,44088;237,85797
41,34000;-32,43784;238,19827
41,40000;-32,43491;237,33992
41,46000;-32,43186;236,79077
41,52000;-32,42881;236,27556
41,58000;-32,42588;236,06720
41,64000;-32,42277;237,10977
41,70000;-32,41978;235,32794
41,76000;-32,41679;235,12538
41,82000;-32,41386;234,61021
41,88000;-32,41081;234,77483
41,94000;-32,40776;234,95767
42,00000;-32,40489;234,23654
42,06000;-32,40184;234,28723
42,12000;-32,39879;234,12162
42,18000;-32,39575;233,14594
42,24000;-32,39288;233,19458
42,30000;-32,38989;232,51630
42,36000;-32,38684;232,22521
42,42000;-32,38391;231,21149
42,48000;-32,38086;231,84998
42,54000;-32,37781;231,71459
42,60000;-32,37476;232,00007
42,66000;-32,37195;230,49675
42,72000;-32,36878;231,85695
42,78000;-32,36579;230,96837
42,84000;-32,36286;230,19600
42,90000;-32,35987;229,84101
42,96000;-32,35682;230,50394
43,02000;-32,35377;230,36371
43,08000;-32,35078;230,19104
43,14000;-32,34779;230,28061
43,20000;-32,34475;230,36683
43,26000;-32,34182;230,19742
43,32000;-32,33883;230,32159
43,38000;-32,33589;230,08939
43,44000;-32,33279;230,48886
43,50000;-32,32980;228,59406
43,56000;-32,32681;228,26064
43,62000;-32,32376;228,89813
43,68000;-32,32089;228,04982
43,74000;-32,31784;228,87932
43,80000;-32,31479;228,61050
43,86000;-32,31180;228,92011
43,92000;-32,30887;227,78520
43,98000;-32,30582;228,04921
44,04000;-32,30277;227,31973
44,10000;-32,29990;226,76252
44,16000;-32,29685;228,45769
44,22000;-32,29380;226,82552
44,28000;-32,29082;226,94985
44,34000;-32,28788;226,61514
44,40000;-32,28484;227,00573
44,46000;-32,28173;226,74911
44,52000;-32,27886;225,82379
44,58000;-32,27587;226,40885
44,64000;-32,27282;226,55802
44,70000;-32,26983;226,30107
44,76000;-32,26684;225,30209
44,82000;-32,26391;224,95403
44,88000;-32,26086;225,10597
44,94000;-32,25793;224,03363
45,00000;-32,25488;225,20146
45,06000;-32,25189;223,33695
45,12000;-32,24884;224,71636
45,18000;-32,24585;222,57394
45,24000;-32,24280;222,78791
45,30000;-32,23975;223,08240
45,36000;-32,23688;222,09203
45,42000;-32,23378;223,31704
45,48000;-32,23079;222,24891
45,54000;-32,22780;221,55493
45,60000;-32,22481;222,03864
45,66000;-32,22176;221,66406
45,72000;-32,21871;221,69549
45,78000;-32,21590;221,47365
45,84000;-32,21285;220,98315
45,90000;-32,20986;220,86001
45,96000;-32,20687;221,05910
46,02000;-32,20382;220,97223
46,08000;-32,20077;219,99930
46,14000;-32,19778;220,28252
46,20000;-32,19485;219,10095
46,26000;-32,19186;218,91047
46,32000;-32,18881;218,39286
46,38000;-32,18583;218,74383
46,44000;-32,18277;216,97232
46,50000;-32,17985;216,75986
46,56000;-32,17668;216,95890
46,62000;-32,17375;215,62481
46,68000;-32,17076;216,34155
46,74000;-32,16777;215,97110
46,80000;-32,16490;215,99645
46,86000;-32,16185;215,68621
46,92000;-32,15880;215,82195
46,98000;-32,15575;215,62304
47,04000;-32,15300;214,83970
47,10000;-32,14977;216,11270
47,16000;-32,14672;215,62960
47,22000;-32,14385;214,90173
47,28000;-32,14080;215,33675
47,34000;-32,13775;214,82280
47,40000;-32,13476;214,63160
47,46000;-32,13177;213,82205
47,52000;-32,12878;213,21534
47,58000;-32,12574;213,11285
47,64000;-32,12281;212,15151
47,70000;-32,11982;211,92667
47,76000;-32,11683;210,67027
47,82000;-32,11378;210,75855
47,88000;-32,11079;209,54036
47,94000;-32,10780;209,10276
48,00000;-32,10475;209,29121
48,06000;-32,10182;208,52089
48,12000;-32,09883;207,94340
48,18000;-32,09584;207,96773
48,24000;-32,09279;207,18235
48,30000;-32,08980;207,70454
48,36000;-32,08681;206,96174
48,42000;-32,08376;206,80879
48,48000;-32,08090;205,96976
48,54000;-32,07779;206,62628
48,60000;-32,07480;206,14369
48,66000;-32,07181;206,39766
48,72000;-32,06882;205,71104
48,78000;-32,06583;204,47627
48,84000;-32,06278;204,69250
48,90000;-32,05991;203,50795
48,96000;-32,05686;204,57185
49,02000;-32,05381;202,38345
49,08000;-32,05088;202,35835
49,14000;-32,04789;201,27122
49,20000;-32,04484;201,58950
49,26000;-32,04173;200,66351
49,32000;-32,03886;199,79237
49,38000;-32,03581;199,88590
49,44000;-32,03282;199,18741
49,50000;-32,02977;199,36583
49,56000;-32,02679;197,56185
49,62000;-32,02379;198,06321
49,68000;-32,02075;198,05362
49,74000;-32,01782;197,35468
49,80000;-32,01471;197,79739
49,86000;-32,01178;196,88820
49,92000;-32,00885;196,38620
49,98000;-32,00586;195,46866
50,04000;-32,00281;195,11302
50,10000;-31,99976;195,13677
50,16000;-31,99689;193,63300
50,22000;-31,99378;194,46345
50,28000;-31,99079;193,36365
50,34000;-31,98780;193,63732
50,40000;-31,98475;193,85247
50,46000;-31,98176;191,76459
50,52000;-31,97877;191,77311
50,58000;-31,97584;191,07551
50,64000;-31,97280;190,53293
50,70000;-31,96974;190,69334
50,76000;-31,96682;190,33873
50,82000;-31,96382;189,72255
50,88000;-31,96078;190,44782
50,94000;-31,95773;188,74849
51,00000;-31,95480;188,27755
51,06000;-31,95181;188,61388
51,12000;-31,94876;188,28430
51,18000;-31,94583;188,14577
51,24000;-31,94278;187,50370
51,30000;-31,93979;187,04705
51,36000;-31,93680;187,44313
51,42000;-31,93381;186,00360
51,48000;-31,93082;185,67049
51,54000;-31,92778;185,57599
51,60000;-31,92490;184,96872
51,66000;-31,92180;184,89605
51,72000;-31,91880;184,89449
51,78000;-31,91576;184,66744
51,84000;-31,91283;183,03675
51,90000;-31,90978;184,15482
51,96000;-31,90673;183,33878
52,02000;-31,90386;181,82360
52,08000;-31,90081;182,17746
52,14000;-31,89776;181,44920
52,20000;-31,89477;180,92552
52,26000;-31,89184;180,71620
52,32000;-31,88891;180,02775
52,38000;-31,88574;180,44738
52,44000;-31,88287;179,36765
52,50000;-31,87988;179,71447
52,56000;-31,87683;179,09423
52,62000;-31,87378;179,47523
52,68000;-31,87085;179,28651
52,74000;-31,86787;178,61804
52,80000;-31,86481;178,63141
52,86000;-31,86206;178,07967
52,92000;-31,85883;178,58514
52,98000;-31,85579;177,73990
53,04000;-31,85280;177,50849
53,10000;-31,84981;177,05469
53,16000;-31,84682;176,57370
53,22000;-31,84383;176,24529
53,28000;-31,84090;175,61883
53,34000;-31,83791;175,40329
53,40000;-31,83486;174,92127
53,46000;-31,83187;175,44134
53,52000;-31,82888;173,89506
53,58000;-31,82583;174,56735
53,64000;-31,82284;174,35538
53,70000;-31,81991;173,24946
53,76000;-31,81687;173,46127
53,82000;-31,81387;173,62570
53,88000;-31,81083;172,41244
53,94000;-31,80790;171,98846
54,00000;-31,80479;172,75276
54,06000;-31,80174;172,13917
54,12000;-31,79887;171,00475
54,18000;-31,79582;171,49998
54,24000;-31,79283;171,07379
54,30000;-31,78984;171,47061
54,36000;-31,78685;170,49644
54,42000;-31,78386;171,29693
54,48000;-31,78075;170,60118
54,54000;-31,77788;169,34845
54,60000;-31,77483;169,97937
54,66000;-31,77184;170,53218
54,72000;-31,76885;170,24452
54,78000;-31,76586;170,07897
54,84000;-31,76288;169,65757
54,90000;-31,75982;170,36472
54,96000;-31,75690;168,16991
55,02000;-31,75379;168,26838
55,08000;-31,75080;167,69569
55,14000;-31,74781;167,91401
55,20000;-31,74482;168,49720
55,26000;-31,74183;167,94899
55,32000;-31,73878;167,68379
55,38000;-31,73591;167,38069
55,44000;-31,73280;167,32223
55,50000;-31,72975;166,75531
55,56000;-31,72682;166,39174
55,62000;-31,72383;166,12131
55,68000;-31,72078;165,66417
55,74000;-31,71779;165,88158
55,80000;-31,71486;165,45700
55,86000;-31,71187;164,79366
55,92000;-31,70877;165,22211
55,98000;-31,70583;164,27728
56,04000;-31,70284;164,17250
56,10000;-31,69979;164,18351
56,16000;-31,69681;163,99930
56,22000;-31,69388;162,54029
56,28000;-31,69083;162,97515
56,34000;-31,68784;163,23178
56,40000;-31,68485;162,63250
56,46000;-31,68180;161,96774
56,52000;-31,67881;160,97679
56,58000;-31,67582;161,05674
56,64000;-31,67289;160,41731
56,70000;-31,66984;160,26723
56,76000;-31,66685;160,13742
56,82000;-31,66392;159,49364
56,88000;-31,66087;159,63705
56,94000;-31,65776;158,44794
57,00000;-31,65477;158,94782
57,06000;-31,65185;157,97919
57,12000;-31,64886;157,50163
57,18000;-31,64581;157,18017
57,24000;-31,64293;157,50329
57,30000;-31,63989;157,65822
57,36000;-31,63684;157,42290
57,42000;-31,63379;156,99386
57,48000;-31,63092;156,59019
57,54000;-31,62781;157,49757
57,60000;-31,62476;156,92962
57,66000;-31,62183;156,91346
57,72000;-31,61884;156,32530
57,78000;-31,61585;155,68816
57,84000;-31,61280;155,82253
57,90000;-31,60981;154,50002
57,96000;-31,60682;154,52353
58,02000;-31,60377;154,72556
58,08000;-31,60084;154,56059
58,14000;-31,59780;154,02721
58,20000;-31,59486;154,03843
58,26000;-31,59182;154,06692
58,32000;-31,58889;152,63131
58,38000;-31,58584;153,36922
58,44000;-31,58285;153,31815
58,50000;-31,57992;153,78518
58,56000;-31,57681;152,80710
58,62000;-31,57376;153,03587
58,68000;-31,57077;153,21679
58,74000;-31,56778;152,65251
58,80000;-31,56479;152,69634
58,86000;-31,56168;152,87839
58,92000;-31,55887;151,79769
58,98000;-31,55576;153,17792
59,04000;-31,55277;152,03713
59,10000;-31,54978;151,90052
59,16000;-31,54685;152,15566
59,22000;-31,54387;151,79622
59,28000;-31,54075;151,33540
59,34000;-31,53789;151,26240
59,40000;-31,53483;151,31249
59,46000;-31,53179;150,96258
59,52000;-31,52880;149,75633
59,58000;-31,52575;149,97158
59,64000;-31,52282;149,59959
59,70000;-31,51977;149,88247
59,76000;-31,51684;148,63224
59,82000;-31,51379;148,63375
59,88000;-31,51074;149,33127
59,94000;-31,50781;149,22089
60,00000;-31,50476;149,18912
60,06000;-31,50177;148,60012
60,12000;-31,49878;149,09320
60,18000;-31,49585;148,61852
60,24000;-31,49281;148,03222
60,30000;-31,48976;147,50701
60,36000;-31,48683;147,71487
60,42000;-31,48383;147,68888
60,48000;-31,48079;147,28800
60,54000;-31,47774;148,09446
60,60000;-31,47481;146,14946
60,66000;-31,47182;146,61987
60,72000;-31,46877;145,48328
60,78000;-31,46578;145,53083
60,84000;-31,46279;145,04784
60,90000;-31,45980;144,99682
60,96000;-31,45675;144,66371
61,02000;-31,45382;142,94597
61,08000;-31,45089;143,67736
61,14000;-31,44784;144,02521
61,20000;-31,44485;143,17567
61,26000;-31,44180;143,01897
61,32000;-31,43881;142,13026
61,38000;-31,43576;141,71023
61,44000;-31,43290;140,43121
61,50000;-31,42979;141,21686
61,56000;-31,42680;140,58325
61,62000;-31,42387;140,78263
61,68000;-31,42070;140,98183
61,74000;-31,41771;139,69291
61,80000;-31,41472;140,31248
61,86000;-31,41185;139,15336
61,92000;-31,40880;138,77173
61,98000;-31,40581;138,58826
62,04000;-31,40288;137,77637
62,10000;-31,39983;138,33923
62,16000;-31,39684;135,99561
62,22000;-31,39379;135,18416
62,28000;-31,39086;134,98404
62,34000;-31,38787;133,99965
62,40000;-31,38483;133,77166
62,46000;-31,38190;132,88265
62,52000;-31,37885;132,94680
62,58000;-31,37586;132,36490
62,64000;-31,37275;132,10268
62,70000;-31,36982;130,87993
62,76000;-31,36677;130,85383
62,82000;-31,36378;130,12327
62,88000;-31,36091;128,74029
62,94000;-31,35774;128,88627
63,00000;-31,35481;127,46265
63,06000;-31,35176;128,14292
63,12000;-31,34883;126,63195
63,18000;-31,34578;126,81710
63,24000;-31,34279;125,55115
63,30000;-31,33992;126,87757
63,36000;-31,33681;125,48437
63,42000;-31,33383;124,86936
63,48000;-31,33083;123,10451
63,54000;-31,32808;122,65838
63,60000;-31,32474;122,13241
63,66000;-31,32175;121,29672
63,72000;-31,31888;120,70972
63,78000;-31,31583;121,83533
63,84000;-31,31284;120,90744
63,90000;-31,30979;120,29078
63,96000;-31,30680;120,34919
64,02000;-31,30381;120,44022
64,08000;-31,30064;120,31923
64,14000;-31,29783;118,24878
64,20000;-31,29478;117,62399
64,26000;-31,29179;117,36746
64,27200;-31,29119;116,92541