File: SU - Suspension/05 - Essais/Excels essais Optimus/Temoins et tests triangles/Temoins alu carbone/temoin deja tiré/temoin deja tiré.is_tens_RawData/Specimen_RawData_1.csv
Temps;Déplacement;Charge
(sec);(mm);(N)
0,00000;0,00813;83,66868
0,04000;0,00861;84,24997
0,08000;0,01076;94,45986
0,12000;0,01411;126,02975
0,16000;0,01788;168,63142
0,20000;0,02170;213,14933
0,24000;0,02559;256,78198
0,28000;0,02948;300,70918
0,32000;0,03312;341,39894
0,36000;0,03677;382,27635
0,40000;0,04036;421,34258
0,44000;0,04377;458,45639
0,48000;0,04723;495,03548
0,52000;0,05076;531,68531
0,56000;0,05411;567,01410
0,60000;0,05746;601,00853
0,64000;0,06087;634,28027
0,68000;0,06409;667,05220
0,72000;0,06744;699,26507
0,76000;0,07079;732,07011
0,80000;0,07414;764,10044
0,84000;0,07749;795,01700
0,88000;0,08084;825,52517
0,92000;0,08412;856,27437
0,96000;0,08747;887,45942
1,00000;0,09082;916,86863
1,04000;0,09411;947,41480
1,08000;0,09746;977,24535
1,12000;0,10081;1006,48245
1,16000;0,10415;1036,16472
1,20000;0,10750;1066,08588
1,24000;0,11091;1098,35733
1,28000;0,11420;1127,64342
1,32000;0,11749;1157,14176
1,36000;0,12083;1187,24136
1,40000;0,12418;1216,18528
1,44000;0,12741;1243,02059
1,48000;0,13076;1270,15244
1,52000;0,13417;1299,32566
1,56000;0,13740;1328,28252
1,60000;0,14074;1355,03737
1,64000;0,14409;1384,03215
1,68000;0,14738;1412,19795
1,72000;0,15079;1440,58252
1,76000;0,15414;1467,03376
1,80000;0,15743;1493,34380
1,84000;0,16083;1519,14917
1,88000;0,16412;1543,97609
1,92000;0,16747;1568,77153
1,96000;0,17088;1592,93674
2,00000;0,17417;1616,27047
2,04000;0,17751;1640,33752
2,08000;0,18086;1665,37166
2,12000;0,18421;1690,45925
2,16000;0,18750;1714,10181
2,20000;0,19079;1739,48612
2,24000;0,19420;1766,85564
2,28000;0,19754;1790,50006
2,32000;0,20077;1814,61144
2,36000;0,20418;1840,13937
2,40000;0,20759;1865,92005
2,44000;0,21076;1890,10762
2,48000;0,21417;1914,05322
2,52000;0,21757;1940,93585
2,56000;0,22086;1967,06969
2,60000;0,22421;1992,26700
2,64000;0,22744;2017,90389
2,68000;0,23091;2043,75386
2,72000;0,23420;2066,91343
2,76000;0,23748;2090,55450
2,80000;0,24083;2115,10006
2,84000;0,24412;2138,42057
2,88000;0,24747;2161,82619
2,92000;0,25088;2186,52580
2,96000;0,25417;2208,61919
3,00000;0,25745;2229,33423
3,04000;0,26080;2249,67953
3,08000;0,26415;2271,83737
3,12000;0,26750;2293,12945
3,16000;0,27073;2312,70567
3,20000;0,27419;2333,81726
3,24000;0,27754;2355,09984
3,28000;0,28089;2373,10864
3,32000;0,28412;2390,58211
3,36000;0,28747;2407,95203
3,40000;0,29088;2426,70011
3,44000;0,29416;2446,79190
3,48000;0,29751;2461,46563
3,52000;0,30086;2477,10757
3,56000;0,30415;2493,13060
3,60000;0,30744;2507,00675
3,64000;0,31079;2522,91318
3,68000;0,31419;2540,95308
3,72000;0,31748;2559,14833
3,76000;0,32065;2576,88891
3,80000;0,32424;2599,89072
3,84000;0,32753;2617,06579
3,88000;0,33088;2634,93117
3,92000;0,33422;2652,24800
3,96000;0,33751;2670,22494
4,00000;0,34080;2687,96850
4,04000;0,34421;2707,70676
4,08000;0,34750;2729,72025
4,12000;0,35084;2749,21823
4,16000;0,35419;2767,10894
4,20000;0,35742;2786,65945
4,24000;0,36077;2805,94584
4,28000;0,36418;2828,26051
4,32000;0,36747;2848,61419
4,36000;0,37075;2867,04283
4,40000;0,37416;2886,34636
4,44000;0,37745;2907,71313
4,48000;0,38074;2924,97091
4,52000;0,38415;2944,53930
4,56000;0,38744;2965,25583
4,60000;0,39072;2984,17136
4,64000;0,39401;3004,72714
4,68000;0,39754;3027,93141
4,72000;0,40083;3046,93077
4,76000;0,40412;3065,61515
4,80000;0,40753;3084,14549
4,84000;0,41081;3103,28621
4,88000;0,41416;3123,44600
4,92000;0,41733;3141,87557
4,96000;0,42086;3162,85826
5,00000;0,42415;3182,88766
5,04000;0,42749;3200,67182
5,08000;0,43078;3220,27281
5,12000;0,43413;3241,21490
5,16000;0,43754;3261,05282
5,20000;0,44083;3279,83722
5,24000;0,44406;3299,95006
5,28000;0,44758;3319,95450
5,32000;0,45075;3339,81439
5,36000;0,45416;3358,56713
5,40000;0,45751;3378,78019
5,44000;0,46080;3398,21316
5,48000;0,46409;3416,87910
5,52000;0,46749;3436,76470
5,56000;0,47078;3456,71251
5,60000;0,47407;3474,09733
5,64000;0,47748;3492,68913
5,68000;0,48083;3513,08025
5,72000;0,48412;3531,19187
5,76000;0,48746;3548,45151
5,80000;0,49081;3568,47830
5,84000;0,49416;3587,47132
5,88000;0,49751;3606,25796
5,92000;0,50086;3624,01307
5,96000;0,50420;3642,77177
6,00000;0,50749;3660,78243
6,04000;0,51078;3677,47247
6,08000;0,51407;3695,59303
6,12000;0,51748;3714,15429
6,16000;0,52077;3731,37407
6,20000;0,52405;3749,12806
6,24000;0,52746;3767,09774
6,28000;0,53081;3785,22836
6,32000;0,53404;3802,01899
6,36000;0,53739;3819,03201
6,40000;0,54080;3837,25017
6,44000;0,54408;3855,82149
6,48000;0,54743;3872,47838
6,52000;0,55084;3890,97184
6,56000;0,55419;3909,47983
6,60000;0,55754;3925,55334
6,64000;0,56083;3941,32994
6,68000;0,56417;3958,65180
6,72000;0,56746;3974,98086
6,76000;0,57081;3991,60758
6,80000;0,57416;4009,21144
6,84000;0,57745;4026,53962
6,88000;0,58080;4042,18249
6,92000;0,58414;4058,32604
6,96000;0,58743;4073,66790
7,00000;0,59078;4090,14337
7,04000;0,59413;4106,10996
7,08000;0,59742;4122,63200
7,12000;0,60082;4138,51514
7,16000;0,60417;4154,08202
7,20000;0,60740;4167,98405
7,24000;0,61081;4183,31549
7,28000;0,61416;4198,92706
7,32000;0,61739;4214,31847
7,36000;0,62073;4227,19568
7,40000;0,62408;4243,54821
7,44000;0,62743;4259,04468
7,48000;0,63078;4272,95789
7,52000;0,63413;4286,71464
7,56000;0,63748;4302,85186
7,60000;0,64076;4315,74509
7,64000;0,64411;4329,46049
7,68000;0,64746;4343,95149
7,72000;0,65081;4357,77307
7,76000;0,65416;4370,92781
7,80000;0,65756;4385,06193
7,84000;0,66091;4398,97887
7,88000;0,66420;4411,91085
7,92000;0,66755;4424,26354
7,96000;0,67084;4438,07989
8,00000;0,67419;4450,33424
8,04000;0,67753;4462,65973
8,08000;0,68088;4475,73140
8,12000;0,68423;4487,40758
8,16000;0,68752;4497,61897
8,20000;0,69081;4508,21742
8,24000;0,69416;4519,65183
8,28000;0,69756;4530,61797
8,32000;0,70079;4539,11535
8,36000;0,70420;4547,12026
8,40000;0,70761;4556,37425
8,44000;0,71090;4563,40536
8,48000;0,71419;4569,57147
8,52000;0,71753;4576,26209
8,56000;0,72088;4583,46121
8,60000;0,72417;4587,68979
8,64000;0,72752;4591,46984
8,68000;0,73093;4596,28105
8,72000;0,73416;4598,19138
8,76000;0,73744;4598,80568
8,80000;0,74085;4601,31504
8,84000;0,74414;4604,58435
8,88000;0,74755;4603,88586
8,92000;0,75084;4602,26387
8,96000;0,75418;4602,11746
9,00000;0,75753;4603,78118
9,04000;0,76082;4607,06651
9,08000;0,76411;4611,85835
9,12000;0,76752;4619,87741
9,16000;0,77087;4627,14136
9,20000;0,77409;4634,02867
9,24000;0,77756;4642,76299
9,28000;0,78091;4652,38355
9,32000;0,78414;4660,88243
9,36000;0,78743;4668,28607
9,40000;0,79084;4679,34348
9,44000;0,79418;4691,76881
9,48000;0,79753;4704,01011
9,52000;0,80082;4716,90595
9,56000;0,80423;4733,71446
9,60000;0,80752;4749,16324
9,64000;0,81075;4764,05174
9,68000;0,81415;4781,90817
9,72000;0,81750;4801,24503
9,76000;0,82079;4818,98077
9,80000;0,82420;4836,22290
9,84000;0,82743;4854,55543
9,88000;0,83083;4873,15841
9,92000;0,83412;4890,57191
9,96000;0,83741;4907,47839
10,00000;0,84082;4925,92640
10,04000;0,84417;4942,85896
10,08000;0,84734;4958,44558
10,12000;0,85086;4977,78468
10,16000;0,85415;4995,67688
10,20000;0,85738;5011,44603
10,24000;0,86079;5027,64620
10,28000;0,86414;5046,50362
10,32000;0,86749;5064,10003
10,36000;0,87077;5080,32441
10,40000;0,87418;5099,55883
10,44000;0,87753;5117,51473
10,48000;0,88082;5133,93246
10,52000;0,88423;5150,85496
10,56000;0,88758;5170,06144
10,60000;0,89086;5185,51394
10,64000;0,89421;5200,71872
10,68000;0,89756;5215,71264
10,72000;0,90085;5232,16911
10,76000;0,90408;5247,84215
10,80000;0,90754;5266,77892
10,84000;0,91083;5283,48573
10,88000;0,91418;5298,87006
10,92000;0,91753;5314,39818
10,96000;0,92076;5329,81381
11,00000;0,92417;5346,39172
11,04000;0,92751;5362,38253
11,08000;0,93080;5377,09445
11,12000;0,93427;5396,54121
11,16000;0,93762;5411,91958
11,20000;0,94091;5426,27238
11,24000;0,94420;5440,41581
11,28000;0,94754;5454,93551
11,32000;0,95083;5468,01500
11,36000;0,95406;5481,63094
11,40000;0,95735;5497,13373
11,44000;0,96088;5516,49965
11,48000;0,96411;5529,59591
11,52000;0,96745;5543,15746
11,56000;0,97086;5557,59594
11,60000;0,97409;5571,49537
11,64000;0,97744;5583,09555
11,68000;0,98079;5597,48970
11,72000;0,98413;5612,86025
11,76000;0,98754;5626,20647
11,80000;0,99095;5639,80713
11,84000;0,99418;5657,90012
11,88000;0,99753;5671,11075
11,92000;1,00082;5683,26525
11,96000;1,00410;5697,62997
12,00000;1,00745;5712,28601
12,04000;1,01086;5727,02028
12,08000;1,01409;5739,55812
12,12000;1,01744;5751,04617
12,16000;1,02079;5764,65614
12,20000;1,02401;5776,72869
12,24000;1,02748;5789,24753
12,28000;1,03083;5805,91001
12,32000;1,03418;5817,77841
12,36000;1,03741;5828,04270
12,40000;1,04082;5840,10109
12,44000;1,04416;5853,80122
12,48000;1,04739;5864,99088
12,52000;1,05074;5876,39660
12,56000;1,05421;5892,50959
12,60000;1,05744;5903,97716
12,64000;1,06079;5914,27349
12,68000;1,06413;5924,37647
12,72000;1,06748;5937,28535
12,76000;1,07077;5947,99630
12,80000;1,07412;5956,05038
12,84000;1,07747;5968,00372
12,88000;1,08081;5980,17797
12,92000;1,08416;5989,54372
12,96000;1,08745;5998,74184
13,00000;1,09080;6008,06363
13,04000;1,09421;6016,66942
13,08000;1,09744;6023,95199
13,12000;1,10084;6031,94796
13,16000;1,10419;6039,50247
13,20000;1,10742;6046,53060
13,24000;1,11077;6052,17330
13,28000;1,11418;6059,86714
13,32000;1,11753;6066,57863
13,36000;1,12075;6071,36562
13,40000;1,12416;6078,18589
13,44000;1,12757;6085,99000
13,48000;1,13080;6091,60326
13,52000;1,13415;6097,43111
13,56000;1,13755;6104,53039
13,60000;1,14078;6110,65179
13,64000;1,14413;6115,68764
13,68000;1,14754;6123,46530
13,72000;1,15083;6130,02256
13,76000;1,15400;6134,96117
13,80000;1,15758;6142,47881
13,84000;1,16087;6150,22108
13,88000;1,16428;6156,02471
13,92000;1,16745;6162,23030
13,96000;1,17086;6171,89892
14,00000;1,17421;6178,91997
14,04000;1,17749;6186,22825
14,08000;1,18078;6193,25712
14,12000;1,18419;6199,56888
14,16000;1,18754;6209,48076
14,20000;1,19077;6217,13698
14,24000;1,19412;6226,75717
14,28000;1,19746;6235,65689
14,32000;1,20087;6244,07865
14,36000;1,20410;6251,28970
14,40000;1,20751;6261,11254
14,44000;1,21086;6271,14549
14,48000;1,21409;6279,62947
14,52000;1,21743;6289,06861
14,56000;1,22084;6301,21604
14,60000;1,22413;6311,33094
14,64000;1,22748;6320,66429
14,68000;1,23083;6330,55419
14,72000;1,23411;6339,74746
14,76000;1,23746;6349,05249
14,80000;1,24075;6358,78891
14,84000;1,24404;6369,20705
14,88000;1,24745;6379,37188
14,92000;1,25074;6389,17610
14,96000;1,25408;6399,50261
15,00000;1,25749;6410,10553
15,04000;1,26084;6421,34324
15,08000;1,26413;6431,49763
15,12000;1,26742;6442,33748
15,16000;1,27083;6454,30163
15,20000;1,27417;6465,89771
15,24000;1,27746;6477,49528
15,28000;1,28081;6489,78502
15,32000;1,28422;6500,84466
15,36000;1,28745;6511,56232
15,40000;1,29080;6522,20100
15,44000;1,29396;6533,62200
15,48000;1,29743;6546,37069
15,52000;1,30078;6559,03295
15,56000;1,30419;6571,00976
15,60000;1,30748;6582,91578
15,64000;1,31082;6592,75055
15,68000;1,31417;6603,76996
15,72000;1,31752;6618,88719
15,76000;1,32087;6629,08629
15,80000;1,32422;6637,88095
15,84000;1,32757;6648,58669
15,88000;1,33091;6660,16415
15,92000;1,33420;6670,46085
15,96000;1,33755;6682,59189
16,00000;1,34090;6696,71372
16,04000;1,34425;6708,07511
16,08000;1,34754;6718,05441
16,12000;1,35088;6729,03880
16,16000;1,35423;6740,53580
16,20000;1,35758;6753,08332
16,24000;1,36075;6762,57908
16,28000;1,36422;6775,86570
16,32000;1,36756;6787,10714
16,36000;1,37085;6797,40235
16,40000;1,37420;6808,16621
16,44000;1,37761;6820,77110
16,48000;1,38084;6831,33230
16,52000;1,38419;6842,25559
16,56000;1,38759;6857,22381
16,60000;1,39076;6868,76848
16,64000;1,39411;6878,88339
16,68000;1,39746;6890,70150
16,72000;1,40081;6905,10646
16,76000;1,40416;6918,24928
16,80000;1,40744;6930,16648
16,84000;1,41079;6942,74604
16,88000;1,41414;6956,47076
16,92000;1,41749;6968,72175
16,96000;1,42078;6980,85129
17,00000;1,42419;6993,52622
17,04000;1,42753;7010,09780
17,08000;1,43082;7026,87874
17,12000;1,43411;7044,29001
17,16000;1,43752;7066,15746
17,20000;1,44081;7087,46538
17,24000;1,44416;7106,60368
17,28000;1,44750;7125,71815
17,32000;1,45085;7146,37190
17,36000;1,45408;7166,05857
17,40000;1,45737;7183,59053
17,44000;1,46084;7203,11552
17,48000;1,46413;7224,25207
17,52000;1,46741;7241,55307
17,56000;1,47082;7261,61972
17,60000;1,47417;7281,22294
17,64000;1,47746;7300,28525
17,68000;1,48081;7318,83571
17,72000;1,48404;7336,92348
17,76000;1,48750;7360,45390
17,80000;1,49079;7379,30089
17,84000;1,49414;7396,66373
17,88000;1,49749;7415,08976
17,92000;1,50084;7432,93166
17,96000;1,50406;7448,73434
18,00000;1,50741;7465,58383
18,04000;1,51076;7485,49476
18,08000;1,51417;7504,95046
18,12000;1,51722;7523,53519
18,16000;1,52092;7546,28107
18,20000;1,52421;7566,43564
18,24000;1,52750;7582,46928
18,28000;1,53085;7599,74048
18,32000;1,53420;7618,17396
18,36000;1,53749;7635,44291
18,40000;1,54083;7653,48896
18,44000;1,54424;7673,49675
18,48000;1,54753;7691,76930
18,52000;1,55088;7708,63369
18,56000;1,55411;7726,03080
18,60000;1,55752;7745,26820
18,64000;1,56086;7764,79021
18,68000;1,56421;7782,37283
18,72000;1,56750;7800,98364
18,76000;1,57085;7817,61855
18,80000;1,57420;7834,59544
18,84000;1,57743;7852,04619
18,88000;1,58083;7869,91790
18,92000;1,58418;7890,47554
18,96000;1,58747;7908,62441
19,00000;1,59082;7925,25932
19,04000;1,59423;7945,06520
19,08000;1,59752;7964,89269
19,12000;1,60080;7980,47930
19,16000;1,60421;7998,30258
19,20000;1,60756;8016,19217
19,24000;1,61079;8033,12063
19,28000;1,61408;8050,71741
19,32000;1,61754;8070,04049
19,36000;1,62077;8088,62373
19,40000;1,62412;8105,20649
19,44000;1,62747;8124,29935
19,48000;1,63076;8143,42126
19,52000;1,63405;8159,87289
19,56000;1,63745;8178,10670
19,60000;1,64074;8197,67863
19,64000;1,64415;8215,35811
19,68000;1,64744;8232,47209
19,72000;1,65079;8251,96430
19,76000;1,65414;8270,79639
19,80000;1,65748;8288,45128
19,84000;1,66077;8305,33877
19,88000;1,66412;8321,66374
19,92000;1,66747;8340,65601
19,96000;1,67076;8357,64930
20,00000;1,67405;8373,00569
20,04000;1,67745;8391,92346
20,08000;1,68080;8410,68253
20,12000;1,68403;8426,58728
20,16000;1,68744;8443,76087
20,20000;1,69085;8462,76656
20,24000;1,69408;8479,32324
20,28000;1,69748;8497,01464
20,32000;1,70089;8514,49966
20,36000;1,70412;8531,80587
20,40000;1,70747;8546,42838
20,44000;1,71082;8564,73446
20,48000;1,71411;8583,32664
20,52000;1,71745;8599,55251
20,56000;1,72080;8616,84009
20,60000;1,72409;8635,34063
20,64000;1,72744;8651,65517
20,68000;1,73073;8667,90339
20,72000;1,73407;8685,86227
20,76000;1,73748;8702,80340
20,80000;1,74077;8721,10575
20,84000;1,74412;8738,61611
20,88000;1,74747;8756,77541
20,92000;1,75082;8774,71939
20,96000;1,75416;8790,86852
21,00000;1,75745;8806,00214
21,04000;1,76086;8823,07291
21,08000;1,76421;8840,76059
21,12000;1,76750;8857,32323
21,16000;1,77085;8873,54985
21,20000;1,77419;8889,99104
21,24000;1,77742;8904,76555
21,28000;1,78083;8920,68595
21,32000;1,78424;8939,33401
21,36000;1,78747;8955,20598
21,40000;1,79081;8972,18063
21,44000;1,79416;8989,62095
21,48000;1,79745;9007,78323
21,52000;1,80080;9021,92444
21,56000;1,80421;9038,51092
21,60000;1,80750;9055,43640
21,64000;1,81090;9071,06027
21,68000;1,81419;9086,26914
21,72000;1,81754;9103,06573
21,76000;1,82083;9118,69481
21,80000;1,82418;9134,05716
21,84000;1,82747;9150,07144
21,88000;1,83075;9166,06411
21,92000;1,83416;9181,46819
21,96000;1,83745;9197,23660
22,00000;1,84074;9213,17711
22,04000;1,84415;9229,95582
22,08000;1,84750;9246,29942
22,12000;1,85078;9262,04771
22,16000;1,85413;9277,96736
22,20000;1,85754;9293,90788
22,24000;1,86071;9308,77775
22,28000;1,86412;9324,18257
22,32000;1,86747;9342,30834
22,36000;1,87075;9358,61990
22,40000;1,87416;9374,03366
22,44000;1,87751;9390,22750
22,48000;1,88080;9405,64349
22,52000;1,88409;9419,44495
22,56000;1,88737;9434,01903
22,60000;1,89078;9451,81772
22,64000;1,89413;9467,17486
22,68000;1,89748;9481,84282
22,72000;1,90077;9498,06049
22,76000;1,90412;9512,44459
22,80000;1,90740;9527,43515
22,84000;1,91075;9543,08584
22,88000;1,91404;9558,54207
22,92000;1,91745;9574,37307
22,96000;1,92086;9590,82097
23,00000;1,92409;9605,59845
23,04000;1,92755;9621,31247
23,08000;1,93084;9637,65234
23,12000;1,93413;9652,74423
23,16000;1,93742;9667,47478
23,20000;1,94089;9684,49190
23,24000;1,94412;9699,60615
23,28000;1,94752;9713,27722
23,32000;1,95087;9729,69607
23,36000;1,95416;9744,74102
23,40000;1,95745;9757,86448
23,44000;1,96080;9773,67312
23,48000;1,96414;9789,96456
23,52000;1,96743;9804,09309
23,56000;1,97084;9819,58434
23,60000;1,97419;9837,02019
23,64000;1,97754;9851,32828
23,68000;1,98083;9866,57813
23,72000;1,98417;9881,87492
23,76000;1,98752;9897,88920
23,80000;1,99087;9912,32470
23,84000;1,99422;9926,73561
23,88000;1,99757;9941,62485
23,92000;2,00092;9956,09164
23,96000;2,00420;9972,15733
24,00000;2,00749;9986,89383
24,04000;2,01084;10002,90886
24,08000;2,01425;10018,78232
24,12000;2,01748;10033,42494
24,16000;2,02088;10048,60401
24,20000;2,02423;10064,86341
24,24000;2,02746;10079,79140
24,28000;2,03081;10094,15686
24,32000;2,03422;10110,23372
24,36000;2,03751;10126,05652
24,40000;2,04079;10139,70375
24,44000;2,04420;10155,44385
24,48000;2,04749;10171,67792
24,52000;2,05084;10185,14186
24,56000;2,05413;10200,76200
24,60000;2,05748;10218,68363
24,64000;2,06076;10234,19574
24,68000;2,06411;10248,18495
24,72000;2,06752;10262,58767
24,76000;2,07075;10278,90742
24,80000;2,07416;10295,20184
24,84000;2,07739;10308,77158
24,88000;2,08079;10324,90954
24,92000;2,08420;10342,03321
24,96000;2,08761;10357,81279
25,00000;2,09084;10371,54645
25,04000;2,09419;10386,41632
25,08000;2,09759;10401,61923
25,12000;2,10076;10415,11223
25,16000;2,10417;10429,77497
25,20000;2,10752;10449,33647
25,24000;2,11081;10463,48885
25,28000;2,11410;10475,49620
25,32000;2,11744;10489,65156
25,36000;2,12079;10505,94077
25,40000;2,12408;10520,07601
25,44000;2,12749;10534,80059
25,48000;2,13084;10553,33242
25,52000;2,13419;10566,83213
25,56000;2,13753;10581,13426
25,60000;2,14088;10595,43192
25,64000;2,14417;10608,88320
25,68000;2,14746;10623,29188
25,72000;2,15081;10636,88919
25,76000;2,15410;10652,29699
25,80000;2,15744;10667,93501
25,84000;2,16073;10683,86137
25,88000;2,16414;10701,25401
25,92000;2,16749;10716,84659
25,96000;2,17084;10730,07584
26,00000;2,17407;10743,15310
26,04000;2,17753;10758,54823
26,08000;2,18088;10774,00446
26,12000;2,18411;10787,64796
26,16000;2,18728;10801,39279
26,20000;2,19099;10820,32919
26,24000;2,19421;10835,44046
26,28000;2,19750;10849,39912
26,32000;2,20085;10864,22503
26,36000;2,20420;10880,09402
26,40000;2,20749;10893,68686
26,44000;2,21084;10907,18880
26,48000;2,21418;10923,45938
26,52000;2,21747;10939,95348
26,56000;2,22076;10952,20670
26,60000;2,22417;10966,73161
26,64000;2,22752;10982,23850
26,68000;2,23081;10996,00568
26,72000;2,23415;11011,56399
26,76000;2,23750;11026,81831
26,80000;2,24085;11040,80677
26,84000;2,24396;11055,49484
26,88000;2,24749;11071,62014
26,92000;2,25089;11089,29142
26,96000;2,25424;11103,27318
27,00000;2,25747;11116,39291
27,04000;2,26082;11131,67852
27,08000;2,26423;11147,86416
27,12000;2,26746;11161,44210
27,16000;2,27075;11174,91573
27,20000;2,27427;11191,65868
27,24000;2,27744;11208,11850
27,28000;2,28079;11220,51850
27,32000;2,28414;11235,99634
27,36000;2,28749;11252,71618
27,40000;2,29077;11266,48411
27,44000;2,29406;11279,84896
27,48000;2,29741;11295,74329
27,52000;2,30082;11312,15319
27,56000;2,30417;11326,46129
27,60000;2,30746;11340,43634
27,64000;2,31080;11353,83919
27,68000;2,31415;11368,58612
27,72000;2,31744;11381,60527
27,76000;2,32073;11395,61981
27,80000;2,32414;11410,77504
27,84000;2,32749;11426,31024
27,88000;2,33071;11440,44399
27,92000;2,33412;11455,72215
27,96000;2,33741;11470,71868
28,00000;2,34070;11484,96494
28,04000;2,34405;11499,88174
28,08000;2,34745;11514,86561
28,12000;2,35068;11529,15284
28,16000;2,35415;11542,92002
28,20000;2,35750;11560,24858
28,24000;2,36079;11574,04035
28,28000;2,36408;11587,04013
28,32000;2,36748;11601,97482
28,36000;2,37083;11618,06807
28,40000;2,37412;11631,31893
28,44000;2,37747;11645,25896
28,48000;2,38082;11661,26654
28,52000;2,38417;11674,86534
28,56000;2,38745;11689,99374
28,60000;2,39086;11704,93290
28,64000;2,39415;11719,67834
28,68000;2,39744;11733,46862
28,72000;2,40079;11746,59654
28,76000;2,40414;11761,10730
28,80000;2,40748;11775,97344
28,84000;2,41077;11789,22504
28,88000;2,41412;11803,71419
28,92000;2,41747;11819,75976
28,96000;2,42088;11834,38003
29,00000;2,42411;11848,47057
29,04000;2,42751;11863,46337
29,08000;2,43086;11877,96965
29,12000;2,43403;11891,28906
29,16000;2,43750;11905,16949
29,20000;2,44091;11921,02656
29,24000;2,44419;11935,33987
29,28000;2,44748;11948,06173
29,32000;2,45089;11961,74398
29,36000;2,45424;11976,79117
29,40000;2,45753;11989,78424
29,44000;2,46082;12002,83840
29,48000;2,46422;12018,82064
29,52000;2,46757;12033,06839
29,56000;2,47086;12047,00023
29,60000;2,47433;12063,54648
29,64000;2,47756;12079,02133
29,68000;2,48091;12092,28262
29,72000;2,48419;12105,61469
29,76000;2,48748;12118,49079
29,80000;2,49083;12132,67222
29,84000;2,49418;12147,91089
29,88000;2,49747;12162,34863
29,92000;2,50087;12177,13952
29,96000;2,50422;12190,34791
30,00000;2,50745;12203,60100
30,04000;2,51080;12219,90064
30,08000;2,51415;12234,73847
30,12000;2,51750;12248,75972
30,16000;2,52084;12261,27520
30,20000;2,52419;12275,63098
30,24000;2,52748;12290,93820
30,28000;2,53077;12303,65932
30,32000;2,53418;12319,88519
30,36000;2,53747;12335,56494
30,40000;2,54081;12348,42986
30,44000;2,54410;12361,76342
30,48000;2,54745;12374,69316
30,52000;2,55080;12389,84913
30,56000;2,55415;12404,31219
30,60000;2,55744;12417,18531
30,64000;2,56078;12430,50769
30,68000;2,56413;12444,30393
30,72000;2,56748;12457,41472
30,76000;2,57077;12471,31899
30,80000;2,57424;12485,93256
30,84000;2,57752;12500,40829
30,88000;2,58075;12513,47959
30,92000;2,58416;12527,48221
30,96000;2,58751;12540,32701
31,00000;2,59074;12553,82895
31,04000;2,59415;12567,71982
31,08000;2,59749;12582,88920
31,12000;2,60078;12596,61764
31,16000;2,60407;12609,35068
31,20000;2,60754;12624,83895
31,24000;2,61083;12639,26625
31,28000;2,61418;12651,30043
31,32000;2,61752;12664,80386
31,36000;2,62087;12679,01957
31,40000;2,62416;12692,44254
31,44000;2,62745;12706,41387
31,48000;2,63086;12721,14217
31,52000;2,63421;12736,33242
31,56000;2,63755;12749,11910
31,60000;2,64084;12762,89523
31,64000;2,64419;12777,45515
31,68000;2,64748;12789,55489
31,72000;2,65083;12802,26409
31,76000;2,65406;12814,01664
31,80000;2,65752;12828,77177
31,84000;2,66081;12842,30500
31,88000;2,66416;12856,29719
31,92000;2,66757;12871,39505
31,96000;2,67092;12884,96554
32,00000;2,67414;12897,67623
32,04000;2,67749;12910,12615
32,08000;2,68084;12924,34782
32,12000;2,68425;12942,40057
32,16000;2,68748;12954,63443
32,20000;2,69089;12967,83686
32,24000;2,69423;12981,35370
32,28000;2,69746;12993,08836
32,32000;2,70075;13005,27453
32,36000;2,70416;13018,57680
32,40000;2,70751;13032,81188
32,44000;2,71062;13046,18269
32,48000;2,71426;13060,94974
32,52000;2,71755;13076,88355
32,56000;2,72084;13088,74488
32,60000;2,72419;13101,88621
32,64000;2,72742;13113,91443
32,68000;2,73083;13127,36869
32,72000;2,73417;13142,26538
32,76000;2,73740;13155,99233
32,80000;2,74087;13169,25436
32,84000;2,74422;13183,12287
32,88000;2,74745;13194,63551
32,92000;2,75079;13207,63230
32,96000;2,75426;13220,87497
33,00000;2,75749;13236,18442
33,04000;2,76084;13247,41393
33,08000;2,76419;13260,01883
33,12000;2,76748;13273,09459
33,16000;2,77076;13283,11414
33,20000;2,77411;13295,87549
33,24000;2,77746;13310,40561
33,28000;2,78081;13322,85404
33,32000;2,78410;13335,97302
33,36000;2,78751;13353,24049
33,40000;2,79085;13365,62186
33,44000;2,79414;13376,33878
33,48000;2,79749;13388,85128
33,52000;2,80078;13400,99573
33,56000;2,80419;13413,93441
33,60000;2,80748;13426,85968
33,64000;2,81076;13440,35864
33,68000;2,81417;13455,66511
33,72000;2,81752;13467,78423
33,76000;2,82069;13480,26246
33,80000;2,82416;13493,57367
33,84000;2,82750;13507,23654
33,88000;2,83073;13520,00982
33,92000;2,83414;13532,29284
33,96000;2,83749;13546,19116
34,00000;2,84072;13558,95847
34,04000;2,84407;13570,46068
34,08000;2,84747;13585,46019
34,12000;2,85082;13598,70434
34,16000;2,85417;13609,37506
34,20000;2,85752;13622,75630
34,24000;2,86087;13636,69485
34,28000;2,86416;13648,27156
34,32000;2,86744;13659,35355
34,36000;2,87085;13672,91808
34,40000;2,87414;13686,73295
34,44000;2,87743;13698,01313
34,48000;2,88078;13710,98608
34,52000;2,88413;13725,27033
34,56000;2,88747;13738,22242
34,60000;2,89082;13752,05964
34,64000;2,89411;13765,18607
34,68000;2,89752;13777,19790
34,72000;2,90081;13788,85806
34,76000;2,90416;13801,89061
34,80000;2,90756;13814,99022
34,84000;2,91085;13828,46683
34,88000;2,91408;13839,83791
34,92000;2,91749;13852,97626
34,96000;2,92084;13867,40059
35,00000;2,92412;13878,79848
35,04000;2,92741;13889,59289
35,08000;2,93082;13902,73124
35,12000;2,93417;13916,55207
35,16000;2,93740;13928,59221
35,20000;2,94081;13942,53373
35,24000;2,94415;13956,90292
35,28000;2,94750;13969,27387
35,32000;2,95085;13981,17393
35,36000;2,95420;13993,51954
35,40000;2,95749;14006,55657
35,44000;2,96084;14018,71890
35,48000;2,96418;14031,76486
35,52000;2,96747;14044,48003
35,56000;2,97082;14056,28771
35,60000;2,97417;14068,76743
35,64000;2,97740;14080,23238
35,68000;2,98075;14093,53912
35,72000;2,98409;14107,00530
35,76000;2,98738;14119,79944
35,80000;2,99079;14132,33727
35,84000;2,99414;14146,45165
35,88000;2,99743;14158,80769
35,92000;3,00077;14170,90744
35,96000;3,00418;14183,72989
36,00000;3,00741;14196,06358
36,04000;3,01076;14207,76099
36,08000;3,01411;14220,96193
36,12000;3,01746;14234,19565
36,16000;3,02074;14245,66358
36,20000;3,02415;14258,59928
36,24000;3,02756;14272,02076
36,28000;3,03079;14284,20842
36,32000;3,03414;14296,94742
36,36000;3,03749;14310,31376
36,40000;3,04077;14323,48937
36,44000;3,04412;14335,51908
36,48000;3,04753;14348,34301
36,52000;3,05082;14361,22656
36,56000;3,05417;14372,89566
36,60000;3,05751;14385,69427
36,64000;3,06074;14398,95332
36,68000;3,06415;14411,51649
36,72000;3,06744;14424,37172
36,76000;3,07085;14436,99449
36,80000;3,07420;14450,22076
36,84000;3,07760;14462,06421
36,88000;3,08077;14474,77937
36,92000;3,08418;14487,44386
36,96000;3,08753;14500,35274
37,00000;3,09088;14513,67289
37,04000;3,09417;14523,95022
37,08000;3,09757;14537,95731
37,12000;3,10092;14551,03457
37,16000;3,10415;14562,57850
37,20000;3,10750;14574,92113
37,24000;3,11085;14588,03862
37,28000;3,11414;14600,23075
37,32000;3,11742;14611,91475
37,36000;3,12089;14625,50163
37,40000;3,12418;14637,91579
37,44000;3,12747;14648,93520
37,48000;3,13070;14661,65930
37,52000;3,13417;14676,07021
37,56000;3,13757;14688,71236
37,60000;3,14086;14699,41586
37,64000;3,14415;14710,54554
37,68000;3,14756;14723,71072
37,72000;3,15091;14735,98927
37,76000;3,15407;14747,48552
37,80000;3,15742;14759,71937
37,84000;3,16083;14773,33605
37,88000;3,16418;14786,95720
37,92000;3,16753;14798,05559
37,96000;3,17088;14810,21792
38,00000;3,17422;14823,40246
38,04000;3,17745;14833,25362
38,08000;3,18080;14844,50996
38,12000;3,18421;14858,88809
38,16000;3,18750;14870,15933
38,20000;3,19085;14880,54246
38,24000;3,19425;14892,68392
38,28000;3,19748;14905,17408
38,32000;3,20083;14916,02063
38,36000;3,20412;14927,11902
38,40000;3,20741;14938,85815
38,44000;3,21076;14950,44529
38,48000;3,21410;14961,32165
38,52000;3,21745;14974,00254
38,56000;3,22080;14986,21106
38,60000;3,22409;14997,29902
38,64000;3,22738;15007,46608
38,68000;3,23078;15019,04428
38,72000;3,23419;15031,57467
38,76000;3,23748;15043,30337
38,80000;3,24089;15054,91436
38,84000;3,24424;15068,48037
38,88000;3,24747;15079,49531
38,92000;3,25081;15089,43290
38,96000;3,25410;15101,42535
39,00000;3,25751;15113,32840
39,04000;3,26062;15123,64149
39,08000;3,26415;15136,41030
39,12000;3,26756;15148,52941
39,16000;3,27078;15158,99897
39,20000;3,27413;15170,39984
39,24000;3,27754;15184,87632
39,28000;3,28083;15195,76609
39,32000;3,28418;15205,87653
39,36000;3,28753;15215,79027
39,40000;3,29087;15228,04648
39,44000;3,29410;15238,19715
39,48000;3,29757;15250,39673
39,52000;3,30080;15260,54293
39,56000;3,30415;15270,65188
39,60000;3,30749;15280,60436
39,64000;3,31066;15290,81464
39,68000;3,31419;15303,68924
39,72000;3,31754;15314,46576
39,76000;3,32077;15324,30798
39,80000;3,32418;15334,46014
39,84000;3,32752;15345,82227
39,88000;3,33087;15357,19037
39,92000;3,33416;15367,01322
39,96000;3,33757;15377,43658
40,00000;3,34092;15390,67477
40,04000;3,34415;15399,71679
40,08000;3,34749;15409,56050
40,12000;3,35084;15420,83323
40,16000;3,35407;15431,26106
40,20000;3,35748;15441,43409
40,24000;3,36083;15452,49075
40,28000;3,36412;15463,27919
40,32000;3,36746;15472,25565
40,36000;3,37075;15482,05167
40,40000;3,37416;15496,34784
40,44000;3,37751;15507,73531
40,48000;3,38092;15515,52117
40,52000;3,38415;15524,50806
40,56000;3,38755;15532,67986
40,60000;3,39090;15543,03467
40,64000;3,39413;15551,61774
40,68000;3,39748;15561,19174
40,72000;3,40083;15572,37804
40,76000;3,40417;15583,79084
40,80000;3,40752;15592,82988
40,84000;3,41087;15601,77207
40,88000;3,41416;15610,54885
40,92000;3,41739;15617,17689
40,96000;3,42080;15626,79112
41,00000;3,42420;15637,48717
41,04000;3,42743;15645,77073
41,08000;3,43084;15654,83361
41,12000;3,43413;15665,56841
41,16000;3,43760;15676,77855
41,20000;3,44083;15684,32748
41,24000;3,44417;15692,17443
41,28000;3,44740;15701,09874
41,32000;3,45075;15708,62234
41,36000;3,45416;15717,69714
41,40000;3,45745;15727,21899
41,44000;3,46085;15735,05104
41,48000;3,46396;15743,49850
41,52000;3,46743;15753,08144
41,56000;3,47084;15762,27993
41,60000;3,47413;15769,57107
41,64000;3,47742;15776,66253
41,68000;3,48082;15784,72406
41,72000;3,48411;15793,37716
41,76000;3,48740;15800,28236
41,80000;3,49069;15806,11318
41,84000;3,49410;15814,45634
41,88000;3,49745;15822,60281
41,92000;3,50073;15828,55284
41,96000;3,50414;15835,64579
42,00000;3,50755;15844,44493
42,04000;3,51084;15850,49331
42,08000;3,51419;15856,52381
42,12000;3,51760;15864,28583
42,16000;3,52088;15870,51600
42,20000;3,52417;15875,92959
42,24000;3,52758;15882,61425
42,28000;3,53087;15890,02609
42,32000;3,53410;15895,65575
42,36000;3,53751;15902,31955
42,40000;3,54079;15909,71947
42,44000;3,54414;15915,67844
42,48000;3,54749;15920,15028
42,52000;3,55084;15927,70070
42,56000;3,55419;15934,36599
42,60000;3,55747;15940,93591
42,64000;3,56088;15948,67706
42,68000;3,56423;15956,44653
42,72000;3,56758;15962,92406
42,76000;3,57087;15968,12159
42,80000;3,57416;15974,70939
42,84000;3,57750;15981,09007
42,88000;3,58079;15988,06679
42,92000;3,58408;15994,15690
42,96000;3,58743;16001,62387
43,00000;3,59078;16009,32479
43,04000;3,59407;16015,23310
43,08000;3,59741;16021,01177
43,12000;3,60082;16027,45503
43,16000;3,60405;16034,06370
43,20000;3,60740;16038,72627
43,24000;3,61081;16046,09042
43,28000;3,61410;16052,63650
43,32000;3,61744;16057,23649
43,36000;3,62085;16063,01367
43,40000;3,62414;16069,81456
43,44000;3,62749;16074,17762
43,48000;3,63078;16078,93407
43,52000;3,63412;16084,02133
43,56000;3,63741;16089,10114
43,60000;3,64082;16093,06782
43,64000;3,64411;16097,84216
43,68000;3,64740;16100,98928
43,72000;3,65081;16104,72351
43,76000;3,65409;16108,51288
43,80000;3,65738;16110,51857
43,84000;3,66079;16114,71176
43,88000;3,66414;16118,48325
43,92000;3,66743;16121,29807
43,96000;3,67090;16125,76395
44,00000;3,67430;16129,19420
44,04000;3,67747;16129,74107
44,08000;3,68082;16129,31639
44,12000;3,68417;16130,53828
44,16000;3,68740;16129,89902
44,20000;3,69087;16128,98856
44,24000;3,69427;16130,88548
44,28000;3,69750;16127,47908
44,32000;3,70085;16120,31162
44,36000;3,70414;16110,46940
44,40000;3,70749;16097,39065
44,44000;3,71089;16077,54230
44,48000;3,71424;16041,02105
44,52000;3,71753;15963,15205
44,56000;3,72202;9622,93819
44,58000;3,72495;2864,86410