File: SU - Suspension/05 - Essais/Excels essais Optimus/collage alu carbone 05_02_19/collage3.is_tens_RawData/Specimen_RawData_1.csv
Temps;Déplacement;Charge
(sec);(mm);(N)
0,00000;0,01453;51,66971
0,04000;0,01519;51,61333
0,08000;0,01758;58,41163
0,12000;0,02075;74,21646
0,16000;0,02451;92,30099
0,20000;0,02828;112,04740
0,24000;0,03205;131,87041
0,28000;0,03587;150,55165
0,32000;0,03952;106,33526
0,36000;0,04317;69,82387
0,40000;0,04676;92,98602
0,44000;0,05016;109,11715
0,48000;0,05357;126,20393
0,52000;0,05704;145,21881
0,56000;0,06045;163,08750
0,60000;0,06386;179,40315
0,64000;0,06720;196,53323
0,68000;0,07055;212,61300
0,72000;0,07384;227,94320
0,76000;0,07713;244,18994
0,80000;0,08054;260,27162
0,84000;0,08382;275,54643
0,88000;0,08717;291,11814
0,92000;0,09058;306,86161
0,96000;0,09387;324,08703
1,00000;0,09722;339,01073
1,04000;0,10051;353,96123
1,08000;0,10385;369,86254
1,12000;0,10726;386,15779
1,16000;0,11061;402,33089
1,20000;0,11390;416,68294
1,24000;0,11731;432,87883
1,28000;0,12060;447,62203
1,32000;0,12388;461,62275
1,36000;0,12723;477,27749
1,40000;0,13052;492,74010
1,44000;0,13393;507,68438
1,48000;0,13716;522,61185
1,52000;0,14057;537,52991
1,56000;0,14391;553,11294
1,60000;0,14714;567,39268
1,64000;0,15049;581,88513
1,68000;0,15390;597,11020
1,72000;0,15719;611,92266
1,76000;0,16053;626,46694
1,80000;0,16388;640,54346
1,84000;0,16723;654,34724
1,88000;0,17058;668,71773
1,92000;0,17387;681,36859
1,96000;0,17710;694,68301
2,00000;0,18050;708,57913
2,04000;0,18379;721,85039
2,08000;0,18708;733,59436
2,12000;0,19049;745,27469
2,16000;0,19384;756,40306
2,20000;0,19707;766,17077
2,24000;0,20041;776,18961
2,28000;0,20382;785,68039
2,32000;0,20717;794,08176
2,36000;0,21046;802,18744
2,40000;0,21387;810,21097
2,44000;0,21716;817,90052
2,48000;0,22050;824,68996
2,52000;0,22385;832,28322
2,56000;0,22720;840,01506
2,60000;0,23055;847,03658
2,64000;0,23390;854,18792
2,68000;0,23730;861,61010
2,72000;0,24053;867,41168
2,76000;0,24388;873,48772
2,80000;0,24723;879,59832
2,84000;0,25052;885,84917
2,88000;0,25387;892,48726
2,92000;0,25721;899,19092
2,96000;0,26050;905,49616
3,00000;0,26385;911,47767
3,04000;0,26720;918,78390
3,08000;0,27049;924,79941
3,12000;0,27390;931,50688
3,16000;0,27724;937,98088
3,20000;0,28053;945,16575
3,24000;0,28388;951,15341
3,28000;0,28723;957,77810
3,32000;0,29058;964,46155
3,36000;0,29387;970,81140
3,40000;0,29727;976,75212
3,44000;0,30062;983,23505
3,48000;0,30385;989,37396
3,52000;0,30714;995,11612
3,56000;0,31055;1001,23137
3,60000;0,31384;1007,30630
3,64000;0,31712;1013,12529
3,68000;0,32053;1019,71040
3,72000;0,32382;1027,10947
3,76000;0,32717;1032,05973
3,80000;0,33046;1037,87500
3,84000;0,33380;1044,90267
3,88000;0,33715;1050,33806
3,92000;0,34050;1056,07463
3,96000;0,34391;1063,01010
4,00000;0,34726;1070,06319
4,04000;0,35055;1076,05224
4,08000;0,35383;1081,89899
4,12000;0,35712;1088,45672
4,16000;0,36047;1095,58981
4,20000;0,36382;1101,57765
4,24000;0,36711;1108,07950
4,28000;0,37052;1115,67322
4,32000;0,37380;1122,32277
4,36000;0,37709;1128,27318
4,40000;0,38038;1133,98423
4,44000;0,38385;1140,78550
4,48000;0,38708;1146,80231
4,52000;0,39031;1152,74992
4,56000;0,39395;1161,06421
4,60000;0,39712;1167,54640
4,64000;0,40047;1172,28776
4,68000;0,40382;1178,84250
4,72000;0,40711;1185,74193
4,76000;0,41045;1191,02066
4,80000;0,41374;1197,45964
4,84000;0,41715;1205,23004
4,88000;0,42050;1212,74656
4,92000;0,42379;1218,15270
4,96000;0,42702;1223,75013
5,00000;0,43048;1230,68215
5,04000;0,43377;1236,82562
5,08000;0,43712;1242,42529
5,12000;0,44047;1249,19200
5,16000;0,44382;1255,86912
5,20000;0,44717;1262,49278
5,24000;0,45051;1268,92570
5,28000;0,45386;1275,75938
5,32000;0,45721;1281,59784
5,36000;0,46044;1287,74131
5,40000;0,46385;1294,08455
5,44000;0,46720;1301,50849
5,48000;0,47042;1307,28958
5,52000;0,47377;1313,43752
5,56000;0,47718;1320,42756
5,60000;0,48041;1326,00460
5,64000;0,48370;1331,90807
5,68000;0,48722;1339,89267
5,72000;0,49051;1346,84322
5,76000;0,49386;1353,40234
5,80000;0,49715;1359,13780
5,84000;0,50050;1367,26070
5,88000;0,50385;1373,45959
5,92000;0,50719;1380,57219
5,96000;0,51048;1387,45811
6,00000;0,51383;1395,99526
6,04000;0,51718;1402,72630
6,08000;0,52047;1409,88687
6,12000;0,52376;1417,91841
6,16000;0,52710;1425,42180
6,20000;0,53045;1431,54133
6,24000;0,53374;1438,90195
6,28000;0,53715;1447,02476
6,32000;0,54050;1453,97112
6,36000;0,54373;1461,01611
6,40000;0,54713;1468,65305
6,44000;0,55048;1475,88486
6,48000;0,55371;1483,07467
6,52000;0,55712;1489,65996
6,56000;0,56053;1498,65206
6,60000;0,56381;1506,64784
6,64000;0,56710;1514,30750
6,68000;0,57045;1523,83661
6,72000;0,57374;1535,00363
6,76000;0,57703;1544,15593
6,80000;0,58044;1556,17101
6,84000;0,58378;1568,73893
6,88000;0,58713;1580,52389
6,92000;0,59042;1592,09277
6,96000;0,59377;1603,80825
7,00000;0,59712;1616,28686
7,04000;0,60041;1629,08658
7,08000;0,60375;1641,52440
7,12000;0,60710;1654,71770
7,16000;0,61051;1667,56902
7,20000;0,61380;1680,20558
7,24000;0,61709;1692,10806
7,28000;0,62044;1704,49894
7,32000;0,62378;1716,46252
7,36000;0,62707;1728,53563
7,40000;0,63048;1741,85745
7,44000;0,63383;1753,87692
7,48000;0,63706;1764,67467
7,52000;0,64047;1775,70544
7,56000;0,64381;1785,98724
7,60000;0,64710;1796,63002
7,64000;0,65039;1805,64281
7,68000;0,65380;1816,50091
7,72000;0,65715;1825,05958
7,76000;0,66049;1833,09074
7,80000;0,66378;1840,24423
7,84000;0,66719;1848,03195
7,88000;0,67054;1855,03308
7,92000;0,67377;1860,29710
7,96000;0,67724;1865,83102
8,00000;0,68058;1870,90654
8,04000;0,68393;1874,24719
8,08000;0,68722;1876,71892
8,12000;0,69057;1878,86842
8,16000;0,69392;1880,96277
8,20000;0,69721;1881,48972
8,24000;0,70049;1881,58266
8,28000;0,70384;1882,33089
8,32000;0,70713;1884,09500
8,36000;0,71054;1885,89972
8,40000;0,71389;1886,91430
8,44000;0,71723;1888,05945
8,48000;0,72052;1888,38840
8,52000;0,72387;1888,82835
8,56000;0,72728;1891,57855
8,60000;0,73057;1892,70731
8,64000;0,73386;1892,63728
8,68000;0,73708;1893,70140
8,72000;0,74061;1895,72517
8,76000;0,74384;1897,00294
8,80000;0,74713;1898,76184
8,84000;0,75054;1901,54314
8,88000;0,75383;1904,16202
8,92000;0,75717;1905,90266
8,96000;0,76034;1907,72377
9,00000;0,76387;1912,33233
9,04000;0,76716;1915,28201
9,08000;0,77051;1917,78559
9,12000;0,77380;1920,38715
9,16000;0,77720;1923,99267
9,20000;0,78055;1927,61645
9,24000;0,78366;1931,22383
9,28000;0,78725;1936,28669
9,32000;0,79054;1941,70251
9,36000;0,79377;1946,53794
9,40000;0,79711;1952,62767
9,44000;0,80052;1961,69652
9,48000;0,80381;1969,17169
9,52000;0,80710;1976,51181
9,56000;0,81045;1983,50605
9,60000;0,81379;1992,27668
9,64000;0,81714;1999,11557
9,68000;0,82037;2006,63172
9,72000;0,82384;2014,92533
9,76000;0,82719;2023,10011
9,80000;0,83054;2029,70076
9,84000;0,83388;2036,10901
9,88000;0,83717;2043,33570
9,92000;0,84052;2051,88338
9,96000;0,84381;2057,45045
10,00000;0,84716;2064,20310
10,04000;0,85057;2071,87627
10,08000;0,85385;2077,71212
10,12000;0,85708;2082,61684
10,16000;0,86049;2089,13032
10,20000;0,86384;2094,40961
10,24000;0,86707;2098,95205
10,28000;0,87054;2104,64690
10,32000;0,87388;2110,35963
10,36000;0,87711;2115,65234
10,40000;0,88058;2120,75450
10,44000;0,88393;2127,75953
10,48000;0,88722;2132,05442
10,52000;0,89056;2137,07983
10,56000;0,89379;2142,05589
10,60000;0,89726;2149,62903
10,64000;0,90055;2155,30377
10,68000;0,90390;2159,60126
10,72000;0,90719;2165,20224
10,76000;0,91047;2170,61788
10,80000;0,91382;2175,59654
10,84000;0,91705;2180,89968
10,88000;0,92058;2188,99958
10,92000;0,92387;2194,73988
10,96000;0,92722;2200,45652
11,00000;0,93050;2205,92245
11,04000;0,93385;2212,28208
11,08000;0,93720;2217,88958
11,12000;0,94031;2223,61982
11,16000;0,94396;2231,08549
11,20000;0,94724;2237,28847
11,24000;0,95047;2242,48189
11,28000;0,95376;2247,11448
11,32000;0,95717;2253,90680
11,36000;0,96040;2259,56123
11,40000;0,96375;2264,52667
11,44000;0,96710;2272,18997
11,48000;0,97044;2280,76000
11,52000;0,97373;2287,28075
11,56000;0,97708;2292,86496
11,60000;0,98037;2299,48200
11,64000;0,98372;2305,78166
11,68000;0,98706;2312,18785
11,72000;0,99047;2318,64844
11,76000;0,99376;2326,89008
11,80000;0,99711;2333,74201
11,84000;1,00052;2340,20799
11,88000;1,00381;2348,93393
11,92000;1,00715;2355,06743
11,96000;1,01050;2361,72937
12,00000;1,01379;2368,35368
12,04000;1,01714;2376,30233
12,08000;1,02049;2383,50648
12,12000;1,02372;2389,88176
12,16000;1,02706;2395,78877
12,20000;1,03047;2402,82398
12,24000;1,03370;2410,20974
12,28000;1,03705;2417,96840
12,32000;1,04052;2426,77331
12,36000;1,04380;2434,77263
12,40000;1,04703;2441,34851
12,44000;1,05050;2449,90587
12,48000;1,05379;2459,02948
12,52000;1,05708;2466,32285
12,56000;1,06049;2475,17619
12,60000;1,06389;2484,34413
12,64000;1,06718;2492,42727
12,68000;1,07047;2500,84307
12,72000;1,07382;2509,83518
12,76000;1,07717;2518,45028
12,80000;1,08046;2526,65244
12,84000;1,08380;2535,24613
12,88000;1,08715;2544,00987
12,92000;1,09050;2553,41809
12,96000;1,09385;2562,16768
13,00000;1,09714;2571,71206
13,04000;1,10049;2581,11618
13,08000;1,10383;2590,66243
13,12000;1,10718;2599,43847
13,16000;1,11059;2608,97093
13,20000;1,11394;2618,91037
13,24000;1,11711;2627,12371
13,28000;1,12046;2636,52299
13,32000;1,12380;2645,60580
13,36000;1,12709;2654,58114
13,40000;1,13044;2662,41450
13,44000;1,13385;2673,13384
13,48000;1,13720;2682,94737
13,52000;1,14042;2691,09514
13,56000;1,14377;2699,39862
13,60000;1,14712;2708,61126
13,64000;1,15035;2716,95182
13,68000;1,15376;2726,13056
13,72000;1,15717;2736,32407
13,76000;1,16051;2745,75017
13,80000;1,16386;2754,41222
13,84000;1,16721;2762,93773
13,88000;1,17050;2772,16248
13,92000;1,17385;2780,93144
13,96000;1,17720;2790,17519
14,00000;1,18048;2799,92595
14,04000;1,18383;2809,72607
14,08000;1,18712;2818,18788
14,12000;1,19041;2828,11522
14,16000;1,19376;2837,28763
14,20000;1,19711;2847,86113
14,24000;1,20039;2857,20509
14,28000;1,20380;2867,74691
14,32000;1,20721;2878,61768
14,36000;1,21050;2887,91098
14,40000;1,21385;2896,91687
14,44000;1,21719;2907,78689
14,48000;1,22054;2917,96792
14,52000;1,22383;2927,70788
14,56000;1,22712;2938,09585
14,60000;1,23047;2949,52262
14,64000;1,23382;2960,92350
14,68000;1,23716;2971,31483
14,72000;1,24045;2981,35262
14,76000;1,24380;2992,21054
14,80000;1,24715;3002,98482
14,84000;1,25044;3012,74266
14,88000;1,25379;3023,97907
14,92000;1,25713;3035,31438
14,96000;1,26048;3045,36074
15,00000;1,26377;3056,65378
15,04000;1,26718;3067,42210
15,08000;1,27047;3077,82199
15,12000;1,27376;3088,68922
15,16000;1,27710;3098,92911
15,20000;1,28051;3110,68874
15,24000;1,28374;3120,92025
15,28000;1,28715;3132,21253
15,32000;1,29050;3143,75609
15,36000;1,29378;3154,38583
15,40000;1,29713;3164,68365
15,44000;1,30048;3176,88622
15,48000;1,30383;3188,49534
15,52000;1,30712;3199,76099
15,56000;1,31053;3212,09654
15,60000;1,31393;3224,03423
15,64000;1,31716;3235,36247
15,68000;1,32045;3247,31208
15,72000;1,32386;3259,07730
15,76000;1,32715;3271,34691
15,80000;1,33044;3283,18514
15,84000;1,33384;3295,11203
15,88000;1,33719;3306,95212
15,92000;1,34048;3318,58322
15,96000;1,34383;3329,95355
16,00000;1,34706;3342,37441
16,04000;1,35052;3354,63434
16,08000;1,35387;3366,50424
16,12000;1,35710;3377,80975
16,16000;1,36051;3389,84653
16,20000;1,36392;3404,00226
16,24000;1,36715;3414,91811
16,28000;1,37049;3426,73063
16,32000;1,37390;3439,52291
16,36000;1,37719;3451,94899
16,40000;1,38048;3464,10759
16,44000;1,38389;3476,20584
16,48000;1,38724;3489,81544
16,52000;1,39052;3501,81907
16,56000;1,39381;3513,32463
16,60000;1,39722;3526,38960
16,64000;1,40051;3539,00976
16,68000;1,40386;3550,47062
16,72000;1,40721;3561,96240
16,76000;1,41049;3574,48608
16,80000;1,41384;3586,26619
16,84000;1,41713;3598,65353
16,88000;1,42048;3611,36943
16,92000;1,42383;3623,93931
16,96000;1,42718;3635,69707
17,00000;1,43040;3647,49357
17,04000;1,43387;3660,23891
17,08000;1,43722;3672,21572
17,12000;1,44045;3684,30987
17,16000;1,44380;3696,26135
17,20000;1,44720;3709,37772
17,24000;1,45049;3721,76804
17,28000;1,45378;3733,74261
17,32000;1,45707;3745,78014
17,36000;1,46048;3757,82214
17,40000;1,46371;3769,66633
17,44000;1,46705;3782,63630
17,48000;1,47052;3797,41229
17,52000;1,47381;3809,15999
17,56000;1,47704;3820,35784
17,60000;1,48045;3832,63864
17,64000;1,48380;3846,22738
17,68000;1,48714;3858,55809
17,72000;1,49037;3871,74375
17,76000;1,49390;3885,61413
17,80000;1,49725;3899,02666
17,84000;1,50054;3909,71005
17,88000;1,50377;3921,81538
17,92000;1,50717;3934,59052
17,96000;1,51046;3946,46935
18,00000;1,51369;3958,13324
18,04000;1,51716;3972,40520
18,08000;1,52051;3985,95780
18,12000;1,52374;3998,58691
18,16000;1,52708;4009,70951
18,20000;1,53043;4023,10602
18,24000;1,53378;4035,82826
18,28000;1,53719;4050,44220
18,32000;1,54054;4063,52319
18,36000;1,54388;4076,72040
18,40000;1,54717;4089,07011
18,44000;1,55052;4102,51692
18,48000;1,55387;4115,40344
18,52000;1,55716;4127,76060
18,56000;1,56039;4140,21797
18,60000;1,56385;4155,00589
18,64000;1,56714;4169,16236
18,68000;1,57049;4181,30122
18,72000;1,57384;4194,41499
18,76000;1,57707;4208,47237
18,80000;1,58042;4221,12979
18,84000;1,58382;4234,61013
18,88000;1,58711;4247,74438
18,92000;1,59052;4262,68131
18,96000;1,59387;4277,13916
19,00000;1,59716;4289,84798
19,04000;1,60050;4302,64547
19,08000;1,60379;4315,90267
19,12000;1,60714;4329,00786
19,16000;1,61031;4342,62119
19,20000;1,61390;4358,68390
19,24000;1,61719;4372,10947
19,28000;1,62047;4383,40902
19,32000;1,62376;4397,45635
19,36000;1,62717;4411,08644
19,40000;1,63040;4423,80495
19,44000;1,63363;4437,31025
19,48000;1,63722;4452,98962
19,52000;1,64044;4467,46349
19,56000;1,64379;4481,56744
19,60000;1,64720;4495,85728
19,64000;1,65043;4508,76392
19,68000;1,65384;4523,18341
19,72000;1,65713;4536,86677
19,76000;1,66047;4552,59643
19,80000;1,66382;4566,76260
19,84000;1,66717;4580,23176
19,88000;1,67040;4594,04439
19,92000;1,67381;4608,52981
19,96000;1,67715;4622,03547
20,00000;1,68038;4635,53928
20,04000;1,68379;4649,84141
20,08000;1,68714;4665,26821
20,12000;1,69043;4678,76606
20,16000;1,69378;4693,23024
20,20000;1,69712;4707,40981
20,24000;1,70047;4721,89635
20,28000;1,70376;4734,82348
20,32000;1,70711;4749,35137
20,36000;1,71052;4763,36293
20,40000;1,71369;4776,11087
20,44000;1,71709;4790,20439
20,48000;1,72050;4805,35068
20,52000;1,72379;4820,01007
20,56000;1,72708;4832,73454
20,60000;1,73049;4846,82694
20,64000;1,73378;4861,56791
20,68000;1,73712;4875,10003
20,72000;1,74047;4889,75197
20,76000;1,74376;4904,00754
20,80000;1,74711;4917,61714
20,84000;1,75046;4931,83807
20,88000;1,75375;4946,29890
20,92000;1,75715;4959,83325
20,96000;1,76038;4973,69468
21,00000;1,76379;4987,48012
21,04000;1,76714;5001,56507
21,08000;1,77049;5015,79158
21,12000;1,77366;5029,17469
21,16000;1,77718;5043,76404
21,20000;1,78053;5059,37077
21,24000;1,78388;5073,63267
21,28000;1,78711;5086,43650
21,32000;1,79046;5100,71963
21,36000;1,79386;5114,52071
21,40000;1,79709;5126,97920
21,44000;1,80050;5143,03632
21,48000;1,80385;5157,96244
21,52000;1,80714;5171,31463
21,56000;1,81043;5184,51743
21,60000;1,81383;5197,56041
21,64000;1,81718;5212,54689
21,68000;1,82047;5226,86392
21,72000;1,82382;5241,05988
21,76000;1,82723;5256,24342
21,80000;1,83057;5270,95236
21,84000;1,83386;5284,34403
21,88000;1,83721;5297,50176
21,92000;1,84056;5312,91589
21,96000;1,84385;5327,25267
22,00000;1,84714;5340,85296
22,04000;1,85048;5354,88762
22,08000;1,85383;5369,28512
22,12000;1,85718;5383,34586
22,16000;1,86041;5397,00277
22,20000;1,86382;5411,55860
22,24000;1,86717;5426,87066
22,28000;1,87033;5439,38838
22,32000;1,87380;5454,34766
22,36000;1,87721;5469,94731
22,40000;1,88050;5484,73820
22,44000;1,88385;5497,41089
22,48000;1,88720;5512,33925
22,52000;1,89048;5526,13996
22,56000;1,89377;5538,89833
22,60000;1,89712;5551,69024
22,64000;1,90041;5566,10301
22,68000;1,90376;5580,33772
22,72000;1,90711;5595,87814
22,76000;1,91045;5609,83606
22,80000;1,91380;5623,42480
22,84000;1,91709;5637,29666
22,88000;1,92032;5650,61569
22,92000;1,92379;5666,07267
22,96000;1,92713;5680,50817
23,00000;1,93042;5694,58604
23,04000;1,93377;5706,91302
23,08000;1,93718;5722,36516
23,12000;1,94047;5736,18151
23,16000;1,94376;5748,95218
23,20000;1,94716;5764,59765
23,24000;1,95051;5778,31194
23,28000;1,95380;5790,48023
23,32000;1,95715;5804,20010
23,36000;1,96056;5818,86955
23,40000;1,96385;5833,25140
23,44000;1,96713;5845,78030
23,48000;1,97054;5859,98036
23,52000;1,97383;5872,89631
23,56000;1,97712;5886,05404
23,60000;1,98059;5899,78620
23,64000;1,98387;5915,41193
23,68000;1,98722;5928,41655
23,72000;1,99051;5942,14015
23,76000;1,99386;5956,37299
23,80000;1,99721;5969,89654
23,84000;2,00050;5983,48007
23,88000;2,00379;5997,73154
23,92000;2,00719;6011,65369
23,96000;2,01054;6026,10596
24,00000;2,01383;6039,14857
24,04000;2,01718;6051,82387
24,08000;2,02059;6065,73597
24,12000;2,02387;6080,23480
24,16000;2,02716;6092,16616
24,20000;2,03051;6106,12184
24,24000;2,03386;6120,54765
24,28000;2,03715;6133,53066
24,32000;2,04044;6146,10016
24,36000;2,04390;6161,19727
24,40000;2,04719;6175,86635
24,44000;2,05054;6187,49596
24,48000;2,05389;6201,05192
24,52000;2,05718;6214,98153
24,56000;2,06053;6228,15974
24,60000;2,06381;6240,60147
24,64000;2,06710;6253,97712
24,68000;2,07045;6268,12130
24,72000;2,07380;6281,53011
24,76000;2,07709;6295,45525
24,80000;2,08049;6310,04348
24,84000;2,08378;6323,38747
24,88000;2,08707;6335,99982
24,92000;2,09048;6349,55466
24,96000;2,09383;6365,48847
25,00000;2,09712;6379,86138
25,04000;2,10046;6391,90227
25,08000;2,10381;6404,91545
25,12000;2,10716;6417,46894
25,16000;2,11045;6429,28407
25,20000;2,11356;6442,17134
25,24000;2,11727;6457,35189
25,28000;2,12043;6470,93281
25,32000;2,12372;6483,71056
25,36000;2,12713;6497,48966
25,40000;2,13048;6510,56767
25,44000;2,13377;6523,53615
25,48000;2,13706;6536,65364
25,52000;2,14046;6551,75894
25,56000;2,14381;6565,42331
25,60000;2,14716;6578,02820
25,64000;2,15045;6591,19114
25,68000;2,15380;6603,20744
25,72000;2,15714;6616,02691
25,76000;2,16043;6628,94174
25,80000;2,16384;6642,24550
25,84000;2,16713;6657,39104
25,88000;2,17042;6671,34002
25,92000;2,17383;6682,75729
25,96000;2,17711;6696,50137
26,00000;2,18046;6709,48625
26,04000;2,18381;6721,65006
26,08000;2,18716;6734,44495
26,12000;2,19051;6748,30452
26,16000;2,19380;6761,56059
26,20000;2,19720;6774,84199
26,24000;2,20055;6789,27377
26,28000;2,20384;6801,79596
26,32000;2,20719;6814,43289
26,36000;2,21060;6827,07652
26,40000;2,21383;6839,94293
26,44000;2,21717;6852,65884
26,48000;2,22052;6865,26150
26,52000;2,22375;6877,68832
26,56000;2,22716;6890,77377
26,60000;2,23051;6903,39729
26,64000;2,23380;6917,88346
26,68000;2,23714;6930,46004
26,72000;2,24049;6943,74591
26,76000;2,24378;6957,03328
26,80000;2,24713;6969,67393
26,84000;2,25048;6982,49787
26,88000;2,25376;6995,03049
26,92000;2,25717;7008,13532
26,96000;2,26052;7021,62012
27,00000;2,26381;7033,87484
27,04000;2,26710;7046,48495
27,08000;2,27051;7059,64342
27,12000;2,27385;7072,85628
27,16000;2,27708;7085,54685
27,20000;2,28043;7097,22489
27,24000;2,28384;7111,24390
27,28000;2,28707;7123,95981
27,32000;2,29036;7135,68330
27,36000;2,29376;7150,46078
27,40000;2,29711;7163,61180
27,44000;2,30040;7176,26959
27,48000;2,30381;7189,42434
27,52000;2,30716;7203,47166
27,56000;2,31051;7216,20396
27,60000;2,31379;7228,27315
27,64000;2,31708;7239,99366
27,68000;2,32049;7253,26464
27,72000;2,32378;7265,93062
27,76000;2,32707;7278,91922
27,80000;2,33042;7291,75955
27,84000;2,33376;7305,24957
27,88000;2,33705;7317,87905
27,92000;2,34040;7329,73441
27,96000;2,34381;7342,43020
28,00000;2,34710;7355,51193
28,04000;2,35044;7368,24051
28,08000;2,35379;7382,16490
28,12000;2,35720;7394,94041
28,16000;2,36043;7406,56182
28,20000;2,36378;7417,70789
28,24000;2,36719;7431,40727
28,28000;2,37041;7444,32956
28,32000;2,37382;7455,26776
28,36000;2,37717;7468,63335
28,40000;2,38046;7480,92309
28,44000;2,38375;7492,92001
28,48000;2,38710;7505,93916
28,52000;2,39044;7518,43527
28,56000;2,39379;7530,53948
28,60000;2,39708;7543,77395
28,64000;2,40043;7557,16711
28,68000;2,40384;7569,23780
28,72000;2,40712;7581,27347
28,76000;2,41047;7593,67794
28,80000;2,41382;7605,53703
28,84000;2,41711;7618,91231
28,88000;2,42046;7630,99045
28,92000;2,42381;7642,85177
28,96000;2,42715;7655,05657
29,00000;2,43050;7667,99003
29,04000;2,43379;7679,77610
29,08000;2,43714;7692,39888
29,12000;2,44055;7704,92554
29,16000;2,44372;7716,90458
29,20000;2,44712;7728,86649
29,24000;2,45053;7742,82515
29,28000;2,45382;7755,29668
29,32000;2,45717;7766,79218
29,36000;2,46058;7779,38068
29,40000;2,46387;7792,09659
29,44000;2,46709;7802,49983
29,48000;2,47050;7814,88121
29,52000;2,47379;7828,33174
29,56000;2,47720;7840,57230
29,60000;2,48049;7852,69663
29,64000;2,48383;7864,54454
29,68000;2,48718;7876,48186
29,72000;2,49047;7887,91776
29,76000;2,49382;7899,87817
29,80000;2,49717;7912,50467
29,84000;2,50052;7924,62379
29,88000;2,50386;7936,79580
29,92000;2,50715;7948,91492
29,96000;2,51056;7962,01304
30,00000;2,51385;7972,96464
30,04000;2,51708;7985,32739
30,08000;2,52043;7997,86970
30,12000;2,52383;8010,15273
30,16000;2,52712;8023,41849
30,20000;2,53047;8034,06090
30,24000;2,53388;8047,30654
30,28000;2,53711;8058,30657
30,32000;2,54046;8068,73292
30,36000;2,54386;8081,11727
30,40000;2,54715;8094,43966
30,44000;2,55050;8105,90610
30,48000;2,55379;8116,88006
30,52000;2,55714;8130,81339
30,56000;2,56048;8142,03694
30,60000;2,56377;8153,18301
30,64000;2,56706;8165,90637
30,68000;2,57047;8178,27508
30,72000;2,57382;8190,68998
30,76000;2,57711;8202,48351
30,80000;2,58045;8214,69575
30,84000;2,58386;8226,54963
30,88000;2,58721;8238,47353
30,92000;2,59044;8248,88125
30,96000;2,59385;8261,18365
31,00000;2,59720;8273,16269
31,04000;2,60048;8284,50397
31,08000;2,60383;8295,50847
31,12000;2,60724;8307,60598
31,16000;2,61047;8318,47712
31,20000;2,61382;8329,61053
31,24000;2,61723;8342,75037
31,28000;2,62045;8354,71004
31,32000;2,62380;8365,47241
31,36000;2,62715;8377,27711
31,40000;2,63044;8389,19729
31,44000;2,63379;8399,77413
31,48000;2,63714;8411,77478
31,52000;2,64048;8424,15988
31,56000;2,64389;8435,16961
31,60000;2,64724;8447,98535
31,64000;2,65053;8459,05021
31,68000;2,65388;8470,77146
31,72000;2,65716;8482,66184
31,76000;2,66045;8493,48232
31,80000;2,66386;8505,62006
31,84000;2,66721;8518,10202
31,88000;2,67056;8529,30322
31,92000;2,67373;8539,60291
31,96000;2,67713;8550,86297
32,00000;2,68054;8563,62283
32,04000;2,68377;8575,05947
32,08000;2,68724;8587,01691
32,12000;2,69059;8600,02935
32,16000;2,69388;8611,48536
32,20000;2,69716;8621,26574
32,24000;2,70057;8632,12794
32,28000;2,70386;8643,98479
32,32000;2,70715;8655,13831
32,36000;2,71056;8666,34846
32,40000;2,71385;8679,77738
32,44000;2,71713;8689,34989
32,48000;2,72048;8700,25977
32,52000;2,72377;8710,99904
32,56000;2,72712;8722,38055
32,60000;2,73047;8733,88201
32,64000;2,73370;8746,08532
32,68000;2,73722;8759,58353
32,72000;2,74051;8770,90991
32,76000;2,74392;8782,32121
32,80000;2,74715;8793,02323
32,84000;2,75050;8803,86904
32,88000;2,75384;8814,27005
32,92000;2,75707;8824,25234
32,96000;2,76048;8835,74560
33,00000;2,76389;8847,87515
33,04000;2,76706;8857,97665
33,08000;2,77041;8868,85226
33,12000;2,77387;8881,70451
33,16000;2,77710;8892,21951
33,20000;2,78045;8901,48282
33,24000;2,78386;8911,60294
33,28000;2,78715;8923,37486
33,32000;2,79044;8933,60302
33,36000;2,79378;8944,15379
33,40000;2,79719;8955,51518
33,44000;2,80048;8967,15000
33,48000;2,80383;8977,30142
33,52000;2,80718;8989,19404
33,56000;2,81046;8999,30075
33,60000;2,81381;9011,28501
33,64000;2,81716;9021,84099
33,68000;2,82039;9032,03264
33,72000;2,82374;9042,74881
33,76000;2,82715;9055,96614
33,80000;2,83043;9066,36566
33,84000;2,83378;9077,30609
33,88000;2,83719;9087,97979
33,92000;2,84036;9098,08427
33,96000;2,84377;9108,75052
34,00000;2,84712;9119,77217
34,04000;2,85040;9130,64033
34,08000;2,85375;9140,39388
34,12000;2,85716;9152,69554
34,16000;2,86045;9163,99062
34,20000;2,86374;9172,75026
34,24000;2,86715;9183,46122
34,28000;2,87043;9195,16683
34,32000;2,87372;9204,35712
34,36000;2,87701;9215,61643
34,40000;2,88048;9226,85266
34,44000;2,88383;9237,15308
34,48000;2,88712;9247,45128
34,52000;2,89046;9258,89909
34,56000;2,89381;9269,63016
34,60000;2,89716;9279,97828
34,64000;2,90045;9290,42101
34,68000;2,90380;9300,52698
34,72000;2,90714;9311,33255
34,76000;2,91043;9322,01743
34,80000;2,91378;9332,82375
34,84000;2,91713;9344,37439
34,88000;2,92054;9355,22616
34,92000;2,92371;9365,37683
34,96000;2,92711;9376,03638
35,00000;2,93052;9386,93136
35,04000;2,93375;9398,04986
35,08000;2,93710;9408,50452
35,12000;2,94051;9419,50083
35,16000;2,94380;9430,87265
35,20000;2,94708;9440,47943
35,24000;2,95049;9452,27146
35,28000;2,95384;9463,48086
35,32000;2,95713;9473,72466
35,36000;2,96048;9483,61531
35,40000;2,96382;9494,59895
35,44000;2,96717;9504,38827
35,48000;2,97052;9515,29965
35,52000;2,97387;9527,34277
35,56000;2,97716;9537,68045
35,60000;2,98051;9548,10455
35,64000;2,98385;9557,30900
35,68000;2,98714;9567,62359
35,72000;2,99055;9578,51559
35,76000;2,99384;9588,39357
35,80000;2,99713;9598,87803
35,84000;3,00048;9610,10903
35,88000;3,00382;9620,74995
35,92000;3,00705;9631,26346
35,96000;3,01046;9640,75103
36,00000;3,01375;9651,52681
36,04000;3,01698;9661,67450
36,08000;3,02045;9672,90178
36,12000;3,02379;9684,34066
36,16000;3,02714;9694,16201
36,20000;3,03043;9703,62425
36,24000;3,03384;9713,94107
36,28000;3,03713;9724,78092
36,32000;3,04042;9733,75887
36,36000;3,04382;9744,08463
36,40000;3,04711;9757,03523
36,44000;3,05046;9765,95655
36,48000;3,05375;9776,01558
36,52000;3,05716;9786,51047
36,56000;3,06050;9798,02907
36,60000;3,06379;9808,38835
36,64000;3,06702;9817,92435
36,68000;3,07049;9830,44654
36,72000;3,07384;9841,10758
36,76000;3,07725;9851,91241
36,80000;3,08053;9862,20613
36,84000;3,08388;9872,78149
36,88000;3,08729;9883,51181
36,92000;3,09046;9892,91891
36,96000;3,09381;9902,47950
37,00000;3,09716;9913,76117
37,04000;3,10038;9924,16814
37,08000;3,10385;9935,31197
37,12000;3,10720;9946,97809
37,16000;3,11055;9958,10628
37,20000;3,11378;9966,19314
37,24000;3,11718;9977,50685
37,28000;3,12053;9990,28683
37,32000;3,12388;9998,90193
37,36000;3,12723;10008,70839
37,40000;3,13058;10020,41325
37,44000;3,13393;10031,13016
37,48000;3,13715;10040,83008
37,52000;3,14056;10052,84712
37,56000;3,14385;10064,03491
37,60000;3,14726;10073,73482
37,64000;3,15055;10083,32297
37,68000;3,15384;10093,19499
37,72000;3,15724;10105,32379
37,76000;3,16053;10115,27628
37,80000;3,16376;10124,86443
37,84000;3,16717;10134,87205
37,88000;3,17052;10146,85184
37,92000;3,17381;10157,11054
37,96000;3,17715;10166,56160
38,00000;3,18062;10178,44751
38,04000;3,18385;10189,35740
38,08000;3,18714;10198,25861
38,12000;3,19049;10208,70283
38,16000;3,19378;10218,36326
38,20000;3,19712;10227,50214
38,24000;3,20047;10237,95605
38,28000;3,20382;10249,14086
38,32000;3,20711;10258,85046
38,36000;3,21040;10268,18976
38,40000;3,21380;10277,81069
38,44000;3,21715;10288,12230
38,48000;3,22044;10297,51375
38,52000;3,22379;10306,65413
38,56000;3,22714;10316,24153
38,60000;3,23043;10325,81627
38,64000;3,23377;10333,83086
38,68000;3,23700;10343,93013
38,72000;3,24047;10353,47655
38,76000;3,24382;10364,42891
38,80000;3,24705;10373,42772
38,84000;3,25052;10383,34072
38,88000;3,25386;10393,06000
38,92000;3,25709;10401,49927
38,96000;3,26038;10410,76481
39,00000;3,26385;10421,01383
39,04000;3,26714;10429,78168
39,08000;3,27049;10438,21052
39,12000;3,27389;10449,20608
39,16000;3,27718;10458,83521
39,20000;3,28053;10466,74401
39,24000;3,28382;10475,81360
39,28000;3,28723;10485,95384
39,32000;3,29051;10496,19690
39,36000;3,29386;10505,35366
39,40000;3,29721;10514,08872
39,44000;3,30056;10521,99528
39,48000;3,30385;10530,66850
39,52000;3,30726;10539,67178
39,56000;3,31054;10548,57224
39,60000;3,31389;10559,56930
39,64000;3,31724;10568,74841
39,68000;3,32041;10577,11169
39,72000;3,32388;10585,79981
39,76000;3,32723;10595,18605
39,80000;3,33057;10604,64457
39,84000;3,33386;10614,55533
39,88000;3,33721;10622,38961
39,92000;3,34044;10630,65156
39,96000;3,34379;10639,21228
40,00000;3,34720;10649,94559
40,04000;3,35048;10659,18580
40,08000;3,35383;10667,45818
40,12000;3,35706;10675,73950
40,16000;3,36059;10687,83402
40,20000;3,36388;10696,56163
40,24000;3,36722;10704,67457
40,28000;3,37057;10713,00954
40,32000;3,37380;10720,61211
40,36000;3,37715;10729,00668
40,40000;3,38050;10737,98463
40,44000;3,38379;10746,71894
40,48000;3,38713;10756,33690
40,52000;3,39054;10766,33632
40,56000;3,39365;10775,54449
40,60000;3,39718;10785,20343
40,64000;3,40053;10794,10985
40,68000;3,40382;10802,28016
40,72000;3,40716;10811,11208
40,76000;3,41057;10820,11834
40,80000;3,41374;10829,04637
40,84000;3,41715;10837,74865
40,88000;3,42050;10847,30402
40,92000;3,42373;10856,59117
40,96000;3,42707;10865,38807
41,00000;3,43048;10874,95238
41,04000;3,43377;10884,01452
41,08000;3,43706;10892,40909
41,12000;3,44047;10902,07025
41,16000;3,44375;10911,01095
41,20000;3,44710;10918,98829
41,24000;3,45039;10928,09439
41,28000;3,45380;10937,38154
41,32000;3,45709;10946,41313
41,36000;3,46044;10954,70488
41,40000;3,46384;10964,46440
41,44000;3,46713;10972,60863
41,48000;3,47048;10980,93539
41,52000;3,47383;10989,67567
41,56000;3,47712;10998,32654
41,60000;3,48047;11006,27854
41,64000;3,48381;11014,46748
41,68000;3,48704;11023,40221
41,72000;3,49045;11031,91823
41,76000;3,49380;11041,45050
41,80000;3,49703;11049,88232
41,84000;3,50050;11057,32322
41,88000;3,50384;11066,97917
41,92000;3,50707;11075,41472
41,96000;3,51042;11082,48830
42,00000;3,51383;11092,36330
42,04000;3,51718;11100,94562
42,08000;3,52047;11109,13381
42,12000;3,52387;11117,61481
42,16000;3,52722;11126,93325
42,20000;3,53051;11134,42108
42,24000;3,53380;11141,87688
42,28000;3,53715;11149,93393
42,32000;3,54043;11158,95584
42,36000;3,54378;11166,69104
42,40000;3,54719;11175,85450
42,44000;3,55048;11185,27725
42,48000;3,55383;11192,87014
42,52000;3,55718;11200,55094
42,56000;3,56046;11208,31147
42,60000;3,56387;11217,00108
42,64000;3,56716;11224,96277
42,68000;3,57051;11234,24992
42,72000;3,57386;11242,95145
42,76000;3,57721;11251,26034
42,80000;3,58049;11259,21980
42,84000;3,58384;11266,51838
42,88000;3,58719;11275,75561
42,92000;3,59048;11284,90269
42,96000;3,59377;11293,33898
43,00000;3,59717;11302,22455
43,04000;3,60052;11311,09819
43,08000;3,60381;11318,48022
43,12000;3,60716;11326,27428
43,16000;3,61051;11334,82084
43,20000;3,61380;11342,50015
43,24000;3,61714;11350,04088
43,28000;3,62049;11357,85431
43,32000;3,62378;11365,30116
43,36000;3,62713;11374,00195
43,40000;3,63048;11383,38894
43,44000;3,63377;11390,74117
43,48000;3,63711;11397,36548
43,52000;3,64046;11406,29351
43,56000;3,64375;11414,03541
43,60000;3,64716;11422,14537
43,64000;3,65045;11429,70696
43,68000;3,65374;11437,98158
43,72000;3,65708;11444,92254
43,76000;3,66043;11452,49680
43,80000;3,66372;11461,20951
43,84000;3,66707;11468,45520
43,88000;3,67042;11476,88031
43,92000;3,67377;11485,89179
43,96000;3,67711;11494,33926
44,00000;3,68052;11503,07581
44,04000;3,68387;11511,69240
44,08000;3,68710;11518,45306
44,12000;3,69051;11526,42816
44,16000;3,69391;11535,44188
44,20000;3,69714;11542,92598
44,24000;3,70049;11551,29969
44,28000;3,70390;11558,87619
44,32000;3,70719;11566,39457
44,36000;3,71048;11572,77077
44,40000;3,71382;11580,91053
44,44000;3,71711;11589,68881
44,48000;3,72052;11598,19886
44,52000;3,72381;11606,02197
44,56000;3,72716;11614,01197
44,60000;3,73057;11621,72854
44,64000;3,73391;11628,96752
44,68000;3,73720;11637,13709
44,72000;3,74055;11644,55861
44,76000;3,74396;11653,55816
44,80000;3,74719;11661,43194
44,84000;3,75053;11667,09960
44,88000;3,75394;11675,36080
44,92000;3,75717;11682,52453
44,96000;3,76046;11689,00654
45,00000;3,76381;11698,24377
45,04000;3,76722;11706,22408
45,08000;3,77044;11712,58688
45,12000;3,77379;11720,30568
45,16000;3,77720;11729,47437
45,20000;3,78049;11736,18138
45,24000;3,78378;11742,83847
45,28000;3,78719;11751,26731
45,32000;3,79053;11759,57844
45,36000;3,79388;11766,81146
45,40000;3,79723;11774,09887
45,44000;3,80052;11781,17096
45,48000;3,80387;11787,93088
45,52000;3,80716;11795,65191
45,56000;3,81044;11802,81267
45,60000;3,81379;11811,62819
45,64000;3,81714;11820,51152
45,68000;3,82043;11827,06952
45,72000;3,82372;11833,58729
45,76000;3,82713;11842,18824
45,80000;3,83047;11849,80497
45,84000;3,83370;11855,13735
45,88000;3,83711;11863,36055
45,92000;3,84052;11872,81609
45,96000;3,84381;11878,83094
46,00000;3,84721;11886,45512
46,04000;3,85056;11896,58269
46,08000;3,85379;11903,01776
46,12000;3,85708;11910,43183
46,16000;3,86055;11918,51720
46,20000;3,86384;11926,04676
46,24000;3,86712;11932,75675
46,28000;3,87047;11939,68058
46,32000;3,87376;11948,39850
46,36000;3,87711;11955,44973
46,40000;3,88046;11962,58441
46,44000;3,88381;11970,86349
46,48000;3,88715;11979,28712
46,52000;3,89050;11986,25118
46,56000;3,89379;11993,25398
46,60000;3,89720;12000,58833
46,64000;3,90055;12008,63197
46,68000;3,90378;12015,86351
46,72000;3,90724;12023,92355
46,76000;3,91053;12033,73447
46,80000;3,91388;12039,56455
46,84000;3,91717;12046,42579
46,88000;3,92052;12052,92717
46,92000;3,92386;12060,21905
46,96000;3,92715;12068,31411
47,00000;3,93056;12076,39277
47,04000;3,93391;12086,71033
47,08000;3,93720;12092,46814
47,12000;3,94061;12099,49404
47,16000;3,94389;12106,37540
47,20000;3,94718;12113,25079
47,24000;3,95053;12121,32275
47,28000;3,95388;12129,33362
47,32000;3,95717;12137,96213
47,36000;3,96052;12146,64131
47,40000;3,96380;12154,17385
47,44000;3,96715;12161,58047
47,48000;3,97050;12170,09500
47,52000;3,97385;12177,42562
47,56000;3,97714;12184,27643
47,60000;3,98049;12191,11979
47,64000;3,98383;12199,35939
47,68000;3,98712;12206,33537
47,72000;3,99041;12212,83451
47,76000;3,99388;12221,03164
47,80000;3,99717;12230,40521
47,84000;4,00046;12236,10193
47,88000;4,00380;12243,21276
47,92000;4,00721;12252,13185
47,96000;4,01050;12259,04599
48,00000;4,01379;12266,28423
48,04000;4,01726;12275,54828
48,08000;4,02048;12284,40404
48,12000;4,02377;12292,24801
48,16000;4,02718;12301,45097
48,20000;4,03047;12310,50268
48,24000;4,03388;12319,05147
48,28000;4,03717;12327,58164
48,32000;4,04045;12335,95982
48,36000;4,04380;12343,68905
48,40000;4,04709;12352,41890
48,44000;4,05038;12360,71587
48,48000;4,05379;12371,51027
48,52000;4,05720;12379,98828
48,56000;4,06042;12389,10779
48,60000;4,06383;12397,93971
48,64000;4,06718;12407,01675
48,68000;4,07047;12416,31806
48,72000;4,07382;12424,33637
48,76000;4,07722;12435,06446
48,80000;4,08051;12443,61550
48,84000;4,08380;12451,64275
48,88000;4,08715;12460,70415
48,92000;4,09050;12470,29081
48,96000;4,09373;12477,12895
49,00000;4,09707;12486,28870
49,04000;4,10048;12496,29930
49,08000;4,10377;12505,36591
49,12000;4,10706;12514,38409
49,16000;4,11047;12524,20098
49,20000;4,11376;12533,31602
49,24000;4,11710;12541,75007
49,28000;4,12051;12551,12141
49,32000;4,12380;12560,82505
49,36000;4,12721;12569,75532
49,40000;4,13050;12577,80194
49,44000;4,13379;12587,42809
49,48000;4,13713;12596,39561
49,52000;4,14042;12604,88778
49,56000;4,14371;12614,19952
49,60000;4,14712;12622,44731
49,64000;4,15035;12632,24036
49,68000;4,15376;12641,89482
49,72000;4,15710;12650,38252
49,76000;4,16045;12659,33216
49,80000;4,16356;12669,07752
49,84000;4,16715;12678,97487
49,88000;4,17050;12689,89742
49,92000;4,17390;12700,24776
49,96000;4,17719;12708,65649
50,00000;4,18048;12717,25148
50,04000;4,18389;12726,09532
50,08000;4,18718;12736,55146
50,12000;4,19047;12745,39679
50,16000;4,19387;12755,37163
50,20000;4,19716;12765,48654
50,24000;4,20045;12773,42141
50,28000;4,20380;12782,67503
50,32000;4,20715;12792,46509
50,36000;4,21044;12800,67414
50,40000;4,21378;12809,54778
50,44000;4,21713;12820,96952
50,48000;4,22048;12830,36321
50,52000;4,22383;12839,70028
50,56000;4,22718;12848,80936
50,60000;4,23052;12858,55770
50,64000;4,23387;12867,74874
50,68000;4,23716;12876,74308
50,72000;4,24045;12886,01309
50,76000;4,24386;12896,63911
50,80000;4,24721;12906,54093
50,84000;4,25049;12915,60829
50,88000;4,25378;12924,75015
50,92000;4,25719;12935,19139
50,96000;4,26042;12943,90708
51,00000;4,26371;12952,34710
51,04000;4,26724;12963,67049
51,08000;4,27052;12972,46516
51,12000;4,27387;12982,09578
51,16000;4,27728;12991,09757
51,20000;4,28051;13000,16344
51,24000;4,28392;13009,46921
51,28000;4,28721;13017,74234
51,32000;4,29037;13026,51167
51,36000;4,29390;13037,47147
51,40000;4,29719;13046,94414
51,44000;4,30048;13056,47790
51,48000;4,30383;13065,76878
51,52000;4,30712;13074,20284
51,56000;4,31022;13081,70259
51,60000;4,31381;13092,27645
51,64000;4,31716;13102,24384
51,68000;4,32045;13110,95655
51,72000;4,32380;13119,73333
51,76000;4,32714;13129,71711
51,80000;4,33049;13138,63695
51,84000;4,33360;13147,05312
51,88000;4,33713;13157,84156
51,92000;4,34060;13169,01445
51,96000;4,34383;13177,56623
52,00000;4,34717;13184,86631
52,04000;4,35046;13194,07970
52,08000;4,35387;13204,55521
52,12000;4,35710;13211,58111
52,16000;4,36051;13218,85139
52,20000;4,36380;13228,69360
52,24000;4,36714;13237,40929
52,28000;4,37055;13245,87911
52,32000;4,37384;13255,97316
52,36000;4,37719;13264,01830
52,40000;4,38048;13272,85618
52,44000;4,38383;13281,79538
52,48000;4,38723;13291,72701
52,52000;4,39058;13301,11325
52,56000;4,39387;13309,99434
52,60000;4,39722;13318,26746
52,64000;4,40057;13328,51201
52,68000;4,40391;13338,42427
52,72000;4,40708;13346,56328
52,76000;4,41055;13355,80647
52,80000;4,41390;13365,82154
52,84000;4,41719;13373,54332
52,88000;4,42048;13381,39176
52,92000;4,42388;13391,73019
52,96000;4,42711;13401,39508
53,00000;4,43040;13408,55509
53,04000;4,43381;13419,53874
53,08000;4,43716;13431,32406
53,12000;4,44051;13439,82965
53,16000;4,44385;13448,42464
53,20000;4,44714;13459,88959
53,24000;4,45049;13469,56193
53,28000;4,45384;13478,14649
53,32000;4,45713;13487,09017
53,36000;4,46054;13497,28554
53,40000;4,46388;13507,86239
53,44000;4,46717;13516,10273
53,48000;4,47052;13525,20734
53,52000;4,47387;13535,49063
53,56000;4,47716;13544,20185
53,60000;4,48044;13552,68359
53,64000;4,48391;13562,71952
53,68000;4,48726;13573,55118
53,72000;4,49049;13581,34598
53,76000;4,49384;13590,33138
53,80000;4,49725;13599,62523
53,84000;4,50041;13608,13826
53,88000;4,50382;13615,88091
53,92000;4,50723;13625,24480
53,96000;4,51052;13636,63971
54,00000;4,51393;13644,97542
54,04000;4,51728;13652,96245
54,08000;4,52050;13660,30723
54,12000;4,52379;13668,62357
54,16000;4,52714;13677,06507
54,20000;4,53043;13685,56470
54,24000;4,53378;13694,37128
54,28000;4,53713;13707,02386
54,32000;4,54047;13715,90346
54,36000;4,54376;13724,33156
54,40000;4,54711;13733,36613
54,44000;4,55046;13741,90152
54,48000;4,55357;13750,78708
54,52000;4,55716;13762,43979
54,56000;4,56050;13772,30287
54,60000;4,56379;13779,89352
54,64000;4,56714;13788,29032
54,68000;4,57049;13796,39208
54,72000;4,57372;13803,70259
54,76000;4,57706;13812,62839
54,80000;4,58041;13821,18613
54,84000;4,58370;13830,62750
54,88000;4,58705;13838,49382
54,92000;4,59052;13849,92152
54,96000;4,59375;13858,42860
55,00000;4,59709;13865,18180
55,04000;4,60050;13873,55477
55,08000;4,60379;13883,09151
55,12000;4,60714;13890,71494
55,16000;4,61049;13898,28026
55,20000;4,61378;13906,30007
55,24000;4,61712;13914,74456
55,28000;4,62047;13923,63757
55,32000;4,62382;13932,15507
55,36000;4,62717;13941,18518
55,40000;4,63052;13949,43893
55,44000;4,63375;13957,30823
55,48000;4,63715;13965,17754
55,52000;4,64050;13974,84243
55,56000;4,64379;13982,31238
55,60000;4,64708;13989,82704
55,64000;4,65049;13998,80797
55,68000;4,65389;14008,24487
55,72000;4,65712;14014,78350
55,76000;4,66053;14022,33392
55,80000;4,66388;14030,54893
55,84000;4,66717;14037,99653
55,88000;4,67046;14045,00008
55,92000;4,67386;14053,17634
55,96000;4,67721;14061,87117
56,00000;4,68050;14068,55136
56,04000;4,68385;14075,84995
56,08000;4,68714;14083,69988
56,12000;4,69049;14090,47395
56,16000;4,69383;14096,79353
56,20000;4,69712;14104,70158
56,24000;4,70053;14110,97646
56,28000;4,70382;14117,24091
56,32000;4,70717;14123,17157
56,36000;4,71052;14130,43588
56,40000;4,71380;14136,34270
56,44000;4,71709;14143,50718
56,48000;4,72044;14150,11883
56,52000;4,72385;14156,90929
56,56000;4,72714;14162,72968
56,60000;4,73042;14167,56362
56,64000;4,73383;14173,28119
56,68000;4,73718;14179,80045
56,72000;4,74035;14184,08453
56,76000;4,74376;14190,44584
56,80000;4,74717;14196,54936
56,84000;4,75045;14201,84672
56,88000;4,75374;14206,54505
56,92000;4,75715;14211,70235
56,96000;4,76038;14217,23813
57,00000;4,76373;14222,70089
57,04000;4,76708;14228,09809
57,08000;4,77042;14233,38503
57,12000;4,77371;14237,87773
57,16000;4,77706;14242,18118
57,20000;4,78047;14247,75869
57,24000;4,78376;14252,16198
57,28000;4,78711;14256,97207
57,32000;4,79051;14261,83879
57,36000;4,79386;14266,44176
57,40000;4,79721;14270,85102
57,44000;4,80056;14274,29467
57,48000;4,80385;14277,99761
57,52000;4,80719;14280,76327
57,56000;4,81048;14283,16981
57,60000;4,81377;14285,29173
57,64000;4,81718;14287,80854
57,68000;4,82053;14290,83198
57,72000;4,82376;14291,14342
57,76000;4,82716;14290,62635
57,80000;4,83057;14290,90798
57,84000;4,83380;14288,48207
57,88000;4,83715;14282,72873
57,92000;4,84056;14276,92920
57,96000;4,84391;14267,29411
58,00000;4,84719;14248,35771
58,04000;4,85060;14221,51029
58,08000;4,85395;14177,15997
58,12000;4,85718;14095,60740
58,16000;4,86047;13510,52374
58,19400;4,86531;2550,33337