File: SU - Suspension/05 - Essais/Excels essais Optimus/Test_Rotules_31_01_19/H7_1.is_tens_RawData/Specimen_RawData_1.csv
Temps;Déplacement;Charge
(sec);(mm);(N)
0,00000;-0,06619;70,55260
0,04000;-0,06595;70,61841
0,08000;-0,06487;75,52177
0,12000;-0,06302;91,84288
0,16000;-0,06081;110,40271
0,20000;-0,05847;129,28064
0,24000;-0,05614;147,81223
0,28000;-0,05381;166,06599
0,32000;-0,05160;183,63708
0,36000;-0,04933;199,17449
0,40000;-0,04729;209,13924
0,44000;-0,04514;215,96747
0,48000;-0,04311;221,04913
0,52000;-0,04108;225,68696
0,56000;-0,03898;230,96383
0,60000;-0,03707;236,42613
0,64000;-0,03504;240,80784
0,68000;-0,03300;246,72293
0,72000;-0,03097;251,19241
0,76000;-0,02894;255,95387
0,80000;-0,02697;262,16109
0,84000;-0,02493;266,49483
0,88000;-0,02296;272,60622
0,92000;-0,02093;278,50373
0,96000;-0,01889;284,26775
1,00000;-0,01692;290,38680
1,04000;-0,01495;296,07227
1,08000;-0,01297;303,20487
1,12000;-0,01094;308,64358
1,16000;-0,00891;315,64999
1,20000;-0,00694;322,03228
1,24000;-0,00496;328,63072
1,28000;-0,00287;336,06254
1,32000;-0,00090;344,13724
1,36000;0,00108;350,76179
1,40000;0,00311;360,70675
1,44000;0,00496;371,36909
1,48000;0,00700;383,46893
1,52000;0,00903;395,67677
1,56000;0,01100;407,36077
1,60000;0,01303;419,80203
1,64000;0,01495;430,93851
1,68000;0,01698;442,58442
1,72000;0,01907;454,98116
1,76000;0,02111;467,14875
1,80000;0,02308;478,36942
1,84000;0,02505;491,04923
1,88000;0,02702;501,71814
1,92000;0,02906;513,36996
1,96000;0,03103;525,96508
2,00000;0,03306;537,77643
2,04000;0,03510;548,86118
2,08000;0,03695;559,71663
2,12000;0,03904;571,19611
2,16000;0,04108;582,59177
2,20000;0,04317;594,39894
2,24000;0,04520;607,25356
2,28000;0,04705;617,04111
2,32000;0,04909;627,31742
2,36000;0,05112;639,66503
2,40000;0,05309;651,16822
2,44000;0,05513;662,57073
2,48000;0,05704;673,63922
2,52000;0,05901;682,57456
2,56000;0,06105;694,62429
2,60000;0,06302;705,30861
2,64000;0,06505;717,14423
2,68000;0,06708;728,35903
2,72000;0,06900;738,82961
2,76000;0,07109;750,36543
2,80000;0,07312;761,53977
2,84000;0,07510;771,83153
2,88000;0,07713;782,81034
2,92000;0,07898;792,98709
2,96000;0,08101;804,30992
3,00000;0,08305;815,39350
3,04000;0,08508;827,01333
3,08000;0,08711;836,44697
3,12000;0,08903;847,66801
3,16000;0,09106;857,98027
3,20000;0,09309;870,94875
3,24000;0,09518;882,17519
3,28000;0,09722;894,19223
3,32000;0,09913;905,41700
3,36000;0,10110;914,39616
3,40000;0,10308;925,81771
3,44000;0,10511;937,09202
3,48000;0,10714;948,14925
3,52000;0,10912;959,82822
3,56000;0,11103;969,49469
3,60000;0,11306;980,43084
3,64000;0,11503;991,56629
3,68000;0,11707;1002,52572
3,72000;0,11910;1014,02476
3,76000;0,12101;1025,33819
3,80000;0,12311;1037,04715
3,84000;0,12508;1048,90689
3,88000;0,12705;1058,85565
3,92000;0,12909;1070,18594
3,96000;0,13094;1081,35138
4,00000;0,13303;1090,66488
4,04000;0,13506;1103,06144
4,08000;0,13710;1113,74957
4,12000;0,13913;1125,05034
4,16000;0,14104;1135,88050
4,20000;0,14308;1146,27602
4,24000;0,14517;1157,38101
4,28000;0,14714;1167,78268
4,32000;0,14917;1178,06681
4,36000;0,15109;1189,24780
4,40000;0,15306;1198,91865
4,44000;0,15509;1210,52507
4,48000;0,15713;1221,73438
4,52000;0,15910;1231,24560
4,56000;0,16113;1242,21453
4,60000;0,16305;1252,35822
4,64000;0,16508;1263,77298
4,68000;0,16711;1274,71471
4,72000;0,16914;1285,28085
4,76000;0,17112;1295,87594
4,80000;0,17297;1304,52989
4,84000;0,17500;1314,10938
4,88000;0,17704;1325,31393
4,92000;0,17907;1335,57906
4,96000;0,18110;1346,61691
5,00000;0,18302;1356,02802
5,04000;0,18499;1364,98772
5,08000;0,18702;1376,06906
5,12000;0,18905;1386,53610
5,16000;0,19115;1396,03568
5,20000;0,19312;1406,09043
5,24000;0,19503;1413,79908
5,28000;0,19707;1423,54388
5,32000;0,19904;1432,09305
5,36000;0,20107;1439,38707
5,40000;0,20310;1446,46252
5,44000;0,20502;1452,04198
5,48000;0,20705;1455,37164
5,52000;0,20908;1459,67649
5,56000;0,21106;1463,71061
5,60000;0,21315;1468,42590
5,64000;0,21506;1472,96935
5,68000;0,21710;1478,01880
5,72000;0,21907;1483,78881
5,76000;0,22104;1489,43784
5,80000;0,22313;1495,21492
5,84000;0,22499;1501,40729
5,88000;0,22702;1505,75479
5,92000;0,22905;1512,49478
5,96000;0,23103;1517,94357
6,00000;0,23306;1523,03344
6,04000;0,23503;1528,93784
6,08000;0,23701;1533,03677
6,12000;0,23910;1537,69106
6,16000;0,24113;1541,70739
6,20000;0,24310;1544,75980
6,24000;0,24508;1548,90912
6,28000;0,24705;1551,53954
6,32000;0,24908;1555,76095
6,36000;0,25112;1559,93449
6,40000;0,25309;1561,98302
6,44000;0,25512;1564,40996
6,48000;0,25698;1566,63787
6,52000;0,25907;1568,26265
6,56000;0,26110;1571,95739
6,60000;0,26313;1574,94005
6,64000;0,26517;1575,84585
6,68000;0,26702;1577,55241
6,72000;0,26905;1576,83864
6,76000;0,27109;1579,93175
6,80000;0,27312;1581,73349
6,84000;0,27515;1582,74192
6,88000;0,27706;1583,68032
6,92000;0,27904;1583,72913
6,96000;0,28107;1584,52298
7,00000;0,28304;1585,92574
7,04000;0,28508;1588,66923
7,08000;0,28711;1590,95693
7,12000;0,28908;1589,11869
7,16000;0,29106;1589,86878
7,20000;0,29303;1591,14115
7,24000;0,29506;1591,95606
7,28000;0,29715;1593,75630
7,32000;0,29901;1593,77791
7,36000;0,30110;1593,99174
7,40000;0,30307;1594,51291
7,44000;0,30505;1594,85694
7,48000;0,30708;1596,47670
7,52000;0,30899;1598,08788
7,56000;0,31102;1597,57305
7,60000;0,31306;1599,10321
7,64000;0,31509;1599,27271
7,68000;0,31712;1600,02969
7,72000;0,31910;1599,85945
7,76000;0,32113;1600,15970
7,80000;0,32310;1600,96120
7,84000;0,32514;1600,89359
7,88000;0,32723;1600,86807
7,92000;0,32908;1600,84050
7,96000;0,33105;1599,94941
8,00000;0,33309;1602,07469
8,04000;0,33512;1603,13249
8,08000;0,33715;1603,31726
8,12000;0,33913;1604,40877
8,16000;0,34110;1602,99074
8,20000;0,34313;1602,41779
8,24000;0,34516;1602,34105
8,28000;0,34714;1602,99018
8,32000;0,34917;1603,02036
8,36000;0,35102;1601,72787
8,40000;0,35306;1601,50547
8,44000;0,35503;1603,12150
8,48000;0,35706;1603,51712
8,52000;0,35910;1604,91168
8,56000;0,36101;1603,91312
8,60000;0,36310;1603,57468
8,64000;0,36507;1603,58641
8,68000;0,36711;1603,88593
8,72000;0,36914;1604,24523
8,76000;0,37111;1605,28943
8,80000;0,37315;1604,77329
8,84000;0,37512;1603,92411
8,88000;0,37709;1603,59479
8,92000;0,37913;1603,66483
8,96000;0,38110;1605,14973
9,00000;0,38307;1604,15098
9,04000;0,38510;1603,57691
9,08000;0,38714;1602,98143
9,12000;0,38911;1602,46417
9,16000;0,39114;1602,06053
9,20000;0,39312;1602,04172
9,24000;0,39515;1601,90873
9,28000;0,39712;1601,42779
9,32000;0,39909;1601,18807
9,36000;0,40113;1600,81778
9,40000;0,40298;1600,11258
9,44000;0,40507;1600,04590
9,48000;0,40705;1601,19683
9,52000;0,40908;1600,86676
9,56000;0,41117;1600,04329
9,60000;0,41303;1599,81940
9,64000;0,41506;1598,94340
9,68000;0,41709;1599,41576
9,72000;0,41912;1599,05218
9,76000;0,42116;1598,02996
9,80000;0,42307;1596,93845
9,84000;0,42504;1594,65894
9,88000;0,42708;1595,11920
9,92000;0,42911;1595,93970
9,96000;0,43114;1595,81639
10,00000;0,43312;1593,97796
10,04000;0,43509;1591,94488
10,08000;0,43712;1592,00598
10,12000;0,43909;1591,12401
10,16000;0,44113;1590,91726
10,20000;0,44316;1590,93626
10,24000;0,44501;1588,92106
10,28000;0,44711;1588,30788
10,32000;0,44902;1588,48967
10,36000;0,45105;1588,94137
10,40000;0,45314;1589,50165
10,44000;0,45500;1589,09019
10,48000;0,45703;1587,37544
10,52000;0,45906;1587,05357
10,56000;0,46104;1586,14386
10,60000;0,46307;1586,99118
10,64000;0,46504;1590,92285
10,68000;0,46708;1593,48231
10,72000;0,46905;1600,07346
10,76000;0,47108;1607,97630
10,80000;0,47305;1616,21813
10,84000;0,47503;1624,77754
10,88000;0,47700;1633,06743
10,92000;0,47909;1642,72562
10,96000;0,48113;1650,48651
11,00000;0,48310;1657,90673
11,04000;0,48513;1665,69985
11,08000;0,48705;1672,75742
11,12000;0,48908;1680,38160
11,16000;0,49111;1688,86986
11,20000;0,49308;1694,45537
11,24000;0,49512;1700,48159
11,28000;0,49697;1705,92610
11,32000;0,49900;1712,33509
11,36000;0,50110;1719,14697
11,40000;0,50307;1724,37169
11,44000;0,50516;1729,50532
11,48000;0,50701;1733,77041
11,52000;0,50905;1736,73555
11,56000;0,51102;1743,11846
11,60000;0,51305;1748,06807
11,64000;0,51509;1754,27422
11,68000;0,51706;1758,90569
11,72000;0,51903;1761,59516
11,76000;0,52107;1766,73103
11,80000;0,52310;1771,52343
11,84000;0,52513;1778,29079
11,88000;0,52716;1781,84994
11,92000;0,52908;1784,32092
11,96000;0,53117;1788,45134
12,00000;0,53308;1792,14645
12,04000;0,53512;1796,05801
12,08000;0,53715;1801,79682
12,12000;0,53906;1805,71377
12,16000;0,54109;1810,06230
12,20000;0,54313;1814,18359
12,24000;0,54510;1817,20518
12,28000;0,54719;1822,13057
12,32000;0,54911;1829,15144
12,36000;0,55114;1832,35183
12,40000;0,55311;1836,60425
12,44000;0,55509;1841,44806
12,48000;0,55712;1845,08115
12,52000;0,55903;1848,63117
12,56000;0,56100;1851,63636
12,60000;0,56298;1857,59999
12,64000;0,56513;1863,95608
12,68000;0,56716;1867,57632
12,72000;0,56908;1870,99036
12,76000;0,57111;1874,15462
12,80000;0,57314;1880,34959
12,84000;0,57517;1884,20899
12,88000;0,57721;1889,02598
12,92000;0,57912;1893,08636
12,96000;0,58103;1894,77224
13,00000;0,58307;1899,28189
13,04000;0,58504;1904,32277
13,08000;0,58713;1911,92050
13,12000;0,58911;1914,70571
13,16000;0,59102;1916,69445
13,20000;0,59311;1920,72708
13,24000;0,59508;1926,19506
13,28000;0,59712;1930,80846
13,32000;0,59915;1935,72212
13,36000;0,60106;1939,36639
13,40000;0,60310;1942,09646
13,44000;0,60507;1947,19378
13,48000;0,60704;1951,25900
13,52000;0,60908;1956,99278
13,56000;0,61105;1960,53367
13,60000;0,61302;1963,61747
13,64000;0,61505;1968,09452
13,68000;0,61709;1971,64062
13,72000;0,61912;1976,25365
13,76000;0,62121;1982,16550
13,80000;0,62313;1987,14826
13,84000;0,62510;1990,24733
13,88000;0,62713;1995,05296
13,92000;0,62910;1998,31631
13,96000;0,63114;2002,78703
14,00000;0,63305;2006,66934
14,04000;0,63508;2010,32180
14,08000;0,63706;2015,53889
14,12000;0,63909;2019,58790
14,16000;0,64112;2023,72316
14,20000;0,64310;2030,17741
14,24000;0,64513;2037,48494
14,28000;0,64716;2041,37359
14,32000;0,64913;2044,00942
14,36000;0,65117;2047,43147
14,40000;0,65302;2050,91964
14,44000;0,65505;2054,85001
14,48000;0,65709;2060,18109
14,52000;0,65906;2063,93506
14,56000;0,66109;2068,26944
14,60000;0,66307;2072,82193
14,64000;0,66498;2076,25087
14,68000;0,66713;2081,57320
14,72000;0,66910;2088,98373
14,76000;0,67114;2092,40057
14,80000;0,67317;2095,59966
14,84000;0,67502;2098,85444
14,88000;0,67706;2102,67287
14,92000;0,67909;2106,52631
14,96000;0,68106;2110,72564
15,00000;0,68309;2114,17153
15,04000;0,68501;2117,70087
15,08000;0,68710;2121,95441
15,12000;0,68907;2125,94867
15,16000;0,69111;2130,99159
15,20000;0,69314;2137,04407
15,24000;0,69505;2140,29532
15,28000;0,69709;2143,05706
15,32000;0,69906;2147,50897
15,36000;0,70109;2151,12418
15,40000;0,70312;2154,80011
15,44000;0,70504;2160,71643
15,48000;0,70707;2163,07640
15,52000;0,70910;2168,19663
15,56000;0,71108;2171,51009
15,60000;0,71311;2174,77940
15,64000;0,71508;2179,89478
15,68000;0,71706;2183,53383
15,72000;0,71909;2189,20615
15,76000;0,72112;2194,60186
15,80000;0,72309;2198,00137
15,84000;0,72513;2202,18040
15,88000;0,72698;2205,30219
15,92000;0,72907;2209,39033
15,96000;0,73111;2214,59679
16,00000;0,73308;2218,35803
16,04000;0,73511;2221,72774
16,08000;0,73697;2225,92186
16,12000;0,73906;2228,88011
16,16000;0,74109;2235,49921
16,20000;0,74312;2240,62148
16,24000;0,74510;2243,42495
16,28000;0,74701;2247,99402
16,32000;0,74898;2251,08135
16,36000;0,75108;2257,75577
16,40000;0,75305;2262,95926
16,44000;0,75514;2267,09545
16,48000;0,75711;2271,90945
16,52000;0,75909;2274,06099
16,56000;0,76112;2279,18029
16,60000;0,76315;2284,64641
16,64000;0,76519;2290,39378
16,68000;0,76716;2295,17333
16,72000;0,76907;2297,94458
16,76000;0,77111;2301,92207
16,80000;0,77308;2305,63842
16,84000;0,77511;2310,54202
16,88000;0,77708;2315,77121
16,92000;0,77900;2319,26069
16,96000;0,78109;2323,16721
17,00000;0,78300;2326,98210
17,04000;0,78510;2332,43518
17,08000;0,78713;2338,30325
17,12000;0,78904;2342,28503
17,16000;0,79107;2345,26210
17,20000;0,79305;2349,91834
17,24000;0,79508;2353,86360
17,28000;0,79711;2358,89498
17,32000;0,79903;2363,94014
17,36000;0,80106;2367,66245
17,40000;0,80309;2373,02743
17,44000;0,80513;2377,47654
17,48000;0,80716;2382,37120
17,52000;0,80913;2390,02444
17,56000;0,81110;2392,78022
17,60000;0,81314;2397,79651
17,64000;0,81517;2402,62244
17,68000;0,81714;2405,91802
17,72000;0,81918;2410,45859
17,76000;0,82103;2413,83687
17,80000;0,82306;2418,06190
17,84000;0,82509;2422,30743
17,88000;0,82713;2428,39176
17,92000;0,82916;2432,67100
17,96000;0,83101;2435,83657
18,00000;0,83305;2440,66380
18,04000;0,83508;2446,34412
18,08000;0,83705;2451,67445
18,12000;0,83909;2456,76227
18,16000;0,84100;2461,22237
18,20000;0,84297;2464,56750
18,24000;0,84506;2471,11879
18,28000;0,84710;2477,82599
18,32000;0,84913;2482,74114
18,36000;0,85110;2487,90924
18,40000;0,85290;2491,17929
18,44000;0,85511;2497,84607
18,48000;0,85708;2504,07308
18,52000;0,85917;2509,28141
18,56000;0,86115;2514,58697
18,60000;0,86306;2517,69423
18,64000;0,86509;2522,47471
18,68000;0,86713;2526,82026
18,72000;0,86916;2531,80899
18,76000;0,87119;2537,46882
18,80000;0,87305;2541,94718
18,84000;0,87514;2546,06698
18,88000;0,87711;2550,79828
18,92000;0,87908;2554,99501
18,96000;0,88112;2560,20352
19,00000;0,88297;2565,59923
19,04000;0,88506;2569,87344
19,08000;0,88704;2574,94282
19,12000;0,88901;2578,99724
19,16000;0,89110;2585,57573
19,20000;0,89308;2589,75029
19,24000;0,89505;2593,72592
19,28000;0,89708;2598,84875
19,32000;0,89911;2604,58495
19,36000;0,90109;2609,81135
19,40000;0,90306;2614,57134
19,44000;0,90497;2621,77307
19,48000;0,90701;2631,10362
19,52000;0,90904;2640,27137
19,56000;0,91107;2648,78515
19,60000;0,91311;2656,47620
19,64000;0,91496;2664,04897
19,68000;0,91705;2673,45905
19,72000;0,91914;2682,29879
19,76000;0,92112;2690,85709
19,80000;0,92321;2699,19410
19,84000;0,92506;2706,33791
19,88000;0,92704;2712,01413
19,92000;0,92901;2720,74603
19,96000;0,93104;2729,11228
20,00000;0,93307;2738,74700
20,04000;0,93499;2746,20336
20,08000;0,93702;2753,00462
20,12000;0,93905;2763,86570
20,16000;0,94109;2771,69514
20,20000;0,94312;2780,20222
20,24000;0,94509;2787,24637
20,28000;0,94701;2793,43985
20,32000;0,94904;2801,34771
20,36000;0,95101;2808,03610
20,40000;0,95304;2816,39788
20,44000;0,95508;2825,44475
20,48000;0,95699;2832,28699
20,52000;0,95908;2838,87926
20,56000;0,96106;2846,95923
20,60000;0,96315;2855,22956
20,64000;0,96512;2865,29288
20,68000;0,96704;2871,10824
20,72000;0,96913;2879,26085
20,76000;0,97110;2888,20416
20,80000;0,97313;2895,37031
20,84000;0,97517;2903,53913
20,88000;0,97708;2911,87800
20,92000;0,97911;2918,71093
20,96000;0,98109;2927,40781
21,00000;0,98312;2936,04266
21,04000;0,98521;2944,54377
21,08000;0,98706;2951,77940
21,12000;0,98910;2957,61563
21,16000;0,99119;2967,01528
21,20000;0,99316;2976,48199
21,24000;0,99514;2982,84274
21,28000;0,99711;2990,75563
21,32000;0,99908;2996,72112
21,36000;1,00106;3004,00909
21,40000;1,00309;3011,70088
21,44000;1,00512;3019,19840
21,48000;1,00709;3027,56634
21,52000;1,00907;3033,37593
21,56000;1,01104;3040,50222
21,60000;1,01307;3048,07611
21,64000;1,01511;3056,20078
21,68000;1,01714;3064,81626
21,72000;1,01905;3071,53463
21,76000;1,02108;3078,49552
21,80000;1,02300;3085,40594
21,84000;1,02509;3094,39637
21,88000;1,02712;3102,11722
21,92000;1,02904;3108,69813
21,96000;1,03113;3114,52840
22,00000;1,03310;3122,03299
22,04000;1,03508;3128,94844
22,08000;1,03711;3136,67357
22,12000;1,03908;3143,95390
22,16000;1,04111;3150,14720
22,20000;1,04315;3157,34074
22,24000;1,04512;3164,38451
22,28000;1,04709;3170,17250
22,32000;1,04907;3176,53157
22,36000;1,05104;3183,50010
22,40000;1,05313;3190,98346
22,44000;1,05511;3198,52121
22,48000;1,05714;3205,31204
22,52000;1,05917;3210,87576
22,56000;1,06102;3216,90105
22,60000;1,06306;3224,21677
22,64000;1,06509;3231,70796
22,68000;1,06712;3238,32445
22,72000;1,06916;3243,82521
22,76000;1,07101;3250,53185
22,80000;1,07304;3255,51443
22,84000;1,07513;3264,09675
22,88000;1,07717;3272,14114
22,92000;1,07920;3277,84456
22,96000;1,08105;3283,61392
23,00000;1,08309;3289,20521
23,04000;1,08506;3295,17573
23,08000;1,08715;3303,40192
23,12000;1,08919;3309,54455
23,16000;1,09110;3314,88810
23,20000;1,09307;3319,59352
23,24000;1,09504;3326,81127
23,28000;1,09708;3332,49308
23,32000;1,09905;3339,35618
23,36000;1,10114;3346,96770
23,40000;1,10306;3351,58817
23,44000;1,10509;3357,76769
23,48000;1,10706;3363,17942
23,52000;1,10904;3370,05779
23,56000;1,11107;3377,46330
23,60000;1,11304;3383,78362
23,64000;1,11507;3389,70013
23,68000;1,11705;3394,81607
23,72000;1,11902;3401,16322
23,76000;1,12105;3407,14604
23,80000;1,12297;3413,86460
23,84000;1,12506;3420,10073
23,88000;1,12703;3429,20721
23,92000;1,12906;3434,11639
23,96000;1,13104;3439,24835
24,00000;1,13301;3445,27215
24,04000;1,13504;3450,97408
24,08000;1,13708;3457,47173
24,12000;1,13905;3463,66391
24,16000;1,14108;3469,06111
24,20000;1,14306;3474,78278
24,24000;1,14503;3479,40400
24,28000;1,14712;3486,11474
24,32000;1,14915;3492,99274
24,36000;1,15113;3499,66250
24,40000;1,15316;3505,28732
24,44000;1,15501;3510,37979
24,48000;1,15705;3515,53634
24,52000;1,15914;3526,60641
24,56000;1,16111;3531,68026
24,60000;1,16314;3537,49506
24,64000;1,16506;3541,49565
24,68000;1,16709;3546,77439
24,72000;1,16912;3551,15421
24,76000;1,17110;3557,09493
24,80000;1,17313;3562,52640
24,84000;1,17504;3569,01996
24,88000;1,17702;3573,50446
24,92000;1,17899;3580,76990
24,96000;1,18108;3588,51291
25,00000;1,18311;3596,73798
25,04000;1,18503;3600,24907
25,08000;1,18706;3604,23289
25,12000;1,18903;3610,57669
25,16000;1,19107;3616,02493
25,20000;1,19316;3621,60318
25,24000;1,19507;3627,95144
25,28000;1,19711;3632,20125
25,32000;1,19908;3639,83512
25,36000;1,20111;3644,76964
25,40000;1,20314;3650,31585
25,44000;1,20512;3656,72074
25,48000;1,20703;3662,23305
25,52000;1,20906;3666,75071
25,56000;1,21110;3674,75152
25,60000;1,21313;3679,80190
25,64000;1,21510;3686,21983
25,68000;1,21702;3690,91183
25,72000;1,21911;3697,82932
25,76000;1,22114;3705,35254
25,80000;1,22311;3712,36242
25,84000;1,22515;3720,81026
25,88000;1,22706;3726,44030
25,92000;1,22903;3731,94925
25,96000;1,23107;3740,31886
26,00000;1,23310;3747,43342
26,04000;1,23513;3754,48503
26,08000;1,23704;3759,98728
26,12000;1,23902;3765,01754
26,16000;1,24105;3771,51035
26,20000;1,24290;3778,55152
26,24000;1,24524;3786,63167
26,28000;1,24715;3794,67681
26,32000;1,24906;3797,95060
26,36000;1,25110;3804,30631
26,40000;1,25313;3810,27162
26,44000;1,25510;3815,77276
26,48000;1,25713;3820,74714
26,52000;1,25905;3826,47328
26,56000;1,26108;3831,42680
26,60000;1,26305;3837,38242
26,64000;1,26509;3843,52133
26,68000;1,26712;3849,76752
26,72000;1,26903;3854,53701
26,76000;1,27106;3860,31717
26,80000;1,27304;3864,79124
26,84000;1,27501;3869,41582
26,88000;1,27716;3876,85820
26,92000;1,27902;3883,12563
26,96000;1,28105;3885,48523
27,00000;1,28302;3891,55000
27,04000;1,28506;3896,81607
27,08000;1,28703;3904,69655
27,12000;1,28906;3913,31539
27,16000;1,29103;3921,55237
27,20000;1,29307;3929,37586
27,24000;1,29504;3938,49984
27,28000;1,29707;3947,21068
27,32000;1,29905;3957,14901
27,36000;1,30096;3964,01882
27,40000;1,30305;3972,99938
27,44000;1,30509;3981,12349
27,48000;1,30706;3989,03899
27,52000;1,30909;3996,77232
27,56000;1,31094;4004,53433
27,60000;1,31304;4011,69397
27,64000;1,31507;4021,16776
27,68000;1,31704;4028,98677
27,72000;1,31908;4036,09946
27,76000;1,32099;4042,73085
27,80000;1,32296;4048,97258
27,84000;1,32499;4056,81320
27,88000;1,32703;4065,81014
27,92000;1,32906;4073,20969
27,96000;1,33103;4080,16741
28,00000;1,33301;4085,10566
28,04000;1,33504;4093,75541
28,08000;1,33707;4101,02457
28,12000;1,33911;4108,34253
28,16000;1,34108;4115,50589
28,20000;1,34299;4121,96219
28,24000;1,34508;4128,06906
28,28000;1,34706;4134,59949
28,32000;1,34903;4142,35964
28,36000;1,35106;4149,38740
28,40000;1,35298;4156,60441
28,44000;1,35501;4162,20352
28,48000;1,35704;4169,70737
28,52000;1,35902;4177,14976
28,56000;1,36111;4184,12462
28,60000;1,36302;4190,58725
28,64000;1,36505;4195,37276
28,68000;1,36709;4202,15502
28,72000;1,36906;4207,75078
28,76000;1,37103;4213,17853
28,80000;1,37301;4220,46334
28,84000;1,37498;4224,50639
28,88000;1,37707;4231,63399
28,92000;1,37904;4237,46556
28,96000;1,38102;4243,14402
29,00000;1,38305;4249,83464
29,04000;1,38502;4254,93009
29,08000;1,38712;4261,18635
29,12000;1,38915;4266,88977
29,16000;1,39112;4269,13761
29,20000;1,39315;4272,50899
29,24000;1,39501;4273,36097
29,28000;1,39710;4274,12353
29,32000;1,39913;4274,75534
29,36000;1,40111;4267,72423
29,40000;1,40314;4245,18585
29,44000;1,40499;4200,08861
29,48000;1,40709;4155,24840
29,52000;1,40912;4141,41305
29,56000;1,41115;4143,89111
29,60000;1,41324;4151,43073
29,64000;1,41510;4160,15312
29,68000;1,41713;4168,14312
29,72000;1,41910;4176,99218
29,76000;1,42114;4186,03383
29,80000;1,42317;4195,39884
29,84000;1,42514;4205,40161
29,88000;1,42712;4211,91417
29,92000;1,42909;4220,15637
29,96000;1,43112;4227,22772
30,00000;1,43309;4235,40771
30,04000;1,43513;4241,83458
30,08000;1,43704;4247,50559
30,12000;1,43907;4253,69218
30,16000;1,44111;4259,99798
30,20000;1,44314;4265,14819
30,24000;1,44511;4271,76878
30,28000;1,44703;4277,73967
30,32000;1,44912;4283,48295
30,36000;1,45109;4290,41609
30,40000;1,45312;4295,63858
30,44000;1,45516;4302,31616
30,48000;1,45707;4308,37274
30,52000;1,45904;4313,03419
30,56000;1,46108;4319,93790
30,60000;1,46311;4326,35173
30,64000;1,46514;4331,14395
30,68000;1,46711;4337,26162
30,72000;1,46909;4342,02626
30,76000;1,47112;4347,68051
30,80000;1,47315;4353,82202
30,84000;1,47513;4358,55798
30,88000;1,47710;4362,51760
30,92000;1,47907;4368,20872
30,96000;1,48111;4374,00453
31,00000;1,48314;4379,50343
31,04000;1,48517;4384,34482
31,08000;1,48714;4388,74289
31,12000;1,48906;4393,45650
31,16000;1,49109;4397,61542
31,20000;1,49306;4403,71186
31,24000;1,49516;4408,82891
31,28000;1,49713;4413,44902
31,32000;1,49898;4416,80104
31,36000;1,50102;4419,94853
31,40000;1,50305;4426,34076
31,44000;1,50502;4432,25540
31,48000;1,50711;4438,53997
31,52000;1,50909;4442,88217
31,56000;1,51106;4444,34099
31,60000;1,51303;4450,01684
31,64000;1,51507;4455,10447
31,68000;1,51716;4460,75611
31,72000;1,51913;4466,17715
31,76000;1,52104;4469,26691
31,80000;1,52308;4473,37553
31,84000;1,52505;4478,94074
31,88000;1,52714;4486,20059
31,92000;1,52912;4492,49223
31,96000;1,53103;4496,11917
32,00000;1,53312;4501,63558
32,04000;1,53510;4505,57992
32,08000;1,53713;4510,74094
32,12000;1,53916;4516,83439
32,16000;1,54101;4521,57557
32,20000;1,54311;4526,68890
32,24000;1,54508;4532,44299
32,28000;1,54705;4537,22291
32,32000;1,54909;4542,03896
32,36000;1,55100;4547,44622
32,40000;1,55297;4552,36398
32,44000;1,55501;4559,01697
32,48000;1,55704;4564,53972
32,52000;1,55907;4569,40755
32,56000;1,56104;4574,30147
32,60000;1,56302;4578,64329
32,64000;1,56511;4585,12418
32,68000;1,56708;4590,22596
32,72000;1,56912;4594,73915
32,76000;1,57109;4599,33542
32,80000;1,57300;4604,03189
32,84000;1,57503;4609,40488
32,88000;1,57713;4615,81722
32,92000;1,57910;4621,95314
32,96000;1,58119;4627,10373
33,00000;1,58305;4630,89980
33,04000;1,58508;4632,88948
33,08000;1,58711;4639,18969
33,12000;1,58914;4645,31481
33,16000;1,59118;4651,43733
33,20000;1,59303;4655,90544
33,24000;1,59506;4658,04413
33,28000;1,59704;4663,42568
33,32000;1,59907;4669,42638
33,36000;1,60110;4675,26503
33,40000;1,60302;4681,71723
33,44000;1,60505;4684,94780
33,48000;1,60708;4689,74374
33,52000;1,60905;4695,56078
33,56000;1,61109;4701,04590
33,60000;1,61306;4707,85834
33,64000;1,61503;4711,17646
33,68000;1,61713;4716,97748
33,72000;1,61910;4722,77738
33,76000;1,62113;4727,30435
33,80000;1,62311;4733,38068
33,84000;1,62508;4738,36251
33,88000;1,62711;4744,60982
33,92000;1,62914;4749,70266
33,96000;1,63118;4754,68114
34,00000;1,63321;4760,39574
34,04000;1,63512;4763,44004
34,08000;1,63716;4767,83291
34,12000;1,63913;4773,08072
34,16000;1,64122;4779,15816
34,20000;1,64319;4784,25026
34,24000;1,64505;4787,67343
34,28000;1,64708;4791,66880
34,32000;1,64905;4798,59039
34,36000;1,65115;4804,22787
34,40000;1,65312;4809,92906
34,44000;1,65503;4814,34949
34,48000;1,65707;4817,61210
34,52000;1,65904;4823,35873
34,56000;1,66107;4829,18844
34,60000;1,66310;4834,91346
34,64000;1,66508;4840,69474
34,68000;1,66699;4843,74091
34,72000;1,66902;4848,80023
34,76000;1,67106;4854,65750
34,80000;1,67315;4860,06737
34,84000;1,67512;4866,22564
34,88000;1,67704;4870,39872
34,92000;1,67913;4874,58110
34,96000;1,68110;4878,38574
35,00000;1,68307;4884,94970
35,04000;1,68517;4891,46486
35,08000;1,68708;4895,91435
35,12000;1,68911;4899,52601
35,16000;1,69109;4904,50524
35,20000;1,69306;4909,35445
35,24000;1,69515;4915,74556
35,28000;1,69706;4921,38155
35,32000;1,69910;4925,70996
35,36000;1,70107;4931,22675
35,40000;1,70310;4935,87852
35,44000;1,70508;4939,90928
35,48000;1,70711;4945,55570
35,52000;1,70902;4951,39919
35,56000;1,71106;4956,37134
35,60000;1,71303;4960,42408
35,64000;1,71506;4966,39609
35,68000;1,71686;4972,10212
35,72000;1,71901;4977,64051
35,76000;1,72110;4984,27376
35,80000;1,72313;4989,58044
35,84000;1,72511;4993,51509
35,88000;1,72714;4998,07335
35,92000;1,72905;5001,19664
35,96000;1,73103;5004,43876
36,00000;1,73306;5010,47559
36,04000;1,73509;5016,14623
36,08000;1,73712;5021,42422
36,12000;1,73904;5027,33402
36,16000;1,74107;5030,48114
36,20000;1,74292;5035,80794
36,24000;1,74520;5045,93924
36,28000;1,74717;5050,41592
36,32000;1,74908;5054,62661
36,36000;1,75105;5057,41388
36,40000;1,75309;5062,89639
36,44000;1,75506;5067,58206
36,48000;1,75709;5072,40742
36,52000;1,75907;5078,35709
36,56000;1,76098;5081,27697
36,60000;1,76301;5087,10183
36,64000;1,76511;5094,67386
36,68000;1,76708;5099,29396
36,72000;1,76917;5105,17918
36,76000;1,77102;5108,72193
36,80000;1,77312;5113,69444
36,84000;1,77509;5118,79474
36,88000;1,77712;5123,53107
36,92000;1,77910;5128,40487
36,96000;1,78101;5133,16207
37,00000;1,78310;5140,62867
37,04000;1,78508;5145,08523
37,08000;1,78705;5149,51274
37,12000;1,78908;5154,20884
37,16000;1,79099;5159,23053
37,20000;1,79309;5163,74037
37,24000;1,79512;5170,07411
37,28000;1,79709;5175,78796
37,32000;1,79913;5180,86255
37,36000;1,80110;5186,01462
37,40000;1,80301;5189,24594
37,44000;1,80510;5196,13847
37,48000;1,80708;5201,87430
37,52000;1,80911;5207,16868
37,56000;1,81108;5210,77476
37,60000;1,81300;5214,55854
37,64000;1,81497;5220,19379
37,68000;1,81712;5228,24712
37,72000;1,81916;5234,60917
37,76000;1,82119;5239,03184
37,80000;1,82304;5242,75303
37,84000;1,82507;5246,33788
37,88000;1,82705;5252,10090
37,92000;1,82902;5257,41093
37,96000;1,83111;5262,05562
38,00000;1,83303;5268,56966
38,04000;1,83506;5271,27609
38,08000;1,83703;5276,66286
38,12000;1,83906;5282,70304
38,16000;1,84116;5291,92686
38,20000;1,84301;5297,17319
38,24000;1,84510;5300,06960
38,28000;1,84708;5305,08906
38,32000;1,84905;5309,17570
38,36000;1,85114;5314,04912
38,40000;1,85306;5319,49066
38,44000;1,85509;5322,56775
38,48000;1,85706;5328,44365
38,52000;1,85909;5331,97597
38,56000;1,86113;5336,88888
38,60000;1,86310;5342,79384
38,64000;1,86501;5347,87700
38,68000;1,86717;5356,55729
38,72000;1,86914;5360,37274
38,76000;1,87117;5363,83651
38,80000;1,87309;5368,39180
38,84000;1,87500;5372,51458
38,88000;1,87709;5378,05371
38,92000;1,87912;5383,02921
38,96000;1,88110;5387,63255
39,00000;1,88313;5392,97909
39,04000;1,88498;5398,35282
39,08000;1,88690;5402,15410
39,12000;1,88911;5410,10052
39,16000;1,89114;5416,80939
39,20000;1,89317;5420,67662
39,24000;1,89503;5423,57229
39,28000;1,89700;5427,03867
39,32000;1,89903;5432,64188
39,36000;1,90107;5438,90931
39,40000;1,90310;5444,25920
39,44000;1,90507;5447,92302
39,48000;1,90705;5452,37586
39,52000;1,90908;5456,81417
39,56000;1,91111;5463,23471
39,60000;1,91308;5468,30632
39,64000;1,91512;5474,09318
39,68000;1,91703;5478,89248
39,72000;1,91906;5483,17321
39,76000;1,92110;5488,25823
39,80000;1,92313;5495,94089
39,84000;1,92510;5501,50126
39,88000;1,92702;5504,81081
39,92000;1,92905;5509,11650
39,96000;1,93108;5514,30173
40,00000;1,93305;5518,48784
40,04000;1,93509;5524,35443
40,08000;1,93700;5530,05598
40,12000;1,93903;5534,55465
40,16000;1,94107;5539,52940
40,20000;1,94304;5544,59058
40,24000;1,94507;5548,68989
40,28000;1,94704;5555,33133
40,32000;1,94896;5559,94585
40,36000;1,95105;5565,28121
40,40000;1,95302;5570,32786
40,44000;1,95506;5574,15821
40,48000;1,95709;5580,73074
40,52000;1,95900;5585,56132
40,56000;1,96110;5590,54576
40,60000;1,96313;5596,48350
40,64000;1,96516;5601,75963
40,68000;1,96713;5606,76455
40,72000;1,96905;5611,50424
40,76000;1,97108;5616,35680
40,80000;1,97311;5623,34284
40,84000;1,97509;5627,78898
40,88000;1,97712;5631,97695
40,92000;1,97897;5637,20129
40,96000;1,98101;5642,15705
41,00000;1,98304;5649,04884
41,04000;1,98513;5654,61442
41,08000;1,98710;5659,51504
41,12000;1,98908;5664,65482
41,16000;1,99099;5667,99864
41,20000;1,99302;5672,96818
41,24000;1,99506;5678,84259
41,28000;1,99709;5685,20948
41,32000;1,99906;5690,08440
41,36000;2,00103;5693,65807
41,40000;2,00307;5699,15175
41,44000;2,00510;5707,71396
41,48000;2,00707;5712,77253
41,52000;2,00911;5717,19222
41,56000;2,01102;5721,96953
41,60000;2,01311;5725,85016
41,64000;2,01515;5730,41514
41,68000;2,01712;5735,35822
41,72000;2,01915;5740,66192
41,76000;2,02106;5745,73018
41,80000;2,02310;5749,74529
41,84000;2,02513;5755,29896
41,88000;2,02710;5759,76446
41,92000;2,02914;5765,58486
41,96000;2,03105;5771,11691
42,00000;2,03308;5774,81948
42,04000;2,03511;5781,15843
42,08000;2,03709;5785,70254
42,12000;2,03912;5789,20953
42,16000;2,04109;5794,62834
42,20000;2,04301;5798,37337
42,24000;2,04510;5803,75604
42,28000;2,04707;5809,24414
42,32000;2,04905;5814,12427
42,36000;2,05108;5819,80906
42,40000;2,05299;5825,72259
42,44000;2,05508;5830,41459
42,48000;2,05712;5836,71182
42,52000;2,05909;5841,84192
42,56000;2,06112;5847,28606
42,60000;2,06298;5850,85936
42,64000;2,06507;5854,72323
42,68000;2,06710;5861,41758
42,72000;2,06913;5866,79727
42,76000;2,07117;5871,86366
42,80000;2,07302;5876,46998
42,84000;2,07505;5879,93413
42,88000;2,07703;5885,64612
42,92000;2,07906;5891,85618
42,96000;2,08115;5897,01049
43,00000;2,08307;5902,23894
43,04000;2,08510;5905,69116
43,08000;2,08707;5911,01423
43,12000;2,08910;5915,65073
43,16000;2,09114;5923,41423
43,20000;2,09311;5928,25152
43,24000;2,09502;5931,95446
43,28000;2,09706;5936,65689
43,32000;2,09909;5941,25353
43,36000;2,10106;5946,41604
43,40000;2,10310;5951,74357
43,44000;2,10507;5956,60023
43,48000;2,10710;5961,33582
43,52000;2,10913;5966,41190
43,56000;2,11117;5970,92547
43,60000;2,11320;5977,52482
43,64000;2,11505;5981,46617
43,68000;2,11709;5985,49470
43,72000;2,11912;5991,61573
43,76000;2,12115;5996,19672
43,80000;2,12312;5999,15348
43,82600;2,12438;6002,31662