File: SU - Suspension/05 - Essais/Excels essais Optimus/Test_Rotules_31_01_19/M7_5.is_tens_RawData/Specimen_RawData_1.csv
Temps;Déplacement;Charge
(sec);(mm);(N)
0,00000;0,00831;23,06627
0,04000;0,00843;22,45460
0,08000;0,00897;23,62704
0,12000;0,01010;24,25688
0,16000;0,01148;25,08371
0,20000;0,01309;26,01732
0,24000;0,01453;26,38348
0,28000;0,01602;27,63780
0,32000;0,01764;28,39047
0,36000;0,01913;28,31428
0,40000;0,02063;29,47747
0,44000;0,02200;29,60544
0,48000;0,02344;30,47357
0,52000;0,02469;31,19720
0,56000;0,02595;31,52573
0,60000;0,02744;31,78963
0,64000;0,02876;32,26637
0,68000;0,03007;32,08283
0,72000;0,03145;33,40469
0,76000;0,03276;33,54961
0,80000;0,03420;33,19973
0,84000;0,03540;33,85388
0,88000;0,03665;33,10084
0,92000;0,03815;33,20834
0,96000;0,03946;34,26244
1,00000;0,04084;34,09711
1,04000;0,04221;34,96886
1,08000;0,04359;36,18865
1,12000;0,04496;37,43029
1,16000;0,04616;38,58141
1,20000;0,04741;40,19684
1,24000;0,04885;42,13221
1,28000;0,05016;42,65876
1,32000;0,05148;43,66497
1,36000;0,05285;43,86279
1,40000;0,05417;45,52205
1,44000;0,05554;45,71803
1,48000;0,05674;46,49893
1,52000;0,05800;46,72622
1,56000;0,05943;48,25077
1,60000;0,06081;49,40557
1,64000;0,06212;50,12430
1,68000;0,06350;49,98801
1,72000;0,06487;51,13034
1,76000;0,06619;51,41174
1,80000;0,06744;51,95305
1,84000;0,06876;52,78739
1,88000;0,07019;53,39167
1,92000;0,07151;54,04286
1,96000;0,07288;54,66650
2,00000;0,07414;54,48663
2,04000;0,07551;54,95616
2,08000;0,07689;55,15376
2,12000;0,07809;55,67619
2,16000;0,07940;55,40644
2,20000;0,08084;56,44147
2,24000;0,08215;56,63816
2,28000;0,08353;57,64043
2,32000;0,08484;57,05598
2,36000;0,08616;58,10892
2,40000;0,08753;58,31399
2,44000;0,08879;59,07890
2,48000;0,09016;58,76655
2,52000;0,09154;60,05681
2,56000;0,09291;60,45426
2,60000;0,09423;61,12615
2,64000;0,09560;61,08828
2,68000;0,09698;61,82814
2,72000;0,09823;61,47848
2,76000;0,09949;62,86907
2,80000;0,10086;63,97367
2,84000;0,10218;64,41313
2,88000;0,10350;64,76534
2,92000;0,10481;65,82646
2,96000;0,10619;66,41743
3,00000;0,10756;67,11738
3,04000;0,10882;67,30281
3,08000;0,11007;68,08699
3,12000;0,11145;68,46848
3,16000;0,11282;70,07791
3,20000;0,11414;70,55121
3,24000;0,11551;72,58331
3,28000;0,11683;74,08277
3,32000;0,11820;75,89595
3,36000;0,11946;77,09158
3,40000;0,12071;79,10679
3,44000;0,12215;80,83952
3,48000;0,12353;84,55744
3,52000;0,12484;86,68933
3,56000;0,12616;89,01096
3,60000;0,12747;92,01067
3,64000;0,12885;95,09576
3,68000;0,13010;96,70060
3,72000;0,13136;99,63292
3,76000;0,13279;102,16407
3,80000;0,13417;104,19936
3,84000;0,13548;106,67875
3,88000;0,13686;109,35225
3,92000;0,13823;112,19591
3,96000;0,13955;115,81868
4,00000;0,14080;117,60121
4,04000;0,14212;119,94615
4,08000;0,14355;122,34696
4,12000;0,14487;123,92168
4,16000;0,14625;125,43818
4,20000;0,14756;126,90616
4,24000;0,14888;128,88028
4,28000;0,15025;129,80684
4,32000;0,15145;130,84902
4,36000;0,15276;132,54101
4,40000;0,15420;134,67389
4,44000;0,15551;136,37914
4,48000;0,15683;138,37614
4,52000;0,15820;140,14662
4,56000;0,15958;142,07076
4,60000;0,16089;144,72981
4,64000;0,16209;146,14308
4,68000;0,16346;148,53989
4,72000;0,16484;150,39169
4,76000;0,16615;152,34133
4,80000;0,16753;154,37041
4,84000;0,16885;156,92756
4,88000;0,17022;158,89630
4,92000;0,17148;160,98677
4,96000;0,17273;163,15333
5,00000;0,17411;165,22671
5,04000;0,17548;167,40292
5,08000;0,17680;169,07409
5,12000;0,17817;170,57625
5,16000;0,17949;172,07281
5,20000;0,18086;173,02691
5,24000;0,18212;173,33332
5,28000;0,18337;171,76737
5,32000;0,18475;172,55698
5,36000;0,18612;171,82599
5,40000;0,18750;170,04884
5,44000;0,18888;168,33335
5,48000;0,19019;165,98111
5,52000;0,19163;164,46040
5,56000;0,19282;163,60552
5,60000;0,19414;161,39274
5,64000;0,19551;161,93419
5,68000;0,19683;161,39401
5,72000;0,19814;160,27413
5,76000;0,19952;159,82884
5,80000;0,20083;159,69938
5,84000;0,20221;159,03233
5,88000;0,20346;158,23229
5,92000;0,20472;155,83716
5,96000;0,20615;157,06436
6,00000;0,20747;155,44122
6,04000;0,20884;155,86908
6,08000;0,21016;154,73677
6,12000;0,21154;154,26767
6,16000;0,21291;153,84883
6,20000;0,21411;153,65473
6,24000;0,21542;153,15739
6,28000;0,21686;153,48399
6,32000;0,21817;152,30031
6,36000;0,21949;152,49646
6,40000;0,22080;151,21269
6,44000;0,22218;151,35312
6,48000;0,22355;150,56400
6,52000;0,22475;149,48123
6,56000;0,22606;149,13167
6,60000;0,22750;149,86630
6,64000;0,22881;148,89889
6,68000;0,23013;148,68452
6,72000;0,23145;148,99251
6,76000;0,23282;149,15018
6,80000;0,23420;147,81383
6,84000;0,23545;147,01912
6,88000;0,23677;145,39559
6,92000;0,23820;145,81933
6,96000;0,23952;144,31908
7,00000;0,24089;144,91940
7,04000;0,24221;142,77198
7,08000;0,24358;142,39730
7,12000;0,24490;141,77153
7,16000;0,24609;140,99376
7,20000;0,24753;140,36647
7,24000;0,24884;141,04561
7,28000;0,25022;139,13128
7,32000;0,25153;139,10132
7,36000;0,25285;137,95793
7,40000;0,25422;138,09204
7,44000;0,25548;137,39625
7,48000;0,25674;136,94019
7,52000;0,25811;135,96162
7,56000;0,25949;136,04045
7,60000;0,26086;135,21491
7,64000;0,26218;135,46570
7,68000;0,26361;134,70816
7,72000;0,26499;134,57796
7,76000;0,26618;134,65900
7,80000;0,26738;133,12845
7,84000;0,26881;133,62697
7,88000;0,27019;133,60082
7,92000;0,27156;132,83720
7,96000;0,27288;133,38258
8,00000;0,27425;132,26818
8,04000;0,27563;131,60137
8,08000;0,27677;131,08004
8,12000;0,27808;130,23000
8,16000;0,27946;130,30957
8,20000;0,28077;130,60899
8,24000;0,28215;129,76347
8,28000;0,28346;129,41787
8,32000;0,28484;128,87926
8,36000;0,28621;129,06841
8,40000;0,28747;127,57007
8,44000;0,28878;128,04474
8,48000;0,29022;128,22415
8,52000;0,29147;127,58721
8,56000;0,29285;127,28382
8,60000;0,29416;127,58819
8,64000;0,29554;126,69517
8,68000;0,29691;127,03346
8,72000;0,29811;125,65342
8,76000;0,29949;126,16605
8,80000;0,30086;126,39926
8,84000;0,30218;126,09999
8,88000;0,30349;125,45101
8,92000;0,30481;126,31196
8,96000;0,30618;125,50100
9,00000;0,30750;125,03339
9,04000;0,30869;124,16176
9,08000;0,31013;125,09052
9,12000;0,31150;124,83170
9,16000;0,31282;124,78107
9,20000;0,31413;124,72618
9,24000;0,31551;124,44640
9,28000;0,31694;123,30825
9,32000;0,31820;123,49652
9,36000;0,31946;122,02678
9,40000;0,32089;123,09036
9,44000;0,32221;122,38163
9,48000;0,32352;120,69625
9,52000;0,32490;120,17634
9,56000;0,32627;120,78473
9,60000;0,32759;120,78385
9,64000;0,32878;120,64984
9,68000;0,33004;119,37439
9,72000;0,33153;120,29709
9,76000;0,33279;119,81531
9,80000;0,33416;119,64771
9,84000;0,33554;119,22612
9,88000;0,33685;119,65858
9,92000;0,33823;119,60834
9,96000;0,33948;119,03129
10,00000;0,34080;117,42567
10,04000;0,34224;118,56572
10,08000;0,34355;118,19325
10,12000;0,34493;118,19310
10,16000;0,34624;117,62716
10,20000;0,34756;118,22195
10,24000;0,34887;117,85313
10,28000;0,35013;116,88618
10,32000;0,35138;116,68140
10,36000;0,35282;117,64289
10,40000;0,35413;116,46748
10,44000;0,35545;116,96070
10,48000;0,35682;116,11468
10,52000;0,35820;116,18475
10,56000;0,35951;116,55071
10,60000;0,36071;117,02710
10,64000;0,36209;116,67690
10,68000;0,36352;116,13006
10,72000;0,36484;115,49464
10,76000;0,36621;116,32170
10,80000;0,36753;115,77697
10,84000;0,36890;115,53062
10,88000;0,37022;114,95944
10,92000;0,37147;114,87498
10,96000;0,37291;114,49902
11,00000;0,37422;114,60092
11,04000;0,37554;113,83932
11,08000;0,37685;114,50148
11,12000;0,37817;113,89592
11,16000;0,37954;113,55812
11,20000;0,38086;113,20683
11,24000;0,38211;112,54292
11,28000;0,38349;112,32820
11,32000;0,38481;112,76850
11,36000;0,38618;111,74944
11,40000;0,38756;112,55956
11,44000;0,38887;111,70689
11,48000;0,39025;111,96053
11,52000;0,39150;111,56822
11,56000;0,39282;110,85343
11,60000;0,39425;110,92261
11,64000;0,39557;111,01834
11,68000;0,39688;109,55629
11,72000;0,39820;109,83339
11,76000;0,39951;109,12304
11,80000;0,40089;109,36974
11,84000;0,40208;108,99295
11,88000;0,40340;108,77774
11,92000;0,40483;108,55373
11,96000;0,40615;108,75987
12,00000;0,40753;108,84180
12,04000;0,40884;108,18781
12,08000;0,41022;107,73968
12,12000;0,41159;108,37427
12,16000;0,41279;106,71817
12,20000;0,41410;106,24649
12,24000;0,41548;106,55854
12,28000;0,41685;106,59958
12,32000;0,41823;105,98365
12,36000;0,41954;106,79994
12,40000;0,42092;104,93046
12,44000;0,42217;105,06898
12,48000;0,42337;103,29585
12,52000;0,42474;104,09893
12,56000;0,42612;104,39052
12,60000;0,42749;105,02883
12,64000;0,42887;103,98802
12,68000;0,43019;104,27790
12,72000;0,43156;103,53358
12,76000;0,43288;103,70462
12,80000;0,43407;102,38334
12,84000;0,43551;103,02885
12,88000;0,43688;103,11968
12,92000;0,43820;103,47379
12,96000;0,43957;102,38021
13,00000;0,44089;102,79984
13,04000;0,44226;102,25378
13,08000;0,44352;102,09263
13,12000;0,44477;101,16763
13,16000;0,44615;101,08796
13,20000;0,44752;101,08856
13,24000;0,44884;100,85357
13,28000;0,45016;101,16596
13,32000;0,45153;100,93931
13,36000;0,45291;100,83917
13,40000;0,45416;100,00089
13,44000;0,45542;99,12534
13,48000;0,45685;99,91124
13,52000;0,45817;99,27254
13,56000;0,45948;98,61881
13,60000;0,46086;98,34499
13,64000;0,46217;98,37579
13,68000;0,46355;98,03136
13,72000;0,46480;97,99146
13,76000;0,46612;97,22688
13,80000;0,46755;98,07872
13,84000;0,46881;96,93950
13,88000;0,47018;96,88877
13,92000;0,47150;96,85532
13,96000;0,47282;96,22602
14,00000;0,47419;96,74603
14,04000;0,47545;95,44063
14,08000;0,47682;96,25531
14,12000;0,47820;96,30834
14,16000;0,47951;94,52204
14,20000;0,48089;94,92341
14,24000;0,48220;94,73925
14,28000;0,48358;94,28083
14,32000;0,48489;94,21234
14,36000;0,48609;93,35505
14,40000;0,48746;93,93308
14,44000;0,48884;94,37211
14,48000;0,49015;93,57574
14,52000;0,49153;93,15518
14,56000;0,49284;92,91559
14,60000;0,49416;92,07790
14,64000;0,49554;92,47912
14,68000;0,49667;91,48130
14,72000;0,49811;92,53180
14,76000;0,49948;92,76037
14,80000;0,50086;92,11638
14,84000;0,50217;91,81079
14,88000;0,50355;91,48375
14,92000;0,50492;92,15242
14,96000;0,50618;91,59691
15,00000;0,50737;90,79555
15,04000;0,50881;90,75094
15,08000;0,51018;91,82348
15,12000;0,51150;91,71139
15,16000;0,51281;90,82924
15,20000;0,51419;90,94915
15,24000;0,51556;90,98984
15,28000;0,51682;90,58921
15,32000;0,51802;89,53357
15,36000;0,51951;90,37063
15,40000;0,52083;90,02092
15,44000;0,52220;90,14201
15,48000;0,52358;89,73031
15,52000;0,52489;89,05357
15,56000;0,52627;89,14488
15,60000;0,52746;88,69656
15,64000;0,52878;88,63085
15,68000;0,53021;89,09915
15,72000;0,53153;88,58786
15,76000;0,53284;88,59995
15,80000;0,53422;89,18836
15,84000;0,53559;88,85276
15,88000;0,53691;88,71810
15,92000;0,53817;88,48709
15,96000;0,53948;87,46631
16,00000;0,54092;88,48336
16,04000;0,54217;88,32570
16,08000;0,54349;87,65233
16,12000;0,54486;88,06246
16,16000;0,54618;87,48614
16,20000;0,54755;88,69499
16,24000;0,54881;87,13521
16,28000;0,55018;87,25409
16,32000;0,55150;87,70203
16,36000;0,55281;87,34355
16,40000;0,55419;87,36329
16,44000;0,55550;87,28642
16,48000;0,55688;87,03278
16,52000;0,55813;87,14681
16,56000;0,55933;87,53765
16,60000;0,56077;86,96319
16,64000;0,56214;87,77484
16,68000;0,56358;87,70800
16,72000;0,56489;87,11028
16,76000;0,56621;87,00193
16,80000;0,56758;87,41563
16,84000;0,56878;87,15054
16,88000;0,57009;86,09578
16,92000;0,57153;87,33455
16,96000;0,57290;86,68904
17,00000;0,57422;86,87305
17,04000;0,57559;86,78325
17,08000;0,57691;86,68595
17,12000;0,57828;86,35823
17,16000;0,57942;86,06483
17,20000;0,58074;86,29027
17,24000;0,58217;86,97166
17,28000;0,58349;86,39554
17,32000;0,58480;86,41513
17,36000;0,58606;86,10929
17,40000;0,58755;86,53587
17,44000;0,58887;85,52612
17,48000;0,59006;84,72025
17,52000;0,59144;85,65534
17,56000;0,59287;86,11639
17,60000;0,59419;85,58340
17,64000;0,59556;85,23291
17,68000;0,59688;85,45791
17,72000;0,59825;85,50590
17,76000;0,59957;85,32629
17,80000;0,60076;84,85618
17,84000;0,60214;84,59989
17,88000;0,60352;85,52009
17,92000;0,60477;84,68587
17,96000;0,60615;85,31997
18,00000;0,60746;84,59984
18,04000;0,60884;84,79032
18,08000;0,61015;85,07647
18,12000;0,61141;84,37588
18,16000;0,61272;83,64850
18,20000;0,61416;84,21742
18,24000;0,61547;83,43682
18,28000;0,61685;83,32073
18,32000;0,61816;83,61079
18,36000;0,61942;84,05035
18,40000;0,62097;84,71633
18,44000;0,62211;83,99111
18,48000;0,62354;83,26814
18,52000;0,62486;83,31951
18,56000;0,62624;82,98992
18,60000;0,62755;83,68370
18,64000;0,62887;83,05553
18,68000;0,63024;83,46189
18,72000;0,63150;83,17339
18,76000;0,63275;82,59967
18,80000;0,63413;83,18891
18,84000;0,63544;83,21124
18,88000;0,63682;82,61450
18,92000;0,63819;82,65157
18,96000;0,63951;82,95883
19,00000;0,64088;82,54355
19,04000;0,64214;82,37139
19,08000;0,64339;82,48910
19,12000;0,64489;83,02395
19,16000;0,64620;82,74886
19,20000;0,64758;82,76962
19,24000;0,64890;82,90971
19,28000;0,65021;82,60843
19,32000;0,65153;82,71958
19,36000;0,65272;81,55255
19,40000;0,65422;83,27235
19,44000;0,65553;81,91802
19,48000;0,65685;81,54373
19,52000;0,65816;81,54701
19,56000;0,65948;81,77230
19,60000;0,66085;81,53644
19,64000;0,66223;81,85172
19,68000;0,66342;81,00957
19,72000;0,66474;81,54975
19,76000;0,66617;81,79771
19,80000;0,66749;81,88561
19,84000;0,66887;81,08312
19,88000;0,67024;81,34395
19,92000;0,67156;82,46991
19,96000;0,67293;81,62124
20,00000;0,67413;80,84691
20,04000;0,67544;81,23505
20,08000;0,67682;81,16465
20,12000;0,67813;80,94969
20,16000;0,67951;80,66838
20,20000;0,68082;80,32881
20,24000;0,68220;80,73796
20,28000;0,68351;80,62564
20,32000;0,68471;79,50101
20,36000;0,68608;80,25350
20,40000;0,68752;80,20987
20,44000;0,68883;79,49425
20,48000;0,69009;80,05348
20,52000;0,69159;80,80049
20,56000;0,69296;80,15004
20,60000;0,69416;80,42077
20,64000;0,69541;79,17093
20,68000;0,69679;79,03398
20,72000;0,69816;80,07551
20,76000;0,69954;79,69692
20,80000;0,70085;79,57866
20,84000;0,70217;78,88243
20,88000;0,70360;79,27596
20,92000;0,70480;78,95940
20,96000;0,70605;79,00998
21,00000;0,70749;78,96165
21,04000;0,70886;79,44293
21,08000;0,71018;78,37843
21,12000;0,71149;78,15260
21,16000;0,71287;78,10227
21,20000;0,71425;78,58560
21,24000;0,71544;78,03910
21,28000;0,71676;77,88535
21,32000;0,71819;78,87866
21,36000;0,71957;78,35194
21,40000;0,72088;77,86445
21,44000;0,72220;77,58451
21,48000;0,72357;77,63543
21,52000;0,72489;77,71951
21,56000;0,72608;77,24567
21,60000;0,72746;77,77454
21,64000;0,72883;77,91551
21,68000;0,73015;77,72582
21,72000;0,73152;77,31653
21,76000;0,73284;76,78501
21,80000;0,73421;77,25350
21,84000;0,73553;76,88573
21,88000;0,73673;76,27704
21,92000;0,73810;76,56261
21,96000;0,73954;76,96917
22,00000;0,74085;76,62940
22,04000;0,74223;76,89170
22,08000;0,74354;76,00382
22,12000;0,74486;75,99383
22,16000;0,74611;75,48591
22,20000;0,74737;75,15941
22,24000;0,74880;76,05646
22,28000;0,75018;75,96244
22,32000;0,75149;75,68888
22,36000;0,75287;75,43289
22,40000;0,75424;76,23351
22,44000;0,75562;76,17069
22,48000;0,75682;75,20902
22,52000;0,75813;75,21822
22,56000;0,75951;75,55207
22,60000;0,76082;76,06767
22,64000;0,76220;75,17347
22,68000;0,76357;74,99239
22,72000;0,76495;76,36930
22,76000;0,76626;76,03369
22,80000;0,76752;75,73275
22,84000;0,76877;74,66149
22,88000;0,77021;75,24946
22,92000;0,77146;75,22003
22,96000;0,77278;74,99626
23,00000;0,77415;75,94320
23,04000;0,77553;75,23032
23,08000;0,77684;74,50730
23,12000;0,77810;74,27961
23,16000;0,77942;74,79360
23,20000;0,78085;75,52141
23,24000;0,78217;74,44207
23,28000;0,78348;74,51792
23,32000;0,78486;74,71794
23,36000;0,78617;74,19838
23,40000;0,78755;74,13545
23,44000;0,78880;74,62741
23,48000;0,79012;73,89548
23,52000;0,79149;74,16630
23,56000;0,79281;73,74682
23,60000;0,79412;74,14706
23,64000;0,79550;73,61457
23,68000;0,79687;74,28372
23,72000;0,79819;74,24426
23,76000;0,79939;73,60330
23,80000;0,80076;73,44270
23,84000;0,80220;73,42869
23,88000;0,80351;74,06661
23,92000;0,80489;74,00041
23,96000;0,80626;73,95482
24,00000;0,80758;74,57457
24,04000;0,80889;73,64590
24,08000;0,81009;72,55535
24,12000;0,81152;72,77677
24,16000;0,81290;72,64496
24,20000;0,81421;72,44591
24,24000;0,81553;73,46228
24,28000;0,81690;72,72917
24,32000;0,81828;72,93219
24,36000;0,81947;73,04162
24,40000;0,82073;72,25710
24,44000;0,82217;72,61989
24,48000;0,82348;71,95881
24,52000;0,82486;72,14688
24,56000;0,82617;72,48234
24,60000;0,82755;72,28707
24,64000;0,82892;72,41198
24,68000;0,83012;72,81457
24,72000;0,83137;71,55744
24,76000;0,83281;72,46016
24,80000;0,83412;72,21911
24,84000;0,83550;72,88214
24,88000;0,83681;72,73652
24,92000;0,83819;72,82383
24,96000;0,83956;72,30553
25,00000;0,84076;72,35993
25,04000;0,84202;71,64709
25,08000;0,84345;72,49899
25,12000;0,84483;72,43357
25,16000;0,84620;71,75124
25,20000;0,84752;72,25348
25,24000;0,84889;72,78617
25,28000;0,85027;72,60676
25,32000;0,85146;71,78322
25,36000;0,85272;72,07843
25,40000;0,85409;72,67453
25,44000;0,85547;71,75604
25,48000;0,85684;71,07063
25,52000;0,85822;71,68749
25,56000;0,85959;72,43534
25,60000;0,86091;72,42961
25,64000;0,86210;71,90279
25,68000;0,86354;71,08194
25,72000;0,86485;70,97838
25,76000;0,86623;71,16591
25,80000;0,86755;70,99214
25,84000;0,86892;71,18790
25,88000;0,87024;71,94476
25,92000;0,87155;71,24103
25,96000;0,87275;70,55851
26,00000;0,87418;70,90400
26,04000;0,87556;70,08002
26,08000;0,87687;70,64189
26,12000;0,87819;70,62808
26,16000;0,87950;70,58284
26,20000;0,88088;70,46948
26,24000;0,88213;70,64145
26,28000;0,88339;69,89067
26,32000;0,88482;70,15528
26,36000;0,88614;69,91892
26,40000;0,88752;70,06768
26,44000;0,88883;70,07321
26,48000;0,89021;69,27038
26,52000;0,89158;69,47060
26,56000;0,89284;69,99110
26,60000;0,89409;69,19620
26,64000;0,89553;69,81095
26,68000;0,89684;68,98995
26,72000;0,89816;68,67555
26,76000;0,89953;69,28693
26,80000;0,90085;69,44131
26,84000;0,90216;69,17352
26,88000;0,90342;68,84291
26,92000;0,90473;69,21485
26,96000;0,90617;69,65108
27,00000;0,90748;69,20060
27,04000;0,90886;69,17171
27,08000;0,91018;69,20129
27,12000;0,91149;68,61214
27,16000;0,91287;69,24404
27,20000;0,91412;68,82523
27,24000;0,91544;68,58864
27,28000;0,91687;69,00498
27,32000;0,91819;69,38687
27,36000;0,91956;69,21804
27,40000;0,92088;69,18631
27,44000;0,92225;69,16143
27,48000;0,92363;68,66815
27,52000;0,92476;68,29509
27,56000;0,92608;68,31820
27,60000;0,92745;69,33893
27,64000;0,92883;68,85099
27,68000;0,93015;68,58961
27,72000;0,93146;68,60739
27,76000;0,93284;68,00864
27,80000;0,93421;69,02110
27,84000;0,93535;68,26258
27,88000;0,93672;68,46813
27,92000;0,93816;69,07388
27,96000;0,93953;67,90342
28,00000;0,94085;67,66349
28,04000;0,94222;68,29103
28,08000;0,94360;68,67428
28,12000;0,94485;67,92423
28,16000;0,94605;66,91927
28,20000;0,94748;67,63024
28,24000;0,94880;67,55101
28,28000;0,95011;67,51997
28,32000;0,95125;67,46151
28,36000;0,95287;68,88414
28,40000;0,95418;67,44780
28,44000;0,95538;66,83901
28,48000;0,95669;67,29488
28,52000;0,95819;68,24534
28,56000;0,95950;67,50847
28,60000;0,96088;67,09084
28,64000;0,96219;67,86484
28,68000;0,96357;67,31363
28,72000;0,96494;68,49467
28,76000;0,96614;67,70898
28,80000;0,96751;67,47536
28,84000;0,96895;67,56370
28,88000;0,97020;67,54627
28,92000;0,97158;67,67852
28,96000;0,97289;67,99376
29,00000;0,97427;67,47536
29,04000;0,97559;66,97288
29,08000;0,97678;66,53298
29,12000;0,97816;67,10386
29,16000;0,97947;67,82869
29,20000;0,98079;66,39608
29,24000;0,98216;66,76576
29,28000;0,98354;67,23069
29,32000;0,98491;66,97234
29,36000;0,98617;67,18211
29,40000;0,98742;66,46365
29,44000;0,98868;66,68174
29,48000;0,99023;67,35344
29,52000;0,99155;66,13235
29,56000;0,99292;66,69168
29,60000;0,99424;66,60687
29,64000;0,99555;66,68140
29,68000;0,99675;65,44135
29,72000;0,99807;65,83043
29,76000;0,99950;66,20149
29,80000;1,00082;65,96303
29,84000;1,00213;65,93800
29,88000;1,00351;65,71732
29,92000;1,00488;65,72995
29,96000;1,00626;65,65709
30,00000;1,00745;65,67918
30,04000;1,00877;64,93672
30,08000;1,01014;65,73509
30,12000;1,01146;65,59080
30,16000;1,01283;65,90657
30,20000;1,01415;65,60357
30,24000;1,01564;66,24860
30,28000;1,01696;66,21823
30,32000;1,01810;65,43024
30,36000;1,01947;65,46182
30,40000;1,02085;65,22894
30,44000;1,02216;64,58951
30,48000;1,02348;64,57526
30,52000;1,02485;64,78684
30,56000;1,02617;64,21189
30,60000;1,02754;64,49270
30,64000;1,02874;64,58735
30,68000;1,03017;64,45828
30,72000;1,03155;64,28695
30,76000;1,03286;64,23554
30,80000;1,03418;63,93455
30,84000;1,03555;64,35761
30,88000;1,03693;64,47028
30,92000;1,03824;64,37940
30,96000;1,03950;63,88788
31,00000;1,04088;63,81028
31,04000;1,04219;64,24264
31,08000;1,04357;63,75656
31,12000;1,04488;64,50514
31,16000;1,04620;63,97304
31,20000;1,04751;63,61985
31,24000;1,04883;64,44070
31,28000;1,05008;64,09555
31,32000;1,05152;64,09114
31,36000;1,05283;64,12634
31,40000;1,05421;64,47238
31,44000;1,05552;64,34204
31,48000;1,05690;63,92152
31,52000;1,05827;64,02773
31,56000;1,05947;63,92251
31,60000;1,06073;62,92085
31,64000;1,06216;63,53093
31,68000;1,06354;64,16361
31,72000;1,06479;63,34398
31,76000;1,06623;63,78222
31,80000;1,06754;63,74359
31,84000;1,06892;63,38310
31,88000;1,07011;63,55517
31,92000;1,07137;62,50695
31,96000;1,07280;63,46698
32,00000;1,07418;63,35279
32,04000;1,07549;62,97745
32,08000;1,07687;62,87232
32,12000;1,07824;62,88332
32,16000;1,07956;63,58332
32,20000;1,08075;62,22581
32,24000;1,08213;63,03347
32,28000;1,08339;62,69375
32,32000;1,08488;62,56066
32,36000;1,08626;62,10989
32,40000;1,08757;62,69448
32,44000;1,08889;61,90208
32,48000;1,09020;62,28721
32,52000;1,09140;61,33455
32,56000;1,09277;61,78736
32,60000;1,09415;61,73371
32,64000;1,09546;61,90110
32,68000;1,09684;61,75949
32,72000;1,09815;61,91701
32,76000;1,09959;61,36476
32,80000;1,10084;61,94240
32,84000;1,10210;61,05978
32,88000;1,10347;61,64790
32,92000;1,10485;61,49175
32,96000;1,10617;61,57925
33,00000;1,10754;61,99614
33,04000;1,10886;62,44102
33,08000;1,11023;60,96403
33,12000;1,11155;61,57316
33,16000;1,11274;61,27829
33,20000;1,11412;61,36892
33,24000;1,11549;61,04654
33,28000;1,11681;61,02602
33,32000;1,11818;61,18322
33,36000;1,11950;60,48341
33,40000;1,12087;61,11086
33,44000;1,12213;61,39607
33,48000;1,12344;61,08821
33,52000;1,12482;61,25192
33,56000;1,12614;61,06389
33,60000;1,12751;61,16995
33,64000;1,12883;61,25209
33,68000;1,13014;60,85011
33,72000;1,13128;60,99995
33,76000;1,13283;62,15168
33,80000;1,13409;60,75035
33,84000;1,13552;60,23239
33,88000;1,13684;59,95075
33,92000;1,13821;60,69485
33,96000;1,13953;60,00164
34,00000;1,14090;60,18830
34,04000;1,14222;60,43802
34,08000;1,14347;60,47355
34,12000;1,14479;59,72590
34,16000;1,14616;59,93461
34,20000;1,14754;60,54212
34,24000;1,14891;60,44867
34,28000;1,15023;59,76465
34,32000;1,15155;59,51287
34,36000;1,15292;60,65271
34,40000;1,15412;59,49914
34,44000;1,15537;59,51452
34,48000;1,15681;60,56817
34,52000;1,15806;59,18682
34,56000;1,15956;60,30932
34,60000;1,16087;59,83693
34,64000;1,16225;60,01082
34,68000;1,16350;59,50152
34,72000;1,16476;58,36408
34,75200;1,16590;59,57078