File: SU - Suspension/05 - Essais/Excels essais Optimus/Collage_alu_alu_31_01_19/collage9.is_tens_RawData/Specimen_RawData_1.csv
Temps;Déplacement;Charge
(sec);(mm);(N)
0,00000;-30,65790;47,50367
0,04000;-30,65731;47,30527
0,08000;-30,65503;52,37659
0,12000;-30,65175;62,79240
0,16000;-30,64798;75,22278
0,20000;-30,64409;88,92935
0,24000;-30,64027;102,86502
0,28000;-30,63650;116,70722
0,32000;-30,63279;132,05451
0,36000;-30,62920;144,90722
0,40000;-30,62562;154,76742
0,44000;-30,62221;83,00178
0,48000;-30,61868;67,77935
0,52000;-30,61527;87,18458
0,56000;-30,61193;105,08769
0,60000;-30,60846;122,50494
0,64000;-30,60517;138,74407
0,68000;-30,60206;154,29838
0,72000;-30,59841;169,42983
0,76000;-30,59507;182,64175
0,80000;-30,59178;195,17066
0,84000;-30,58843;208,08305
0,88000;-30,58508;221,52201
0,92000;-30,58173;235,30277
0,96000;-30,57862;247,14596
1,00000;-30,57503;261,15151
1,04000;-30,57169;274,81366
1,08000;-30,56846;287,44696
1,12000;-30,56505;301,48644
1,16000;-30,56164;315,18321
1,20000;-30,55835;327,73102
1,24000;-30,55507;340,55968
1,28000;-30,55172;353,32632
1,32000;-30,54843;365,61941
1,36000;-30,54544;377,19251
1,40000;-30,54161;391,26487
1,44000;-30,53832;402,28791
1,48000;-30,53504;411,28192
1,52000;-30,53175;421,05960
1,56000;-30,52846;430,96719
1,60000;-30,52511;439,09345
1,64000;-30,52176;448,32239
1,68000;-30,51847;458,81285
1,72000;-30,51495;468,24082
1,76000;-30,51166;479,02497
1,80000;-30,50837;486,81819
1,84000;-30,50508;494,65438
1,88000;-30,50179;503,22004
1,92000;-30,49839;511,59463
1,96000;-30,49516;519,54882
2,00000;-30,49175;528,71429
2,04000;-30,48840;537,35841
2,08000;-30,48541;544,27516
2,12000;-30,48170;553,74498
2,16000;-30,47836;561,04921
2,20000;-30,47513;565,98131
2,24000;-30,47178;571,82615
2,28000;-30,46837;578,18615
2,32000;-30,46514;583,26488
2,36000;-30,46179;587,45132
2,40000;-30,45845;591,60581
2,44000;-30,45516;595,69939
2,48000;-30,45181;598,12935
2,52000;-30,44846;600,83880
2,56000;-30,44511;604,82896
2,60000;-30,44176;605,54757
2,64000;-30,43842;605,38566
2,68000;-30,43519;603,32161
2,72000;-30,43178;602,88864
2,76000;-30,42843;601,77217
2,80000;-30,42514;599,70976
2,84000;-30,42174;600,54432
2,88000;-30,41833;606,86856
2,92000;-30,41504;610,68567
2,96000;-30,41181;614,59113
3,00000;-30,40846;621,06638
3,04000;-30,40505;624,72220
3,08000;-30,40183;625,94046
3,12000;-30,39866;625,93310
3,16000;-30,39495;625,91783
3,20000;-30,39178;618,90553
3,24000;-30,38843;611,85653
3,28000;-30,38508;605,78613
3,32000;-30,38180;598,94021
3,36000;-30,37845;593,56480
3,40000;-30,37510;587,10533
3,44000;-30,37169;583,52589
3,48000;-30,36840;578,64250
3,52000;-30,36506;572,69800
3,56000;-30,36177;570,30129
3,60000;-30,35842;572,68199
3,64000;-30,35507;575,33430
3,68000;-30,35178;576,46432
3,72000;-30,34843;578,37083
3,76000;-30,34509;579,17563
3,80000;-30,34180;579,21978
3,84000;-30,33845;578,89163
3,88000;-30,33510;579,03794
3,92000;-30,33175;578,44338
3,96000;-30,32852;577,74791
4,00000;-30,32511;577,55774
4,04000;-30,32171;576,41049
4,08000;-30,31848;573,58360
4,12000;-30,31507;570,33310
4,16000;-30,31166;568,03352
4,20000;-30,30849;571,10586
4,24000;-30,30509;580,41238
4,28000;-30,30174;590,45698
4,32000;-30,29845;599,91130
4,36000;-30,29528;612,77607
4,40000;-30,29175;632,15131
4,44000;-30,28852;652,87040
4,48000;-30,28518;671,93164
4,52000;-30,28189;691,50524
4,56000;-30,27848;713,30736
4,60000;-30,27513;731,10280
4,64000;-30,27184;748,04146
4,68000;-30,26849;766,64803
4,72000;-30,26515;784,84295
4,76000;-30,26180;802,37584
4,80000;-30,25851;819,95456
4,84000;-30,25510;839,16681
4,88000;-30,25181;856,37076
4,92000;-30,24847;873,26029
4,96000;-30,24524;890,00780
5,00000;-30,24183;907,77595
5,04000;-30,23848;927,29405
5,08000;-30,23525;945,53744
5,12000;-30,23184;965,13517
5,16000;-30,22850;985,35018
5,20000;-30,22521;1003,47875
5,24000;-30,22180;1021,68368
5,28000;-30,21845;1040,72606
5,32000;-30,21516;1059,61142
5,36000;-30,21187;1078,04472
5,40000;-30,20847;1097,24980
5,44000;-30,20518;1116,77432
5,48000;-30,20183;1134,67034
5,52000;-30,19848;1153,01106
5,56000;-30,19513;1172,26327
5,60000;-30,19179;1190,61423
5,64000;-30,18850;1208,08091
5,68000;-30,18515;1225,81236
5,72000;-30,18180;1244,19704
5,76000;-30,17845;1262,02917
5,80000;-30,17522;1278,32927
5,84000;-30,17175;1297,06487
5,88000;-30,16841;1315,09500
5,92000;-30,16500;1330,56957
5,96000;-30,16177;1346,01314
6,00000;-30,15842;1362,83683
6,04000;-30,15507;1380,05214
6,08000;-30,15191;1397,62275
6,12000;-30,14838;1416,41460
6,16000;-30,14503;1433,41888
6,20000;-30,14174;1448,70440
6,24000;-30,13845;1463,06055
6,28000;-30,13510;1479,67758
6,32000;-30,13182;1496,71882
6,36000;-30,12847;1511,72411
6,40000;-30,12494;1529,51470
6,44000;-30,12171;1549,08150
6,48000;-30,11836;1562,43881
6,52000;-30,11514;1577,03888
6,56000;-30,11178;1593,34354
6,60000;-30,10850;1608,76736
6,64000;-30,10509;1624,56818
6,68000;-30,10180;1639,19218
6,72000;-30,09833;1656,20837
6,76000;-30,09498;1675,14794
6,80000;-30,09170;1688,70036
6,84000;-30,08847;1702,63089
6,88000;-30,08506;1718,50603
6,92000;-30,08171;1733,95034
6,96000;-30,07848;1747,63314
7,00000;-30,07513;1763,68766
7,04000;-30,07167;1780,78078
7,08000;-30,06850;1794,78247
7,12000;-30,06515;1808,89759
7,16000;-30,06180;1826,13004
7,20000;-30,05851;1840,63688
7,24000;-30,05529;1853,87973
7,28000;-30,05176;1868,60133
7,32000;-30,04847;1884,38799
7,36000;-30,04512;1896,59726
7,40000;-30,04183;1910,13403
7,44000;-30,03848;1924,01223
7,48000;-30,03508;1936,73596
7,52000;-30,03173;1949,43193
7,56000;-30,02844;1960,57372
7,60000;-30,02509;1973,02531
7,64000;-30,02174;1985,60767
7,68000;-30,01845;1996,99849
7,72000;-30,01517;2007,39186
7,76000;-30,01176;2021,16799
7,80000;-30,00847;2032,33622
7,84000;-30,00512;2041,43431
7,88000;-30,00183;2051,79378
7,92000;-29,99842;2062,60942
7,96000;-29,99514;2071,44003
8,00000;-29,99185;2078,97853
8,04000;-29,98844;2088,28431
8,08000;-29,98509;2100,16612
8,12000;-29,98174;2106,54922
8,16000;-29,97840;2115,77918
8,20000;-29,97505;2125,47369
8,24000;-29,97176;2131,30303
8,28000;-29,96847;2138,60776
8,32000;-29,96518;2147,52704
8,36000;-29,96166;2157,40688
8,40000;-29,95843;2166,70875
8,44000;-29,95508;2172,92923
8,48000;-29,95173;2178,86809
8,52000;-29,94844;2184,75200
8,56000;-29,94515;2191,86433
8,60000;-29,94180;2199,07816
8,64000;-29,93846;2206,93033
8,68000;-29,93505;2214,90040
8,72000;-29,93176;2221,60667
8,76000;-29,92829;2232,20643
8,80000;-29,92500;2241,45148
8,84000;-29,92178;2244,83572
8,88000;-29,91843;2250,92713
8,92000;-29,91508;2257,70622
8,96000;-29,91185;2264,21375
9,00000;-29,90850;2271,44621
9,04000;-29,90515;2279,46583
9,08000;-29,90181;2288,90274
9,12000;-29,89846;2293,72252
9,16000;-29,89505;2300,04992
9,20000;-29,89176;2307,59308
9,24000;-29,88841;2313,26874
9,28000;-29,88506;2320,11341
9,32000;-29,88172;2327,66476
9,36000;-29,87837;2336,34878
9,40000;-29,87508;2340,40096
9,44000;-29,87173;2345,93041
9,48000;-29,86844;2352,50182
9,52000;-29,86510;2359,41932
9,56000;-29,86181;2365,76889
9,60000;-29,85858;2372,36414
9,64000;-29,85505;2380,93697
9,68000;-29,85176;2388,08729
9,72000;-29,84847;2392,78022
9,76000;-29,84513;2399,59527
9,80000;-29,84172;2407,24999
9,84000;-29,83849;2413,55021
9,88000;-29,83526;2419,09549
9,92000;-29,83173;2427,42170
9,96000;-29,82850;2433,53117
10,00000;-29,82516;2439,60433
10,04000;-29,82175;2446,64457
10,08000;-29,81846;2452,88815
10,12000;-29,81517;2458,60275
10,16000;-29,81182;2465,18143
10,20000;-29,80847;2473,04309
10,24000;-29,80518;2477,96141
10,28000;-29,80184;2484,06455
10,32000;-29,79849;2492,54163
10,36000;-29,79514;2498,59989
10,40000;-29,79179;2505,47957
10,44000;-29,78850;2511,09656
10,48000;-29,78522;2516,71374
10,52000;-29,78181;2522,72468
10,56000;-29,77852;2528,13753
10,60000;-29,77523;2534,00113
10,64000;-29,77176;2540,98736
10,68000;-29,76847;2547,52710
10,72000;-29,76525;2552,47727
10,76000;-29,76178;2559,97088
10,80000;-29,75843;2567,41848
10,84000;-29,75514;2573,40278
10,88000;-29,75179;2580,01368
10,92000;-29,74838;2586,97364
10,96000;-29,74516;2592,44796
11,00000;-29,74187;2598,65690
11,04000;-29,73846;2605,72676
11,08000;-29,73523;2612,32313
11,12000;-29,73188;2618,59298
11,16000;-29,72848;2625,79098
11,20000;-29,72519;2632,69674
11,24000;-29,72184;2638,26475
11,28000;-29,71849;2644,96654
11,32000;-29,71514;2653,53434
11,36000;-29,71179;2660,70757
11,40000;-29,70851;2667,67535
11,44000;-29,70510;2674,82232
11,48000;-29,70175;2681,87132
11,52000;-29,69840;2688,62527
11,56000;-29,69511;2693,87662
11,60000;-29,69182;2699,65455
11,64000;-29,68848;2707,24818
11,68000;-29,68513;2714,84610
11,72000;-29,68184;2722,66697
11,76000;-29,67843;2729,04262
11,80000;-29,67508;2735,29757
11,84000;-29,67186;2741,36439
11,88000;-29,66845;2747,92258
11,92000;-29,66510;2755,37353
11,96000;-29,66181;2761,94476
12,00000;-29,65846;2769,31562
12,04000;-29,65505;2777,10315
12,08000;-29,65177;2783,82841
12,12000;-29,64842;2789,80434
12,16000;-29,64507;2798,54052
12,20000;-29,64172;2808,45333
12,24000;-29,63843;2817,71943
12,28000;-29,63514;2827,74121
12,32000;-29,63180;2839,72565
12,36000;-29,62845;2850,73500
12,40000;-29,62516;2860,91026
12,44000;-29,62181;2872,43202
12,48000;-29,61846;2883,83067
12,52000;-29,61518;2894,81990
12,56000;-29,61183;2905,99857
12,60000;-29,60854;2917,75558
12,64000;-29,60513;2929,47553
12,68000;-29,60178;2939,03630
12,72000;-29,59849;2948,83717
12,76000;-29,59509;2959,36111
12,80000;-29,59180;2969,16980
12,84000;-29,58851;2979,31656
12,88000;-29,58516;2990,67292
12,92000;-29,58181;3001,53419
12,96000;-29,57852;3012,34182
13,00000;-29,57518;3021,60122
13,04000;-29,57183;3031,14206
13,08000;-29,56848;3042,94191
13,12000;-29,56519;3051,48959
13,16000;-29,56184;3061,46052
13,20000;-29,55850;3074,37666
13,24000;-29,55509;3083,66213
13,28000;-29,55180;3094,02775
13,32000;-29,54839;3104,81768
13,36000;-29,54510;3115,10786
13,40000;-29,54181;3124,76307
13,44000;-29,53846;3135,31086
13,48000;-29,53512;3144,78911
13,52000;-29,53177;3156,05253
13,56000;-29,52848;3166,02848
13,60000;-29,52513;3176,33636
13,64000;-29,52172;3186,68820
13,68000;-29,51843;3197,50980
13,72000;-29,51515;3207,19853
13,76000;-29,51174;3219,03564
13,80000;-29,50839;3231,58354
13,84000;-29,50516;3240,63189
13,88000;-29,50175;3250,69129
13,92000;-29,49829;3261,19997
13,96000;-29,49506;3272,03460
14,00000;-29,49177;3281,07439
14,04000;-29,48836;3292,24430
14,08000;-29,48507;3303,53156
14,12000;-29,48178;3312,08892
14,16000;-29,47838;3322,91909
14,20000;-29,47503;3333,65761
14,24000;-29,47174;3342,51486
14,28000;-29,46845;3352,04490
14,32000;-29,46504;3363,75795
14,36000;-29,46169;3373,47277
14,40000;-29,45835;3382,54608
14,44000;-29,45506;3392,26462
14,48000;-29,45171;3402,09939
14,52000;-29,44836;3412,51381
14,56000;-29,44507;3422,91370
14,60000;-29,44178;3434,26242
14,64000;-29,43838;3444,87540
14,68000;-29,43503;3455,78156
14,72000;-29,43180;3465,96092
14,76000;-29,42839;3476,94494
14,80000;-29,42504;3488,21506
14,84000;-29,42181;3498,32326
14,88000;-29,41847;3508,07086
14,92000;-29,41506;3519,59094
14,96000;-29,41177;3529,99307
15,00000;-29,40848;3538,70131
15,04000;-29,40507;3551,51892
15,08000;-29,40173;3563,49014
15,12000;-29,39850;3572,10115
15,16000;-29,39515;3581,83794
15,20000;-29,39174;3594,52739
15,24000;-29,38845;3605,83737
15,28000;-29,38516;3615,13011
15,32000;-29,38176;3626,38235
15,36000;-29,37847;3637,55114
15,40000;-29,37512;3646,49221
15,44000;-29,37183;3656,80717
15,48000;-29,36842;3671,77986
15,52000;-29,36508;3681,30766
15,56000;-29,36173;3690,65143
15,60000;-29,35850;3699,78584
15,64000;-29,35515;3708,82079
15,68000;-29,35180;3719,88006
15,72000;-29,34857;3728,73619
15,76000;-29,34534;3737,65491
15,80000;-29,34176;3752,30350
15,84000;-29,33853;3761,40736
15,88000;-29,33524;3767,55036
15,92000;-29,33189;3776,58829
15,96000;-29,32848;3788,19257
16,00000;-29,32520;3797,21262
16,04000;-29,32179;3809,08474
16,08000;-29,31844;3829,61482
16,12000;-29,31509;3842,83997
16,16000;-29,31180;3858,56889
16,20000;-29,30845;3874,76608
16,24000;-29,30511;3891,50642
16,28000;-29,30182;3908,19535
16,32000;-29,29871;3925,84912
16,36000;-29,29512;3946,78041
16,40000;-29,29177;3965,79206
16,44000;-29,28849;3982,37593
16,48000;-29,28520;4001,18120
16,52000;-29,28185;4019,11065
16,56000;-29,27844;4035,66509
16,60000;-29,27515;4053,88139
16,64000;-29,27174;4071,96581
16,68000;-29,26833;4089,76078
16,72000;-29,26517;4107,48385
16,76000;-29,26182;4122,98962
16,80000;-29,25871;4140,74808
16,84000;-29,25506;4162,51086
16,88000;-29,25177;4179,65986
16,92000;-29,24836;4196,93999
16,96000;-29,24508;4215,11941
17,00000;-29,24179;4231,15753
17,04000;-29,23844;4248,13963
17,08000;-29,23527;4266,17041
17,12000;-29,23175;4285,75054
17,16000;-29,22846;4302,39066
17,20000;-29,22505;4319,25468
17,24000;-29,22170;4332,78047
17,28000;-29,21841;4350,00323
17,32000;-29,21506;4368,33203
17,36000;-29,21177;4387,07061
17,40000;-29,20843;4404,92220
17,44000;-29,20514;4421,82571
17,48000;-29,20179;4440,98189
17,52000;-29,19838;4461,96645
17,56000;-29,19509;4478,38232
17,60000;-29,19186;4494,58994
17,64000;-29,18846;4512,73024
17,68000;-29,18511;4531,28330
17,72000;-29,18188;4548,84432
17,76000;-29,17853;4565,61781
17,80000;-29,17506;4584,54154
17,84000;-29,17178;4603,73648
17,88000;-29,16849;4618,71102
17,92000;-29,16514;4637,90819
17,96000;-29,16179;4656,34018
18,00000;-29,15856;4672,56904
18,04000;-29,15521;4690,29732
18,08000;-29,15181;4709,44270
18,12000;-29,14852;4727,53942
18,16000;-29,14523;4743,39761
18,20000;-29,14182;4761,01302
18,24000;-29,13853;4778,67573
18,28000;-29,13518;4795,80052
18,32000;-29,13184;4812,78636
18,36000;-29,12849;4831,06561
18,40000;-29,12520;4848,92838
18,44000;-29,12173;4866,71925
18,48000;-29,11850;4885,82253
18,52000;-29,11516;4903,21144
18,56000;-29,11180;4921,15170
18,60000;-29,10858;4940,18719
18,64000;-29,10517;4958,09391
18,68000;-29,10182;4977,39427
18,72000;-29,09859;4995,05587
18,76000;-29,09519;5013,33773
18,80000;-29,09184;5032,52558
18,84000;-29,08861;5051,32191
18,88000;-29,08514;5072,53520
18,92000;-29,08179;5091,97973
18,96000;-29,07844;5110,76152
19,00000;-29,07516;5128,35421
19,04000;-29,07181;5148,54789
19,08000;-29,06846;5167,65416
19,12000;-29,06517;5186,17444
19,16000;-29,06188;5204,83553
19,20000;-29,05841;5226,75738
19,24000;-29,05507;5244,82355
19,28000;-29,05178;5263,28646
19,32000;-29,04843;5281,26694
19,36000;-29,04514;5300,43319
19,40000;-29,04185;5318,62453
19,44000;-29,03851;5337,05018
19,48000;-29,03516;5357,46217
19,52000;-29,03175;5376,29575
19,56000;-29,02846;5394,71395
19,60000;-29,02517;5412,72201
19,64000;-29,02176;5431,55782
19,68000;-29,01841;5450,53221
19,72000;-29,01531;5468,96532
19,76000;-29,01178;5488,71830
19,80000;-29,00843;5508,56628
19,84000;-29,00508;5528,07525
19,88000;-29,00179;5545,41238
19,92000;-28,99839;5564,93811
19,96000;-28,99504;5585,27671
20,00000;-28,99187;5603,14842
20,04000;-28,98852;5621,64746
20,08000;-28,98505;5643,45866
20,12000;-28,98176;5661,99049
20,16000;-28,97848;5679,49042
20,20000;-28,97507;5699,35702
20,24000;-28,97178;5718,99824
20,28000;-28,96843;5737,12327
20,32000;-28,96514;5755,53514
20,36000;-28,96185;5775,78060
20,40000;-28,95857;5794,46517
20,44000;-28,95510;5815,67809
20,48000;-28,95181;5835,74288
20,52000;-28,94840;5854,47103
20,56000;-28,94505;5873,51359
20,60000;-28,94182;5892,53083
20,64000;-28,93848;5912,28679
20,68000;-28,93513;5931,70635
20,72000;-28,93172;5951,66869
20,76000;-28,92843;5973,20944
20,80000;-28,92508;5990,57414
20,84000;-28,92180;6010,12893
20,88000;-28,91851;6027,17884
20,92000;-28,91516;6045,73600
20,96000;-28,91181;6066,29215
21,00000;-28,90846;6084,79939
21,04000;-28,90541;6102,37010
21,08000;-28,90177;6123,91308
21,12000;-28,89848;6143,58932
21,16000;-28,89513;6160,54237
21,20000;-28,89178;6178,17827
21,24000;-28,88849;6198,04412
21,28000;-28,88508;6215,89161
21,32000;-28,88180;6233,59196
21,36000;-28,87845;6252,30595
21,40000;-28,87510;6272,82634
21,44000;-28,87181;6289,54619
21,48000;-28,86852;6307,96030
21,52000;-28,86512;6326,65679
21,56000;-28,86177;6344,33404
21,60000;-28,85854;6362,60957
21,64000;-28,85507;6382,73507
21,68000;-28,85172;6401,57312
21,72000;-28,84849;6418,69381
21,76000;-28,84515;6435,56342
21,80000;-28,84168;6454,92151
21,84000;-28,83839;6474,65065
21,88000;-28,83504;6491,00840
21,92000;-28,83175;6507,08899
21,96000;-28,82840;6526,48136
22,00000;-28,82512;6543,27273
22,04000;-28,82183;6559,92180
22,08000;-28,81842;6578,98784
22,12000;-28,81513;6598,56498
22,16000;-28,81178;6615,68493
22,20000;-28,80844;6632,30643
22,24000;-28,80509;6650,13269
22,28000;-28,80180;6667,55736
22,32000;-28,79845;6684,88517
22,36000;-28,79528;6702,04833
22,40000;-28,79175;6720,60773
22,44000;-28,78847;6737,84465
22,48000;-28,78518;6754,02582
22,52000;-28,78177;6772,14116
22,56000;-28,77836;6790,48896
22,60000;-28,77513;6806,73495
22,64000;-28,77190;6822,10177
22,68000;-28,76831;6842,61546
22,72000;-28,76509;6861,11450
22,76000;-28,76180;6875,10744
22,80000;-28,75845;6892,00759
22,84000;-28,75510;6910,19893
22,88000;-28,75181;6925,32957
22,92000;-28,74852;6941,39600
22,96000;-28,74530;6958,93243
23,00000;-28,74171;6978,96630
23,04000;-28,73848;6995,90072
23,08000;-28,73507;7012,53712
23,12000;-28,73179;7028,84197
23,16000;-28,72844;7044,97769
23,20000;-28,72521;7061,22145
23,24000;-28,72174;7079,59458
23,28000;-28,71845;7098,44232
23,32000;-28,71510;7115,04519
23,36000;-28,71188;7131,57803
23,40000;-28,70853;7148,28148
23,44000;-28,70512;7165,16748
23,48000;-28,70189;7180,79358
23,52000;-28,69854;7196,51729
23,56000;-28,69508;7214,31822
23,60000;-28,69179;7233,92665
23,64000;-28,68850;7247,50385
23,68000;-28,68515;7262,90494
23,72000;-28,68186;7278,75903
23,76000;-28,67857;7293,25116
23,80000;-28,67516;7310,17068
23,84000;-28,67175;7327,81887
23,88000;-28,66847;7342,48608
23,92000;-28,66518;7358,60690
23,96000;-28,66171;7378,92762
24,00000;-28,65848;7392,05331
24,04000;-28,65520;7406,94255
24,08000;-28,65179;7424,02226
24,12000;-28,64850;7440,35542
24,16000;-28,64515;7456,24676
24,20000;-28,64180;7472,98151
24,24000;-28,63881;7488,81623
24,28000;-28,63511;7506,92412
24,32000;-28,63182;7524,78614
24,36000;-28,62853;7539,91082
24,40000;-28,62518;7557,01065
24,44000;-28,62177;7573,15531
24,48000;-28,61854;7590,45482
24,52000;-28,61514;7607,88321
24,56000;-28,61179;7624,96591
24,60000;-28,60850;7644,33667
24,64000;-28,60515;7663,42282
24,68000;-28,60180;7681,11721
24,72000;-28,59845;7697,41535
24,76000;-28,59517;7714,25664
24,80000;-28,59176;7731,51591
24,84000;-28,58847;7748,99051
24,88000;-28,58518;7765,43617
24,92000;-28,58183;7781,98466
24,96000;-28,57842;7800,63272
25,00000;-28,57520;7817,22665
25,04000;-28,57185;7833,40260
25,08000;-28,56844;7851,34658
25,12000;-28,56509;7870,48414
25,16000;-28,56180;7887,30234
25,20000;-28,55845;7903,79941
25,24000;-28,55511;7921,51988
25,28000;-28,55176;7939,71717
25,32000;-28,54847;7954,43505
25,36000;-28,54518;7972,12720
25,40000;-28,54177;7990,64636
25,44000;-28,53849;8007,38335
25,48000;-28,53526;8023,66883
25,52000;-28,53185;8040,54514
25,56000;-28,52844;8057,65539
25,60000;-28,52515;8072,35762
25,64000;-28,52186;8085,90353
25,68000;-28,51852;8101,99007
25,72000;-28,51517;8116,97692
25,76000;-28,51188;8130,53474
25,80000;-28,50847;8147,19796
25,84000;-28,50506;8163,18393
25,88000;-28,50177;8176,39828
25,92000;-28,49843;8189,90618
25,96000;-28,49508;8202,13482
26,00000;-28,49179;8216,82811
26,04000;-28,48850;8230,83669
26,08000;-28,48509;8245,10977
26,12000;-28,48180;8260,21880
26,16000;-28,47851;8273,11873
26,20000;-28,47517;8286,24442
26,24000;-28,47188;8301,46447
26,28000;-28,46853;8315,25475
26,32000;-28,46518;8329,71409
26,36000;-28,46190;8344,77395
26,40000;-28,45849;8358,87939
26,44000;-28,45508;8374,12402
26,48000;-28,45179;8387,29814
26,52000;-28,44844;8400,13772
26,56000;-28,44509;8413,69331
26,60000;-28,44186;8427,67656
26,64000;-28,43852;8440,33137
26,68000;-28,43517;8454,80561
26,72000;-28,43182;8468,94681
26,76000;-28,42853;8481,77671
26,80000;-28,42519;8496,87457
26,84000;-28,42178;8510,65218
26,88000;-28,41855;8523,33754
26,92000;-28,41520;8537,06077
26,96000;-28,41179;8552,18172
27,00000;-28,40844;8565,08911
27,04000;-28,40509;8578,00990
27,08000;-28,40169;8592,25690
27,12000;-28,39840;8605,50702
27,16000;-28,39517;8617,44061
27,20000;-28,39176;8630,14609
27,24000;-28,38853;8645,48907
27,28000;-28,38512;8658,88894
27,32000;-28,38184;8672,29328
27,36000;-28,37849;8686,03587
27,40000;-28,37508;8699,52887
27,44000;-28,37179;8711,71802
27,48000;-28,36850;8724,02042
27,52000;-28,36510;8739,93859
27,56000;-28,36175;8753,61115
27,60000;-28,35840;8765,40169
27,64000;-28,35511;8778,80976
27,68000;-28,35170;8792,34076
27,72000;-28,34835;8805,77713
27,76000;-28,34513;8817,53489
27,80000;-28,34178;8831,37509
27,84000;-28,33843;8845,29501
27,88000;-28,33514;8858,11299
27,92000;-28,33179;8870,19411
27,96000;-28,32839;8884,70858
28,00000;-28,32510;8897,62640
28,04000;-28,32181;8908,69647
28,08000;-28,31846;8922,33700
28,12000;-28,31517;8936,65627
28,16000;-28,31176;8949,20602
28,20000;-28,30847;8960,32602
28,24000;-28,30513;8973,77804
28,28000;-28,30172;8987,62718
28,32000;-28,29843;8999,70010
28,36000;-28,29514;9011,21274
28,40000;-28,29179;9024,64688
28,44000;-28,28845;9038,01993
28,48000;-28,28516;9049,76800
28,52000;-28,28181;9061,80814
28,56000;-28,27840;9075,74221
28,60000;-28,27505;9088,20182
28,64000;-28,27182;9098,74961
28,68000;-28,26848;9111,61155
28,72000;-28,26507;9125,65067
28,76000;-28,26178;9135,80135
28,80000;-28,25843;9147,18360
28,84000;-28,25502;9160,59539
28,88000;-28,25174;9172,26672
28,92000;-28,24851;9183,32413
28,96000;-28,24516;9196,04823
29,00000;-28,24181;9209,25587
29,04000;-28,23846;9219,35141
29,08000;-28,23511;9231,26265
29,12000;-28,23183;9244,93000
29,16000;-28,22842;9256,75035
29,20000;-28,22513;9267,86661
29,24000;-28,22184;9279,71900
29,28000;-28,21843;9290,63410
29,32000;-28,21514;9302,31214
29,36000;-28,21180;9313,63702
29,40000;-28,20839;9326,30524
29,44000;-28,20510;9339,31917
29,48000;-28,20181;9349,77680
29,52000;-28,19852;9360,20985
29,56000;-28,19511;9372,48692
29,60000;-28,19177;9383,84980
29,64000;-28,18860;9394,36406
29,68000;-28,18513;9407,70283
29,72000;-28,18172;9420,11476
29,76000;-28,17849;9430,24904
29,80000;-28,17509;9442,47991
29,84000;-28,17168;9458,71994
29,88000;-28,16839;9467,67107
29,92000;-28,16510;9477,23612
29,96000;-28,16175;9487,16849
30,00000;-28,15846;9498,30115
30,04000;-28,15512;9510,23325
30,08000;-28,15177;9520,28036
30,12000;-28,14848;9532,16925
30,16000;-28,14501;9544,84120
30,20000;-28,14172;9557,14509
30,24000;-28,13849;9566,10814
30,28000;-28,13509;9575,83785
30,32000;-28,13174;9587,28716
30,36000;-28,12881;9597,53022
30,40000;-28,12498;9611,24972
30,44000;-28,12169;9623,79500
30,48000;-28,11834;9632,25439
30,52000;-28,11512;9642,25233
30,56000;-28,11177;9652,02898
30,60000;-28,10842;9662,40242
30,64000;-28,10525;9672,47039
30,68000;-28,10172;9685,11626
30,72000;-28,09837;9699,52941
30,76000;-28,09515;9708,07672
30,80000;-28,09186;9717,08074
30,84000;-28,08845;9729,23115
30,88000;-28,08516;9739,51221
30,92000;-28,08181;9747,86654
30,96000;-28,07847;9759,39408
31,00000;-28,07506;9772,89081
31,04000;-28,07171;9784,87208
31,08000;-28,06836;9793,88654
31,12000;-28,06513;9802,28558
31,16000;-28,06172;9812,62326
31,20000;-28,05843;9822,24792
31,24000;-28,05521;9832,48800
31,28000;-28,05180;9842,54479
31,32000;-28,04839;9854,87849
31,36000;-28,04516;9868,07644
31,40000;-28,04181;9875,42644
31,44000;-28,03846;9885,52570
31,48000;-28,03518;9894,59157
31,52000;-28,03189;9903,51886
31,56000;-28,02848;9914,77594
31,60000;-28,02513;9925,32223
31,64000;-28,02190;9933,53128
31,68000;-28,01856;9944,44191
31,72000;-28,01509;9955,43450
31,76000;-28,01180;9966,78844
31,80000;-28,00851;9975,09137
31,84000;-28,00510;9985,33964
31,88000;-28,00187;9995,21092
31,92000;-27,99853;10005,21034
31,96000;-27,99518;10015,16283
32,00000;-27,99183;10026,33423
32,04000;-27,98848;10035,51483
32,08000;-27,98531;10045,27062
32,12000;-27,98178;10057,55141
32,16000;-27,97844;10067,32434
32,20000;-27,97515;10075,91113
32,24000;-27,97186;10085,16997
32,28000;-27,96845;10095,19100
32,32000;-27,96510;10105,36179
32,36000;-27,96176;10113,90164
32,40000;-27,95847;10122,45640
32,44000;-27,95512;10133,69188
32,48000;-27,95177;10143,29344
32,52000;-27,94854;10152,05309
32,56000;-27,94513;10162,71561
32,60000;-27,94173;10172,33655
32,64000;-27,93856;10180,53964
32,68000;-27,93515;10189,51908
32,72000;-27,93174;10200,92219
32,76000;-27,92845;10210,68096
32,80000;-27,92516;10218,96452
32,84000;-27,92176;10229,86174
32,88000;-27,91847;10239,47448
32,92000;-27,91518;10247,01074
32,96000;-27,91183;10256,77323
33,00000;-27,90848;10267,38584
33,04000;-27,90514;10276,10525
33,08000;-27,90179;10284,77252
33,12000;-27,89844;10296,37828
33,16000;-27,89497;10300,90675
33,20000;-27,89174;10307,77320
33,24000;-27,88839;10318,34707
33,28000;-27,88510;10328,51636
33,32000;-27,88176;10338,72664
33,36000;-27,87847;10346,92228
33,40000;-27,87518;10355,09109
33,44000;-27,87177;10366,13137
33,48000;-27,86848;10375,17563
33,52000;-27,86519;10382,72157
33,56000;-27,86179;10393,07937
33,60000;-27,85844;10403,17267
33,64000;-27,85515;10411,04198
33,68000;-27,85180;10418,51938
33,72000;-27,84845;10428,40630
33,76000;-27,84522;10437,17191
33,80000;-27,84188;10444,45187
33,84000;-27,83847;10455,05479
33,88000;-27,83518;10464,07968
33,92000;-27,83183;10471,67182
33,96000;-27,82842;10481,24656
34,00000;-27,82514;10490,92859
34,04000;-27,82179;10497,61996
34,08000;-27,81856;10506,28200
34,12000;-27,81515;10514,99173
34,16000;-27,81186;10522,35663
34,20000;-27,80851;10530,22593
34,24000;-27,80517;10538,98260
34,28000;-27,80182;10547,83463
34,32000;-27,79841;10556,67251
34,36000;-27,79512;10563,14260
34,40000;-27,79183;10572,12651
34,44000;-27,78843;10581,61557
34,48000;-27,78508;10589,08030
34,52000;-27,78179;10596,23659
34,56000;-27,77838;10604,46724
34,60000;-27,77503;10611,97892
34,64000;-27,77180;10618,88561
34,68000;-27,76846;10626,14694
34,72000;-27,76511;10633,76889
34,76000;-27,76182;10641,90120
34,80000;-27,75841;10652,87590
34,84000;-27,75506;10660,33617
34,88000;-27,75178;10666,71908
34,92000;-27,74849;10672,21314
34,96000;-27,74532;10678,07525
35,00000;-27,74173;10687,75132
35,04000;-27,73838;10693,31467
35,08000;-27,73503;10695,98198
35,12000;-27,73169;10700,28469
35,16000;-27,72834;10704,77143
35,20000;-27,72529;10707,55571
35,24000;-27,72170;10709,51521
35,28000;-27,71841;10708,69491
35,32000;-27,71506;10685,28295
35,36000;-27,71112;6760,17776
35,37800;-27,70873;2021,07858