File: SU - Suspension/05 - Essais/Excels essais Optimus/Collage_alu_alu_31_01_19/collage7.is_tens_RawData/Specimen_RawData_1.csv
Temps;Déplacement;Charge
(sec);(mm);(N)
0,00000;-38,97612;63,69849
0,04000;-38,97546;64,34874
0,08000;-38,97289;74,11269
0,12000;-38,96954;94,90416
0,16000;-38,96578;122,17328
0,20000;-38,96195;150,71462
0,24000;-38,95812;178,09210
0,28000;-38,95441;75,03201
0,32000;-38,95065;52,08675
0,36000;-38,94706;84,17536
0,40000;-38,94359;111,03131
0,44000;-38,94006;138,37379
0,48000;-38,93659;166,04594
0,52000;-38,93325;192,15826
0,56000;-38,92978;216,87469
0,60000;-38,92637;240,73494
0,64000;-38,92308;262,29073
0,68000;-38,91974;283,56430
0,72000;-38,91639;305,19343
0,76000;-38,91304;327,24361
0,80000;-38,90969;348,72186
0,84000;-38,90634;369,68277
0,88000;-38,90306;391,25658
0,92000;-38,89971;411,63750
0,96000;-38,89636;431,58997
1,00000;-38,89301;451,69573
1,04000;-38,88967;471,99442
1,08000;-38,88631;491,24407
1,12000;-38,88297;511,34634
1,16000;-38,87968;531,73862
1,20000;-38,87633;549,48791
1,24000;-38,87298;568,77392
1,28000;-38,86969;587,49658
1,32000;-38,86634;606,72425
1,36000;-38,86294;626,87816
1,40000;-38,85965;645,85209
1,44000;-38,85636;663,75374
1,48000;-38,85307;682,74289
1,52000;-38,84972;701,98178
1,56000;-38,84638;719,42895
1,60000;-38,84309;737,19909
1,64000;-38,83968;755,87281
1,68000;-38,83633;775,28893
1,72000;-38,83298;793,02788
1,76000;-38,82969;809,21585
1,80000;-38,82647;826,85985
1,84000;-38,82306;844,28638
1,88000;-38,81971;860,26397
1,92000;-38,81666;874,81821
1,96000;-38,81295;893,90464
2,00000;-38,80966;909,26439
2,04000;-38,80643;922,53387
2,08000;-38,80309;938,62945
2,12000;-38,79974;954,41435
2,16000;-38,79645;970,14876
2,20000;-38,79310;985,36843
2,24000;-38,78963;1002,07198
2,28000;-38,78641;1017,20989
2,32000;-38,78312;1031,64138
2,36000;-38,77971;1047,86158
2,40000;-38,77636;1063,71278
2,44000;-38,77307;1076,75623
2,48000;-38,76979;1090,41082
2,52000;-38,76632;1107,10645
2,56000;-38,76303;1122,11686
2,60000;-38,75974;1135,13106
2,64000;-38,75639;1150,05579
2,68000;-38,75304;1163,49515
2,72000;-38,74975;1175,37947
2,76000;-38,74641;1189,40240
2,80000;-38,74300;1204,90026
2,84000;-38,73965;1218,31885
2,88000;-38,73636;1230,71456
2,92000;-38,73307;1243,61226
2,96000;-38,72973;1257,00757
3,00000;-38,72638;1269,65037
3,04000;-38,72309;1282,06033
3,08000;-38,71968;1295,94309
3,12000;-38,71633;1310,21701
3,16000;-38,71311;1321,36894
3,20000;-38,70970;1333,42491
3,24000;-38,70629;1346,38697
3,28000;-38,70300;1359,06702
3,32000;-38,69971;1369,36242
3,36000;-38,69630;1381,34928
3,40000;-38,69295;1394,24298
3,44000;-38,68967;1404,49116
3,48000;-38,68632;1415,63071
3,52000;-38,68297;1427,67578
3,56000;-38,67968;1438,09905
3,60000;-38,67633;1449,97230
3,64000;-38,67293;1460,49811
3,68000;-38,66964;1471,39262
3,72000;-38,66641;1480,62510
3,76000;-38,66300;1491,40880
3,80000;-38,65971;1501,92529
3,84000;-38,65642;1511,35325
3,88000;-38,65296;1522,26230
3,92000;-38,64967;1533,19743
3,96000;-38,64626;1542,04834
4,00000;-38,64291;1551,56925
4,04000;-38,63974;1560,66623
4,08000;-38,63633;1570,00963
4,12000;-38,63298;1578,80951
4,16000;-38,62976;1588,26616
4,20000;-38,62641;1597,79489
4,24000;-38,62306;1606,31910
4,28000;-38,61971;1614,78072
4,32000;-38,61642;1623,05310
4,36000;-38,61308;1631,32604
4,40000;-38,60973;1639,48312
4,44000;-38,60644;1646,34790
4,48000;-38,60309;1654,41576
4,52000;-38,59968;1662,52442
4,56000;-38,59639;1669,46184
4,60000;-38,59305;1677,71615
4,64000;-38,58964;1684,88510
4,68000;-38,58635;1691,89032
4,72000;-38,58300;1699,51487
4,76000;-38,57971;1706,49681
4,80000;-38,57643;1714,75504
4,84000;-38,57302;1721,69693
4,88000;-38,56973;1729,37941
4,92000;-38,56638;1738,01966
4,96000;-38,56303;1745,53022
5,00000;-38,55969;1752,47304
5,04000;-38,55646;1759,74220
5,08000;-38,55305;1766,61257
5,12000;-38,54970;1774,40736
5,16000;-38,54641;1781,69534
5,20000;-38,54306;1788,25967
5,24000;-38,53959;1798,26636
5,28000;-38,53631;1804,91600
5,32000;-38,53302;1810,67418
5,36000;-38,52967;1818,02567
5,40000;-38,52632;1825,57926
5,44000;-38,52309;1832,51649
5,48000;-38,51975;1840,08814
5,52000;-38,51628;1848,26981
5,56000;-38,51299;1855,90908
5,60000;-38,50976;1862,66471
5,64000;-38,50629;1869,69731
5,68000;-38,50301;1878,81701
5,72000;-38,49966;1884,74283
5,76000;-38,49631;1891,02814
5,80000;-38,49302;1898,36174
5,84000;-38,48991;1904,95998
5,88000;-38,48620;1913,65760
5,92000;-38,48298;1921,00313
5,96000;-38,47969;1926,56759
6,00000;-38,47628;1932,55115
6,04000;-38,47305;1938,37732
6,08000;-38,46970;1943,97196
6,12000;-38,46623;1950,98966
6,16000;-38,46300;1959,80035
6,20000;-38,45972;1963,58766
6,24000;-38,45637;1970,22147
6,28000;-38,45302;1976,54832
6,32000;-38,44973;1982,15805
6,36000;-38,44650;1987,22575
6,40000;-38,44292;1994,04322
6,44000;-38,43969;1999,80177
6,48000;-38,43640;2004,36562
6,52000;-38,43299;2011,20228
6,56000;-38,42970;2016,81145
6,60000;-38,42635;2023,24595
6,64000;-38,42301;2028,53754
6,68000;-38,41972;2033,27611
6,72000;-38,41631;2040,07085
6,76000;-38,41302;2044,36202
6,80000;-38,40973;2049,72737
6,84000;-38,40632;2056,53682
6,88000;-38,40292;2062,74092
6,92000;-38,39969;2067,69835
6,96000;-38,39640;2073,06948
7,00000;-38,39299;2079,27339
7,04000;-38,38976;2085,58738
7,08000;-38,38653;2089,85563
7,12000;-38,38307;2096,41177
7,16000;-38,37972;2103,38831
7,20000;-38,37649;2108,00134
7,24000;-38,37302;2115,55380
7,28000;-38,36967;2121,63758
7,32000;-38,36632;2127,02509
7,36000;-38,36303;2132,13805
7,40000;-38,35969;2138,03798
7,44000;-38,35634;2144,23742
7,48000;-38,35311;2149,06503
7,52000;-38,34964;2155,48743
7,56000;-38,34636;2161,00328
7,60000;-38,34301;2164,99213
7,64000;-38,33972;2169,26951
7,68000;-38,33637;2175,43244
7,72000;-38,33308;2181,43985
7,76000;-38,32961;2188,75688
7,80000;-38,32638;2193,53922
7,84000;-38,32304;2198,01106
7,88000;-38,31969;2202,71461
7,92000;-38,31640;2208,32173
7,96000;-38,31299;2213,64181
8,00000;-38,30964;2220,00182
8,04000;-38,30635;2226,02282
8,08000;-38,30325;2230,99943
8,12000;-38,29960;2241,80613
8,16000;-38,29631;2249,45210
8,20000;-38,29302;2257,24299
8,24000;-38,28968;2267,69745
8,28000;-38,28633;2277,89748
8,32000;-38,28310;2287,60485
8,36000;-38,27975;2297,22466
8,40000;-38,27628;2309,20948
8,44000;-38,27299;2320,71895
8,48000;-38,26970;2327,96688
8,52000;-38,26630;2336,66133
8,56000;-38,26301;2345,78587
8,60000;-38,25966;2355,75475
8,64000;-38,25631;2364,36855
8,68000;-38,25308;2373,21556
8,72000;-38,24967;2384,04255
8,76000;-38,24633;2391,96345
8,80000;-38,24310;2400,09259
8,84000;-38,23969;2408,72297
8,88000;-38,23634;2418,35527
8,92000;-38,23305;2426,94635
8,96000;-38,22983;2435,03973
9,00000;-38,22630;2444,88493
9,04000;-38,22307;2452,38077
9,08000;-38,21972;2459,99210
9,12000;-38,21649;2468,21474
9,16000;-38,21297;2480,07085
9,20000;-38,20968;2487,31468
9,24000;-38,20633;2495,09308
9,28000;-38,20298;2504,04645
9,32000;-38,19969;2514,99955
9,36000;-38,19640;2525,28936
9,40000;-38,19299;2536,27039
9,44000;-38,18971;2548,23789
9,48000;-38,18636;2559,22955
9,52000;-38,18307;2569,51898
9,56000;-38,17972;2582,01566
9,60000;-38,17637;2594,65519
9,64000;-38,17309;2604,40633
9,68000;-38,16980;2615,88115
9,72000;-38,16639;2628,95729
9,76000;-38,16310;2640,50085
9,80000;-38,15981;2652,65480
9,84000;-38,15640;2665,30327
9,88000;-38,15305;2678,05159
9,92000;-38,14977;2689,70560
9,96000;-38,14642;2700,81814
10,00000;-38,14301;2714,27445
10,04000;-38,13972;2726,27436
10,08000;-38,13643;2736,62023
10,12000;-38,13309;2749,95770
10,16000;-38,12974;2763,00441
10,20000;-38,12645;2774,09647
10,24000;-38,12310;2786,55458
10,28000;-38,11969;2799,57149
10,32000;-38,11641;2811,50751
10,36000;-38,11312;2822,86946
10,40000;-38,10971;2836,01079
10,44000;-38,10642;2849,32889
10,48000;-38,10313;2861,93769
10,52000;-38,09972;2874,20563
10,56000;-38,09643;2887,05993
10,60000;-38,09309;2898,59921
10,64000;-38,08974;2910,47618
10,68000;-38,08645;2923,37909
10,72000;-38,08310;2934,76339
10,76000;-38,07975;2946,21717
10,80000;-38,07647;2959,47865
10,84000;-38,07300;2971,97532
10,88000;-38,06971;2984,59530
10,92000;-38,06642;2996,62556
10,96000;-38,06307;3007,17186
11,00000;-38,05967;3019,24851
11,04000;-38,05632;3025,45149
11,08000;-38,05303;3037,66448
11,12000;-38,04968;3052,32033
11,16000;-38,04633;3065,07517
11,20000;-38,04304;3076,06645
11,24000;-38,03969;3089,08261
11,28000;-38,03628;3101,79517
11,32000;-38,03306;3114,35685
11,36000;-38,02971;3127,09399
11,40000;-38,02630;3140,24873
11,44000;-38,02301;3152,73143
11,48000;-38,01973;3165,03346
11,52000;-38,01632;3176,34009
11,56000;-38,01303;3188,86265
11,60000;-38,00974;3201,05217
11,64000;-38,00639;3213,71704
11,68000;-38,00310;3226,48585
11,72000;-37,99970;3237,90908
11,76000;-37,99635;3250,95616
11,80000;-37,99306;3263,34648
11,84000;-37,98965;3275,94802
11,88000;-37,98630;3288,38751
11,92000;-37,98307;3300,93652
11,96000;-37,97967;3312,20590
12,00000;-37,97632;3326,53746
12,04000;-37,97297;3338,57872
12,08000;-37,96968;3350,08167
12,12000;-37,96633;3362,70481
12,16000;-37,96298;3375,15213
12,20000;-37,95976;3386,40995
12,24000;-37,95641;3398,77345
12,28000;-37,95300;3411,54002
12,32000;-37,94971;3423,99590
12,36000;-37,94637;3435,95892
12,40000;-37,94296;3447,78560
12,44000;-37,93967;3460,07496
12,48000;-37,93638;3471,76157
12,52000;-37,93297;3483,98611
12,56000;-37,92968;3498,46147
12,60000;-37,92633;3510,68974
12,64000;-37,92298;3521,36716
12,68000;-37,91970;3533,16702
12,72000;-37,91629;3544,97880
12,76000;-37,91306;3556,73470
12,80000;-37,90977;3569,50983
12,84000;-37,90649;3580,41897
12,88000;-37,90308;3592,78545
12,92000;-37,89979;3604,52943
12,96000;-37,89644;3616,87019
13,00000;-37,89303;3629,12938
13,04000;-37,88974;3641,32263
13,08000;-37,88640;3652,50520
13,12000;-37,88305;3666,99360
13,16000;-37,87964;3679,29414
13,20000;-37,87641;3690,32659
13,24000;-37,87300;3701,44099
13,28000;-37,86965;3713,73445
13,32000;-37,86637;3725,75745
13,36000;-37,86314;3736,57048
13,40000;-37,85973;3750,35591
13,44000;-37,85644;3762,09579
13,48000;-37,85309;3771,87990
13,52000;-37,84974;3784,36781
13,56000;-37,84646;3797,24912
13,60000;-37,84305;3808,24730
13,64000;-37,83976;3820,34183
13,68000;-37,83641;3832,88786
13,72000;-37,83301;3844,81959
13,76000;-37,82965;3856,80124
13,80000;-37,82636;3868,35672
13,84000;-37,82296;3880,24710
13,88000;-37,81961;3892,38410
13,92000;-37,81638;3903,64602
13,96000;-37,81303;3914,82078
14,00000;-37,80968;3927,92411
14,04000;-37,80633;3940,43177
14,08000;-37,80305;3950,53849
14,12000;-37,79970;3963,29351
14,16000;-37,79635;3976,40057
14,20000;-37,79306;3987,06272
14,24000;-37,78978;3997,93275
14,28000;-37,78625;4011,38850
14,32000;-37,78302;4023,19767
14,36000;-37,77973;4034,73787
14,40000;-37,77632;4045,76883
14,44000;-37,77297;4058,50597
14,48000;-37,76968;4069,70829
14,52000;-37,76640;4081,32263
14,56000;-37,76299;4095,27905
14,60000;-37,75964;4107,55016
14,64000;-37,75629;4118,88771
14,68000;-37,75300;4129,36807
14,72000;-37,74971;4140,71381
14,76000;-37,74631;4153,04676
14,80000;-37,74320;4163,80018
14,84000;-37,73961;4176,58947
14,88000;-37,73626;4190,43340
14,92000;-37,73298;4200,95995
14,96000;-37,72969;4209,74828
15,00000;-37,72634;4222,02684
15,04000;-37,72293;4234,40598
15,08000;-37,71970;4244,15767
15,12000;-37,71641;4255,97467
15,16000;-37,71295;4268,76731
15,20000;-37,70972;4280,20768
15,24000;-37,70679;4289,64496
15,28000;-37,70284;4304,11920
15,32000;-37,69973;4315,58825
15,36000;-37,69638;4325,21105
15,40000;-37,69303;4335,35092
15,44000;-37,68975;4347,30463
15,48000;-37,68640;4358,86979
15,52000;-37,68305;4370,06541
15,56000;-37,67976;4381,63467
15,60000;-37,67641;4391,75665
15,64000;-37,67319;4403,13071
15,68000;-37,66972;4417,81394
15,72000;-37,66637;4428,83857
15,76000;-37,66302;4439,41168
15,80000;-37,65973;4449,89875
15,84000;-37,65645;4460,91741
15,88000;-37,65304;4472,15773
15,92000;-37,64975;4483,13244
15,96000;-37,64646;4493,25666
16,00000;-37,64329;4504,38298
16,04000;-37,63964;4518,98165
16,08000;-37,63635;4529,78425
16,12000;-37,63307;4539,46367
16,16000;-37,62972;4550,22864
16,20000;-37,62643;4559,99039
16,24000;-37,62308;4570,83434
16,28000;-37,61991;4582,82344
16,32000;-37,61633;4597,11775
16,36000;-37,61304;4608,25004
16,40000;-37,60969;4617,60312
16,44000;-37,60640;4628,83189
16,48000;-37,60305;4639,69298
16,52000;-37,59970;4650,40244
16,56000;-37,59636;4661,82642
16,60000;-37,59295;4674,01892
16,64000;-37,58966;4686,10898
16,68000;-37,58637;4696,25294
16,72000;-37,58296;4707,80209
16,76000;-37,57967;4718,97423
16,80000;-37,57633;4729,95974
16,84000;-37,57310;4740,94041
16,88000;-37,56963;4755,74955
16,92000;-37,56634;4767,29907
16,96000;-37,56311;4775,91306
17,00000;-37,55971;4787,48940
17,04000;-37,55630;4800,10957
17,08000;-37,55307;4811,75147
17,12000;-37,54972;4823,58448
17,16000;-37,54631;4836,09550
17,20000;-37,54302;4847,55561
17,24000;-37,53968;4858,02554
17,28000;-37,53633;4868,69030
17,32000;-37,53304;4880,52964
17,36000;-37,52969;4891,80014
17,40000;-37,52640;4901,54251
17,44000;-37,52311;4913,90824
17,48000;-37,51971;4925,32887
17,52000;-37,51648;4935,69709
17,56000;-37,51313;4947,40456
17,60000;-37,50978;4958,69145
17,64000;-37,50637;4970,25698
17,68000;-37,50308;4980,17184
17,72000;-37,49974;4992,22167
17,76000;-37,49633;5005,16966
17,80000;-37,49304;5016,53217
17,84000;-37,48975;5027,85072
17,88000;-37,48634;5040,23172
17,92000;-37,48305;5051,28615
17,96000;-37,47976;5063,87651
18,00000;-37,47642;5075,51879
18,04000;-37,47307;5086,23980
18,08000;-37,46984;5098,97657
18,12000;-37,46643;5110,58159
18,16000;-37,46309;5123,46849
18,20000;-37,45998;5135,28325
18,24000;-37,45639;5149,05043
18,28000;-37,45304;5161,90268
18,32000;-37,44975;5173,70924
18,36000;-37,44640;5183,71724
18,40000;-37,44306;5195,63854
18,44000;-37,43977;5208,19910
18,48000;-37,43642;5219,27886
18,52000;-37,43307;5232,03276
18,56000;-37,42972;5246,15794
18,60000;-37,42637;5256,95086
18,64000;-37,42308;5268,90531
18,68000;-37,41974;5280,49320
18,72000;-37,41639;5292,39960
18,76000;-37,41310;5304,72398
18,80000;-37,40975;5316,66949
18,84000;-37,40647;5328,63960
18,88000;-37,40306;5341,53916
18,92000;-37,39965;5353,44146
18,96000;-37,39642;5364,55438
19,00000;-37,39301;5376,97673
19,04000;-37,38960;5389,26870
19,08000;-37,38644;5399,25732
19,12000;-37,38303;5412,19637
19,16000;-37,37968;5425,27884
19,20000;-37,37639;5436,61751
19,24000;-37,37316;5446,78383
19,28000;-37,36963;5460,81550
19,32000;-37,36640;5471,72725
19,36000;-37,36306;5483,01600
19,40000;-37,35971;5493,80518
19,44000;-37,35636;5506,51625
19,48000;-37,35301;5518,07657
19,52000;-37,34966;5529,24387
19,56000;-37,34632;5541,46059
19,60000;-37,34297;5553,38040
19,64000;-37,33962;5564,69932
19,68000;-37,33633;5575,03253
19,72000;-37,33299;5586,66363
19,76000;-37,32970;5598,48882
19,80000;-37,32629;5610,73460
19,84000;-37,32300;5623,19010
19,88000;-37,31959;5634,33878
19,92000;-37,31630;5645,60294
19,96000;-37,31313;5655,51892
20,00000;-37,30966;5667,13437
20,04000;-37,30631;5680,71008
20,08000;-37,30303;5690,84324
20,12000;-37,29968;5699,30039
20,16000;-37,29633;5711,35767
20,20000;-37,29304;5722,64828
20,24000;-37,28988;5732,78442
20,28000;-37,28635;5745,81251
20,32000;-37,28312;5758,20468
20,36000;-37,27965;5767,41099
20,40000;-37,27636;5777,14853
20,44000;-37,27308;5788,08412
20,48000;-37,26967;5798,88187
20,52000;-37,26638;5809,52540
20,56000;-37,26303;5820,94043
20,60000;-37,25974;5832,33573
20,64000;-37,25639;5842,37874
20,68000;-37,25304;5853,25956
20,72000;-37,24976;5863,83827
20,76000;-37,24641;5874,67216
20,80000;-37,24306;5885,32314
20,84000;-37,23971;5896,37123
20,88000;-37,23636;5909,37473
20,92000;-37,23302;5919,81821
20,96000;-37,22979;5929,38215
21,00000;-37,22638;5939,46949
21,04000;-37,22291;5952,48006
21,08000;-37,21974;5963,03605
21,12000;-37,21645;5972,85256
21,16000;-37,21299;5984,82750
21,20000;-37,20970;5996,03243
21,24000;-37,20635;6005,83777
21,28000;-37,20306;6016,27380
21,32000;-37,19971;6027,82369
21,36000;-37,19636;6037,41780
21,40000;-37,19307;6048,02184
21,44000;-37,18973;6059,03082
21,48000;-37,18638;6071,59771
21,52000;-37,18303;6081,51890
21,56000;-37,17974;6091,55893
21,60000;-37,17634;6102,57275
21,64000;-37,17299;6113,54038
21,68000;-37,16964;6123,44742
21,72000;-37,16635;6133,18235
21,76000;-37,16294;6143,86722
21,80000;-37,15959;6156,16180
21,84000;-37,15636;6166,57324
21,88000;-37,15296;6177,11395
21,92000;-37,14955;6188,87283
21,96000;-37,14638;6198,30452
22,00000;-37,14303;6207,48252
22,04000;-37,13956;6219,61504
22,08000;-37,13633;6232,58241
22,12000;-37,13305;6241,28357
22,16000;-37,12964;6252,26870
22,20000;-37,12635;6262,90217
22,24000;-37,12300;6272,88073
22,28000;-37,11989;6282,54265
22,32000;-37,11631;6295,61245
22,36000;-37,11296;6307,42162
22,40000;-37,10961;6317,03734
22,44000;-37,10632;6326,96077
22,48000;-37,10303;6337,11517
22,52000;-37,09963;6348,31786
22,56000;-37,09634;6357,53497
22,60000;-37,09305;6367,13132
22,64000;-37,08970;6377,17247
22,68000;-37,08629;6388,14718
22,72000;-37,08306;6403,31283
22,76000;-37,07971;6412,62531
22,80000;-37,07631;6421,85360
22,84000;-37,07308;6431,24804
22,88000;-37,06973;6441,64383
22,92000;-37,06632;6452,54627
22,96000;-37,06303;6462,91822
23,00000;-37,05975;6472,14949
23,04000;-37,05622;6483,42818
23,08000;-37,05305;6494,19576
23,12000;-37,04970;6503,21022
23,16000;-37,04635;6512,74994
23,20000;-37,04312;6523,65386
23,24000;-37,03971;6534,28063
23,28000;-37,03643;6544,94911
23,32000;-37,03308;6555,73905
23,36000;-37,02967;6567,48191
23,40000;-37,02638;6578,79338
23,44000;-37,02309;6588,45752
23,48000;-37,01975;6597,47422
23,52000;-37,01640;6607,82531
23,56000;-37,01305;6617,82846
23,60000;-37,00976;6626,20068
23,64000;-37,00641;6637,03904
23,68000;-37,00319;6648,32145
23,72000;-36,99972;6660,82129
23,76000;-36,99637;6670,86095
23,80000;-36,99302;6680,57278
23,84000;-36,98979;6690,92834
23,88000;-36,98638;6700,22368
23,92000;-36,98303;6710,43620
23,96000;-36,97980;6720,42519
24,00000;-36,97646;6730,95807
24,04000;-36,97299;6742,87751
24,08000;-36,96976;6753,46553
24,12000;-36,96641;6762,28106
24,16000;-36,96307;6773,76091
24,20000;-36,95972;6784,07922
24,24000;-36,95637;6793,71357
24,28000;-36,95308;6804,04231
24,32000;-36,94967;6815,15187
24,36000;-36,94639;6825,15353
24,40000;-36,94304;6834,67984
24,44000;-36,93975;6845,58600
24,48000;-36,93640;6856,84904
24,52000;-36,93305;6867,14947
24,56000;-36,92976;6877,40073
24,60000;-36,92641;6887,24592
24,64000;-36,92301;6898,35846
24,68000;-36,91972;6908,29679
24,72000;-36,91649;6918,14870
24,76000;-36,91308;6929,58087
24,80000;-36,90973;6939,83883
24,84000;-36,90651;6949,29659
24,88000;-36,90310;6959,99116
24,92000;-36,89969;6972,65789
24,96000;-36,89640;6982,71096
25,00000;-36,89305;6991,44676
25,04000;-36,88971;7001,71292
25,08000;-36,88636;7013,66812
25,12000;-36,88307;7022,79955
25,16000;-36,87972;7033,65207
25,20000;-36,87637;7044,55003
25,24000;-36,87302;7055,05162
25,28000;-36,86973;7063,90813
25,32000;-36,86639;7074,14970
25,36000;-36,86310;7085,86499
25,40000;-36,85975;7096,26824
25,44000;-36,85640;7107,54320
25,48000;-36,85311;7117,48153
25,52000;-36,84977;7126,87075
25,56000;-36,84642;7137,18086
25,60000;-36,84313;7147,45373
25,64000;-36,83972;7158,34498
25,68000;-36,83637;7169,77119
25,72000;-36,83308;7180,28769
25,76000;-36,82968;7191,52614
25,80000;-36,82639;7200,90568
25,84000;-36,82310;7211,74702
25,88000;-36,81969;7221,43874
25,92000;-36,81634;7233,52730
25,96000;-36,81311;7243,10353
26,00000;-36,80976;7252,52181
26,04000;-36,80635;7264,13503
26,08000;-36,80313;7275,28036
26,12000;-36,79972;7285,04658
26,16000;-36,79637;7295,67632
26,20000;-36,79302;7307,34766
26,24000;-36,78974;7316,86801
26,28000;-36,78639;7327,29658
26,32000;-36,78298;7338,01946
26,36000;-36,77969;7348,75500
26,40000;-36,77635;7359,12994
26,44000;-36,77299;7369,33798
26,48000;-36,76970;7380,02509
26,52000;-36,76642;7389,77343
26,56000;-36,76307;7399,21108
26,60000;-36,75984;7410,60749
26,64000;-36,75643;7422,21400
26,68000;-36,75308;7432,60086
26,72000;-36,74974;7442,98026
26,76000;-36,74639;7453,65769
26,80000;-36,74298;7464,73372
26,84000;-36,73993;7473,40024
26,88000;-36,73640;7484,65359
26,92000;-36,73300;7497,35162
26,96000;-36,72971;7507,58201
27,00000;-36,72636;7516,35805
27,04000;-36,72295;7527,96680
27,08000;-36,71960;7538,32310
27,12000;-36,71638;7546,31460
27,16000;-36,71302;7556,76031
27,20000;-36,70968;7568,35490
27,24000;-36,70639;7577,82310
27,28000;-36,70304;7588,36046
27,32000;-36,69963;7599,30760
27,36000;-36,69628;7611,01469
27,40000;-36,69299;7620,47619
27,44000;-36,68965;7631,16702
27,48000;-36,68636;7642,56716
27,52000;-36,68295;7653,81902
27,56000;-36,67960;7664,02408
27,60000;-36,67644;7673,40213
27,64000;-36,67297;7685,71272
27,68000;-36,66956;7695,83061
27,72000;-36,66639;7703,54718
27,76000;-36,66304;7712,41337
27,80000;-36,65963;7723,83288
27,84000;-36,65640;7734,20781
27,88000;-36,65306;7743,77808
27,92000;-36,64965;7755,15437
27,96000;-36,64636;7765,93462
28,00000;-36,64307;7774,42679
28,04000;-36,63972;7784,03357
28,08000;-36,63637;7796,52074
28,12000;-36,63297;7804,82665
28,16000;-36,62968;7814,49080
28,20000;-36,62627;7823,93739
28,24000;-36,62298;7833,91520
28,28000;-36,61970;7843,60319
28,32000;-36,61635;7853,24126
28,36000;-36,61300;7863,26528
28,40000;-36,60965;7873,84212
28,44000;-36,60630;7884,02781
28,48000;-36,60301;7893,72921
28,52000;-36,59966;7904,19504
28,56000;-36,59632;7914,22874
28,60000;-36,59309;7923,50918
28,64000;-36,58968;7933,85506
28,68000;-36,58633;7943,43650
28,72000;-36,58328;7952,20137
28,76000;-36,57963;7962,42207
28,80000;-36,57635;7973,52940
28,84000;-36,57312;7982,43955
28,88000;-36,56977;7990,90788
28,92000;-36,56636;8002,17912
28,96000;-36,56302;8012,77757
29,00000;-36,55973;8019,57920
29,04000;-36,55632;8030,23130
29,08000;-36,55303;8043,09621
29,12000;-36,54974;8050,23909
29,16000;-36,54663;8057,60399
29,20000;-36,54293;8070,56874
29,24000;-36,53970;8079,91326
29,28000;-36,53635;8087,38247
29,32000;-36,53306;8095,62430
29,36000;-36,52971;8105,62298
29,40000;-36,52636;8116,04187
29,44000;-36,52313;8125,25079
29,48000;-36,51973;8135,27033
29,52000;-36,51638;8145,62291
29,56000;-36,51333;8153,46539
29,60000;-36,50962;8164,76643
29,64000;-36,50633;8174,88134
29,68000;-36,50299;8182,49360
29,72000;-36,49976;8191,59970
29,76000;-36,49641;8199,65601
29,80000;-36,49300;8210,58378
29,84000;-36,48971;8219,58631
29,88000;-36,48636;8227,26414
29,92000;-36,48289;8236,33224
29,96000;-36,47967;8247,69586
30,00000;-36,47638;8254,45354
30,04000;-36,47309;8262,71847
30,08000;-36,46974;8273,08148
30,12000;-36,46639;8281,76290
30,16000;-36,46305;8290,70956
30,20000;-36,45970;8299,49901
30,24000;-36,45635;8308,09027
30,28000;-36,45300;8315,79641
30,32000;-36,44971;8323,11586
30,36000;-36,44637;8332,65930
30,40000;-36,44290;8344,71807
30,44000;-36,43967;8349,60490
30,48000;-36,43638;8356,32682
30,52000;-36,43297;8364,11789
30,56000;-36,42968;8371,76219
30,60000;-36,42645;8378,87600
30,64000;-36,42310;8385,84080
30,68000;-36,41964;8396,06747
30,72000;-36,41635;8406,09670
30,76000;-36,41306;8410,02092
30,80000;-36,40971;8416,37477
30,84000;-36,40643;8423,31201
30,88000;-36,40308;8428,41938
30,92000;-36,39973;8435,78428
30,96000;-36,39638;8443,18494
31,00000;-36,39309;8449,47696
31,04000;-36,38974;8455,35845
31,08000;-36,38634;8464,32969
31,12000;-36,38305;8467,65488
31,16000;-36,37976;8471,50311
31,20000;-36,37635;8476,13737
31,24000;-36,37306;8481,31180
31,28000;-36,36977;8484,03573
31,32000;-36,36637;8487,52931
31,36000;-36,36308;8492,84530
31,40000;-36,35973;8494,76308
31,44000;-36,35644;8495,62511
31,48000;-36,35315;8497,15918
31,52000;-36,34975;8500,09546
31,56000;-36,34634;8501,11246
31,60000;-36,34305;8500,47544
31,64000;-36,33964;8503,40128
31,68000;-36,33635;8502,41929
31,72000;-36,33312;8498,64706
31,76000;-36,32978;8494,39502
31,80000;-36,32643;8489,66986
31,84000;-36,32308;8482,77435
31,88000;-36,31979;8470,88322
31,92000;-36,31644;8454,61115
31,96000;-36,31303;8425,98453
32,00000;-36,30974;8364,39952
32,04000;-36,30568;4415,18202
32,05400;-36,30401;1640,06669