File: SU - Suspension/05 - Essais/Excels essais Optimus/Test_Rotules_31_01_19/K7_4.is_tens_RawData/Specimen_RawData_1.csv
Temps;Déplacement;Charge
(sec);(mm);(N)
0,00000;0,01303;9,27649
0,04000;0,01315;9,40191
0,08000;0,01357;10,43850
0,12000;0,01453;12,42203
0,16000;0,01590;12,54474
0,20000;0,01752;12,40068
0,24000;0,01913;12,11208
0,28000;0,02069;11,97265
0,32000;0,02218;12,54420
0,36000;0,02362;11,86419
0,40000;0,02499;11,69519
0,44000;0,02631;11,62302
0,48000;0,02780;11,92117
0,52000;0,02912;10,96018
0,56000;0,03049;10,98644
0,60000;0,03181;11,08866
0,64000;0,03324;12,08564
0,68000;0,03456;12,07352
0,72000;0,03581;11,80639
0,76000;0,03713;11,39246
0,80000;0,03856;11,75341
0,84000;0,03988;12,06995
0,88000;0,04125;11,47122
0,92000;0,04263;11,46476
0,96000;0,04401;11,27598
1,00000;0,04532;11,47176
1,04000;0,04652;11,66748
1,08000;0,04789;12,46497
1,12000;0,04927;12,51095
1,16000;0,05058;11,93458
1,20000;0,05190;12,29186
1,24000;0,05327;12,75323
1,28000;0,05465;12,50157
1,32000;0,05596;12,33463
1,36000;0,05710;12,94995
1,40000;0,05847;13,34725
1,44000;0,05985;13,14987
1,48000;0,06122;14,12599
1,52000;0,06254;13,43429
1,56000;0,06386;13,33721
1,60000;0,06523;13,16892
1,64000;0,06661;13,06034
1,68000;0,06780;12,54895
1,72000;0,06924;13,02653
1,76000;0,07061;13,03164
1,80000;0,07193;13,15988
1,84000;0,07330;12,83762
1,88000;0,07456;12,96236
1,92000;0,07593;12,78410
1,96000;0,07725;13,18579
2,00000;0,07844;12,90754
2,04000;0,07988;12,26289
2,08000;0,08125;12,11803
2,12000;0,08257;12,42357
2,16000;0,08394;12,69548
2,20000;0,08526;13,28614
2,24000;0,08663;12,38692
2,28000;0,08789;12,31776
2,32000;0,08915;13,12079
2,36000;0,09058;12,71501
2,40000;0,09196;13,48401
2,44000;0,09333;13,83200
2,48000;0,09465;14,01371
2,52000;0,09602;14,06327
2,56000;0,09740;13,16265
2,60000;0,09859;14,01991
2,64000;0,09985;14,65734
2,68000;0,10128;14,61853
2,72000;0,10260;14,51563
2,76000;0,10391;13,85450
2,80000;0,10523;14,51970
2,84000;0,10660;13,99819
2,88000;0,10798;13,29410
2,92000;0,10918;13,40047
2,96000;0,11043;13,92876
3,00000;0,11193;13,85622
3,04000;0,11324;13,35303
3,08000;0,11456;14,02840
3,12000;0,11593;14,48182
3,16000;0,11731;14,78198
3,20000;0,11862;14,22928
3,24000;0,11988;13,17631
3,28000;0,12119;13,84501
3,32000;0,12257;14,09749
3,36000;0,12394;13,57073
3,40000;0,12526;13,61933
3,44000;0,12657;13,64682
3,48000;0,12789;14,33155
3,52000;0,12926;13,85264
3,56000;0,13046;13,06634
3,60000;0,13184;13,25145
3,64000;0,13321;13,89916
3,68000;0,13453;14,07103
3,72000;0,13590;13,73449
3,76000;0,13728;13,72377
3,80000;0,13865;13,35966
3,84000;0,13997;12,51900
3,88000;0,14116;12,54699
3,92000;0,14254;13,40038
3,96000;0,14397;13,12169
4,00000;0,14529;12,75859
4,04000;0,14666;12,01523
4,08000;0,14798;12,29731
4,12000;0,14929;13,32666
4,16000;0,15061;12,68962
4,20000;0,15181;12,85483
4,24000;0,15324;12,60154
4,28000;0,15462;12,62565
4,32000;0,15593;13,15682
4,36000;0,15725;12,67577
4,40000;0,15862;12,14964
4,44000;0,16000;13,28888
4,48000;0,16119;12,98807
4,52000;0,16251;13,32482
4,56000;0,16394;13,42873
4,60000;0,16526;14,38959
4,64000;0,16663;14,31162
4,68000;0,16795;13,45559
4,72000;0,16926;13,79352
4,76000;0,17064;13,82397
4,80000;0,17189;13,24435
4,84000;0,17309;13,80241
4,88000;0,17453;14,87925
4,92000;0,17584;14,45073
4,96000;0,17716;15,66558
5,00000;0,17853;15,05263
5,04000;0,17991;14,95556
5,08000;0,18128;15,29143
5,12000;0,18254;15,15884
5,16000;0,18379;14,85229
5,20000;0,18517;15,40006
5,24000;0,18654;15,08894
5,28000;0,18792;15,45003
5,32000;0,18929;15,42264
5,36000;0,19067;15,40604
5,40000;0,19204;15,49978
5,44000;0,19324;15,61475
5,48000;0,19450;15,48384
5,52000;0,19587;15,54892
5,56000;0,19719;15,34258
5,60000;0,19856;16,12573
5,64000;0,19994;16,06572
5,68000;0,20125;16,38451
5,72000;0,20263;16,72964
5,76000;0,20382;16,23480
5,80000;0,20520;15,98743
5,84000;0,20657;16,34186
5,88000;0,20789;17,20112
5,92000;0,20926;17,29484
5,96000;0,21058;17,53717
6,00000;0,21195;17,98858
6,04000;0,21327;16,92327
6,08000;0,21452;16,80651
6,12000;0,21590;17,38854
6,16000;0,21728;16,67000
6,20000;0,21859;16,97116
6,24000;0,21991;16,90249
6,28000;0,22122;16,99584
6,32000;0,22260;16,62924
6,36000;0,22391;16,54235
6,40000;0,22517;15,86398
6,44000;0,22648;15,58079
6,48000;0,22792;16,10080
6,52000;0,22923;16,02706
6,56000;0,23055;15,17465
6,60000;0,23186;15,69731
6,64000;0,23324;16,12193
6,68000;0,23455;16,07644
6,72000;0,23581;16,02263
6,76000;0,23724;15,94811
6,80000;0,23856;16,31804
6,84000;0,23994;16,20121
6,88000;0,24125;15,98385
6,92000;0,24263;15,90063
6,96000;0,24400;16,06966
7,00000;0,24520;15,48105
7,04000;0,24645;16,22990
7,08000;0,24795;16,82013
7,12000;0,24926;16,56933
7,16000;0,25058;16,74279
7,20000;0,25195;16,54105
7,24000;0,25327;16,78646
7,28000;0,25464;16,51037
7,32000;0,25584;16,89509
7,36000;0,25709;17,40455
7,40000;0,25853;17,50045
7,44000;0,25990;17,76603
7,48000;0,26128;17,62839
7,52000;0,26266;17,52126
7,56000;0,26403;17,10887
7,60000;0,26535;17,23045
7,64000;0,26648;17,42215
7,68000;0,26786;18,00900
7,72000;0,26923;17,92608
7,76000;0,27061;17,50040
7,80000;0,27198;17,02443
7,84000;0,27330;16,11860
7,88000;0,27467;16,81893
7,92000;0,27599;15,64837
7,96000;0,27718;15,93809
8,00000;0,27850;16,82294
8,04000;0,27987;16,38108
8,08000;0,28119;16,97574
8,12000;0,28251;17,26647
8,16000;0,28388;16,53295
8,20000;0,28532;16,63014
8,24000;0,28663;15,77335
8,28000;0,28783;16,12680
8,32000;0,28920;15,45956
8,36000;0,29058;15,69246
8,40000;0,29189;15,18334
8,44000;0,29321;15,38001
8,48000;0,29458;14,25325
8,52000;0,29596;14,57603
8,56000;0,29727;14,47675
8,60000;0,29847;14,69394
8,64000;0,29990;14,49218
8,68000;0,30128;14,75086
8,72000;0,30253;14,23800
8,76000;0,30391;14,25827
8,80000;0,30523;13,51390
8,84000;0,30660;13,74962
8,88000;0,30780;13,60444
8,92000;0,30911;13,65463
8,96000;0,31055;13,80035
9,00000;0,31186;13,56722
9,04000;0,31324;13,76069
9,08000;0,31455;14,54388
9,12000;0,31593;14,17508
9,16000;0,31730;13,87943
9,20000;0,31850;13,98943
9,24000;0,31987;13,95863
9,28000;0,32131;14,31539
9,32000;0,32262;14,20683
9,36000;0,32394;13,71236
9,40000;0,32531;13,43987
9,44000;0,32669;13,86168
9,48000;0,32795;12,93389
9,52000;0,32914;13,69441
9,56000;0,33046;14,22774
9,60000;0,33189;14,51850
9,64000;0,33321;14,81777
9,68000;0,33458;14,48699
9,72000;0,33590;14,77804
9,76000;0,33727;14,54653
9,80000;0,33859;13,69223
9,84000;0,33984;13,86163
9,88000;0,34122;13,78076
9,92000;0,34259;14,03504
9,96000;0,34397;14,24608
10,00000;0,34528;14,38955
10,04000;0,34666;14,26510
10,08000;0,34797;13,62211
10,12000;0,34923;13,99347
10,16000;0,35049;13,80833
10,20000;0,35180;13,09065
10,24000;0,35318;14,09938
10,28000;0,35449;13,71642
10,32000;0,35587;14,28216
10,36000;0,35724;14,14614
10,40000;0,35862;13,22866
10,44000;0,35987;13,87602
10,48000;0,36113;13,69458
10,52000;0,36256;13,37024
10,56000;0,36388;13,06827
10,60000;0,36525;14,04659
10,64000;0,36663;13,89475
10,68000;0,36794;13,10252
10,72000;0,36932;13,03728
10,76000;0,37058;12,90862
10,80000;0,37189;13,87426
10,84000;0,37327;12,97284
10,88000;0,37458;12,91163
10,92000;0,37590;12,51044
10,96000;0,37727;13,00307
11,00000;0,37859;13,28761
11,04000;0,37996;12,63975
11,08000;0,38116;12,08449
11,12000;0,38253;13,11168
11,16000;0,38391;13,35528
11,20000;0,38522;13,51836
11,24000;0,38660;13,36946
11,28000;0,38791;12,48696
11,32000;0,38929;13,07143
11,36000;0,39060;12,83552
11,40000;0,39192;12,58366
11,44000;0,39324;13,32639
11,48000;0,39461;12,71609
11,52000;0,39599;12,44509
11,56000;0,39730;12,49905
11,60000;0,39862;13,30098
11,64000;0,39993;13,62327
11,68000;0,40125;13,45267
11,72000;0,40250;13,31231
11,76000;0,40382;13,04026
11,80000;0,40519;12,98314
11,84000;0,40657;13,04274
11,88000;0,40794;12,83341
11,92000;0,40926;12,54172
11,96000;0,41063;12,91031
12,00000;0,41195;11,92371
12,04000;0,41315;12,43050
12,08000;0,41452;12,08375
12,12000;0,41590;12,44842
12,16000;0,41727;13,04151
12,20000;0,41859;12,84296
12,24000;0,41996;12,19686
12,28000;0,42134;12,25467
12,32000;0,42253;12,18075
12,36000;0,42379;12,09810
12,40000;0,42522;12,80748
12,44000;0,42660;12,84093
12,48000;0,42791;12,73090
12,52000;0,42929;12,83537
12,56000;0,43060;12,19537
12,60000;0,43198;12,15571
12,64000;0,43323;12,11977
12,68000;0,43449;12,63111
12,72000;0,43593;12,84497
12,76000;0,43724;13,25728
12,80000;0,43862;12,16176
12,84000;0,43993;12,72478
12,88000;0,44131;12,12687
12,92000;0,44268;12,31318
12,96000;0,44382;11,92719
13,00000;0,44519;11,84231
13,04000;0,44657;11,79190
13,08000;0,44788;11,16157
13,12000;0,44920;11,66028
13,16000;0,45051;11,70251
13,20000;0,45189;12,00693
13,24000;0,45326;12,15005
13,28000;0,45452;11,63438
13,32000;0,45584;11,23808
13,36000;0,45721;11,29483
13,40000;0,45853;11,98232
13,44000;0,45990;12,03736
13,48000;0,46122;11,15376
13,52000;0,46259;11,22114
13,56000;0,46391;11,63261
13,60000;0,46516;11,47118
13,64000;0,46654;11,38835
13,68000;0,46791;11,27828
13,72000;0,46923;11,28856
13,76000;0,47054;10,98267
13,80000;0,47186;11,19244
13,84000;0,47323;11,86162
13,88000;0,47455;11,08119
13,92000;0,47580;10,19598
13,96000;0,47724;11,09693
14,00000;0,47856;10,97467
14,04000;0,47993;10,94243
14,08000;0,48131;10,61343
14,12000;0,48262;10,66232
14,16000;0,48400;10,62692
14,20000;0,48531;10,27515
14,24000;0,48645;10,52776
14,28000;0,48782;10,05278
14,32000;0,48926;10,61343
14,36000;0,49057;10,84501
14,40000;0,49195;10,12170
14,44000;0,49326;10,86810
14,48000;0,49464;11,02655
14,52000;0,49589;10,49148
14,56000;0,49709;11,08584
14,60000;0,49852;10,25691
14,64000;0,49990;10,74524
14,68000;0,50128;10,57984
14,72000;0,50259;10,97680
14,76000;0,50397;11,20760
14,80000;0,50534;10,72037
14,84000;0,50654;10,47344
14,88000;0,50779;10,18944
14,92000;0,50923;10,72703
14,96000;0,51054;11,33944
15,00000;0,51186;10,99301
15,04000;0,51323;11,44016
15,08000;0,51461;10,79705
15,12000;0,51598;10,37830
15,16000;0,51718;10,07640
15,20000;0,51849;9,63697
15,24000;0,51993;10,42063
15,28000;0,52124;10,48176
15,32000;0,52262;10,06350
15,36000;0,52394;9,94175
15,40000;0,52531;9,97984
15,44000;0,52663;9,90089
15,48000;0,52788;9,78602
15,52000;0,52926;10,39664
15,56000;0,53063;10,51802
15,60000;0,53195;10,39414
15,64000;0,53326;10,96064
15,68000;0,53464;10,70820
15,72000;0,53601;9,46637
15,76000;0,53733;8,64755
15,80000;0,53852;9,72354
15,84000;0,53984;10,02102
15,88000;0,54127;10,03784
15,92000;0,54259;8,55085
15,96000;0,54391;9,65540
16,00000;0,54528;10,13046
16,04000;0,54666;9,11825
16,08000;0,54791;8,84402
16,12000;0,54911;9,66840
16,16000;0,55054;9,58617
16,20000;0,55192;10,00411
16,24000;0,55323;9,49431
16,28000;0,55455;9,73269
16,32000;0,55592;9,36181
16,36000;0,55724;9,35265
16,40000;0,55849;10,09148
16,44000;0,55975;9,61182
16,48000;0,56106;9,66759
16,52000;0,56262;9,74121
16,56000;0,56393;9,42948
16,60000;0,56525;9,40712
16,64000;0,56662;9,44620
16,68000;0,56794;9,57532
16,72000;0,56920;9,82950
16,76000;0,57057;9,96393
16,80000;0,57195;9,85026
16,84000;0,57326;9,37828
16,88000;0,57464;9,95137
16,92000;0,57595;9,69553
16,96000;0,57733;8,99523
17,00000;0,57864;9,06728
17,04000;0,57978;9,29710
17,08000;0,58115;10,03826
17,12000;0,58253;8,52685
17,16000;0,58384;9,36301
17,20000;0,58522;9,53389
17,24000;0,58653;9,26855
17,28000;0,58797;8,89262
17,32000;0,58923;7,93778
17,36000;0,59048;8,40420
17,40000;0,59192;9,23797
17,44000;0,59323;8,85881
17,48000;0,59461;8,17852
17,52000;0,59592;8,21693
17,56000;0,59730;8,87558
17,60000;0,59867;8,44466
17,64000;0,59993;8,12086
17,68000;0,60118;8,39607
17,72000;0,60256;8,73329
17,76000;0,60387;8,51094
17,80000;0,60519;8,31525
17,84000;0,60656;8,53491
17,88000;0,60788;8,00378
17,92000;0,60925;7,97825
17,96000;0,61051;8,01078
18,00000;0,61177;7,43219
18,04000;0,61314;7,75945
18,08000;0,61452;8,23412
18,12000;0,61589;7,67621
18,16000;0,61727;7,95381
18,20000;0,61852;8,17807
18,24000;0,62002;8,81100
18,28000;0,62127;7,22396
18,32000;0,62253;8,01788
18,36000;0,62396;8,10100
18,40000;0,62528;7,73499
18,44000;0,62659;7,62589
18,48000;0,62791;7,39960
18,52000;0,62928;8,04070
18,56000;0,63066;8,25221
18,60000;0,63186;7,92133
18,64000;0,63311;7,90066
18,68000;0,63455;8,03483
18,72000;0,63586;8,88770
18,76000;0,63724;8,52551
18,80000;0,63855;8,44104
18,84000;0,63993;8,78485
18,88000;0,64130;8,31334
18,92000;0,64250;7,65532
18,96000;0,64381;7,83302
19,00000;0,64525;8,03808
19,04000;0,64662;7,97734
19,08000;0,64806;7,45187
19,12000;0,64931;6,40698
19,16000;0,65063;6,91047
19,20000;0,65194;7,57000
19,24000;0,65308;7,51085
19,28000;0,65452;7,33732
19,32000;0,65589;7,95876
19,36000;0,65721;7,28069
19,40000;0,65852;7,58148
19,44000;0,65990;7,26840
19,48000;0,66127;7,65327
19,52000;0,66259;6,57638
19,56000;0,66378;6,51882
19,60000;0,66516;7,00671
19,64000;0,66653;7,63226
19,68000;0,66791;7,08135
19,72000;0,66928;6,78835
19,76000;0,67060;6,48322
19,80000;0,67197;6,67717
19,84000;0,67329;6,18008
19,88000;0,67449;6,44593
19,92000;0,67574;5,92913
19,96000;0,67730;6,69732
20,00000;0,67861;5,94864
20,04000;0,67993;5,52637
20,08000;0,68124;6,19232
20,12000;0,68262;6,71093
20,16000;0,68387;6,49913
20,20000;0,68513;5,62058
20,24000;0,68656;6,15515
20,28000;0,68788;6,91759
20,32000;0,68925;6,04944
20,36000;0,69057;6,44481
20,40000;0,69188;6,26493
20,44000;0,69332;6,30168
20,48000;0,69457;6,06986
20,52000;0,69583;5,61705
20,56000;0,69726;5,81355
20,60000;0,69858;5,89929
20,64000;0,69996;5,51038
20,68000;0,70109;6,02454
20,72000;0,70265;6,24564
20,76000;0,70402;5,48844
20,80000;0,70516;6,14715
20,84000;0,70647;6,50205
20,88000;0,70791;5,47224
20,92000;0,70922;6,40931
20,96000;0,71060;6,08837
21,00000;0,71191;5,95670
21,04000;0,71329;5,29305
21,08000;0,71460;5,40094
21,12000;0,71586;6,00101
21,16000;0,71723;5,36197
21,20000;0,71861;5,26644
21,24000;0,71993;6,19983
21,28000;0,72124;5,40082
21,32000;0,72262;5,94389
21,36000;0,72393;5,67765
21,40000;0,72525;5,46514
21,44000;0,72650;5,52517
21,48000;0,72788;5,20109
21,52000;0,72925;4,95470
21,56000;0,73057;5,66496
21,60000;0,73194;5,07826
21,64000;0,73326;5,76037
21,68000;0,73463;5,26700
21,72000;0,73589;4,54276
21,76000;0,73708;4,75615
21,80000;0,73852;5,27190
21,84000;0,73995;5,02440
21,88000;0,74127;4,92236
21,92000;0,74259;4,73164
21,96000;0,74396;4,89673
22,00000;0,74528;4,26703
22,04000;0,74647;4,50432
22,08000;0,74779;3,85090
22,12000;0,74922;4,61305
22,16000;0,75060;4,03660
22,20000;0,75191;5,10764
22,24000;0,75329;4,52359
22,28000;0,75466;4,02781
22,32000;0,75604;4,16563
22,36000;0,75723;3,87152
22,40000;0,75855;4,71590
22,44000;0,75992;4,39001
22,48000;0,76124;4,19853
22,52000;0,76261;4,39045
22,56000;0,76399;4,71237
22,60000;0,76537;3,29809
22,64000;0,76668;4,09394
22,68000;0,76782;4,54993
22,72000;0,76919;5,00391
22,76000;0,77057;5,07413
22,80000;0,77188;4,80616
22,84000;0,77320;4,67131
22,88000;0,77457;4,34060
22,92000;0,77595;4,39721
22,96000;0,77726;4,22017
23,00000;0,77846;4,86867
23,04000;0,77989;4,32094
23,08000;0,78121;5,16542
23,12000;0,78252;4,28939
23,16000;0,78390;5,07202
23,20000;0,78528;4,60115
23,24000;0,78659;4,01920
23,28000;0,78791;3,66163
23,32000;0,78916;4,83782
23,36000;0,79054;4,34494
23,40000;0,79185;4,50983
23,44000;0,79323;4,30907
23,48000;0,79454;3,72377
23,52000;0,79598;3,65201
23,56000;0,79729;2,73479
23,60000;0,79855;3,00594
23,64000;0,79980;3,30151
23,68000;0,80124;3,05556
23,72000;0,80255;3,57521
23,76000;0,80393;3,41073
23,80000;0,80530;2,67412
23,84000;0,80662;3,47977
23,88000;0,80794;3,55219
23,92000;0,80919;3,29588
23,96000;0,81057;3,17176
24,00000;0,81194;2,74353
24,04000;0,81326;2,64237
24,08000;0,81463;3,33941
24,12000;0,81595;3,19036
24,16000;0,81726;2,53727
24,20000;0,81864;1,97968
24,24000;0,81989;3,17771
24,28000;0,82115;2,60775
24,32000;0,82258;2,89158
24,36000;0,82396;3,30281
24,40000;0,82527;3,50896
24,44000;0,82659;3,52480
24,48000;0,82796;3,41078
24,52000;0,82928;3,47865
24,56000;0,83048;2,69094
24,60000;0,83179;2,56405
24,64000;0,83323;3,08847
24,68000;0,83454;3,17612
24,72000;0,83592;3,21299
24,76000;0,83723;3,30879
24,80000;0,83861;2,79828
24,84000;0,83992;3,03781
24,88000;0,84112;2,66609
24,92000;0,84249;2,76527
24,96000;0,84387;2,30047
25,00000;0,84524;3,16755
25,04000;0,84662;2,72130
25,08000;0,84793;2,39116
25,12000;0,84937;2,15142
25,16000;0,85063;2,26132
25,20000;0,85182;2,14929
25,24000;0,85320;2,58452
25,28000;0,85451;2,90252
25,32000;0,85589;3,40282
25,36000;0,85726;2,51942
25,40000;0,85864;3,02256
25,44000;0,86001;2,42477
25,48000;0,86121;2,28262
25,52000;0,86246;2,00010
25,56000;0,86396;2,27033
25,60000;0,86527;2,31401
25,64000;0,86659;2,29531
25,68000;0,86796;2,29100
25,72000;0,86934;1,34854
25,76000;0,87065;1,76984
25,80000;0,87185;1,48062
25,84000;0,87317;1,61790
25,88000;0,87460;1,99042
25,92000;0,87592;1,62989
25,96000;0,87723;1,97204
26,00000;0,87855;1,19836
26,04000;0,87992;1,73211
26,08000;0,88130;0,80598
26,12000;0,88249;1,23957
26,16000;0,88381;1,05193
26,20000;0,88518;1,62808
26,24000;0,88656;1,49757
26,28000;0,88793;0,93258
26,32000;0,88925;0,67216
26,36000;0,89056;1,25729
26,40000;0,89194;1,00821
26,44000;0,89320;1,14575
26,48000;0,89451;0,86643
26,52000;0,89589;1,66961
26,56000;0,89726;1,36024
26,60000;0,89858;2,12765
26,64000;0,89989;1,55113
26,68000;0,90127;1,42500
26,72000;0,90258;0,86758
26,76000;0,90378;1,50259
26,80000;0,90515;0,83805
26,84000;0,90653;2,04306
26,88000;0,90790;1,26190
26,92000;0,90922;1,16514
26,96000;0,91053;0,86653
27,00000;0,91197;1,16264
27,04000;0,91322;0,52370
27,08000;0,91442;0,96292
27,12000;0,91592;0,85154
27,16000;0,91729;0,96500
27,20000;0,91867;0,73298
27,24000;0,91998;0,12169
27,28000;0,92130;0,35609
27,32000;0,92267;0,87172
27,36000;0,92393;0,57761
27,40000;0,92512;0,56395
27,44000;0,92650;0,64844
27,48000;0,92787;1,53713
27,52000;0,92925;0,63081
27,56000;0,93056;0,51422
27,60000;0,93188;0,85252
27,64000;0,93325;0,56128
27,68000;0,93451;0,53577
27,72000;0,93577;0,43399
27,76000;0,93720;-0,31493
27,80000;0,93858;0,79034
27,84000;0,93989;1,19883
27,88000;0,94127;0,33247
27,92000;0,94264;0,35854
27,96000;0,94402;0,19370
28,00000;0,94515;0,14547
28,04000;0,94647;0,34206
28,08000;0,94790;0,30336
28,12000;0,94922;0,57252
28,16000;0,95047;0,03745
28,20000;0,95173;0,43402
28,24000;0,95328;-0,16323
28,28000;0,95460;-0,25196
28,32000;0,95579;-0,06721
28,36000;0,95717;-0,14849
28,40000;0,95855;0,35430
28,44000;0,95992;1,14773
28,48000;0,96124;0,51050
28,52000;0,96261;0,03189
28,56000;0,96399;-0,21394
28,60000;0,96530;-0,46437
28,64000;0,96650;0,53229
28,68000;0,96793;0,87669
28,72000;0,96931;-0,90672
28,76000;0,97062;-0,26630
28,80000;0,97194;0,04509
28,84000;0,97331;-0,73000
28,88000;0,97469;-0,37263
28,92000;0,97588;-0,49314
28,96000;0,97714;0,16963
29,00000;0,97857;-0,00216
29,04000;0,97989;-0,94589
29,08000;0,98121;-0,26427
29,12000;0,98258;-0,40823
29,16000;0,98396;-0,66728
29,20000;0,98533;-0,76888
29,24000;0,98659;-1,31191
29,28000;0,98784;-0,75471
29,32000;0,98922;-0,16301
29,36000;0,99059;-0,79062
29,40000;0,99197;-0,75081
29,44000;0,99328;-0,48902
29,48000;0,99466;-0,96146
29,52000;0,99597;-1,55536
29,56000;0,99717;-0,40919
29,60000;0,99848;-0,65577
29,64000;0,99986;-0,69162
29,68000;1,00123;-0,71407
29,72000;1,00255;-0,28533
29,76000;1,00393;-0,89725
29,80000;1,00530;-0,39596
29,84000;1,00662;-0,96952
29,88000;1,00787;-0,51270
29,92000;1,00919;-0,19788
29,96000;1,01056;-0,97789
30,00000;1,01188;-0,61660
30,04000;1,01325;-0,78830
30,08000;1,01457;-1,17520
30,12000;1,01606;-1,28032
30,16000;1,01726;-2,01894
30,20000;1,01851;-1,13688
30,24000;1,01989;-0,92121
30,28000;1,02120;-1,48064
30,32000;1,02258;-1,38075
30,36000;1,02390;-1,22139
30,40000;1,02527;-2,10668
30,44000;1,02659;-1,77764
30,48000;1,02790;-1,93183
30,52000;1,02916;-1,53462
30,56000;1,03059;-2,16055
30,60000;1,03191;-1,88786
30,64000;1,03328;-1,59079
30,68000;1,03460;-1,08838
30,72000;1,03591;-1,42928
30,76000;1,03735;-1,41970
30,80000;1,03860;-1,68086
30,84000;1,03992;-1,31506
30,88000;1,04129;-1,72882
30,92000;1,04261;-2,13513
30,96000;1,04392;-1,97355
31,00000;1,04524;-1,91601
31,04000;1,04662;-2,35075
31,08000;1,04793;-1,89442
31,12000;1,04919;-1,95325
31,16000;1,05050;-1,85180
31,20000;1,05194;-1,97673
31,24000;1,05325;-2,04430
31,28000;1,05463;-2,90352
31,32000;1,05594;-2,67845
31,36000;1,05732;-3,20931
31,40000;1,05863;-2,47936
31,44000;1,05989;-3,13667
31,48000;1,06114;-3,34839
31,52000;1,06258;-2,87206
31,56000;1,06395;-2,88665
31,60000;1,06527;-2,22643
31,64000;1,06658;-2,38532
31,68000;1,06796;-2,96379
31,72000;1,06928;-2,77699
31,76000;1,07047;-1,55607
31,80000;1,07179;-2,69593
31,84000;1,07316;-2,56889
31,88000;1,07460;-2,30967
31,92000;1,07597;-3,16132
31,96000;1,07729;-2,80231
32,00000;1,07866;-2,25911
32,04000;1,07998;-2,83712
32,08000;1,08117;-2,94705
32,12000;1,08255;-2,60216
32,16000;1,08392;-2,08440
32,20000;1,08524;-2,71304
32,24000;1,08661;-2,54074
32,28000;1,08799;-2,74629
32,32000;1,08930;-3,01624
32,36000;1,09056;-3,19841
32,40000;1,09176;-3,31896
32,44000;1,09319;-2,79244
32,48000;1,09457;-3,01227
32,52000;1,09588;-3,16573
32,56000;1,09720;-3,10286
32,60000;1,09857;-3,49291
32,64000;1,10001;-3,19552
32,68000;1,10120;-4,27768
32,72000;1,10246;-4,00538
32,76000;1,10389;-3,09634
32,80000;1,10521;-3,09590
32,84000;1,10652;-3,58927
32,88000;1,10790;-2,93358
32,92000;1,10921;-3,10232
32,96000;1,11053;-3,86798
33,00000;1,11185;-3,70158
33,04000;1,11316;-3,87229
33,08000;1,11454;-3,02698
33,12000;1,11585;-3,99537
33,16000;1,11723;-3,24855
33,20000;1,11854;-3,84174
33,24000;1,11986;-3,31862
33,28000;1,12123;-3,37111
33,32000;1,12249;-3,25350
33,36000;1,12380;-3,95140
33,40000;1,12524;-3,76139
33,44000;1,12655;-4,25821
33,48000;1,12793;-3,08709
33,52000;1,12924;-3,85547
33,56000;1,13056;-3,98021
33,60000;1,13193;-3,68990
33,64000;1,13313;-4,09677
33,68000;1,13451;-4,22217
33,72000;1,13588;-3,90987
33,76000;1,13726;-4,55969
33,80000;1,13863;-3,81358
33,84000;1,13995;-3,69641
33,88000;1,14132;-4,46854
33,92000;1,14264;-4,64119
33,96000;1,14383;-4,61647
34,00000;1,14521;-4,07704
34,04000;1,14658;-3,91749
34,08000;1,14796;-3,99500
34,12000;1,14927;-4,27652
34,16000;1,15065;-4,47376
34,20000;1,15196;-4,50372
34,24000;1,15328;-4,46822
34,28000;1,15448;-4,59703
34,32000;1,15567;-4,30201
34,36000;1,15729;-4,12224
34,40000;1,15860;-4,21493
34,44000;1,15992;-4,63600
34,48000;1,16129;-4,21028
34,52000;1,16267;-4,02345
34,56000;1,16386;-5,53691
34,60000;1,16518;-5,09270
34,64000;1,16661;-4,79320
34,68000;1,16793;-4,72945
34,72000;1,16924;-5,10450
34,76000;1,17056;-4,08003
34,80000;1,17193;-4,09702
34,84000;1,17331;-4,83698
34,88000;1,17456;-5,13670
34,92000;1,17582;-5,20334
34,96000;1,17720;-5,05989
35,00000;1,17857;-5,01370
35,04000;1,17989;-4,67373
35,08000;1,18126;-5,29096
35,12000;1,18258;-5,43695
35,16000;1,18389;-5,06322
35,20000;1,18515;-5,51515
35,24000;1,18652;-5,97295
35,28000;1,18790;-5,42650
35,32000;1,18921;-6,00534
35,36000;1,19059;-5,88738
35,40000;1,19196;-4,70125
35,44000;1,19334;-5,26851
35,48000;1,19465;-5,36612
35,52000;1,19585;-5,79087
35,56000;1,19728;-4,92947
35,60000;1,19860;-5,09231
35,64000;1,19992;-4,83255
35,68000;1,20129;-4,72950
35,72000;1,20261;-4,42180
35,76000;1,20398;-5,85470
35,80000;1,20524;-5,42334
35,84000;1,20643;-4,92982
35,88000;1,20793;-4,27929
35,92000;1,20924;-5,05965
35,96000;1,21062;-5,66855
36,00000;1,21193;-5,32411
36,04000;1,21331;-6,39997
36,08000;1,21462;-5,74474
36,12000;1,21588;-5,42211
36,16000;1,21719;-5,38723
36,20000;1,21857;-5,46082
36,24000;1,21994;-5,57197
36,28000;1,22126;-5,41526
36,32000;1,22258;-5,97285
36,36000;1,22395;-5,31723
36,40000;1,22533;-6,02225
36,44000;1,22652;-5,99305
36,48000;1,22778;-5,47656
36,52000;1,22921;-5,57799
36,56000;1,23053;-5,07512
36,60000;1,23190;-5,95713
36,64000;1,23328;-6,17982
36,68000;1,23459;-5,82468
36,72000;1,23597;-5,96044
36,76000;1,23716;-5,91669
36,80000;1,23854;-6,39189
36,84000;1,23991;-6,17140
36,88000;1,24123;-5,75079
36,92000;1,24272;-5,75657
36,96000;1,24404;-6,69648
37,00000;1,24536;-6,68446
37,04000;1,24661;-6,96265
37,08000;1,24787;-6,33005
37,12000;1,24924;-6,26164
37,16000;1,25062;-6,41158
37,20000;1,25193;-5,99351
37,24000;1,25325;-6,20568
37,28000;1,25456;-6,43398
37,32000;1,25594;-6,06586
37,36000;1,25725;-6,25440
37,40000;1,25851;-6,09068
37,44000;1,25988;-6,13326
37,48000;1,26120;-6,14871
37,52000;1,26257;-6,04368
37,56000;1,26389;-6,47011
37,60000;1,26527;-6,53257
37,64000;1,26658;-6,14528
37,68000;1,26790;-5,85472
37,72000;1,26915;-6,24632
37,76000;1,27053;-6,77309
37,80000;1,27190;-6,23525
37,84000;1,27322;-5,75934
37,88000;1,27453;-5,98411
37,92000;1,27591;-5,83709
37,96000;1,27722;-5,97011
38,00000;1,27854;-5,95698
38,04000;1,27979;-6,48943
38,08000;1,28117;-5,95926
38,12000;1,28254;-6,74711
38,16000;1,28386;-6,65447
38,20000;1,28518;-6,14486
38,24000;1,28655;-6,56452
38,28000;1,28793;-6,89880
38,32000;1,28918;-6,79074
38,36000;1,29050;-6,99852
38,40000;1,29187;-6,73881
38,44000;1,29325;-6,59098
38,48000;1,29456;-7,49018
38,52000;1,29594;-6,77894
38,56000;1,29725;-6,63074
38,60000;1,29863;-6,90142
38,64000;1,29982;-6,57884
38,68000;1,30120;-6,73242
38,72000;1,30257;-6,51078
38,76000;1,30395;-6,64955
38,80000;1,30526;-6,46588
38,84000;1,30664;-6,50992
38,88000;1,30795;-7,12603
38,92000;1,30927;-7,23928
38,96000;1,31047;-7,06024
39,00000;1,31184;-7,36995
39,04000;1,31328;-7,10678
39,08000;1,31459;-6,59845
39,12000;1,31591;-7,49209
39,16000;1,31722;-7,31373
39,20000;1,31860;-7,51040
39,24000;1,31991;-7,42310
39,28000;1,32111;-7,35016
39,32000;1,32248;-7,77712
39,36000;1,32386;-7,14706
39,40000;1,32517;-7,16958
39,44000;1,32655;-7,01145
39,48000;1,32786;-7,48191
39,52000;1,32924;-7,25992
39,56000;1,33056;-7,04482
39,60000;1,33175;-7,79264
39,64000;1,33319;-8,33728
39,68000;1,33456;-7,17808
39,72000;1,33588;-6,95399
39,76000;1,33725;-6,89912
39,80000;1,33863;-7,78762
39,84000;1,34000;-7,65196
39,88000;1,34126;-8,56354
39,92000;1,34245;-7,59320
39,96000;1,34389;-7,96306
40,00000;1,34520;-7,16248
40,04000;1,34652;-7,40736
40,08000;1,34789;-7,50210
40,12000;1,34921;-8,11578
40,16000;1,35058;-7,10654
40,20000;1,35190;-7,38410
40,24000;1,35310;-7,19761
40,28000;1,35453;-7,51114
40,32000;1,35591;-7,80028
40,36000;1,35722;-7,68954
40,40000;1,35854;-7,54580
40,44000;1,35991;-6,46889
40,48000;1,36129;-7,40087
40,52000;1,36254;-7,89635
40,56000;1,36380;-7,71111
40,60000;1,36523;-7,91907
40,64000;1,36655;-8,17910
40,68000;1,36792;-7,50059
40,72000;1,36918;-7,81274
40,76000;1,37055;-7,53900
40,80000;1,37193;-7,76412
40,84000;1,37313;-8,06319
40,88000;1,37444;-7,73175
40,92000;1,37588;-7,55670
40,96000;1,37725;-7,27513
41,00000;1,37857;-7,97981
41,04000;1,37988;-8,22689
41,08000;1,38126;-7,80615
41,12000;1,38257;-8,25281
41,16000;1,38383;-8,08180
41,20000;1,38520;-7,86388
41,24000;1,38664;-7,89211
41,28000;1,38795;-8,54717
41,32000;1,38927;-9,14858
41,36000;1,39058;-8,13650
41,40000;1,39202;-8,66684
41,44000;1,39327;-9,27327
41,48000;1,39447;-8,59537
41,52000;1,39585;-8,41716
41,56000;1,39728;-8,67484
41,60000;1,39860;-8,65562
41,64000;1,39991;-8,91049
41,68000;1,40129;-8,57091
41,72000;1,40266;-8,96565
41,76000;1,40386;-8,92777
41,80000;1,40511;-8,27054
41,84000;1,40655;-8,74653
41,88000;1,40792;-8,87925
41,92000;1,40924;-7,99281
41,96000;1,41061;-8,49428
42,00000;1,41199;-9,02139
42,04000;1,41336;-8,94256
42,08000;1,41456;-8,32795
42,12000;1,41587;-8,20752
42,16000;1,41731;-8,07203
42,20000;1,41857;-8,56709
42,24000;1,41994;-8,13738
42,28000;1,42132;-8,76070
42,32000;1,42269;-9,00864
42,36000;1,42401;-9,04267
42,40000;1,42520;-8,54668
42,44000;1,42646;-8,25812
42,48000;1,42789;-8,69090
42,52000;1,42921;-8,94138
42,56000;1,43058;-9,51388
42,60000;1,43190;-9,00056
42,64000;1,43327;-8,82098
42,68000;1,43459;-9,31611
42,72000;1,43578;-8,96951
42,76000;1,43722;-8,78455
42,80000;1,43859;-8,79329
42,84000;1,43991;-8,60154
42,88000;1,44129;-8,64111
42,92000;1,44260;-8,68890
42,96000;1,44398;-8,46150
43,00000;1,44529;-9,54713
43,04000;1,44655;-9,51636
43,08000;1,44786;-9,40499
43,12000;1,44924;-8,62223
43,16000;1,45055;-8,30787
43,20000;1,45187;-9,22741
43,24000;1,45324;-9,00675
43,28000;1,45462;-9,91202
43,32000;1,45593;-9,68081
43,36000;1,45713;-9,17372
43,40000;1,45850;-8,83459
43,44000;1,45988;-8,83315
43,48000;1,46126;-9,27327
43,52000;1,46263;-9,12610
43,56000;1,46395;-9,81779
43,60000;1,46532;-9,16288
43,64000;1,46664;-9,83074
43,68000;1,46783;-9,50556
43,72000;1,46927;-9,83152
43,76000;1,47064;-9,91998
43,80000;1,47196;-10,55709
43,84000;1,47327;-9,78956
43,88000;1,47459;-9,14060
43,92000;1,47596;-9,80496
43,96000;1,47722;-10,11297
44,00000;1,47847;-9,61057
44,04000;1,47991;-10,36507
44,08000;1,48122;-9,23211
44,12000;1,48260;-9,85632
44,16000;1,48398;-10,95258
44,20000;1,48529;-9,81142
44,24000;1,48667;-9,15490
44,28000;1,48786;-10,36328
44,32000;1,48912;-10,26922
44,36000;1,49055;-9,81867
44,40000;1,49193;-9,81377
44,44000;1,49324;-9,43223
44,48000;1,49462;-9,86492
44,52000;1,49593;-9,99107
44,56000;1,49731;-10,23242
44,60000;1,49850;-10,27226
44,64000;1,49976;-10,11958
44,68000;1,50119;-10,24694
44,72000;1,50251;-10,13545
44,76000;1,50389;-10,32014
44,80000;1,50520;-9,84472
44,84000;1,50658;-9,58547
44,88000;1,50795;-9,94226
44,92000;1,50915;-9,79556
44,96000;1,51052;-9,80709
45,00000;1,51190;-9,54554
45,04000;1,51321;-9,89505
45,08000;1,51459;-10,18123
45,12000;1,51596;-9,83887
45,16000;1,51734;-10,46418
45,20000;1,51859;-10,51113
45,24000;1,51979;-9,54544
45,28000;1,52122;-9,78755
45,32000;1,52260;-9,75631
45,36000;1,52391;-9,10133
45,40000;1,52529;-9,10862
45,44000;1,52661;-10,23524
45,48000;1,52792;-10,24386
45,52000;1,52918;-10,43764
45,56000;1,53049;-10,10874
45,60000;1,53193;-10,37949
45,64000;1,53324;-10,02417
45,68000;1,53456;-10,55452
45,72000;1,53593;-9,95548
45,76000;1,53725;-10,03916
45,80000;1,53862;-10,23884
45,84000;1,53988;-10,75390
45,88000;1,54119;-10,73365
45,92000;1,54257;-10,50411
45,96000;1,54388;-10,16311
46,00000;1,54526;-10,65773
46,04000;1,54657;-10,72834
46,08000;1,54789;-9,56469
46,12000;1,54927;-10,24454
46,16000;1,55046;-10,50536
46,20000;1,55172;-10,74210
46,24000;1,55315;-10,29299
46,28000;1,55453;-10,82811
46,32000;1,55590;-10,33361
46,36000;1,55722;-10,37371
46,40000;1,55859;-10,57165
46,44000;1,55997;-10,80140
46,48000;1,56116;-10,45614
46,52000;1,56254;-10,73106
46,56000;1,56391;-10,69137
46,60000;1,56529;-10,58529
46,64000;1,56660;-10,79131
46,68000;1,56792;-10,34605
46,72000;1,56923;-10,09077
46,76000;1,57061;-10,33026
46,80000;1,57181;-10,42870
46,84000;1,57318;-10,55956
46,88000;1,57456;-10,88427
46,92000;1,57593;-10,83959
46,96000;1,57731;-10,08856
47,00000;1,57862;-10,72225
47,04000;1,58000;-11,13152
47,08000;1,58125;-11,01045
47,12000;1,58245;-10,81450
47,16000;1,58388;-10,41477
47,20000;1,58526;-11,17809
47,24000;1,58657;-10,62206
47,28000;1,58795;-11,38193
47,32000;1,58932;-11,16553
47,36000;1,59070;-11,10714
47,40000;1,59190;-11,01459
47,44000;1,59315;-10,56661
47,48000;1,59453;-10,31623
47,52000;1,59584;-10,69629
47,56000;1,59722;-10,77212
47,60000;1,59853;-10,14708
47,64000;1,59991;-10,12649
47,68000;1,60128;-10,65046
47,72000;1,60248;-10,72915
47,76000;1,60373;-10,72406
47,80000;1,60523;-10,85852
47,84000;1,60654;-10,67869
47,88000;1,60786;-11,06226
47,92000;1,60923;-10,71806
47,96000;1,61061;-10,43715
48,00000;1,61198;-10,80110
48,04000;1,61318;-10,93696
48,08000;1,61450;-11,14437
48,12000;1,61593;-11,17302
48,16000;1,61725;-10,56206
48,20000;1,61862;-10,11114
48,24000;1,61994;-11,09210
48,28000;1,62125;-11,07323
48,32000;1,62263;-11,60900
48,36000;1,62382;-11,56239
48,40000;1,62526;-12,27831
48,44000;1,62663;-11,19547
48,48000;1,62795;-11,53220
48,52000;1,62926;-11,15999
48,56000;1,63070;-11,80631
48,60000;1,63201;-12,47777
48,64000;1,63327;-12,58388
48,68000;1,63453;-11,43589
48,72000;1,63596;-11,52163
48,76000;1,63728;-11,61801
48,80000;1,63859;-11,24686
48,84000;1,63997;-11,62707
48,88000;1,64134;-11,72366
48,92000;1,64266;-12,10367
48,96000;1,64385;-12,48186
49,00000;1,64511;-12,62202
49,04000;1,64654;-11,35642
49,08000;1,64792;-12,14547
49,12000;1,64923;-11,81505
49,16000;1,65061;-11,26037
49,20000;1,65198;-11,60705
49,24000;1,65330;-12,30225
49,28000;1,65455;-12,17989
49,32000;1,65581;-12,19355
49,36000;1,65725;-11,44416
49,40000;1,65856;-11,55747
49,44000;1,65994;-11,90253
49,48000;1,66125;-11,88482
49,52000;1,66263;-12,09023
49,56000;1,66394;-12,56285
49,60000;1,66514;-11,75852
49,64000;1,66645;-12,27341
49,68000;1,66789;-11,83062
49,72000;1,66920;-11,94637
49,76000;1,67058;-11,37999
49,80000;1,67195;-11,58408
49,84000;1,67333;-12,09951
49,88000;1,67464;-12,30370
49,92000;1,67590;-11,79799
49,96000;1,67715;-11,87670
50,00000;1,67859;-11,80251
50,04000;1,67991;-11,38913
50,08000;1,68128;-11,85248
50,12000;1,68260;-11,79764
50,16000;1,68397;-12,07236
50,20000;1,68529;-12,44530
50,24000;1,68654;-11,51820
50,28000;1,68786;-11,10966
50,32000;1,68923;-11,53095
50,36000;1,69055;-11,52838
50,40000;1,69186;-11,10910
50,44000;1,69318;-11,64433
50,48000;1,69455;-12,00349
50,52000;1,69593;-12,63833
50,56000;1,69718;-12,27750
50,60000;1,69856;-12,27065
50,64000;1,69987;-12,31826
50,68000;1,70125;-11,89166
50,72000;1,70257;-12,67919
50,76000;1,70394;-11,98077
50,80000;1,70526;-13,10102
50,84000;1,70657;-12,48480
50,88000;1,70783;-12,60434
50,92000;1,70920;-12,53560
50,96000;1,71052;-12,74974
51,00000;1,71183;-12,67566
51,04000;1,71327;-11,91105
51,08000;1,71458;-12,81063
51,12000;1,71596;-12,58385
51,16000;1,71721;-13,26481
51,20000;1,71847;-12,75352
51,24000;1,71990;-12,16505
51,28000;1,72128;-12,43803
51,32000;1,72265;-11,95343
51,36000;1,72397;-12,75288
51,40000;1,72529;-12,65451
51,44000;1,72666;-12,74279
51,48000;1,72786;-12,79000
51,52000;1,72911;-12,89831
51,56000;1,73055;-12,63886
51,60000;1,73186;-12,38660
51,64000;1,73330;-12,34067
51,68000;1,73461;-12,57178
51,72000;1,73593;-12,48181
51,76000;1,73730;-12,37311
51,80000;1,73850;-11,93570
51,84000;1,73981;-12,73574
51,88000;1,74125;-11,98682
51,92000;1,74256;-11,76596
51,96000;1,74394;-12,95976
52,00000;1,74532;-13,42870
52,04000;1,74663;-12,69033
52,08000;1,74795;-12,94399
52,12000;1,74914;-13,48684
52,16000;1,75052;-12,05748
52,20000;1,75195;-12,56094
52,24000;1,75327;-13,39058
52,28000;1,75458;-12,45444
52,32000;1,75590;-12,67326
52,36000;1,75727;-13,39858
52,40000;1,75859;-12,96172
52,44000;1,75978;-12,56140
52,48000;1,76122;-12,36650
52,52000;1,76253;-12,28656
52,56000;1,76391;-13,27257
52,60000;1,76528;-12,15585
52,64000;1,76660;-12,13261
52,68000;1,76798;-12,66467
52,72000;1,76929;-13,20649
52,76000;1,77049;-12,26783
52,80000;1,77192;-12,97114
52,84000;1,77324;-12,95733
52,88000;1,77461;-12,81712
52,92000;1,77593;-12,70362
52,96000;1,77724;-13,14073
53,00000;1,77862;-12,74321
53,04000;1,77987;-12,87781
53,08000;1,78113;-12,38461
53,12000;1,78256;-12,49757
53,16000;1,78388;-12,58625
53,20000;1,78525;-13,06060
53,24000;1,78657;-13,07686
53,28000;1,78789;-13,03252
53,32000;1,78926;-13,73145
53,36000;1,79052;-12,99193
53,40000;1,79183;-12,26046
53,44000;1,79327;-12,75518
53,48000;1,79458;-13,48310
53,52000;1,79596;-13,41810
53,56000;1,79727;-13,55412
53,60000;1,79865;-13,21582
53,64000;1,79996;-13,06623
53,68000;1,80116;-13,08991
53,72000;1,80247;-13,30552
53,76000;1,80391;-13,19966
53,80000;1,80522;-13,13809
53,84000;1,80660;-12,70105
53,88000;1,80791;-13,05269
53,92000;1,80923;-12,85514
53,96000;1,81061;-12,78270
54,00000;1,81186;-12,90325
54,04000;1,81318;-14,06336
54,08000;1,81449;-13,01095
54,12000;1,81599;-13,15192
54,16000;1,81730;-13,90351
54,20000;1,81862;-13,52379
54,24000;1,81999;-12,75501
54,28000;1,82125;-13,51299
54,32000;1,82250;-13,12487
54,36000;1,82388;-13,20965
54,40000;1,82525;-12,61414
54,44000;1,82657;-12,53469
54,48000;1,82788;-13,40673
54,52000;1,82920;-12,73028
54,56000;1,83057;-13,08934
54,60000;1,83189;-13,40566
54,64000;1,83309;-13,31380
54,68000;1,83452;-13,81797
54,72000;1,83590;-13,39692
54,76000;1,83727;-12,85083
54,80000;1,83859;-13,17861
54,84000;1,83996;-12,42579
54,88000;1,84134;-13,39467
54,92000;1,84253;-13,51720
54,96000;1,84385;-12,43294
55,00000;1,84528;-13,58010
55,04000;1,84660;-13,69007
55,08000;1,84791;-13,07478
55,12000;1,84923;-13,12225
55,16000;1,85060;-12,81306
55,20000;1,85198;-13,28094
55,24000;1,85318;-13,32205
55,28000;1,85455;-13,20280
55,32000;1,85593;-13,71536
55,36000;1,85718;-12,81977
55,40000;1,85856;-12,92384
55,44000;1,85993;-12,78525
55,48000;1,86131;-12,77073
55,52000;1,86262;-13,41584
55,56000;1,86388;-13,57929
55,60000;1,86525;-12,88770
55,64000;1,86663;-12,89086
55,68000;1,86794;-13,52202
55,72000;1,86926;-13,19374
55,76000;1,87063;-13,12379
55,80000;1,87195;-13,01957
55,84000;1,87326;-12,69099
55,88000;1,87446;-13,94609
55,92000;1,87590;-12,87967
55,96000;1,87727;-12,44957
56,00000;1,87859;-13,26283
56,04000;1,87990;-13,39090
56,08000;1,88122;-12,98681
56,12000;1,88259;-13,56102
56,16000;1,88391;-14,18166
56,20000;1,88510;-13,27585
56,24000;1,88654;-13,28863
56,28000;1,88785;-13,45847
56,32000;1,88929;-13,32009
56,36000;1,89060;-12,85456
56,40000;1,89198;-13,54369
56,44000;1,89329;-13,02875
56,44800;1,89359;-13,09081