File: SU - Suspension/05 - Essais/Excels essais Optimus/Temoins et tests triangles/Temoin alu alu/collage alu alu.is_tens_RawData/Specimen_RawData_1.csv
Temps;Déplacement;Charge
(sec);(mm);(N)
0,00000;0,00849;58,65656
0,06000;0,00981;61,12211
0,12000;0,01447;88,07578
0,18000;0,02015;127,83678
0,24000;0,02601;164,19551
0,30000;0,03169;194,83970
0,36000;0,03707;219,64149
0,42000;0,04239;240,45033
0,48000;0,04759;258,27745
0,54000;0,05267;272,54533
0,60000;0,05776;284,98422
0,66000;0,06278;294,58054
0,72000;0,06786;301,17878
0,78000;0,07288;302,37976
0,84000;0,07791;297,73561
0,90000;0,08287;295,48001
0,96000;0,08789;296,22319
1,02000;0,09291;296,80410
1,08000;0,09794;299,78487
1,14000;0,10290;303,47607
1,20000;0,10792;306,13416
1,26000;0,11288;309,60396
1,32000;0,11790;311,54265
1,38000;0,12293;313,02765
1,44000;0,12789;313,58250
1,50000;0,13285;313,86572
1,56000;0,13793;313,99899
1,62000;0,14284;313,45696
1,68000;0,14792;312,78762
1,74000;0,15288;312,73759
1,80000;0,15790;310,92023
1,86000;0,16299;311,30244
1,92000;0,16789;310,11554
1,98000;0,17297;310,43058
2,04000;0,17793;310,24921
2,10000;0,18290;311,36833
2,16000;0,18792;313,98931
2,22000;0,19288;318,36641
2,28000;0,19790;325,71920
2,34000;0,20287;333,84629
2,40000;0,20789;343,66304
2,46000;0,21297;352,28662
2,52000;0,21787;358,41851
2,58000;0,22290;366,33527
2,64000;0,22756;373,67833
2,70000;0,23294;383,45465
2,76000;0,23790;389,69642
2,82000;0,24286;396,29964
2,88000;0,24783;403,96997
2,94000;0,25279;410,03413
3,00000;0,25793;418,44952
3,06000;0,26295;424,01273
3,12000;0,26792;430,44048
3,18000;0,27294;436,22735
3,24000;0,27784;442,24509
3,30000;0,28286;451,18299
3,36000;0,28789;457,84400
3,42000;0,29285;464,23143
3,48000;0,29787;470,44037
3,54000;0,30283;477,30566
3,60000;0,30792;483,22212
3,66000;0,31294;491,14707
3,72000;0,31796;497,33333
3,78000;0,32286;503,38334
3,84000;0,32789;509,85841
3,90000;0,33285;515,30516
3,96000;0,33793;522,08104
4,02000;0,34283;527,39615
4,08000;0,34780;533,43284
4,14000;0,35282;540,14996
4,20000;0,35766;545,04159
4,26000;0,36286;552,50395
4,32000;0,36788;558,02055
4,38000;0,37285;563,80844
4,44000;0,37787;569,20359
4,50000;0,38283;575,43754
4,56000;0,38785;581,84834
4,62000;0,39282;586,87013
4,68000;0,39778;594,11465
4,74000;0,40286;600,47414
4,80000;0,40782;605,95726
4,86000;0,41285;613,01547
4,92000;0,41775;618,37048
4,98000;0,42283;626,34647
5,04000;0,42785;631,28122
5,10000;0,43288;637,25417
5,16000;0,43790;643,32131
5,22000;0,44280;648,52792
5,28000;0,44782;655,61156
5,34000;0,45255;661,46748
5,40000;0,45793;669,86009
5,46000;0,46295;674,33962
5,52000;0,46785;680,35987
5,58000;0,47288;685,72527
5,64000;0,47784;691,91768
5,70000;0,48292;697,88466
5,76000;0,48788;704,79834
5,82000;0,49290;709,34868
5,88000;0,49787;717,55219
5,94000;0,50289;721,46920
6,00000;0,50791;727,58729
6,06000;0,51293;733,10207
6,12000;0,51796;741,18813
6,18000;0,52292;746,64038
6,24000;0,52794;750,37666
6,30000;0,53290;756,30415
6,36000;0,53793;762,86872
6,42000;0,54289;767,99663
6,48000;0,54797;777,22771
6,54000;0,55287;784,05375
6,60000;0,55796;792,79840
6,66000;0,56280;800,43124
6,72000;0,56794;809,91872
6,78000;0,57284;817,69601
6,84000;0,57781;825,14742
6,90000;0,58289;834,47797
6,96000;0,58785;841,39863
7,02000;0,59293;848,80572
7,08000;0,59789;856,11260
7,14000;0,60286;862,32293
7,20000;0,60788;869,83927
7,26000;0,61278;877,05078
7,32000;0,61786;884,11914
7,38000;0,62283;892,56931
7,44000;0,62779;899,17518
7,50000;0,63281;906,83782
7,56000;0,63771;912,18948
7,62000;0,64292;920,79155
7,68000;0,64788;928,67846
7,74000;0,65290;936,37658
7,80000;0,65786;942,73351
7,86000;0,66277;948,69034
7,92000;0,66785;956,75476
7,98000;0,67293;965,78058
8,04000;0,67789;974,37762
8,10000;0,68292;980,07862
8,16000;0,68788;986,15838
8,22000;0,69296;993,98540
8,28000;0,69792;1001,11440
8,34000;0,70306;1010,46721
8,40000;0,70791;1017,00844
8,46000;0,71293;1023,14660
8,52000;0,71783;1031,77335
8,58000;0,72268;1039,17047
8,64000;0,72782;1049,21162
8,70000;0,73284;1054,71704
8,76000;0,73786;1063,01373
8,82000;0,74282;1070,41635
8,88000;0,74791;1079,19108
8,94000;0,75287;1086,20441
9,00000;0,75789;1094,51283
9,06000;0,76291;1106,42333
9,12000;0,76788;1113,59777
9,18000;0,77284;1122,17534
9,24000;0,77786;1130,33568
9,30000;0,78282;1138,57482
9,36000;0,78791;1150,03204
9,42000;0,79281;1157,71145
9,48000;0,79783;1165,53279
9,54000;0,80279;1174,69653
9,60000;0,80788;1183,53730
9,66000;0,81284;1192,10528
9,72000;0,81792;1203,10737
9,78000;0,82282;1209,92344
9,84000;0,82779;1216,74202
9,90000;0,83281;1226,62392
9,96000;0,83783;1234,93653
10,02000;0,84285;1243,11158
10,08000;0,84787;1251,56166
10,14000;0,85278;1259,67031
10,20000;0,85786;1268,72519
10,26000;0,86288;1277,79972
10,32000;0,86784;1285,68076
10,38000;0,87287;1294,47868
10,44000;0,87783;1303,25621
10,50000;0,88291;1312,20296
10,56000;0,88781;1320,83278
10,62000;0,89290;1330,18633
10,68000;0,89780;1338,26863
10,74000;0,90288;1348,37097
10,80000;0,90784;1356,74104
10,86000;0,91287;1364,83526
10,92000;0,91789;1374,37778
10,98000;0,92285;1383,00434
11,04000;0,92787;1392,53726
11,10000;0,93290;1399,66235
11,16000;0,93786;1408,15359
11,22000;0,94282;1416,65768
11,28000;0,94784;1425,90236
11,34000;0,95287;1433,91443
11,40000;0,95777;1440,04561
11,46000;0,96285;1447,53084
11,52000;0,96781;1456,06454
11,58000;0,97283;1464,12626
11,64000;0,97792;1471,75509
11,70000;0,98288;1476,97898
11,76000;0,98790;1483,28301
11,82000;0,99274;1488,83518
11,88000;0,99789;1495,61772
11,94000;1,00279;1501,18535
12,00000;1,00787;1506,61608
12,06000;1,01283;1512,59555
12,12000;1,01780;1518,32635
12,18000;1,02282;1526,30005
12,24000;1,02790;1537,61785
12,30000;1,03286;1548,84225
12,36000;1,03795;1559,71982
12,42000;1,04279;1571,29094
12,48000;1,04781;1582,50332
12,54000;1,05277;1594,11840
12,60000;1,05786;1608,73625
12,66000;1,06282;1622,00425
12,72000;1,06778;1633,70278
12,78000;1,07280;1648,02317
12,84000;1,07783;1663,53956
12,90000;1,08285;1685,19188
12,96000;1,08787;1707,44117
13,02000;1,09277;1731,19325
13,08000;1,09779;1754,56628
13,14000;1,10282;1777,49600
13,20000;1,10790;1801,77093
13,26000;1,11286;1825,79104
13,32000;1,11782;1849,67443
13,38000;1,12297;1875,27761
13,44000;1,12787;1899,93717
13,50000;1,13301;1925,32409
13,56000;1,13785;1947,88799
13,62000;1,14294;1973,28273
13,68000;1,14784;1996,68873
13,74000;1,15292;2022,33456
13,80000;1,15794;2047,66579
13,86000;1,16285;2071,36571
13,92000;1,16787;2097,78547
13,98000;1,17289;2121,85755
14,04000;1,17791;2148,13277
14,10000;1,18294;2173,17753
14,16000;1,18784;2200,18886
14,22000;1,19286;2228,01380
14,28000;1,19782;2253,42643
14,34000;1,20296;2280,55269
14,40000;1,20787;2307,29766
14,46000;1,21289;2334,18997
14,52000;1,21791;2363,34112
14,58000;1,22287;2389,87543
14,64000;1,22796;2419,79435
14,70000;1,23280;2445,96936
14,76000;1,23788;2474,95025
14,82000;1,24284;2502,79158
14,88000;1,24787;2531,39958
14,94000;1,25283;2560,17111
15,00000;1,25767;2588,24509
15,06000;1,26287;2620,60538
15,12000;1,26790;2646,80106
15,18000;1,27280;2673,62166
15,24000;1,27788;2702,04358
15,30000;1,28278;2730,77544
15,36000;1,28781;2761,21292
15,42000;1,29283;2792,25353
15,48000;1,29773;2821,17613
15,54000;1,30281;2853,62806
15,60000;1,30784;2880,94431
15,66000;1,31286;2910,72130
15,72000;1,31788;2938,68296
15,78000;1,32284;2967,01714
15,84000;1,32786;2996,24689
15,90000;1,33277;3026,25261
15,96000;1,33785;3059,66157
16,02000;1,34281;3087,25238
16,08000;1,34783;3116,89302
16,14000;1,35286;3145,97078
16,20000;1,35788;3175,02506
16,26000;1,36290;3205,65775
16,32000;1,36780;3234,35292
16,38000;1,37283;3264,12916
16,44000;1,37779;3292,00365
16,50000;1,38245;3323,69246
16,56000;1,38789;3360,40296
16,62000;1,39286;3387,86468
16,68000;1,39782;3416,70029
16,74000;1,40284;3446,07569
16,80000;1,40786;3477,37484
16,86000;1,41283;3506,32556
16,92000;1,41785;3537,36691
16,98000;1,42287;3565,83409
17,04000;1,42789;3599,80762
17,10000;1,43286;3631,01587
17,16000;1,43776;3659,27853
17,22000;1,44278;3690,38098
17,28000;1,44780;3720,43401
17,34000;1,45265;3748,94403
17,40000;1,45791;3781,52877
17,46000;1,46287;3809,81304
17,52000;1,46795;3840,55153
17,58000;1,47285;3868,37125
17,64000;1,47788;3897,80998
17,70000;1,48278;3927,42567
17,76000;1,48786;3957,72867
17,82000;1,49282;3986,01480
17,88000;1,49785;4015,91733
17,94000;1,50281;4046,96651
18,00000;1,50783;4076,73791
18,06000;1,51279;4105,04825
18,12000;1,51782;4134,10775
18,18000;1,52278;4161,91034
18,24000;1,52780;4191,76035
18,30000;1,53276;4219,61173
18,36000;1,53779;4249,66365
18,42000;1,54263;4278,21428
18,48000;1,54783;4310,00851
18,54000;1,55279;4337,23517
18,60000;1,55782;4364,04012
18,66000;1,56284;4392,68574
18,72000;1,56774;4420,04465
18,78000;1,57282;4451,33410
18,84000;1,57784;4478,72579
18,90000;1,58287;4506,29815
18,96000;1,58789;4534,64910
19,02000;1,59285;4561,40079
19,08000;1,59787;4589,99313
19,14000;1,60284;4616,98696
19,20000;1,60792;4646,40595
19,26000;1,61294;4673,40760
19,32000;1,61784;4699,06367
19,38000;1,62287;4727,22203
19,44000;1,62783;4753,00215
19,50000;1,63297;4782,34626
19,56000;1,63787;4806,79385
19,62000;1,64284;4833,47401
19,68000;1,64786;4859,82150
19,74000;1,65288;4887,19717
19,80000;1,65784;4914,92637
19,86000;1,66287;4939,83738
19,92000;1,66777;4965,58324
19,98000;1,67267;4992,67727
20,04000;1,67781;5022,36150
20,10000;1,68289;5049,14671
20,16000;1,68780;5074,87059
20,22000;1,69282;5102,34162
20,28000;1,69754;5128,23239
20,34000;1,70286;5158,15765
20,40000;1,70789;5184,06890
20,46000;1,71273;5209,37070
20,52000;1,71781;5237,47429
20,58000;1,72283;5265,79283
20,64000;1,72786;5292,93753
20,70000;1,73288;5322,19522
20,76000;1,73784;5347,45827
20,82000;1,74280;5373,22015
20,88000;1,74783;5398,81326
20,94000;1,75285;5425,26580
21,00000;1,75787;5453,27440
21,06000;1,76283;5481,33180
21,12000;1,76786;5507,54406
21,18000;1,77282;5533,48921
21,24000;1,77790;5561,10144
21,30000;1,78286;5586,69083
21,36000;1,78783;5612,86584
21,42000;1,79291;5639,27069
21,48000;1,79787;5664,31284
21,54000;1,80295;5692,33187
21,60000;1,80785;5717,04358
21,66000;1,81288;5743,36648
21,72000;1,81784;5768,16797
21,78000;1,82292;5794,31430
21,84000;1,82788;5819,41307
21,90000;1,83291;5843,92920
21,96000;1,83787;5868,73963
22,02000;1,84277;5893,30569
22,08000;1,84791;5921,77697
22,14000;1,85294;5945,69407
22,20000;1,85784;5969,02072
22,26000;1,86298;5995,20206
22,32000;1,86782;6020,38875
22,38000;1,87291;6043,55447
22,44000;1,87781;6067,39745
22,50000;1,88277;6090,42495
22,56000;1,88785;6117,75778
22,62000;1,89276;6141,07884
22,68000;1,89790;6172,21631
22,74000;1,90286;6192,72031
22,80000;1,90782;6214,49798
22,86000;1,91279;6237,29825
22,92000;1,91781;6263,72471
22,98000;1,92283;6287,82138
23,04000;1,92779;6310,56204
23,10000;1,93276;6333,88385
23,16000;1,93784;6359,97653
23,22000;1,94268;6381,50498
23,28000;1,94788;6407,31007
23,34000;1,95278;6427,88634
23,40000;1,95787;6451,41080
23,46000;1,96277;6474,04343
23,52000;1,96773;6498,48655
23,58000;1,97287;6524,85639
23,64000;1,97784;6545,03256
23,70000;1,98286;6566,88884
23,76000;1,98782;6589,77255
23,82000;1,99284;6611,72196
23,88000;1,99787;6633,27724
23,94000;2,00289;6657,92897
24,00000;2,00785;6681,43034
24,06000;2,01281;6704,51447
24,12000;2,01790;6728,19167
24,18000;2,02280;6750,85783
24,24000;2,02788;6774,56856
24,30000;2,03278;6797,83449
24,36000;2,03786;6822,14350
24,42000;2,04289;6844,03107
24,48000;2,04785;6865,94769
24,54000;2,05287;6890,68511
24,60000;2,05783;6911,42902
24,66000;2,06286;6935,92355
24,72000;2,06788;6958,69476
24,78000;2,07290;6981,60678
24,84000;2,07786;7003,13523
24,90000;2,08283;7024,30531
24,96000;2,08785;7045,17588
25,02000;2,09281;7067,41214
25,08000;2,09777;7089,68490
25,14000;2,10286;7112,16331
25,20000;2,10776;7132,68891
25,26000;2,11284;7154,97881
25,32000;2,11780;7176,88650
25,38000;2,12289;7199,83429
25,44000;2,12791;7221,76582
25,50000;2,13287;7240,30957
25,56000;2,13777;7262,82224
25,62000;2,14280;7284,77985
25,68000;2,14776;7306,92446
25,74000;2,15284;7328,85972
25,80000;2,15780;7350,41797
25,86000;2,16277;7370,43247
25,92000;2,16779;7393,98077
25,98000;2,17287;7415,26261
26,04000;2,17789;7435,41121
26,10000;2,18285;7455,53374
26,16000;2,18782;7475,80007
26,22000;2,19278;7496,73918
26,28000;2,19786;7518,31606
26,34000;2,20282;7539,29392
26,40000;2,20785;7560,33659
26,46000;2,21281;7580,54107
26,52000;2,21789;7601,10691
26,58000;2,22285;7621,25030
26,64000;2,22794;7642,32725
26,70000;2,23296;7662,30673
26,76000;2,23798;7682,31079
26,82000;2,24282;7703,56879
26,88000;2,24785;7723,66747
26,94000;2,25287;7743,72593
27,00000;2,25789;7764,68888
27,06000;2,26285;7783,82346
27,12000;2,26793;7807,09535
27,18000;2,27290;7825,11532
27,24000;2,27792;7844,07854
27,30000;2,28288;7863,31594
27,36000;2,28784;7882,17187
27,42000;2,29287;7902,22436
27,48000;2,29789;7920,03274
27,54000;2,30291;7940,57325
27,60000;2,30781;7958,48966
27,66000;2,31278;7978,46243
27,72000;2,31786;8000,92444
27,78000;2,32288;8017,71581
27,84000;2,32784;8036,37356
27,90000;2,33281;8054,67963
27,96000;2,33777;8073,23307
28,02000;2,34285;8093,55304
28,08000;2,34781;8111,87103
28,14000;2,35290;8132,43538
28,20000;2,35780;8149,57470
28,26000;2,36282;8170,04368
28,32000;2,36784;8190,19899
28,38000;2,37287;8206,37569
28,44000;2,37783;8225,96177
28,50000;2,38279;8240,68189
28,56000;2,38781;8260,50043
28,62000;2,39284;8277,93032
28,68000;2,39780;8297,29438
28,74000;2,40288;8315,77182
28,80000;2,40784;8332,13851
28,86000;2,41292;8352,05466
28,92000;2,41789;8368,98759
28,98000;2,42291;8388,30769
29,04000;2,42787;8406,70615
29,10000;2,43283;8422,03870
29,16000;2,43792;8440,59885
29,22000;2,44282;8457,83278
29,28000;2,44802;8477,79736
29,34000;2,45286;8495,40383
29,40000;2,45795;8512,54463
29,46000;2,46291;8529,80688
29,52000;2,46787;8546,33674
29,58000;2,47289;8565,01907
29,64000;2,47744;8583,70364
29,70000;2,48294;8607,01874
29,76000;2,48790;8622,33043
29,82000;2,49286;8639,03090
29,88000;2,49789;8657,26322
29,94000;2,50279;8674,19690
30,00000;2,50793;8693,81949
30,06000;2,51289;8710,92975
30,12000;2,51780;8727,21896
30,18000;2,52288;8747,89134
30,24000;2,52784;8762,73215
30,30000;2,53286;8782,05597
30,36000;2,53776;8798,29749
30,42000;2,54291;8817,66751
30,48000;2,54781;8833,84719
30,54000;2,55289;8851,46111
30,60000;2,55785;8869,91397
30,66000;2,56288;8886,71577
30,72000;2,56796;8908,87827
30,78000;2,57286;8924,11694
30,84000;2,57782;8941,42538
30,90000;2,58291;8959,50422
30,96000;2,58781;8976,21512
31,02000;2,59283;8993,46769
31,08000;2,59761;9009,24578
31,14000;2,60288;9031,90672
31,20000;2,60778;9047,48067
31,26000;2,61286;9063,60373
31,32000;2,61782;9080,54337
31,38000;2,62279;9096,09944
31,44000;2,62781;9115,06340
31,50000;2,63283;9130,84820
31,56000;2,63779;9151,58764
31,62000;2,64281;9166,94105
31,68000;2,64784;9184,31953
31,74000;2,65286;9203,18067
31,80000;2,65788;9221,19021
31,86000;2,66290;9239,88298
31,92000;2,66787;9257,17875
31,98000;2,67289;9275,23971
32,04000;2,67791;9290,74213
32,10000;2,68281;9307,70114
32,16000;2,68790;9325,89397
32,22000;2,69280;9340,87411
32,28000;2,69788;9358,94921
32,34000;2,70278;9376,16751
32,40000;2,70793;9395,01077
32,46000;2,71283;9411,77979
32,52000;2,71785;9428,11891
32,58000;2,72287;9446,38550
32,64000;2,72790;9462,72314
32,70000;2,73292;9481,68337
32,76000;2,73788;9497,39739
32,82000;2,74290;9516,73314
32,88000;2,74792;9533,47757
32,94000;2,75283;9547,93617
33,00000;2,75791;9565,50837
33,06000;2,76275;9581,92050
33,12000;2,76784;9601,10500
33,18000;2,77286;9617,22955
33,24000;2,77782;9631,79842
33,30000;2,78290;9649,37955
33,36000;2,78780;9665,37967
33,42000;2,79289;9684,31532
33,48000;2,79785;9699,86543
33,54000;2,80287;9715,35444
33,60000;2,80783;9731,78372
33,66000;2,81280;9747,58416
33,72000;2,81776;9764,77712
33,78000;2,82266;9780,87112
33,84000;2,82780;9801,38555
33,90000;2,83289;9816,85519
33,96000;2,83785;9832,83818
34,02000;2,84287;9850,17419
34,08000;2,84783;9865,82041
34,14000;2,85286;9881,97997
34,20000;2,85782;9897,85194
34,26000;2,86284;9912,12726
34,32000;2,86774;9929,25316
34,38000;2,87289;9948,59487
34,44000;2,87785;9965,07183
34,50000;2,88281;9979,42835
34,56000;2,88795;9998,32228
34,62000;2,89291;10016,12172
34,68000;2,89794;10030,19884
34,74000;2,90290;10046,94402
34,80000;2,90792;10062,48817
34,86000;2,91288;10082,90127
34,92000;2,91797;10098,22711
34,98000;2,92287;10112,54415
35,04000;2,92783;10128,77971
35,10000;2,93285;10145,52861
35,16000;2,93794;10160,89618
35,22000;2,94290;10176,24214
35,28000;2,94798;10193,85606
35,34000;2,95288;10209,83309
35,40000;2,95791;10227,69287
35,46000;2,96281;10245,72402
35,52000;2,96783;10258,34605
35,58000;2,97285;10277,58569
35,64000;2,97788;10293,45617
35,70000;2,98284;10309,77070
35,76000;2,98786;10326,31621
35,82000;2,99282;10342,05928
35,88000;2,99790;10358,74560
35,94000;3,00287;10376,08981
36,00000;3,00783;10390,64676
36,06000;3,01285;10410,86167
36,12000;3,01781;10425,77699
36,18000;3,02290;10443,89084
36,24000;3,02780;10458,07227
36,30000;3,03282;10473,54490
36,36000;3,03778;10489,74618
36,42000;3,04287;10508,88002
36,48000;3,04789;10524,98892
36,54000;3,05285;10538,60411
36,60000;3,05787;10555,97067
36,66000;3,06284;10574,70217
36,72000;3,06786;10589,06987
36,78000;3,07288;10603,85704
36,84000;3,07778;10619,05622
36,90000;3,08281;10638,76450
36,96000;3,08777;10654,56495
37,02000;3,09297;10676,77364
37,08000;3,09787;10691,96984
37,14000;3,10290;10704,87425
37,20000;3,10786;10720,46012
37,26000;3,11282;10735,86717
37,32000;3,11790;10756,26537
37,38000;3,12286;10770,05491
37,44000;3,12789;10785,06932
37,50000;3,13285;10800,62613
37,56000;3,13799;10818,79139
37,62000;3,14289;10834,67007
37,68000;3,14786;10849,19125
37,74000;3,15282;10865,08557
37,80000;3,15784;10881,96337
37,86000;3,16286;10897,97243
37,92000;3,16795;10917,91689
37,98000;3,17285;10930,47410
38,04000;3,17793;10947,03004
38,10000;3,18283;10961,28747
38,16000;3,18792;10977,82925
38,22000;3,19282;10993,50750
38,28000;3,19784;11009,08071
38,34000;3,20280;11027,91727
38,40000;3,20783;11043,37573
38,46000;3,21285;11060,77880
38,52000;3,21787;11076,74092
38,58000;3,22283;11093,87130
38,64000;3,22792;11110,46523
38,70000;3,23282;11124,50659
38,76000;3,23784;11138,77222
38,82000;3,24280;11153,89168
38,88000;3,24777;11168,24076
38,94000;3,25279;11184,88163
39,00000;3,25775;11199,30446
39,06000;3,26283;11215,76875
39,12000;3,26779;11230,07759
39,18000;3,27288;11247,54548
39,24000;3,27778;11261,58461
39,30000;3,28286;11277,98706
39,36000;3,28782;11292,50750
39,42000;3,29285;11308,00620
39,48000;3,29781;11324,14341
39,54000;3,30277;11339,30460
39,60000;3,30779;11354,63715
39,66000;3,31282;11370,28858
39,72000;3,31784;11386,89071
39,78000;3,32286;11401,62125
39,84000;3,32782;11415,47486
39,90000;3,33285;11429,72857
39,96000;3,33787;11446,97368
40,02000;3,34289;11462,20639
40,08000;3,34779;11476,60762
40,14000;3,35288;11491,28228
40,20000;3,35790;11506,34363
40,26000;3,36286;11521,78347
40,32000;3,36788;11537,99146
40,38000;3,37284;11549,74252
40,44000;3,37793;11565,05793
40,50000;3,38289;11578,75061
40,56000;3,38791;11592,85009
40,62000;3,39293;11608,27205
40,68000;3,39790;11622,46838
40,74000;3,40286;11636,35179
40,80000;3,40788;11651,06371
40,86000;3,41284;11664,64835
40,92000;3,41787;11679,82221
40,98000;3,42283;11694,38884
41,04000;3,42791;11709,01060
41,10000;3,43281;11722,11468
41,16000;3,43790;11737,99708
41,22000;3,44286;11752,42066
41,28000;3,44788;11766,46426
41,34000;3,45284;11779,65552
41,40000;3,45781;11790,94240
41,46000;3,46283;11807,79338
41,52000;3,46785;11821,01592
41,58000;3,47281;11834,64676
41,64000;3,47789;11847,12574
41,70000;3,48286;11860,45185
41,76000;3,48782;11874,05139
41,82000;3,49290;11889,52923
41,88000;3,49786;11901,57011
41,94000;3,50289;11916,07937
42,00000;3,50785;11927,57711
42,06000;3,51287;11942,34639
42,12000;3,51783;11954,25019
42,18000;3,52298;11972,04068
42,24000;3,52788;11982,48565
42,30000;3,53284;11995,73427
42,36000;3,53786;12008,41442
42,42000;3,54289;12021,90146
42,48000;3,54791;12036,38762
42,54000;3,55293;12048,05151
42,60000;3,55795;12062,11299
42,66000;3,56292;12075,33255
42,72000;3,56788;12086,34377
42,78000;3,57290;12098,61562
42,84000;3,57780;12111,27192
42,90000;3,58289;12124,46168
42,96000;3,58785;12136,87137
43,02000;3,59287;12148,97782
43,08000;3,59789;12162,26518
43,14000;3,60286;12173,11025
43,20000;3,60794;12187,98831
43,26000;3,61284;12198,39007
43,32000;3,61792;12211,58132
43,38000;3,62282;12222,72664
43,44000;3,62791;12237,33649
43,50000;3,63281;12249,87656
43,56000;3,63777;12262,05230
43,62000;3,64285;12276,41031
43,68000;3,64788;12288,82298
43,74000;3,65290;12304,76871
43,80000;3,65792;12317,84448
43,86000;3,66288;12328,52042
43,92000;3,66791;12339,65680
43,98000;3,67281;12350,45344
44,04000;3,67795;12362,79160
44,10000;3,68285;12378,32829
44,16000;3,68782;12386,16630
44,22000;3,69284;12399,32254
44,28000;3,69780;12409,21244
44,34000;3,70282;12422,65031
44,40000;3,70791;12434,85361
44,46000;3,71281;12445,31870
44,52000;3,71795;12460,62070
44,58000;3,72285;12469,20079
44,64000;3,72782;12481,92638
44,70000;3,73284;12494,80620
44,76000;3,73786;12508,19266
44,82000;3,74288;12519,53244
44,88000;3,74761;12530,32982
44,94000;3,75299;12549,05462
45,00000;3,75789;12557,26963
45,06000;3,76291;12569,84621
45,12000;3,76787;12580,03265
45,18000;3,77290;12593,66572
45,24000;3,77786;12605,27372
45,30000;3,78300;12620,47887
45,36000;3,78790;12632,76488
45,42000;3,79281;12642,39103
45,48000;3,79783;12655,38335
45,54000;3,80285;12666,90046
45,60000;3,80781;12681,47677
45,66000;3,81290;12694,15915
45,72000;3,81786;12705,96385
45,78000;3,82294;12722,91839
45,84000;3,82784;12732,90217
45,90000;3,83287;12744,91102
45,96000;3,83789;12758,84211
46,02000;3,84279;12767,86029
46,08000;3,84793;12785,04133
46,14000;3,85283;12794,78222
46,20000;3,85792;12808,88766
46,26000;3,86276;12819,80872
46,32000;3,86784;12832,60882
46,38000;3,87286;12846,69638
46,44000;3,87789;12859,43538
46,50000;3,88285;12872,02984
46,56000;3,88781;12883,86732
46,62000;3,89277;12896,64060
46,68000;3,89780;12911,17370
46,74000;3,90276;12923,59829
46,80000;3,90784;12936,64575
46,86000;3,91274;12948,66502
46,92000;3,91777;12962,35919
46,98000;3,92273;12973,67364
47,04000;3,92781;12986,89097
47,10000;3,93259;13000,17685
47,16000;3,93786;13014,58180
47,22000;3,94288;13025,97523
47,28000;3,94784;13036,81433
47,34000;3,95286;13050,24773
47,40000;3,95783;13062,83474
47,46000;3,96291;13078,60911
47,52000;3,96787;13090,42275
47,58000;3,97283;13103,23030
47,64000;3,97779;13117,03473
47,70000;3,98282;13130,17756
47,76000;3,98784;13145,75374
47,82000;3,99292;13158,63729
47,88000;3,99788;13170,88008
47,94000;4,00291;13184,74561
48,00000;4,00775;13196,22397
48,06000;4,01289;13214,68651
48,12000;4,01785;13225,83258
48,18000;4,02294;13236,93097
48,24000;4,02790;13251,56391
48,30000;4,03280;13263,10933
48,36000;4,03788;13278,96416
48,42000;4,04291;13291,42898
48,48000;4,04793;13308,49230
48,54000;4,05295;13320,08839
48,60000;4,05785;13331,91246
48,66000;4,06282;13345,89571
48,72000;4,06784;13361,95618
48,78000;4,07286;13376,11973
48,84000;4,07752;13389,33706
48,90000;4,08285;13406,55833
48,96000;4,08793;13420,36426
49,02000;4,09289;13431,63848
49,08000;4,09791;13447,47543
49,14000;4,10269;13459,08046
49,20000;4,10790;13476,29279
49,26000;4,11286;13488,99901
49,32000;4,11788;13500,22256
49,38000;4,12284;13514,93746
49,44000;4,12781;13527,22496
49,50000;4,13289;13541,85790
49,56000;4,13785;13555,25255
49,62000;4,14269;13566,89483
49,68000;4,14796;13584,84477
49,74000;4,15286;13595,44396
49,80000;4,15794;13609,45702
49,86000;4,16284;13622,41656
49,92000;4,16793;13636,99883
49,98000;4,17283;13651,81953
50,04000;4,17791;13663,58548
50,10000;4,18287;13678,84576
50,16000;4,18790;13690,49400
50,22000;4,19292;13705,12545
50,28000;4,19788;13717,94492
50,34000;4,20284;13731,57352
50,40000;4,20786;13746,74737
50,46000;4,21289;13759,65178
50,52000;4,21785;13774,59466
50,58000;4,22281;13785,08359
50,64000;4,22783;13797,45007
50,70000;4,23286;13811,36477
50,76000;4,23788;13826,89178
50,82000;4,24290;13840,62618
50,88000;4,24780;13851,67688
50,94000;4,25295;13867,91170
51,00000;4,25791;13883,12727
51,06000;4,26293;13895,17337
51,12000;4,26789;13908,17463
51,18000;4,27280;13919,36392
51,24000;4,27794;13936,92046
51,30000;4,28290;13951,00653
51,36000;4,28786;13964,09869
51,42000;4,29289;13977,35029
51,48000;4,29767;13988,15960
51,54000;4,30287;14006,19745
51,60000;4,30783;14018,61608
51,66000;4,31291;14030,70986
51,72000;4,31788;14044,32058
51,78000;4,32284;14054,68136
51,84000;4,32786;14070,15771
51,90000;4,33288;14083,49723
51,96000;4,33797;14096,49700
52,02000;4,34281;14105,95477
52,08000;4,34789;14121,21803
52,14000;4,35279;14133,89891
52,20000;4,35794;14150,47497
52,26000;4,36284;14164,27344
52,32000;4,36786;14173,70737
52,38000;4,37282;14187,64740
52,44000;4,37785;14200,51455
52,50000;4,38281;14214,16998
52,56000;4,38783;14226,81659
52,62000;4,39279;14242,37490
52,68000;4,39782;14256,51759
52,74000;4,40278;14267,60107
52,80000;4,40786;14281,15368
52,86000;4,41276;14292,73784
52,92000;4,41785;14306,59443
52,98000;4,42287;14321,64907
53,04000;4,42795;14334,29569
53,10000;4,43291;14349,98363
53,16000;4,43781;14358,38938
53,22000;4,44290;14373,39783
53,28000;4,44786;14385,37538
53,34000;4,45282;14398,02051
53,40000;4,45784;14414,00200
53,46000;4,46287;14426,50259
53,52000;4,46789;14439,08662
53,58000;4,47285;14451,27875
53,64000;4,47793;14464,06245
53,70000;4,48290;14479,35104
53,76000;4,48786;14490,97693
53,82000;4,49294;14505,86766
53,88000;4,49778;14517,32218
53,94000;4,50287;14530,17592
54,00000;4,50777;14544,90870
54,06000;4,51279;14559,07226
54,12000;4,51781;14574,63503
54,18000;4,52284;14585,48009
54,24000;4,52780;14598,07605
54,30000;4,53282;14611,11009
54,36000;4,53778;14624,39299
54,42000;4,54281;14637,22885
54,48000;4,54783;14649,67579
54,54000;4,55279;14661,30763
54,60000;4,55781;14676,70351
54,66000;4,56283;14689,14598
54,72000;4,56786;14702,50338
54,78000;4,57288;14714,13821
54,84000;4,57790;14726,41528
54,90000;4,58280;14738,21700
54,96000;4,58783;14753,58903
55,02000;4,59279;14766,33996
55,08000;4,59787;14781,16065
55,14000;4,60283;14794,99340
55,20000;4,60786;14807,44928
55,26000;4,61288;14822,15226
55,32000;4,61790;14833,80646
55,38000;4,62292;14846,86583
55,44000;4,62783;14858,89107
55,50000;4,63279;14872,47199
55,56000;4,63793;14885,67740
55,62000;4,64289;14899,39243
55,68000;4,64798;14911,03023
55,74000;4,65288;14923,60830
55,80000;4,65790;14937,28310
55,86000;4,66292;14949,96399
55,92000;4,66794;14962,30662
55,98000;4,67297;14976,64899
56,04000;4,67787;14987,36590
56,10000;4,68289;15000,83357
56,16000;4,68785;15012,54290
56,22000;4,69294;15027,54539
56,28000;4,69790;15042,08148
56,34000;4,70274;15053,55686
56,40000;4,70788;15070,82134
56,46000;4,71291;15081,74390
56,52000;4,71787;15093,27888
56,58000;4,72289;15108,06978
56,64000;4,72779;15120,18889
56,70000;4,73288;15136,41626
56,76000;4,73790;15140,85978
56,82000;4,74292;15156,38679
56,88000;4,74782;15171,86463
56,94000;4,75285;15185,23693
57,00000;4,75781;15201,23035
57,06000;4,76289;15209,86110
57,12000;4,76785;15225,23612
57,18000;4,77282;15235,77720
57,24000;4,77778;15250,26262
57,30000;4,78280;15263,04036
57,36000;4,78782;15276,79563
57,42000;4,79285;15291,66102
57,48000;4,79775;15303,13790
57,54000;4,80283;15316,81120
57,60000;4,80785;15330,34295
57,66000;4,81293;15345,89529
57,72000;4,81790;15360,99762
57,78000;4,82286;15372,00660
57,84000;4,82788;15387,09998
57,90000;4,83267;15398,51874
57,96000;4,83793;15416,55213
58,02000;4,84283;15427,11109
58,08000;4,84785;15440,01102
58,14000;4,85293;15457,01921
58,20000;4,85790;15466,06272
58,26000;4,86292;15478,37257
58,32000;4,86788;15490,17727
58,38000;4,87284;15502,43646
58,44000;4,87793;15519,44017
58,50000;4,88283;15528,88602
58,56000;4,88791;15541,47154
58,62000;4,89281;15552,64890
58,68000;4,89790;15565,91392
58,74000;4,90292;15578,97925
58,80000;4,90776;15589,37132
58,86000;4,91296;15606,97109
58,92000;4,91787;15615,03857
58,98000;4,92289;15628,95477
59,04000;4,92779;15640,06805
59,10000;4,93287;15652,84580
59,16000;4,93783;15663,89352
59,22000;4,94262;15674,91889
59,28000;4,94788;15692,26384
59,34000;4,95290;15700,98996
59,40000;4,95786;15709,29140
59,46000;4,96289;15720,63118
59,52000;4,96779;15730,62390
59,58000;4,97281;15743,30330
59,64000;4,97783;15756,25539
59,70000;4,98292;15765,28847
59,76000;4,98776;15772,35758
59,82000;4,99284;15780,33119
59,88000;4,99780;15788,51938
59,94000;5,00289;15790,81863
60,00000;5,01006;3006,17255