File: SU - Suspension/05 - Essais/Excels essais Optimus/Test_Rotules_31_01_19/K7_5.is_tens_RawData/Specimen_RawData_1.csv
Temps;Déplacement;Charge
(sec);(mm);(N)
0,00000;0,01387;26,61567
0,04000;0,01399;26,78411
0,08000;0,01441;27,11343
0,12000;0,01549;30,19720
0,16000;0,01698;32,37578
0,20000;0,01847;35,20829
0,24000;0,02003;37,68612
0,28000;0,02152;40,95888
0,32000;0,02302;43,90575
0,36000;0,02439;45,92152
0,40000;0,02565;47,77213
0,44000;0,02714;51,14350
0,48000;0,02852;53,78160
0,52000;0,02989;56,48097
0,56000;0,03127;58,80223
0,60000;0,03259;61,21228
0,64000;0,03402;63,77611
0,68000;0,03522;65,68881
0,72000;0,03653;67,79397
0,76000;0,03797;69,71580
0,80000;0,03928;73,09440
0,84000;0,04066;74,87835
0,88000;0,04203;77,55177
0,92000;0,04341;79,22540
0,96000;0,04478;81,39252
1,00000;0,04604;83,57610
1,04000;0,04723;85,62061
1,08000;0,04867;87,78435
1,12000;0,04998;90,46334
1,16000;0,05136;92,23181
1,20000;0,05267;94,05848
1,24000;0,05399;96,74022
1,28000;0,05537;98,59137
1,32000;0,05662;100,59336
1,36000;0,05788;102,23448
1,40000;0,05931;104,71300
1,44000;0,06063;107,45802
1,48000;0,06194;108,93574
1,52000;0,06332;112,09120
1,56000;0,06463;115,27922
1,60000;0,06601;118,51024
1,64000;0,06720;122,18121
1,68000;0,06858;124,08444
1,72000;0,07001;127,38322
1,76000;0,07133;131,49300
1,80000;0,07270;135,01272
1,84000;0,07402;138,52861
1,88000;0,07533;142,23120
1,92000;0,07671;146,47824
1,96000;0,07791;149,09900
2,00000;0,07922;152,79822
2,04000;0,08066;157,76790
2,08000;0,08197;161,34925
2,12000;0,08335;165,59017
2,16000;0,08466;168,54384
2,20000;0,08604;172,69505
2,24000;0,08735;177,31203
2,28000;0,08855;181,40536
2,32000;0,08998;185,91775
2,36000;0,09136;190,57976
2,40000;0,09273;194,48821
2,44000;0,09411;200,34830
2,48000;0,09542;204,84771
2,52000;0,09680;210,28034
2,56000;0,09811;215,44641
2,60000;0,09925;218,75924
2,64000;0,10069;223,59474
2,68000;0,10200;229,33111
2,72000;0,10332;234,43338
2,76000;0,10463;239,56595
2,80000;0,10601;244,93528
2,84000;0,10738;250,67187
2,88000;0,10870;255,96130
2,92000;0,10989;260,60343
2,96000;0,11127;265,90582
3,00000;0,11264;271,65888
3,04000;0,11402;277,61681
3,08000;0,11533;282,59773
3,12000;0,11665;289,09794
3,16000;0,11802;294,95128
3,20000;0,11928;301,95753
3,24000;0,12054;306,82005
3,28000;0,12197;312,88594
3,32000;0,12335;319,11980
3,36000;0,12466;325,21707
3,40000;0,12598;330,84201
3,44000;0,12729;337,62048
3,48000;0,12867;343,87675
3,52000;0,12992;349,12867
3,56000;0,13118;354,95032
3,60000;0,13261;361,77323
3,64000;0,13399;368,30585
3,68000;0,13530;373,82520
3,72000;0,13668;378,95690
3,76000;0,13805;384,57878
3,80000;0,13943;389,12720
3,84000;0,14062;390,70430
3,88000;0,14194;390,92056
3,92000;0,14338;393,35270
3,96000;0,14475;395,56432
4,00000;0,14607;397,59665
4,04000;0,14738;388,87670
4,08000;0,14876;378,04698
4,12000;0,15007;382,18175
4,16000;0,15127;388,35581
4,20000;0,15258;394,90927
4,24000;0,15402;400,19248
4,28000;0,15533;402,23473
4,32000;0,15671;404,15949
4,36000;0,15802;407,46145
4,40000;0,15934;411,60714
4,44000;0,16071;418,15429
4,48000;0,16191;422,68219
4,52000;0,16329;429,10785
4,56000;0,16466;437,41390
4,60000;0,16604;444,12739
4,64000;0,16735;451,44646
4,68000;0,16867;458,62827
4,72000;0,17004;465,19563
4,76000;0,17136;472,86376
4,80000;0,17255;478,22688
4,84000;0,17393;485,81036
4,88000;0,17530;494,24903
4,92000;0,17662;501,06798
4,96000;0,17799;508,32699
5,00000;0,17931;515,84761
5,04000;0,18068;522,95630
5,08000;0,18200;530,33545
5,12000;0,18320;536,13563
5,16000;0,18457;543,95124
5,20000;0,18595;551,56201
5,24000;0,18732;558,34730
5,28000;0,18870;566,92297
5,32000;0,19007;573,98248
5,36000;0,19145;581,58664
5,40000;0,19270;589,56132
5,44000;0,19396;595,58772
5,48000;0,19533;602,09725
5,52000;0,19665;610,11403
5,56000;0,19796;616,67818
5,60000;0,19934;624,22422
5,64000;0,20065;631,49193
5,68000;0,20203;638,66619
5,72000;0,20328;645,61060
5,76000;0,20454;651,66792
5,80000;0,20597;659,24446
5,84000;0,20735;667,18836
5,88000;0,20867;673,75912
5,92000;0,20998;680,92346
5,96000;0,21136;687,43732
6,00000;0,21273;695,01055
6,04000;0,21399;702,82402
6,08000;0,21524;707,85950
6,12000;0,21668;715,64219
6,16000;0,21799;722,70641
6,20000;0,21937;729,06981
6,24000;0,22062;735,49347
6,28000;0,22200;742,30912
6,32000;0,22337;749,47057
6,36000;0,22457;755,73525
6,40000;0,22588;761,48799
6,44000;0,22732;767,90084
6,48000;0,22864;774,27393
6,52000;0,22995;778,41543
6,56000;0,23127;783,16024
6,60000;0,23264;786,70960
6,64000;0,23402;789,18990
6,68000;0,23527;790,11461
6,72000;0,23659;789,03399
6,76000;0,23802;790,08294
6,80000;0,23934;789,98646
6,84000;0,24071;790,35517
6,88000;0,24203;791,59979
6,92000;0,24340;793,92418
6,96000;0,24472;798,08049
7,00000;0,24591;800,02146
7,04000;0,24729;802,89971
7,08000;0,24872;807,11907
7,12000;0,25004;809,84272
7,16000;0,25135;812,73662
7,20000;0,25267;816,67537
7,24000;0,25405;820,71926
7,28000;0,25536;823,76441
7,32000;0,25656;825,96717
7,36000;0,25793;829,45116
7,40000;0,25931;834,57390
7,44000;0,26068;837,54575
7,48000;0,26206;840,87308
7,52000;0,26343;844,09593
7,56000;0,26481;847,40045
7,60000;0,26600;849,65043
7,64000;0,26726;851,11000
7,68000;0,26863;854,60497
7,72000;0,27001;858,57008
7,76000;0,27138;861,75716
7,80000;0,27270;864,56006
7,84000;0,27408;866,78620
7,88000;0,27545;870,38660
7,92000;0,27665;872,96208
7,96000;0,27790;874,07967
8,00000;0,27928;878,08464
8,04000;0,28059;881,75256
8,08000;0,28197;885,63273
8,12000;0,28328;889,97800
8,16000;0,28466;892,40978
8,20000;0,28603;896,41921
8,24000;0,28723;898,35683
8,28000;0,28860;901,64272
8,32000;0,29004;905,26557
8,36000;0,29135;909,19770
8,40000;0,29267;912,48248
8,44000;0,29398;915,40907
8,48000;0,29536;918,65174
8,52000;0,29674;922,64432
8,56000;0,29793;924,91191
8,60000;0,29925;927,56059
8,64000;0,30068;932,02526
8,68000;0,30200;935,54156
8,72000;0,30331;938,35443
8,76000;0,30463;941,33802
8,80000;0,30600;944,59970
8,84000;0,30732;948,76224
8,88000;0,30857;951,86811
8,92000;0,30989;955,04895
8,96000;0,31132;960,09029
9,00000;0,31264;963,14186
9,04000;0,31395;967,02492
9,08000;0,31533;970,31891
9,12000;0,31676;973,38548
9,16000;0,31802;978,24112
9,20000;0,31928;979,10920
9,24000;0,32071;982,68893
9,28000;0,32203;988,35509
9,32000;0,32334;990,17685
9,36000;0,32472;994,26685
9,40000;0,32609;997,82292
9,44000;0,32741;1000,69651
9,48000;0,32866;1003,73756
9,52000;0,32986;1006,71453
9,56000;0,33129;1010,59014
9,60000;0,33267;1015,52289
9,64000;0,33398;1018,29171
9,68000;0,33536;1020,88563
9,72000;0,33667;1024,77083
9,76000;0,33805;1027,55353
9,80000;0,33925;1030,99840
9,84000;0,34062;1033,43567
9,88000;0,34206;1037,50974
9,92000;0,34337;1040,48029
9,96000;0,34475;1043,80576
10,00000;0,34606;1046,93649
10,04000;0,34738;1050,62695
10,08000;0,34875;1053,69445
10,12000;0,34995;1056,04809
10,16000;0,35120;1057,31320
10,20000;0,35264;1062,59109
10,24000;0,35395;1066,56253
10,28000;0,35527;1070,04251
10,32000;0,35664;1073,51150
10,36000;0,35802;1076,82245
10,40000;0,35933;1079,33413
10,44000;0,36053;1081,30658
10,48000;0,36191;1082,98706
10,52000;0,36334;1086,20645
10,56000;0,36466;1087,80665
10,60000;0,36603;1090,73315
10,64000;0,36741;1091,59807
10,68000;0,36878;1092,40850
10,72000;0,37010;1093,13643
10,76000;0,37129;1092,35840
10,80000;0,37267;1092,75347
10,84000;0,37404;1092,37079
10,88000;0,37536;1092,09064
10,92000;0,37667;1091,70210
10,96000;0,37799;1090,36136
11,00000;0,37942;1089,60057
11,04000;0,38068;1089,41318
11,08000;0,38194;1086,91780
11,12000;0,38331;1085,86941
11,16000;0,38469;1086,69968
11,20000;0,38600;1085,27048
11,24000;0,38738;1083,59242
11,28000;0,38869;1082,47604
11,32000;0,38995;1080,74471
11,36000;0,39132;1080,50145
11,40000;0,39264;1076,44862
11,44000;0,39407;1073,51206
11,48000;0,39539;1069,71627
11,52000;0,39670;1064,64587
11,56000;0,39802;1060,38284
11,60000;0,39939;1055,43016
11,64000;0,40071;1051,55949
11,68000;0,40190;1047,10078
11,72000;0,40322;1042,28025
11,76000;0,40466;1039,92317
11,80000;0,40597;1035,52621
11,84000;0,40735;1030,77898
11,88000;0,40866;1025,76250
11,92000;0,41004;1021,43791
11,96000;0,41141;1018,36277
12,00000;0,41261;1014,90533
12,04000;0,41392;1010,32918
12,08000;0,41536;1008,97048
12,12000;0,41667;1006,08710
12,16000;0,41805;1001,95622
12,20000;0,41936;998,89692
12,24000;0,42080;995,04823
12,28000;0,42205;991,99032
12,32000;0,42325;987,50545
12,36000;0,42457;983,54835
12,40000;0,42600;983,23254
12,44000;0,42738;981,51369
12,48000;0,42875;978,58058
12,52000;0,43007;976,09926
12,56000;0,43144;974,22265
12,60000;0,43270;971,97350
12,64000;0,43389;967,24089
12,68000;0,43533;966,62315
12,72000;0,43670;967,97552
12,76000;0,43802;965,59869
12,80000;0,43939;963,42508
12,84000;0,44071;962,34027
12,88000;0,44214;962,24751
12,92000;0,44334;959,85057
12,96000;0,44459;956,98340
13,00000;0,44597;956,53087
13,04000;0,44729;955,99024
13,08000;0,44860;954,81249
13,12000;0,44998;953,99339
13,16000;0,45129;952,21363
13,20000;0,45273;952,39393
13,24000;0,45398;949,66069
13,28000;0,45524;945,40445
13,32000;0,45661;943,80109
13,36000;0,45799;942,93524
13,40000;0,45930;940,16362
13,44000;0,46068;938,42298
13,48000;0,46199;935,55627
13,52000;0,46337;933,60115
13,56000;0,46462;930,57482
13,60000;0,46594;926,97851
13,64000;0,46737;925,58572
13,68000;0,46869;922,80833
13,72000;0,46995;919,04616
13,76000;0,47132;916,95497
13,80000;0,47264;914,73563
13,84000;0,47401;912,47102
13,88000;0,47527;910,04726
13,92000;0,47658;907,49310
13,96000;0,47802;906,63061
14,00000;0,47933;904,30453
14,04000;0,48071;901,81539
14,08000;0,48208;899,56531
14,12000;0,48340;896,77470
14,16000;0,48471;896,03867
14,20000;0,48591;892,83725
14,24000;0,48728;890,42634
14,28000;0,48866;890,46685
14,32000;0,49003;890,08491
14,36000;0,49135;886,73132
14,40000;0,49267;884,55146
14,44000;0,49404;883,01469
14,48000;0,49536;881,57700
14,52000;0,49655;879,13014
14,56000;0,49787;876,84039
14,60000;0,49936;876,80416
14,64000;0,50068;875,52536
14,68000;0,50205;871,75574
14,72000;0,50337;870,21822
14,76000;0,50474;868,60601
14,80000;0,50606;866,86639
14,84000;0,50725;862,99861
14,88000;0,50863;861,74337
14,92000;0,51000;863,08951
14,96000;0,51132;861,57750
15,00000;0,51264;859,50606
15,04000;0,51401;857,36969
15,08000;0,51539;856,59334
15,12000;0,51670;855,03561
15,16000;0,51790;851,72690
15,20000;0,51933;851,38269
15,24000;0,52065;851,03996
15,28000;0,52190;850,57952
15,32000;0,52340;850,18864
15,36000;0,52477;848,70299
15,40000;0,52615;846,88151
15,44000;0,52728;845,81906
15,48000;0,52860;842,66411
15,52000;0,53003;844,26459
15,56000;0,53135;843,64153
15,60000;0,53266;841,94345
15,64000;0,53398;840,01934
15,68000;0,53541;841,01288
15,72000;0,53679;840,03974
15,76000;0,53799;837,90971
15,80000;0,53930;835,28738
15,84000;0,54074;836,66248
15,88000;0,54199;835,09255
15,92000;0,54337;833,63475
15,96000;0,54468;832,38436
16,00000;0,54606;832,65342
16,04000;0,54743;831,58063
16,08000;0,54863;830,89462
16,12000;0,54988;828,75947
16,16000;0,55138;830,95254
16,20000;0,55269;828,46247
16,24000;0,55401;825,54240
16,28000;0,55538;823,34103
16,32000;0,55670;822,99886
16,36000;0,55802;821,45212
16,40000;0,55921;819,98957
16,44000;0,56065;818,52702
16,48000;0,56202;821,27647
16,52000;0,56334;817,87314
16,56000;0,56471;815,91243
16,60000;0,56603;814,59340
16,64000;0,56740;813,29672
16,68000;0,56872;811,76888
16,72000;0,56991;809,64966
16,76000;0,57135;809,00863
16,80000;0,57260;808,74898
16,84000;0,57410;807,21006
16,88000;0,57541;805,91403
16,92000;0,57679;802,76299
16,96000;0,57810;801,40484
17,00000;0,57930;798,77870
17,04000;0,58056;797,71057
17,08000;0,58199;797,70153
17,12000;0,58331;796,94195
17,16000;0,58462;795,20410
17,20000;0,58600;795,02668
17,24000;0,58731;793,49801
17,28000;0,58869;792,61474
17,32000;0,58994;790,54637
17,36000;0,59126;788,46933
17,40000;0,59269;789,47917
17,44000;0,59401;789,86064
17,48000;0,59538;787,96642
17,52000;0,59670;787,27175
17,56000;0,59807;786,43644
17,60000;0,59939;785,77716
17,64000;0,60065;784,37822
17,68000;0,60196;782,56205
17,72000;0,60334;783,36000
17,76000;0,60459;782,41779
17,80000;0,60597;781,78598
17,84000;0,60734;783,06003
17,88000;0,60872;781,92791
17,92000;0,61003;778,79098
17,96000;0,61123;775,44409
18,00000;0,61260;774,32380
18,04000;0,61398;775,05424
18,08000;0,61529;774,79677
18,12000;0,61667;773,94275
18,16000;0,61804;772,99117
18,20000;0,61942;773,19620
18,24000;0,62073;772,65976
18,28000;0,62199;770,11730
18,32000;0,62331;769,47743
18,36000;0,62468;770,39013
18,40000;0,62606;769,42220
18,44000;0,62737;767,45064
18,48000;0,62869;766,50209
18,52000;0,63006;764,69635
18,56000;0,63138;765,14487
18,60000;0,63257;761,69763
18,64000;0,63395;760,78945
18,68000;0,63532;760,63462
18,72000;0,63664;760,64714
18,76000;0,63771;758,78352
18,80000;0,63945;760,72980
18,84000;0,64076;758,21937
18,88000;0,64196;754,65175
18,92000;0,64322;752,65435
18,96000;0,64471;753,62870
19,00000;0,64603;752,60131
19,04000;0,64740;750,41256
19,08000;0,64872;749,48701
19,12000;0,65003;748,77269
19,16000;0,65141;748,28598
19,20000;0,65260;746,29127
19,24000;0,65386;744,02946
19,28000;0,65535;744,90444
19,32000;0,65667;744,40902
19,36000;0,65798;742,41734
19,40000;0,65936;740,75507
19,44000;0,66067;741,60607
19,48000;0,66205;740,44745
19,52000;0,66330;738,97676
19,56000;0,66456;737,58927
19,60000;0,66588;739,44740
19,64000;0,66737;742,28346
19,68000;0,66875;738,30620
19,72000;0,67006;735,96137
19,76000;0,67144;736,25967
19,80000;0,67275;735,23377
19,84000;0,67395;733,59902
19,88000;0,67526;731,62895
19,92000;0,67664;733,21983
19,96000;0,67795;732,55263
20,00000;0,67933;731,16943
20,04000;0,68064;729,55703
20,08000;0,68202;728,72597
20,12000;0,68333;728,00620
20,16000;0,68459;725,50545
20,20000;0,68596;725,56576
20,24000;0,68734;725,86252
20,28000;0,68866;724,85558
20,32000;0,68991;724,61320
20,36000;0,69135;726,01987
20,40000;0,69272;722,97347
20,44000;0,69404;720,93192
20,48000;0,69523;719,37069
20,52000;0,69667;719,00915
20,56000;0,69798;718,96794
20,60000;0,69936;717,52346
20,64000;0,70067;716,41156
20,68000;0,70199;715,40973
20,72000;0,70342;715,65690
20,76000;0,70462;713,89819
20,80000;0,70587;711,79061
20,84000;0,70731;710,86478
20,88000;0,70868;711,44230
20,92000;0,71000;709,97635
20,96000;0,71132;708,79590
21,00000;0,71269;707,20776
21,04000;0,71407;707,83668
21,08000;0,71526;706,43756
21,12000;0,71658;705,59457
21,16000;0,71801;705,20430
21,20000;0,71939;704,78213
21,24000;0,72070;703,35185
21,28000;0,72202;701,89680
21,32000;0,72339;700,37087
21,36000;0,72471;701,02601
21,40000;0,72596;699,89651
21,44000;0,72728;698,19367
21,48000;0,72871;698,91191
21,52000;0,73003;698,59028
21,56000;0,73135;696,21569
21,60000;0,73266;696,10099
21,64000;0,73404;695,48339
21,68000;0,73541;696,65345
21,72000;0,73661;693,72444
21,76000;0,73792;693,00965
21,80000;0,73936;694,71304
21,84000;0,74067;694,17395
21,88000;0,74205;692,47396
21,92000;0,74336;691,70278
21,96000;0,74468;689,97587
22,00000;0,74599;690,15957
22,04000;0,74719;687,80771
22,08000;0,74862;687,89977
22,12000;0,75000;688,70247
22,16000;0,75131;686,70851
22,20000;0,75269;685,27060
22,24000;0,75407;685,46226
22,28000;0,75544;684,76051
22,32000;0,75670;683,50434
22,36000;0,75795;681,17920
22,40000;0,75933;681,05930
22,44000;0,76070;681,74256
22,48000;0,76202;681,08244
22,52000;0,76339;679,61956
22,56000;0,76477;679,25272
22,60000;0,76614;678,20721
22,64000;0,76734;677,13200
22,68000;0,76859;674,11773
22,72000;0,77003;675,06032
22,76000;0,77134;674,67093
22,80000;0,77266;673,24545
22,84000;0,77403;672,64191
22,88000;0,77535;671,58043
22,92000;0,77673;671,87892
22,96000;0,77798;670,39146
23,00000;0,77924;668,81273
23,04000;0,78067;669,68794
23,08000;0,78199;668,10707
23,12000;0,78336;667,91414
23,16000;0,78468;667,65118
23,20000;0,78605;666,83288
23,24000;0,78737;666,33020
23,28000;0,78862;665,48930
23,32000;0,78994;662,66274
23,36000;0,79131;663,39346
23,40000;0,79263;662,14711
23,44000;0,79400;661,39940
23,48000;0,79526;660,43129
23,52000;0,79675;662,17799
23,56000;0,79801;660,35548
23,60000;0,79927;658,50951
23,64000;0,80064;657,05436
23,68000;0,80202;658,57461
23,72000;0,80339;656,60817
23,76000;0,80477;656,52281
23,80000;0,80602;655,08340
23,84000;0,80740;655,49482
23,88000;0,80871;655,11074
23,92000;0,80997;653,99059
23,96000;0,81134;653,70081
24,00000;0,81272;653,88083
24,04000;0,81409;652,43486
24,08000;0,81541;652,05470
24,12000;0,81672;650,95974
24,16000;0,81810;650,96174
24,20000;0,81936;649,38935
24,24000;0,82061;648,87493
24,28000;0,82181;648,59642
24,32000;0,82336;651,31709
24,36000;0,82474;649,50832
24,40000;0,82605;647,66030
24,44000;0,82737;646,27333
24,48000;0,82874;646,01782
24,52000;0,83000;644,42665
24,56000;0,83119;644,02935
24,60000;0,83263;643,84397
24,64000;0,83400;644,13305
24,68000;0,83532;642,19697
24,72000;0,83663;641,35017
24,76000;0,83801;641,13941
24,80000;0,83938;640,81750
24,84000;0,84058;638,82796
24,88000;0,84184;637,92886
24,92000;0,84327;638,56612
24,96000;0,84465;639,42112
25,00000;0,84602;637,89664
25,04000;0,84740;636,86762
25,08000;0,84877;636,18002
25,12000;0,85009;635,66817
25,16000;0,85128;634,19566
25,20000;0,85254;632,79439
25,24000;0,85397;633,89451
25,28000;0,85529;634,82672
25,32000;0,85666;632,95667
25,36000;0,85804;632,90591
25,40000;0,85941;632,57748
25,44000;0,86073;631,54595
25,48000;0,86199;629,17653
25,52000;0,86330;629,00763
25,56000;0,86468;629,74729
25,60000;0,86605;629,39385
25,64000;0,86737;628,59789
25,68000;0,86874;628,04958
25,72000;0,87012;627,14852
25,76000;0,87137;627,09809
25,80000;0,87263;626,17911
25,84000;0,87400;625,38213
25,88000;0,87538;626,05347
25,92000;0,87669;624,87065
25,96000;0,87801;624,68173
26,00000;0,87932;624,93039
26,04000;0,88070;625,51759
26,08000;0,88201;623,03543
26,12000;0,88321;621,18191
26,16000;0,88465;620,93828
26,20000;0,88596;621,02377
26,24000;0,88734;619,81725
26,28000;0,88871;619,25887
26,32000;0,89003;618,34054
26,36000;0,89140;617,75544
26,40000;0,89266;618,32932
26,44000;0,89391;616,50025
26,48000;0,89535;616,24092
26,52000;0,89666;616,17563
26,56000;0,89804;614,73534
26,60000;0,89935;614,69483
26,64000;0,90067;613,71354
26,68000;0,90204;612,86832
26,72000;0,90330;612,93864
26,76000;0,90456;611,46175
26,80000;0,90599;612,58590
26,84000;0,90731;612,20592
26,88000;0,90868;611,22566
26,92000;0,91000;610,86151
26,96000;0,91131;609,35840
27,00000;0,91275;609,49246
27,04000;0,91394;608,85954
27,08000;0,91532;608,36705
27,12000;0,91669;608,61502
27,16000;0,91807;607,71452
27,20000;0,91944;606,82790
27,24000;0,92076;606,00918
27,28000;0,92207;604,75008
27,32000;0,92345;605,45010
27,36000;0,92458;603,25889
27,40000;0,92590;602,46009
27,44000;0,92734;603,21349
27,48000;0,92865;603,17046
27,52000;0,92997;601,84598
27,56000;0,93128;600,50325
27,60000;0,93266;600,05630
27,64000;0,93403;600,02818
27,68000;0,93523;598,53131
27,72000;0,93654;598,01973
27,76000;0,93798;599,08093
27,80000;0,93935;598,75795
27,84000;0,94073;597,71617
27,88000;0,94204;596,47555
27,92000;0,94342;597,06247
27,96000;0,94467;596,57088
28,00000;0,94593;594,31838
28,04000;0,94730;594,32355
28,08000;0,94868;595,38847
28,12000;0,94994;593,99265
28,16000;0,95107;593,90939
28,20000;0,95269;594,90888
28,24000;0,95406;592,75972
28,28000;0,95526;591,16180
28,32000;0,95651;589,69762
28,36000;0,95795;590,13027
28,40000;0,95932;590,27718
28,44000;0,96070;588,66632
28,48000;0,96201;588,42483
28,52000;0,96339;587,90892
28,56000;0,96476;587,13518
28,60000;0,96602;586,71790
28,64000;0,96727;585,02802
28,68000;0,96877;586,55287
28,72000;0,97008;586,35459
28,76000;0,97140;585,20059
28,80000;0,97272;584,36454
28,84000;0,97409;583,96999
28,88000;0,97541;584,26620
28,92000;0,97666;582,42581
28,96000;0,97792;580,97644
29,00000;0,97935;582,67699
29,04000;0,98067;579,81019
29,08000;0,98204;579,28883
29,12000;0,98342;580,06081
29,16000;0,98479;579,20176
29,20000;0,98605;578,18103
29,24000;0,98724;576,15964
29,28000;0,98868;577,58847
29,32000;0,99005;577,52705
29,36000;0,99137;576,76220
29,40000;0,99274;576,38576
29,44000;0,99406;576,93827
29,48000;0,99544;576,09901
29,52000;0,99663;575,08233
29,56000;0,99789;573,17466
29,60000;0,99932;573,09023
29,64000;1,00058;574,36754
29,68000;1,00201;574,48545
29,72000;1,00339;572,35281
29,76000;1,00470;571,30465
29,80000;1,00608;570,57901
29,84000;1,00733;570,37403
29,88000;1,00859;568,91791
29,92000;1,01002;569,49421
29,96000;1,01134;569,12769
30,00000;1,01265;568,65537
30,04000;1,01403;567,88139
30,08000;1,01540;567,46500
30,12000;1,01678;567,45824
30,16000;1,01798;565,52705
30,20000;1,01929;564,57226
30,24000;1,02067;565,40496
30,28000;1,02186;565,11960
30,32000;1,02336;564,85264
30,36000;1,02467;563,82916
30,40000;1,02605;562,13262
30,44000;1,02736;562,30593
30,48000;1,02862;559,98815
30,52000;1,02999;559,38978
30,56000;1,03137;560,10406
30,60000;1,03268;559,63420
30,64000;1,03406;557,45370
30,68000;1,03537;557,37868
30,72000;1,03675;557,38189
30,76000;1,03807;557,04308
30,80000;1,03932;554,59063
30,84000;1,04070;554,55533
30,88000;1,04207;554,22168
30,92000;1,04339;552,67634
30,96000;1,04470;552,37710
31,00000;1,04602;550,45560
31,04000;1,04733;549,82454
31,08000;1,04871;550,04843
31,12000;1,04990;548,89251
31,16000;1,05134;548,38732
31,20000;1,05265;549,00819
31,24000;1,05403;548,07630
31,28000;1,05540;547,35471
31,32000;1,05672;546,56249
31,36000;1,05809;546,40276
31,40000;1,05935;545,87019
31,44000;1,06061;545,12802
31,48000;1,06198;544,84624
31,52000;1,06336;545,24648
31,56000;1,06473;544,45737
31,60000;1,06605;545,07591
31,64000;1,06736;542,78774
31,68000;1,06874;542,33689
31,72000;1,06999;542,08157
31,76000;1,07119;541,05977
31,80000;1,07256;540,88910
31,84000;1,07400;542,86122
31,88000;1,07537;540,89860
31,92000;1,07675;540,36211
31,96000;1,07806;539,39535
32,00000;1,07944;539,35009
32,04000;1,08058;536,58751
32,08000;1,08195;536,35845
32,12000;1,08333;536,88833
32,16000;1,08470;537,19007
32,20000;1,08608;537,77630
32,24000;1,08739;536,63813
32,28000;1,08877;535,89172
32,32000;1,09008;535,28589
32,36000;1,09122;533,73557
32,40000;1,09259;533,60914
32,44000;1,09397;535,02452
32,48000;1,09534;533,77002
32,52000;1,09666;533,09500
32,56000;1,09797;532,12363
32,60000;1,09935;532,54711
32,64000;1,10072;531,80722
32,68000;1,10192;528,27555
32,72000;1,10330;527,84430
32,76000;1,10467;528,20947
32,80000;1,10599;526,20228
32,84000;1,10730;525,99479
32,88000;1,10868;526,34985
32,92000;1,11005;525,01811
32,96000;1,11137;524,81443
33,00000;1,11262;522,97511
33,04000;1,11400;521,76602
33,08000;1,11531;522,95756
33,12000;1,11663;521,97534
33,16000;1,11794;520,49099
33,20000;1,11932;520,24638
33,24000;1,12069;520,63856
33,28000;1,12195;520,07674
33,32000;1,12321;518,78346
33,36000;1,12464;519,57830
33,40000;1,12596;519,05238
33,44000;1,12733;518,78309
33,48000;1,12865;517,61987
33,52000;1,12996;515,69231
33,56000;1,13134;515,90991
33,60000;1,13265;515,68593
33,64000;1,13391;514,17048
33,68000;1,13534;515,56667
33,72000;1,13666;514,51195
33,76000;1,13803;512,97094
33,80000;1,13935;512,49960
33,84000;1,14072;512,33792
33,88000;1,14210;512,41349
33,92000;1,14329;510,82284
33,96000;1,14461;509,89934
34,00000;1,14604;510,26540
34,04000;1,14736;510,54684
34,08000;1,14874;509,86861
34,12000;1,15005;509,02851
34,16000;1,15143;507,78221
34,20000;1,15280;508,12033
34,24000;1,15400;507,11962
34,28000;1,15525;505,50895
34,32000;1,15675;508,09179
34,36000;1,15806;507,71884
34,40000;1,15938;504,50815
34,44000;1,16069;503,77268
34,48000;1,16207;504,16635
34,52000;1,16338;503,73920
34,56000;1,16458;500,58383
34,60000;1,16595;500,63869
34,64000;1,16739;501,89104
34,68000;1,16871;500,48972
34,72000;1,17002;498,96180
34,76000;1,17134;498,06442
34,80000;1,17277;498,35723
34,84000;1,17409;498,16617
34,88000;1,17528;495,39134
34,92000;1,17666;495,11702
34,96000;1,17797;495,89393
35,00000;1,17935;494,86831
35,04000;1,18072;496,08569
35,08000;1,18204;495,13509
35,12000;1,18335;493,45861
35,16000;1,18461;491,84808
35,20000;1,18586;490,71298
35,24000;1,18736;492,33241
35,28000;1,18867;491,69036
35,32000;1,18999;490,21561
35,36000;1,19137;490,42245
35,40000;1,19274;490,00843
35,44000;1,19412;489,55791
35,48000;1,19531;488,76675
35,52000;1,19669;487,45675
35,56000;1,19806;487,10080
35,60000;1,19932;486,14484
35,64000;1,20069;485,81562
35,68000;1,20207;485,32845
35,72000;1,20344;485,01855
35,76000;1,20476;484,32006
35,80000;1,20595;482,78733
35,84000;1,20709;482,42835
35,88000;1,20870;485,69171
35,92000;1,21002;482,64368
35,96000;1,21139;481,13014
36,00000;1,21271;481,13484
36,04000;1,21409;480,81200
36,08000;1,21534;480,44757
36,12000;1,21660;478,48127
36,16000;1,21797;479,17771
36,20000;1,21941;479,72118
36,24000;1,22072;478,13090
36,28000;1,22204;477,46743
36,32000;1,22335;477,63311
36,36000;1,22473;477,54748
36,40000;1,22604;476,61350
36,44000;1,22724;474,57446
36,48000;1,22861;474,43523
36,52000;1,22999;475,52353
36,56000;1,23130;473,71052
36,60000;1,23268;473,41040
36,64000;1,23406;472,87587
36,68000;1,23543;472,45449
36,72000;1,23663;471,56103
36,76000;1,23788;470,17899
36,80000;1,23938;470,89532
36,84000;1,24069;470,79483
36,88000;1,24207;469,73703
36,92000;1,24344;470,54882
36,96000;1,24476;467,52323
37,00000;1,24607;466,85785
37,04000;1,24733;464,98342
37,08000;1,24858;464,79357
37,12000;1,25002;465,46217
37,16000;1,25133;464,98710
37,20000;1,25265;463,08232
37,24000;1,25396;462,64804
37,28000;1,25534;461,95197
37,32000;1,25672;461,50372
37,36000;1,25797;460,89436
37,40000;1,25923;459,40448
37,44000;1,26066;460,52090
37,48000;1,26198;459,13705
37,52000;1,26329;458,60796
37,56000;1,26467;459,28634
37,60000;1,26598;458,84512
37,64000;1,26736;458,15562
37,68000;1,26861;457,13694
37,72000;1,26993;455,73139
37,76000;1,27130;456,48548
37,80000;1,27262;455,28752
37,84000;1,27399;455,35308
37,88000;1,27531;454,66172
37,92000;1,27669;454,65454
37,96000;1,27806;454,76793
38,00000;1,27920;454,23014
38,04000;1,28057;451,45638
38,08000;1,28195;452,18519
38,12000;1,28332;451,71436
38,16000;1,28464;450,97293
38,20000;1,28595;450,61936
38,24000;1,28739;450,27053
38,28000;1,28870;449,08244
38,32000;1,28990;448,32542
38,36000;1,29133;447,66767
38,40000;1,29265;447,61514
38,44000;1,29402;447,09644
38,48000;1,29540;446,75274
38,52000;1,29671;446,01518
38,56000;1,29809;444,85540
38,60000;1,29929;445,49513
38,64000;1,30054;443,97707
38,68000;1,30198;444,04091
38,72000;1,30335;444,42732
38,76000;1,30473;442,73934
38,80000;1,30604;442,77143
38,84000;1,30736;441,73077
38,88000;1,30873;441,60965
38,92000;1,30999;440,80797
38,96000;1,31124;439,28651
39,00000;1,31268;439,73187
39,04000;1,31405;439,13680
39,08000;1,31537;438,76539
39,12000;1,31668;437,09273
39,16000;1,31800;436,57729
39,20000;1,31937;435,80523
39,24000;1,32063;435,24583
39,28000;1,32189;433,77760
39,32000;1,32326;434,23492
39,36000;1,32464;434,19632
39,40000;1,32595;432,91165
39,44000;1,32733;431,97563
39,48000;1,32870;431,44654
39,52000;1,33002;430,47294
39,56000;1,33127;429,07498
39,60000;1,33259;428,28540
39,64000;1,33396;429,11414
39,68000;1,33534;428,78762
39,72000;1,33671;428,22347
39,76000;1,33803;426,88688
39,80000;1,33940;426,41913
39,84000;1,34072;425,83216
39,88000;1,34198;424,32304
39,92000;1,34329;424,09743
39,96000;1,34467;424,34814
40,00000;1,34598;423,47964
40,04000;1,34730;422,43632
40,08000;1,34861;421,85863
40,12000;1,34999;421,92661
40,16000;1,35136;420,50118
40,20000;1,35256;419,93018
40,24000;1,35393;419,01711
40,28000;1,35531;420,13959
40,32000;1,35668;418,62959
40,36000;1,35800;418,24859
40,40000;1,35931;417,63498
40,44000;1,36069;417,15698
40,48000;1,36200;416,76210
40,52000;1,36326;415,19632
40,56000;1,36464;414,56283
40,60000;1,36601;415,01028
40,64000;1,36733;414,02145
40,68000;1,36864;413,49838
40,72000;1,36996;412,80128
40,76000;1,37133;412,26819
40,80000;1,37265;412,75974
40,84000;1,37384;410,59162
40,88000;1,37528;410,43763
40,92000;1,37665;410,50692
40,96000;1,37797;409,51418
41,00000;1,37928;408,92391
41,04000;1,38066;408,65056
41,08000;1,38203;409,01201
41,12000;1,38329;407,93819
41,16000;1,38460;406,10656
41,20000;1,38604;406,93153
41,24000;1,38736;405,29328
41,28000;1,38873;404,96560
41,32000;1,39005;403,98696
41,36000;1,39142;403,36167
41,40000;1,39274;403,24358
41,44000;1,39393;401,87305
41,48000;1,39525;400,30079
41,52000;1,39668;401,04208
41,56000;1,39806;401,15863
41,60000;1,39937;399,82637
41,64000;1,40069;399,09990
41,68000;1,40206;398,50655
41,72000;1,40338;398,07414
41,76000;1,40457;396,38011
41,80000;1,40595;395,68851
41,84000;1,40738;396,31915
41,88000;1,40870;395,48017
41,92000;1,41002;394,82564
41,96000;1,41139;394,50224
42,00000;1,41283;394,39700
42,04000;1,41402;392,60406
42,08000;1,41528;390,54803
42,12000;1,41671;390,29096
42,16000;1,41803;391,22100
42,20000;1,41934;389,56511
42,24000;1,42072;388,87714
42,28000;1,42209;388,94888
42,32000;1,42347;388,36168
42,36000;1,42472;387,26358
42,40000;1,42592;385,67467
42,44000;1,42735;385,84273
42,48000;1,42867;386,54141
42,52000;1,42999;385,33078
42,56000;1,43136;384,63809
42,60000;1,43268;384,69536
42,64000;1,43405;383,76665
42,68000;1,43531;383,09870
42,72000;1,43662;381,80945
42,76000;1,43800;382,79679
42,80000;1,43931;382,28927
42,84000;1,44069;381,38626
42,88000;1,44206;381,23578
42,92000;1,44338;380,91801
42,96000;1,44475;379,91353
43,00000;1,44595;380,11933
43,04000;1,44726;378,61287
43,08000;1,44870;378,80105
43,12000;1,45001;377,82399
43,16000;1,45133;377,33205
43,20000;1,45271;376,59232
43,24000;1,45402;375,63550
43,28000;1,45540;376,19572
43,32000;1,45659;375,08444
43,36000;1,45791;373,79803
43,40000;1,45934;374,47272
43,44000;1,46066;373,28061
43,48000;1,46203;372,24030
43,52000;1,46341;372,45324
43,56000;1,46472;371,24332
43,60000;1,46610;371,01479
43,64000;1,46729;370,33670
43,68000;1,46867;370,53460
43,72000;1,47004;369,68247
43,76000;1,47136;369,10658
43,80000;1,47273;367,88315
43,84000;1,47405;367,53092
43,88000;1,47537;366,87504
43,92000;1,47674;367,35891
43,96000;1,47794;366,24016
44,00000;1,47931;364,59120
44,04000;1,48069;365,02841
44,08000;1,48206;364,10494
44,12000;1,48338;364,09176
44,16000;1,48475;362,83508
44,20000;1,48607;362,53051
44,24000;1,48738;362,28250
44,28000;1,48858;360,50582
44,32000;1,48995;360,61844
44,36000;1,49133;360,72689
44,40000;1,49270;360,19394
44,44000;1,49408;359,93753
44,48000;1,49539;359,02667
44,52000;1,49677;358,80697
44,56000;1,49797;357,93670
44,60000;1,49922;356,70975
44,64000;1,50060;356,92395
44,68000;1,50197;357,13015
44,72000;1,50329;356,49308
44,76000;1,50466;355,82974
44,80000;1,50598;355,92683
44,84000;1,50735;355,26576
44,88000;1,50867;354,29292
44,92000;1,50986;353,17799
44,96000;1,51130;354,16400
45,00000;1,51267;353,96710
45,04000;1,51405;353,41922
45,08000;1,51542;353,64027
45,12000;1,51674;352,39263
45,16000;1,51812;351,34472
45,20000;1,51925;350,60467
45,24000;1,52063;349,46098
45,28000;1,52200;350,95045
45,32000;1,52332;349,44296
45,36000;1,52469;348,83555
45,40000;1,52607;348,66473
45,44000;1,52738;347,30157
45,48000;1,52870;346,09355
45,52000;1,52989;345,11064
45,56000;1,53127;344,30383
45,60000;1,53270;344,64218
45,64000;1,53402;343,02713
45,68000;1,53533;342,75125
45,72000;1,53671;342,18167
45,76000;1,53808;341,56018
45,80000;1,53940;341,20993
45,84000;1,54060;339,82520
45,88000;1,54197;340,56068
45,92000;1,54335;339,96748
45,96000;1,54466;339,07818
46,00000;1,54604;339,03504
46,04000;1,54729;337,26506
46,08000;1,54867;337,49738
46,12000;1,54998;337,26373
46,16000;1,55118;335,23059
46,20000;1,55255;335,57883
46,24000;1,55393;335,84903
46,28000;1,55530;335,18085
46,32000;1,55668;334,37281
46,36000;1,55799;333,04510
46,40000;1,55937;332,95730
46,44000;1,56069;332,87967
46,48000;1,56194;332,02725
46,52000;1,56332;332,22290
46,56000;1,56469;331,83545
46,60000;1,56607;331,25028
46,64000;1,56738;330,57283
46,68000;1,56870;330,16226
46,72000;1,57007;330,31709
46,76000;1,57127;329,59231
46,80000;1,57258;328,87927
46,84000;1,57402;329,71133
46,88000;1,57533;328,71922
46,92000;1,57671;328,17163
46,96000;1,57808;327,97009
47,00000;1,57940;327,84196
47,04000;1,58077;327,09960
47,08000;1,58197;326,17615
47,12000;1,58323;325,70364
47,16000;1,58466;325,92565
47,20000;1,58604;325,28122
47,24000;1,58741;324,73099
47,28000;1,58873;324,08554
47,32000;1,59010;323,18062
47,36000;1,59142;322,34523
47,40000;1,59261;321,23101
47,44000;1,59393;320,08206
47,48000;1,59530;320,46437
47,52000;1,59662;319,92942
47,56000;1,59799;318,58031
47,60000;1,59931;317,85464
47,64000;1,60068;317,51893
47,68000;1,60200;317,20076
47,72000;1,60320;315,08389
47,76000;1,60463;315,61716
47,80000;1,60601;315,88702
47,84000;1,60732;313,94884
47,88000;1,60864;313,39631
47,92000;1,61001;313,22190
47,96000;1,61139;312,51647
48,00000;1,61264;312,58599
48,04000;1,61390;310,66767
48,08000;1,61539;310,83799
48,12000;1,61671;310,99594
48,16000;1,61802;309,70497
48,20000;1,61934;307,91471
48,24000;1,62071;308,58377
48,28000;1,62203;308,02710
48,32000;1,62334;307,87098
48,36000;1,62460;305,08814
48,40000;1,62609;306,46906
48,44000;1,62735;304,79333
48,48000;1,62873;304,61084
48,52000;1,63010;303,93591
48,56000;1,63148;304,22616
48,60000;1,63279;303,29584
48,64000;1,63399;302,66375
48,68000;1,63536;302,27054
48,72000;1,63674;302,76000
48,76000;1,63805;301,49808
48,80000;1,63937;301,61804
48,84000;1,64074;301,60826
48,88000;1,64212;301,56143
48,92000;1,64337;300,29570
48,96000;1,64457;299,71721
49,00000;1,64589;299,86601
49,04000;1,64732;300,37109
49,08000;1,64864;299,18046
49,12000;1,65001;299,20323
49,16000;1,65139;298,03629
49,20000;1,65276;298,19694
49,24000;1,65408;297,00419
49,28000;1,65527;296,05399
49,32000;1,65665;295,30111
49,36000;1,65796;295,87771
49,40000;1,65934;294,74329
49,44000;1,66071;295,46435
49,48000;1,66203;294,31102
49,52000;1,66340;293,91916
49,56000;1,66466;292,64768
49,60000;1,66591;291,41856
49,64000;1,66729;290,85628
49,68000;1,66866;291,27048
49,72000;1,66998;289,25233
49,76000;1,67136;289,20239
49,80000;1,67273;289,66214
49,84000;1,67411;289,76544
49,88000;1,67536;288,31984
49,92000;1,67662;286,88591
49,96000;1,67799;287,11706
50,00000;1,67937;287,34789
50,04000;1,68068;285,92299
50,08000;1,68200;286,17352
50,12000;1,68343;286,37152
50,16000;1,68475;285,91056
50,20000;1,68600;284,58170
50,24000;1,68732;283,60323
50,28000;1,68869;283,90079
50,32000;1,69001;283,49806
50,36000;1,69133;281,96417
50,40000;1,69264;282,13672
50,44000;1,69402;282,25321
50,48000;1,69539;281,73099
50,52000;1,69665;280,29848
50,56000;1,69796;279,76232
50,60000;1,69934;280,85888
50,64000;1,70065;279,80986
50,68000;1,70203;279,20534
50,72000;1,70334;279,49859
50,76000;1,70466;277,97439
50,80000;1,70603;278,54929
50,84000;1,70735;277,87366
50,88000;1,70860;276,82451
50,92000;1,70998;276,18809
50,96000;1,71129;276,47351
51,00000;1,71267;275,37891
51,04000;1,71399;276,19461
51,08000;1,71536;275,22764
51,12000;1,71668;274,83827
51,16000;1,71787;274,21187
51,20000;1,71925;274,08211
51,24000;1,72074;274,13974
51,28000;1,72206;274,24418
51,32000;1,72343;272,82434
51,36000;1,72469;271,63634
51,40000;1,72612;271,21550
51,44000;1,72738;272,20713
51,48000;1,72857;269,61095
51,52000;1,72995;270,05854
51,56000;1,73126;269,26855
51,60000;1,73264;269,02747
51,64000;1,73401;268,50498
51,68000;1,73533;267,83689
51,72000;1,73671;266,97956
51,76000;1,73796;266,56033
51,80000;1,73922;265,49685
51,84000;1,74065;265,84147
51,88000;1,74197;265,20090
51,92000;1,74346;266,33779
51,96000;1,74478;265,33012
52,00000;1,74609;264,36371
52,04000;1,74741;262,94605
52,08000;1,74860;262,69560
52,12000;1,74992;261,82153
52,16000;1,75135;262,79152
52,20000;1,75267;261,81168
52,24000;1,75398;261,06052
52,28000;1,75530;261,02173
52,32000;1,75668;260,34014
52,36000;1,75805;260,06075
52,40000;1,75925;259,54808
52,44000;1,76056;257,84948
52,48000;1,76200;259,11685
52,52000;1,76331;258,88572
52,56000;1,76469;257,88385
52,60000;1,76600;256,91083
52,64000;1,76738;256,92731
52,68000;1,76881;257,61758
52,72000;1,77001;255,74716
52,76000;1,77132;254,74837
52,80000;1,77270;255,16257
52,84000;1,77401;254,28785
52,88000;1,77533;254,33495
52,92000;1,77670;253,66198
52,96000;1,77808;253,20160
53,00000;1,77934;253,13767
53,04000;1,78059;252,01461
53,08000;1,78197;251,81272
53,12000;1,78334;252,40264
53,16000;1,78466;250,65069
53,20000;1,78597;250,75763
53,24000;1,78729;250,01138
53,28000;1,78866;250,01045
53,32000;1,79004;249,27016
53,36000;1,79123;249,02734
53,40000;1,79267;247,82550
53,44000;1,79398;247,85299
53,48000;1,79542;248,51828
53,52000;1,79673;246,44702
53,56000;1,79805;245,57975
53,60000;1,79942;246,23084
53,64000;1,80062;245,65447
53,68000;1,80188;244,38545
53,72000;1,80325;244,42612
53,76000;1,80463;244,83278
53,80000;1,80600;243,59559
53,84000;1,80732;243,35310
53,88000;1,80869;242,82488
53,92000;1,81007;243,15519
53,96000;1,81126;241,62037
54,00000;1,81258;241,54601
54,04000;1,81395;241,90771
54,08000;1,81533;241,00039
54,12000;1,81670;240,68279
54,16000;1,81808;240,33652
54,20000;1,81945;240,08704
54,24000;1,82077;239,47987
54,28000;1,82197;237,61052
54,32000;1,82328;237,73853
54,36000;1,82466;238,63502
54,37000;1,82501;238,55297