File: SU - Suspension/05 - Essais/Excels essais Optimus/Temoins et tests triangles/Temoins alu carbone/temoin 2/temoin 2.is_tens_RawData/Specimen_RawData_1.csv
Temps;Déplacement;Charge
(sec);(mm);(N)
0,00000;0,00801;81,73384
0,04000;0,00855;81,08302
0,08000;0,01088;88,58232
0,12000;0,01417;113,32086
0,16000;0,01800;150,17838
0,20000;0,02176;190,33552
0,24000;0,02553;229,52927
0,28000;0,02942;270,11749
0,32000;0,03306;308,02684
0,36000;0,03665;344,36495
0,40000;0,04030;381,06588
0,44000;0,04371;417,18618
0,48000;0,04717;452,66068
0,52000;0,05070;488,25173
0,56000;0,05399;522,03927
0,60000;0,05740;554,35770
0,64000;0,06075;587,59204
0,68000;0,06409;620,92096
0,72000;0,06744;654,61714
0,76000;0,07079;688,10061
0,80000;0,07408;721,02430
0,84000;0,07743;753,21044
0,88000;0,08078;785,31969
0,92000;0,08406;818,24018
0,96000;0,08741;849,51762
1,00000;0,09082;881,79717
1,04000;0,09411;913,99997
1,08000;0,09746;943,20579
1,12000;0,10081;974,27387
1,16000;0,10415;1006,17334
1,20000;0,10744;1036,09962
1,24000;0,11079;1066,45608
1,28000;0,11414;1097,14344
1,32000;0,11749;1126,84034
1,36000;0,12077;1155,55748
1,40000;0,12412;1185,31827
1,44000;0,12747;1215,95273
1,48000;0,13082;1245,92492
1,52000;0,13411;1276,43989
1,56000;0,13746;1306,68310
1,60000;0,14080;1334,80122
1,64000;0,14415;1364,02464
1,68000;0,14750;1393,06160
1,72000;0,15085;1422,21618
1,76000;0,15414;1451,51559
1,80000;0,15743;1479,96414
1,84000;0,16083;1508,12892
1,88000;0,16412;1536,03563
1,92000;0,16747;1564,63329
1,96000;0,17082;1591,98642
2,00000;0,17417;1620,27683
2,04000;0,17746;1648,02931
2,08000;0,18074;1675,13154
2,12000;0,18415;1703,65442
2,16000;0,18750;1730,64861
2,20000;0,19073;1755,23087
2,24000;0,19414;1781,85198
2,28000;0,19754;1809,70281
2,32000;0,20083;1836,20621
2,36000;0,20418;1862,72692
2,40000;0,20753;1889,36684
2,44000;0,21082;1916,23103
2,48000;0,21411;1941,53916
2,52000;0,21733;1966,24156
2,56000;0,22086;1994,50385
2,60000;0,22415;2020,03401
2,64000;0,22744;2043,56443
2,68000;0,23073;2068,78819
2,72000;0,23408;2091,23138
2,76000;0,23736;2115,61564
2,80000;0,24077;2141,27321
2,84000;0,24412;2165,44997
2,88000;0,24747;2187,72739
2,92000;0,25076;2210,50251
2,96000;0,25411;2234,03834
3,00000;0,25751;2255,56437
3,04000;0,26080;2275,65281
3,08000;0,26409;2296,04878
3,12000;0,26750;2316,28250
3,16000;0,27085;2335,34891
3,20000;0,27408;2353,69597
3,24000;0,27742;2371,06960
3,28000;0,28083;2389,14713
3,32000;0,28406;2405,40430
3,36000;0,28741;2418,25003
3,40000;0,29088;2431,54801
3,44000;0,29410;2442,15950
3,48000;0,29745;2449,63933
3,52000;0,30080;2456,77419
3,56000;0,30409;2461,06852
3,60000;0,30744;2460,22046
3,64000;0,31085;2455,39248
3,68000;0,31413;2445,13471
3,72000;0,31748;2427,90058
3,76000;0,32083;2405,91168
3,80000;0,32412;2382,79998
3,84000;0,32747;2359,56479
3,88000;0,33076;2345,52957
3,92000;0,33410;2349,19041
3,96000;0,33745;2362,21198
4,00000;0,34080;2379,45095
4,04000;0,34415;2399,54181
4,08000;0,34744;2418,97739
4,12000;0,35073;2440,97393
4,16000;0,35413;2464,21807
4,20000;0,35736;2487,45866
4,24000;0,36071;2510,46550
4,28000;0,36418;2533,37640
4,32000;0,36741;2555,29508
4,36000;0,37075;2577,24263
4,40000;0,37416;2598,61797
4,44000;0,37739;2620,29693
4,48000;0,38074;2641,01662
4,52000;0,38409;2662,32342
4,56000;0,38744;2682,91980
4,60000;0,39072;2702,99073
4,64000;0,39413;2723,10823
4,68000;0,39748;2744,00152
4,72000;0,40077;2762,12841
4,76000;0,40412;2780,38103
4,80000;0,40741;2799,02909
4,84000;0,41075;2816,50890
4,88000;0,41404;2832,73887
4,92000;0,41745;2849,99255
4,96000;0,42080;2865,50298
5,00000;0,42415;2880,20447
5,04000;0,42749;2893,39274
5,08000;0,43078;2907,71481
5,12000;0,43413;2924,45235
5,16000;0,43754;2940,66817
5,20000;0,44077;2957,97568
5,24000;0,44418;2975,86676
5,28000;0,44752;2995,35841
5,32000;0,45075;3014,85788
5,36000;0,45410;3034,59875
5,40000;0,45745;3056,11230
5,44000;0,46074;3077,97622
5,48000;0,46409;3097,46899
5,52000;0,46743;3118,10281
5,56000;0,47084;3140,35118
5,60000;0,47413;3160,15482
5,64000;0,47748;3181,52979
5,68000;0,48077;3205,37165
5,72000;0,48418;3225,86335
5,76000;0,48746;3246,48842
5,80000;0,49081;3267,53967
5,84000;0,49416;3288,05596
5,88000;0,49745;3309,20927
5,92000;0,50074;3328,85049
5,96000;0,50403;3350,56074
6,00000;0,50737;3371,60341
6,04000;0,51078;3392,37712
6,08000;0,51407;3412,81965
6,12000;0,51748;3434,39765
6,16000;0,52083;3455,13225
6,20000;0,52405;3475,28979
6,24000;0,52746;3496,75640
6,28000;0,53081;3518,68719
6,32000;0,53410;3539,78276
6,36000;0,53745;3559,77044
6,40000;0,54092;3581,97093
6,44000;0,54420;3603,46064
6,48000;0,54749;3621,78236
6,52000;0,55078;3641,40458
6,56000;0,55407;3663,24335
6,60000;0,55748;3683,70451
6,64000;0,56077;3704,16306
6,68000;0,56411;3724,58063
6,72000;0,56752;3746,14000
6,76000;0,57081;3765,84530
6,80000;0,57410;3784,97317
6,84000;0,57745;3804,44787
6,88000;0,58085;3825,19513
6,92000;0,58420;3844,39938
6,96000;0,58749;3862,60897
7,00000;0,59090;3883,75632
7,04000;0,59425;3902,63461
7,08000;0,59748;3920,60317
7,12000;0,60076;3939,88453
7,16000;0,60417;3962,15394
7,20000;0,60740;3979,64604
7,24000;0,61075;3998,26318
7,28000;0,61416;4018,05714
7,32000;0,61745;4037,45547
7,36000;0,62073;4054,52549
7,40000;0,62408;4072,45122
7,44000;0,62743;4093,58926
7,48000;0,63078;4110,22827
7,52000;0,63413;4128,72732
7,56000;0,63754;4148,41473
7,60000;0,64082;4166,91229
7,64000;0,64399;4184,23153
7,68000;0,64752;4205,28129
7,72000;0,65087;4223,90886
7,76000;0,65416;4240,89320
7,80000;0,65751;4257,71326
7,84000;0,66079;4274,01736
7,88000;0,66414;4292,14351
7,92000;0,66743;4309,97834
7,96000;0,67072;4327,74834
8,00000;0,67419;4348,88564
8,04000;0,67753;4366,51409
8,08000;0,68076;4382,70383
8,12000;0,68411;4397,92350
8,16000;0,68752;4414,73238
8,20000;0,69075;4430,87816
8,24000;0,69416;4446,70245
8,28000;0,69756;4468,07407
8,32000;0,70079;4483,04564
8,36000;0,70414;4497,56570
8,40000;0,70743;4513,35646
8,44000;0,71078;4530,01782
8,48000;0,71413;4545,05309
8,52000;0,71735;4560,61214
8,56000;0,72088;4580,75888
8,60000;0,72417;4596,00203
8,64000;0,72746;4611,55288
8,68000;0,73081;4626,74983
8,72000;0,73410;4640,50993
8,76000;0,73744;4654,83405
8,80000;0,74073;4669,68380
8,84000;0,74402;4684,98096
8,88000;0,74737;4701,55552
8,92000;0,75084;4720,15515
8,96000;0,75407;4734,05533
9,00000;0,75747;4747,34902
9,04000;0,76082;4761,85530
9,08000;0,76405;4775,03724
9,12000;0,76746;4788,56377
9,16000;0,77087;4805,24711
9,20000;0,77415;4819,91284
9,24000;0,77750;4831,68252
9,28000;0,78079;4844,82683
9,32000;0,78414;4857,76700
9,36000;0,78713;4869,81869
9,40000;0,79090;4886,24536
9,44000;0,79412;4901,54475
9,48000;0,79753;4913,34945
9,52000;0,80076;4923,83949
9,56000;0,80417;4936,34194
9,60000;0,80752;4949,04742
9,64000;0,81081;4960,42967
9,68000;0,81397;4972,04252
9,72000;0,81756;4986,96603
9,76000;0,82085;4999,92818
9,80000;0,82420;5008,95418
9,84000;0,82749;5018,84781
9,88000;0,83083;5030,08589
9,92000;0,83412;5039,86776
9,96000;0,83741;5050,06015
10,00000;0,84082;5060,95327
10,04000;0,84417;5072,32770
10,08000;0,84740;5081,78659
10,12000;0,85080;5091,62508
10,16000;0,85421;5105,27454
10,20000;0,85744;5114,30763
10,24000;0,86079;5122,21456
10,28000;0,86420;5131,82208
10,32000;0,86749;5141,19118
10,36000;0,87077;5147,26080
10,40000;0,87418;5154,48600
10,44000;0,87753;5162,89547
10,48000;0,88082;5168,68085
10,52000;0,88411;5175,15615
10,56000;0,88752;5182,01329
10,60000;0,89080;5189,79989
10,64000;0,89409;5194,62787
10,68000;0,89744;5200,10218
10,72000;0,90073;5205,65622
10,76000;0,90414;5209,18742
10,80000;0,90748;5213,15336
10,84000;0,91071;5216,99972
10,88000;0,91418;5220,06750
10,92000;0,91747;5223,16769
10,96000;0,92076;5226,01604
11,00000;0,92417;5227,28823
11,04000;0,92751;5228,69341
11,08000;0,93074;5227,30388
11,12000;0,93409;5228,19273
11,16000;0,93744;5227,95729
11,20000;0,94073;5224,97669
11,24000;0,94402;5220,78648
11,28000;0,94742;5218,04169
11,32000;0,95077;5214,18117
11,36000;0,95412;5207,86010
11,40000;0,95747;5203,60135
11,44000;0,96082;5195,31369
11,48000;0,96411;5185,77062
11,52000;0,96739;5175,61287
11,56000;0,97086;5165,37316
11,60000;0,97415;5153,79272
11,64000;0,97738;5140,22037
11,68000;0,98091;5128,98155
11,72000;0,98413;5115,88566
11,76000;0,98748;5100,84517
11,80000;0,99083;5083,96141
11,84000;0,99412;5067,75901
11,88000;0,99747;5050,72623
11,92000;1,00076;5033,63535
11,96000;1,00404;5017,65311
12,00000;1,00745;5002,48820
12,04000;1,01080;4989,54169
12,08000;1,01409;4979,28411
12,12000;1,01750;4972,12075
12,16000;1,02085;4969,45940
12,20000;1,02413;4968,60594
12,24000;1,02742;4968,67858
12,28000;1,03083;4973,14818
12,32000;1,03418;4977,37937
12,36000;1,03729;4981,16463
12,40000;1,04088;4989,03021
12,44000;1,04422;4996,64843
12,48000;1,04751;5002,65621
12,52000;1,05080;5008,64908
12,56000;1,05421;5016,60109
12,60000;1,05750;5024,51994
12,64000;1,06084;5031,98020
12,68000;1,06425;5041,85036
12,72000;1,06754;5050,95012
12,76000;1,07089;5059,84761
12,80000;1,07424;5067,17153
12,84000;1,07747;5075,78067
12,88000;1,08081;5085,13153
12,92000;1,08422;5095,81789
12,96000;1,08751;5108,33263
13,00000;1,09086;5118,55818
13,04000;1,09427;5127,31671
13,08000;1,09750;5136,91939
13,12000;1,10055;5145,36053
13,16000;1,10419;5159,98714
13,20000;1,10754;5171,69572
13,24000;1,11083;5184,86723
13,28000;1,11418;5200,40765
13,32000;1,11759;5218,79569
13,36000;1,12063;5237,15913
13,40000;1,12422;5258,26849
13,44000;1,12751;5280,33823
13,48000;1,13080;5300,18248
13,52000;1,13421;5319,73206
13,56000;1,13755;5338,10444
13,60000;1,14084;5358,13384
13,64000;1,14419;5378,50112
13,68000;1,14736;5397,44198
13,72000;1,15089;5419,96621
13,76000;1,15418;5440,02652
13,80000;1,15752;5458,16049
13,84000;1,16081;5475,98936
13,88000;1,16422;5494,22912
13,92000;1,16751;5512,73525
13,96000;1,17062;5530,41957
14,00000;1,17415;5548,54013
14,04000;1,17749;5567,66391
14,08000;1,18078;5583,89053
14,12000;1,18407;5600,18271
14,16000;1,18748;5618,01381
14,20000;1,19083;5636,51584
14,24000;1,19412;5651,56601
14,28000;1,19740;5667,51137
14,32000;1,20081;5685,56674
14,36000;1,20416;5702,14950
14,40000;1,20745;5717,71711
14,44000;1,21080;5733,21432
14,48000;1,21415;5748,23059
14,52000;1,21743;5764,61516
14,56000;1,22072;5778,48703
14,60000;1,22413;5795,83570
14,64000;1,22748;5812,21730
14,68000;1,23083;5825,84403
14,72000;1,23411;5839,85932
14,76000;1,23752;5854,94712
14,80000;1,24087;5869,05852
14,84000;1,24410;5881,10983
14,88000;1,24757;5894,96978
14,92000;1,25092;5910,02330
14,96000;1,25414;5922,05711
15,00000;1,25749;5932,28526
15,04000;1,26090;5943,41755
15,08000;1,26413;5952,82167
15,12000;1,26742;5956,17481
15,16000;1,27053;5957,39447
15,20000;1,27423;5956,99102
15,24000;1,27746;5948,43999
15,28000;1,28081;5936,57233
15,32000;1,28416;5926,95363
15,36000;1,28751;5918,05317
15,40000;1,29080;5911,82336
15,44000;1,29420;5909,50362
15,48000;1,29749;5918,19398
15,52000;1,30084;5934,41948
15,56000;1,30401;5954,69102
15,60000;1,30754;5980,27222
15,64000;1,31088;6002,40827
15,68000;1,31417;6024,28131
15,72000;1,31746;6045,38620
15,76000;1,32081;6066,19529
15,80000;1,32410;6087,68128
15,84000;1,32733;6109,44815
15,88000;1,33085;6132,40823
15,92000;1,33414;6154,78978
15,96000;1,33743;6176,40875
16,00000;1,34078;6195,47926
16,04000;1,34413;6216,56477
16,08000;1,34742;6238,57863
16,12000;1,35076;6258,63969
16,16000;1,35417;6278,92464
16,20000;1,35752;6302,07807
16,24000;1,36081;6320,69856
16,28000;1,36410;6341,10719
16,32000;1,36751;6361,35936
16,36000;1,37073;6381,72403
16,40000;1,37402;6401,11938
16,44000;1,37731;6422,09202
16,48000;1,38078;6444,38416
16,52000;1,38413;6464,89933
16,56000;1,38742;6483,73738
16,60000;1,39070;6502,88761
16,64000;1,39417;6523,92134
16,68000;1,39746;6545,06534
16,72000;1,40075;6565,12529
16,76000;1,40410;6584,55268
16,80000;1,40744;6604,59697
16,84000;1,41067;6625,14940
16,88000;1,41408;6644,05599
16,92000;1,41749;6666,61039
16,96000;1,42078;6687,47947
17,00000;1,42407;6705,87644
17,04000;1,42753;6727,15455
17,08000;1,43076;6748,82531
17,12000;1,43405;6765,97580
17,16000;1,43740;6785,41288
17,20000;1,44081;6807,27512
17,24000;1,44410;6826,34190
17,28000;1,44744;6844,99517
17,32000;1,45079;6866,38057
17,36000;1,45414;6886,35111
17,40000;1,45743;6904,96340
17,44000;1,46078;6924,69254
17,48000;1,46413;6944,75695
17,52000;1,46741;6965,12982
17,56000;1,47082;6982,53661
17,60000;1,47405;7003,37291
17,64000;1,47746;7023,23392
17,68000;1,48081;7043,14187
17,72000;1,48404;7061,99631
17,76000;1,48744;7081,63604
17,80000;1,49079;7101,95750
17,84000;1,49408;7120,63387
17,88000;1,49743;7140,29223
17,92000;1,50084;7160,40432
17,96000;1,50400;7180,16550
18,00000;1,50747;7200,11070
18,04000;1,51082;7220,79799
18,08000;1,51417;7240,16204
18,12000;1,51740;7258,12688
18,16000;1,52081;7278,58767
18,20000;1,52421;7299,06708
18,24000;1,52744;7317,45139
18,28000;1,53079;7337,64991
18,32000;1,53420;7358,49291
18,36000;1,53743;7378,40533
18,40000;1,54078;7396,82615
18,44000;1,54412;7415,06368
18,48000;1,54747;7435,28008
18,52000;1,55076;7454,36251
18,56000;1,55411;7475,23457
18,60000;1,55740;7496,50300
18,64000;1,56074;7513,83603
18,68000;1,56403;7532,23449
18,72000;1,56738;7551,76395
18,76000;1,57079;7571,40592
18,80000;1,57408;7591,03745
18,84000;1,57743;7610,92231
18,88000;1,58077;7631,12828
18,92000;1,58412;7651,03102
18,96000;1,58741;7670,63797
19,00000;1,59076;7689,33371
19,04000;1,59411;7709,27742
19,08000;1,59746;7728,41647
19,12000;1,60068;7746,16525
19,16000;1,60403;7766,68340
19,20000;1,60744;7787,11885
19,24000;1,61073;7806,68184
19,28000;1,61408;7825,07807
19,32000;1,61743;7845,34216
19,36000;1,62071;7864,52219
19,40000;1,62406;7883,62026
19,44000;1,62747;7904,28519
19,48000;1,63076;7925,58193
19,52000;1,63411;7944,20615
19,56000;1,63751;7963,60448
19,60000;1,64074;7983,57055
19,64000;1,64409;8002,72301
19,68000;1,64744;8022,02001
19,72000;1,65073;8041,24773
19,76000;1,65408;8060,71237
19,80000;1,65742;8079,86334
19,84000;1,66083;8100,58117
19,88000;1,66412;8120,83706
19,92000;1,66753;8139,63786
19,96000;1,67082;8158,54818
20,00000;1,67411;8176,19413
20,04000;1,67745;8196,03801
20,08000;1,68092;8216,14638
20,12000;1,68421;8235,79133
20,16000;1,68756;8254,60330
20,20000;1,69097;8274,55074
20,24000;1,69414;8293,14962
20,28000;1,69748;8310,73299
20,32000;1,70083;8330,30492
20,36000;1,70412;8349,59149
20,40000;1,70747;8367,55186
20,44000;1,71070;8387,28026
20,48000;1,71422;8408,94729
20,52000;1,71745;8428,19139
20,56000;1,72080;8446,01840
20,60000;1,72409;8466,66470
20,64000;1,72750;8485,18014
20,68000;1,73085;8504,75356
20,72000;1,73413;8523,30849
20,76000;1,73754;8542,35888
20,80000;1,74089;8563,61240
20,84000;1,74412;8581,73594
20,88000;1,74747;8599,38562
20,92000;1,75082;8618,16928
20,96000;1,75416;8636,04695
21,00000;1,75739;8654,29342
21,04000;1,76080;8673,32369
21,08000;1,76415;8692,75182
21,12000;1,76744;8710,78596
21,16000;1,77079;8728,55335
21,20000;1,77419;8749,56921
21,24000;1,77742;8766,61316
21,28000;1,78077;8783,83964
21,32000;1,78418;8803,20668
21,36000;1,78747;8820,86679
21,40000;1,79081;8838,39354
21,44000;1,79416;8856,70632
21,48000;1,79745;8876,37362
21,52000;1,80080;8894,11122
21,56000;1,80409;8912,25636
21,60000;1,80738;8931,26130
21,64000;1,81078;8949,08309
21,68000;1,81407;8966,55545
21,72000;1,81736;8983,63665
21,76000;1,82077;9002,03064
21,80000;1,82412;9020,39930
21,84000;1,82741;9038,53700
21,88000;1,83075;9056,61210
21,92000;1,83410;9076,09537
21,96000;1,83745;9094,75759
22,00000;1,84074;9111,95427
22,04000;1,84409;9131,94418
22,08000;1,84750;9151,79700
22,12000;1,85078;9170,10382
22,16000;1,85407;9185,27469
22,20000;1,85748;9203,15087
22,24000;1,86077;9220,66197
22,28000;1,86376;9236,94223
22,32000;1,86752;9255,88235
22,36000;1,87081;9276,08684
22,40000;1,87422;9293,15314
22,44000;1,87751;9309,66064
22,48000;1,88080;9326,21136
22,52000;1,88421;9344,36619
22,56000;1,88749;9361,67017
22,60000;1,89084;9379,25726
22,64000;1,89419;9399,54594
22,68000;1,89754;9416,32017
22,72000;1,90083;9432,19438
22,76000;1,90418;9448,43963
22,80000;1,90752;9464,77428
22,84000;1,91081;9482,42694
22,88000;1,91410;9497,76247
22,92000;1,91751;9518,99067
22,96000;1,92086;9535,71498
23,00000;1,92421;9552,07795
23,04000;1,92755;9569,21130
23,08000;1,93090;9585,46177
23,12000;1,93413;9601,59376
23,16000;1,93742;9617,64380
23,20000;1,94083;9635,16682
23,24000;1,94412;9652,17128
23,28000;1,94752;9669,83438
23,32000;1,95087;9685,06783
23,36000;1,95416;9702,11476
23,40000;1,95745;9717,85486
23,44000;1,96080;9734,12395
23,48000;1,96414;9751,21260
23,52000;1,96749;9767,05551
23,56000;1,97078;9783,10406
23,60000;1,97407;9798,77189
23,64000;1,97748;9815,63553
23,68000;1,98083;9836,02256
23,72000;1,98411;9850,74267
23,76000;1,98740;9865,92248
23,80000;1,99081;9883,05137
23,84000;1,99416;9899,35771
23,88000;1,99739;9913,88559
23,92000;2,00080;9930,10029
23,96000;2,00420;9949,17378
24,00000;2,00737;9963,30753
24,04000;2,01078;9978,86583
24,08000;2,01425;9995,97162
24,12000;2,01742;10011,12759
24,16000;2,02082;10025,66814
24,20000;2,02417;10041,92606
24,24000;2,02746;10057,14387
24,28000;2,03075;10071,13606
24,32000;2,03410;10085,39870
24,36000;2,03745;10105,41692
24,40000;2,04079;10120,13182
24,44000;2,04408;10132,76353
24,48000;2,04737;10147,96868
24,52000;2,05078;10162,70146
24,56000;2,05407;10178,31564
24,60000;2,05736;10193,40456
24,64000;2,06076;10208,49943
24,68000;2,06417;10225,33998
24,72000;2,06746;10240,80738
24,76000;2,07081;10253,39812
24,80000;2,07416;10268,45574
24,84000;2,07751;10283,74583
24,88000;2,08073;10296,62117
24,92000;2,08408;10311,61100
24,96000;2,08749;10327,35556
25,00000;2,09072;10342,22320
25,04000;2,09407;10358,15924
25,08000;2,09748;10373,29212
25,12000;2,10076;10389,17974
25,16000;2,10411;10403,25761
25,20000;2,10746;10417,68789
25,24000;2,11081;10433,73495
25,28000;2,11410;10448,02144
25,32000;2,11750;10463,71534
25,36000;2,12085;10479,85405
25,40000;2,12414;10494,24186
25,44000;2,12755;10509,07671
25,48000;2,13078;10525,47544
25,52000;2,13413;10539,77683
25,56000;2,13741;10553,98881
25,60000;2,14076;10570,51569
25,64000;2,14411;10586,55232
25,68000;2,14746;10601,77386
25,72000;2,15081;10617,49831
25,76000;2,15416;10634,63464
25,80000;2,15750;10649,88822
25,84000;2,16079;10665,06281
25,88000;2,16408;10678,24289
25,92000;2,16749;10692,72757
25,96000;2,17084;10709,19931
26,00000;2,17413;10724,00212
26,04000;2,17747;10742,15099
26,08000;2,18088;10757,33155
26,12000;2,18411;10771,16951
26,16000;2,18746;10785,50145
26,20000;2,19087;10801,37715
26,24000;2,19409;10816,56888
26,28000;2,19732;10829,67743
26,32000;2,20085;10846,54778
26,36000;2,20414;10863,70349
26,40000;2,20749;10877,20618
26,44000;2,21078;10890,77219
26,48000;2,21412;10905,82311
26,52000;2,21747;10920,96046
26,56000;2,22070;10936,03745
26,60000;2,22411;10951,24036
26,64000;2,22746;10966,16387
26,68000;2,23081;10980,91602
26,72000;2,23409;10996,46464
26,76000;2,23744;11011,19742
26,80000;2,24079;11027,40616
26,84000;2,24414;11041,34396
26,88000;2,24737;11055,60511
26,92000;2,25072;11070,19931
26,96000;2,25412;11086,59133
27,00000;2,25735;11101,81734
27,04000;2,26082;11116,28115
27,08000;2,26417;11131,60923
27,12000;2,26746;11147,10048
27,16000;2,27075;11160,80880
27,20000;2,27409;11176,20319
27,24000;2,27738;11191,92243
27,28000;2,28073;11206,37804
27,32000;2,28414;11223,36760
27,36000;2,28749;11239,03617
27,40000;2,29083;11251,78114
27,44000;2,29400;11265,70106
27,48000;2,29747;11284,06078
27,52000;2,30082;11298,59686
27,56000;2,30417;11312,79394
27,60000;2,30752;11326,60881
27,64000;2,31080;11340,20016
27,68000;2,31415;11356,04605
27,72000;2,31744;11371,56114
27,76000;2,32079;11387,60522
27,80000;2,32414;11403,01749
27,84000;2,32755;11416,95380
27,88000;2,33083;11430,63456
27,92000;2,33412;11443,96067
27,96000;2,33759;11459,44521
28,00000;2,34082;11473,17961
28,04000;2,34411;11486,61375
28,08000;2,34757;11502,82025
28,12000;2,35080;11517,65212
28,16000;2,35415;11530,32482
28,20000;2,35756;11545,06430
28,24000;2,36085;11560,90945
28,28000;2,36414;11574,37339
28,32000;2,36731;11588,63083
28,36000;2,37083;11606,15236
28,40000;2,37418;11620,68471
28,44000;2,37753;11634,10619
28,48000;2,38082;11647,88380
28,52000;2,38423;11662,72536
28,56000;2,38757;11677,73008
28,60000;2,39074;11691,34825
28,64000;2,39421;11706,49901
28,68000;2,39756;11721,73768
28,72000;2,40091;11735,06752
28,76000;2,40414;11747,95106
28,80000;2,40754;11762,52812
28,84000;2,41089;11777,85099
28,88000;2,41412;11791,22329
28,92000;2,41741;11804,16420
28,96000;2,42088;11820,80209
29,00000;2,42405;11835,62204
29,04000;2,42739;11848,80286
29,08000;2,43080;11862,98728
29,12000;2,43409;11879,25115
29,16000;2,43744;11891,60272
29,20000;2,44061;11904,59505
29,24000;2,44413;11919,26226
29,28000;2,44748;11934,53521
29,32000;2,45077;11947,88888
29,36000;2,45424;11963,08807
29,40000;2,45753;11979,81462
29,44000;2,46082;11992,08051
29,48000;2,46410;12005,37905
29,52000;2,46745;12018,74390
29,56000;2,47080;12034,10551
29,60000;2,47409;12047,80713
29,64000;2,47750;12063,44739
29,68000;2,48085;12078,50799
29,72000;2,48413;12092,18279
29,76000;2,48736;12103,46892
29,80000;2,49071;12117,24579
29,84000;2,49418;12133,43516
29,88000;2,49747;12148,75728
29,92000;2,50076;12161,13344
29,96000;2,50422;12175,93178
30,00000;2,50751;12193,55017
30,04000;2,51080;12204,03612
30,08000;2,51415;12216,72818
30,12000;2,51738;12231,38273
30,16000;2,52072;12243,51600
30,20000;2,52407;12256,55526
30,24000;2,52742;12271,46909
30,28000;2,53083;12286,08489
30,32000;2,53412;12299,58534
30,36000;2,53741;12312,24835
30,40000;2,54081;12325,20044
30,44000;2,54416;12339,08907
30,48000;2,54721;12351,62392
30,52000;2,55092;12366,44760
30,56000;2,55421;12380,41446
30,60000;2,55750;12392,49036
30,64000;2,56078;12404,54167
30,68000;2,56413;12418,01977
30,72000;2,56754;12432,36437
30,76000;2,57077;12445,83279
30,80000;2,57418;12459,84286
30,84000;2,57758;12474,53988
30,88000;2,58081;12486,19705
30,92000;2,58416;12499,11711
30,96000;2,58757;12515,52254
31,00000;2,59080;12529,00958
31,04000;2,59415;12539,57450
31,08000;2,59755;12552,35672
31,12000;2,60078;12566,19096
31,16000;2,60413;12578,85695
31,20000;2,60748;12592,31418
31,24000;2,61077;12605,69394
31,28000;2,61412;12619,30615
31,32000;2,61728;12631,75756
31,36000;2,62087;12648,50199
31,40000;2,62416;12661,21119
31,44000;2,62745;12673,51508
31,48000;2,63074;12685,77129
31,52000;2,63409;12699,17935
31,56000;2,63743;12712,53526
31,60000;2,64078;12725,78388
31,64000;2,64407;12738,20549
31,68000;2,64748;12751,47200
31,72000;2,65083;12765,86801
31,76000;2,65406;12777,79788
31,80000;2,65740;12790,46237
31,84000;2,66081;12804,10141
31,88000;2,66404;12816,54537
31,92000;2,66739;12828,44692
31,96000;2,67086;12843,31083
32,00000;2,67414;12857,51462
32,04000;2,67743;12869,11666
32,08000;2,68078;12882,10899
32,12000;2,68413;12895,51258
32,16000;2,68742;12906,79574
32,20000;2,69077;12919,06238
32,24000;2,69411;12932,83701
32,28000;2,69740;12945,70267
32,32000;2,70069;12958,13471
32,36000;2,70404;12972,06879
32,40000;2,70739;12986,05949
32,44000;2,71074;13000,52702
32,48000;2,71408;13012,34812
32,52000;2,71737;13023,83393
32,56000;2,72078;13037,16302
32,60000;2,72413;13051,12690
32,64000;2,72736;13062,90776
32,68000;2,73077;13076,46632
32,72000;2,73417;13090,25437
32,76000;2,73740;13101,95178
32,80000;2,74075;13112,94287
32,84000;2,74410;13126,69218
32,88000;2,74739;13139,60105
32,92000;2,75074;13151,84534
32,96000;2,75408;13164,95985
33,00000;2,75737;13177,62882
33,04000;2,76078;13188,38894
33,08000;2,76413;13201,96390
33,12000;2,76748;13215,78324
33,16000;2,77082;13228,13630
33,20000;2,77417;13240,58771
33,24000;2,77752;13253,54278
33,28000;2,78087;13266,35331
33,32000;2,78422;13278,73319
33,36000;2,78757;13291,56607
33,40000;2,79085;13304,11583
33,44000;2,79414;13316,01292
33,48000;2,79749;13328,80706
33,52000;2,80078;13341,57884
33,56000;2,80413;13354,13754
33,60000;2,80748;13366,23132
33,64000;2,81076;13378,58438
33,68000;2,81411;13390,80185
33,72000;2,81752;13403,58853
33,76000;2,82075;13415,61228
33,80000;2,82416;13427,99515
33,84000;2,82756;13441,39576
33,88000;2,83079;13453,22430
33,92000;2,83420;13465,35087
33,96000;2,83761;13478,49220
34,00000;2,84084;13490,74394
34,04000;2,84413;13500,85735
34,08000;2,84747;13514,10300
34,12000;2,85082;13527,34119
34,16000;2,85411;13539,55418
34,20000;2,85752;13551,10109
34,24000;2,86081;13564,82059
34,28000;2,86416;13575,30504
34,32000;2,86750;13586,57032
34,36000;2,87091;13599,82491
34,40000;2,87414;13614,11363
34,44000;2,87755;13626,09863
34,48000;2,88090;13638,02999
34,52000;2,88419;13650,45756
34,56000;2,88753;13662,53197
34,60000;2,89082;13674,22491
34,64000;2,89411;13686,22482
34,68000;2,89746;13698,26794
34,72000;2,90087;13710,89816
34,76000;2,90404;13722,26328
34,80000;2,90744;13734,26169
34,84000;2,91085;13747,36279
34,88000;2,91408;13759,52363
34,92000;2,91743;13770,08408
34,96000;2,92078;13783,32824
35,00000;2,92406;13796,75418
35,04000;2,92747;13808,95674
35,08000;2,93064;13820,46938
35,12000;2,93417;13833,30524
35,16000;2,93752;13845,82072
35,20000;2,94081;13856,11147
35,24000;2,94415;13867,31863
35,28000;2,94750;13879,16207
35,32000;2,95079;13891,06959
35,36000;2,95420;13903,62233
35,40000;2,95749;13915,73846
35,44000;2,96084;13927,79499
35,48000;2,96418;13939,56840
35,52000;2,96747;13950,86646
35,56000;2,97082;13962,71437
35,60000;2,97423;13974,72918
35,64000;2,97746;13985,95572
35,68000;2,98086;13997,02132
35,72000;2,98421;14009,25368
35,76000;2,98744;14019,58168
35,80000;2,99079;14030,63536
35,84000;2,99420;14043,17617
35,88000;2,99749;14054,99727
35,92000;3,00083;14065,66948
35,96000;3,00424;14078,78697
36,00000;3,00753;14091,44700
36,04000;3,01082;14101,75860
36,08000;3,01417;14113,63930
36,12000;3,01752;14126,10859
36,16000;3,02086;14136,84636
36,20000;3,02415;14147,00001
36,24000;3,02744;14158,73617
36,28000;3,03085;14172,03993
36,32000;3,03414;14183,66879
36,36000;3,03749;14194,17411
36,40000;3,04083;14205,45429
36,44000;3,04418;14216,20399
36,48000;3,04747;14227,35453
36,52000;3,05082;14238,36648
36,56000;3,05417;14251,98466
36,60000;3,05751;14262,58832
36,64000;3,06062;14274,15162
36,68000;3,06421;14287,28700
36,72000;3,06756;14300,12733
36,76000;3,07079;14309,17680
36,80000;3,07414;14317,95359
36,84000;3,07748;14329,89687
36,88000;3,08077;14341,26049
36,92000;3,08388;14350,56180
36,96000;3,08747;14363,59584
37,00000;3,09082;14376,82360
37,04000;3,09411;14385,77175
37,08000;3,09739;14394,86593
37,12000;3,10080;14407,22197
37,16000;3,10415;14418,78974
37,20000;3,10714;14429,47984
37,24000;3,11091;14441,76584
37,28000;3,11420;14454,53167
37,32000;3,11754;14464,89692
37,36000;3,12089;14474,62738
37,40000;3,12412;14484,09855
37,44000;3,12747;14494,42506
37,48000;3,13082;14505,53238
37,52000;3,13381;14515,26135
37,56000;3,13745;14528,79906
37,60000;3,14080;14541,81522
37,64000;3,14409;14551,55909
37,68000;3,14744;14561,09881
37,72000;3,15085;14572,48628
37,76000;3,15407;14582,62503
37,80000;3,15736;14590,47049
37,84000;3,16059;14602,03230
37,88000;3,16418;14616,59819
37,92000;3,16747;14625,38242
37,96000;3,17082;14635,46604
38,00000;3,17416;14646,38710
38,04000;3,17751;14655,84934
38,08000;3,18074;14666,33379
38,12000;3,18409;14676,35781
38,16000;3,18744;14686,34605
38,20000;3,19073;14696,13910
38,24000;3,19407;14706,39557
38,28000;3,19748;14718,02592
38,32000;3,20077;14730,08096
38,36000;3,20412;14738,89351
38,40000;3,20741;14748,15756
38,44000;3,21082;14759,08458
38,48000;3,21416;14769,41109
38,52000;3,21751;14778,97912
38,56000;3,22086;14790,48580
38,60000;3,22421;14800,71545
38,64000;3,22738;14809,97503
38,68000;3,23084;14822,49647
38,72000;3,23419;14833,43691
38,76000;3,23742;14842,31204
38,80000;3,24077;14851,37790
38,84000;3,24412;14862,27214
38,88000;3,24747;14873,01588
38,92000;3,25075;14881,86717
38,96000;3,25392;14891,22957
39,00000;3,25757;14904,27405
39,04000;3,26080;14914,48581
39,08000;3,26415;14922,69337
39,12000;3,26750;14933,61443
39,16000;3,27084;14943,75020
39,20000;3,27419;14952,36754
39,24000;3,27748;14961,24715
39,28000;3,28083;14971,10426
39,32000;3,28418;14981,52465
39,36000;3,28747;14990,56965
39,40000;3,29075;15000,37611
39,44000;3,29416;15011,02149
39,48000;3,29745;15020,28108
39,52000;3,30068;15028,66745
39,56000;3,30409;15037,79292
39,60000;3,30749;15048,30718
39,64000;3,31078;15057,97207
39,68000;3,31413;15068,01844
39,72000;3,31748;15078,30471
39,76000;3,32071;15087,44657
39,80000;3,32406;15095,22051
39,84000;3,32746;15105,31902
39,88000;3,33081;15115,45479
39,92000;3,33398;15123,33602
39,96000;3,33751;15133,39728
40,00000;3,34080;15144,26023
40,04000;3,34403;15151,90303
40,08000;3,34743;15162,31894
40,12000;3,35084;15173,36667
40,16000;3,35407;15181,55634
40,20000;3,35748;15190,64456
40,24000;3,36083;15198,12495
40,28000;3,36412;15206,74974
40,32000;3,36746;15215,10035
40,36000;3,37075;15222,83107
40,40000;3,37404;15232,01317
40,44000;3,37745;15239,98827
40,48000;3,38074;15248,23606
40,52000;3,38409;15257,86370
40,56000;3,38743;15266,08467
40,60000;3,39078;15273,51737
40,64000;3,39407;15282,09597
40,68000;3,39742;15289,09951
40,72000;3,40083;15297,82712
40,76000;3,40411;15305,96167
40,80000;3,40746;15312,19035
40,84000;3,41081;15320,98651
40,88000;3,41416;15329,27752
40,92000;3,41727;15335,54196
40,96000;3,42086;15344,32471
41,00000;3,42414;15352,59783
41,04000;3,42749;15358,86824
41,08000;3,43078;15364,70503
41,12000;3,43419;15373,07650
41,16000;3,43754;15380,69397
41,20000;3,44083;15387,07763
41,24000;3,44423;15393,56112
41,28000;3,44752;15400,19810
41,32000;3,45087;15406,88127
41,36000;3,45428;15413,05929
41,40000;3,45757;15421,57084
41,44000;3,46091;15426,72366
41,48000;3,46426;15432,68710
41,52000;3,46749;15436,47647
41,56000;3,47084;15441,53392
41,60000;3,47419;15447,13229
41,64000;3,47736;15454,20289
41,68000;3,48088;15462,36873
41,72000;3,48423;15468,18912
41,76000;3,48752;15473,42390
41,80000;3,49081;15477,00167
41,84000;3,49422;15483,07687
41,88000;3,49763;15490,83292
41,92000;3,50085;15494,85326
41,96000;3,50420;15497,81859
42,00000;3,50755;15503,44527
42,04000;3,51078;15507,56246
42,08000;3,51407;15511,49040
42,12000;3,51754;15519,66816
42,16000;3,52076;15525,12497
42,20000;3,52417;15528,76532
42,24000;3,52752;15531,97503
42,28000;3,53075;15535,68691
42,32000;3,53404;15540,13640
42,36000;3,53756;15545,10593
42,40000;3,54073;15549,11435
42,44000;3,54420;15552,51479
42,48000;3,54755;15556,51277
42,52000;3,55078;15559,62265
42,56000;3,55419;15562,28548
42,60000;3,55741;15565,95564
42,64000;3,56082;15571,19340
42,68000;3,56411;15574,69964
42,72000;3,56752;15579,21171
42,76000;3,57081;15583,02194
42,80000;3,57410;15585,02764
42,84000;3,57750;15587,18681
42,88000;3,58079;15590,27880
42,92000;3,58414;15593,11450
42,96000;3,58743;15594,78194
43,00000;3,59084;15595,89356
43,04000;3,59413;15597,34493
43,08000;3,59753;15598,34927
43,12000;3,60088;15599,17331
43,16000;3,60417;15601,27139
43,20000;3,60752;15601,75270
43,24000;3,61081;15601,33249
43,28000;3,61404;15602,01198
43,32000;3,61750;15604,81638
43,36000;3,62085;15606,09639
43,40000;3,62408;15605,78197
43,44000;3,62749;15606,75204
43,48000;3,63084;15607,82939
43,52000;3,63406;15606,94724
43,56000;3,63747;15606,65220
43,60000;3,64082;15608,61021
43,64000;3,64411;15610,26424
43,68000;3,64752;15610,08096
43,72000;3,65087;15611,56064
43,76000;3,65421;15613,32345
43,80000;3,65750;15611,18066
43,84000;3,66085;15610,01241
43,88000;3,66426;15610,30447
43,92000;3,66755;15609,48193
43,96000;3,67090;15608,71601
44,00000;3,67424;15611,75436
44,04000;3,67747;15610,87370
44,08000;3,68082;15608,92761
44,12000;3,68417;15608,73687
44,16000;3,68746;15608,07526
44,20000;3,69081;15607,95158
44,24000;3,69421;15608,01119
44,28000;3,69756;15609,31504
44,32000;3,70085;15612,21033
44,36000;3,70420;15611,60386
44,40000;3,70749;15611,17321
44,44000;3,71084;15610,57866
44,48000;3,71418;15611,23878
44,52000;3,71747;15611,19556
44,56000;3,72076;15611,88102
44,60000;3,72423;15614,45147
44,64000;3,72752;15614,25477
44,68000;3,73080;15611,94509
44,72000;3,73415;15611,22686
44,76000;3,73750;15610,80813
44,80000;3,74079;15608,65343
44,84000;3,74414;15607,04410
44,88000;3,74761;15606,71479
44,92000;3,75077;15602,30404
44,96000;3,75412;15594,44368
45,00000;3,75747;15585,99323
45,04000;3,76076;15575,99753
45,08000;3,76417;15560,32747
45,12000;3,76752;15539,38538
45,16000;3,77080;15505,59849
45,20000;3,77421;15437,58363
45,24000;3,77804;11725,69916
45,26400;3,78175;3113,44005