File: SU - Suspension/05 - Essais/Excels essais Optimus/Test_Rotules_31_01_19/P7_5.is_tens_RawData/Specimen_RawData_1.csv
Temps;Déplacement;Charge
(sec);(mm);(N)
0,00000;-0,11354;61,20043
0,04000;-0,11318;60,50190
0,08000;-0,11193;65,58350
0,12000;-0,11007;75,76095
0,16000;-0,10774;86,79309
0,20000;-0,10541;99,83813
0,24000;-0,10308;112,24605
0,28000;-0,10081;125,05277
0,32000;-0,09859;137,28481
0,36000;-0,09638;150,12424
0,40000;-0,09423;162,93651
0,44000;-0,09208;175,10429
0,48000;-0,09004;186,66711
0,52000;-0,08807;197,67380
0,56000;-0,08598;207,00435
0,60000;-0,08400;215,56197
0,64000;-0,08191;222,74286
0,68000;-0,07994;229,65888
0,72000;-0,07803;235,42796
0,76000;-0,07593;241,64477
0,80000;-0,07390;247,37590
0,84000;-0,07187;253,75572
0,88000;-0,06983;259,59739
0,92000;-0,06792;265,65248
0,96000;-0,06589;272,61116
1,00000;-0,06391;279,44057
1,04000;-0,06194;286,15065
1,08000;-0,05985;293,85947
1,12000;-0,05800;300,90555
1,16000;-0,05596;308,50915
1,20000;-0,05393;317,76049
1,24000;-0,05190;326,51480
1,28000;-0,04986;335,50465
1,32000;-0,04789;345,19255
1,36000;-0,04592;353,61431
1,40000;-0,04395;362,23966
1,44000;-0,04191;370,70857
1,48000;-0,03988;378,34302
1,52000;-0,03791;382,06610
1,56000;-0,03599;381,37750
1,60000;-0,03396;380,31030
1,64000;-0,03193;381,06202
1,68000;-0,02989;383,70094
1,72000;-0,02786;388,47362
1,76000;-0,02595;393,34283
1,80000;-0,02392;398,38436
1,84000;-0,02194;403,80340
1,88000;-0,01991;410,35595
1,92000;-0,01788;417,21403
1,96000;-0,01596;423,37277
2,00000;-0,01393;428,36484
2,04000;-0,01196;434,81058
2,08000;-0,00993;441,00657
2,12000;-0,00789;446,90059
2,16000;-0,00598;452,65164
2,20000;-0,00389;457,42509
2,24000;-0,00185;463,90225
2,28000;0,00012;469,68497
2,32000;0,00209;475,27426
2,36000;0,00407;480,99877
2,40000;0,00598;486,57237
2,44000;0,00801;492,92617
2,48000;0,01004;497,62134
2,52000;0,01202;503,67354
2,56000;0,01405;509,55932
2,60000;0,01590;514,68881
2,64000;0,01800;520,76266
2,68000;0,02009;526,84080
2,72000;0,02206;533,38804
2,76000;0,02415;537,97411
2,80000;0,02601;543,41676
2,84000;0,02804;548,83878
2,88000;0,03001;555,39659
2,92000;0,03205;562,53551
2,96000;0,03408;568,06807
3,00000;0,03599;574,70039
3,04000;0,03797;579,85908
3,08000;0,04006;586,30817
3,12000;0,04209;593,18054
3,16000;0,04412;599,33299
3,20000;0,04616;605,23408
3,24000;0,04801;610,57666
3,28000;0,05010;616,79864
3,32000;0,05208;624,15586
3,36000;0,05411;631,17454
3,40000;0,05614;637,50600
3,44000;0,05794;642,79200
3,48000;0,06003;649,25845
3,52000;0,06206;656,33054
3,56000;0,06403;662,98954
3,60000;0,06607;670,52897
3,64000;0,06804;677,89149
3,68000;0,07007;683,75026
3,72000;0,07211;691,33905
3,76000;0,07408;697,84820
3,80000;0,07611;703,79912
3,84000;0,07809;710,14501
3,88000;0,08000;715,24736
3,92000;0,08203;723,07317
3,96000;0,08406;729,60490
4,00000;0,08610;734,95340
4,04000;0,08807;741,24089
4,08000;0,09004;746,99195
4,12000;0,09208;753,84905
4,16000;0,09411;761,14736
4,20000;0,09620;767,81730
4,24000;0,09817;774,00897
4,28000;0,10009;779,41217
4,32000;0,10212;783,94311
4,36000;0,10409;790,07866
4,40000;0,10613;795,31623
4,44000;0,10816;800,92987
4,48000;0,11001;804,91072
4,52000;0,11205;807,88108
4,56000;0,11408;812,46356
4,60000;0,11605;814,35591
4,64000;0,11814;816,38731
4,68000;0,12006;816,98922
4,72000;0,12209;814,83042
4,76000;0,12406;811,10802
4,80000;0,12610;807,37341
4,84000;0,12807;801,34375
4,88000;0,13004;797,72873
4,92000;0,13196;790,43740
4,96000;0,13405;787,72586
5,00000;0,13608;783,00787
5,04000;0,13811;778,20271
5,08000;0,14015;774,88110
5,12000;0,14206;771,34692
5,16000;0,14415;768,34289
5,20000;0,14619;766,02353
5,24000;0,14816;761,36440
5,28000;0,15013;758,39604
5,32000;0,15204;754,79033
5,36000;0,15414;752,63986
5,40000;0,15611;750,42066
5,44000;0,15808;747,99084
5,48000;0,16012;744,30886
5,52000;0,16209;741,50101
5,56000;0,16406;737,38224
5,60000;0,16610;735,84309
5,64000;0,16813;732,18038
5,68000;0,17016;729,58828
5,72000;0,17207;725,71691
5,76000;0,17399;720,64330
5,80000;0,17602;720,36157
5,84000;0,17805;719,03686
5,88000;0,18009;716,40071
5,92000;0,18206;714,44130
5,96000;0,18397;711,43359
6,00000;0,18601;709,60238
6,04000;0,18804;709,67739
6,08000;0,19007;708,79110
6,12000;0,19216;705,41869
6,16000;0,19408;702,73648
6,20000;0,19611;698,98097
6,24000;0,19802;698,75671
6,28000;0,20006;697,11832
6,32000;0,20209;695,86551
6,36000;0,20406;692,95699
6,40000;0,20603;689,97331
6,44000;0,20807;688,88944
6,48000;0,21010;687,82554
6,52000;0,21213;684,86608
6,56000;0,21411;682,62024
6,60000;0,21608;677,94072
6,64000;0,21811;676,23192
6,68000;0,22009;672,47595
6,72000;0,22206;670,12296
6,76000;0,22409;668,40369
6,80000;0,22600;665,38383
6,84000;0,22804;661,49039
6,88000;0,23001;660,40847
6,92000;0,23204;657,01883
6,96000;0,23408;655,92560
7,00000;0,23599;653,91646
7,04000;0,23808;651,39201
7,08000;0,24011;650,39061
7,12000;0,24209;649,01398
7,16000;0,24412;648,02174
7,20000;0,24603;648,25504
7,24000;0,24807;647,26067
7,28000;0,25010;648,33397
7,32000;0,25207;647,02202
7,36000;0,25411;645,78652
7,40000;0,25602;644,96361
7,44000;0,25799;644,06716
7,48000;0,26002;643,88881
7,52000;0,26206;644,44477
7,56000;0,26415;641,96782
7,60000;0,26612;641,99367
7,64000;0,26804;638,03857
7,68000;0,27007;638,57902
7,72000;0,27210;638,61166
7,76000;0,27408;637,61864
7,80000;0,27617;636,29686
7,84000;0,27802;634,08599
7,88000;0,28005;632,46456
7,92000;0,28203;633,51495
7,96000;0,28406;632,37478
8,00000;0,28615;632,10642
8,04000;0,28801;630,00279
8,08000;0,29010;627,47081
8,12000;0,29207;626,57464
8,16000;0,29404;624,91130
8,20000;0,29614;623,11152
8,24000;0,29805;623,09518
8,28000;0,30008;619,50260
8,32000;0,30212;619,80453
8,36000;0,30403;617,47683
8,40000;0,30606;617,86347
8,44000;0,30804;616,91804
8,48000;0,31001;615,03532
8,52000;0,31204;615,47346
8,56000;0,31407;614,96687
8,60000;0,31611;613,05137
8,64000;0,31814;615,16184
8,68000;0,32011;613,33175
8,72000;0,32215;613,65431
8,76000;0,32418;612,76765
8,80000;0,32621;612,57216
8,84000;0,32818;612,48229
8,88000;0,33004;610,07300
8,92000;0,33207;609,32962
8,96000;0,33410;610,43683
9,00000;0,33614;608,48994
9,04000;0,33817;606,25146
9,08000;0,34008;604,24488
9,12000;0,34212;602,70033
9,16000;0,34415;600,73505
9,20000;0,34618;599,98031
9,24000;0,34815;599,04028
9,28000;0,35007;597,11342
9,32000;0,35204;594,46017
9,36000;0,35401;594,43912
9,40000;0,35605;593,57872
9,44000;0,35808;592,26663
9,48000;0,36005;589,82624
9,52000;0,36203;587,50813
9,56000;0,36406;586,89290
9,60000;0,36609;585,53461
9,64000;0,36806;584,86476
9,68000;0,37016;584,85665
9,72000;0,37207;582,66642
9,76000;0,37410;580,91730
9,80000;0,37608;579,78649
9,84000;0,37805;578,72222
9,88000;0,38014;579,68856
9,92000;0,38205;578,42890
9,96000;0,38409;577,59588
10,00000;0,38612;577,29534
10,04000;0,38809;575,70525
10,08000;0,39013;575,73393
10,12000;0,39210;575,63572
10,16000;0,39413;574,75483
10,20000;0,39611;574,09438
10,24000;0,39814;573,49685
10,28000;0,40011;571,28696
10,32000;0,40202;571,79243
10,36000;0,40406;570,69389
10,40000;0,40609;570,66106
10,44000;0,40812;568,94524
10,48000;0,41010;567,18336
10,52000;0,41213;565,72184
10,56000;0,41404;563,94343
10,60000;0,41608;563,69840
10,64000;0,41811;562,22505
10,68000;0,42014;560,65847
10,72000;0,42217;559,42023
10,76000;0,42403;556,74743
10,80000;0,42606;555,53634
10,84000;0,42809;556,18901
10,88000;0,43013;555,79753
10,92000;0,43216;554,73642
10,96000;0,43407;552,80123
11,00000;0,43610;552,12905
11,04000;0,43808;552,34274
11,08000;0,44011;552,61985
11,12000;0,44214;552,19652
11,16000;0,44406;551,56113
11,20000;0,44603;549,16898
11,24000;0,44806;551,37831
11,28000;0,45004;550,57039
11,32000;0,45207;550,39106
11,36000;0,45404;549,64661
11,40000;0,45601;549,07016
11,44000;0,45805;547,81265
11,48000;0,46002;548,06452
11,52000;0,46205;547,10070
11,56000;0,46409;547,83686
11,60000;0,46600;547,03383
11,64000;0,46803;546,72770
11,68000;0,47001;545,78735
11,72000;0,47204;545,50669
11,76000;0,47401;543,83962
11,80000;0,47598;543,97094
11,84000;0,47808;541,63318
11,88000;0,48011;540,86912
11,92000;0,48214;538,75903
11,96000;0,48412;537,85588
12,00000;0,48603;536,93848
12,04000;0,48806;535,91053
12,08000;0,49009;537,27538
12,12000;0,49207;536,74644
12,16000;0,49410;534,86675
12,20000;0,49601;535,35034
12,24000;0,49799;533,25924
12,28000;0,50008;535,75803
12,32000;0,50211;535,78811
12,36000;0,50409;534,37427
12,40000;0,50612;535,15215
12,44000;0,50803;534,34041
12,48000;0,51000;534,66670
12,52000;0,51210;536,32711
12,56000;0,51407;536,50937
12,60000;0,51610;537,11729
12,64000;0,51802;536,49978
12,68000;0,52005;536,23789
12,72000;0,52190;537,68982
12,76000;0,52411;539,48918
12,80000;0,52621;539,01314
12,84000;0,52806;536,98509
12,88000;0,53015;535,75481
12,92000;0,53213;536,42709
12,96000;0,53410;536,10248
13,00000;0,53619;535,16035
13,04000;0,53811;534,56300
13,08000;0,54008;532,25616
13,12000;0,54211;533,12979
13,16000;0,54414;531,92591
13,20000;0,54588;531,17070
13,24000;0,54815;533,96923
13,28000;0,55012;531,36959
13,32000;0,55216;529,70536
13,36000;0,55413;528,47723
13,40000;0,55616;527,61827
13,44000;0,55808;527,06967
13,48000;0,55999;525,35431
13,52000;0,56202;525,49709
13,56000;0,56405;526,58156
13,60000;0,56609;525,78696
13,64000;0,56812;524,76088
13,68000;0,57003;523,69381
13,72000;0,57207;522,74400
13,76000;0,57416;525,22593
13,80000;0,57619;525,42971
13,84000;0,57822;522,30349
13,88000;0,58002;521,00299
13,92000;0,58205;520,28280
13,96000;0,58402;521,77762
14,00000;0,58606;522,32868
14,04000;0,58809;521,49878
14,08000;0,59000;519,75586
14,12000;0,59204;519,33033
14,16000;0,59407;519,86109
14,20000;0,59610;521,07181
14,24000;0,59813;520,42962
14,28000;0,60011;519,42952
14,32000;0,60208;516,82829
14,36000;0,60405;515,31224
14,40000;0,60609;515,20788
14,44000;0,60812;516,24179
14,48000;0,61009;512,51417
14,52000;0,61201;510,48519
14,56000;0,61404;509,24588
14,60000;0,61607;508,83093
14,64000;0,61810;508,21630
14,68000;0,62014;507,58026
14,72000;0,62211;507,05802
14,76000;0,62408;504,85535
14,80000;0,62612;503,99555
14,84000;0,62809;503,32206
14,88000;0,63012;501,91460
14,92000;0,63209;501,74184
14,96000;0,63401;500,09065
15,00000;0,63604;500,68158
15,04000;0,63807;498,45395
15,08000;0,64005;497,81376
15,12000;0,64220;499,05800
15,16000;0,64411;498,35877
15,20000;0,64614;495,13420
15,24000;0,64818;494,32884
15,28000;0,65015;492,42214
15,32000;0,65212;491,75005
15,36000;0,65398;490,76439
15,40000;0,65607;489,95614
15,44000;0,65804;490,60630
15,48000;0,66008;489,21346
15,52000;0,66211;488,34295
15,56000;0,66396;487,88679
15,60000;0,66600;487,44334
15,64000;0,66815;490,50455
15,68000;0,67012;489,04442
15,72000;0,67215;487,07132
15,76000;0,67407;485,65613
15,80000;0,67604;484,06534
15,84000;0,67807;483,67316
15,88000;0,68011;482,97909
15,92000;0,68208;482,09988
15,96000;0,68405;481,40143
16,00000;0,68602;479,86805
16,04000;0,68806;480,04454
16,08000;0,68985;479,60533
16,12000;0,69212;481,58439
16,16000;0,69410;479,60989
16,20000;0,69601;476,07915
16,24000;0,69804;475,23938
16,28000;0,70008;474,50070
16,32000;0,70205;473,69422
16,36000;0,70408;473,49506
16,40000;0,70599;471,80182
16,44000;0,70809;471,86753
16,48000;0,71006;470,91427
16,52000;0,71209;468,20301
16,56000;0,71413;468,58033
16,60000;0,71604;466,91503
16,64000;0,71801;465,10505
16,68000;0,72010;466,49706
16,72000;0,72208;464,82589
16,76000;0,72411;462,28510
16,80000;0,72602;462,47086
16,84000;0,72806;460,30609
16,88000;0,73009;460,98675
16,92000;0,73206;459,41025
16,96000;0,73410;457,74253
17,00000;0,73607;457,66262
17,04000;0,73798;456,21172
17,08000;0,74007;457,75417
17,12000;0,74211;458,20894
17,16000;0,74414;457,39510
17,20000;0,74611;456,55416
17,24000;0,74797;454,36313
17,28000;0,75006;455,19089
17,32000;0,75203;455,62712
17,36000;0,75412;455,41292
17,40000;0,75616;454,96961
17,44000;0,75801;452,74068
17,48000;0,76004;452,61276
17,52000;0,76208;453,73468
17,56000;0,76417;453,24485
17,60000;0,76620;453,00527
17,64000;0,76812;450,69382
17,68000;0,77015;449,27597
17,72000;0,77206;448,87639
17,76000;0,77409;447,30655
17,80000;0,77607;447,41165
17,84000;0,77804;445,89820
17,88000;0,78007;443,54484
17,92000;0,78205;442,72272
17,96000;0,78408;441,33887
18,00000;0,78611;441,17575
18,04000;0,78809;438,58676
18,08000;0,79006;437,14731
18,12000;0,79209;435,91247
18,16000;0,79406;435,21468
18,20000;0,79610;433,34910
18,24000;0,79807;433,45657
18,28000;0,79998;432,58402
18,32000;0,80208;430,27238
18,36000;0,80411;429,93301
18,40000;0,80596;429,87815
18,44000;0,80817;430,23895
18,48000;0,81009;429,98437
18,52000;0,81212;428,11311
18,56000;0,81415;428,90315
18,60000;0,81613;429,15838
18,64000;0,81816;427,52977
18,68000;0,82007;428,01364
18,72000;0,82205;426,66164
18,76000;0,82402;427,45117
18,80000;0,82605;427,23333
18,84000;0,82808;426,65116
18,88000;0,83006;425,90047
18,92000;0,83197;424,92966
18,96000;0,83406;425,51160
19,00000;0,83604;425,42778
19,04000;0,83807;424,09520
19,08000;0,84010;423,43852
19,12000;0,84196;421,34053
19,16000;0,84405;421,08833
19,20000;0,84602;420,87524
19,24000;0,84811;419,42745
19,28000;0,85015;418,15913
19,32000;0,85200;415,79697
19,36000;0,85403;413,75486
19,40000;0,85607;415,57904
19,44000;0,85810;412,88668
19,48000;0,86013;411,29235
19,52000;0,86204;409,72065
19,56000;0,86408;407,36236
19,60000;0,86611;405,90945
19,64000;0,86814;405,68598
19,68000;0,87018;404,33304
19,72000;0,87209;403,35837
19,76000;0,87412;401,59808
19,80000;0,87610;400,69269
19,84000;0,87807;400,00640
19,88000;0,88010;400,12160
19,92000;0,88207;400,20309
19,96000;0,88405;399,50740
20,00000;0,88608;399,25990
20,04000;0,88805;397,84755
20,08000;0,89009;398,08475
20,12000;0,89212;398,96653
20,16000;0,89403;397,31576
20,20000;0,89607;397,90696
20,24000;0,89810;397,05625
20,28000;0,90007;396,71939
20,32000;0,90210;396,13554
20,36000;0,90396;394,97870
20,40000;0,90599;395,04943
20,44000;0,90802;394,44757
20,48000;0,91006;392,75764
20,52000;0,91209;391,32955
20,56000;0,91400;390,05452
20,60000;0,91603;388,33837
20,64000;0,91807;388,95735
20,68000;0,92016;387,06029
20,72000;0,92213;384,69504
20,76000;0,92411;383,73973
20,80000;0,92602;380,48688
20,84000;0,92805;378,47308
20,88000;0,93009;378,10511
20,92000;0,93206;377,32020
20,96000;0,93409;376,24419
21,00000;0,93588;374,89519
21,04000;0,93804;374,99662
21,08000;0,94007;374,14413
21,12000;0,94210;373,24326
21,16000;0,94414;372,90957
21,20000;0,94599;371,44350
21,24000;0,94808;370,00764
21,28000;0,95006;370,27847
21,32000;0,95197;369,45664
21,36000;0,95412;369,20535
21,40000;0,95597;369,40728
21,44000;0,95807;368,36506
21,48000;0,96010;367,67975
21,52000;0,96189;366,64500
21,56000;0,96417;368,12401
21,60000;0,96608;366,25946
21,64000;0,96811;364,41819
21,68000;0,97014;365,16623
21,72000;0,97212;363,70279
21,76000;0,97415;362,35431
21,80000;0,97612;361,51407
21,84000;0,97810;358,16538
21,88000;0,98007;358,04943
21,92000;0,98210;356,83564
21,96000;0,98413;355,90716
22,00000;0,98617;353,87657
22,04000;0,98808;350,05671
22,08000;0,98999;349,54825
22,12000;0,99215;349,74436
22,16000;0,99412;346,74681
22,20000;0,99615;345,26463
22,24000;0,99807;342,49942
22,28000;1,00004;340,81663
22,32000;1,00207;339,93849
22,36000;1,00410;339,36312
22,40000;1,00614;338,97595
22,44000;1,00805;337,08795
22,48000;1,01008;335,34071
22,52000;1,01206;335,23536
22,56000;1,01409;335,51317
22,60000;1,01618;335,24099
22,64000;1,01810;333,91849
22,68000;1,02007;332,78745
22,72000;1,02192;332,17103
22,76000;1,02407;332,64353
22,80000;1,02611;332,06309
22,84000;1,02808;330,39623
22,88000;1,03011;327,82683
22,92000;1,03215;326,64991
22,96000;1,03412;325,16944
23,00000;1,03609;323,82039
23,04000;1,03812;321,90278
23,08000;1,04010;320,42076
23,12000;1,04213;319,59335
23,16000;1,04416;317,60409
23,20000;1,04614;316,51305
23,24000;1,04811;315,61262
23,28000;1,05008;314,90671
23,32000;1,05212;314,03184
23,36000;1,05415;313,30823
23,40000;1,05612;312,51616
23,44000;1,05815;312,93032
23,48000;1,06007;312,46089
23,52000;1,06204;311,38796
23,56000;1,06407;312,06710
23,60000;1,06611;312,62683
23,64000;1,06808;310,95422
23,68000;1,07011;309,22380
23,72000;1,07203;308,86715
23,76000;1,07400;309,24426
23,80000;1,07615;309,45633
23,84000;1,07812;307,34951
23,88000;1,08016;306,41307
23,92000;1,08207;305,42416
23,96000;1,08410;304,76293
24,00000;1,08614;305,68959
24,04000;1,08817;305,04982
24,08000;1,09014;304,31102
24,12000;1,09200;302,28451
24,16000;1,09409;302,78023
24,20000;1,09606;302,25392
24,24000;1,09803;301,50679
24,28000;1,10013;301,39750
24,32000;1,10204;300,94536
24,36000;1,10407;299,06398
24,40000;1,10605;299,08840
24,44000;1,10808;298,45852
24,48000;1,11011;298,57687
24,52000;1,11208;297,64404
24,56000;1,11406;296,62689
24,60000;1,11603;296,23909
24,64000;1,11806;296,29942
24,68000;1,12004;296,65867
24,72000;1,12207;297,27155
24,76000;1,12398;296,92508
24,80000;1,12602;297,19085
24,84000;1,12805;297,79298
24,88000;1,13002;295,51499
24,92000;1,13205;295,84761
24,96000;1,13397;294,86851
25,00000;1,13606;295,28949
25,04000;1,13803;294,29393
25,08000;1,14007;293,84641
25,12000;1,14216;293,79243
25,16000;1,14401;293,05140
25,20000;1,14604;292,31634
25,24000;1,14814;292,44125
25,28000;1,15011;291,17598
25,32000;1,15214;291,08799
25,36000;1,15406;289,36139
25,40000;1,15567;288,57428
25,44000;1,15812;292,49673
25,48000;1,16010;290,05562
25,52000;1,16213;287,78284
25,56000;1,16404;287,57104
25,60000;1,16607;286,46006
25,64000;1,16811;287,52421
25,68000;1,17008;287,20140
25,72000;1,17211;286,74332
25,76000;1,17409;287,38584
25,80000;1,17600;286,53899
25,84000;1,17803;286,13773
25,88000;1,18001;286,73348
25,92000;1,18210;286,91450
25,96000;1,18407;284,98992
26,00000;1,18598;284,48256
26,04000;1,18808;283,94859
26,08000;1,19005;284,27318
26,12000;1,19208;283,64256
26,16000;1,19418;284,16482
26,20000;1,19603;283,59706
26,24000;1,19812;283,47920
26,28000;1,20009;283,39943
26,32000;1,20213;282,75780
26,36000;1,20416;282,71202
26,40000;1,20601;282,25698
26,44000;1,20805;281,95493
26,48000;1,21008;283,71508
26,52000;1,21211;280,63229
26,56000;1,21415;280,26847
26,60000;1,21606;280,90531
26,64000;1,21809;279,77661
26,68000;1,22012;280,22665
26,72000;1,22210;279,13488
26,76000;1,22413;278,81705
26,80000;1,22610;278,06507
26,84000;1,22802;277,16882
26,88000;1,23005;277,62076
26,92000;1,23202;276,95103
26,96000;1,23411;277,11799
27,00000;1,23609;276,74220
27,04000;1,23800;275,09916
27,08000;1,24009;275,99137
27,12000;1,24213;276,14629
27,16000;1,24398;275,44710
27,20000;1,24619;278,23010
27,24000;1,24811;275,33253
27,28000;1,25014;275,27530
27,32000;1,25211;276,29151
27,36000;1,25408;275,20680
27,40000;1,25612;274,70931
27,44000;1,25809;274,82829
27,48000;1,26006;274,37748
27,52000;1,26210;273,97925
27,56000;1,26407;273,45247
27,60000;1,26610;273,65421
27,64000;1,26814;272,59563
27,68000;1,27005;271,51620
27,72000;1,27208;271,39382
27,76000;1,27405;270,99182
27,80000;1,27579;270,85256
27,84000;1,27812;271,73688
27,88000;1,27997;270,26485
27,92000;1,28207;269,32098
27,96000;1,28404;268,37925
28,00000;1,28607;268,68351
28,04000;1,28810;268,81744
28,08000;1,29002;268,51948
28,12000;1,29211;267,05391
28,16000;1,29402;266,98834
28,20000;1,29606;267,14122
28,24000;1,29809;266,45928
28,28000;1,30000;266,68950
28,32000;1,30204;265,83816
28,36000;1,30407;265,84980
28,40000;1,30610;265,55341
28,44000;1,30807;265,16018
28,48000;1,31005;265,76426
28,52000;1,31202;265,73483
28,56000;1,31405;266,57330
28,60000;1,31609;267,36159
28,64000;1,31812;266,10608
28,68000;1,32009;266,56715
28,72000;1,32195;265,80235
28,76000;1,32404;266,14326
28,80000;1,32601;267,04420
28,84000;1,32804;265,98363
28,88000;1,33008;264,28953
28,92000;1,33199;263,93111
28,96000;1,33402;263,30934
29,00000;1,33606;263,22068
29,04000;1,33809;263,21304
29,08000;1,34012;262,13941
29,12000;1,34203;261,60658
29,16000;1,34407;261,03349
29,20000;1,34604;261,20380
29,24000;1,34801;260,88287
29,28000;1,35005;260,43446
29,32000;1,35202;260,24221
29,36000;1,35399;258,83247
29,40000;1,35603;259,27017
29,44000;1,35806;258,13093
29,48000;1,36003;258,44516
29,52000;1,36206;257,30133
29,56000;1,36398;256,15462
29,60000;1,36601;256,50864
29,64000;1,36804;257,37458
29,68000;1,37002;255,82449
29,72000;1,37205;256,30170
29,76000;1,37396;255,79745
29,80000;1,37600;255,72656
29,84000;1,37803;255,61657
29,88000;1,38000;254,43712
29,92000;1,38209;254,64727
29,96000;1,38401;254,96045
30,00000;1,38604;253,61194
30,04000;1,38813;254,19556
30,08000;1,39011;253,35120
30,12000;1,39214;252,48502
30,16000;1,39405;252,00481
30,20000;1,39602;251,33262
30,24000;1,39812;252,00599
30,28000;1,40009;251,62245
30,32000;1,40212;250,48573
30,36000;1,40410;251,01013
30,40000;1,40601;250,22360
30,44000;1,40810;251,58485
30,48000;1,41008;250,54771
30,52000;1,41217;250,37399
30,56000;1,41420;250,16838
30,60000;1,41605;248,67493
30,64000;1,41815;248,62411
30,68000;1,42012;248,24820
30,72000;1,42215;248,15723
30,76000;1,42419;248,43309
30,80000;1,42604;246,31554
30,84000;1,42807;246,41999
30,88000;1,43005;245,91873
30,92000;1,43208;245,81561
30,96000;1,43411;245,60252
31,00000;1,43602;244,83984
31,04000;1,43812;243,88032
31,08000;1,44009;243,74479
31,12000;1,44212;244,24056
31,16000;1,44416;243,80512
31,20000;1,44607;243,31633
31,24000;1,44804;242,69503
31,28000;1,45007;244,36894
31,32000;1,45211;242,97070
31,36000;1,45414;243,89874
31,40000;1,45611;243,67759
31,44000;1,45803;242,63465
31,48000;1,46006;243,05291
31,52000;1,46209;241,84356
31,56000;1,46407;241,45283
31,60000;1,46616;242,29435
31,64000;1,46807;241,31769
31,68000;1,47010;241,31709
31,72000;1,47214;240,78297
31,76000;1,47417;239,75424
31,80000;1,47614;239,59915
31,84000;1,47806;240,16921
31,88000;1,48009;238,80969
31,92000;1,48212;238,59518
31,96000;1,48415;238,22573
32,00000;1,48619;236,78474
32,04000;1,48810;236,55416
32,08000;1,49007;235,92510
32,12000;1,49211;236,45794
32,16000;1,49414;236,09202
32,20000;1,49611;235,13183
32,24000;1,49809;234,84787
32,28000;1,50000;234,65597
32,32000;1,50203;234,98517
32,36000;1,50400;234,62151
32,40000;1,50604;234,37801
32,44000;1,50813;234,87827
32,48000;1,51004;233,28897
32,52000;1,51202;233,29642
32,56000;1,51405;233,73519
32,60000;1,51608;233,95177
32,64000;1,51817;233,15677
32,68000;1,52003;231,97769
32,72000;1,52206;232,35162
32,76000;1,52403;231,87636
32,80000;1,52607;232,08233
32,84000;1,52810;232,53986
32,88000;1,53001;231,94919
32,92000;1,53211;230,27281
32,96000;1,53408;230,23316
33,00000;1,53605;230,02089
33,04000;1,53808;229,21781
33,08000;1,54006;229,92003
33,12000;1,54203;228,61417
33,16000;1,54406;229,27695
33,20000;1,54604;228,10928
33,24000;1,54801;227,47186
33,28000;1,55004;228,10297
33,32000;1,55196;227,74856
33,36000;1,55399;226,94250
33,40000;1,55602;226,66203
33,44000;1,55805;225,82256
33,48000;1,56009;224,69971
33,52000;1,56200;224,35631
33,56000;1,56409;224,47300
33,60000;1,56607;223,62794
33,64000;1,56810;222,49157
33,68000;1,57007;221,39715
33,72000;1,57199;221,26543
33,76000;1,57402;220,37183
33,80000;1,57605;221,23165
33,84000;1,57808;220,68152
33,88000;1,58018;219,89804
33,92000;1,58209;219,09515
33,96000;1,58406;218,37160
34,00000;1,58610;219,48765
34,04000;1,58807;218,50909
34,08000;1,59016;218,47989
34,12000;1,59213;219,17874
34,16000;1,59405;216,76745
34,20000;1,59602;217,18375
34,24000;1,59805;217,21052
34,28000;1,60009;216,61003
34,32000;1,60212;216,47043
34,36000;1,60403;214,92871
34,40000;1,60607;214,40224
34,44000;1,60804;213,88109
34,48000;1,61007;213,25939
34,52000;1,61210;213,57043
34,56000;1,61402;212,90008
34,60000;1,61611;212,25663
34,64000;1,61808;211,53479
34,68000;1,62006;211,58713
34,72000;1,62209;211,28606
34,76000;1,62406;210,35864
34,80000;1,62615;209,34781
34,84000;1,62813;208,96031
34,88000;1,63016;208,25020
34,92000;1,63219;208,26210
34,96000;1,63411;206,94798
35,00000;1,63614;206,28572
35,04000;1,63811;205,10911
35,08000;1,64015;204,81893
35,12000;1,64218;204,53616
35,16000;1,64409;203,86621
35,20000;1,64600;202,37709
35,24000;1,64810;203,22253
35,28000;1,65007;202,66450
35,32000;1,65216;202,70750
35,36000;1,65414;201,28877
35,40000;1,65605;200,02725
35,44000;1,65802;200,03058
35,48000;1,66006;199,11767
35,52000;1,66209;198,93646
35,56000;1,66412;197,54539
35,60000;1,66603;196,64061
35,64000;1,66807;195,88005
35,68000;1,67004;195,68885
35,72000;1,67207;195,19351
35,76000;1,67417;195,56961
35,80000;1,67608;194,71106
35,84000;1,67811;192,22025
35,88000;1,68008;193,32686
35,92000;1,68212;193,33838
35,96000;1,68415;192,60943
36,00000;1,68612;191,20030
36,04000;1,68810;188,57862
36,08000;1,69013;189,51478
36,12000;1,69210;189,10607
36,16000;1,69408;188,12980
36,20000;1,69611;188,29291
36,24000;1,69808;187,53130
36,28000;1,70011;187,35733
36,32000;1,70215;186,38463
36,36000;1,70412;185,57284
36,40000;1,70603;184,88792
36,44000;1,70807;185,68889
36,48000;1,71010;183,90112
36,52000;1,71207;183,13120
36,56000;1,71411;182,65408
36,60000;1,71608;182,49524
36,64000;1,71805;182,84760
36,68000;1,72008;182,48834
36,72000;1,72212;180,81113
36,76000;1,72415;180,80785
36,80000;1,72618;179,27710
36,84000;1,72810;178,72243
36,88000;1,73007;176,88329
36,92000;1,73204;176,92501
36,96000;1,73407;176,46719
37,00000;1,73611;174,91509
37,04000;1,73808;174,35591
37,08000;1,73999;173,35267
37,12000;1,74209;174,23708
37,16000;1,74418;174,46583
37,20000;1,74615;173,72911
37,24000;1,74819;172,00211
37,28000;1,75004;170,28564
37,32000;1,75207;171,67826
37,36000;1,75404;170,58986
37,40000;1,75602;170,24778
37,44000;1,75811;170,38077
37,48000;1,75996;169,73233
37,52000;1,76206;169,05161
37,56000;1,76409;168,89145
37,60000;1,76606;167,29265
37,64000;1,76815;166,94578
37,68000;1,77007;166,25556
37,72000;1,77210;166,14882
37,76000;1,77407;165,34153
37,80000;1,77611;165,84077
37,84000;1,77814;164,54736
37,87200;1,77969;163,33602