File: SU - Suspension/05 - Essais/Excels essais Optimus/Temoins et tests triangles/Triangles tests/R-R sup/RR sup rr.is_tcyclic_RawData/Specimen_RawData_1.csv
Temps;Déplacement;Charge
(sec);(mm);(N)
0,00000;-289,38686;0,44888
0,00200;-289,38686;0,45510
0,00400;-289,38686;0,46801
0,10400;-289,38465;14,60130
0,20400;-289,37884;91,47454
0,30400;-289,37295;178,19499
0,40400;-289,36736;252,61967
0,50400;-289,36213;312,46252
0,60400;-289,35703;314,53355
0,70400;-289,35179;314,16279
0,80400;-289,34699;313,92935
0,90400;-289,34196;313,37363
1,00400;-289,33700;314,25597
1,10400;-289,33197;315,50110
1,20400;-289,32691;314,06055
1,30400;-289,32191;315,01229
1,40400;-289,31674;316,99240
1,50400;-289,31187;315,73558
1,60400;-289,30699;316,10709
1,70400;-289,30189;315,98255
1,80400;-289,29688;316,07922
1,90400;-289,29191;316,72732
2,00400;-289,28690;317,49117
2,10400;-289,28187;317,39934
2,20400;-289,27686;321,90506
2,30400;-289,27194;365,09058
2,40400;-289,26693;428,46953
2,50400;-289,26196;490,90483
2,60400;-289,25702;554,24357
2,70400;-289,25192;618,94567
2,80400;-289,24691;686,96551
2,90400;-289,24188;747,11707
3,00400;-289,23698;808,79712
3,10400;-289,23189;872,83226
3,20400;-289,22694;932,38503
3,30400;-289,22191;990,68815
3,40400;-289,21701;1051,19022
3,50400;-289,21193;1107,88792
3,60400;-289,20701;1166,97662
3,70400;-289,20205;1223,83293
3,80400;-289,19689;1283,67571
3,90400;-289,19190;1340,90064
4,00400;-289,18691;1398,47072
4,10400;-289,18184;1454,17042
4,20400;-289,17700;1506,81958
4,30400;-289,17186;1562,24864
4,40400;-289,16689;1615,42036
4,50400;-289,16201;1668,74286
4,60400;-289,15690;1723,33084
4,70400;-289,15202;1774,65100
4,80400;-289,14686;1829,53756
4,90400;-289,14209;1879,40206
5,00400;-289,13688;1934,25640
5,10400;-289,13192;1984,77786
5,20400;-289,12695;2033,81833
5,30400;-289,12202;2084,00153
5,40400;-289,11697;2135,51540
5,50400;-289,11203;2185,91634
5,60400;-289,10698;2236,28525
5,70400;-289,10197;2287,83842
5,80400;-289,09694;2338,16560
5,90400;-289,09193;2391,04182
6,00400;-289,08690;2438,76763
6,10400;-289,08195;2486,44631
6,20400;-289,07679;2534,39900
6,30400;-289,07187;2579,50425
6,40400;-289,06694;2626,87132
6,50400;-289,06196;2672,38617
6,60400;-289,05695;2713,97028
6,70400;-289,05185;2757,53736
6,80400;-289,04691;2796,48416
6,90400;-289,04187;2837,73653
7,00400;-289,03686;2875,29752
7,10400;-289,03183;2915,09442
7,20400;-289,02687;2949,06627
7,30400;-289,02190;2982,19845
7,40400;-289,01696;3013,64176
7,50400;-289,01186;3043,11831
7,60400;-289,00690;3068,97648
7,70400;-289,00182;3090,42465
7,80400;-288,99699;3108,26227
7,90400;-288,99189;3125,96001
8,00400;-288,98694;3134,66564
8,10400;-288,98180;3140,46256
8,20400;-288,97690;3141,47919
8,30400;-288,97187;3140,99528
8,40400;-288,96691;3141,26648
8,50400;-288,96183;3136,00339
8,60400;-288,95682;3131,97039
8,70400;-288,95184;3126,04457
8,80400;-288,94680;3123,64735
8,90400;-288,94192;3118,55245
9,00400;-288,93681;3116,91388
9,10400;-288,93188;3118,28963
9,20400;-288,92683;3121,16519
9,30400;-288,92189;3124,89048
9,40400;-288,91679;3129,93489
9,50400;-288,91208;3130,25974
9,60400;-288,90692;3134,11541
9,70400;-288,90198;3131,05918
9,80400;-288,89688;3133,13007
9,90400;-288,89200;3128,34494
10,00400;-288,88684;3127,14204
10,10400;-288,88196;3123,43184
10,20400;-288,87685;3121,03815
10,30400;-288,87190;3118,48428
10,40400;-288,86687;3113,49370
10,50400;-288,86192;3122,25949
10,60400;-288,85689;3147,85950
10,70400;-288,85193;3185,87944
10,80400;-288,84690;3224,15866
10,90400;-288,84184;3261,64588
11,00400;-288,83692;3302,25155
11,10400;-288,83191;3336,44599
11,20400;-288,82693;3369,43492
11,30400;-288,82187;3405,78891
11,40400;-288,81695;3437,19125
11,50400;-288,81174;3473,57839
11,60400;-288,80708;3505,28099
11,70400;-288,80175;3544,97507
11,80400;-288,79687;3573,29734
11,90400;-288,79182;3604,22172
12,00400;-288,78694;3633,73980
12,10400;-288,78197;3664,47829
12,20400;-288,77696;3697,53279
12,30400;-288,77191;3728,53763
12,40400;-288,76692;3766,58738
12,50400;-288,76187;3796,40982
12,60400;-288,75694;3825,88878
12,70400;-288,75183;3857,68153
12,80400;-288,74688;3886,29921
12,90400;-288,74185;3916,73446
13,00400;-288,73689;3946,60570
13,10400;-288,73187;3979,16399
13,20400;-288,72686;4011,50286
13,30400;-288,72194;4037,97217
13,40400;-288,71687;4070,33376
13,50400;-288,71201;4096,93979
13,60400;-288,70683;4128,28363
13,70400;-288,70191;4155,70401
13,80400;-288,69685;4184,63983
13,90400;-288,69187;4210,66321
14,00400;-288,68686;4237,99381
14,10400;-288,68183;4274,78813
14,20400;-288,67684;4302,27630
14,30400;-288,67196;4325,54446
14,40400;-288,66693;4352,90188
14,50400;-288,66209;4378,76508
14,60400;-288,65688;4410,42297
14,70400;-288,65194;4435,61785
14,80400;-288,64684;4465,97375
14,90400;-288,64196;4491,78964
15,00400;-288,63691;4520,37975
15,10400;-288,63197;4550,20964
15,20400;-288,62700;4576,98554
15,30400;-288,62193;4610,18868
15,40400;-288,61701;4636,74627
15,50400;-288,61195;4664,71426
15,60400;-288,60690;4691,46557
15,70400;-288,60189;4721,00489
15,80400;-288,59681;4749,79281
15,90400;-288,59191;4774,41140
16,00400;-288,58693;4802,97580
16,10400;-288,58181;4831,66948
16,20400;-288,57689;4857,10353
16,30400;-288,57188;4884,71650
16,40400;-288,56691;4909,96242
16,50400;-288,56190;4939,25698
16,60400;-288,55693;4965,31911
16,70400;-288,55186;4994,97764
16,80400;-288,54694;5018,87649
16,90400;-288,54184;5046,07856
17,00400;-288,53690;5071,55284
17,10400;-288,53193;5097,51253
17,20400;-288,52692;5126,03186
17,30400;-288,52187;5152,97167
17,40400;-288,51699;5183,55034
17,50400;-288,51196;5210,49835
17,60400;-288,50695;5237,43220
17,70400;-288,50198;5263,86686
17,80400;-288,49691;5292,02595
17,90400;-288,49199;5322,35950
18,00400;-288,48693;5350,82258
18,10400;-288,48194;5376,68653
18,20400;-288,47694;5403,73251
18,30400;-288,47203;5429,27198
18,40400;-288,46683;5460,45341
18,50400;-288,46197;5482,96608
18,60400;-288,45690;5511,13375
18,70400;-288,45193;5536,46125
18,80400;-288,44686;5563,98109
18,90400;-288,44189;5590,86464
19,00400;-288,43693;5616,57771
19,10400;-288,43191;5641,45856
19,20400;-288,42689;5667,45922
19,30400;-288,42198;5692,34565
19,40400;-288,41691;5721,42340
19,50400;-288,41194;5746,63281
19,60400;-288,40683;5773,97421
19,70400;-288,40195;5797,62980
19,80400;-288,39692;5823,13985
19,90400;-288,39203;5846,74254
20,00400;-288,38687;5874,18117
20,10400;-288,38199;5898,11951
20,20400;-288,37683;5922,73660
20,30400;-288,37189;5949,00809
20,40400;-288,36684;5971,36430
20,50400;-288,36178;5993,24182
20,54600;-288,35975;6000,14329
20,54800;-288,35963;6000,41226
20,64800;-288,35922;5983,73190
20,74800;-288,36356;5906,93541
20,84800;-288,37081;5775,84244
20,94800;-288,37778;5649,30104
21,04800;-288,38396;5544,80404
21,14800;-288,38940;5452,70555
21,24800;-288,39465;5369,42221
21,34800;-288,39976;5287,19947
21,44800;-288,40482;5207,57399
21,54800;-288,40974;5130,70486
21,64800;-288,41473;5052,71219
21,74800;-288,41978;4974,12235
21,84800;-288,42479;4896,85945
21,94800;-288,42982;4818,46780
22,04800;-288,43470;4745,36680
22,14800;-288,43980;4667,52946
22,24800;-288,44476;4591,49554
22,34800;-288,44979;4513,98082
22,44800;-288,45474;4438,91399
22,54800;-288,45971;4365,56153
22,64800;-288,46478;4287,40419
22,74800;-288,46970;4214,30916
22,84800;-288,47478;4137,99323
22,94800;-288,47974;4061,69593
23,04800;-288,48477;3987,61407
23,14800;-288,48978;3912,51594
23,24800;-288,49475;3840,95237
23,34800;-288,49982;3764,70014
23,44800;-288,50473;3691,66918
23,54800;-288,50980;3617,05832
23,64800;-288,51479;3544,85996
23,74800;-288,51978;3472,27678
23,84800;-288,52470;3399,29238
23,94800;-288,52971;3329,98894
24,04800;-288,53469;3257,16957
24,14800;-288,53983;3181,86022
24,24800;-288,54474;3112,77825
24,34800;-288,54974;3038,57196
24,44800;-288,55465;2970,14453
24,54800;-288,55972;2898,32130
24,64800;-288,56477;2826,07973
24,74800;-288,56978;2756,32031
24,84800;-288,57475;2688,08212
24,94800;-288,57976;2618,53784
25,04800;-288,58479;2547,35332
25,14800;-288,58975;2481,92865
25,24800;-288,59483;2410,30119
25,34800;-288,59979;2342,86357
25,44800;-288,60476;2276,62250
25,54800;-288,60979;2206,84912
25,64800;-288,61485;2141,15195
25,74800;-288,62001;2069,81804
25,84800;-288,62491;2002,45380
25,94800;-288,62970;1936,86541
26,04800;-288,63471;1873,56826
26,14800;-288,63981;1808,82625
26,24800;-288,64475;1743,11567
26,34800;-288,64972;1682,08536
26,44800;-288,65468;1619,40921
26,54800;-288,65971;1556,44026
26,64800;-288,66485;1489,63491
26,74800;-288,66976;1428,06098
26,84800;-288,67476;1367,50061
26,94800;-288,67975;1308,52228
27,04800;-288,68468;1251,21390
27,14800;-288,68973;1188,33715
27,24800;-288,69485;1123,34089
27,34800;-288,69972;1067,49414
27,44800;-288,70478;1009,27595
27,54800;-288,70976;954,30296
27,64800;-288,71477;896,40748
27,74800;-288,71980;839,63992
27,84800;-288,72475;779,47206
27,94800;-288,72978;724,31564
28,04800;-288,73466;672,46221
28,14800;-288,73976;616,22495
28,24800;-288,74474;564,93934
28,34800;-288,74980;512,77070
28,44800;-288,75472;463,88344
28,54800;-288,75973;414,61554
28,64800;-288,76476;365,07933
28,74800;-288,76977;321,25120
28,84800;-288,77474;314,67723
28,94800;-288,77975;313,88463
29,04800;-288,78473;313,51103
29,14800;-288,78974;312,88257
29,24800;-288,79466;312,48606
29,34800;-288,79967;312,07511
29,44800;-288,80477;311,99011
29,54800;-288,80971;312,23791
29,64800;-288,81475;312,97409
29,74800;-288,81975;311,71779
29,84800;-288,82479;311,63064
29,94800;-288,82980;311,51141
30,04800;-288,83483;311,73483
30,14800;-288,83984;307,36267
30,24800;-288,84487;289,87471
30,34800;-288,84983;249,10162
30,44800;-288,85480;193,42108
30,54800;-288,85975;131,15464
30,64800;-288,86443;73,52783
30,74800;-288,86974;10,48569
30,76800;-288,87078;-0,17337