File: SU - Suspension/05 - Essais/Excels essais Optimus/collage alu carbone 05_02_19/collage1.is_tens_RawData/Specimen_RawData_1.csv
Temps;Déplacement;Charge
(sec);(mm);(N)
0,00000;0,01279;42,60442
0,04000;0,01315;42,68252
0,08000;0,01489;46,68908
0,12000;0,01812;58,73318
0,16000;0,02182;73,84695
0,20000;0,02559;89,41145
0,24000;0,02948;105,66189
0,28000;0,03336;121,79145
0,32000;0,03707;137,93336
0,36000;0,04078;153,51651
0,40000;0,04436;168,67896
0,44000;0,04777;182,78648
0,48000;0,05124;197,35247
0,52000;0,05477;210,43171
0,56000;0,05812;222,69115
0,60000;0,06152;234,09757
0,64000;0,06493;246,15489
0,68000;0,06822;257,54650
0,72000;0,07157;269,24999
0,76000;0,07492;281,02538
0,80000;0,07820;293,28233
0,84000;0,08155;305,24945
0,88000;0,08490;317,83888
0,92000;0,08819;329,88572
0,96000;0,09154;342,21201
1,00000;0,09489;354,88300
1,04000;0,09823;368,84574
1,08000;0,10158;381,09627
1,12000;0,10499;394,64366
1,16000;0,10828;408,11985
1,20000;0,11163;421,17001
1,24000;0,11492;435,02548
1,28000;0,11826;449,68082
1,32000;0,12155;464,37192
1,36000;0,12496;479,22111
1,40000;0,12831;494,57476
1,44000;0,13160;508,30916
1,48000;0,13489;523,25949
1,52000;0,13823;538,29495
1,56000;0,14152;553,93730
1,60000;0,14487;568,81779
1,64000;0,14822;584,49213
1,68000;0,15151;600,32676
1,72000;0,15485;615,29847
1,76000;0,15820;630,09588
1,80000;0,16155;645,03839
1,84000;0,16484;659,28865
1,88000;0,16825;674,83466
1,92000;0,17160;691,28554
1,96000;0,17494;705,80454
2,00000;0,17829;721,58212
2,04000;0,18164;736,97446
2,08000;0,18487;752,71986
2,12000;0,18822;767,37679
2,16000;0,19157;782,99632
2,20000;0,19479;799,27882
2,24000;0,19820;814,56834
2,28000;0,20155;831,57420
2,32000;0,20484;847,05865
2,36000;0,20813;862,13415
2,40000;0,21154;878,44869
2,44000;0,21476;894,03652
2,48000;0,21811;908,66433
2,52000;0,22158;925,36639
2,56000;0,22487;942,57323
2,60000;0,22822;957,36757
2,64000;0,23145;972,74529
2,68000;0,23491;989,67990
2,72000;0,23820;1004,33733
2,76000;0,24149;1019,44190
2,80000;0,24490;1035,80821
2,84000;0,24825;1052,07711
2,88000;0,25153;1066,31313
2,92000;0,25488;1080,85535
2,96000;0,25817;1095,13309
3,00000;0,26152;1108,85929
3,04000;0,26487;1123,87268
3,08000;0,26810;1138,11409
3,12000;0,27150;1152,90415
3,16000;0,27485;1167,36218
3,20000;0,27814;1181,30669
3,24000;0,28155;1196,63151
3,28000;0,28490;1210,72959
3,32000;0,28819;1223,66734
3,36000;0,29159;1236,99699
3,40000;0,29494;1251,16659
3,44000;0,29823;1263,93437
3,48000;0,30152;1276,16394
3,52000;0,30493;1289,21513
3,56000;0,30821;1302,37499
3,60000;0,31150;1315,02291
3,64000;0,31497;1328,15503
3,68000;0,31832;1341,55899
3,72000;0,32155;1353,28034
3,76000;0,32490;1365,91662
3,80000;0,32830;1378,33925
3,84000;0,33159;1389,35447
3,88000;0,33494;1400,63036
3,92000;0,33823;1411,69000
3,96000;0,34158;1423,47999
4,00000;0,34493;1434,07071
4,04000;0,34821;1444,21039
4,08000;0,35150;1454,26644
4,12000;0,35485;1463,84453
4,16000;0,35820;1473,29243
4,20000;0,36149;1482,64356
4,24000;0,36490;1492,76946
4,28000;0,36824;1502,43985
4,32000;0,37153;1511,21551
4,36000;0,37482;1519,61576
4,40000;0,37817;1528,65620
4,44000;0,38146;1537,25930
4,48000;0,38481;1545,03258
4,52000;0,38821;1554,17761
4,56000;0,39156;1562,38433
4,60000;0,39485;1569,19230
4,64000;0,39814;1577,80349
4,68000;0,40155;1585,47964
4,72000;0,40466;1593,11201
4,76000;0,40812;1600,87068
4,80000;0,41153;1610,06525
4,84000;0,41482;1617,74661
4,88000;0,41817;1624,52776
4,92000;0,42152;1631,00511
4,96000;0,42480;1638,32605
5,00000;0,42815;1645,76769
5,04000;0,43150;1651,63111
5,08000;0,43479;1658,65459
5,12000;0,43820;1665,48435
5,16000;0,44149;1672,46312
5,20000;0,44483;1678,80803
5,24000;0,44818;1684,90019
5,28000;0,45147;1691,93558
5,32000;0,45476;1698,89368
5,36000;0,45817;1707,06529
5,40000;0,46157;1716,36697
5,44000;0,46486;1725,11898
5,48000;0,46821;1734,51565
5,52000;0,47150;1743,88196
5,56000;0,47491;1754,15743
5,60000;0,47814;1763,63029
5,64000;0,48154;1774,27810
5,68000;0,48489;1785,71288
5,72000;0,48818;1795,45209
5,76000;0,49135;1805,01156
5,80000;0,49494;1816,94478
5,84000;0,49829;1827,60935
5,88000;0,50151;1836,41519
5,92000;0,50492;1845,88004
5,96000;0,50827;1855,69283
6,00000;0,51162;1865,12377
6,04000;0,51485;1873,63997
6,08000;0,51832;1882,72092
6,12000;0,52166;1892,12747
6,16000;0,52495;1900,02099
6,20000;0,52824;1907,09718
6,24000;0,53153;1915,22129
6,28000;0,53488;1922,48020
6,32000;0,53822;1930,07775
6,36000;0,54157;1937,40129
6,40000;0,54498;1944,11129
6,44000;0,54827;1948,69153
6,48000;0,55138;1952,48984
6,52000;0,55497;1957,49681
6,56000;0,55837;1961,65647
6,60000;0,56160;1964,04215
6,64000;0,56477;1965,06865
6,68000;0,56836;1967,11272
6,72000;0,57159;1968,99716
6,76000;0,57488;1967,89149
6,80000;0,57822;1967,95259
6,84000;0,58151;1967,92297
6,88000;0,58492;1965,94223
6,92000;0,58821;1965,01613
6,96000;0,59156;1964,40537
7,00000;0,59491;1964,47819
7,04000;0,59825;1962,69769
7,08000;0,60148;1962,10202
7,12000;0,60495;1962,37825
7,16000;0,60830;1963,61877
7,20000;0,61159;1964,04923
7,24000;0,61488;1965,66842
7,28000;0,61828;1968,31245
7,32000;0,62151;1968,72167
7,36000;0,62480;1970,70148
7,40000;0,62821;1974,40106
7,44000;0,63162;1978,85912
7,48000;0,63490;1980,21047
7,52000;0,63819;1982,21914
7,56000;0,64154;1986,03552
7,60000;0,64489;1989,37841
7,64000;0,64818;1992,08446
7,68000;0,65159;1995,92374
7,72000;0,65493;2000,58855
7,76000;0,65828;2003,94206
7,80000;0,66157;2007,57645
7,84000;0,66492;2012,85202
7,88000;0,66827;2017,03422
7,92000;0,67156;2020,73194
7,96000;0,67472;2024,51441
8,00000;0,67825;2029,99022
8,04000;0,68160;2034,86420
8,08000;0,68477;2039,62177
8,12000;0,68824;2044,85580
8,16000;0,69153;2049,90003
8,20000;0,69487;2053,01214
8,24000;0,69816;2056,84621
8,28000;0,70163;2062,94693
8,32000;0,70492;2067,95279
8,36000;0,70827;2072,13815
8,40000;0,71161;2078,17256
8,44000;0,71496;2086,07428
8,48000;0,71831;2091,52382
8,52000;0,72160;2097,93169
8,56000;0,72495;2106,37394
8,60000;0,72836;2116,06938
8,64000;0,73164;2124,34530
8,68000;0,73493;2132,84809
8,72000;0,73822;2142,78363
8,76000;0,74157;2151,68502
8,80000;0,74492;2161,69469
8,84000;0,74809;2172,44942
8,88000;0,75167;2184,33980
8,92000;0,75496;2195,76247
8,96000;0,75819;2206,41419
9,00000;0,76154;2216,76901
9,04000;0,76489;2227,38702
9,08000;0,76824;2237,43021
9,12000;0,77158;2247,66620
9,16000;0,77493;2260,61735
9,20000;0,77828;2270,18893
9,24000;0,78151;2280,82426
9,28000;0,78486;2291,27370
9,32000;0,78820;2301,41468
9,36000;0,79149;2312,30929
9,40000;0,79466;2322,29996
9,44000;0,79825;2334,64967
9,48000;0,80148;2345,28091
9,52000;0,80483;2354,41681
9,56000;0,80817;2363,55960
9,60000;0,81140;2373,82501
9,64000;0,81475;2382,35034
9,68000;0,81816;2392,95587
9,72000;0,82145;2402,64665
9,76000;0,82486;2413,17265
9,80000;0,82814;2422,28229
9,84000;0,83149;2434,27549
9,88000;0,83484;2443,03476
9,92000;0,83819;2451,05717
9,96000;0,84142;2460,15005
10,00000;0,84483;2468,87989
10,04000;0,84817;2478,42185
10,08000;0,85146;2487,73266
10,12000;0,85481;2496,44592
10,16000;0,85816;2505,00105
10,20000;0,86145;2514,19973
10,24000;0,86480;2523,41852
10,28000;0,86820;2532,61384
10,32000;0,87155;2542,48288
10,36000;0,87478;2550,98063
10,40000;0,87819;2559,08500
10,44000;0,88160;2570,15545
10,48000;0,88482;2578,09386
10,52000;0,88817;2586,84494
10,56000;0,89164;2597,27444
10,60000;0,89487;2605,44270
10,64000;0,89822;2614,41972
10,68000;0,90157;2623,51073
10,72000;0,90485;2632,48067
10,76000;0,90820;2640,51203
10,80000;0,91149;2648,50724
10,84000;0,91484;2657,83183
10,88000;0,91825;2667,09477
10,92000;0,92154;2676,08985
10,96000;0,92482;2684,48330
11,00000;0,92823;2692,94046
11,04000;0,93158;2701,44045
11,08000;0,93493;2709,76145
11,12000;0,93828;2718,84035
11,16000;0,94162;2727,21425
11,20000;0,94491;2734,96751
11,24000;0,94820;2743,17339
11,28000;0,95155;2752,01779
11,32000;0,95484;2759,47489
11,36000;0,95813;2767,19257
11,40000;0,96159;2776,28470
11,44000;0,96494;2784,90670
11,48000;0,96817;2792,18722
11,52000;0,97152;2799,18239
11,56000;0,97487;2808,21919
11,60000;0,97810;2816,03523
11,64000;0,98144;2823,48841
11,68000;0,98491;2832,84765
11,72000;0,98826;2840,92668
11,76000;0,99161;2848,43426
11,80000;0,99490;2855,47040
11,84000;0,99825;2863,29053
11,88000;1,00153;2870,32984
11,92000;1,00488;2877,93055
11,96000;1,00823;2885,95017
12,00000;1,01158;2893,46240
12,04000;1,01487;2900,37673
12,08000;1,01816;2907,12025
12,12000;1,02150;2914,41288
12,16000;1,02479;2922,81266
12,20000;1,02814;2930,02781
12,24000;1,03149;2938,02656
12,28000;1,03490;2945,27598
12,32000;1,03824;2953,22146
12,36000;1,04153;2959,20819
12,40000;1,04488;2965,14798
12,44000;1,04829;2971,11627
12,48000;1,05152;2976,19645
12,52000;1,05487;2981,92296
12,56000;1,05821;2989,06080
12,60000;1,06150;2995,10229
12,64000;1,06485;3001,64577
12,68000;1,06820;3007,88190
12,72000;1,07149;3013,05912
12,76000;1,07484;3019,86448
12,80000;1,07812;3025,57163
12,84000;1,08147;3032,38537
12,88000;1,08488;3038,21415
12,92000;1,08817;3044,22770
12,96000;1,09152;3051,03660
13,00000;1,09487;3057,18910
13,04000;1,09821;3062,89103
13,08000;1,10150;3069,94691
13,12000;1,10485;3076,12214
13,16000;1,10820;3082,17183
13,20000;1,11155;3089,18618
13,24000;1,11483;3095,60262
13,28000;1,11824;3101,85701
13,32000;1,12159;3107,21416
13,36000;1,12482;3112,49942
13,40000;1,12817;3118,52228
13,44000;1,13164;3125,51260
13,48000;1,13486;3132,85515
13,52000;1,13827;3138,67070
13,56000;1,14162;3145,43284
13,60000;1,14491;3153,19635
13,64000;1,14820;3158,89120
13,68000;1,15155;3165,21786
13,72000;1,15483;3172,31193
13,76000;1,15824;3179,78933
13,80000;1,16153;3187,41575
13,84000;1,16488;3197,90989
13,88000;1,16829;3208,20734
13,92000;1,17152;3220,69712
13,96000;1,17486;3234,11673
14,00000;1,17821;3247,99679
14,04000;1,18162;3263,48357
14,08000;1,18491;3277,92093
14,12000;1,18820;3290,57463
14,16000;1,19166;3306,04576
14,20000;1,19495;3320,14561
14,24000;1,19818;3333,26049
14,28000;1,20159;3347,90051
14,32000;1,20494;3362,19221
14,36000;1,20817;3375,70012
14,40000;1,21151;3389,14394
14,44000;1,21498;3404,11551
14,48000;1,21827;3418,26826
14,52000;1,22156;3431,23898
14,56000;1,22491;3445,76649
14,60000;1,22826;3460,29997
14,64000;1,23160;3473,30421
14,68000;1,23489;3487,07549
14,72000;1,23824;3500,67951
14,76000;1,24159;3513,26726
14,80000;1,24488;3526,70774
14,84000;1,24823;3539,72465
14,88000;1,25157;3553,91912
14,92000;1,25486;3568,13334
14,96000;1,25821;3580,96361
15,00000;1,26150;3593,34573
15,04000;1,26491;3607,70486
15,08000;1,26825;3621,89226
15,12000;1,27148;3635,00379
15,16000;1,27489;3649,20162
15,20000;1,27830;3663,66357
15,24000;1,28153;3676,63018
15,28000;1,28482;3690,80566
15,32000;1,28828;3705,87558
15,36000;1,29145;3720,59159
15,40000;1,29474;3734,17214
15,44000;1,29827;3749,41714
15,48000;1,30156;3766,50207
15,52000;1,30485;3779,28652
15,56000;1,30813;3792,66515
15,60000;1,31148;3808,44176
15,64000;1,31483;3822,72266
15,68000;1,31812;3838,36813
15,72000;1,32147;3852,90161
15,76000;1,32494;3870,57625
15,80000;1,32822;3884,48723
15,84000;1,33151;3898,31103
15,88000;1,33486;3912,26187
15,92000;1,33821;3925,80293
15,96000;1,34150;3940,12854
16,00000;1,34479;3954,35728
16,04000;1,34819;3971,44891
16,08000;1,35154;3986,11389
16,12000;1,35483;3998,77727
16,16000;1,35812;4013,51973
16,20000;1,36159;4028,80982
16,24000;1,36487;4045,41939
16,28000;1,36822;4059,32441
16,32000;1,37163;4074,44835
16,36000;1,37492;4088,96431
16,40000;1,37821;4103,38901
16,44000;1,38156;4117,26497
16,48000;1,38484;4133,76763
16,52000;1,38819;4146,42468
16,56000;1,39154;4160,66758
16,60000;1,39483;4175,44432
16,64000;1,39818;4189,64177
16,68000;1,40153;4204,92552
16,72000;1,40481;4220,33854
16,76000;1,40816;4234,75020
16,80000;1,41151;4248,65521
16,84000;1,41474;4262,76289
16,88000;1,41827;4279,41419
16,92000;1,42155;4295,00304
16,96000;1,42490;4310,06178
17,00000;1,42819;4323,59986
17,04000;1,43154;4336,89579
17,08000;1,43489;4351,19309
17,12000;1,43800;4365,91096
17,16000;1,44164;4382,93479
17,20000;1,44493;4398,66781
17,24000;1,44816;4412,41860
17,28000;1,45151;4426,62500
17,32000;1,45486;4440,83437
17,36000;1,45815;4455,76422
17,40000;1,46149;4469,87115
17,44000;1,46472;4485,51327
17,48000;1,46825;4502,26702
17,52000;1,47154;4516,73530
17,56000;1,47489;4531,24680
17,60000;1,47818;4546,27685
17,64000;1,48152;4560,89489
17,68000;1,48481;4575,81915
17,72000;1,48816;4591,05335
17,76000;1,49157;4607,32915
17,80000;1,49486;4622,61848
17,84000;1,49815;4637,21119
17,88000;1,50149;4651,14340
17,92000;1,50484;4667,92248
17,96000;1,50819;4682,74876
18,00000;1,51148;4696,31627
18,04000;1,51489;4711,28412
18,08000;1,51817;4726,24227
18,12000;1,52146;4740,15884
18,16000;1,52481;4755,20380
18,20000;1,52822;4770,92564
18,24000;1,53145;4784,57063
18,28000;1,53480;4798,77107
18,32000;1,53820;4814,76486
18,36000;1,54143;4829,44623
18,40000;1,54478;4843,76699
18,44000;1,54819;4859,76152
18,48000;1,55148;4875,25575
18,52000;1,55483;4889,28072
18,56000;1,55817;4903,98593
18,60000;1,56152;4919,69399
18,64000;1,56481;4933,77149
18,68000;1,56816;4948,74567
18,72000;1,57151;4963,70643
18,76000;1,57486;4979,16490
18,80000;1,57814;4993,39812
18,84000;1,58155;5009,47200
18,88000;1,58484;5023,53609
18,92000;1,58819;5039,20354
18,96000;1,59154;5053,78097
19,00000;1,59482;5068,69666
19,04000;1,59805;5084,32724
19,08000;1,60164;5100,38882
19,12000;1,60487;5116,01157
19,16000;1,60822;5132,38497
19,20000;1,61163;5147,25111
19,24000;1,61485;5160,41480
19,28000;1,61820;5174,54185
19,32000;1,62155;5189,73060
19,36000;1,62484;5204,43097
19,40000;1,62819;5219,43793
19,44000;1,63154;5235,28494
19,48000;1,63488;5251,27091
19,52000;1,63817;5264,84028
19,56000;1,64152;5279,46167
19,60000;1,64493;5295,75907
19,64000;1,64822;5310,52649
19,68000;1,65157;5325,12814
19,72000;1,65497;5341,84165
19,76000;1,65826;5357,03301
19,80000;1,66155;5371,91480
19,84000;1,66496;5387,06109
19,88000;1,66825;5402,74717
19,92000;1,67159;5417,01727
19,96000;1,67482;5432,38856
20,00000;1,67823;5447,97331
20,04000;1,68158;5463,06185
20,08000;1,68493;5478,88801
20,12000;1,68816;5493,92514
20,16000;1,69156;5508,56926
20,20000;1,69491;5524,15811
20,24000;1,69808;5538,60404
20,28000;1,70149;5553,43889
20,32000;1,70490;5569,76236
20,36000;1,70819;5584,95931
20,40000;1,71153;5599,36650
20,44000;1,71494;5614,32838
20,48000;1,71823;5629,87179
20,52000;1,72152;5644,06700
20,56000;1,72481;5657,72951
20,60000;1,72816;5673,28893
20,64000;1,73138;5688,64867
20,68000;1,73485;5706,04689
20,72000;1,73820;5721,53516
20,76000;1,74149;5736,10328
20,80000;1,74484;5750,70865
20,84000;1,74813;5764,29926
20,88000;1,75141;5779,26859
20,92000;1,75482;5794,79262
20,96000;1,75787;5808,26364
21,00000;1,76158;5823,82753
21,04000;1,76493;5839,79376
21,08000;1,76827;5854,07019
21,12000;1,77150;5867,05133
21,16000;1,77485;5881,73382
21,20000;1,77826;5896,67708
21,24000;1,78149;5911,20645
21,28000;1,78484;5924,36232
21,32000;1,78830;5939,91689
21,36000;1,79153;5956,07795
21,40000;1,79488;5968,71637
21,44000;1,79823;5982,11475
21,48000;1,80158;5996,31593
21,52000;1,80493;6009,18978
21,56000;1,80809;6022,26444
21,60000;1,81162;6037,86595
21,64000;1,81497;6052,22024
21,68000;1,81826;6064,24361
21,72000;1,82155;6078,46715
21,76000;1,82495;6093,35601
21,80000;1,82824;6107,26178
21,84000;1,83159;6120,52791
21,88000;1,83488;6133,98366
21,92000;1,83829;6148,92431
21,96000;1,84164;6162,65573
22,00000;1,84486;6174,96185
22,04000;1,84827;6189,28894
22,08000;1,85168;6203,42307
22,12000;1,85491;6216,58787
22,16000;1,85820;6230,00562
22,20000;1,86161;6244,19227
22,24000;1,86489;6258,77753
22,28000;1,86818;6271,67076
22,32000;1,87159;6286,37969
22,36000;1,87494;6302,05050
22,40000;1,87829;6315,81768
22,44000;1,88158;6330,28969
22,48000;1,88492;6344,59257
22,52000;1,88821;6358,71068
22,56000;1,89156;6373,06124
22,60000;1,89485;6387,38424
22,64000;1,89820;6400,91971
22,68000;1,90155;6416,33347
22,72000;1,90477;6429,85404
22,76000;1,90818;6445,47269
22,80000;1,91153;6460,59662
22,84000;1,91488;6475,32120
22,88000;1,91793;6488,40219
22,92000;1,92157;6506,03622
22,96000;1,92492;6523,26643
23,00000;1,92821;6537,62966
23,04000;1,93150;6550,75684
23,08000;1,93491;6565,89791
23,12000;1,93814;6579,69341
23,16000;1,94148;6593,41216
23,20000;1,94489;6608,22839
23,24000;1,94818;6624,24490
23,28000;1,95153;6638,27062
23,32000;1,95482;6651,81354
23,36000;1,95817;6665,86384
23,40000;1,96151;6679,28159
23,44000;1,96486;6692,90274
23,48000;1,96815;6706,24971
23,52000;1,97150;6721,27157
23,56000;1,97485;6735,47164
23,60000;1,97820;6749,98015
23,64000;1,98148;6761,71258
23,68000;1,98483;6775,36950
23,72000;1,98818;6787,99227
23,76000;1,99147;6801,80341
23,80000;1,99488;6816,28659
23,84000;1,99822;6831,90450
23,88000;2,00151;6845,20230
23,92000;2,00486;6857,89958
23,96000;2,00827;6870,71830
24,00000;2,01150;6883,54000
24,04000;2,01485;6896,81843
24,08000;2,01819;6909,46952
24,12000;2,02148;6923,06310
24,16000;2,02489;6936,60006
24,20000;2,02824;6950,66974
24,24000;2,03153;6962,71881
24,28000;2,03488;6975,37810
24,32000;2,03828;6987,19099
24,36000;2,04157;7000,23696
24,40000;2,04492;7011,70340
24,44000;2,04827;7024,00282
24,48000;2,05156;7036,38196
24,52000;2,05491;7048,76408
24,56000;2,05825;7060,79528
24,60000;2,06160;7075,69495
24,64000;2,06489;7087,53243
24,68000;2,06824;7099,68209
24,72000;2,07159;7112,70049
24,76000;2,07481;7123,80558
24,80000;2,07822;7136,75544
24,84000;2,08151;7149,93402
24,88000;2,08486;7163,81148
24,92000;2,08821;7176,38880
24,96000;2,09156;7190,27966
25,00000;2,09484;7202,33545
25,04000;2,09819;7214,50970
25,08000;2,10154;7226,94993
25,12000;2,10483;7238,80827
25,16000;2,10812;7250,87672
25,20000;2,11153;7263,69619
25,24000;2,11481;7276,08800
25,28000;2,11810;7287,66695
25,32000;2,12145;7300,66150
25,36000;2,12486;7314,63283
25,40000;2,12815;7326,55749
25,44000;2,13144;7338,63041
25,48000;2,13490;7352,84835
25,52000;2,13819;7365,91965
25,56000;2,14154;7378,41800
25,60000;2,14489;7390,52817
25,64000;2,14824;7402,66070
25,68000;2,15152;7415,15458
25,72000;2,15481;7427,46666
25,76000;2,15810;7439,13352
25,80000;2,16151;7451,07681
25,84000;2,16480;7463,00295
25,88000;2,16809;7474,14082
25,92000;2,17143;7486,69133
25,96000;2,17484;7498,97063
26,00000;2,17813;7511,16574
26,04000;2,18148;7523,05537
26,08000;2,18489;7537,19509
26,12000;2,18818;7548,65110
26,16000;2,19152;7559,48350
26,20000;2,19487;7571,74715
26,24000;2,19822;7584,10618
26,28000;2,20151;7595,82892
26,32000;2,20486;7607,91525
26,36000;2,20821;7619,76987
26,40000;2,21149;7630,86602
26,44000;2,21484;7642,15589
26,48000;2,21819;7654,43668
26,52000;2,22148;7666,06629
26,56000;2,22483;7677,92016
26,60000;2,22823;7690,48333
26,64000;2,23152;7702,04812
26,68000;2,23487;7714,31252
26,72000;2,23822;7724,73514
26,76000;2,24151;7736,21500
26,80000;2,24486;7748,04652
26,84000;2,24820;7760,35711
26,88000;2,25149;7772,38235
26,92000;2,25490;7783,63124
26,96000;2,25825;7794,72813
27,00000;2,26154;7806,89493
27,04000;2,26489;7818,51336
27,08000;2,26823;7830,48421
27,12000;2,27146;7841,45966
27,16000;2,27481;7850,90253
27,20000;2,27828;7864,38584
27,24000;2,28163;7876,87525
27,28000;2,28492;7887,54374
27,32000;2,28826;7898,55793
27,36000;2,29161;7909,59224
27,40000;2,29484;7920,29053
27,44000;2,29819;7931,30696
27,48000;2,30160;7943,90962
27,52000;2,30488;7955,64801
27,56000;2,30823;7967,29475
27,60000;2,31164;7979,18439
27,64000;2,31493;7991,04646
27,68000;2,31822;8000,88868
27,72000;2,32151;8012,01314
27,76000;2,32485;8023,67628
27,80000;2,32820;8034,53475
27,84000;2,33155;8045,78885
27,88000;2,33484;8058,12925
27,92000;2,33825;8068,11377
27,96000;2,34160;8078,66678
28,00000;2,34482;8089,39487
28,04000;2,34817;8099,16332
28,08000;2,35152;8112,30168
28,12000;2,35487;8124,03858
28,16000;2,35822;8135,04905
28,20000;2,36157;8146,47451
28,24000;2,36491;8157,18397
28,28000;2,36820;8167,68333
28,32000;2,37149;8179,00598
28,36000;2,37490;8191,41567
28,40000;2,37825;8202,59601
28,44000;2,38154;8213,02608
28,48000;2,38488;8223,75193
28,52000;2,38823;8235,01647
28,56000;2,39152;8245,36234
28,60000;2,39481;8255,01531
28,64000;2,39816;8265,92222
28,68000;2,40156;8277,56897
28,72000;2,40485;8287,61309
28,76000;2,40814;8297,77122
28,80000;2,41161;8310,34780
28,84000;2,41496;8320,51262
28,88000;2,41813;8329,91824
28,92000;2,42153;8340,12553
28,96000;2,42494;8352,14555
29,00000;2,42823;8362,94815
29,04000;2,43158;8372,51246
29,08000;2,43493;8383,66002
29,12000;2,43822;8394,36054
29,16000;2,44150;8404,86586
29,20000;2,44491;8416,39265
29,24000;2,44826;8427,45602
29,28000;2,45155;8437,08813
29,32000;2,45490;8447,53087
29,36000;2,45824;8457,51390
29,40000;2,46153;8467,66308
29,44000;2,46482;8477,81450
29,48000;2,46829;8488,89872
29,52000;2,47158;8500,34431
29,56000;2,47493;8510,50913
29,60000;2,47827;8519,99000
29,64000;2,48162;8531,01984
29,68000;2,48491;8541,74793
29,72000;2,48820;8551,38823
29,76000;2,49149;8561,73337
29,80000;2,49490;8574,12666
29,84000;2,49824;8583,83700
29,88000;2,50147;8593,51903
29,92000;2,50482;8601,92552
29,96000;2,50823;8613,47169
30,00000;2,51152;8624,28322
30,04000;2,51475;8634,01666
30,08000;2,51833;8645,83701
30,12000;2,52162;8655,87816
30,16000;2,52497;8664,92093
30,20000;2,52826;8674,14176
30,24000;2,53161;8684,69626
30,28000;2,53490;8694,86853
30,32000;2,53800;8703,75633
30,36000;2,54165;8716,39326
30,40000;2,54488;8726,08945
30,44000;2,54823;8734,81855
30,48000;2,55152;8744,75017
30,52000;2,55486;8754,89414
30,56000;2,55821;8766,15345
30,60000;2,56156;8776,37118
30,64000;2,56485;8787,17452
30,68000;2,56826;8797,57553
30,72000;2,57161;8808,07415
30,76000;2,57489;8817,51329
30,80000;2,57824;8827,16775
30,84000;2,58159;8836,40870
30,88000;2,58482;8844,80551
30,92000;2,58817;8854,12022
30,96000;2,59164;8866,21401
31,00000;2,59486;8876,28421
31,04000;2,59815;8884,02164
31,08000;2,60150;8893,28793
31,12000;2,60491;8904,02198
31,16000;2,60820;8912,03582
31,20000;2,61149;8921,41089
31,24000;2,61489;8931,78806
31,28000;2,61824;8942,37608
31,32000;2,62153;8952,26970
31,36000;2,62488;8960,45268
31,40000;2,62817;8969,31067
31,44000;2,63151;8979,15065
31,48000;2,63486;8988,13382
31,52000;2,63821;9000,69252
31,56000;2,64156;9010,20914
31,60000;2,64491;9018,79966
31,64000;2,64814;9028,58153
31,68000;2,65148;9037,20856
31,72000;2,65483;9047,05152
31,76000;2,65812;9056,99208
31,80000;2,66147;9066,51095
31,84000;2,66494;9077,37464
31,88000;2,66817;9088,01109
31,92000;2,67157;9095,91019
31,96000;2,67486;9106,16741
32,00000;2,67815;9115,79281
32,04000;2,68150;9123,80517
32,08000;2,68491;9134,65843
32,12000;2,68820;9144,62432
32,16000;2,69142;9153,42346
32,20000;2,69483;9162,72104
32,24000;2,69818;9172,79348
32,28000;2,70147;9182,12682
32,32000;2,70476;9191,89379
32,36000;2,70816;9200,78456
32,40000;2,71151;9211,74809
32,44000;2,71480;9220,47421
32,48000;2,71821;9229,65407
32,52000;2,72156;9239,70640
32,56000;2,72485;9249,39364
32,60000;2,72819;9257,76362
32,64000;2,73148;9267,53134
32,68000;2,73489;9277,74906
32,72000;2,73818;9286,73819
32,76000;2,74147;9296,33901
32,80000;2,74488;9306,81229
32,84000;2,74822;9316,44291
32,88000;2,75151;9324,78979
32,92000;2,75480;9333,57030
32,96000;2,75821;9343,72395
33,00000;2,76150;9353,37543
33,04000;2,76479;9361,17396
33,08000;2,76819;9371,92738
33,12000;2,77160;9382,15330
33,16000;2,77477;9390,80343
33,20000;2,77818;9399,72922
33,24000;2,78159;9410,92074
33,28000;2,78487;9420,65343
33,32000;2,78816;9429,47194
33,36000;2,79157;9438,70619
33,40000;2,79486;9448,03208
33,44000;2,79821;9456,59950
33,48000;2,80162;9466,76806
33,52000;2,80490;9476,75109
33,56000;2,80825;9485,64932
33,60000;2,81160;9493,22507
33,64000;2,81489;9502,80800
33,68000;2,81824;9511,68388
33,72000;2,82159;9519,92199
33,76000;2,82487;9529,52206
33,80000;2,82822;9538,26755
33,84000;2,83157;9547,09873
33,88000;2,83486;9556,13703
33,92000;2,83815;9564,96447
33,96000;2,84150;9574,09739
34,00000;2,84478;9582,89951
34,04000;2,84813;9591,77688
34,08000;2,85154;9602,65696
34,12000;2,85495;9611,94932
34,16000;2,85812;9619,92145
34,20000;2,86152;9629,37698
34,24000;2,86493;9639,10669
34,28000;2,86816;9647,91998
34,32000;2,87151;9655,42346
34,36000;2,87492;9666,58220
34,40000;2,87815;9675,70096
34,44000;2,88155;9684,39952
34,48000;2,88484;9692,33736
34,52000;2,88819;9702,02908
34,56000;2,89154;9711,10240
34,60000;2,89483;9718,68411
34,64000;2,89818;9729,18272
34,68000;2,90158;9737,61901
34,72000;2,90481;9746,90765
34,76000;2,90828;9756,88845
34,80000;2,91163;9765,80009
34,84000;2,91498;9774,23042
34,88000;2,91821;9781,88142
34,92000;2,92149;9790,17392
34,96000;2,92490;9798,85608
35,00000;2,92807;9808,67669
35,04000;2,93154;9818,04356
35,08000;2,93489;9828,27172
35,12000;2,93829;9837,85912
35,16000;2,94152;9845,70161
35,20000;2,94487;9853,23712
35,24000;2,94828;9865,19158
35,28000;2,95157;9873,39765
35,32000;2,95492;9880,80725
35,36000;2,95832;9890,02287
35,40000;2,96161;9899,24446
35,44000;2,96496;9907,56676
35,48000;2,96831;9916,86210
35,52000;2,97160;9925,50328
35,56000;2,97495;9934,63770
35,60000;2,97829;9942,98086
35,64000;2,98158;9951,16234
35,68000;2,98493;9960,73410
35,72000;2,98828;9969,39465
35,76000;2,99151;9978,10513
35,80000;2,99486;9985,27706
35,84000;2,99826;9996,08412
35,88000;3,00161;10004,17620
35,92000;3,00490;10012,61622
35,96000;3,00825;10021,63813
36,00000;3,01160;10031,66437
36,04000;3,01489;10039,08068
36,08000;3,01823;10046,63184
36,12000;3,02164;10056,21105
36,16000;3,02487;10063,49027
36,20000;3,02816;10071,54807
36,24000;3,03157;10080,74284
36,28000;3,03485;10089,02788
36,32000;3,03820;10097,49696
36,36000;3,04149;10105,11518
36,40000;3,04484;10113,25717
36,44000;3,04819;10122,15614
36,48000;3,05154;10130,00458
36,52000;3,05482;10137,31658
36,56000;3,05817;10146,08070
36,60000;3,06146;10153,96267
36,64000;3,06475;10161,65838
36,68000;3,06816;10170,09318
36,72000;3,07151;10179,86536
36,76000;3,07479;10188,03492
36,80000;3,07820;10196,02492
36,84000;3,08155;10206,38496
36,88000;3,08490;10214,57538
36,92000;3,08819;10221,44035
36,96000;3,09160;10230,52856
37,00000;3,09494;10240,85134
37,04000;3,09817;10247,81018
37,08000;3,10158;10255,65341
37,12000;3,10493;10266,68772
37,16000;3,10822;10274,25155
37,20000;3,11156;10282,06423
37,24000;3,11479;10290,48488
37,28000;3,11820;10300,52155
37,32000;3,12155;10308,69037
37,36000;3,12496;10316,32870
37,40000;3,12825;10324,96542
37,44000;3,13159;10332,43909
37,48000;3,13494;10340,20409
37,52000;3,13793;10348,16280
37,56000;3,14164;10357,72860
37,60000;3,14499;10367,48588
37,64000;3,14822;10374,86196
37,68000;3,15156;10381,68296
37,72000;3,15491;10391,30837
37,76000;3,15826;10398,93255
37,80000;3,16155;10406,45987
37,84000;3,16490;10414,86263
37,88000;3,16830;10425,24800
37,92000;3,17153;10432,93402
37,96000;3,17488;10440,80779
38,00000;3,17829;10449,05260
38,04000;3,18158;10455,80432
38,08000;3,18493;10463,61849
38,12000;3,18833;10473,34820
38,16000;3,19162;10482,02813
38,20000;3,19497;10488,96015
38,24000;3,19832;10495,82064
38,28000;3,20155;10503,53572
38,32000;3,20490;10510,23826
38,36000;3,20824;10517,73727
38,40000;3,21147;10525,41733
38,44000;3,21482;10532,71443
38,48000;3,21823;10541,22299
38,52000;3,22152;10549,62650
38,56000;3,22493;10557,09049
38,60000;3,22827;10565,38671
38,64000;3,23156;10571,90374
38,68000;3,23491;10579,05927
38,72000;3,23826;10586,09635
38,76000;3,24155;10593,79056
38,80000;3,24484;10599,43065
38,84000;3,24818;10607,06899
38,88000;3,25153;10614,24240
38,92000;3,25476;10620,83244
38,96000;3,25817;10628,68983
39,00000;3,26152;10637,01361
39,04000;3,26481;10643,91509
39,08000;3,26815;10651,19505
39,12000;3,27156;10659,01443
39,16000;3,27479;10665,72294
39,20000;3,27808;10672,28317
39,24000;3,28149;10679,49384
39,28000;3,28483;10687,49577
39,32000;3,28818;10693,65963
39,36000;3,29153;10701,29126
39,40000;3,29482;10709,17547
39,44000;3,29823;10715,12103
39,48000;3,30152;10721,21710
39,52000;3,30480;10727,19321
39,56000;3,30815;10734,35619
39,60000;3,31150;10740,88141
39,64000;3,31479;10747,60929
39,68000;3,31814;10753,61371
39,72000;3,32155;10761,62383
39,76000;3,32483;10768,15426
39,80000;3,32818;10773,88078
39,84000;3,33153;10781,72401
39,88000;3,33488;10787,66435
39,92000;3,33811;10793,17033
39,96000;3,34152;10799,84754
40,00000;3,34492;10807,50450
40,04000;3,34821;10813,55140
40,08000;3,35150;10820,73897
40,12000;3,35497;10828,65223
40,16000;3,35820;10836,05662
40,20000;3,36148;10842,11171
40,24000;3,36489;10848,41117
40,28000;3,36818;10855,67400
40,32000;3,37147;10861,91759
40,36000;3,37482;10868,90548
40,40000;3,37823;10876,64887
40,44000;3,38157;10882,75686
40,48000;3,38486;10887,71597
40,52000;3,38821;10893,23238
40,56000;3,39156;10898,30101
40,60000;3,39491;10903,03436
40,64000;3,39826;10908,79440
40,68000;3,40154;10913,33926
40,72000;3,40495;10917,62781
40,76000;3,40824;10919,68715
40,80000;3,41153;10923,22171
40,84000;3,41494;10926,52977
40,88000;3,41828;10929,87731
40,92000;3,42151;10933,19356
40,96000;3,42486;10934,73732
41,00000;3,42827;10936,84956
41,04000;3,43156;10937,90606
41,08000;3,43491;10935,90930
41,12000;3,43825;10934,00493
41,16000;3,44154;10931,08505
41,20000;3,44483;10924,48086
41,24000;3,44824;10917,01537
41,28000;3,45153;10906,21874
41,32000;3,45488;10889,75072
41,36000;3,45822;10861,33942
41,40000;3,46151;10802,93208
41,44000;3,46492;10687,78262
41,48000;3,46964;2607,60225
41,48400;3,47006;1995,25002