File: SU - Suspension/05 - Essais/Excels essais Optimus/Test_Rotules_31_01_19/k7_1.is_tens_RawData/Specimen_RawData_1.csv
Temps;Déplacement;Charge
(sec);(mm);(N)
0,00000;0,10481;17,14355
0,04000;0,10493;16,92029
0,08000;0,10535;16,59002
0,12000;0,10654;19,16640
0,16000;0,10834;21,94578
0,20000;0,11043;25,61913
0,24000;0,11258;30,40587
0,28000;0,11474;34,57475
0,32000;0,11695;37,33269
0,36000;0,11904;40,17862
0,40000;0,12119;43,29920
0,44000;0,12323;45,58418
0,48000;0,12532;48,31313
0,52000;0,12741;51,21850
0,56000;0,12944;54,32126
0,60000;0,13148;58,48536
0,64000;0,13351;62,22568
0,68000;0,13548;66,59187
0,72000;0,13746;71,36989
0,76000;0,13949;76,33720
0,80000;0,14152;81,87925
0,84000;0,14355;88,50454
0,88000;0,14547;93,53111
0,92000;0,14750;100,02828
0,96000;0,14947;107,42617
1,00000;0,15151;114,77245
1,04000;0,15354;121,55200
1,08000;0,15545;129,40249
1,12000;0,15755;138,12468
1,16000;0,15952;148,10405
1,20000;0,16149;157,66182
1,24000;0,16352;167,16394
1,28000;0,16544;176,94398
1,32000;0,16747;186,60299
1,36000;0,16950;196,58243
1,40000;0,17148;206,45184
1,44000;0,17357;216,20721
1,48000;0,17554;225,97671
1,52000;0,17746;231,97858
1,56000;0,17943;231,32940
1,60000;0,18146;225,84167
1,64000;0,18349;221,60523
1,68000;0,18547;218,36276
1,72000;0,18744;215,79138
1,76000;0,18947;215,10993
1,80000;0,19145;213,05422
1,84000;0,19348;212,88954
1,88000;0,19551;212,01349
1,92000;0,19742;210,77741
1,96000;0,19952;210,25832
2,00000;0,20149;210,19196
2,04000;0,20346;208,81717
2,08000;0,20556;208,10128
2,12000;0,20741;208,27432
2,16000;0,20950;207,37362
2,20000;0,21148;207,62687
2,24000;0,21351;206,90584
2,28000;0,21554;206,31708
2,32000;0,21751;205,83228
2,36000;0,21955;207,09720
2,40000;0,22152;205,92487
2,44000;0,22349;205,34806
2,48000;0,22553;206,05971
2,52000;0,22750;205,32042
2,56000;0,22941;205,00622
2,60000;0,23145;205,96732
2,64000;0,23348;205,68788
2,68000;0,23545;205,59689
2,72000;0,23748;205,67537
2,76000;0,23940;205,40068
2,80000;0,24149;205,27313
2,84000;0,24352;205,07996
2,88000;0,24556;203,40956
2,92000;0,24753;203,21002
2,96000;0,24950;204,01045
3,00000;0,25147;202,98585
3,04000;0,25351;202,20024
3,08000;0,25548;202,30708
3,12000;0,25751;202,22326
3,16000;0,25949;201,03736
3,20000;0,26140;200,16397
3,24000;0,26349;200,10942
3,28000;0,26553;199,58180
3,32000;0,26762;199,30613
3,36000;0,26959;198,45914
3,40000;0,27150;197,50411
3,44000;0,27360;197,35156
3,48000;0,27551;196,30406
3,52000;0,27754;196,37828
3,56000;0,27958;196,99882
3,60000;0,28143;195,59013
3,64000;0,28352;196,39542
3,68000;0,28555;196,53952
3,72000;0,28753;196,17889
3,76000;0,28962;196,40722
3,80000;0,29147;195,11057
3,84000;0,29357;196,49668
3,88000;0,29554;196,60597
3,92000;0,29757;196,94697
3,96000;0,29955;197,39692
4,00000;0,30140;197,02110
4,04000;0,30349;197,22402
4,08000;0,30546;198,00051
4,12000;0,30750;199,18650
4,16000;0,30953;198,90848
4,20000;0,31144;198,63916
4,24000;0,31354;198,93018
4,28000;0,31551;198,69420
4,32000;0,31754;198,38368
4,36000;0,31963;199,31034
4,40000;0,32155;198,73828
4,44000;0,32358;197,56968
4,48000;0,32549;197,26041
4,52000;0,32753;196,75777
4,56000;0,32956;196,84371
4,60000;0,33159;196,41810
4,64000;0,33351;194,93214
4,68000;0,33554;195,52412
4,72000;0,33757;195,46014
4,76000;0,33960;193,92002
4,80000;0,34158;194,14609
4,84000;0,34349;193,19988
4,88000;0,34552;192,77829
4,92000;0,34744;191,95464
4,96000;0,34959;192,58341
5,00000;0,35156;191,35663
5,04000;0,35342;190,96602
5,08000;0,35551;191,09098
5,12000;0,35748;190,47539
5,16000;0,35951;191,29287
5,20000;0,36155;190,77839
5,24000;0,36352;190,04601
5,28000;0,36543;190,08161
5,32000;0,36753;190,56328
5,36000;0,36956;189,87659
5,40000;0,37153;190,11941
5,44000;0,37350;190,60760
5,48000;0,37548;190,23154
5,52000;0,37757;191,76240
5,56000;0,37954;191,11825
5,60000;0,38158;190,53600
5,64000;0,38361;190,18527
5,68000;0,38546;189,83555
5,72000;0,38756;190,19403
5,76000;0,38953;189,24136
5,80000;0,39156;189,16992
5,84000;0,39359;188,76771
5,88000;0,39545;188,17523
5,92000;0,39742;188,53180
5,96000;0,39951;188,56450
6,00000;0,40155;188,19212
6,04000;0,40358;186,59070
6,08000;0,40549;186,60936
6,12000;0,40747;185,99733
6,16000;0,40944;185,58382
6,20000;0,41147;185,36313
6,24000;0,41356;185,56105
6,28000;0,41548;184,79665
6,32000;0,41745;184,23854
6,36000;0,41948;184,71727
6,40000;0,42146;183,73322
6,44000;0,42331;183,64385
6,48000;0,42558;184,22263
6,52000;0,42749;182,17468
6,56000;0,42953;182,89012
6,60000;0,43156;183,37851
6,64000;0,43353;183,33527
6,68000;0,43557;183,51766
6,72000;0,43748;183,16091
6,76000;0,43951;183,58460
6,80000;0,44155;183,84628
6,84000;0,44352;183,96629
6,88000;0,44555;183,31495
6,92000;0,44740;183,12349
6,96000;0,44956;184,30440
7,00000;0,45153;183,60777
7,04000;0,45350;183,72900
7,08000;0,45554;183,88834
7,12000;0,45745;183,11262
7,16000;0,45942;183,34080
7,20000;0,46152;184,65113
7,24000;0,46349;183,24399
7,28000;0,46552;182,53233
7,32000;0,46749;182,62777
7,36000;0,46947;182,18742
7,40000;0,47150;182,61513
7,44000;0,47353;181,25530
7,48000;0,47551;181,06753
7,52000;0,47754;181,48001
7,56000;0,47945;179,95703
7,60000;0,48125;179,93343
7,64000;0,48358;180,74582
7,68000;0,48555;178,93062
7,72000;0,48758;178,51436
7,76000;0,48950;177,38076
7,80000;0,49153;177,93662
7,84000;0,49356;178,00345
7,88000;0,49554;177,79490
7,92000;0,49757;177,05087
7,96000;0,49948;177,49808
8,00000;0,50151;176,59961
8,04000;0,50313;177,26936
8,08000;0,50552;178,47744
8,12000;0,50755;176,40238
8,16000;0,50947;177,16879
8,20000;0,51144;177,54004
8,24000;0,51347;177,62842
8,28000;0,51545;177,09872
8,32000;0,51748;177,55732
8,36000;0,51951;177,93353
8,40000;0,52142;177,41508
8,44000;0,52352;177,98245
8,48000;0,52549;178,23608
8,52000;0,52752;177,82087
8,56000;0,52956;178,08517
8,60000;0,53141;177,39922
8,64000;0,53350;178,26728
8,68000;0,53553;177,38648
8,72000;0,53733;176,58379
8,76000;0,53966;177,92770
8,80000;0,54145;175,39036
8,84000;0,54355;175,63973
8,88000;0,54552;175,67675
8,92000;0,54755;175,16090
8,96000;0,54958;175,72243
9,00000;0,55150;174,63570
9,04000;0,55347;174,39321
9,08000;0,55550;174,38984
9,12000;0,55748;174,57448
9,16000;0,55957;173,69585
9,20000;0,56148;172,54995
9,24000;0,56346;172,43542
9,28000;0,56543;172,61356
9,32000;0,56758;172,23755
9,36000;0,56961;171,67685
9,40000;0,57159;171,42213
9,44000;0,57350;170,99525
9,48000;0,57547;170,94624
9,52000;0,57745;170,49208
9,56000;0,57948;170,96131
9,60000;0,58151;170,65939
9,64000;0,58337;170,48458
9,68000;0,58546;170,46491
9,72000;0,58749;171,68047
9,76000;0,58923;170,55025
9,80000;0,59162;171,59777
9,84000;0,59347;170,72476
9,88000;0,59556;170,84409
9,92000;0,59754;171,05029
9,96000;0,59951;171,02585
10,00000;0,60154;170,56577
10,04000;0,60352;170,43381
10,08000;0,60549;171,57255
10,12000;0,60752;171,16090
10,16000;0,60949;170,57160
10,20000;0,61147;170,68485
10,24000;0,61344;170,27687
10,28000;0,61547;168,61703
10,32000;0,61751;169,47462
10,36000;0,61948;168,50285
10,40000;0,62151;168,52885
10,44000;0,62348;167,61300
10,48000;0,62540;168,11230
10,52000;0,62743;168,34498
10,56000;0,62946;167,82042
10,60000;0,63144;167,75519
10,64000;0,63353;167,70628
10,68000;0,63538;167,19351
10,72000;0,63742;166,92288
10,76000;0,63945;165,52530
10,80000;0,64148;165,93838
10,84000;0,64357;165,51076
10,88000;0,64543;165,78858
10,92000;0,64746;165,74775
10,96000;0,64943;165,30186
11,00000;0,65147;164,21082
11,04000;0,65356;164,39600
11,08000;0,65547;164,51543
11,12000;0,65745;164,64676
11,16000;0,65948;164,71423
11,20000;0,66151;165,20473
11,24000;0,66354;164,49888
11,28000;0,66558;164,95235
11,32000;0,66749;164,38812
11,36000;0,66946;164,81300
11,40000;0,67144;164,37897
11,44000;0,67347;164,76961
11,48000;0,67550;163,67846
11,52000;0,67741;164,29215
11,56000;0,67945;164,43111
11,60000;0,68142;164,33431
11,64000;0,68345;164,33925
11,68000;0,68549;163,45793
11,72000;0,68746;163,14567
11,76000;0,68943;162,62027
11,80000;0,69147;162,62237
11,84000;0,69344;161,90894
11,88000;0,69547;161,62450
11,92000;0,69744;162,24367
11,96000;0,69942;160,32050
12,00000;0,70151;160,87254
12,04000;0,70348;160,11401
12,08000;0,70552;160,62888
12,12000;0,70749;160,70219
12,16000;0,70946;159,40411
12,20000;0,71155;159,60732
12,24000;0,71359;159,02291
12,28000;0,71556;159,15697
12,32000;0,71759;158,82719
12,36000;0,71945;157,35244
12,40000;0,72148;157,54139
12,44000;0,72351;158,03690
12,48000;0,72549;157,44144
12,52000;0,72758;157,06024
12,56000;0,72943;156,80959
12,60000;0,73152;157,39530
12,64000;0,73350;157,58645
12,68000;0,73547;157,21536
12,72000;0,73750;156,56947
12,76000;0,73942;157,54239
12,80000;0,74151;156,27082
12,84000;0,74348;157,92444
12,88000;0,74552;157,08162
12,92000;0,74755;157,56678
12,96000;0,74952;157,21975
13,00000;0,75143;157,41421
13,04000;0,75353;157,54130
13,08000;0,75556;157,22064
13,12000;0,75759;156,78949
13,16000;0,75957;156,42054
13,20000;0,76154;155,84078
13,24000;0,76357;156,19047
13,28000;0,76554;155,04580
13,32000;0,76758;155,60426
13,36000;0,76955;155,43638
13,40000;0,77146;154,68013
13,44000;0,77356;155,15343
13,48000;0,77553;154,16092
13,52000;0,77750;153,77745
13,56000;0,77954;153,92167
13,60000;0,78145;152,44056
13,64000;0,78348;153,00119
13,68000;0,78551;151,59033
13,72000;0,78749;153,05053
13,76000;0,78952;151,73191
13,80000;0,79149;151,98077
13,84000;0,79347;151,03400
13,88000;0,79550;151,43801
13,92000;0,79753;150,61431
13,96000;0,79956;151,11844
14,00000;0,80148;150,74331
14,04000;0,80339;150,30084
14,08000;0,80548;150,77955
14,12000;0,80752;151,01654
14,16000;0,80955;150,43431
14,20000;0,81152;150,47401
14,24000;0,81344;149,98983
14,28000;0,81553;150,93533
14,32000;0,81756;150,98327
14,36000;0,81959;151,72642
14,40000;0,82163;150,59456
14,44000;0,82348;150,51654
14,48000;0,82551;150,22239
14,52000;0,82749;150,48471
14,56000;0,82946;150,17855
14,60000;0,83149;150,16780
14,64000;0,83341;149,58866
14,68000;0,83544;149,22945
14,72000;0,83747;148,85794
14,76000;0,83950;148,77338
14,80000;0,84154;149,32987
14,84000;0,84351;149,41823
14,88000;0,84548;148,06269
14,92000;0,84752;148,05791
14,96000;0,84949;147,48760
15,00000;0,85152;147,22864
15,04000;0,85350;147,99426
15,08000;0,85541;147,20128
15,12000;0,85750;146,59259
15,16000;0,85947;146,16939
15,20000;0,86151;146,05508
15,24000;0,86360;146,73506
15,28000;0,86551;145,83808
15,32000;0,86761;146,02536
15,36000;0,86958;145,45579
15,40000;0,87155;144,73730
15,44000;0,87352;145,76621
15,48000;0,87544;145,26866
15,52000;0,87747;144,88576
15,56000;0,87944;145,25772
15,60000;0,88148;144,35654
15,64000;0,88351;145,65839
15,68000;0,88542;145,00908
15,72000;0,88746;144,35810
15,76000;0,88955;145,24271
15,80000;0,89152;145,00004
15,84000;0,89355;144,50749
15,88000;0,89553;144,47178
15,92000;0,89744;144,18410
15,96000;0,89947;144,93827
16,00000;0,90151;144,64539
16,04000;0,90348;144,85079
16,08000;0,90557;143,84433
16,12000;0,90748;143,32070
16,16000;0,90952;143,56630
16,20000;0,91149;143,55320
16,24000;0,91352;142,83143
16,28000;0,91556;142,89826
16,32000;0,91747;142,35007
16,36000;0,91950;142,10772
16,40000;0,92148;141,83072
16,44000;0,92351;142,13112
16,48000;0,92554;141,55705
16,52000;0,92745;141,33641
16,56000;0,92949;139,71865
16,60000;0,93152;140,32390
16,64000;0,93349;139,71952
16,68000;0,93553;140,15026
16,72000;0,93750;139,55862
16,76000;0,93947;139,78826
16,80000;0,94156;140,01238
16,84000;0,94354;139,51061
16,88000;0,94551;139,03030
16,92000;0,94748;139,86714
16,96000;0,94946;139,30365
17,00000;0,95149;139,50982
17,04000;0,95352;139,01010
17,08000;0,95556;138,54757
17,12000;0,95753;138,23287
17,16000;0,95944;138,11205
17,20000;0,96153;138,54167
17,24000;0,96357;138,88446
17,28000;0,96554;138,00251
17,32000;0,96757;137,84766
17,36000;0,96943;137,06998
17,40000;0,97152;137,96763
17,44000;0,97349;137,88691
17,48000;0,97553;138,19782
17,52000;0,97762;138,43121
17,56000;0,97947;138,05699
17,60000;0,98156;137,35475
17,64000;0,98348;137,77429
17,68000;0,98551;137,12696
17,72000;0,98754;137,29664
17,76000;0,98952;136,57915
17,80000;0,99149;136,90967
17,84000;0,99346;136,24405
17,88000;0,99549;136,02127
17,92000;0,99753;135,78141
17,96000;0,99950;135,31734
18,00000;1,00147;135,09723
18,04000;1,00351;134,86780
18,08000;1,00548;134,44469
18,12000;1,00751;134,17888
18,16000;1,00955;134,20145
18,20000;1,01146;135,09187
18,24000;1,01355;133,30012
18,28000;1,01552;133,53616
18,32000;1,01750;133,22296
18,36000;1,01953;133,02509
18,40000;1,02150;132,71533
18,44000;1,02354;132,60003
18,48000;1,02551;132,97413
18,52000;1,02754;132,79244
18,56000;1,02952;132,23143
18,60000;1,03137;132,58052
18,64000;1,03358;131,79159
18,68000;1,03555;132,09885
18,72000;1,03759;132,22366
18,76000;1,03956;132,86644
18,80000;1,04153;132,32909
18,84000;1,04351;132,47906
18,88000;1,04554;131,74566
18,92000;1,04757;131,90069
18,96000;1,04960;132,43774
19,00000;1,05158;132,23042
19,04000;1,05349;131,02138
19,08000;1,05546;130,99972
19,12000;1,05756;131,39970
19,16000;1,05959;131,48735
19,20000;1,06156;130,53381
19,24000;1,06348;130,92019
19,28000;1,06551;129,93383
19,32000;1,06748;130,20190
19,36000;1,06951;130,31295
19,40000;1,07155;130,07661
19,44000;1,07352;129,54101
19,48000;1,07549;128,27649
19,52000;1,07747;128,40006
19,56000;1,07950;127,97281
19,60000;1,08147;128,14155
19,64000;1,08339;127,92054
19,68000;1,08554;127,41509
19,72000;1,08751;127,14544
19,76000;1,08954;127,34884
19,80000;1,09158;127,59141
19,84000;1,09361;127,33095
19,88000;1,09552;126,79663
19,92000;1,09756;127,41511
19,96000;1,09953;127,31139
20,00000;1,10156;126,98767
20,04000;1,10359;126,17683
20,08000;1,10545;125,93082
20,12000;1,10748;126,00506
20,16000;1,10945;125,79660
20,20000;1,11149;126,48798
20,24000;1,11346;126,05669
20,28000;1,11519;125,82883
20,32000;1,11759;125,65975
20,36000;1,11950;125,31341
20,40000;1,12153;125,62729
20,44000;1,12350;124,65602
20,48000;1,12548;125,45625
20,52000;1,12739;124,78664
20,56000;1,12942;124,51834
20,60000;1,13146;124,34793
20,64000;1,13343;123,91574
20,68000;1,13546;124,25510
20,72000;1,13738;123,89921
20,76000;1,13941;124,31195
20,80000;1,14150;123,91969
20,84000;1,14353;123,75689
20,88000;1,14557;124,04454
20,92000;1,14748;123,09524
20,96000;1,14951;122,66129
21,00000;1,15149;122,93677
21,04000;1,15352;122,31782
21,08000;1,15561;122,76975
21,12000;1,15746;121,71868
21,16000;1,15950;121,75912
21,20000;1,16147;121,93011
21,24000;1,16344;121,65733
21,28000;1,16554;121,52634
21,32000;1,16745;122,28296
21,36000;1,16948;121,43418
21,40000;1,17152;121,38446
21,44000;1,17349;120,80381
21,48000;1,17552;119,88219
21,52000;1,17743;120,18218
21,56000;1,17941;119,90607
21,60000;1,18150;119,68436
21,64000;1,18347;119,85487
21,68000;1,18545;120,07962
21,72000;1,18754;120,46633
21,76000;1,18951;119,44567
21,80000;1,19154;119,93020
21,84000;1,19352;119,89530
21,88000;1,19561;119,43735
21,92000;1,19758;119,52622
21,96000;1,19950;119,43945
22,00000;1,20153;119,89970
22,04000;1,20350;118,80324
22,08000;1,20554;118,94316
22,12000;1,20757;118,98825
22,16000;1,20948;118,62220
22,20000;1,21151;118,35259
22,24000;1,21349;117,51909
22,28000;1,21558;117,54911
22,32000;1,21761;117,05618
22,36000;1,21953;116,43105
22,40000;1,22144;117,04122
22,44000;1,22353;117,13890
22,48000;1,22551;115,81228
22,52000;1,22760;116,00740
22,56000;1,22951;115,70798
22,60000;1,23148;115,89307
22,64000;1,23352;115,55408
22,68000;1,23555;115,40824
22,72000;1,23758;115,01313
22,76000;1,23962;115,36074
22,80000;1,24147;115,30312
22,84000;1,24356;115,57939
22,88000;1,24553;114,58150
22,92000;1,24757;115,02454
22,96000;1,24960;114,92147
23,00000;1,25151;114,56526
23,04000;1,25355;114,18101
23,08000;1,25552;114,36490
23,12000;1,25749;114,08295
23,16000;1,25959;114,55026
23,20000;1,26150;113,96074
23,24000;1,26353;114,06631
23,28000;1,26556;113,21215
23,32000;1,26754;113,23813
23,36000;1,26951;112,53031
23,40000;1,27148;112,56225
23,44000;1,27340;111,98490
23,48000;1,27549;111,69302
23,52000;1,27746;111,21724
23,56000;1,27950;111,43651
23,60000;1,28153;112,37036
23,64000;1,28344;112,03928
23,68000;1,28553;112,78488
23,72000;1,28751;112,17450
23,76000;1,28954;111,23666
23,80000;1,29145;111,52751
23,84000;1,29349;111,19173
23,88000;1,29552;110,77783
23,92000;1,29749;110,99166
23,96000;1,29952;110,46319
24,00000;1,30156;109,65497
24,04000;1,30341;109,93241
24,08000;1,30550;109,51679
24,12000;1,30748;109,60723
24,16000;1,30951;109,53906
24,20000;1,31154;109,66939
24,24000;1,31352;109,59854
24,28000;1,31537;108,92930
24,32000;1,31752;108,60635
24,36000;1,31949;108,56357
24,40000;1,32153;108,49379
24,44000;1,32350;108,72509
24,48000;1,32547;108,32235
24,52000;1,32745;109,02142
24,56000;1,32948;109,24129
24,60000;1,33145;108,01597
24,64000;1,33354;107,47358
24,68000;1,33540;107,38375
24,72000;1,33749;107,15920
24,76000;1,33946;107,10629
24,80000;1,34144;106,68815
24,84000;1,34353;106,88471
24,88000;1,34538;106,21548
24,92000;1,34748;105,54024
24,96000;1,34945;106,36845
25,00000;1,35142;105,82608
25,04000;1,35345;105,21462
25,08000;1,35543;105,94431
25,12000;1,35746;105,03095
25,16000;1,35949;104,99234
25,20000;1,36147;105,38982
25,24000;1,36350;104,94681
25,28000;1,36547;105,01421
25,32000;1,36745;104,01756
25,36000;1,36948;103,94935
25,40000;1,37151;103,54386
25,44000;1,37348;103,10350
25,48000;1,37552;103,82045
25,52000;1,37743;103,04118
25,56000;1,37946;102,51055
25,60000;1,38150;102,15172
25,64000;1,38353;102,24263
25,68000;1,38556;103,31962
25,72000;1,38742;102,08964
25,76000;1,38951;101,88313
25,80000;1,39148;101,66207
25,84000;1,39351;101,50364
25,88000;1,39555;102,17112
25,92000;1,39746;101,46173
25,96000;1,39949;101,18810
26,00000;1,40147;101,58161
26,04000;1,40350;100,18823
26,08000;1,40553;100,56228
26,12000;1,40744;99,86667
26,16000;1,40948;100,23230
26,20000;1,41151;100,74852
26,24000;1,41348;100,41486
26,28000;1,41558;100,04735
26,32000;1,41755;100,52599
26,36000;1,41958;99,62167
26,40000;1,42155;99,99726
26,44000;1,42353;99,72143
26,48000;1,42556;99,68692
26,52000;1,42759;100,07354
26,56000;1,42951;99,00696
26,60000;1,43154;99,72631
26,64000;1,43351;98,81000
26,68000;1,43555;98,62463
26,72000;1,43758;98,47063
26,76000;1,43949;97,97985
26,80000;1,44152;97,49194
26,84000;1,44356;97,23242
26,88000;1,44559;96,77922
26,92000;1,44756;97,20764
26,96000;1,44948;96,86907
27,00000;1,45145;96,72800
27,04000;1,45348;96,34328
27,08000;1,45534;96,70273
27,12000;1,45755;97,39981
27,16000;1,45952;96,27943
27,20000;1,46143;96,34348
27,24000;1,46353;96,26937
27,28000;1,46556;96,12986
27,32000;1,46753;95,91953
27,36000;1,46957;96,34803
27,40000;1,47142;95,12913
27,44000;1,47351;95,41871
27,48000;1,47554;95,00502
27,52000;1,47752;94,83734
27,56000;1,47961;94,95227
27,60000;1,48152;94,50521
27,64000;1,48350;94,91307
27,68000;1,48565;94,94644
27,72000;1,48762;94,06302
27,76000;1,48966;93,77961
27,80000;1,49151;93,64557
27,84000;1,49354;94,03612
27,88000;1,49545;93,87064
27,92000;1,49749;93,85144
27,96000;1,49952;94,21633
28,00000;1,50143;93,90697
28,04000;1,50347;92,95246
28,08000;1,50550;92,42033
28,12000;1,50747;92,58079
28,16000;1,50951;92,37297
28,20000;1,51154;92,96536
28,24000;1,51351;92,03313
28,28000;1,51554;92,46072
28,32000;1,51752;91,61247
28,36000;1,51955;91,60693
28,40000;1,52152;91,51365
28,44000;1,52344;91,32832
28,48000;1,52553;91,08253
28,52000;1,52750;89,80338
28,56000;1,52953;90,48072
28,60000;1,53157;90,00309
28,64000;1,53342;90,56989
28,68000;1,53551;90,22302
28,72000;1,53755;89,77452
28,76000;1,53952;89,20465
28,80000;1,54155;89,21528
28,84000;1,54329;88,79692
28,88000;1,54550;89,04863
28,92000;1,54747;88,24836
28,96000;1,54950;88,55058
29,00000;1,55154;87,78066
29,04000;1,55345;87,89407
29,08000;1,55542;88,20847
29,12000;1,55746;88,00456
29,16000;1,55949;88,52383
29,20000;1,56152;88,13236
29,24000;1,56355;88,14840
29,28000;1,56547;87,15831
29,32000;1,56750;87,06207
29,36000;1,56947;86,89524
29,40000;1,57145;86,94675
29,44000;1,57354;87,41469
29,48000;1,57545;86,71382
29,52000;1,57749;86,57765
29,56000;1,57952;86,67264
29,60000;1,58155;85,85137
29,64000;1,58358;86,01736
29,68000;1,58550;85,93493
29,72000;1,58759;85,60612
29,76000;1,58956;85,44838
29,80000;1,59154;84,71023
29,84000;1,59351;84,61406
29,88000;1,59542;84,55681
29,92000;1,59752;84,73611
29,96000;1,59955;84,37469
30,00000;1,60152;83,57241
30,04000;1,60355;83,99067
30,08000;1,60547;84,18945
30,12000;1,60750;82,99031
30,16000;1,60953;83,33689
30,20000;1,61151;83,39263
30,24000;1,61354;82,98825
30,28000;1,61551;82,73890
30,32000;1,61743;82,14127
30,36000;1,61946;82,82588
30,40000;1,62137;83,07688
30,44000;1,62358;82,77133
30,48000;1,62556;82,22818
30,52000;1,62747;81,34462
30,56000;1,62950;81,76009
30,60000;1,63154;81,61077
30,64000;1,63357;81,22686
30,68000;1,63560;81,43393
30,72000;1,63751;82,02777
30,76000;1,63955;82,01447
30,80000;1,64152;81,65509
30,84000;1,64349;81,84055
30,88000;1,64541;81,69292
30,92000;1,64756;81,31216
30,96000;1,64959;80,90851
31,00000;1,65151;80,62784
31,04000;1,65354;79,60189
31,08000;1,65557;79,43131
31,12000;1,65748;79,10158
31,16000;1,65952;79,29475
31,20000;1,66149;79,75309
31,24000;1,66352;78,37371
31,28000;1,66556;79,53816
31,32000;1,66753;79,20164
31,36000;1,66950;78,16171
31,40000;1,67153;78,47595
31,44000;1,67357;78,05306
31,48000;1,67560;77,97708
31,52000;1,67757;78,10398
31,56000;1,67895;77,72131
31,60000;1,68164;78,41716
31,64000;1,68355;77,54802
31,68000;1,68559;76,50185
31,72000;1,68762;77,17853
31,76000;1,68947;76,78776
31,80000;1,69156;76,39672
31,84000;1,69354;76,24505
31,88000;1,69557;76,57703
31,92000;1,69754;75,72533
31,96000;1,69952;76,10934
32,00000;1,70149;76,48199
32,04000;1,70352;75,65920
32,08000;1,70556;76,09235
32,12000;1,70759;76,26779
32,16000;1,70950;75,60580
32,20000;1,71147;75,77339
32,24000;1,71351;75,35316
32,28000;1,71554;75,36124
32,32000;1,71751;75,32351
32,36000;1,71955;75,28628
32,40000;1,72140;74,82965
32,44000;1,72349;74,19091
32,48000;1,72546;73,89529
32,52000;1,72750;73,43068
32,56000;1,72953;73,24973
32,60000;1,73144;72,99809
32,64000;1,73348;73,10309
32,68000;1,73545;73,67051
32,72000;1,73724;72,64921
32,76000;1,73958;72,49803
32,80000;1,74149;72,11673
32,84000;1,74346;71,85876
32,88000;1,74549;72,74871
32,92000;1,74747;72,22510
32,96000;1,74950;72,47896
33,00000;1,75147;72,83915
33,04000;1,75339;71,30305
33,08000;1,75548;72,12075
33,12000;1,75751;71,75404
33,16000;1,75949;71,66089
33,20000;1,76152;71,79329
33,24000;1,76349;71,13566
33,28000;1,76552;71,37547
33,32000;1,76756;70,91524
33,36000;1,76953;70,91156
33,40000;1,77156;70,87587
33,44000;1,77342;70,04362
33,48000;1,77545;69,97319
33,52000;1,77748;70,81290
33,56000;1,77945;70,81716
33,60000;1,78149;70,14095
33,64000;1,78346;70,11962
33,68000;1,78531;70,82566
33,72000;1,78753;70,58129
33,76000;1,78950;69,45432
33,80000;1,79153;69,34403
33,84000;1,79351;68,36597
33,88000;1,79542;69,44615
33,92000;1,79745;68,93690
33,96000;1,79948;68,43300
34,00000;1,80152;67,78122
34,04000;1,80349;67,76337
34,08000;1,80540;68,18646
34,12000;1,80744;67,76315
34,16000;1,80947;67,89607
34,20000;1,81150;66,95478
34,24000;1,81353;67,52195
34,28000;1,81545;67,70464
34,32000;1,81748;67,20864
34,36000;1,81945;66,36146
34,40000;1,82143;66,63173
34,44000;1,82346;66,67254
34,48000;1,82537;66,48356
34,52000;1,82747;66,17816
34,56000;1,82950;65,96193
34,60000;1,83147;66,02810
34,64000;1,83350;66,26885
34,68000;1,83542;65,57786
34,72000;1,83751;65,66343
34,76000;1,83954;65,64091
34,80000;1,84152;64,93460
34,84000;1,84355;65,79111
34,88000;1,84546;65,23457
34,92000;1,84750;64,72099
34,96000;1,84953;64,50875
35,00000;1,85156;65,10285
35,04000;1,85359;65,18151
35,08000;1,85557;64,69692
35,12000;1,85754;64,45905
35,16000;1,85957;64,56648
35,20000;1,86161;64,71365
35,24000;1,86364;63,82267
35,28000;1,86561;64,23019
35,32000;1,86747;63,79422
35,36000;1,86950;63,64487
35,40000;1,87147;62,41309
35,44000;1,87350;62,52797
35,48000;1,87554;62,45002
35,52000;1,87745;62,05900
35,56000;1,87948;62,06426
35,60000;1,88152;62,91093
35,64000;1,88355;62,75196
35,68000;1,88558;62,19116
35,72000;1,88749;62,27932
35,76000;1,88947;61,95696
35,80000;1,89144;62,13404
35,84000;1,89347;62,09753
35,88000;1,89551;61,89661
35,92000;1,89754;61,80044
35,96000;1,89939;60,74934
36,00000;1,90143;61,50823
36,04000;1,90346;60,90356
36,08000;1,90549;60,65036
36,12000;1,90752;60,05996
36,16000;1,90950;60,21349
36,20000;1,91153;59,72077
36,24000;1,91356;60,11771
36,28000;1,91548;60,31952
36,32000;1,91751;59,86906
36,36000;1,91948;59,67550
36,40000;1,92151;59,76888
36,44000;1,92349;60,25545
36,48000;1,92552;59,67061
36,52000;1,92749;59,75801
36,56000;1,92947;60,04908
36,60000;1,93144;59,29386
36,64000;1,93347;59,42247
36,68000;1,93545;59,11051
36,72000;1,93748;58,30968
36,76000;1,93945;58,76687
36,80000;1,94142;57,99311
36,84000;1,94346;58,36036
36,88000;1,94549;58,08360
36,92000;1,94746;58,14608
36,96000;1,94950;58,52645
37,00000;1,95141;57,72331
37,04000;1,95350;57,79390
37,08000;1,95548;57,87567
37,12000;1,95751;57,73289
37,16000;1,95954;57,92271
37,20000;1,96145;57,17977
37,24000;1,96355;57,18511
37,28000;1,96552;56,70747
37,32000;1,96755;57,29844
37,36000;1,96959;57,46311
37,40000;1,97150;56,80577
37,44000;1,97347;57,02146
37,48000;1,97550;56,75761
37,52000;1,97748;55,86360
37,56000;1,97951;56,08071
37,60000;1,98148;55,69609
37,64000;1,98346;54,94740
37,68000;1,98543;55,55438
37,72000;1,98746;55,60391
37,76000;1,98950;55,16773
37,80000;1,99147;55,71631
37,84000;1,99344;55,26419
37,88000;1,99547;55,03748
37,92000;1,99745;55,69570
37,96000;1,99942;55,79104
38,00000;2,00151;55,31408
38,04000;2,00343;55,34014
38,08000;2,00552;55,54887
38,12000;2,00749;55,16271
38,16000;2,00946;54,19615
38,20000;2,01150;55,16638
38,24000;2,01347;54,03109
38,28000;2,01550;54,12351
38,32000;2,01748;54,11756
38,36000;2,01951;53,59906
38,40000;2,02148;54,13979
38,44000;2,02346;53,84862
38,48000;2,02543;53,37644
38,52000;2,02746;53,26754
38,56000;2,02949;53,93014
38,60000;2,03153;53,44774
38,64000;2,03350;53,54951
38,68000;2,03547;53,29007
38,72000;2,03751;53,26431
38,76000;2,03954;52,89837
38,80000;2,04157;53,47276
38,84000;2,04355;53,32332
38,88000;2,04546;52,57115
38,92000;2,04749;52,36844
38,96000;2,04952;52,15002
39,00000;2,05150;52,53749
39,04000;2,05353;52,77850
39,08000;2,05544;52,05523
39,12000;2,05754;51,49317
39,16000;2,05951;52,02852
39,20000;2,06154;51,49841
39,24000;2,06357;52,10086
39,28000;2,06543;51,74293
39,32000;2,06752;51,37071
39,36000;2,06949;51,35847
39,40000;2,07147;50,79522
39,44000;2,07356;51,43750
39,48000;2,07547;50,36391
39,52000;2,07751;49,97384
39,56000;2,07948;50,57079
39,60000;2,08145;50,91415
39,64000;2,08354;49,84563
39,68000;2,08552;50,15989
39,72000;2,08755;49,94861
39,76000;2,08952;49,37843
39,80000;2,09150;49,68913
39,84000;2,09353;49,34429
39,88000;2,09550;49,92295
39,92000;2,09742;49,61965
39,96000;2,09951;49,49890
40,00000;2,10154;49,36422
40,04000;2,10357;49,15913
40,08000;2,10561;49,67293
40,12000;2,10752;49,32949
40,16000;2,10949;48,76493
40,20000;2,11159;49,44257
40,24000;2,11356;48,71210
40,28000;2,11559;49,03762
40,32000;2,11744;48,28923
40,36000;2,11948;48,19373
40,40000;2,12151;47,75676
40,44000;2,12354;47,96719
40,48000;2,12552;48,10544
40,52000;2,12755;47,03814
40,56000;2,12946;47,51090
40,60000;2,13156;47,93046
40,64000;2,13353;47,26267
40,68000;2,13556;47,80031
40,72000;2,13759;47,46397
40,76000;2,13951;47,14268
40,79800;2,14142;46,50392