File: SU - Suspension/05 - Essais/Excels essais Optimus/collage alu carbone 05_02_19/collage10.is_tens_RawData/Specimen_RawData_1.csv
Temps;Déplacement;Charge
(sec);(mm);(N)
0,00000;-0,00717;19,68247
0,06000;-0,00646;19,13569
0,12000;-0,00281;23,89332
0,18000;0,00233;32,28089
0,24000;0,00783;40,30515
0,30000;0,01327;48,39356
0,36000;0,01871;57,06919
0,42000;0,02404;64,64799
0,48000;0,02936;71,85048
0,54000;0,03438;75,29134
0,60000;0,03946;78,73955
0,66000;0,04448;80,86746
0,72000;0,04951;88,72637
0,78000;0,05453;107,65139
0,84000;0,05949;126,08058
0,90000;0,06451;144,58998
0,96000;0,06954;162,48169
1,02000;0,07462;180,27619
1,08000;0,07958;198,57401
1,14000;0,08460;216,72626
1,20000;0,08962;235,55665
1,26000;0,09465;253,41790
1,32000;0,09961;272,50075
1,38000;0,10457;288,85370
1,44000;0,10959;303,74688
1,50000;0,11456;315,11486
1,56000;0,11958;323,80791
1,62000;0,12460;328,28567
1,68000;0,12962;332,49427
1,74000;0,13459;336,50449
1,80000;0,13955;338,52002
1,86000;0,14457;341,15557
1,92000;0,14953;343,28557
1,98000;0,15456;346,99431
2,04000;0,15952;350,30132
2,10000;0,16448;353,68227
2,16000;0,16956;358,50306
2,22000;0,17453;363,11271
2,28000;0,17961;369,24579
2,34000;0,18457;376,71211
2,40000;0,18959;384,01666
2,46000;0,19455;389,68099
2,52000;0,19958;343,90755
2,58000;0,20460;363,83369
2,64000;0,20962;382,89358
2,70000;0,21452;396,82128
2,76000;0,21955;412,04551
2,82000;0,22451;425,37618
2,88000;0,22959;438,87533
2,94000;0,23455;447,90106
3,00000;0,23946;452,39483
3,06000;0,24442;456,88874
3,12000;0,24950;459,40005
3,18000;0,25452;460,65962
3,24000;0,25955;461,25548
3,30000;0,26457;463,48609
3,36000;0,26959;464,33615
3,42000;0,27455;464,41779
3,48000;0,27964;464,79385
3,54000;0,28454;464,53914
3,60000;0,28956;465,17951
3,66000;0,29458;465,88033
3,72000;0,29961;466,32588
3,78000;0,30463;467,68934
3,84000;0,30959;468,06224
3,90000;0,31461;468,91272
3,96000;0,31957;469,62560
4,02000;0,32466;471,39484
4,08000;0,32962;473,38721
4,14000;0,33458;476,21205
4,20000;0,33960;480,52189
4,26000;0,34457;484,79591
4,32000;0,34965;489,20391
4,38000;0,35461;493,67757
4,44000;0,35957;497,48588
4,50000;0,36466;502,28816
4,56000;0,36956;505,71072
4,62000;0,37464;509,66474
4,68000;0,37954;513,70626
4,74000;0,38451;517,70653
4,80000;0,38953;522,45120
4,86000;0,39449;524,98979
4,92000;0,39951;529,30992
4,98000;0,40454;533,12439
5,04000;0,40950;538,33975
5,10000;0,41458;547,12058
5,16000;0,41954;557,86860
5,22000;0,42457;567,96889
5,28000;0,42959;575,99870
5,34000;0,43461;582,12229
5,40000;0,43957;589,73045
5,46000;0,44448;595,10111
5,52000;0,44956;600,19023
5,58000;0,45446;607,87359
5,64000;0,45954;621,04422
5,70000;0,46456;632,03522
5,76000;0,46959;642,14813
5,82000;0,47449;653,04642
5,88000;0,47957;663,55742
5,94000;0,48453;670,17083
6,00000;0,48944;678,11175
6,06000;0,49452;686,47661
6,12000;0,49948;693,27559
6,18000;0,50450;700,42452
6,24000;0,50959;708,58169
6,30000;0,51437;715,63954
6,36000;0,51957;721,47716
6,42000;0,52453;723,17617
6,48000;0,52956;723,85785
6,54000;0,53458;723,46418
6,60000;0,53954;721,88280
6,66000;0,54456;719,25526
6,72000;0,54958;715,29625
6,78000;0,55461;712,75355
6,84000;0,55957;708,94733
6,90000;0,56465;705,77790
6,96000;0,56955;703,46366
7,02000;0,57458;701,90947
7,08000;0,57960;701,52972
7,14000;0,58456;701,64818
7,20000;0,58958;701,61498
7,26000;0,59455;702,28642
7,32000;0,59951;703,73188
7,38000;0,60453;704,53365
7,44000;0,60943;706,39290
7,50000;0,61452;708,66542
7,56000;0,61948;711,79774
7,62000;0,62456;715,75018
7,68000;0,62952;719,96637
7,74000;0,63449;722,72508
7,80000;0,63957;726,51673
7,86000;0,64453;727,90910
7,92000;0,64955;730,13087
7,98000;0,65446;731,42420
8,04000;0,65954;733,50836
8,10000;0,66450;734,88830
8,16000;0,66952;736,35983
8,22000;0,67455;738,09754
8,28000;0,67951;739,92652
8,34000;0,68447;742,37795
8,40000;0,68949;744,26048
8,46000;0,69451;746,57365
8,52000;0,69960;749,08659
8,58000;0,70450;750,80814
8,64000;0,70952;753,44397
8,70000;0,71448;758,10216
8,76000;0,71951;763,84069
8,82000;0,72447;769,65969
8,88000;0,72949;776,98235
8,94000;0,73445;783,95996
9,00000;0,73954;791,26516
9,06000;0,74456;798,70308
9,12000;0,74952;806,03324
9,18000;0,75454;812,75804
9,24000;0,75957;820,73873
9,30000;0,76447;828,17879
9,36000;0,76949;835,49032
9,42000;0,77451;842,72400
9,48000;0,77954;850,53872
9,54000;0,78456;858,62735
9,60000;0,78952;865,57902
9,66000;0,79460;873,77010
9,72000;0,79956;881,32694
9,78000;0,80465;888,95215
9,84000;0,80949;895,31299
9,90000;0,81451;903,73317
9,96000;0,81947;911,50943
10,02000;0,82456;917,51963
10,08000;0,82952;926,07783
10,14000;0,83448;932,76268
10,20000;0,83950;941,40777
10,26000;0,84453;948,69873
10,32000;0,84955;957,05595
10,38000;0,85469;965,61406
10,44000;0,85953;972,41933
10,50000;0,86456;980,74879
10,56000;0,86946;988,51705
10,62000;0,87454;996,27664
10,68000;0,87956;1004,83345
10,74000;0,88453;1012,24510
10,80000;0,88955;1022,01002
10,86000;0,89457;1028,65249
10,92000;0,89959;1035,80970
10,98000;0,90462;1043,72082
11,04000;0,90958;1050,39226
11,10000;0,91460;1058,58548
11,16000;0,91956;1066,19671
11,22000;0,92452;1072,87643
11,28000;0,92955;1080,45433
11,34000;0,93451;1087,74565
11,40000;0,93959;1099,41969
11,46000;0,94455;1112,37215
11,52000;0,94958;1125,36978
11,58000;0,95448;1138,42860
11,64000;0,95956;1151,33217
11,70000;0,96452;1164,01650
11,76000;0,96955;1175,16862
11,82000;0,97457;1188,08607
11,88000;0,97953;1198,83427
11,94000;0,98455;1209,88954
12,00000;0,98958;1220,05502
12,06000;0,99460;1231,40682
12,12000;0,99956;1243,01240
12,18000;1,00458;1254,95279
12,24000;1,00961;1266,66129
12,30000;1,01457;1277,33871
12,36000;1,01959;1289,27352
12,42000;1,02461;1301,21466
12,48000;1,02963;1312,44510
12,54000;1,03466;1325,09526
12,60000;1,03956;1336,00011
12,66000;1,04458;1347,01794
12,72000;1,04954;1358,08652
12,78000;1,05463;1370,78138
12,84000;1,05953;1381,95250
12,90000;1,06449;1391,77032
12,96000;1,06951;1404,14974
13,02000;1,07454;1415,99886
13,08000;1,07956;1426,98484
13,14000;1,08458;1439,45785
13,20000;1,08948;1449,66431
13,26000;1,09457;1461,51148
13,32000;1,09947;1473,69169
13,38000;1,10449;1485,70184
13,44000;1,10945;1498,60829
13,50000;1,11448;1509,79115
13,56000;1,11950;1522,95614
13,62000;1,12446;1534,16796
13,68000;1,12960;1548,15530
13,74000;1,13451;1559,95535
13,80000;1,13953;1572,40313
13,86000;1,14449;1584,04522
13,92000;1,14951;1595,73592
13,98000;1,15459;1609,61207
14,04000;1,15950;1621,40168
14,10000;1,16446;1632,95772
14,16000;1,16948;1645,14426
14,22000;1,17450;1656,85695
14,28000;1,17959;1670,43563
14,34000;1,18455;1683,08225
14,40000;1,18957;1695,40923
14,46000;1,19447;1707,22622
14,52000;1,19962;1721,54121
14,58000;1,20452;1733,11848
14,64000;1,20954;1745,55723
14,70000;1,21450;1759,30075
14,76000;1,21947;1771,79594
14,82000;1,22455;1786,36182
14,88000;1,22951;1798,16950
14,94000;1,23453;1812,07601
15,00000;1,23956;1823,26045
15,06000;1,24452;1836,38427
15,12000;1,24954;1847,93659
15,18000;1,25450;1861,04197
15,24000;1,25953;1872,77272
15,30000;1,26455;1885,35657
15,36000;1,26951;1896,66785
15,42000;1,27459;1908,78287
15,48000;1,27950;1921,42650
15,54000;1,28458;1934,49613
15,60000;1,28948;1946,03801
15,66000;1,29456;1959,17152
15,72000;1,29946;1970,88327
15,78000;1,30449;1983,92011
15,84000;1,30921;1995,95969
15,90000;1,31447;2009,18242
15,96000;1,31949;2022,32022
16,02000;1,32452;2034,73642
16,08000;1,32948;2046,22895
16,14000;1,33450;2058,17278
16,20000;1,33946;2070,33195
16,26000;1,34455;2083,20543
16,32000;1,34951;2094,68231
16,38000;1,35453;2106,66489
16,44000;1,35943;2119,16324
16,50000;1,36452;2132,33922
16,56000;1,36954;2144,35831
16,62000;1,37450;2156,79295
16,68000;1,37958;2169,88660
16,74000;1,38449;2180,96077
16,80000;1,38957;2194,32395
16,86000;1,39453;2206,24954
16,92000;1,39961;2218,73168
16,98000;1,40457;2231,96633
17,04000;1,40948;2243,41992
17,10000;1,41462;2256,59050
17,16000;1,41958;2269,45207
17,22000;1,42460;2280,62049
17,28000;1,42963;2292,74780
17,34000;1,43453;2303,50327
17,40000;1,43955;2315,65032
17,46000;1,44457;2328,40367
17,52000;1,44960;2340,01502
17,58000;1,45456;2352,19374
17,64000;1,45964;2364,83086
17,70000;1,46460;2377,22564
17,76000;1,46957;2387,79448
17,82000;1,47459;2400,87230
17,88000;1,47949;2411,80379
17,94000;1,48457;2423,51480
18,00000;1,48954;2435,42083
18,06000;1,49444;2445,39250
18,12000;1,49958;2458,12312
18,18000;1,50454;2469,11850
18,24000;1,50957;2479,62698
18,30000;1,51459;2491,88282
18,36000;1,51955;2501,84014
18,42000;1,52457;2514,49291
18,48000;1,52947;2524,80898
18,54000;1,53456;2537,37215
18,60000;1,53952;2549,05764
18,66000;1,54454;2559,60748
18,72000;1,54956;2571,16780
18,78000;1,55447;2581,75973
18,84000;1,55955;2594,29533
18,90000;1,56457;2604,40111
18,96000;1,56953;2616,61187
19,02000;1,57456;2627,97251
19,08000;1,57940;2639,00384
19,14000;1,58454;2649,85878
19,20000;1,58944;2661,42134
19,26000;1,59453;2671,75976
19,32000;1,59949;2682,34424
19,38000;1,60451;2692,04117
19,44000;1,60959;2703,85277
19,50000;1,61438;2714,48102
19,56000;1,61964;2725,99887
19,62000;1,62460;2735,32383
19,68000;1,62950;2745,83753
19,74000;1,63464;2757,69997
19,80000;1,63961;2767,33208
19,86000;1,64457;2777,56266
19,92000;1,64953;2787,07929
19,98000;1,65455;2797,79062
20,04000;1,65964;2809,38838
20,10000;1,66454;2818,68428
20,16000;1,66956;2829,19817
20,22000;1,67452;2838,94911
20,28000;1,67961;2850,74301
20,34000;1,68451;2859,39053
20,40000;1,68953;2869,05617
20,46000;1,69449;2880,09625
20,52000;1,69928;2888,90563
20,58000;1,70448;2900,89492
20,64000;1,70950;2908,84692
20,70000;1,71446;2918,82306
20,76000;1,71943;2927,39309
20,82000;1,72451;2937,66782
20,88000;1,72953;2948,39256
20,94000;1,73449;2957,53069
21,00000;1,73952;2968,69930
21,06000;1,74454;2977,91753
21,12000;1,74950;2987,61874
21,18000;1,75452;2997,57924
21,24000;1,75949;3006,93363
21,30000;1,76451;3016,40294
21,36000;1,76941;3025,99408
21,42000;1,77455;3036,52789
21,48000;1,77945;3046,73947
21,54000;1,78454;3056,02420
21,60000;1,78944;3066,29222
21,66000;1,79452;3076,62748
21,72000;1,79954;3087,28479
21,78000;1,80451;3096,56132
21,84000;1,80953;3107,23949
21,90000;1,81449;3116,91947
21,96000;1,81951;3127,40617
22,02000;1,82454;3137,78706
22,08000;1,82950;3147,78090
22,14000;1,83452;3158,99849
22,20000;1,83954;3169,72658
22,26000;1,84463;3180,78063
22,32000;1,84959;3190,67053
22,38000;1,85455;3200,41552
22,44000;1,85957;3211,70650
22,50000;1,86448;3221,89406
22,56000;1,86962;3232,74508
22,62000;1,87452;3242,40178
22,68000;1,87954;3252,75101
22,74000;1,88445;3262,61744
22,80000;1,88953;3272,78525
22,86000;1,89455;3284,71102
22,92000;1,89951;3293,13017
22,98000;1,90453;3303,60793
23,04000;1,90950;3313,43375
23,10000;1,91452;3323,95062
23,16000;1,91954;3333,65239
23,22000;1,92444;3343,46630
23,28000;1,92947;3352,91550
23,34000;1,93443;3362,97937
23,40000;1,93951;3374,53038
23,46000;1,94453;3384,58084
23,52000;1,94956;3394,22710
23,58000;1,95458;3404,34499
23,64000;1,95948;3413,94618
23,70000;1,96456;3424,88736
23,76000;1,96953;3435,20306
23,82000;1,97449;3445,74489
23,88000;1,97951;3454,79548
23,94000;1,98447;3464,82024
24,00000;1,98950;3475,16276
24,06000;1,99452;3484,89359
24,12000;1,99954;3495,27821
24,18000;2,00456;3504,60373
24,24000;2,00946;3514,34536
24,30000;2,01455;3525,43108
24,36000;2,01951;3534,90002
24,42000;2,02459;3544,50010
24,48000;2,02949;3554,12848
24,54000;2,03452;3563,66560
24,60000;2,03948;3574,55313
24,66000;2,04456;3583,86375
24,72000;2,04952;3595,01354
24,78000;2,05449;3603,79592
24,84000;2,05951;3615,55889
24,90000;2,06453;3623,86853
24,96000;2,06955;3634,02292
25,02000;2,07458;3643,62299
25,08000;2,07954;3654,29036
25,14000;2,08456;3664,35982
25,20000;2,08958;3675,26598
25,26000;2,09461;3684,47676
25,32000;2,09963;3694,69635
25,38000;2,10453;3703,45786
25,44000;2,10961;3714,74326
25,50000;2,11452;3723,72232
25,56000;2,11966;3734,55510
25,62000;2,12456;3743,76997
25,68000;2,12958;3753,64982
25,74000;2,13454;3764,13912
25,80000;2,13957;3773,40093
25,86000;2,14453;3782,21795
25,92000;2,14955;3792,81156
25,98000;2,15451;3802,77485
26,04000;2,15954;3812,00016
26,10000;2,16450;3821,61736
26,16000;2,16958;3831,36049
26,22000;2,17448;3841,13342
26,28000;2,17957;3852,32307
26,34000;2,18453;3862,42643
26,40000;2,18949;3872,64676
26,46000;2,19457;3883,00307
26,52000;2,19942;3892,99095
26,58000;2,20450;3903,94814
26,64000;2,20946;3915,14935
26,70000;2,21454;3924,74197
26,76000;2,21951;3936,50010
26,82000;2,22453;3946,39634
26,88000;2,22955;3957,75102
26,94000;2,23457;3969,74757
27,00000;2,23953;3979,77903
27,06000;2,24456;3989,80193
27,12000;2,24934;4000,03791
27,18000;2,25454;4012,72364
27,24000;2,25944;4023,96619
27,30000;2,26453;4035,28288
27,36000;2,26949;4046,68376
27,42000;2,27457;4058,13232
27,48000;2,27953;4070,16315
27,54000;2,28456;4082,42755
27,60000;2,28958;4094,35742
27,66000;2,29454;4104,77072
27,72000;2,29956;4116,11758
27,78000;2,30453;4128,13015
27,84000;2,30949;4139,34216
27,90000;2,31451;4151,33759
27,96000;2,31953;4162,91989
28,02000;2,32462;4176,27320
28,08000;2,32964;4187,67110
28,14000;2,33454;4198,67784
28,20000;2,33956;4210,44305
28,26000;2,34447;4221,46283
28,32000;2,34961;4235,58764
28,38000;2,35451;4246,47294
28,44000;2,35953;4257,59777
28,50000;2,36450;4269,57384
28,56000;2,36946;4281,38785
28,62000;2,37454;4294,01062
28,68000;2,37950;4305,37276
28,74000;2,38446;4318,08904
28,80000;2,38943;4328,52283
28,86000;2,39457;4342,78809
28,92000;2,39953;4353,83432
28,98000;2,40449;4364,93903
29,04000;2,40952;4374,53799
29,10000;2,41448;4386,84672
29,16000;2,41950;4398,26511
29,22000;2,42446;4409,74534
29,28000;2,42949;4421,10039
29,34000;2,43451;4433,39981
29,40000;2,43947;4443,38992
29,46000;2,44461;4456,70411
29,52000;2,44946;4466,87229
29,58000;2,45454;4479,98196
29,64000;2,45950;4490,82144
29,70000;2,46458;4503,25012
29,76000;2,46949;4514,65845
29,82000;2,47451;4526,33277
29,88000;2,47953;4539,07624
29,94000;2,48455;4549,65644
30,00000;2,48951;4561,91041
30,06000;2,49436;4573,40367
30,12000;2,49950;4586,62175
30,18000;2,50458;4597,31407
30,24000;2,50948;4609,24469
30,30000;2,51457;4622,76414
30,36000;2,51947;4634,01154
30,42000;2,52455;4647,04670
30,48000;2,52957;4659,19487
30,54000;2,53454;4670,68069
30,60000;2,53956;4684,44712
30,66000;2,54452;4695,61554
30,72000;2,54960;4707,91273
30,78000;2,55451;4720,12237
30,84000;2,55959;4733,43842
30,90000;2,56461;4746,51456
30,96000;2,56963;4758,91307
31,02000;2,57460;4770,68201
31,08000;2,57950;4783,01793
31,14000;2,58452;4796,19242
31,20000;2,58960;4809,96780
31,26000;2,59451;4822,02694
31,32000;2,59953;4836,30113
31,38000;2,60443;4848,58789
31,44000;2,60957;4861,68675
31,50000;2,61453;4876,57487
31,56000;2,61956;4889,15108
31,62000;2,62452;4902,36469
31,68000;2,62948;4914,65218
31,74000;2,63444;4927,14457
31,80000;2,63953;4941,33793
31,86000;2,64449;4955,32639
31,92000;2,64951;4967,85156
31,98000;2,65435;4978,88476
32,04000;2,65956;4993,61940
32,10000;2,66452;5005,73814
32,16000;2,66954;5017,99881
32,22000;2,67456;5031,46574
32,28000;2,67953;5044,11310
32,34000;2,68455;5058,66669
32,40000;2,68951;5069,65108
32,46000;2,69459;5083,40113
32,52000;2,69956;5096,41729
32,58000;2,70458;5109,10600
32,64000;2,70960;5120,65925
32,70000;2,71462;5133,43625
32,76000;2,71964;5146,82196
32,82000;2,72455;5157,81045
32,88000;2,72963;5172,59166
32,94000;2,73459;5183,83197
33,00000;2,73949;5195,82294
33,06000;2,74464;5209,19524
33,12000;2,74948;5220,43519
33,18000;2,75462;5233,71138
33,24000;2,75958;5245,49298
33,30000;2,76455;5257,33195
33,36000;2,76957;5270,86705
33,42000;2,77447;5281,74452
33,48000;2,77955;5296,35288
33,54000;2,78458;5307,78132
33,60000;2,78960;5320,57658
33,66000;2,79456;5332,86110
33,72000;2,79952;5344,13122
33,78000;2,80455;5357,07474
33,84000;2,80945;5368,62202
33,90000;2,81453;5382,04536
33,96000;2,81955;5393,78487
34,02000;2,82452;5404,95887
34,08000;2,82960;5420,07610
34,14000;2,83450;5431,74222
34,20000;2,83958;5443,19749
34,26000;2,84448;5453,57391
34,32000;2,84957;5466,46491
34,38000;2,85453;5480,60164
34,44000;2,85949;5491,23958
34,50000;2,86451;5502,97573
34,56000;2,86960;5514,66756
34,62000;2,87450;5527,56190
34,68000;2,87952;5538,43305
34,74000;2,88448;5550,57004
34,80000;2,88951;5561,52351
34,86000;2,89447;5572,93855
34,92000;2,89955;5586,08882
34,98000;2,90451;5599,12845
35,04000;2,90954;5610,27527
35,10000;2,91456;5621,13784
35,16000;2,91952;5632,93099
35,22000;2,92454;5645,94343
35,28000;2,92951;5659,15555
35,34000;2,93459;5670,84476
35,40000;2,93955;5681,67493
35,46000;2,94469;5694,74548
35,52000;2,94959;5706,84560
35,58000;2,95456;5719,05822
35,64000;2,95952;5730,49933
35,70000;2,96454;5742,66352
35,76000;2,96956;5755,69607
35,82000;2,97459;5766,86300
35,88000;2,97949;5778,24004
35,94000;2,98451;5790,48097
36,00000;2,98941;5802,70067
36,06000;2,99456;5815,21019
36,12000;2,99946;5827,72270
36,18000;3,00454;5839,68498
36,24000;3,00950;5851,61895
36,30000;3,01447;5864,22458
36,36000;3,01949;5877,58273
36,42000;3,02445;5889,04619
36,48000;3,02953;5902,64313
36,54000;3,03444;5915,77962
36,60000;3,03952;5929,64888
36,66000;3,04454;5943,21489
36,72000;3,04956;5955,09708
36,78000;3,05459;5968,15161
36,84000;3,05949;5980,69355
36,90000;3,06451;5994,16383
36,96000;3,06947;6008,13702
37,02000;3,07444;6019,10539
37,08000;3,07952;6032,64235
37,14000;3,08442;6045,43947
37,20000;3,08956;6058,57410
37,26000;3,09452;6070,87910
37,32000;3,09955;6082,87416
37,38000;3,10451;6095,33228
37,44000;3,10953;6108,52838
37,50000;3,11449;6121,06957
37,56000;3,11952;6133,38426
37,62000;3,12448;6146,89440
37,68000;3,12950;6158,81346
37,74000;3,13452;6171,95703
37,80000;3,13949;6184,06534
37,86000;3,14451;6196,09654
37,92000;3,14953;6208,84262
37,98000;3,15455;6221,58423
38,04000;3,15958;6234,60598
38,10000;3,16460;6247,20380
38,16000;3,16956;6259,28715
38,22000;3,17458;6272,01945
38,28000;3,17949;6284,06107
38,34000;3,18463;6298,50775
38,40000;3,18959;6311,12009
38,46000;3,19461;6323,58342
38,52000;3,19952;6335,83143
38,58000;3,20454;6347,95874
38,64000;3,20950;6361,22301
38,70000;3,21452;6373,79810
38,76000;3,21954;6387,37977
38,82000;3,22451;6398,34329
38,88000;3,22953;6411,07783
38,94000;3,23455;6424,91356
39,00000;3,23957;6437,35826
39,06000;3,24460;6450,40199
39,12000;3,24950;6462,80348
39,18000;3,25452;6475,88968
39,24000;3,25954;6490,87727
39,30000;3,26451;6503,74815
39,36000;3,26959;6518,03538
39,42000;3,27449;6530,92340
39,48000;3,27957;6545,71950
39,54000;3,28454;6560,09540
39,60000;3,28956;6572,46411
39,66000;3,29458;6587,36750
39,72000;3,29948;6599,98432
39,78000;3,30451;6613,89306
39,84000;3,30947;6627,71612
39,90000;3,31449;6641,50566
39,96000;3,31957;6655,79438
40,02000;3,32447;6668,46931
40,08000;3,32956;6683,33769
40,14000;3,33452;6697,05570
40,20000;3,33960;6711,92035
40,26000;3,34450;6726,24260
40,32000;3,34953;6740,20052
40,38000;3,35449;6754,86177
40,44000;3,35951;6768,31156
40,50000;3,36447;6782,60103
40,56000;3,36950;6795,98600
40,62000;3,37458;6811,33121
40,68000;3,37954;6825,41505
40,74000;3,38462;6839,42437
40,80000;3,38959;6854,12735
40,86000;3,39449;6866,93713
40,92000;3,39957;6883,43570
40,98000;3,40459;6897,06206
41,04000;3,40956;6910,96336
41,10000;3,41458;6925,93679
41,16000;3,41930;6938,73093
41,22000;3,42462;6956,09748
41,28000;3,42958;6967,18097
41,34000;3,43461;6982,30118
41,40000;3,43957;6996,41556
41,46000;3,44465;7010,45990
41,52000;3,44955;7026,41234
41,58000;3,45452;7038,06430
41,64000;3,45954;7052,55046
41,70000;3,46456;7067,27877
41,76000;3,46958;7081,87148
41,82000;3,47461;7097,36124
41,88000;3,47957;7110,39975
41,94000;3,48459;7124,52605
42,00000;3,48949;7137,02515
42,06000;3,49452;7150,31624
42,12000;3,49954;7166,52349
42,18000;3,50444;7178,51371
42,24000;3,50958;7193,49608
42,30000;3,51449;7206,27159
42,36000;3,51963;7221,13848
42,42000;3,52453;7234,38412
42,48000;3,52955;7246,72675
42,54000;3,53452;7259,57602
42,60000;3,53930;7272,57356
42,66000;3,54456;7288,67501
42,72000;3,54952;7301,44978
42,78000;3,55449;7313,93769
42,84000;3,55951;7327,53277
42,90000;3,56447;7340,80896
42,96000;3,56955;7355,58867
43,02000;3,57446;7369,31339
43,08000;3,57954;7381,45113
43,14000;3,58444;7395,01193
43,20000;3,58952;7407,81724
43,26000;3,59448;7423,37778
43,32000;3,59945;7434,70490
43,38000;3,60447;7447,97587
43,44000;3,60943;7460,12405
43,50000;3,61451;7474,46045
43,56000;3,61954;7486,34562
43,62000;3,62456;7500,03234
43,68000;3,62952;7512,25874
43,74000;3,63454;7525,70480
43,80000;3,63951;7537,76357
43,86000;3,64447;7551,63357
43,92000;3,64949;7564,35543
43,98000;3,65457;7578,35954
44,04000;3,65948;7589,60024
44,10000;3,66456;7604,24957
44,16000;3,66946;7615,79797
44,22000;3,67454;7629,52045
44,28000;3,67945;7642,24976
44,34000;3,68453;7655,47380
44,40000;3,68955;7669,26259
44,46000;3,69451;7679,91692
44,52000;3,69953;7693,45909
44,58000;3,70456;7705,51711
44,64000;3,70952;7719,08313
44,70000;3,71460;7731,65673
44,76000;3,71950;7743,94274
44,82000;3,72459;7755,12829
44,88000;3,72955;7768,37692
44,94000;3,73457;7781,27909
45,00000;3,73953;7793,78414
45,06000;3,74450;7805,81608
45,12000;3,74946;7817,12234
45,18000;3,75448;7830,66526
45,24000;3,75962;7843,49740
45,30000;3,76453;7854,66582
45,36000;3,76961;7868,36967
45,42000;3,77445;7879,25050
45,48000;3,77953;7893,42225
45,54000;3,78450;7905,83342
45,60000;3,78946;7917,45558
45,66000;3,79448;7930,06048
45,72000;3,79944;7941,84059
45,78000;3,80452;7956,12857
45,84000;3,80955;7968,90259
45,90000;3,81463;7981,93067
45,96000;3,81965;7993,89333
46,02000;3,82455;8005,16009
46,08000;3,82952;8016,65410
46,14000;3,83454;8030,12550
46,20000;3,83956;8043,83308
46,26000;3,84458;8055,95592
46,32000;3,84943;8066,64824
46,38000;3,85463;8081,48533
46,44000;3,85959;8091,69263
46,50000;3,86461;8104,07177
46,56000;3,86964;8117,90153
46,62000;3,87466;8130,86107
46,68000;3,87956;8143,79230
46,74000;3,88458;8155,48971
46,80000;3,88961;8168,41871
46,86000;3,89463;8181,70309
46,92000;3,89953;8192,89833
46,98000;3,90461;8206,43827
47,04000;3,90952;8219,00740
47,10000;3,91466;8232,29998
47,16000;3,91950;8245,07624
47,22000;3,92458;8256,05318
47,28000;3,92954;8268,09406
47,34000;3,93451;8279,90398
47,40000;3,93953;8293,29938
47,46000;3,94443;8303,97978
47,52000;3,94951;8315,88954
47,58000;3,95454;8327,50127
47,64000;3,95944;8339,45945
47,70000;3,96452;8351,72832
47,76000;3,96942;8362,32603
47,82000;3,97451;8374,86386
47,88000;3,97953;8388,25628
47,94000;3,98455;8400,34038
48,00000;3,98957;8413,34984
48,06000;3,99448;8423,32691
48,12000;3,99962;8436,52263
48,18000;4,00446;8446,98399
48,24000;4,00960;8461,30252
48,30000;4,01451;8470,90855
48,36000;4,01935;8482,48824
48,42000;4,02455;8496,33142
48,48000;4,02957;8507,95656
48,54000;4,03459;8519,51838
48,60000;4,03962;8530,44540
48,66000;4,04440;8541,80008
48,72000;4,04960;8556,39875
48,78000;4,05450;8567,23487
48,84000;4,05959;8578,92781
48,90000;4,06449;8589,87868
48,96000;4,06963;8601,76161
49,02000;4,07453;8614,67645
49,08000;4,07950;8626,77544
49,14000;4,08452;8638,60697
49,20000;4,08954;8651,07253
49,26000;4,09462;8663,22517
49,32000;4,09959;8675,72576
49,38000;4,10461;8687,44031
49,44000;4,10951;8698,49697
49,50000;4,11453;8710,65110
49,56000;4,11950;8722,92295
49,62000;4,12458;8736,38168
49,68000;4,12954;8749,09386
49,74000;4,13456;8762,79175
49,80000;4,13953;8773,51388
49,86000;4,14461;8786,41531
49,92000;4,14951;8797,46154
49,98000;4,15453;8810,08357
50,04000;4,15944;8822,10732
50,10000;4,16452;8834,39109
50,16000;4,16948;8846,92371
50,22000;4,17450;8858,38643
50,28000;4,17946;8871,55160
50,34000;4,18449;8881,45193
50,40000;4,18951;8895,06340
50,46000;4,19447;8906,77869
50,52000;4,19949;8919,48268
50,58000;4,20452;8931,27993
50,64000;4,20948;8943,82000
50,70000;4,21450;8955,29911
50,76000;4,21946;8966,96374
50,82000;4,22449;8979,29296
50,88000;4,22951;8991,91573
50,94000;4,23453;9004,04379
51,00000;4,23955;9017,17171
51,06000;4,24446;9028,61506
51,12000;4,24960;9041,54703
51,18000;4,25456;9053,16621
51,24000;4,25958;9067,53615
51,30000;4,26455;9078,69339
51,36000;4,26957;9090,11066
51,42000;4,27453;9102,00402
51,48000;4,27949;9114,59550
51,54000;4,28452;9127,31662
51,60000;4,28954;9139,16975
51,66000;4,29450;9150,21673
51,72000;4,29958;9162,56383
51,78000;4,30448;9175,58968
51,84000;4,30957;9187,55531
51,90000;4,31453;9199,24900
51,96000;4,31955;9211,12299
52,02000;4,32457;9224,67932
52,08000;4,32954;9237,46079
52,14000;4,33456;9252,31129
52,20000;4,33952;9263,32921
52,26000;4,34454;9275,89610
52,32000;4,34951;9287,48250
52,38000;4,35453;9299,33861
52,44000;4,35949;9311,38247
52,50000;4,36451;9323,63719
52,56000;4,36948;9335,35174
52,62000;4,37450;9347,77111
52,68000;4,37946;9359,34484
52,74000;4,38448;9371,69641
52,80000;4,38945;9382,74860
52,86000;4,39453;9394,70306
52,92000;4,39943;9406,46380
52,98000;4,40451;9418,93607
53,04000;4,40947;9430,86222
53,10000;4,41456;9443,75992
53,16000;4,41952;9455,29267
53,22000;4,42460;9466,94985
53,28000;4,42956;9479,62627
53,34000;4,43453;9489,79184
53,40000;4,43955;9502,01973
53,46000;4,44451;9512,16221
53,52000;4,44947;9524,48249
53,58000;4,45456;9536,51294
53,64000;4,45958;9548,40258
53,70000;4,46460;9560,96873
53,76000;4,46956;9571,92853
53,82000;4,47459;9584,50213
53,88000;4,47967;9596,43275
53,94000;4,48457;9607,40075
54,00000;4,48965;9619,69942
54,06000;4,49450;9630,34183
54,12000;4,49958;9642,98993
54,18000;4,50448;9654,61284
54,24000;4,50962;9667,04935
54,30000;4,51458;9679,51864
54,36000;4,51955;9690,61479
54,42000;4,52463;9703,79710
54,48000;4,52965;9714,49688
54,54000;4,53461;9724,88597
54,60000;4,53958;9736,26822
54,66000;4,54448;9747,80768
54,72000;4,54950;9760,08102
54,78000;4,55446;9771,63613
54,84000;4,55949;9781,87695
54,90000;4,56451;9794,73814
54,96000;4,56947;9803,95079
55,02000;4,57461;9817,69860
55,08000;4,57940;9827,68983
55,14000;4,58466;9841,75950
55,20000;4,58950;9851,48177
55,26000;4,59464;9864,65365
55,32000;4,59955;9876,28326
55,38000;4,60451;9885,10028
55,44000;4,60953;9898,26322
55,50000;4,61449;9909,33850
55,56000;4,61958;9922,13935
55,62000;4,62454;9933,46572
55,68000;4,62950;9943,89132
55,74000;4,63458;9955,82789
55,80000;4,63948;9966,82048
55,86000;4,64457;9980,97137
55,92000;4,64953;9990,57814
55,98000;4,65455;10001,72719
56,04000;4,65951;10014,20841
56,10000;4,66442;10024,17356
56,16000;4,66956;10038,77446
56,22000;4,67464;10049,03018
56,28000;4,67960;10058,93871
56,34000;4,68457;10069,51854
56,40000;4,68959;10081,46927
56,46000;4,69455;10094,51598
56,52000;4,69957;10104,21440
56,58000;4,70454;10116,31414
56,64000;4,70956;10126,70621
56,70000;4,71458;10138,24567
56,76000;4,71960;10151,13592
56,82000;4,72451;10160,67266
56,88000;4,72959;10172,27247
56,94000;4,73419;10183,04750
57,00000;4,73963;10198,21018
57,06000;4,74454;10207,97864
57,12000;4,74956;10218,16507
57,18000;4,75452;10229,51156
57,24000;4,75948;10241,38927
57,30000;4,76456;10254,01503
57,36000;4,76953;10265,72213
57,42000;4,77455;10276,49641
57,48000;4,77951;10288,66395
57,54000;4,78447;10299,09104
57,60000;4,78956;10311,35023
57,66000;4,79446;10321,96954
57,72000;4,79960;10333,49782
57,78000;4,80456;10345,39565
57,84000;4,80959;10356,04551
57,90000;4,81455;10367,47321
57,96000;4,81951;10377,04945
58,02000;4,82453;10389,10225
58,08000;4,82944;10397,84774
58,14000;4,83452;10409,75377
58,20000;4,83942;10421,34836
58,26000;4,84450;10433,65821
58,32000;4,84947;10445,01588
58,38000;4,85455;10457,07241
58,44000;4,85951;10468,71617
58,50000;4,86447;10479,41893
58,56000;4,86950;10490,64100
58,62000;4,87446;10501,87498
58,68000;4,87942;10512,21713
58,74000;4,88444;10524,19692
58,80000;4,88941;10535,51286
58,86000;4,89455;10546,54494
58,92000;4,89939;10557,59341
58,98000;4,90453;10570,37190
59,04000;4,90955;10581,77799
59,10000;4,91452;10590,32530
59,16000;4,91960;10602,39226
59,22000;4,92450;10612,35443
59,28000;4,92958;10624,18967
59,34000;4,93455;10635,19418
59,40000;4,93957;10646,45275
59,46000;4,94453;10656,60790
59,52000;4,94955;10668,35299
59,58000;4,95452;10679,44616
59,64000;4,95954;10690,55051
59,70000;4,96456;10701,97374
59,76000;4,96958;10712,38220
59,82000;4,97455;10722,80779
59,88000;4,97957;10735,00887
59,94000;4,98453;10745,31153
60,00000;4,98955;10755,24166
60,06000;4,99446;10765,85352
60,12000;4,99954;10776,87591
60,18000;5,00456;10788,30361
60,24000;5,00958;10798,39915
60,30000;5,01454;10810,33722
60,36000;5,01957;10819,03353
60,42000;5,02453;10829,15142
60,48000;5,02961;10840,03374
60,54000;5,03451;10853,05065
60,60000;5,03954;10863,04113
60,66000;5,04450;10872,50710
60,72000;5,04952;10885,40480
60,78000;5,05454;10895,20156
60,84000;5,05951;10905,62493
60,90000;5,06453;10916,86860
60,96000;5,06949;10926,29880
61,02000;5,07463;10938,91487
61,08000;5,07954;10948,29738
61,14000;5,08444;10958,08670
61,20000;5,08952;10969,98677
61,26000;5,09454;10978,44616
61,32000;5,09957;10988,54318
61,38000;5,10447;10998,32132
61,44000;5,10955;11009,80192
61,50000;5,11451;11019,49736
61,56000;5,11953;11030,38639
61,62000;5,12462;11040,56984
61,68000;5,12952;11050,35320
61,74000;5,13460;11062,10500
61,80000;5,13950;11071,22749
61,86000;5,14459;11080,88568
61,92000;5,14961;11091,90881
61,98000;5,15451;11099,19846
62,04000;5,15959;11110,14262
62,10000;5,16444;11119,02073
62,16000;5,16958;11129,60577
62,22000;5,17454;11140,44636
62,28000;5,17956;11148,43935
62,34000;5,18453;11159,21512
62,40000;5,18955;11167,26995
62,46000;5,19457;11177,67468
62,52000;5,19959;11188,32678
62,58000;5,20456;11197,63181
62,64000;5,20958;11207,53810
62,70000;5,21454;11215,88126
62,76000;5,21962;11228,13821
62,82000;5,22453;11236,37930
62,88000;5,22961;11245,72232
62,94000;5,23451;11254,94018
63,00000;5,23959;11263,33848
63,06000;5,24461;11274,14256
63,12000;5,24958;11285,38698
63,18000;5,25454;11293,08492
63,24000;5,25950;11300,74039
63,30000;5,26446;11308,35339
63,36000;5,26955;11318,56814
63,42000;5,27451;11330,63585
63,48000;5,27953;11334,68971
63,54000;5,28449;11340,17855
63,60000;5,28952;11346,67397
63,66000;5,29460;11357,23814
63,72000;5,29956;11363,25821
63,78000;5,30452;11368,74780
63,84000;5,30949;11374,06006
63,90000;5,31451;11380,91907
63,96000;5,31947;11388,17221
64,02000;5,32461;11395,78298
64,08000;5,32952;11401,36942
64,14000;5,33454;11406,16238
64,20000;5,33950;11411,28242
64,26000;5,34458;11415,84516
64,32000;5,34955;11419,06753
64,38000;5,35451;11423,19441
64,44000;5,35953;11427,90839
64,50000;5,36455;11429,93346
64,56000;5,36951;11431,51820
64,62000;5,37460;11432,70656
64,68000;5,37944;11432,07625
64,74000;5,38458;11431,95108
64,80000;5,38954;11428,97606
64,86000;5,39457;11423,08488
64,92000;5,39953;11414,73949
64,98000;5,40449;11400,92015
65,04000;5,40963;11380,74175
65,10001;5,41460;11335,80357
65,16000;5,42093;3399,60568
65,16600;5,42165;2075,34991