File: SU - Suspension/05 - Essais/Excels essais Optimus/Test_Rotules_31_01_19/M7_1.is_tens_RawData/Specimen_RawData_1.csv
Temps;Déplacement;Charge
(sec);(mm);(N)
0,00000;0,46295;88,93838
0,02000;0,46301;89,47885
0,04000;0,46319;88,67040
0,06000;0,46361;89,77558
0,08000;0,46421;94,33605
0,10000;0,46504;101,72714
0,12000;0,46612;110,52064
0,14000;0,46725;119,71683
0,16000;0,46839;129,00371
0,18000;0,46953;138,46656
0,20000;0,47066;147,58343
0,22000;0,47186;157,10857
0,24000;0,47299;166,29535
0,26000;0,47419;174,91151
0,28000;0,47527;183,59934
0,30000;0,47640;191,86019
0,32000;0,47760;200,22325
0,34000;0,47867;208,60974
0,36000;0,47981;216,59532
0,38000;0,48089;223,53104
0,40000;0,48196;230,30292
0,42000;0,48304;236,52143
0,44000;0,48412;243,31457
0,46000;0,48507;249,20595
0,48000;0,48603;254,37544
0,50000;0,48705;259,51262
0,52000;0,48806;264,53806
0,54000;0,48914;268,53459
0,56000;0,49015;271,54149
0,58000;0,49117;273,57815
0,60000;0,49213;273,67461
0,62000;0,49314;272,13641
0,64000;0,49422;268,16584
0,66000;0,49518;262,18612
0,68000;0,49613;255,99550
0,70000;0,49709;251,04943
0,72000;0,49811;248,28571
0,74000;0,49918;246,30071
0,76000;0,50020;245,12676
0,78000;0,50122;242,28198
0,80000;0,50223;238,87700
0,82000;0,50325;236,18813
0,84000;0,50426;232,81786
0,86000;0,50534;229,85653
0,88000;0,50630;227,74634
0,90000;0,50719;225,27438
0,92000;0,50821;222,39459
0,94000;0,50923;220,18328
0,96000;0,51018;218,70816
0,98000;0,51132;216,61911
1,00000;0,51228;214,49313
1,02000;0,51323;211,40261
1,04000;0,51425;207,93362
1,06000;0,51533;205,78569
1,08000;0,51628;204,27550
1,10000;0,51724;201,98387
1,12000;0,51820;199,91416
1,14000;0,51921;198,84189
1,16000;0,52029;197,01461
1,18000;0,52124;195,60920
1,20000;0,52226;193,76224
1,22000;0,52334;192,67311
1,24000;0,52435;190,66300
1,26000;0,52537;188,02657
1,28000;0,52639;185,89026
1,30000;0,52734;183,81351
1,32000;0,52824;181,76520
1,34000;0,52932;180,17403
1,36000;0,53033;179,09210
1,38000;0,53135;177,89842
1,40000;0,53231;175,43661
1,42000;0,53332;173,84783
1,44000;0,53428;172,01070
1,46000;0,53536;170,41503
1,48000;0,53637;169,64012
1,50000;0,53733;167,95341
1,52000;0,53828;164,49275
1,54000;0,53924;162,09111
1,56000;0,54032;161,27026
1,58000;0,54133;160,20468
1,60000;0,54229;158,08615
1,62000;0,54331;155,43038
1,64000;0,54432;152,83014
1,66000;0,54528;151,47224
1,68000;0,54630;150,41626
1,70000;0,54743;149,81178
1,72000;0,54833;147,50439
1,74000;0,54929;144,31098
1,76000;0,55030;142,49615
1,78000;0,55132;142,31977
1,80000;0,55234;141,83217
1,82000;0,55329;141,06455
1,84000;0,55431;140,03178
1,86000;0,55532;138,41206
1,88000;0,55634;136,99859
1,90000;0,55736;135,82386
1,92000;0,55825;135,86999
1,94000;0,55921;135,04864
1,96000;0,56017;133,59580
1,98000;0,56124;133,44279
2,00000;0,56226;134,25375
2,02000;0,56328;133,09460
2,04000;0,56429;132,44419
2,06000;0,56531;131,93382
2,08000;0,56633;130,67067
2,10000;0,56734;130,39113
2,12000;0,56830;130,35240
2,14000;0,56926;129,15599
2,16000;0,57027;128,94607
2,18000;0,57129;128,60204
2,20000;0,57230;128,28774
2,22000;0,57332;127,93299
2,24000;0,57440;127,93699
2,26000;0,57541;127,62441
2,28000;0,57637;125,86357
2,30000;0,57739;124,66460
2,32000;0,57840;123,87641
2,34000;0,57930;123,30319
2,36000;0,58020;121,77841
2,38000;0,58121;120,96314
2,40000;0,58223;120,88494
2,42000;0,58325;121,36735
2,44000;0,58420;120,62440
2,46000;0,58522;119,84708
2,48000;0,58624;119,30718
2,50000;0,58725;118,39962
2,52000;0,58827;116,91774
2,54000;0,58923;116,30245
2,56000;0,59018;115,72314
2,58000;0,59120;115,43008
2,60000;0,59221;115,04747
2,62000;0,59329;115,13478
2,64000;0,59425;114,32650
2,66000;0,59526;113,33349
2,68000;0,59628;113,24995
2,70000;0,59730;113,29623
2,72000;0,59831;112,50402
2,74000;0,59927;110,13171
2,76000;0,60029;109,60700
2,78000;0,60130;110,09146
2,80000;0,60232;109,03460
2,82000;0,60334;108,20292
2,84000;0,60429;107,67919
2,86000;0,60525;106,90099
2,88000;0,60627;106,47479
2,90000;0,60728;105,95390
2,92000;0,60830;105,11235
2,94000;0,60931;104,62949
2,96000;0,61027;104,30736
2,98000;0,61123;103,30044
3,00000;0,61218;102,40555
3,02000;0,61320;101,61177
3,04000;0,61422;101,18304
3,06000;0,61523;101,74736
3,08000;0,61625;102,26370
3,10000;0,61727;101,81102
3,12000;0,61828;101,10822
3,14000;0,61930;100,57827
3,16000;0,62032;99,62423
3,18000;0,62133;99,42362
3,20000;0,62229;98,95596
3,22000;0,62325;97,74485
3,24000;0,62432;97,80508
3,26000;0,62528;97,99242
3,28000;0,62629;98,02352
3,30000;0,62731;97,95178
3,32000;0,62833;97,77830
3,34000;0,62928;96,87000
3,36000;0,63030;96,34044
3,38000;0,63132;96,83038
3,40000;0,63227;96,25671
3,42000;0,63323;95,06078
3,44000;0,63425;94,88020
3,46000;0,63526;94,84617
3,48000;0,63598;94,69541
3,50000;0,63730;94,31005
3,52000;0,63831;94,83412
3,54000;0,63933;93,82040
3,56000;0,64035;92,73313
3,58000;0,64136;91,63885
3,60000;0,64226;91,20723
3,62000;0,64322;90,82187
3,64000;0,64429;90,33550
3,66000;0,64531;90,72605
3,68000;0,64632;90,90306
3,70000;0,64734;90,15374
3,72000;0,64836;89,39067
3,74000;0,64931;88,89025
3,76000;0,65033;88,39751
3,78000;0,65135;87,95109
3,80000;0,65230;87,50404
3,82000;0,65320;86,61572
3,84000;0,65416;85,62990
3,86000;0,65523;85,57550
3,88000;0,65625;85,60655
3,90000;0,65715;85,01054
3,92000;0,65828;84,28620
3,94000;0,65930;84,45499
3,96000;0,66032;83,82926
3,98000;0,66133;82,39277
4,00000;0,66235;81,50327
4,02000;0,66324;81,07546
4,04000;0,66420;80,66024
4,06000;0,66522;79,64916
4,08000;0,66623;79,32892
4,10000;0,66725;79,85471
4,12000;0,66827;79,44477
4,14000;0,66928;78,87722
4,16000;0,67030;78,69003
4,18000;0,67132;77,73398
4,20000;0,67233;77,75518
4,22000;0,67335;77,94762
4,24000;0,67425;76,80830
4,26000;0,67520;75,70986
4,28000;0,67598;75,66364
4,30000;0,67724;75,78679
4,32000;0,67831;76,30381
4,34000;0,67933;76,07010
4,36000;0,68028;74,92754
4,38000;0,68130;73,85687
4,40000;0,68232;73,88038
4,42000;0,68327;73,86353
4,44000;0,68423;73,71781
4,46000;0,68519;73,30930
4,48000;0,68626;73,62238
4,50000;0,68728;73,90784
4,52000;0,68830;74,02370
4,54000;0,68925;74,06145
4,56000;0,69027;73,86172
4,58000;0,69123;73,98947
4,60000;0,69230;73,82573
4,62000;0,69332;73,37070
4,64000;0,69428;73,22909
4,66000;0,69523;72,49310
4,68000;0,69625;72,41304
4,70000;0,69726;72,66633
4,72000;0,69828;72,60439
4,74000;0,69930;72,17987
4,76000;0,70031;71,65751
4,78000;0,70121;71,43109
4,80000;0,70211;71,87114
4,82000;0,70330;71,89802
4,84000;0,70438;71,85312
4,86000;0,70522;71,24777
4,88000;0,70623;69,94476
4,90000;0,70725;69,35757
4,92000;0,70827;70,00112
4,94000;0,70928;69,79174
4,96000;0,71030;68,86934
4,98000;0,71126;68,55135
5,00000;0,71227;68,81381
5,02000;0,71329;68,86155
5,04000;0,71436;68,70691
5,06000;0,71526;68,46836
5,08000;0,71622;67,58263
5,10000;0,71723;66,67418
5,12000;0,71831;67,07594
5,14000;0,71933;66,62321
5,16000;0,72028;66,14511
5,18000;0,72130;65,72896
5,20000;0,72232;65,55146
5,22000;0,72327;64,80430
5,24000;0,72429;64,39436
5,26000;0,72531;64,13573
5,28000;0,72620;63,75806
5,30000;0,72722;63,70126
5,32000;0,72824;63,71022
5,34000;0,72931;63,16210
5,36000;0,73027;62,51381
5,38000;0,73129;61,62465
5,40000;0,73230;60,73608
5,42000;0,73326;60,72046
5,44000;0,73433;60,35557
5,46000;0,73529;60,67203
5,48000;0,73625;60,69422
5,50000;0,73720;58,86566
5,52000;0,73816;58,34159
5,54000;0,73924;59,02901
5,56000;0,74025;59,57022
5,58000;0,74127;59,46308
5,60000;0,74229;59,00369
5,62000;0,74330;58,50195
5,64000;0,74432;58,29252
5,66000;0,74534;58,04417
5,68000;0,74629;58,03555
5,70000;0,74719;57,41057
5,72000;0,74815;56,98128
5,74000;0,74922;56,99930
5,76000;0,75024;57,45179
5,78000;0,75125;57,27248
5,80000;0,75227;56,83772
5,82000;0,75329;56,56459
5,84000;0,75430;56,48522
5,86000;0,75538;56,38029
5,88000;0,75634;56,64269
5,90000;0,75729;56,74714
5,92000;0,75825;55,86272
5,94000;0,75927;55,37107
5,96000;0,76028;55,49490
5,98000;0,76130;55,72352
6,00000;0,76232;55,92550
6,02000;0,76333;55,69845
6,04000;0,76435;56,00810
6,06000;0,76543;55,92800
6,08000;0,76638;55,53745
6,10000;0,76734;55,41073
6,12000;0,76829;54,82853
6,12200;0,76835;54,74671