File: SU - Suspension/05 - Essais/Excels essais Optimus/Test_Rotules_31_01_19/M7_3.is_tens_RawData/Specimen_RawData_1.csv
Temps;Déplacement;Charge
(sec);(mm);(N)
0,00000;9,14576;86,24475
0,04000;9,14588;86,06819
0,08000;9,14660;89,46573
0,12000;9,14779;98,91370
0,16000;9,14929;111,38692
0,20000;9,15072;123,32032
0,24000;9,15228;133,95672
0,28000;9,15383;145,20102
0,32000;9,15533;155,51239
0,36000;9,15682;165,66591
0,40000;9,15826;175,77916
0,44000;9,15969;184,91478
0,48000;9,16101;194,18183
0,52000;9,16232;202,94080
0,56000;9,16376;211,33451
0,60000;9,16513;220,86126
0,64000;9,16645;229,24517
0,68000;9,16782;237,54309
0,72000;9,16920;245,90378
0,76000;9,17051;254,63132
0,80000;9,17171;262,93211
0,84000;9,17314;270,22439
0,88000;9,17452;278,37853
0,92000;9,17583;286,91168
0,96000;9,17721;295,31969
1,00000;9,17858;305,07892
1,04000;9,17996;313,27913
1,08000;9,18121;320,65434
1,12000;9,18247;327,02226
1,16000;9,18385;333,76906
1,20000;9,18516;340,32373
1,24000;9,18654;345,46782
1,28000;9,18791;349,62927
1,32000;9,18923;353,33231
1,36000;9,19060;356,93008
1,40000;9,19180;360,41208
1,44000;9,19311;361,92392
1,48000;9,19455;365,97010
1,52000;9,19592;369,05101
1,56000;9,19724;371,84572
1,60000;9,19861;375,24283
1,64000;9,19993;377,25265
1,68000;9,20124;379,62277
1,72000;9,20244;382,10403
1,76000;9,20376;384,15585
1,80000;9,20525;387,17494
1,84000;9,20657;390,56402
1,88000;9,20788;393,04751
1,92000;9,20920;395,55463
1,96000;9,21057;397,57858
2,00000;9,21189;400,38209
2,04000;9,21314;403,02938
2,08000;9,21446;405,17189
2,12000;9,21583;408,84134
2,16000;9,21715;411,60090
2,20000;9,21852;413,65703
2,24000;9,21990;417,02027
2,28000;9,22121;419,70746
2,32000;9,22259;422,05458
2,36000;9,22384;424,28640
2,40000;9,22510;426,96940
2,44000;9,22653;431,06228
2,48000;9,22791;434,12396
2,52000;9,22923;436,84603
2,56000;9,23054;439,96875
2,60000;9,23192;442,05259
2,64000;9,23329;445,62332
2,68000;9,23443;448,27363
2,72000;9,23580;449,70545
2,76000;9,23718;454,13454
2,80000;9,23855;456,85838
2,84000;9,23987;459,66594
2,88000;9,24118;462,44529
2,92000;9,24256;465,37509
2,96000;9,24393;468,48301
3,00000;9,24513;470,43008
3,04000;9,24651;473,19257
3,08000;9,24782;475,74211
3,12000;9,24920;478,25412
3,16000;9,25051;480,69297
3,20000;9,25189;482,53611
3,24000;9,25326;485,22763
3,28000;9,25452;487,16515
3,32000;9,25577;486,69176
3,36000;9,25715;488,75241
3,40000;9,25852;489,56024
3,44000;9,25990;489,86911
3,48000;9,26115;490,44043
3,52000;9,26259;491,73781
3,56000;9,26396;490,48932
3,60000;9,26516;488,62658
3,64000;9,26641;486,71477
3,68000;9,26785;486,21898
3,72000;9,26922;485,08034
3,76000;9,27054;481,99873
3,80000;9,27186;479,97334
3,84000;9,27323;478,12373
3,88000;9,27461;476,78649
3,92000;9,27580;474,45334
3,96000;9,27712;472,12355
4,00000;9,27861;471,23688
4,04000;9,27993;469,39338
4,08000;9,28124;466,92700
4,12000;9,28256;464,90110
4,16000;9,28393;462,10969
4,20000;9,28531;460,70139
4,24000;9,28650;458,16544
4,28000;9,28788;454,71694
4,32000;9,28925;454,64966
4,36000;9,29057;453,43973
4,40000;9,29188;450,47305
4,44000;9,29326;447,40560
4,48000;9,29458;445,03878
4,52000;9,29595;443,58727
4,56000;9,29709;440,34421
4,60000;9,29846;437,70303
4,64000;9,29990;439,09568
4,68000;9,30103;437,29241
4,72000;9,30259;435,88211
4,76000;9,30396;434,60522
4,80000;9,30534;430,80426
4,84000;9,30659;427,65285
4,88000;9,30779;424,82023
4,92000;9,30922;423,92788
4,96000;9,31054;422,61365
5,00000;9,31191;420,97527
5,04000;9,31323;418,71886
5,08000;9,31461;416,33006
5,12000;9,31598;415,25499
5,16000;9,31724;411,75717
5,20000;9,31843;408,03808
5,24000;9,31987;406,42666
5,28000;9,32118;405,01500
5,32000;9,32244;403,47865
5,36000;9,32393;403,38975
5,40000;9,32525;402,44297
5,44000;9,32662;398,79857
5,48000;9,32788;395,52194
5,52000;9,32913;392,66460
5,56000;9,33057;392,12764
5,60000;9,33188;391,53234
5,64000;9,33326;390,76749
5,68000;9,33463;388,57320
5,72000;9,33595;387,25887
5,76000;9,33732;386,53107
5,80000;9,33858;383,77589
5,84000;9,33984;380,82299
5,88000;9,34121;380,59051
5,92000;9,34253;378,29278
5,96000;9,34384;376,21881
6,00000;9,34522;375,70174
6,04000;9,34653;375,17075
6,08000;9,34791;373,60876
6,12000;9,34916;371,55300
6,16000;9,35042;369,25420
6,20000;9,35185;370,82725
6,24000;9,35323;370,06487
6,28000;9,35454;367,33632
6,32000;9,35592;367,00142
6,36000;9,35723;365,59298
6,40000;9,35861;364,56422
6,44000;9,35969;363,01457
6,48000;9,36130;363,90105
6,52000;9,36262;362,95650
6,56000;9,36393;360,16931
6,60000;9,36525;358,88446
6,64000;9,36662;357,20975
6,68000;9,36794;355,95449
6,72000;9,36919;355,07036
6,76000;9,37045;352,73915
6,80000;9,37188;354,04230
6,84000;9,37320;354,30288
6,88000;9,37457;353,68721
6,92000;9,37589;353,41661
6,96000;9,37726;352,48208
7,00000;9,37864;352,65277
7,04000;9,37989;352,18475
7,08000;9,38115;350,59946
7,12000;9,38253;351,42512
7,16000;9,38384;351,38789
7,20000;9,38522;350,40381
7,24000;9,38653;349,49207
7,28000;9,38797;352,10866
7,32000;9,38928;349,89035
7,36000;9,39048;346,90651
7,40000;9,39179;345,68277
7,44000;9,39317;347,35326
7,48000;9,39448;347,81483
7,52000;9,39586;347,63745
7,56000;9,39717;347,46041
7,60000;9,39861;347,54090
7,64000;9,39992;346,74807
7,68000;9,40112;344,31529
7,72000;9,40249;343,69645
7,76000;9,40387;344,43729
7,80000;9,40519;343,34126
7,84000;9,40656;343,12014
7,88000;9,40788;342,89323
7,92000;9,40931;342,01432
7,96000;9,41063;342,07513
8,00000;9,41182;339,40985
8,04000;9,41320;338,67597
8,08000;9,41457;339,65027
8,12000;9,41589;337,20280
8,16000;9,41726;336,71001
8,20000;9,41852;335,35799
8,24000;9,41995;335,42360
8,28000;9,42121;335,06567
8,32000;9,42247;331,79128
8,36000;9,42390;331,69079
8,40000;9,42527;332,75764
8,44000;9,42659;330,45844
8,48000;9,42791;328,02576
8,52000;9,42922;327,70121
8,56000;9,43060;327,77789
8,60000;9,43185;326,45368
8,64000;9,43305;323,98035
8,68000;9,43454;325,53999
8,72000;9,43586;324,87465
8,76000;9,43723;323,72584
8,80000;9,43849;322,81058
8,84000;9,43986;322,38527
8,88000;9,44124;322,68160
8,92000;9,44243;321,68692
8,96000;9,44375;320,62104
9,00000;9,44518;321,26592
9,04000;9,44650;321,99353
9,08000;9,44788;320,66591
9,12000;9,44919;320,18605
9,16000;9,45057;317,90377
9,20000;9,45194;318,07595
9,24000;9,45314;316,64812
9,28000;9,45445;315,36513
9,32000;9,45589;317,41755
9,36000;9,45720;315,29667
9,40000;9,45858;313,94446
9,44000;9,45989;312,80317
9,48000;9,46127;311,40649
9,52000;9,46258;311,94540
9,56000;9,46378;309,93833
9,60000;9,46515;309,16331
9,64000;9,46653;310,90265
9,68000;9,46791;310,08739
9,72000;9,46928;311,01743
9,76000;9,47060;311,27625
9,80000;9,47197;309,85293
9,84000;9,47329;309,66159
9,88000;9,47442;307,82372
9,92000;9,47580;306,35810
9,96000;9,47723;309,18799
10,00000;9,47861;311,26684
10,04000;9,47992;307,89806
10,08000;9,48124;306,65111
10,12000;9,48261;306,43262
10,16000;9,48387;305,87011
10,20000;9,48512;303,56024
10,24000;9,48650;303,58688
10,28000;9,48787;304,77759
10,32000;9,48919;304,51545
10,36000;9,49057;303,69605
10,40000;9,49188;303,49570
10,44000;9,49326;303,43723
10,48000;9,49451;303,59873
10,52000;9,49577;300,46308
10,56000;9,49726;302,09520
10,60000;9,49858;305,31876
10,64000;9,49989;301,09836
10,68000;9,50121;300,62760
10,72000;9,50258;299,70207
10,76000;9,50396;300,17556
10,80000;9,50515;299,30654
10,84000;9,50647;297,70930
10,88000;9,50790;299,90654
10,92000;9,50922;300,09986
10,96000;9,51054;299,37704
11,00000;9,51185;298,91843
11,04000;9,51323;297,54387
11,08000;9,51460;298,20343
11,12000;9,51580;296,99497
11,16000;9,51717;296,42326
11,20000;9,51861;297,09379
11,24000;9,51992;296,83604
11,28000;9,52124;295,36856
11,32000;9,52261;295,23489
11,36000;9,52399;294,94520
11,40000;9,52530;293,99341
11,44000;9,52650;291,75573
11,48000;9,52787;292,96651
11,52000;9,52925;295,52055
11,56000;9,53057;290,96326
11,60000;9,53188;289,37543
11,64000;9,53326;289,10483
11,68000;9,53463;289,38551
11,72000;9,53589;288,03269
11,76000;9,53708;285,92495
11,80000;9,53852;286,16586
11,84000;9,53989;288,48415
11,88000;9,54121;286,65434
11,92000;9,54258;285,30161
11,96000;9,54390;284,92440
12,00000;9,54527;284,52543
12,04000;9,54653;283,31452
12,08000;9,54778;282,12280
12,12000;9,54916;282,35470
12,16000;9,55053;283,82738
12,20000;9,55191;283,09408
12,24000;9,55322;283,18760
12,28000;9,55460;280,38924
12,32000;9,55592;280,33988
12,36000;9,55711;278,01795
12,40000;9,55843;276,23014
12,44000;9,55992;277,46239
12,48000;9,56124;278,38736
12,52000;9,56261;277,07841
12,56000;9,56393;277,18605
12,60000;9,56530;277,81799
12,64000;9,56668;277,16784
12,68000;9,56781;276,21556
12,72000;9,56913;274,37888
12,76000;9,57056;276,27491
12,80000;9,57188;276,26236
12,84000;9,57319;276,31447
12,88000;9,57457;276,51521
12,92000;9,57588;276,23386
12,96000;9,57714;275,49732
13,00000;9,57852;276,15612
13,04000;9,57989;274,65709
13,08000;9,58127;273,79140
13,12000;9,58252;272,57421
13,16000;9,58390;273,30848
13,20000;9,58521;273,06641
13,24000;9,58659;273,29565
13,28000;9,58790;273,54597
13,32000;9,58916;272,83833
13,36000;9,59053;271,83474
13,40000;9,59191;272,70271
13,44000;9,59322;272,18631
13,48000;9,59460;270,79696
13,52000;9,59591;270,62932
13,56000;9,59729;269,93803
13,60000;9,59855;269,14990
13,64000;9,59980;267,08297
13,68000;9,60118;267,73587
13,72000;9,60261;269,09553
13,76000;9,60393;268,24002
13,80000;9,60524;266,29071
13,84000;9,60662;265,29240
13,88000;9,60799;265,20223
13,92000;9,60919;264,24788
13,96000;9,61044;263,03150
14,00000;9,61188;263,56727
14,04000;9,61319;263,06715
14,08000;9,61457;262,57711
14,12000;9,61594;261,64108
14,16000;9,61726;260,14559
14,20000;9,61863;260,31237
14,24000;9,61983;259,81714
14,28000;9,62109;257,24596
14,32000;9,62252;258,15095
14,36000;9,62384;258,90032
14,40000;9,62521;257,91680
14,44000;9,62653;257,98671
14,48000;9,62796;258,99922
14,52000;9,62928;256,36412
14,56000;9,63047;253,29976
14,60000;9,63179;252,93292
14,64000;9,63322;255,25163
14,68000;9,63454;255,52073
14,72000;9,63591;254,93943
14,76000;9,63723;254,78185
14,80000;9,63860;254,69705
14,84000;9,63992;255,20921
14,88000;9,64112;253,81243
14,92000;9,64249;253,02938
14,96000;9,64387;254,39453
15,00000;9,64518;254,24871
15,04000;9,64650;253,81274
15,08000;9,64781;254,10457
15,12000;9,64919;253,68209
15,16000;9,65050;253,86326
15,20000;9,65170;252,54376
15,24000;9,65313;252,16271
15,28000;9,65451;253,58680
15,32000;9,65582;253,40819
15,36000;9,65714;252,75538
15,40000;9,65857;254,01085
15,44000;9,65995;253,78491
15,48000;9,66120;252,49850
15,52000;9,66246;250,46626
15,56000;9,66384;249,71708
15,60000;9,66521;250,49751
15,64000;9,66653;250,34689
15,68000;9,66790;249,15126
15,72000;9,66922;248,66327
15,76000;9,67059;248,81917
15,80000;9,67179;248,06520
15,84000;9,67310;245,76758
15,88000;9,67454;246,82502
15,92000;9,67585;246,72102
15,96000;9,67723;246,43035
16,00000;9,67854;246,56383
16,04000;9,67986;244,96131
16,08000;9,68123;244,94103
16,12000;9,68249;244,70405
16,16000;9,68380;242,65593
16,20000;9,68524;243,26711
16,24000;9,68656;243,64227
16,28000;9,68793;242,36771
16,32000;9,68925;242,62820
16,36000;9,69062;242,02536
16,40000;9,69194;242,56378
16,44000;9,69313;242,37183
16,48000;9,69445;240,50665
16,52000;9,69588;242,42648
16,56000;9,69726;242,33081
16,60000;9,69857;241,60955
16,64000;9,69989;240,60321
16,68000;9,70126;240,77380
16,72000;9,70258;240,78684
16,76000;9,70378;239,73251
16,80000;9,70509;239,40131
16,84000;9,70653;241,52757
16,88000;9,70790;241,44060
16,92000;9,70922;241,12950
16,96000;9,71059;240,45974
17,00000;9,71197;241,00570
17,04000;9,71328;240,03033
17,08000;9,71442;238,98287
17,12000;9,71579;238,22507
17,16000;9,71717;239,99398
17,20000;9,71854;240,83296
17,24000;9,71986;239,91859
17,28000;9,72117;238,59467
17,32000;9,72261;239,49454
17,36000;9,72386;239,20231
17,40000;9,72506;236,21144
17,44000;9,72649;236,93475
17,48000;9,72787;238,79542
17,52000;9,72924;237,42497
17,56000;9,73056;237,33615
17,60000;9,73194;236,55486
17,64000;9,73331;235,80051
17,68000;9,73451;234,55445
17,72000;9,73576;233,20301
17,76000;9,73726;234,01487
17,80000;9,73857;234,06704
17,84000;9,73989;232,52533
17,88000;9,74120;231,99699
17,92000;9,74258;232,47991
17,96000;9,74395;231,88242
18,00000;9,74515;230,90870
18,04000;9,74652;228,50099
18,08000;9,74790;229,99640
18,12000;9,74921;228,86372
18,16000;9,75053;227,37773
18,20000;9,75185;228,07999
18,24000;9,75322;229,44121
18,28000;9,75460;229,31793
18,32000;9,75579;228,17391
18,36000;9,75717;227,45354
18,40000;9,75854;227,62304
18,44000;9,75986;227,06680
18,48000;9,76123;226,30568
18,52000;9,76261;225,90065
18,56000;9,76392;225,28321
18,60000;9,76524;226,49607
18,64000;9,76649;226,14351
18,68000;9,76781;225,03729
18,72000;9,76918;226,02610
18,76000;9,77056;226,57078
18,80000;9,77193;225,98840
18,84000;9,77325;225,36458
18,88000;9,77457;225,44959
18,92000;9,77594;225,09370
18,96000;9,77714;224,28029
19,00000;9,77851;223,67008
19,04000;9,77989;224,01793
19,08000;9,78120;224,69915
19,12000;9,78258;224,23104
19,16000;9,78395;223,25213
19,20000;9,78533;223,59458
19,24000;9,78658;223,72571
19,28000;9,78784;222,37722
19,32000;9,78915;221,89550
19,36000;9,79053;223,49705
19,40000;9,79190;223,16310
19,44000;9,79328;222,36947
19,48000;9,79459;222,70794
19,52000;9,79597;221,73342
19,56000;9,79729;221,35579
19,60000;9,79848;220,20983
19,64000;9,79986;220,61055
19,68000;9,80123;220,38855
19,72000;9,80255;219,72263
19,76000;9,80392;218,92507
19,80000;9,80524;217,92541
19,84000;9,80661;217,55984
19,88000;9,80787;216,46712
19,92000;9,80918;214,63758
19,96000;9,81056;214,95174
20,00000;9,81187;215,08543
20,04000;9,81325;213,76542
20,08000;9,81456;214,26545
20,12000;9,81594;213,89166
20,16000;9,81725;214,38482
20,20000;9,81851;213,00842
20,24000;9,81983;211,40815
20,28000;9,82120;212,82805
20,32000;9,82252;211,77421
20,36000;9,82383;211,24471
20,40000;9,82521;212,23791
20,44000;9,82658;211,03602
20,48000;9,82790;211,09281
20,52000;9,82915;210,20223
20,56000;9,83047;209,27414
20,60000;9,83184;210,58670
20,64000;9,83316;210,86414
20,68000;9,83453;210,07562
20,72000;9,83585;210,49739
20,76000;9,83723;210,27792
20,80000;9,83860;210,21389
20,84000;9,83980;208,98427
20,88000;9,84117;208,79342
20,92000;9,84255;210,11126
20,96000;9,84386;209,50644
21,00000;9,84518;209,51123
21,04000;9,84655;209,50134
21,08000;9,84793;208,54115
21,12000;9,84918;208,87675
21,16000;9,85044;207,83585
21,20000;9,85187;207,74819
21,24000;9,85325;208,59588
21,28000;9,85456;207,23415
21,32000;9,85594;207,24514
21,36000;9,85725;207,16493
21,40000;9,85863;207,15867
21,44000;9,85989;206,73187
21,48000;9,86108;204,88189
21,52000;9,86258;204,95718
21,56000;9,86389;206,86556
21,60000;9,86527;206,07046
21,64000;9,86658;205,20720
21,68000;9,86790;204,43031
21,72000;9,86927;204,09981
21,76000;9,87047;203,78211
21,80000;9,87172;203,28062
21,84000;9,87316;203,46630
21,88000;9,87447;203,95243
21,92000;9,87585;203,51340
21,96000;9,87722;202,39328
22,00000;9,87854;201,96296
22,04000;9,87991;201,44379
22,08000;9,88111;200,17815
22,12000;9,88237;198,94191
22,16000;9,88380;200,23372
22,20000;9,88518;199,79586
22,24000;9,88655;198,08991
22,28000;9,88787;198,35474
22,32000;9,88924;197,09398
22,36000;9,89062;197,04609
22,40000;9,89181;195,94976
22,44000;9,89313;195,52396
22,48000;9,89450;196,11912
22,52000;9,89582;197,21789
22,56000;9,89719;197,35852
22,60000;9,89851;195,97546
22,64000;9,89988;194,71222
22,68000;9,90126;194,94563
22,72000;9,90245;194,02646
22,76000;9,90383;194,24587
22,80000;9,90520;195,33916
22,84000;9,90658;194,61620
22,88000;9,90796;194,54000
22,92000;9,90927;194,22751
22,96000;9,91065;193,66025
23,00000;9,91190;194,35824
23,04000;9,91310;192,25088
23,08000;9,91447;191,40438
23,12000;9,91585;193,29257
23,16000;9,91722;192,19477
23,20000;9,91854;192,60661
23,24000;9,91985;191,72054
23,28000;9,92123;192,29691
23,32000;9,92248;191,39193
23,36000;9,92374;190,29536
23,40000;9,92512;190,86208
23,44000;9,92649;191,45153
23,48000;9,92787;190,96786
23,52000;9,92918;189,53180
23,56000;9,93050;188,96440
23,60000;9,93193;190,68576
23,64000;9,93319;190,44069
23,68000;9,93444;189,23106
23,72000;9,93594;190,15528
23,76000;9,93725;190,06151
23,80000;9,93857;188,63506
23,84000;9,93988;188,48615
23,88000;9,94126;188,58678
23,92000;9,94263;189,59693
23,96000;9,94383;188,15441
24,00000;9,94514;186,59537
24,04000;9,94658;187,14294
24,08000;9,94790;187,13129
24,12000;9,94927;186,81007
24,16000;9,95059;185,76834
24,20000;9,95196;184,49589
24,24000;9,95328;184,64773
24,28000;9,95441;183,14666
24,32000;9,95579;182,31968
24,36000;9,95722;183,48104
24,40000;9,95860;182,72521
24,44000;9,95991;181,73376
24,48000;9,96129;181,49569
24,52000;9,96266;180,99606
24,56000;9,96398;180,21452
24,60000;9,96517;178,74101
24,64000;9,96649;178,93085
24,68000;9,96792;180,62245
24,72000;9,96918;179,64510
24,76000;9,97055;179,71983
24,80000;9,97193;179,63203
24,84000;9,97331;179,24496
24,88000;9,97456;177,69546
24,92000;9,97576;176,58753
24,96000;9,97719;176,08186
25,00000;9,97851;177,24131
25,04000;9,97988;176,52902
25,08000;9,98120;176,20208
25,12000;9,98257;175,31849
25,16000;9,98395;174,75965
25,20000;9,98520;175,10398
25,24000;9,98646;173,20394
25,28000;9,98789;173,35225
25,32000;9,98921;174,31226
25,36000;9,99053;173,57984
25,40000;9,99190;173,82384
25,44000;9,99322;173,39060
25,48000;9,99465;174,34224
25,52000;9,99585;173,83270
25,56000;9,99716;172,05189
25,60000;9,99860;173,44254
25,64000;9,99991;173,59693
25,68000;10,00123;172,59931
25,72000;10,00260;172,59314
25,76000;10,00398;170,92706
25,80000;10,00529;171,07542
25,84000;10,00649;170,52897
25,88000;10,00780;169,89115
25,92000;10,00924;170,31773
25,96000;10,01055;169,81360
26,00000;10,01187;168,86597
26,04000;10,01325;168,87111
26,08000;10,01456;168,18218
26,12000;10,01588;168,13247
26,16000;10,01713;167,17525
26,20000;10,01851;166,37536
26,24000;10,01988;166,50805
26,28000;10,02126;165,76031
26,32000;10,02257;164,43816
26,36000;10,02395;163,89326
26,40000;10,02526;163,08392
26,44000;10,02658;163,16682
26,48000;10,02783;161,75384
26,52000;10,02921;161,71520
26,56000;10,03052;162,29382
26,60000;10,03190;161,69635
26,64000;10,03321;161,84722
26,68000;10,03459;161,83859
26,72000;10,03596;161,17321
26,76000;10,03722;160,93263
26,80000;10,03842;158,56924
26,84000;10,03985;159,82329
26,88000;10,04117;160,70848
26,92000;10,04254;159,96406
26,96000;10,04392;159,34975
27,00000;10,04529;159,39318
27,04000;10,04667;158,51406
27,08000;10,04786;157,63298
27,12000;10,04912;156,17118
27,16000;10,05049;155,69224
27,20000;10,05187;156,59658
27,24000;10,05318;156,88592
27,28000;10,05456;156,57552
27,32000;10,05588;156,58096
27,36000;10,05725;154,70692
27,40000;10,05850;154,35907
27,44000;10,05976;152,74156
27,48000;10,06114;153,91158
27,52000;10,06245;154,23548
27,56000;10,06383;153,03663
27,60000;10,06520;153,50507
27,64000;10,06658;153,91369
27,68000;10,06795;153,68767
27,72000;10,06915;152,46589
27,76000;10,07046;151,85489
27,80000;10,07190;152,44733
27,84000;10,07321;150,82437
27,88000;10,07459;150,27259
27,92000;10,07590;150,00724
27,96000;10,07728;151,42170
28,00000;10,07859;151,09481
28,04000;10,07985;149,14953
28,08000;10,08105;148,31094
28,12000;10,08260;151,14358
28,16000;10,08392;149,18689
28,20000;10,08523;146,58776
28,24000;10,08655;146,54996
28,28000;10,08792;146,33104
28,32000;10,08924;147,03908
28,36000;10,09049;145,27099
28,40000;10,09187;145,33387
28,44000;10,09324;146,22116
28,48000;10,09456;144,41690
28,52000;10,09593;143,42555
28,56000;10,09719;142,92866
28,60000;10,09856;142,82288
28,64000;10,09994;143,15854
28,68000;10,10114;142,10276
28,72000;10,10245;141,51043
28,76000;10,10389;143,32816
28,80000;10,10520;142,69670
28,84000;10,10658;140,34922
28,88000;10,10789;140,15767
28,92000;10,10927;140,03051
28,96000;10,11046;139,25009
29,00000;10,11172;137,90703
29,04000;10,11321;138,39869
29,08000;10,11453;138,67280
29,12000;10,11590;136,83077
29,16000;10,11722;136,96636
29,20000;10,11859;136,19977
29,24000;10,11997;136,51353
29,28000;10,12116;135,42817
29,32000;10,12242;134,13642
29,36000;10,12385;134,59978
29,40000;10,12529;136,55829
29,44000;10,12661;137,41778
29,48000;10,12792;134,61447
29,52000;10,12930;133,76096
29,56000;10,13061;133,74176
29,60000;10,13181;132,28985
29,64000;10,13312;130,65196
29,68000;10,13456;133,21768
29,72000;10,13587;132,21293
29,76000;10,13725;132,18971
29,80000;10,13862;132,23129
29,84000;10,14000;131,93294
29,88000;10,14131;131,91458
29,92000;10,14251;130,05401
29,96000;10,14382;129,71443
30,00000;10,14520;130,56025
30,04000;10,14658;130,24242
30,08000;10,14795;131,26296
30,12000;10,14921;131,06082
30,16000;10,15058;129,41158
30,20000;10,15184;128,32040
30,24000;10,15309;127,09582
30,28000;10,15453;127,25741
30,32000;10,15590;127,94409
30,36000;10,15722;126,88312
30,40000;10,15853;126,51627
30,44000;10,15985;127,11433
30,48000;10,16128;126,46295
30,52000;10,16254;126,22356
30,56000;10,16379;124,73610
30,60000;10,16523;125,10461
30,64000;10,16660;125,82723
30,68000;10,16792;124,80377
30,72000;10,16924;124,49430
30,76000;10,17055;124,10210
30,80000;10,17199;125,01010
30,84000;10,17318;124,36274
30,88000;10,17444;121,77189
30,92000;10,17587;122,46724
30,96000;10,17719;122,32065
31,00000;10,17850;120,98326
31,04000;10,17988;120,97822
31,08000;10,18125;121,52874
31,12000;10,18263;121,68806
31,16000;10,18388;120,62269
31,20000;10,18514;118,85035
31,24000;10,18657;120,68991
31,28000;10,18789;120,52779
31,32000;10,18927;118,47487
31,36000;10,19064;119,05222
31,40000;10,19196;118,64253
31,44000;10,19327;118,27647
31,48000;10,19447;117,56893
31,52000;10,19578;116,22537
31,56000;10,19716;117,23018
31,60000;10,19859;118,50097
31,64000;10,19991;117,34099
31,68000;10,20122;115,35217
31,72000;10,20254;115,06862
31,76000;10,20391;114,79519
31,80000;10,20511;113,59687
31,84000;10,20649;113,68319
31,88000;10,20786;115,25326
31,92000;10,20923;114,20144
31,96000;10,21055;113,34979
32,00000;10,21193;113,12426
32,04000;10,21324;112,36260
32,08000;10,21456;113,07157
32,12000;10,21581;111,62730
32,16000;10,21713;110,74049
32,20000;10,21856;112,25523
32,24000;10,21988;110,88694
32,28000;10,22113;111,23391
32,32000;10,22263;113,02647
32,36000;10,22394;111,17192
32,40000;10,22520;109,35223
32,44000;10,22639;108,27642
32,48000;10,22783;108,75661
32,52000;10,22915;109,48351
32,56000;10,23052;108,53931
32,60000;10,23190;108,41342
32,64000;10,23321;107,98988
32,68000;10,23459;108,30868
32,72000;10,23590;107,17344
32,76000;10,23716;105,22143
32,80000;10,23859;106,31713
32,84000;10,23991;107,08377
32,88000;10,24122;104,84842
32,92000;10,24260;105,45681
32,96000;10,24391;103,98981
33,00000;10,24529;104,15606
33,04000;10,24648;103,05404
33,08000;10,24780;103,07191
33,12000;10,24923;103,14737
33,16000;10,25055;102,80476
33,20000;10,25192;100,99462
33,24000;10,25324;101,68689
33,28000;10,25456;100,54434
33,32000;10,25593;100,89997
33,36000;10,25701;99,81769
33,40000;10,25856;102,26615
33,44000;10,25994;100,72859
33,48000;10,26125;98,55404
33,49000;10,26161;98,33801