File: SU - Suspension/05 - Essais/Excels essais Optimus/collage alu carbone 05_02_19/collage6.is_tens_RawData/Specimen_RawData_1.csv
Temps;Déplacement;Charge
(sec);(mm);(N)
0,00000;0,12257;22,21945
0,04000;0,12287;21,04852
0,08000;0,12400;22,20292
0,12000;0,12669;27,63483
0,16000;0,13010;34,54120
0,20000;0,13375;42,77783
0,24000;0,13752;52,55836
0,28000;0,14116;63,14702
0,32000;0,14487;74,03846
0,36000;0,14846;85,71649
0,40000;0,15198;96,99963
0,44000;0,15545;109,01549
0,48000;0,15886;120,92980
0,52000;0,16227;133,22267
0,56000;0,16568;145,20228
0,60000;0,16902;157,46878
0,64000;0,17237;169,22260
0,68000;0,17584;181,68727
0,72000;0,17907;194,96232
0,76000;0,18248;207,17315
0,80000;0,18583;219,13543
0,84000;0,18911;230,93733
0,88000;0,19252;241,08626
0,92000;0,19587;251,19365
0,96000;0,19916;260,56538
1,00000;0,20257;262,60354
1,04000;0,20586;189,68286
1,08000;0,20914;187,99898
1,12000;0,21249;203,33128
1,16000;0,21584;218,08494
1,20000;0,21919;230,13004
1,24000;0,22254;243,26157
1,28000;0,22582;253,01552
1,32000;0,22917;259,36195
1,36000;0,23252;262,82561
1,40000;0,23587;263,23569
1,44000;0,23916;262,86521
1,48000;0,24257;262,03240
1,52000;0,24585;261,15950
1,56000;0,24920;268,92249
1,60000;0,25249;279,29759
1,64000;0,25584;291,30741
1,68000;0,25925;304,01030
1,72000;0,26248;317,34444
1,76000;0,26588;330,59320
1,80000;0,26923;343,97545
1,84000;0,27246;357,30568
1,88000;0,27581;369,76873
1,92000;0,27922;383,51924
1,96000;0,28251;396,30579
2,00000;0,28585;406,84962
2,04000;0,28920;419,25744
2,08000;0,29255;431,23863
2,12000;0,29578;442,52831
2,16000;0,29913;454,64598
2,20000;0,30248;466,83820
2,24000;0,30582;478,80630
2,28000;0,30911;490,81892
2,32000;0,31252;503,33650
2,36000;0,31581;516,24440
2,40000;0,31916;529,15933
2,44000;0,32244;541,53865
2,48000;0,32573;553,85153
2,52000;0,32914;567,81522
2,56000;0,33249;581,51274
2,60000;0,33578;595,70405
2,64000;0,33919;608,73074
2,68000;0,34253;622,35747
2,72000;0,34576;636,27302
2,76000;0,34911;649,79512
2,80000;0,35246;663,56012
2,84000;0,35569;676,30205
2,88000;0,35910;689,62714
2,92000;0,36244;704,13239
2,96000;0,36573;717,13757
3,00000;0,36908;729,49077
3,04000;0,37243;743,45507
3,08000;0,37578;756,84912
3,12000;0,37913;770,22505
3,16000;0,38247;784,13542
3,20000;0,38582;797,31727
3,24000;0,38917;810,33316
3,28000;0,39252;822,06242
3,32000;0,39587;835,22033
3,36000;0,39915;847,34485
3,40000;0,40244;859,84273
3,44000;0,40579;872,51822
3,48000;0,40908;884,61163
3,52000;0,41249;897,06201
3,56000;0,41578;909,52124
3,60000;0,41912;920,84836
3,64000;0,42247;932,33595
3,68000;0,42588;943,47643
3,72000;0,42905;954,72662
3,76000;0,43246;966,13206
3,80000;0,43587;978,24754
3,84000;0,43915;987,84650
3,88000;0,44256;997,72420
3,92000;0,44591;1007,41936
3,96000;0,44920;1016,95172
4,00000;0,45243;1024,87551
4,04000;0,45578;1033,99949
4,08000;0,45912;1042,94615
4,12000;0,46241;1051,32507
4,16000;0,46582;1058,95381
4,20000;0,46917;1066,78586
4,24000;0,47252;1074,55049
4,28000;0,47580;1081,06360
4,32000;0,47915;1088,87749
4,36000;0,48244;1095,83363
4,40000;0,48579;1102,86120
4,44000;0,48920;1110,27714
4,48000;0,49249;1117,30257
4,52000;0,49589;1123,95100
4,56000;0,49918;1130,50221
4,60000;0,50247;1137,08610
4,64000;0,50582;1142,90565
4,68000;0,50917;1149,58389
4,72000;0,51240;1155,71534
4,76000;0,51580;1160,87953
4,80000;0,51921;1168,85370
4,84000;0,52244;1174,04005
4,88000;0,52579;1180,38375
4,92000;0,52920;1186,49499
4,96000;0,53249;1192,93267
5,00000;0,53589;1199,28829
5,04000;0,53918;1204,28279
5,08000;0,54253;1209,23715
5,12000;0,54588;1215,20935
5,16000;0,54917;1219,54056
5,20000;0,55251;1224,72020
5,24000;0,55580;1229,84499
5,28000;0,55915;1235,20894
5,32000;0,56250;1240,35673
5,36000;0,56585;1244,95234
5,40000;0,56920;1249,49729
5,44000;0,57254;1254,00452
5,48000;0,57577;1259,24014
5,52000;0,57918;1264,12585
5,56000;0,58259;1268,24025
5,60000;0,58582;1272,36424
5,64000;0,58923;1276,14308
5,68000;0,59257;1280,82242
5,72000;0,59580;1284,35576
5,76000;0,59915;1288,89894
5,80000;0,60256;1293,78056
5,84000;0,60585;1298,07843
5,88000;0,60920;1302,03171
5,92000;0,61260;1305,85255
5,96000;0,61589;1310,52788
6,00000;0,61918;1313,19994
6,04000;0,62247;1316,31754
6,08000;0,62588;1319,90314
6,12000;0,62922;1323,01552
6,16000;0,63251;1325,21056
6,20000;0,63592;1329,44398
6,24000;0,63921;1332,41061
6,28000;0,64250;1335,06488
6,32000;0,64591;1337,85121
6,36000;0,64919;1342,08146
6,40000;0,65254;1345,01383
6,44000;0,65589;1347,40621
6,48000;0,65906;1348,97418
6,52000;0,66253;1351,72755
6,56000;0,66588;1355,24441
6,60000;0,66916;1357,44670
6,64000;0,67263;1359,46404
6,68000;0,67598;1362,34900
6,72000;0,67921;1363,83167
6,76000;0,68250;1364,41607
6,80000;0,68585;1366,63504
6,84000;0,68919;1367,87603
6,88000;0,69248;1369,50603
6,92000;0,69583;1371,92002
6,96000;0,69924;1376,59730
7,00000;0,70247;1378,49515
7,04000;0,70581;1382,65416
7,08000;0,70916;1386,98705
7,12000;0,71251;1393,27934
7,16000;0,71586;1398,23081
7,20000;0,71915;1402,90428
7,24000;0,72250;1408,62744
7,28000;0,72590;1414,18427
7,32000;0,72925;1418,86994
7,36000;0,73236;1422,23993
7,40000;0,73583;1427,80859
7,44000;0,73918;1431,82613
7,48000;0,74241;1434,82126
7,52000;0,74575;1439,12416
7,56000;0,74916;1443,07399
7,60000;0,75245;1446,34740
7,64000;0,75574;1448,39538
7,68000;0,75909;1450,64797
7,72000;0,76244;1453,25772
7,76000;0,76578;1454,27976
7,80000;0,76919;1456,83885
7,84000;0,77254;1461,00000
7,88000;0,77583;1461,90841
7,92000;0,77912;1463,48104
7,96000;0,78247;1465,60064
8,00000;0,78581;1466,66514
8,04000;0,78910;1468,99652
8,08000;0,79251;1471,34159
8,12000;0,79586;1475,30278
8,16000;0,79915;1476,83891
8,20000;0,80249;1477,13721
8,24000;0,80572;1479,74631
8,28000;0,80913;1481,39885
8,32000;0,81242;1484,44921
8,36000;0,81571;1487,77710
8,40000;0,81918;1491,10211
8,44000;0,82246;1495,04291
8,48000;0,82587;1499,53049
8,52000;0,82916;1504,15683
8,56000;0,83257;1506,99168
8,60000;0,83580;1511,15125
8,64000;0,83915;1515,36567
8,68000;0,84255;1519,61921
8,72000;0,84584;1523,72569
8,76000;0,84913;1528,04451
8,80000;0,85254;1533,85168
8,84000;0,85583;1538,71477
8,88000;0,85912;1542,64867
8,92000;0,86246;1547,85709
8,96000;0,86593;1553,62217
9,00000;0,86922;1558,69899
9,04000;0,87251;1563,66546
9,08000;0,87592;1568,79630
9,12000;0,87920;1573,61198
9,16000;0,88255;1578,44406
9,20000;0,88584;1583,22416
9,24000;0,88919;1589,01364
9,28000;0,89254;1594,13051
9,32000;0,89577;1599,07807
9,36000;0,89911;1605,01599
9,40000;0,90246;1610,23252
9,44000;0,90581;1615,93910
9,48000;0,90910;1620,87511
9,52000;0,91251;1627,74902
9,56000;0,91586;1637,54672
9,60000;0,91914;1648,23942
9,64000;0,92243;1659,46633
9,68000;0,92584;1672,21613
9,72000;0,92913;1683,76323
9,76000;0,93242;1695,57240
9,80000;0,93583;1708,88677
9,84000;0,93917;1722,75268
9,88000;0,94240;1733,34908
9,92000;0,94575;1745,93870
9,96000;0,94910;1758,07085
10,00000;0,95227;1769,74628
10,04000;0,95574;1783,21674
10,08000;0,95914;1795,70541
10,12000;0,96243;1806,46814
10,16000;0,96578;1816,66519
10,20000;0,96907;1827,47822
10,24000;0,97242;1837,27760
10,28000;0,97576;1846,46510
10,32000;0,97905;1856,20915
10,36000;0,98240;1865,87889
10,40000;0,98581;1874,84473
10,44000;0,98910;1883,90557
10,48000;0,99245;1893,24394
10,52000;0,99579;1901,86556
10,56000;0,99908;1910,87704
10,60000;1,00237;1920,24559
10,64000;1,00578;1930,91817
10,68000;1,00919;1940,52402
10,72000;1,01248;1949,75547
10,76000;1,01582;1957,72052
10,80000;1,01911;1967,68288
10,84000;1,02252;1976,85920
10,88000;1,02575;1986,57997
10,92000;1,02910;1996,78913
10,96000;1,03250;2007,56937
11,00000;1,03585;2017,00814
11,04000;1,03914;2026,79392
11,08000;1,04255;2037,04014
11,12000;1,04590;2047,49573
11,16000;1,04913;2058,32962
11,20000;1,05247;2067,57933
11,24000;1,05588;2079,40675
11,28000;1,05923;2089,59207
11,32000;1,06258;2099,87145
11,36000;1,06587;2109,31599
11,40000;1,06922;2119,54731
11,44000;1,07256;2129,34148
11,48000;1,07585;2139,47967
11,52000;1,07914;2149,23602
11,56000;1,08225;2159,76033
11,60000;1,08590;2170,64526
11,64000;1,08919;2182,16348
11,68000;1,09253;2192,13367
11,72000;1,09588;2202,06231
11,76000;1,09893;2211,69572
11,80000;1,10258;2223,08692
11,84000;1,10593;2234,70833
11,88000;1,10921;2243,31059
11,92000;1,11250;2252,02125
11,96000;1,11591;2262,24568
12,00000;1,11920;2271,81502
12,04000;1,12243;2281,19884
12,08000;1,12584;2291,07719
12,12000;1,12912;2301,21333
12,16000;1,13247;2310,04450
12,20000;1,13582;2318,38562
12,24000;1,13917;2327,58261
12,28000;1,14252;2337,98157
12,32000;1,14581;2346,38508
12,36000;1,14909;2354,48182
12,40000;1,15250;2363,35844
12,44000;1,15591;2372,73891
12,48000;1,15914;2380,93976
12,52000;1,16255;2388,56599
12,56000;1,16590;2398,02152
12,60000;1,16912;2406,46191
12,64000;1,17241;2413,52096
12,68000;1,17582;2423,69454
12,72000;1,17917;2433,06402
12,76000;1,18246;2440,40247
12,80000;1,18580;2447,56564
12,84000;1,18915;2456,25116
12,88000;1,19250;2464,67963
12,92000;1,19579;2473,11443
12,96000;1,19920;2481,29033
13,00000;1,20255;2490,58791
13,04000;1,20589;2497,98074
13,08000;1,20918;2505,83086
13,12000;1,21253;2514,77249
13,16000;1,21588;2522,81781
13,20000;1,21917;2530,33508
13,24000;1,22240;2539,17258
13,28000;1,22586;2547,98234
13,32000;1,22921;2556,16270
13,36000;1,23244;2565,06950
13,40000;1,23585;2572,70895
13,44000;1,23914;2580,77439
13,48000;1,24243;2588,87149
13,52000;1,24577;2596,14848
13,56000;1,24918;2606,25072
13,60000;1,25253;2615,20166
13,64000;1,25582;2623,48633
13,68000;1,25923;2631,77715
13,72000;1,26257;2640,78323
13,76000;1,26586;2647,30230
13,80000;1,26921;2655,23046
13,84000;1,27256;2663,99942
13,88000;1,27591;2673,14650
13,92000;1,27920;2680,14912
13,96000;1,28254;2687,37990
14,00000;1,28583;2694,49055
14,04000;1,28912;2701,59561
14,08000;1,29253;2709,23749
14,12000;1,29582;2716,71955
14,16000;1,29917;2724,30889
14,20000;1,30257;2733,92368
14,24000;1,30580;2740,76965
14,28000;1,30915;2747,75792
14,32000;1,31250;2755,14256
14,36000;1,31579;2762,60264
14,40000;1,31920;2768,83580
14,44000;1,32248;2777,72974
14,48000;1,32583;2787,90612
14,52000;1,32912;2793,68162
14,56000;1,33247;2801,58352
14,60000;1,33576;2809,63443
14,64000;1,33911;2815,81264
14,68000;1,34233;2823,91217
14,72000;1,34586;2833,67336
14,76000;1,34909;2842,25065
14,80000;1,35244;2850,17118
14,84000;1,35579;2857,36229
14,88000;1,35902;2864,82461
14,92000;1,36242;2872,66728
14,96000;1,36577;2880,58799
15,00000;1,36912;2889,04663
15,04000;1,37247;2898,04805
15,08000;1,37582;2905,96187
15,12000;1,37910;2913,67043
15,16000;1,38245;2921,71966
15,20000;1,38580;2929,50813
15,24000;1,38903;2937,40612
15,28000;1,39244;2945,52464
15,32000;1,39579;2954,64564
15,36000;1,39907;2962,39592
15,40000;1,40242;2970,67333
15,44000;1,40577;2978,81793
15,48000;1,40906;2986,58516
15,52000;1,41241;2993,91318
15,56000;1,41582;3003,06752
15,60000;1,41916;3012,29153
15,64000;1,42239;3019,00208
15,68000;1,42580;3027,05374
15,72000;1,42915;3036,00114
15,76000;1,43244;3043,27980
15,80000;1,43578;3051,92843
15,84000;1,43925;3060,86559
15,88000;1,44248;3068,90029
15,92000;1,44583;3076,87037
15,96000;1,44918;3084,96077
16,00000;1,45247;3093,12753
16,04000;1,45581;3101,15274
16,08000;1,45910;3109,41711
16,12000;1,46245;3118,38407
16,16000;1,46580;3125,86203
16,20000;1,46915;3134,18135
16,24000;1,47244;3143,31166
16,28000;1,47584;3151,97594
16,32000;1,47919;3160,18499
16,36000;1,48248;3169,25719
16,40000;1,48589;3177,58583
16,44000;1,48924;3187,15833
16,48000;1,49253;3195,91388
16,52000;1,49581;3203,83012
16,56000;1,49916;3212,28877
16,60000;1,50251;3221,15496
16,64000;1,50580;3229,07940
16,68000;1,50921;3238,26969
16,72000;1,51255;3247,39181
16,76000;1,51578;3255,36877
16,80000;1,51913;3262,54256
16,84000;1,52248;3271,60209
16,88000;1,52571;3278,65556
16,92000;1,52906;3287,23453
16,96000;1,53246;3299,78392
17,00000;1,53587;3314,95553
17,04000;1,53922;3329,17683
17,08000;1,54251;3344,34249
17,12000;1,54580;3360,25022
17,16000;1,54915;3376,27158
17,20000;1,55249;3393,11063
17,24000;1,55578;3410,46937
17,28000;1,55913;3427,25180
17,32000;1,56248;3444,27563
17,36000;1,56577;3461,27376
17,40000;1,56906;3477,04925
17,44000;1,57240;3494,91909
17,48000;1,57575;3512,61720
17,52000;1,57910;3529,67642
17,56000;1,58251;3547,59730
17,60000;1,58586;3565,88438
17,64000;1,58914;3582,45969
17,68000;1,59249;3599,55840
17,72000;1,59590;3617,93600
17,76000;1,59913;3634,68342
17,80000;1,60242;3651,12945
17,84000;1,60583;3669,24703
17,88000;1,60911;3687,32400
17,92000;1,61246;3704,13885
17,96000;1,61581;3720,86279
18,00000;1,61910;3738,32844
18,04000;1,62245;3754,87953
18,08000;1,62574;3772,32134
18,12000;1,62908;3788,86312
18,16000;1,63243;3805,83964
18,20000;1,63578;3823,36564
18,24000;1,63913;3840,13057
18,28000;1,64248;3857,68712
18,32000;1,64583;3874,88119
18,36000;1,64911;3891,48407
18,40000;1,65240;3908,79288
18,44000;1,65581;3925,80144
18,48000;1,65916;3943,16092
18,52000;1,66245;3960,56958
18,56000;1,66579;3977,60160
18,60000;1,66920;3995,51168
18,64000;1,67237;4011,17578
18,68000;1,67578;4029,09778
18,72000;1,67919;4047,36027
18,76000;1,68242;4064,59905
18,80000;1,68582;4082,06955
18,84000;1,68923;4100,31453
18,88000;1,69246;4117,21393
18,92000;1,69581;4134,39535
18,96000;1,69916;4152,01522
19,00000;1,70245;4170,05308
19,04000;1,70585;4187,66364
19,08000;1,70914;4204,55150
19,12000;1,71249;4223,38583
19,16000;1,71584;4241,06121
19,20000;1,71913;4258,52984
19,24000;1,72248;4276,79010
19,28000;1,72582;4295,00267
19,32000;1,72917;4313,23163
19,36000;1,73252;4330,34413
19,40000;1,73581;4348,16629
19,44000;1,73922;4366,42058
19,48000;1,74256;4384,39734
19,52000;1,74579;4401,06876
19,56000;1,74920;4419,85689
19,60000;1,75255;4438,19538
19,64000;1,75578;4456,22876
19,68000;1,75919;4473,89781
19,72000;1,76259;4492,17409
19,76000;1,76588;4510,13893
19,80000;1,76917;4528,06205
19,84000;1,77252;4546,33571
19,88000;1,77581;4565,27621
19,92000;1,77916;4581,59745
19,96000;1,78250;4598,96959
20,00000;1,78585;4616,72954
20,04000;1,78920;4633,98285
20,08000;1,79249;4651,18140
20,12000;1,79578;4669,57055
20,16000;1,79913;4688,52818
20,20000;1,80247;4705,74871
20,24000;1,80582;4723,39652
20,28000;1,80911;4740,95903
20,32000;1,81252;4759,01254
20,36000;1,81587;4776,80564
20,40000;1,81910;4793,38355
20,44000;1,82250;4812,41755
20,48000;1,82591;4831,59944
20,52000;1,82914;4848,85462
20,56000;1,83243;4866,19622
20,60000;1,83590;4885,19818
20,64000;1,83906;4902,81582
20,68000;1,84235;4919,98121
20,72000;1,84582;4937,98330
20,76000;1,84911;4957,61298
20,80000;1,85246;4974,23597
20,84000;1,85575;4989,67841
20,88000;1,85909;5008,16219
20,92000;1,86244;5026,04134
20,96000;1,86573;5044,21704
21,00000;1,86920;5063,42910
21,04000;1,87255;5083,55610
21,08000;1,87584;5102,21310
21,12000;1,87912;5118,13276
21,16000;1,88253;5135,65205
21,20000;1,88582;5152,62634
21,24000;1,88887;5170,88734
21,28000;1,89252;5189,41693
21,32000;1,89581;5208,67258
21,36000;1,89915;5225,52207
21,40000;1,90238;5242,49598
21,44000;1,90573;5259,96126
21,48000;1,90914;5280,17506
21,52000;1,91243;5297,49170
21,56000;1,91577;5316,05780
21,60000;1,91918;5334,14558
21,64000;1,92253;5352,63382
21,68000;1,92588;5372,56673
21,72000;1,92923;5389,22586
21,76000;1,93246;5405,71809
21,80000;1,93580;5422,87976
21,84000;1,93915;5441,11319
21,88000;1,94244;5460,64638
21,92000;1,94585;5478,81238
21,96000;1,94914;5497,02086
22,00000;1,95243;5514,96372
22,04000;1,95577;5532,28334
22,08000;1,95912;5548,95140
22,12000;1,96247;5567,16919
22,16000;1,96588;5584,44113
22,20000;1,96923;5604,07154
22,24000;1,97252;5621,28164
22,28000;1,97580;5638,25555
22,32000;1,97915;5654,95901
22,36000;1,98250;5672,94881
22,40000;1,98573;5690,97176
22,44000;1,98926;5710,53289
22,48000;1,99260;5730,59544
22,52000;1,99577;5747,71501
22,56000;1,99912;5763,30684
22,60000;2,00247;5780,93342
22,64000;2,00576;5797,55791
22,68000;2,00905;5814,35636
22,72000;2,01251;5832,73284
22,76000;2,01580;5851,91287
22,80000;2,01909;5867,89846
22,84000;2,02244;5886,15723
22,88000;2,02579;5904,36533
22,92000;2,02914;5922,45758
22,96000;2,03236;5939,23479
23,00000;2,03583;5958,70651
23,04000;2,03918;5977,66489
23,08000;2,04247;5996,16058
23,12000;2,04576;6012,75787
23,16000;2,04905;6029,71092
23,20000;2,05245;6047,45187
23,24000;2,05574;6064,97750
23,28000;2,05903;6082,32245
23,32000;2,06244;6100,31933
23,36000;2,06579;6117,74176
23,40000;2,06908;6135,36909
23,44000;2,07242;6153,23894
23,48000;2,07583;6171,21868
23,52000;2,07906;6188,49918
23,56000;2,08241;6205,02532
23,60000;2,08582;6223,23677
23,64000;2,08904;6242,15044
23,68000;2,09239;6257,95498
23,72000;2,09580;6277,22293
23,76000;2,09909;6295,99467
23,80000;2,10244;6311,74445
23,84000;2,10579;6329,73984
23,88000;2,10913;6347,82016
23,92000;2,11242;6364,63836
23,96000;2,11577;6382,47505
24,00000;2,11912;6401,11268
24,04000;2,12247;6418,08510
24,08000;2,12576;6434,69840
24,12000;2,12910;6452,81598
24,16000;2,13245;6470,55879
24,20000;2,13580;6488,98929
24,24000;2,13915;6506,33425
24,28000;2,14250;6525,27437
24,32000;2,14584;6542,82272
24,36000;2,14913;6561,11911
24,40000;2,15248;6578,55794
24,44000;2,15583;6598,37127
24,48000;2,15924;6615,30495
24,52000;2,16247;6632,75495
24,56000;2,16581;6649,21328
24,60000;2,16916;6666,45542
24,64000;2,17227;6683,83688
24,68000;2,17580;6701,83077
24,72000;2,17915;6719,88428
24,76000;2,18250;6738,12404
24,80000;2,18578;6754,08393
24,84000;2,18913;6771,91988
24,88000;2,19248;6790,17901
24,92000;2,19577;6807,20657
24,96000;2,19912;6824,47106
25,00000;2,20253;6843,49611
25,04000;2,20587;6861,49970
25,08000;2,20916;6878,38346
25,12000;2,21257;6896,08455
25,16000;2,21586;6914,45544
25,20000;2,21921;6930,65599
25,24000;2,22249;6948,34739
25,28000;2,22578;6966,16694
25,32000;2,22913;6983,73988
25,36000;2,23254;7000,85461
25,40000;2,23577;7018,07812
25,44000;2,23912;7036,13460
25,48000;2,24252;7052,64807
25,52000;2,24569;7069,48936
25,56000;2,24910;7087,01462
25,60000;2,25251;7106,12610
25,64000;2,25580;7123,84209
25,68000;2,25915;7141,28390
25,72000;2,26249;7158,83225
25,76000;2,26578;7176,13325
25,80000;2,26913;7192,66608
25,84000;2,27242;7209,18700
25,88000;2,27577;7226,13856
25,92000;2,27906;7242,86512
25,96000;2,28246;7261,36342
26,00000;2,28581;7279,21128
26,04000;2,28910;7296,13379
26,08000;2,29245;7312,59286
26,12000;2,29556;7330,29768
26,16000;2,29909;7348,70359
26,20000;2,30249;7366,94634
26,24000;2,30584;7383,71313
26,28000;2,30907;7399,74380
26,32000;2,31254;7417,05447
26,36000;2,31583;7434,55663
26,40000;2,31911;7450,68565
26,44000;2,32246;7467,80038
26,48000;2,32581;7485,88815
26,52000;2,32910;7502,87399
26,56000;2,33233;7518,77055
26,60000;2,33586;7539,27976
26,64000;2,33914;7557,62905
26,68000;2,34249;7573,31550
26,72000;2,34578;7589,46091
26,76000;2,34913;7606,71422
26,80000;2,35248;7623,27760
26,84000;2,35577;7640,32006
26,88000;2,35923;7658,63657
26,92000;2,36258;7675,91670
26,96000;2,36581;7692,16940
27,00000;2,36922;7709,44133
27,04000;2,37251;7727,69600
27,08000;2,37586;7743,94870
27,12000;2,37914;7761,31749
27,16000;2,38249;7778,85467
27,20000;2,38590;7796,09904
27,24000;2,38925;7813,81950
27,28000;2,39242;7830,90219
27,32000;2,39588;7848,26949
27,36000;2,39923;7865,46469
27,40000;2,40246;7881,79040
27,44000;2,40575;7897,54018
27,48000;2,40922;7915,32397
27,52000;2,41245;7931,93877
27,56000;2,41573;7948,52078
27,60000;2,41914;7966,08850
27,64000;2,42255;7985,75133
27,68000;2,42584;8001,61511
27,72000;2,42919;8018,74921
27,76000;2,43248;8035,86468
27,80000;2,43582;8052,11961
27,84000;2,43917;8067,62651
27,88000;2,44246;8084,31581
27,92000;2,44581;8100,68399
27,96000;2,44910;8118,11537
28,00000;2,45245;8135,28076
28,04000;2,45579;8153,92733
28,08000;2,45914;8170,92732
28,12000;2,46249;8187,28283
28,16000;2,46566;8203,90806
28,20000;2,46919;8223,59920
28,24000;2,47253;8241,08720
28,28000;2,47576;8257,88304
28,32000;2,47911;8274,03143
28,36000;2,48252;8289,80729
28,40000;2,48575;8305,73291
28,44000;2,48910;8321,72185
28,48000;2,49256;8339,65689
28,52000;2,49579;8358,42490
28,56000;2,49908;8374,33934
28,60000;2,50243;8391,33188
28,64000;2,50578;8408,63287
28,68000;2,50913;8425,21191
28,72000;2,51247;8440,60555
28,76000;2,51588;8458,48992
28,80000;2,51917;8476,20592
28,84000;2,52246;8492,61284
28,88000;2,52581;8509,88105
28,92000;2,52910;8525,49821
28,96000;2,53244;8541,01107
29,00000;2,53579;8558,39401
29,04000;2,53896;8574,56774
29,08000;2,54249;8593,54138
29,12000;2,54584;8611,44289
29,16000;2,54912;8628,20521
29,20000;2,55247;8643,38726
29,24000;2,55582;8659,31511
29,28000;2,55911;8675,99398
29,32000;2,56246;8691,99261
29,36000;2,56575;8708,65360
29,40000;2,56909;8726,91497
29,44000;2,57244;8743,46271
29,48000;2,57585;8759,66474
29,52000;2,57914;8777,06856
29,56000;2,58249;8793,44419
29,60000;2,58590;8810,04706
29,64000;2,58918;8827,26088
29,68000;2,59253;8841,91766
29,72000;2,59582;8859,23132
29,76000;2,59917;8874,76355
29,80000;2,60246;8889,47621
29,84000;2,60581;8907,18922
29,88000;2,60915;8922,91591
29,92000;2,61250;8938,88324
29,96000;2,61579;8955,08304
30,00000;2,61914;8971,24931
30,04000;2,62243;8988,02653
30,08000;2,62577;9004,05198
30,12000;2,62906;9020,46636
30,16000;2,63241;9037,41419
30,20000;2,63582;9054,17129
30,24000;2,63917;9071,59224
30,28000;2,64240;9087,64899
30,32000;2,64580;9103,38238
30,36000;2,64915;9119,07330
30,40000;2,65238;9135,40870
30,44000;2,65573;9150,16457
30,48000;2,65914;9167,04386
30,52000;2,66243;9183,26676
30,56000;2,66571;9198,76769
30,60000;2,66906;9214,80581
30,64000;2,67247;9232,31840
30,68000;2,67576;9247,84616
30,72000;2,67905;9262,99840
30,76000;2,68246;9280,42978
30,80000;2,68580;9297,76877
30,84000;2,68915;9312,52986
30,88000;2,69250;9328,08071
30,92000;2,69579;9343,61592
30,96000;2,69914;9361,05698
31,00000;2,70243;9376,43424
31,04000;2,70571;9391,95380
31,08000;2,70912;9408,34880
31,12000;2,71241;9424,26771
31,16000;2,71570;9439,67849
31,20000;2,71905;9454,63404
31,24000;2,72245;9470,60511
31,28000;2,72568;9485,92871
31,32000;2,72909;9501,08916
31,36000;2,73250;9517,68458
31,40000;2,73579;9533,35240
31,44000;2,73914;9547,27307
31,48000;2,74248;9562,52962
31,52000;2,74583;9578,99615
31,56000;2,74912;9593,60525
31,60000;2,75247;9609,93692
31,64000;2,75582;9625,98622
31,68000;2,75905;9641,50727
31,72000;2,76245;9656,99106
31,76000;2,76580;9672,91966
31,80000;2,76909;9688,67838
31,84000;2,77244;9704,46989
31,88000;2,77579;9718,87037
31,92000;2,77914;9735,17671
31,96000;2,78242;9749,61072
32,00000;2,78583;9764,25856
32,04000;2,78912;9779,07702
32,08000;2,79247;9794,27397
32,12000;2,79582;9809,76000
32,16000;2,79910;9825,42709
32,20000;2,80251;9841,39889
32,24000;2,80586;9856,75529
32,28000;2,80915;9871,54394
32,32000;2,81250;9886,87947
32,36000;2,81585;9902,87215
32,40000;2,81907;9916,77940
32,44000;2,82242;9931,53155
32,48000;2,82583;9947,75295
32,52000;2,82918;9964,01906
32,56000;2,83253;9977,18573
32,60000;2,83588;9992,90869
32,64000;2,83922;10009,07868
32,68000;2,84245;10022,19617
32,72000;2,84580;10036,53184
32,76000;2,84915;10052,99836
32,80000;2,85250;10068,76826
32,84000;2,85579;10082,75151
32,88000;2,85919;10097,66310
32,92000;2,86248;10112,71402
32,96000;2,86583;10126,40074
33,00000;2,86912;10140,75652
33,04000;2,87247;10155,50569
33,08000;2,87581;10170,52680
33,12000;2,87916;10185,81241
33,16000;2,88245;10200,43716
33,20000;2,88586;10215,29585
33,24000;2,88921;10230,85490
33,28000;2,89244;10244,93501
33,32000;2,89578;10259,23491
33,36000;2,89913;10274,62259
33,40000;2,90248;10290,10117
33,44000;2,90583;10303,68581
33,48000;2,90918;10318,07661
33,52000;2,91253;10333,12678
33,56000;2,91581;10345,78905
33,60000;2,91910;10359,93248
33,64000;2,92245;10376,28800
33,68000;2,92586;10390,05220
33,72000;2,92915;10403,89389
33,76000;2,93249;10417,85628
33,80000;2,93584;10432,59725
33,84000;2,93913;10447,68170
33,88000;2,94242;10460,80068
33,92000;2,94577;10475,61914
33,96000;2,94918;10490,07699
34,00000;2,95246;10503,13190
34,04000;2,95575;10517,55697
34,08000;2,95922;10531,25486
34,12000;2,96257;10544,89836
34,16000;2,96574;10558,06428
34,20000;2,96915;10571,67053
34,24000;2,97249;10585,82440
34,28000;2,97584;10599,78828
34,32000;2,97919;10612,82232
34,36000;2,98254;10627,05219
34,40000;2,98583;10640,83576
34,44000;2,98912;10653,48089
34,48000;2,99246;10668,20920
34,52000;2,99581;10682,57540
34,56000;2,99916;10694,24897
34,60000;3,00245;10708,12419
34,64000;3,00580;10721,38324
34,68000;3,00909;10734,63485
34,72000;3,01243;10746,96928
34,76000;3,01584;10760,44217
34,80000;3,01919;10774,92684
34,84000;3,02248;10787,16144
34,88000;3,02589;10799,83711
34,92000;3,02917;10814,46111
34,96000;3,03246;10827,29474
35,00000;3,03563;10840,73186
35,04000;3,03916;10854,86934
35,08000;3,04251;10868,40779
35,12000;3,04586;10880,37118
35,16000;3,04908;10893,24579
35,20000;3,05243;10904,92085
35,24000;3,05584;10919,19765
35,28000;3,05907;10931,22885
35,32000;3,06242;10942,88006
35,36000;3,06589;10958,83846
35,40000;3,06917;10970,97397
35,44000;3,07252;10982,11929
35,48000;3,07587;10993,15360
35,52000;3,07922;11006,73452
35,56000;3,08251;11018,72176
35,60000;3,08568;11030,25228
35,64000;3,08926;11045,61239
35,68000;3,09249;11057,10939
35,72000;3,09584;11066,86890
35,76000;3,09913;11078,84943
35,80000;3,10248;11091,17493
35,84000;3,10582;11103,52725
35,88000;3,10905;11115,47202
35,92000;3,11258;11129,28018
35,96000;3,11587;11142,70911
36,00000;3,11928;11154,08912
36,04000;3,12251;11164,27854
36,08000;3,12585;11174,44560
36,12000;3,12920;11186,25253
36,16000;3,13243;11196,50826
36,20000;3,13578;11207,14620
36,24000;3,13919;11220,00515
36,28000;3,14248;11233,19864
36,32000;3,14570;11242,55955
36,36000;3,14911;11254,68835
36,40000;3,15246;11267,43630
36,44000;3,15581;11278,47284
36,48000;3,15910;11289,61742
36,52000;3,16251;11303,56565
36,56000;3,16579;11314,25500
36,60000;3,16914;11323,91244
36,64000;3,17249;11334,94824
36,68000;3,17578;11346,01682
36,72000;3,17913;11356,96173
36,76000;3,18248;11368,37974
36,80000;3,18582;11380,93472
36,84000;3,18917;11393,32578
36,88000;3,19246;11403,86611
36,92000;3,19575;11414,55397
36,96000;3,19910;11424,72178
37,00000;3,20244;11436,27688
37,04000;3,20567;11447,33727
37,08000;3,20902;11459,01754
37,12000;3,21249;11472,48521
37,16000;3,21572;11483,72293
37,20000;3,21913;11493,97567
37,24000;3,22247;11505,56430
37,28000;3,22576;11516,88695
37,32000;3,22911;11527,82142
37,36000;3,23252;11541,03726
37,40000;3,23581;11551,60293
37,44000;3,23910;11561,62694
37,48000;3,24244;11572,29096
37,52000;3,24579;11584,12769
37,56000;3,24908;11595,06813
37,60000;3,25237;11606,21122
37,64000;3,25584;11617,54727
37,68000;3,25912;11629,50471
37,72000;3,26247;11639,94148
37,76000;3,26582;11650,92140
37,80000;3,26917;11662,62627
37,84000;3,27252;11673,66505
37,88000;3,27581;11684,12939
37,92000;3,27909;11694,21375
37,96000;3,28244;11705,16685
38,00000;3,28579;11716,59902
38,04000;3,28908;11727,52306
38,08000;3,29249;11739,04017
38,12000;3,29584;11750,40379
38,16000;3,29912;11759,85858
38,20000;3,30241;11770,71109
38,24000;3,30582;11782,25279
38,28000;3,30911;11793,16640
38,32000;3,31240;11802,79180
38,36000;3,31581;11813,20772
38,40000;3,31921;11824,98708
38,44000;3,32238;11835,01109
38,48000;3,32579;11845,77793
38,52000;3,32920;11857,98571
38,56000;3,33249;11868,98127
38,60000;3,33578;11879,01050
38,64000;3,33918;11888,39599
38,68000;3,34247;11900,26700
38,72000;3,34582;11910,36478
38,76000;3,34917;11922,11062
38,80000;3,35246;11932,97654
38,84000;3,35586;11942,41941
38,88000;3,35915;11952,46875
38,92000;3,36250;11961,58677
38,96000;3,36585;11972,18671
39,00000;3,36914;11981,89333
39,04000;3,37243;11991,55524
39,08000;3,37577;12000,77906
39,12000;3,37912;12010,89621
39,16000;3,38241;12021,24208
39,20000;3,38576;12030,24238
39,24000;3,38911;12039,96539
39,28000;3,39240;12050,36938
39,32000;3,39574;12060,46492
39,36000;3,39915;12070,94863
39,40000;3,40256;12081,68417
39,44000;3,40573;12090,80368
39,48000;3,40920;12101,12274
39,52000;3,41255;12112,23751
39,56000;3,41577;12121,57980
39,60000;3,41906;12130,14200
39,64000;3,42253;12141,62782
39,68000;3,42576;12151,40894
39,72000;3,42911;12160,97102
39,76000;3,43245;12169,73811
39,80000;3,43580;12179,97819
39,84000;3,43915;12189,21319
39,88000;3,44232;12198,40720
39,92000;3,44585;12208,84994
39,96000;3,44920;12219,27479
40,00000;3,45254;12227,69916
40,04000;3,45589;12237,49071
40,08000;3,45924;12246,83002
40,12000;3,46259;12255,42501
40,16000;3,46588;12264,06321
40,20000;3,46917;12271,48175
40,24000;3,47251;12280,32038
40,28000;3,47580;12288,99285
40,32000;3,47915;12299,69263
40,36000;3,48250;12309,28525
40,40000;3,48591;12318,17231
40,44000;3,48914;12325,87919
40,48000;3,49248;12333,07123
40,52000;3,49589;12342,85459
40,56000;3,49924;12349,91550
40,60000;3,50253;12356,65753
40,64000;3,50594;12363,51579
40,68000;3,50928;12372,49821
40,72000;3,51257;12378,86846
40,76000;3,51586;12384,70003
40,80000;3,51921;12390,81472
40,84000;3,52256;12396,23576
40,88000;3,52591;12400,85810
40,92000;3,52901;12404,25706
40,96000;3,53254;12408,51134
41,00000;3,53589;12412,25004
41,04000;3,53912;12415,00601
41,08000;3,54247;12416,41119
41,12000;3,54588;12419,29829
41,16000;3,54922;12420,68633
41,20000;3,55251;12419,69913
41,24000;3,55592;12418,90565
41,28000;3,55927;12418,36324
41,32000;3,56250;12410,49618
41,36000;3,56585;12400,01395
41,40000;3,56925;12384,36177
41,44000;3,57248;12353,71009
41,48000;3,57583;12285,51120
41,52000;3,57978;9343,68670
41,55200;3,58360;2364,11523