File: SU - Suspension/05 - Essais/Excels essais Optimus/Test_Rotules_31_01_19/M7_2.is_tens_RawData/Specimen_RawData_1.csv
Temps;Déplacement;Charge
(sec);(mm);(N)
0,00000;10,59147;94,34685
0,04000;10,59159;93,96556
0,08000;10,59231;97,30003
0,12000;10,59350;110,47097
0,16000;10,59500;127,19379
0,20000;10,59649;142,51482
0,24000;10,59811;158,47770
0,28000;10,59960;172,68220
0,32000;10,60104;185,68626
0,36000;10,60259;200,07035
0,40000;10,60408;214,98092
0,44000;10,60546;227,14797
0,48000;10,60684;239,83419
0,52000;10,60827;253,10738
0,56000;10,60953;265,11592
0,60000;10,61078;275,33327
0,64000;10,61222;286,90305
0,68000;10,61359;299,45555
0,72000;10,61497;310,85375
0,76000;10,61628;322,49717
0,80000;10,61766;333,54645
0,84000;10,61909;343,89799
0,88000;10,62035;353,63489
0,92000;10,62154;360,60801
0,96000;10,62298;368,48199
1,00000;10,62429;376,34638
1,04000;10,62561;383,07223
1,08000;10,62692;388,92955
1,12000;10,62830;395,82341
1,16000;10,62967;402,15962
1,20000;10,63093;409,72983
1,24000;10,63219;413,97042
1,28000;10,63356;419,62792
1,32000;10,63494;426,13833
1,36000;10,63625;431,44105
1,40000;10,63757;435,99326
1,44000;10,63894;441,30636
1,48000;10,64032;446,65718
1,52000;10,64157;451,55622
1,56000;10,64283;454,93031
1,60000;10,64426;459,39516
1,64000;10,64558;463,25205
1,68000;10,64695;466,89194
1,72000;10,64827;470,32554
1,76000;10,64958;473,51620
1,80000;10,65096;477,70902
1,84000;10,65221;481,90784
1,88000;10,65353;484,06753
1,92000;10,65491;488,41559
1,96000;10,65622;491,63429
2,00000;10,65760;495,23790
2,04000;10,65891;499,46010
2,08000;10,66029;503,64486
2,12000;10,66166;508,04741
2,16000;10,66292;511,39044
2,20000;10,66417;514,39945
2,24000;10,66561;519,20046
2,28000;10,66698;523,75817
2,32000;10,66836;527,89953
2,36000;10,66967;531,56340
2,40000;10,67105;535,16831
2,44000;10,67236;538,57444
2,48000;10,67362;541,06107
2,52000;10,67494;543,41219
2,56000;10,67631;547,97996
2,60000;10,67769;550,75921
2,64000;10,67900;552,28993
2,68000;10,68032;554,15826
2,72000;10,68169;555,24274
2,76000;10,68301;556,73374
2,80000;10,68426;556,42445
2,84000;10,68558;555,76684
2,88000;10,68701;556,18109
2,92000;10,68833;555,79133
2,96000;10,68970;554,01158
3,00000;10,69102;552,71047
3,04000;10,69239;550,44894
3,08000;10,69365;548,50406
3,12000;10,69490;545,60755
3,16000;10,69628;543,48484
3,20000;10,69766;544,03208
3,24000;10,69897;542,66006
3,28000;10,70029;542,76926
3,32000;10,70166;542,30927
3,36000;10,70304;541,86587
3,40000;10,70429;540,18018
3,44000;10,70549;537,44898
3,48000;10,70692;536,77359
3,52000;10,70830;536,13107
3,56000;10,70961;533,57263
3,60000;10,71099;531,40591
3,64000;10,71236;528,90470
3,68000;10,71374;527,05682
3,72000;10,71499;523,69521
3,76000;10,71619;518,52730
3,80000;10,71762;515,86428
3,84000;10,71894;515,27573
3,88000;10,72026;509,57454
3,92000;10,72163;507,51721
3,96000;10,72301;502,63666
4,00000;10,72438;499,48124
4,04000;10,72558;494,53261
4,08000;10,72689;490,16289
4,12000;10,72833;487,93536
4,16000;10,72964;484,47922
4,20000;10,73102;479,96845
4,24000;10,73233;477,78892
4,28000;10,73371;473,32719
4,32000;10,73502;470,31105
4,36000;10,73628;468,17558
4,40000;10,73760;464,68875
4,44000;10,73903;464,21285
4,48000;10,74034;461,35639
4,52000;10,74166;457,77834
4,56000;10,74298;455,30549
4,60000;10,74429;454,25352
4,64000;10,74567;452,44331
4,68000;10,74686;450,03733
4,72000;10,74818;447,38892
4,76000;10,74961;448,15950
4,80000;10,75093;445,75171
4,84000;10,75224;443,68431
4,88000;10,75356;442,16933
4,92000;10,75493;439,45704
4,96000;10,75631;437,88478
5,00000;10,75756;436,30428
5,04000;10,75888;434,11073
5,08000;10,76031;434,57011
5,12000;10,76169;434,20424
5,16000;10,76301;434,94208
5,20000;10,76432;435,02003
5,24000;10,76570;436,13631
5,28000;10,76701;438,56381
5,32000;10,76821;438,44492
5,36000;10,76958;439,19608
5,40000;10,77096;443,29101
5,44000;10,77227;444,50671
5,48000;10,77359;445,75525
5,52000;10,77490;446,81192
5,56000;10,77628;447,60406
5,60000;10,77765;448,42768
5,64000;10,77885;448,81906
5,68000;10,78028;447,40792
5,72000;10,78166;450,06955
5,76000;10,78298;448,18558
5,80000;10,78435;446,78086
5,84000;10,78567;444,98709
5,88000;10,78704;443,84901
5,92000;10,78830;441,80611
5,96000;10,78955;437,95183
6,00000;10,79093;434,89193
6,04000;10,79230;434,60312
6,08000;10,79362;431,28720
6,12000;10,79493;429,45864
6,16000;10,79625;427,01117
6,20000;10,79762;425,24943
6,24000;10,79888;423,64160
6,28000;10,80013;419,31923
6,32000;10,80157;417,44220
6,36000;10,80294;418,12970
6,40000;10,80426;415,76196
6,44000;10,80564;415,03068
6,48000;10,80695;413,83458
6,52000;10,80839;413,15746
6,56000;10,80964;411,93599
6,60000;10,81090;408,66779
6,64000;10,81227;408,15012
6,68000;10,81365;409,48507
6,72000;10,81496;407,02550
6,76000;10,81628;406,02884
6,80000;10,81759;404,19903
6,84000;10,81897;404,80979
6,88000;10,82028;404,27344
6,92000;10,82154;403,11883
6,96000;10,82291;400,65227
7,00000;10,82429;401,71836
7,04000;10,82561;398,75996
7,08000;10,82692;398,29644
7,12000;10,82824;398,48555
7,16000;10,82961;398,14720
7,20000;10,83087;397,94929
7,24000;10,83218;396,79715
7,28000;10,83362;398,70269
7,32000;10,83499;400,35406
7,36000;10,83631;400,13911
7,40000;10,83762;400,43485
7,44000;10,83900;401,61256
7,48000;10,84031;402,27184
7,52000;10,84151;401,67710
7,56000;10,84288;401,60180
7,60000;10,84432;403,50235
7,64000;10,84563;405,21426
7,68000;10,84695;402,34998
7,72000;10,84827;400,58363
7,76000;10,84964;400,33860
7,80000;10,85096;399,56449
7,84000;10,85221;396,91543
7,88000;10,85353;396,26667
7,92000;10,85496;397,01876
7,96000;10,85634;395,16916
8,00000;10,85765;393,18735
8,04000;10,85903;390,67729
8,08000;10,86034;389,09926
8,12000;10,86166;387,80090
8,16000;10,86285;384,77271
8,20000;10,86423;384,14584
8,24000;10,86560;384,16975
8,28000;10,86692;382,79314
8,32000;10,86829;381,54530
8,36000;10,86961;380,71221
8,40000;10,87098;380,29698
8,44000;10,87230;379,51090
8,48000;10,87350;376,86934
8,52000;10,87493;376,92545
8,56000;10,87625;378,27198
8,60000;10,87756;376,51542
8,64000;10,87894;375,40223
8,68000;10,88037;375,42623
8,72000;10,88175;375,29971
8,76000;10,88294;372,74598
8,80000;10,88420;369,32244
8,84000;10,88563;370,16924
8,88000;10,88695;370,38126
8,92000;10,88832;369,07527
8,96000;10,88964;368,94942
9,00000;10,89095;367,49721
9,04000;10,89233;368,32697
9,08000;10,89359;367,70874
9,12000;10,89490;366,26749
9,16000;10,89634;367,55342
9,20000;10,89765;367,44669
9,24000;10,89897;367,23751
9,28000;10,90028;367,01215
9,32000;10,90166;368,29857
9,36000;10,90303;369,93069
9,40000;10,90429;370,68934
9,44000;10,90566;370,51120
9,48000;10,90704;373,19970
9,52000;10,90835;373,27139
9,56000;10,90967;373,58436
9,60000;10,91098;374,68695
9,64000;10,91230;373,18910
9,68000;10,91367;374,38113
9,72000;10,91487;374,95440
9,76000;10,91625;373,25914
9,80000;10,91762;374,13493
9,84000;10,91894;373,20498
9,88000;10,92031;371,53685
9,92000;10,92163;370,00314
9,96000;10,92300;368,59189
10,00000;10,92432;368,27400
10,04000;10,92551;365,78930
10,08000;10,92689;364,78424
10,12000;10,92832;365,72155
10,16000;10,92964;363,25341
10,20000;10,93101;361,19148
10,24000;10,93233;359,18860
10,28000;10,93370;358,63051
10,32000;10,93496;356,92025
10,36000;10,93616;354,69625
10,40000;10,93759;354,40021
10,44000;10,93891;355,61014
10,48000;10,94028;354,09115
10,52000;10,94160;353,33347
10,56000;10,94297;352,44778
10,60000;10,94435;351,98692
10,64000;10,94560;351,04111
10,68000;10,94686;348,94471
10,72000;10,94829;349,47598
10,76000;10,94967;350,25286
10,80000;10,95104;348,85453
10,84000;10,95242;347,74330
10,88000;10,95373;346,81933
10,92000;10,95505;345,00870
10,96000;10,95625;342,60785
11,00000;10,95750;341,48516
11,04000;10,95893;343,07889
11,08000;10,96025;344,37284
11,12000;10,96163;344,04097
11,16000;10,96294;344,20136
11,20000;10,96426;343,46797
11,24000;10,96563;343,51095
11,28000;10,96689;343,00212
11,32000;10,96814;340,70280
11,36000;10,96958;342,99437
11,40000;10,97089;343,06596
11,44000;10,97227;343,11239
11,48000;10,97358;342,29937
11,52000;10,97496;342,51295
11,56000;10,97633;342,07304
11,60000;10,97753;341,11773
11,64000;10,97885;339,59697
11,68000;10,98028;340,16261
11,72000;10,98160;340,90024
11,76000;10,98291;340,27288
11,80000;10,98423;340,43458
11,84000;10,98560;340,11905
11,88000;10,98698;339,80899
11,92000;10,98817;338,52896
11,96000;10,98955;337,33901
12,00000;10,99092;338,99285
12,04000;10,99224;337,35202
12,08000;10,99361;337,17672
12,12000;10,99493;337,20513
12,16000;10,99630;336,68149
12,20000;10,99762;336,61646
12,24000;10,99887;334,48266
12,28000;11,00025;332,76605
12,32000;11,00163;333,84985
12,36000;11,00300;331,73151
12,40000;11,00437;331,38718
12,44000;11,00569;331,11954
12,48000;11,00707;330,43511
12,52000;11,00832;330,06729
12,56000;11,00952;327,23593
12,60000;11,01095;328,04180
12,64000;11,01233;327,63646
12,68000;11,01370;327,96639
12,72000;11,01502;327,22389
12,76000;11,01633;325,53223
12,80000;11,01771;324,40536
12,84000;11,01896;323,94791
12,88000;11,02016;322,65396
12,92000;11,02159;322,61342
12,96000;11,02297;324,12135
13,00000;11,02429;323,48677
13,04000;11,02560;322,72907
13,08000;11,02698;322,42844
13,12000;11,02835;323,48323
13,16000;11,02955;322,60432
13,20000;11,03086;321,55940
13,24000;11,03230;323,31774
13,28000;11,03361;325,32765
13,32000;11,03499;324,53530
13,36000;11,03630;324,56694
13,40000;11,03768;325,03847
13,44000;11,03905;326,01689
13,48000;11,04025;324,45050
13,52000;11,04156;323,28023
13,56000;11,04294;325,39661
13,60000;11,04431;326,42938
13,64000;11,04563;325,99103
13,68000;11,04700;326,69448
13,72000;11,04838;326,54915
13,76000;11,04970;326,03648
13,80000;11,05089;324,41220
13,84000;11,05227;323,81052
13,88000;11,05364;324,37539
13,92000;11,05496;323,40304
13,96000;11,05633;322,89047
14,00000;11,05771;322,83934
14,04000;11,05908;322,78656
14,08000;11,06040;321,48829
14,12000;11,06159;319,41109
14,16000;11,06297;318,07953
14,20000;11,06428;318,39164
14,24000;11,06560;316,70078
14,28000;11,06697;316,81380
14,32000;11,06835;316,30583
14,36000;11,06967;315,59339
14,40000;11,07092;314,76382
14,44000;11,07218;311,83169
14,48000;11,07361;311,75364
14,52000;11,07493;312,71668
14,56000;11,07630;310,92388
14,60000;11,07768;310,95278
14,64000;11,07899;310,23338
14,68000;11,08037;310,03389
14,72000;11,08162;309,76408
14,76000;11,08294;307,89480
14,80000;11,08437;308,76335
14,84000;11,08569;309,44347
14,88000;11,08706;308,65395
14,92000;11,08838;307,61873
14,96000;11,08970;306,00876
15,00000;11,09101;305,57590
15,04000;11,09227;305,77597
15,08000;11,09358;306,85419
15,12000;11,09496;306,67644
15,16000;11,09627;306,45737
15,20000;11,09765;306,78466
15,24000;11,09902;305,79634
15,28000;11,10040;305,60156
15,32000;11,10171;305,20279
15,36000;11,10291;303,73512
15,40000;11,10428;303,49079
15,44000;11,10566;306,67381
15,48000;11,10697;305,95020
15,52000;11,10835;306,54483
15,56000;11,10966;306,59067
15,60000;11,11104;306,57833
15,64000;11,11236;306,00787
15,68000;11,11355;305,65248
15,72000;11,11493;305,53066
15,76000;11,11630;305,98810
15,80000;11,11762;306,22743
15,84000;11,11899;306,01141
15,88000;11,12031;305,41441
15,92000;11,12168;305,22249
15,96000;11,12300;304,75075
16,00000;11,12419;302,84894
16,04000;11,12563;302,27546
16,08000;11,12694;302,29876
16,12000;11,12832;301,35277
16,16000;11,12963;301,39762
16,20000;11,13101;300,63631
16,24000;11,13238;301,19950
16,28000;11,13364;299,67560
16,32000;11,13490;296,34186
16,36000;11,13627;297,04324
16,40000;11,13759;297,92921
16,44000;11,13890;297,69007
16,48000;11,14028;296,76158
16,52000;11,14159;297,57246
16,56000;11,14303;298,07573
16,60000;11,14428;297,36867
16,64000;11,14554;295,13263
16,68000;11,14697;296,33893
16,72000;11,14829;296,49758
16,76000;11,14966;294,78183
16,80000;11,15098;295,98784
16,84000;11,15236;295,43943
16,88000;11,15373;295,89825
16,92000;11,15493;294,67833
16,96000;11,15624;292,86514
17,00000;11,15768;293,80890
17,04000;11,15893;292,23801
17,08000;11,16031;292,28139
17,12000;11,16162;293,80135
17,16000;11,16294;292,79815
17,20000;11,16431;293,09047
17,24000;11,16551;292,73294
17,28000;11,16688;292,34504
17,32000;11,16832;293,28761
17,36000;11,16963;293,01106
17,40000;11,17101;292,17533
17,44000;11,17232;292,27287
17,48000;11,17370;292,30684
17,52000;11,17502;293,26822
17,56000;11,17621;292,43503
17,60000;11,17759;292,63373
17,64000;11,17896;293,45322
17,68000;11,18034;292,71180
17,72000;11,18165;291,97261
17,76000;11,18303;290,73968
17,80000;11,18434;289,52914
17,84000;11,18560;288,52595
17,88000;11,18679;286,12667
17,92000;11,18823;286,06388
17,96000;11,18960;286,85918
18,00000;11,19098;284,95179
18,04000;11,19229;282,75433
18,08000;11,19367;281,89558
18,12000;11,19504;280,19913
18,16000;11,19630;278,30468
18,20000;11,19756;275,86494
18,24000;11,19899;276,24432
18,28000;11,20031;276,44869
18,32000;11,20162;274,85832
18,36000;11,20300;274,19308
18,40000;11,20437;272,54031
18,44000;11,20569;273,25873
18,48000;11,20694;271,94596
18,52000;11,20820;270,29642
18,56000;11,20963;271,53858
18,60000;11,21089;271,64081
18,64000;11,21226;271,27652
18,68000;11,21358;271,84451
18,72000;11,21489;271,67441
18,76000;11,21633;272,11548
18,80000;11,21753;271,90268
18,84000;11,21890;269,18198
18,88000;11,22028;270,71037
18,92000;11,22165;272,01578
18,96000;11,22302;271,27494
19,00000;11,22434;270,79450
19,04000;11,22572;271,03052
19,08000;11,22709;271,58705
19,12000;11,22823;270,53459
19,16000;11,22960;269,38803
19,20000;11,23098;270,77531
19,24000;11,23229;271,37855
19,28000;11,23367;270,97471
19,32000;11,23492;270,88264
19,36000;11,23630;271,07117
19,40000;11,23767;273,40825
19,44000;11,23893;272,33749
19,48000;11,24031;271,71338
19,52000;11,24168;272,86024
19,56000;11,24299;273,25558
19,60000;11,24431;272,90538
19,64000;11,24569;272,60564
19,68000;11,24706;273,38348
19,72000;11,24832;273,43039
19,76000;11,24951;271,89720
19,80000;11,25095;272,91558
19,84000;11,25232;272,34836
19,88000;11,25364;270,03114
19,92000;11,25495;269,04116
19,96000;11,25627;268,79781
20,00000;11,25764;268,35860
20,04000;11,25890;268,07389
20,08000;11,26015;265,83474
20,12000;11,26159;265,94098
20,16000;11,26296;264,98057
20,20000;11,26434;263,47695
20,24000;11,26566;262,96312
20,28000;11,26697;261,35882
20,32000;11,26835;260,66459
20,36000;11,26960;259,28544
20,40000;11,27086;256,46563
20,44000;11,27235;258,55086
20,48000;11,27367;259,09927
20,52000;11,27498;255,47205
20,56000;11,27630;254,30555
20,60000;11,27773;254,62005
20,64000;11,27905;252,62188
20,68000;11,28030;251,43540
20,72000;11,28162;250,09522
20,76000;11,28299;250,87078
20,80000;11,28431;250,35548
20,84000;11,28562;249,52742
20,88000;11,28706;249,57752
20,92000;11,28838;250,22984
20,96000;11,28975;249,28455
21,00000;11,29095;245,94211
21,04000;11,29226;243,80796
21,08000;11,29364;246,66698
21,12000;11,29495;246,12686
21,16000;11,29633;246,48905
21,20000;11,29770;248,67386
21,24000;11,29902;245,10559
21,28000;11,30033;244,82673
21,32000;11,30153;243,74030
21,36000;11,30290;243,44763
21,40000;11,30428;245,81950
21,44000;11,30565;245,28406
21,48000;11,30697;243,92577
21,52000;11,30829;243,68889
21,56000;11,30972;244,11771
21,60000;11,31098;244,23767
21,64000;11,31223;242,08585
21,68000;11,31361;243,06448
21,72000;11,31498;243,39312
21,76000;11,31630;241,54352
21,80000;11,31761;240,88728
21,84000;11,31899;239,79552
21,88000;11,32036;239,85666
21,92000;11,32126;238,67437
21,96000;11,32293;239,09747
22,00000;11,32431;239,02191
22,04000;11,32562;235,96927
22,08000;11,32700;235,46969
22,12000;11,32832;234,22092
22,16000;11,32969;233,83063
22,20000;11,33101;234,22220
22,24000;11,33226;233,16471
22,28000;11,33364;232,08619
22,32000;11,33507;232,52850
22,36000;11,33639;232,33029
22,40000;11,33770;231,08369
22,44000;11,33902;230,02976
22,48000;11,34039;229,69102
22,52000;11,34171;229,86343
22,56000;11,34290;228,39594
22,60000;11,34428;227,00038
22,64000;11,34559;227,98101
22,68000;11,34691;228,42928
22,72000;11,34828;228,47550
22,76000;11,34966;229,60063
22,80000;11,35104;229,50873
22,84000;11,35229;225,89657
22,88000;11,35349;223,52703
22,92000;11,35492;224,62553
22,96000;11,35630;225,34342
23,00000;11,35761;225,22085
23,04000;11,35899;224,71093
23,08000;11,36030;224,50390
23,12000;11,36168;223,82929
23,16000;11,36299;224,28536
23,20000;11,36419;222,16807
23,24000;11,36556;222,54128
23,28000;11,36688;223,92287
23,32000;11,36825;223,80962
23,36000;11,36957;223,73802
23,40000;11,37089;224,32983
23,44000;11,37226;224,29198
23,48000;11,37358;223,34019
23,52000;11,37483;222,03003
23,56000;11,37621;221,74104
23,60000;11,37758;222,53143
23,64000;11,37896;222,21277
23,68000;11,38027;221,91594
23,72000;11,38147;221,20457
23,76000;11,38314;224,46497
23,80000;11,38434;221,70471
23,84000;11,38559;218,78618
23,88000;11,38697;219,96778
23,92000;11,38834;219,26521
23,96000;11,38966;217,88473
24,00000;11,39097;217,93377
24,04000;11,39229;216,33455
24,08000;11,39367;216,70179
24,12000;11,39492;215,60625
24,16000;11,39618;214,25623
24,20000;11,39761;214,00435
24,24000;11,39899;213,98114
24,28000;11,40030;213,16274
24,32000;11,40162;212,35526
24,36000;11,40299;211,96790
24,40000;11,40437;212,79540
24,44000;11,40556;211,44582
24,48000;11,40688;209,79070
24,52000;11,40831;210,47117
24,56000;11,40963;210,48421
24,60000;11,41094;209,30262
24,64000;11,41232;209,00809
24,68000;11,41363;209,07463
24,72000;11,41441;208,55111
24,76000;11,41633;211,81556
24,80000;11,41764;209,59396
24,84000;11,41896;207,14952
24,88000;11,42027;206,66963
24,92000;11,42159;206,82155
24,96000;11,42296;206,67585
25,00000;11,42428;206,92947
25,04000;11,42559;206,23407
25,08000;11,42685;205,24308
25,12000;11,42822;206,50749
25,16000;11,42966;207,55765
25,20000;11,43097;206,74816
25,24000;11,43235;205,94543
25,28000;11,43366;205,69228
25,32000;11,43504;206,05980
25,36000;11,43629;206,77368
25,40000;11,43755;204,85288
25,44000;11,43893;204,90864
25,48000;11,44030;207,01452
25,52000;11,44168;205,17556
25,56000;11,44299;205,16256
25,60000;11,44437;204,98580
25,64000;11,44568;205,14377
25,68000;11,44694;204,24703
25,72000;11,44819;203,01002
25,76000;11,44963;202,78119
25,80000;11,45094;203,90726
25,84000;11,45232;203,58125
25,88000;11,45339;203,00550
25,92000;11,45507;204,32076
25,96000;11,45638;202,62720
26,00000;11,45758;197,93469
26,04000;11,45890;197,47259
26,08000;11,46027;199,21467
26,12000;11,46159;198,02493
26,16000;11,46290;197,63506
26,20000;11,46422;197,26655
26,24000;11,46559;196,76897
26,28000;11,46697;197,01060
26,32000;11,46816;195,67152
26,36000;11,46954;194,74779
26,40000;11,47097;196,00855
26,44000;11,47229;195,28244
26,48000;11,47360;194,89479
26,52000;11,47492;194,20193
26,56000;11,47629;194,44181
26,60000;11,47767;194,43892
26,64000;11,47886;193,15290
26,68000;11,48030;191,83633
26,72000;11,48168;194,87697
26,76000;11,48305;193,92625
26,80000;11,48437;192,96717
26,84000;11,48568;191,32729
26,88000;11,48700;190,46726
26,92000;11,48831;191,64933
26,96000;11,48951;190,56896
27,00000;11,49100;191,10596
27,04000;11,49238;191,83251
27,08000;11,49369;190,44660
27,12000;11,49501;189,92453
27,16000;11,49638;189,74091
27,20000;11,49776;190,54565
27,24000;11,49901;189,75316
27,28000;11,50021;188,63630
27,32000;11,50164;190,03358
27,36000;11,50296;189,95479
27,40000;11,50428;189,42131
27,44000;11,50565;189,91253
27,48000;11,50703;189,52434
27,52000;11,50834;188,65574
27,56000;11,50954;188,47316
27,60000;11,51085;188,51997
27,64000;11,51229;188,96231
27,68000;11,51360;187,85683
27,72000;11,51498;187,47769
27,76000;11,51629;187,73500
27,80000;11,51767;187,15163
27,84000;11,51898;185,74119
27,88000;11,52024;184,80523
27,92000;11,52155;183,84149
27,96000;11,52299;185,35315
28,00000;11,52430;185,14832
28,04000;11,52568;183,89756
28,08000;11,52706;183,54187
28,12000;11,52837;182,57448
28,16000;11,52969;181,62421
28,20000;11,53088;180,66146
28,24000;11,53226;179,76054
28,28000;11,53363;180,95666
28,32000;11,53489;179,66820
28,36000;11,53626;179,65895
28,40000;11,53758;180,42657
28,44000;11,53895;179,96316
28,48000;11,54027;179,47213
28,52000;11,54152;177,76012
28,56000;11,54284;177,01825
28,60000;11,54421;177,72551
28,64000;11,54553;177,22083
28,68000;11,54697;177,60583
28,72000;11,54828;177,99491
28,76000;11,54972;177,50791
28,80000;11,55097;176,83709
28,84000;11,55223;175,11322
28,88000;11,55366;175,92530
28,92000;11,55498;176,34684
28,96000;11,55629;175,24963
29,00000;11,55767;174,94747
29,04000;11,55898;174,81731
29,08000;11,56036;176,10452
29,12000;11,56167;175,59660
29,16000;11,56293;173,85687
29,20000;11,56430;175,06235
29,24000;11,56562;174,41022
29,28000;11,56699;173,98094
29,32000;11,56825;174,32341
29,36000;11,56969;176,17395
29,40000;11,57100;175,11307
29,44000;11,57226;173,46182
29,48000;11,57357;172,89979
29,52000;11,57495;174,21852
29,56000;11,57632;174,09748
29,60000;11,57764;173,22453
29,64000;11,57901;172,97119
29,68000;11,58033;172,49485
29,72000;11,58170;172,92511
29,76000;11,58290;171,46727
29,80000;11,58421;170,95088
29,84000;11,58559;171,74579
29,88000;11,58696;171,98278
29,92000;11,58834;171,25212
29,96000;11,58965;170,09184
30,00000;11,59103;169,56454
30,04000;11,59235;169,48159
30,08000;11,59354;168,99997
30,12000;11,59486;167,62875
30,16000;11,59629;169,03997
30,20000;11,59761;168,26363
30,24000;11,59898;167,42506
30,28000;11,60030;167,14977
30,32000;11,60167;166,55118
30,36000;11,60299;166,40516
30,40000;11,60418;165,58098
30,44000;11,60556;165,34335
30,48000;11,60699;166,31834
30,52000;11,60831;165,23807
30,56000;11,60968;164,57730
30,60000;11,61106;164,47030
30,64000;11,61237;163,26943
30,68000;11,61363;162,48554
30,72000;11,61483;161,12104
30,76000;11,61632;162,50337
30,80000;11,61764;163,93742
30,84000;11,61895;161,30451
30,88000;11,62033;160,94765
30,92000;11,62164;160,35791
30,96000;11,62302;160,86455
31,00000;11,62427;159,51679
31,04000;11,62553;158,23058
31,08000;11,62696;158,56951
31,12000;11,62828;159,46230
31,16000;11,62965;158,16413
31,20000;11,63097;158,17231
31,24000;11,63229;158,50895
31,28000;11,63372;158,62175
31,32000;11,63492;158,65804
31,36000;11,63623;157,01408
31,40000;11,63761;158,13216
31,44000;11,63892;158,17960
31,48000;11,64024;157,71419
31,52000;11,64161;158,38242
31,56000;11,64293;157,98511
31,60000;11,64430;158,38819
31,64000;11,64550;156,83277
31,68000;11,64681;155,55590
31,72000;11,64825;157,48385
31,76000;11,64962;157,55829
31,80000;11,65094;156,69395
31,84000;11,65225;155,46356
31,88000;11,65357;154,94634
31,92000;11,65500;157,53033
31,96000;11,65626;154,89160
32,00000;11,65758;153,19686
32,04000;11,65895;154,69044
32,08000;11,66033;153,67432
32,12000;11,66170;153,83272
32,16000;11,66296;152,60619
32,20000;11,66433;152,62592
32,24000;11,66565;152,86821
32,28000;11,66690;151,86521
32,32000;11,66822;150,34009
32,36000;11,66965;152,02611
32,40000;11,67103;152,47135
32,44000;11,67234;151,10694
32,48000;11,67366;150,12758
32,52000;11,67503;149,09579
32,56000;11,67635;149,42312
32,60000;11,67755;148,31842
32,64000;11,67892;148,27454
32,68000;11,68029;149,65140
32,72000;11,68167;148,52412
32,76000;11,68299;147,65171
32,80000;11,68436;147,43288
32,84000;11,68574;147,06760
32,88000;11,68699;146,64078
32,92000;11,68819;145,06165
32,96000;11,68956;144,73951
33,00000;11,69094;145,84401
33,04000;11,69225;145,17760
33,08000;11,69363;145,03644
33,12000;11,69494;143,97731
33,16000;11,69638;143,73729
33,20000;11,69758;143,81186
33,24000;11,69883;143,28622
33,28000;11,70026;143,37421
33,32000;11,70164;144,49365
33,36000;11,70302;143,41911
33,40000;11,70433;142,94758
33,44000;11,70571;142,77904
33,48000;11,70708;142,31632
33,52000;11,70822;140,88968
33,56000;11,70953;140,71555
33,60000;11,71097;142,00852
33,64000;11,71222;142,04163
33,68000;11,71366;142,70736
33,72000;11,71497;142,73899
33,76000;11,71641;141,60422
33,80000;11,71772;141,08303
33,84000;11,71892;140,03974
33,88000;11,72029;139,95478
33,92000;11,72167;141,05351
33,96000;11,72293;140,15241
34,00000;11,72430;139,39756
34,04000;11,72568;140,38068
34,08000;11,72705;140,28323
34,12000;11,72837;140,42602
34,16000;11,72956;138,52367
34,20000;11,73094;138,34162
34,24000;11,73231;140,24117
34,28000;11,73363;138,27870
34,32000;11,73494;137,25508
34,36000;11,73632;137,51206
34,40000;11,73769;138,20898
34,44000;11,73895;137,57889
34,48000;11,74020;136,04506
34,52000;11,74158;136,49735
34,56000;11,74295;137,47402
34,60000;11,74427;135,54591
34,64000;11,74564;134,88812
34,68000;11,74702;133,94710
34,72000;11,74840;134,33236
34,76000;11,74959;132,99718
34,80000;11,75091;131,37041
34,84000;11,75228;132,05166
34,88000;11,75372;132,84867
34,92000;11,75503;133,24866
34,96000;11,75635;131,13244
35,00000;11,75772;130,86543
35,04000;11,75904;129,05720
35,08000;11,76023;127,75923
35,12000;11,76149;127,55138
35,16000;11,76293;129,80539
35,20000;11,76430;129,48025
35,24000;11,76568;128,30710
35,28000;11,76699;128,79896
35,32000;11,76837;127,33862
35,36000;11,76968;126,70755
35,40000;11,77094;126,86459
35,44000;11,77231;126,39879
35,48000;11,77369;127,69925
35,52000;11,77500;126,87492
35,56000;11,77638;126,96766
35,60000;11,77769;127,33475
35,64000;11,77907;126,76201
35,68000;11,78038;126,08898
35,72000;11,78158;125,10449
35,76000;11,78295;124,68324
35,80000;11,78427;125,04152
35,84000;11,78558;125,81355
35,88000;11,78696;126,44975
35,92000;11,78828;124,82338
35,96000;11,78965;124,78563
36,00000;11,79097;124,31723
36,04000;11,79216;122,28033
36,08000;11,79360;124,11020
36,12000;11,79491;124,43861
36,16000;11,79623;123,24876
36,20000;11,79760;123,92678
36,24000;11,79898;123,82581
36,28000;11,80035;123,46617
36,32000;11,80161;122,01082
36,36000;11,80286;120,74972
36,40000;11,80430;121,29486
36,44000;11,80561;121,30871
36,48000;11,80699;120,64249
36,52000;11,80830;119,67974
36,56000;11,80962;119,70521
36,60000;11,81100;120,13688
36,64000;11,81231;119,54680
36,68000;11,81351;117,72050
36,72000;11,81494;118,67449
36,76000;11,81632;118,48190
36,80000;11,81763;117,43773
36,84000;11,81901;116,48085
36,88000;11,82032;116,48912
36,92000;11,82170;116,56272
36,96000;11,82289;115,36910
37,00000;11,82421;114,63109
37,04000;11,82564;114,81359
37,08000;11,82702;114,57498
37,12000;11,82833;114,46447
37,16000;11,82971;114,06839
37,20000;11,83102;113,05485
37,24000;11,83234;112,90943
37,28000;11,83354;112,27342
37,29800;11,83407;111,33152