File: SU - Suspension/05 - Essais/Excels essais Optimus/Temoins et tests triangles/Triangles tests/F-R inf/FR inf rr.is_tcyclic_RawData/Specimen_RawData_1.csv
Temps;Déplacement;Charge
(sec);(mm);(N)
0,00000;169,99474;0,33979
0,00200;169,99485;0,33276
0,00600;169,99485;0,32721
0,10600;169,99653;1,63323
0,20600;170,00226;4,94453
0,30600;170,00843;3,71045
0,40600;170,01422;4,03443
0,50600;170,01955;4,08640
0,60600;170,02475;3,94152
0,70600;170,02977;3,96568
0,80600;170,03486;3,85646
0,90600;170,03970;4,07100
1,00600;170,04477;20,78694
1,10600;170,04980;57,98911
1,20600;170,05488;98,14965
1,30600;170,05984;139,01115
1,40600;170,06492;179,27127
1,50600;170,06977;218,49216
1,60600;170,07485;259,95930
1,70600;170,07986;301,47687
1,80600;170,08489;342,83670
1,90600;170,08981;385,04491
2,00600;170,09484;427,13028
2,10600;170,09974;468,55528
2,20600;170,10488;513,75316
2,30600;170,10977;555,03366
2,40600;170,11486;596,61800
2,50600;170,11987;639,00365
2,60600;170,12484;680,50413
2,70600;170,12993;723,45240
2,80600;170,13483;765,13779
2,90600;170,13978;805,21880
3,00600;170,14481;846,79872
3,10600;170,14982;888,04299
3,20600;170,15480;929,03702
3,30600;170,15975;969,24137
3,40600;170,16478;1008,50118
3,50600;170,16986;1047,45952
3,60600;170,17482;1087,02518
3,70600;170,17985;1127,02213
3,80600;170,18475;1165,09143
3,90600;170,18983;1206,17077
4,00600;170,19473;1245,51617
4,10600;170,19982;1285,72378
4,20600;170,20471;1325,43035
4,30600;170,20980;1363,62845
4,40600;170,21481;1404,13260
4,50600;170,21978;1441,78513
4,60600;170,22481;1485,90337
4,70600;170,22990;1524,07298
4,80600;170,23480;1561,91029
4,90600;170,23982;1599,97344
5,00600;170,24472;1638,87907
5,10600;170,24973;1679,28915
5,20600;170,25482;1716,58769
5,30600;170,25979;1754,32563
5,40600;170,26480;1795,06578
5,50600;170,26978;1832,33600
5,60600;170,27479;1872,66767
5,70600;170,27976;1909,97496
5,80600;170,28477;1949,46304
5,90600;170,28974;1989,10721
6,00600;170,29470;2028,02308
6,10600;170,29973;2069,08192
6,20600;170,30479;2106,92864
6,30600;170,30977;2145,44982
6,40600;170,31472;2184,42660
6,50600;170,31970;2222,54731
6,60600;170,32484;2261,33950
6,70600;170,32973;2301,35117
6,80600;170,33482;2340,40357
6,90600;170,33977;2377,83063
7,00600;170,34480;2415,85169
7,10600;170,34981;2453,08578
7,20600;170,35479;2492,36524
7,30600;170,35987;2530,52972
7,40600;170,36477;2568,24698
7,50600;170,36986;2606,38334
7,60600;170,37475;2643,22385
7,70600;170,37984;2681,12719
7,80600;170,38474;2716,89966
7,90600;170,38977;2754,13804
8,00600;170,39472;2791,93725
8,10600;170,39975;2828,83532
8,20600;170,40478;2866,88432
8,30600;170,40979;2903,44805
8,40600;170,41463;2938,13311
8,50600;170,41977;2974,59718
8,60600;170,42467;3008,25071
8,70600;170,42976;3044,64269
8,80600;170,43466;3076,34566
8,90600;170,43974;3108,61766
9,00600;170,44472;3142,21978
9,10600;170,44986;3173,78752
9,20600;170,45481;3205,61081
9,30600;170,45977;3233,55757
9,40600;170,46480;3262,45502
9,50600;170,46969;3288,82076
9,60600;170,47478;3317,44514
9,70600;170,47973;3344,16777
9,80600;170,48476;3371,85636
9,90600;170,48979;3399,92568
10,00600;170,49477;3426,34209
10,10600;170,49978;3454,31119
10,20600;170,50486;3480,78869
10,30600;170,50983;3505,37747
10,40600;170,51479;3533,95566
10,50600;170,51969;3559,94999
10,60600;170,52477;3589,95050
10,70600;170,52973;3617,63760
10,80600;170,53481;3647,88659
10,90600;170,53971;3677,72840
11,00600;170,54474;3707,76094
11,10600;170,54977;3739,13571
11,20600;170,55478;3770,45423
11,30600;170,55981;3802,40418
11,40600;170,56476;3832,83719
11,50600;170,56974;3864,64112
11,60600;170,57475;3895,72270
11,70600;170,57978;3927,82278
11,80600;170,58479;3959,42777
11,90600;170,58976;3991,08566
12,00600;170,59471;4022,51109
12,10600;170,59980;4056,47159
12,20600;170,60475;4087,69809
12,30600;170,60984;4120,00492
12,40600;170,61474;4149,58224
12,50600;170,61977;4184,16262
12,60600;170,62480;4216,78051
12,70600;170,62983;4250,12782
12,80600;170,63478;4281,43330
12,90600;170,63975;4313,78782
13,00600;170,64476;4347,92377
13,10600;170,64985;4380,91755
13,20600;170,65475;4412,07215
13,30600;170,65978;4445,46603
13,40600;170,66462;4476,92908
13,50600;170,66982;4510,14414
13,60600;170,67466;4541,01600
13,70600;170,67980;4575,49095
13,80600;170,68470;4606,77072
13,90600;170,68978;4639,37856
14,00600;170,69481;4672,44834
14,10600;170,69977;4702,83926
14,20600;170,70480;4736,20594
14,30600;170,70975;4767,34452
14,40600;170,71478;4800,59832
14,50600;170,71979;4832,66674
14,60600;170,72482;4865,10247
14,70600;170,72972;4896,45042
14,80600;170,73480;4928,13252
14,90600;170,73983;4961,81399
15,00600;170,74479;4992,34237
15,10600;170,74982;5024,62611
15,20600;170,75477;5056,49783
15,30600;170,75980;5089,94758
15,40600;170,76483;5122,12738
15,50600;170,76967;5151,20141
15,60600;170,77481;5183,74369
15,70600;170,77971;5214,55035
15,80600;170,78485;5249,00146
15,90600;170,78975;5279,64458
16,00600;170,79478;5308,80056
16,10600;170,79974;5338,85658
16,20600;170,80477;5369,10519
16,30600;170,80979;5402,75760
16,40600;170,81480;5432,84267
16,50600;170,81978;5462,37044
16,60600;170,82479;5492,05020
16,70600;170,82976;5521,83054
16,80600;170,83490;5554,71331
16,90600;170,83986;5584,56481
17,00600;170,84476;5610,76663
17,10600;170,84979;5639,80378
17,20600;170,85468;5665,49562
17,30600;170,85982;5695,08411
17,40600;170,86448;5720,54945
17,50600;170,86986;5749,99377
17,60600;170,87476;5773,24033
17,70600;170,87979;5797,55530
17,80600;170,88482;5820,00278
17,90600;170,88985;5841,26376
18,00600;170,89481;5861,87243
18,10600;170,89989;5884,37319
18,20600;170,90473;5904,12207
18,30600;170,90982;5921,37873
18,40600;170,91472;5938,26137
18,50600;170,91975;5952,87941
18,60600;170,92470;5968,57965
18,70600;170,92984;5987,95041
18,76800;170,93295;6000,05202
18,77000;170,93306;6000,51284
18,87000;170,93338;5998,90165
18,97000;170,92908;5964,02101
19,07000;170,92165;5887,61121
19,17000;170,91485;5813,02419
19,27000;170,90879;5749,72145
19,37000;170,90322;5694,92951
19,47000;170,89808;5643,58458
19,57000;170,89302;5592,70643
19,67000;170,88804;5545,49359
19,77000;170,88296;5497,50403
19,87000;170,87795;5449,92201
19,97000;170,87286;5400,63307
20,07000;170,86791;5354,59407
20,17000;170,86294;5306,94462
20,27000;170,85798;5258,69653
20,37000;170,85295;5210,94650
20,47000;170,84794;5163,98102
20,57000;170,84291;5118,67702
20,67000;170,83796;5071,74656
20,77000;170,83293;5024,18242
20,87000;170,82784;4976,16753
20,97000;170,82289;4929,13797
21,07000;170,81786;4883,92003
21,17000;170,81290;4836,94337
21,27000;170,80780;4788,78357
21,37000;170,80290;4742,43872
21,47000;170,79782;4696,55804
21,57000;170,79292;4650,85059
21,67000;170,78796;4605,13085
21,77000;170,78299;4558,46302
21,87000;170,77791;4511,14327
21,97000;170,77295;4463,75683
22,07000;170,76792;4417,48761
22,17000;170,76297;4370,41670
22,27000;170,75794;4324,51256
22,37000;170,75293;4277,96282
22,47000;170,74795;4231,84969
22,57000;170,74294;4185,36253
22,67000;170,73791;4139,53774
22,77000;170,73290;4093,48123
22,87000;170,72793;4047,65308
22,97000;170,72292;4002,49809
23,07000;170,71795;3956,54179
23,17000;170,71281;3909,76779
23,27000;170,70785;3864,24027
23,37000;170,70282;3816,28498
23,47000;170,69792;3771,11435
23,57000;170,69278;3726,01338
23,67000;170,68788;3680,57415
23,77000;170,68280;3634,52882
23,87000;170,67790;3588,12995
23,97000;170,67293;3543,79229
24,07000;170,66784;3497,54915
24,17000;170,66287;3453,33144
24,27000;170,65786;3405,81946
24,37000;170,65296;3360,53371
24,47000;170,64793;3313,70234
24,57000;170,64285;3269,77186
24,67000;170,63789;3224,41868
24,77000;170,63286;3178,11519
24,87000;170,62796;3133,32155
24,97000;170,62288;3088,21704
25,07000;170,61787;3043,02331
25,17000;170,61289;2998,05980
25,27000;170,60794;2953,38314
25,37000;170,60310;2910,27427
25,47000;170,59783;2861,22095
25,57000;170,59293;2817,29624
25,67000;170,58784;2771,77598
25,77000;170,58300;2729,19685
25,87000;170,57793;2684,70105
25,97000;170,57290;2640,16688
26,07000;170,56787;2596,57502
26,17000;170,56298;2549,97276
26,27000;170,55802;2507,49495
26,37000;170,55299;2462,73428
26,47000;170,54791;2418,91611
26,57000;170,54284;2373,43907
26,67000;170,53785;2329,40130
26,77000;170,53295;2285,59095
26,87000;170,52794;2243,95301
26,97000;170,52291;2200,46733
27,07000;170,51788;2157,89545
27,17000;170,51293;2113,85358
27,27000;170,50790;2071,99678
27,37000;170,50294;2028,81563
27,47000;170,49791;1986,62840
27,57000;170,49285;1943,76763
27,67000;170,48787;1899,92823
27,77000;170,48286;1857,28520
27,87000;170,47789;1814,61498
27,97000;170,47280;1773,71781
28,07000;170,46791;1732,33375
28,17000;170,46295;1690,90200
28,27000;170,45798;1648,45362
28,37000;170,45291;1606,31090
28,47000;170,44788;1566,65556
28,57000;170,44280;1521,93476
28,67000;170,43790;1480,71982
28,77000;170,43287;1439,37999
28,87000;170,42786;1399,15906
28,97000;170,42283;1358,84620
29,07000;170,41788;1317,95462
29,17000;170,41290;1276,47165
29,27000;170,40795;1235,04763
29,37000;170,40297;1196,92162
29,47000;170,39794;1155,30500
29,57000;170,39293;1114,34786
29,67000;170,38796;1071,99643
29,77000;170,38295;1032,60502
29,87000;170,37792;992,54176
29,97000;170,37284;954,24578
30,07000;170,36788;914,61111
30,17000;170,36298;875,20890
30,27000;170,35790;836,46849
30,37000;170,35300;799,69224
30,47000;170,34786;759,82348
30,57000;170,34288;722,35735
30,67000;170,33787;684,18244
30,77000;170,33290;645,18824
30,87000;170,32789;607,13869
30,97000;170,32286;569,88820
31,07000;170,31783;533,17868
31,17000;170,31293;496,17048
31,27000;170,30792;459,25244
31,37000;170,30289;422,80983
31,47000;170,29786;386,05940
31,57000;170,29310;351,80438
31,67000;170,28796;312,66452
31,77000;170,28293;277,91040
31,87000;170,27790;243,92654
31,97000;170,27294;209,13943
32,07000;170,26791;175,98601
32,17000;170,26288;141,25211
32,27000;170,25786;107,92892
32,37000;170,25279;72,82168
32,47000;170,24787;41,43669
32,57000;170,24292;12,34832
32,67000;170,23796;1,31626
32,77000;170,23288;1,92044
32,87000;170,22790;2,22700
32,97000;170,22289;1,92134
33,07000;170,21792;2,49356
33,17000;170,21291;1,93623
33,27000;170,20794;1,68024
33,30000;170,20639;0,49528