File: SU - Suspension/05 - Essais/Excels essais Optimus/Collage_alu_alu_31_01_19/collage6.is_tens_RawData/Specimen_RawData_1.csv
Temps;Déplacement;Charge
(sec);(mm);(N)
0,00000;-29,93212;55,07296
0,04000;-29,93164;54,99516
0,08000;-29,92943;63,10280
0,12000;-29,92614;83,85956
0,16000;-29,92249;108,27465
0,20000;-29,91849;134,08378
0,24000;-29,91472;162,04747
0,28000;-29,91101;184,11597
0,32000;-29,90737;205,10363
0,36000;-29,90372;225,24681
0,40000;-29,90013;235,72315
0,44000;-29,89660;82,92822
0,48000;-29,89314;73,00390
0,52000;-29,88979;107,19826
0,56000;-29,88632;138,24106
0,60000;-29,88297;164,08634
0,64000;-29,87962;186,04954
0,68000;-29,87634;207,37678
0,72000;-29,87293;228,05384
0,76000;-29,86970;246,83373
0,80000;-29,86629;265,28153
0,84000;-29,86294;283,53212
0,88000;-29,86001;300,59949
0,92000;-29,85625;318,93165
0,96000;-29,85296;335,27955
1,00000;-29,84967;351,78065
1,04000;-29,84632;367,38049
1,08000;-29,84291;382,57011
1,12000;-29,83968;397,81481
1,16000;-29,83634;412,62265
1,20000;-29,83299;427,29615
1,24000;-29,82964;441,63237
1,28000;-29,82635;453,65868
1,32000;-29,82288;469,16464
1,36000;-29,81959;484,71829
1,40000;-29,81631;496,56080
1,44000;-29,81296;509,07047
1,48000;-29,80961;522,31573
1,52000;-29,80632;534,00910
1,56000;-29,80303;547,13818
1,60000;-29,79962;559,88850
1,64000;-29,79628;572,50555
1,68000;-29,79293;584,21451
1,72000;-29,78964;594,53016
1,76000;-29,78635;605,91879
1,80000;-29,78294;616,22155
1,84000;-29,77966;625,56877
1,88000;-29,77637;634,02704
1,92000;-29,77296;643,38315
1,96000;-29,76961;651,97470
2,00000;-29,76638;659,16502
2,04000;-29,76297;667,96336
2,08000;-29,75957;678,16810
2,12000;-29,75634;685,07916
2,16000;-29,75299;693,40449
2,20000;-29,74958;700,73367
2,24000;-29,74635;708,80814
2,28000;-29,74300;714,58649
2,32000;-29,73966;722,92010
2,36000;-29,73631;730,84589
2,40000;-29,73302;736,96878
2,44000;-29,72967;744,81741
2,48000;-29,72632;752,35018
2,52000;-29,72298;758,82338
2,56000;-29,71969;765,45775
2,60000;-29,71628;772,29240
2,64000;-29,71293;779,38344
2,68000;-29,70964;785,23979
2,72000;-29,70623;792,41050
2,76000;-29,70295;799,67026
2,80000;-29,69960;805,08254
2,84000;-29,69625;809,71839
2,88000;-29,69302;816,17963
2,92000;-29,68961;821,67229
2,96000;-29,68626;827,43270
3,00000;-29,68298;834,81828
3,04000;-29,67963;841,44082
3,08000;-29,67622;847,31961
3,12000;-29,67299;853,87127
3,16000;-29,66964;861,61960
3,20000;-29,66624;869,44047
3,24000;-29,66295;878,81628
3,28000;-29,65960;886,39893
3,32000;-29,65625;895,31373
3,36000;-29,65284;904,38835
3,40000;-29,64961;911,76294
3,44000;-29,64627;919,51145
3,48000;-29,64286;927,75021
3,52000;-29,63957;936,09206
3,56000;-29,63634;942,76443
3,60000;-29,63293;951,35802
3,64000;-29,62964;959,15431
3,68000;-29,62630;966,09015
3,72000;-29,62295;973,48886
3,76000;-29,61960;982,51384
3,80000;-29,61625;989,92512
3,84000;-29,61296;997,26059
3,88000;-29,60967;1004,95806
3,92000;-29,60627;1012,89963
3,96000;-29,60292;1021,15376
4,00000;-29,59963;1028,16056
4,04000;-29,59622;1034,44289
4,08000;-29,59287;1041,70563
4,12000;-29,58965;1049,15369
4,16000;-29,58630;1056,54867
4,20000;-29,58301;1064,27008
4,24000;-29,57966;1072,15866
4,28000;-29,57637;1078,85590
4,32000;-29,57296;1086,56343
4,36000;-29,56962;1093,71049
4,40000;-29,56633;1099,66565
4,44000;-29,56304;1106,56545
4,48000;-29,55963;1114,93068
4,52000;-29,55634;1122,80352
4,56000;-29,55299;1128,85637
4,60000;-29,54958;1136,41117
4,64000;-29,54630;1145,50088
4,68000;-29,54295;1154,84921
4,72000;-29,53960;1165,06387
4,76000;-29,53637;1175,88872
4,80000;-29,53297;1185,27664
4,84000;-29,52961;1195,07518
4,88000;-29,52633;1204,51497
4,92000;-29,52292;1213,69269
4,96000;-29,51963;1223,31139
5,00000;-29,51634;1232,83863
5,04000;-29,51293;1241,48391
5,08000;-29,50959;1252,09121
5,12000;-29,50630;1261,25487
5,16000;-29,50289;1269,73018
5,20000;-29,49948;1280,15662
5,24000;-29,49619;1289,72773
5,28000;-29,49290;1298,08486
5,32000;-29,48962;1307,79464
5,36000;-29,48621;1317,66116
5,40000;-29,48292;1326,68959
5,44000;-29,47957;1335,81413
5,48000;-29,47622;1345,94971
5,52000;-29,47293;1356,32977
5,56000;-29,46959;1365,53524
5,60000;-29,46624;1375,52172
5,64000;-29,46289;1386,16031
5,68000;-29,45954;1394,97714
5,72000;-29,45619;1404,44804
5,76000;-29,45297;1414,23922
5,80000;-29,44956;1423,85447
5,84000;-29,44627;1433,80538
5,88000;-29,44298;1443,21797
5,92000;-29,43957;1453,26704
5,96000;-29,43622;1462,40955
6,00000;-29,43294;1471,09721
6,04000;-29,42959;1480,34180
6,08000;-29,42618;1488,78731
6,12000;-29,42289;1496,71398
6,16000;-29,41966;1504,51437
6,20000;-29,41625;1513,33036
6,24000;-29,41291;1520,14634
6,28000;-29,40962;1525,92342
6,32000;-29,40627;1531,77865
6,36000;-29,40286;1539,79296
6,40000;-29,39963;1544,28771
6,44000;-29,39634;1548,86926
6,48000;-29,39300;1555,15019
6,52000;-29,38959;1561,62279
6,56000;-29,38624;1566,06417
6,60000;-29,38295;1571,63646
6,64000;-29,37960;1578,33807
6,68000;-29,37625;1585,66516
6,72000;-29,37297;1590,24820
6,76000;-29,36968;1596,58045
6,80000;-29,36627;1604,26926
6,84000;-29,36298;1611,79416
6,88000;-29,35963;1617,99900
6,92000;-29,35634;1624,10978
6,96000;-29,35294;1631,21074
7,00000;-29,34971;1639,81374
7,04000;-29,34636;1644,69182
7,08000;-29,34301;1651,89747
7,12000;-29,33966;1658,95931
7,16000;-29,33644;1664,29803
7,20000;-29,33303;1672,43648
7,24000;-29,32968;1678,31145
7,28000;-29,32639;1683,07908
7,32000;-29,32304;1688,95740
7,36000;-29,31963;1696,03284
7,40000;-29,31623;1702,81585
7,44000;-29,31294;1707,75950
7,48000;-29,30959;1713,24518
7,52000;-29,30630;1719,14585
7,56000;-29,30295;1724,21560
7,60000;-29,29966;1730,75851
7,64000;-29,29632;1739,56193
7,68000;-29,29297;1746,60720
7,72000;-29,28998;1754,12931
7,76000;-29,28627;1764,02275
7,80000;-29,28293;1772,99101
7,84000;-29,27964;1780,04205
7,88000;-29,27629;1788,17958
7,92000;-29,27294;1796,57768
7,96000;-29,26959;1805,51633
8,00000;-29,26624;1814,27784
8,04000;-29,26295;1824,05766
8,08000;-29,25961;1834,53467
8,12000;-29,25626;1845,02322
8,16000;-29,25303;1855,25957
8,20000;-29,24950;1870,04041
8,24000;-29,24615;1879,57082
8,28000;-29,24293;1890,19032
8,32000;-29,23964;1900,27189
8,36000;-29,23623;1910,44249
8,40000;-29,23300;1922,25240
8,44000;-29,22965;1938,08619
8,48000;-29,22624;1955,27617
8,52000;-29,22290;1974,79520
8,56000;-29,21955;1991,13991
8,60000;-29,21626;2005,85630
8,64000;-29,21297;2023,13252
8,68000;-29,20956;2039,36379
8,72000;-29,20627;2054,49928
8,76000;-29,20299;2069,99928
8,80000;-29,19958;2089,45628
8,84000;-29,19623;2106,28901
8,88000;-29,19300;2122,97663
8,92000;-29,18971;2138,58020
8,96000;-29,18630;2157,43575
9,00000;-29,18296;2174,19937
9,04000;-29,17973;2189,81523
9,08000;-29,17626;2207,16782
9,12000;-29,17291;2225,70281
9,16000;-29,16968;2240,19643
9,20000;-29,16633;2256,92596
9,24000;-29,16293;2272,66755
9,28000;-29,15970;2285,91431
9,32000;-29,15635;2299,86161
9,36000;-29,15300;2314,73241
9,40000;-29,14965;2328,47463
9,44000;-29,14637;2340,87892
9,48000;-29,14302;2353,52293
9,52000;-29,13973;2366,84978
9,56000;-29,13632;2378,11208
9,60000;-29,13303;2388,13981
9,64000;-29,12968;2400,19467
9,68000;-29,12628;2412,30428
9,72000;-29,12299;2421,94403
9,76000;-29,11970;2432,70639
9,80000;-29,11635;2443,78336
9,84000;-29,11300;2453,46799
9,88000;-29,10971;2463,40018
9,92000;-29,10637;2472,23489
9,96000;-29,10296;2483,29360
10,00000;-29,09967;2492,01562
10,04000;-29,09632;2501,10086
10,08000;-29,09303;2510,81455
10,12000;-29,08963;2520,53495
10,16000;-29,08634;2530,47831
10,20000;-29,08299;2542,47766
10,24000;-29,07958;2552,54190
10,28000;-29,07629;2561,52805
10,32000;-29,07294;2570,61217
10,36000;-29,06960;2581,05434
10,40000;-29,06631;2590,34652
10,44000;-29,06302;2599,04433
10,48000;-29,05961;2608,52221
10,52000;-29,05644;2618,44043
10,56000;-29,05292;2627,96395
10,60000;-29,04956;2636,64089
10,64000;-29,04628;2645,32901
10,68000;-29,04293;2653,26388
10,72000;-29,03964;2661,57072
10,76000;-29,03629;2670,78914
10,80000;-29,03295;2680,52649
10,84000;-29,02960;2689,17847
10,88000;-29,02631;2697,01388
10,92000;-29,02296;2705,10111
10,96000;-29,01955;2714,54882
11,00000;-29,01626;2722,08862
11,04000;-29,01297;2729,65506
11,08000;-29,00957;2740,07563
11,12000;-29,00622;2747,89538
11,16000;-29,00299;2754,28072
11,20000;-28,99958;2761,59309
11,24000;-28,99623;2769,68069
11,28000;-28,99294;2777,42185
11,32000;-28,98978;2784,63811
11,36000;-28,98625;2793,94872
11,40000;-28,98296;2801,65393
11,44000;-28,97961;2808,60178
11,48000;-28,97626;2816,45153
11,52000;-28,97297;2823,68679
11,56000;-28,96963;2831,33276
11,60000;-28,96634;2838,14315
11,64000;-28,96299;2844,91014
11,68000;-28,95970;2853,09497
11,72000;-28,95629;2860,93019
11,76000;-28,95295;2869,91689
11,80000;-28,94960;2878,05926
11,84000;-28,94625;2887,57160
11,88000;-28,94320;2897,49242
11,92000;-28,93955;2910,53504
11,96000;-28,93626;2924,26609
12,00000;-28,93286;2934,95599
12,04000;-28,92963;2945,21451
12,08000;-28,92628;2956,31830
12,12000;-28,92287;2967,98330
12,16000;-28,91970;2977,90207
12,20000;-28,91629;2988,32748
12,24000;-28,91295;3001,17005
12,28000;-28,90966;3012,12445
12,32000;-28,90631;3021,54217
12,36000;-28,90296;3032,01601
12,40000;-28,89967;3042,66457
12,44000;-28,89632;3053,70335
12,48000;-28,89292;3063,81788
12,52000;-28,88963;3075,64903
12,56000;-28,88622;3086,30746
12,60000;-28,88293;3095,14701
12,64000;-28,87964;3105,17382
12,68000;-28,87624;3115,47685
12,72000;-28,87295;3125,49509
12,76000;-28,86960;3135,61447
12,80000;-28,86625;3147,21800
12,84000;-28,86290;3157,14404
12,88000;-28,85961;3165,76101
12,92000;-28,85632;3175,75708
12,96000;-28,85292;3186,06384
13,00000;-28,84957;3195,29846
13,04000;-28,84634;3202,63058
13,08000;-28,84293;3213,25734
13,12000;-28,83947;3223,70082
13,16000;-28,83618;3233,86118
13,20000;-28,83289;3248,63642
13,24000;-28,82954;3267,20588
13,28000;-28,82625;3289,09270
13,32000;-28,82296;3309,67121
13,36000;-28,81974;3331,39040
13,40000;-28,81627;3354,73642
13,44000;-28,81292;3376,30138
13,48000;-28,80963;3397,10116
13,52000;-28,80628;3419,10496
13,56000;-28,80299;3441,03798
13,60000;-28,79964;3461,93984
13,64000;-28,79636;3482,66885
13,68000;-28,79295;3502,86812
13,72000;-28,78960;3525,38899
13,76000;-28,78631;3546,02113
13,80000;-28,78291;3566,13733
13,84000;-28,77956;3589,45355
13,88000;-28,77621;3609,69976
13,92000;-28,77298;3629,61851
13,96000;-28,76993;3651,07469
14,00000;-28,76616;3674,44232
14,04000;-28,76293;3694,22249
14,08000;-28,75965;3714,14237
14,12000;-28,75624;3735,44358
14,16000;-28,75301;3755,51023
14,20000;-28,74966;3774,57365
14,24000;-28,74631;3794,04016
14,28000;-28,74296;3814,89173
14,32000;-28,73968;3834,34109
14,36000;-28,73621;3856,10275
14,40000;-28,73298;3880,54810
14,44000;-28,72963;3898,26633
14,48000;-28,72628;3918,00813
14,52000;-28,72305;3937,46123
14,56000;-28,71965;3957,62995
14,60000;-28,71630;3977,77185
14,64000;-28,71307;3997,98751
14,68000;-28,70966;4017,95730
14,72000;-28,70631;4039,13856
14,76000;-28,70303;4057,72105
14,80000;-28,69974;4076,37209
14,84000;-28,69651;4096,77885
14,88000;-28,69292;4119,67225
14,92000;-28,68969;4137,24892
14,96000;-28,68634;4155,36761
15,00000;-28,68300;4174,26787
15,04000;-28,67971;4193,27728
15,08000;-28,67636;4211,32036
15,12000;-28,67295;4231,44326
15,16000;-28,66966;4249,66775
15,20000;-28,66637;4267,33382
15,24000;-28,66291;4287,43400
15,28000;-28,65968;4308,22223
15,32000;-28,65633;4325,19130
15,36000;-28,65298;4344,02004
15,40000;-28,64969;4362,88938
15,44000;-28,64635;4380,55694
15,48000;-28,64300;4400,51369
15,52000;-28,63971;4419,60990
15,56000;-28,63636;4436,72575
15,60000;-28,63307;4456,55361
15,64000;-28,62966;4477,34222
15,68000;-28,62632;4497,03149
15,72000;-28,62297;4515,31559
15,76000;-28,61968;4533,82656
15,80000;-28,61633;4551,05156
15,84000;-28,61298;4569,87768
15,88000;-28,60969;4588,34097
15,92000;-28,60641;4606,43061
15,96000;-28,60294;4625,66726
16,00000;-28,59959;4645,43998
16,04000;-28,59636;4662,80729
16,08000;-28,59295;4680,98558
16,12000;-28,58961;4699,96445
16,16000;-28,58632;4717,66219
16,20000;-28,58303;4735,15615
16,24000;-28,57962;4753,27559
16,28000;-28,57633;4772,43066
16,32000;-28,57298;4789,94846
16,36000;-28,56970;4808,02506
16,40000;-28,56635;4827,48821
16,44000;-28,56294;4845,44076
16,48000;-28,55965;4863,60453
16,52000;-28,55630;4881,79103
16,56000;-28,55296;4899,46827
16,60000;-28,54961;4917,79633
16,64000;-28,54632;4935,86771
16,68000;-28,54303;4954,36750
16,72000;-28,53968;4972,36215
16,76000;-28,53633;4990,06994
16,80000;-28,53304;5008,87558
16,84000;-28,52964;5028,07163
16,88000;-28,52629;5046,21826
16,92000;-28,52306;5063,15306
16,96000;-28,51971;5080,88134
17,00000;-28,51630;5100,16121
17,04000;-28,51308;5118,22626
17,08000;-28,50967;5136,32186
17,12000;-28,50626;5156,21305
17,16000;-28,50297;5174,78697
17,20000;-28,49962;5192,15725
17,24000;-28,49628;5209,07976
17,28000;-28,49299;5227,73899
17,32000;-28,48970;5245,34136
17,36000;-28,48635;5262,74890
17,40000;-28,48300;5282,63152
17,44000;-28,47965;5299,96641
17,48000;-28,47636;5316,33869
17,52000;-28,47302;5335,69232
17,56000;-28,46967;5352,73664
17,60000;-28,46638;5370,82925
17,64000;-28,46303;5390,43508
17,68000;-28,45968;5408,79592
17,72000;-28,45627;5427,42088
17,76000;-28,45293;5444,68649
17,80000;-28,44964;5461,51772
17,84000;-28,44629;5479,52950
17,88000;-28,44294;5497,40940
17,92000;-28,43971;5514,55207
17,96000;-28,43636;5531,65302
18,00000;-28,43302;5549,97250
18,04000;-28,42973;5567,92580
18,08000;-28,42638;5585,80831
18,12000;-28,42297;5604,04845
18,16000;-28,41968;5622,47559
18,20000;-28,41640;5639,06059
18,24000;-28,41299;5658,48239
18,28000;-28,40964;5677,60207
18,32000;-28,40629;5694,46273
18,36000;-28,40288;5713,03107
18,40000;-28,39953;5731,03167
18,44000;-28,39625;5748,31776
18,48000;-28,39296;5764,82117
18,52000;-28,38967;5783,60073
18,56000;-28,38632;5800,97251
18,60000;-28,38303;5818,84943
18,64000;-28,37968;5837,16631
18,68000;-28,37628;5855,51187
18,72000;-28,37293;5872,81063
18,76000;-28,36970;5889,89109
18,80000;-28,36629;5909,08006
18,84000;-28,36294;5928,41133
18,88000;-28,35959;5945,55959
18,92000;-28,35631;5962,85090
18,96000;-28,35290;5981,14319
19,00000;-28,34955;5999,24400
19,04000;-28,34632;6016,00111
19,08000;-28,34297;6033,61167
19,12000;-28,33963;6052,95487
19,16000;-28,33628;6071,37419
19,20000;-28,33299;6087,28752
19,24000;-28,32964;6104,99643
19,28000;-28,32629;6123,56104
19,32000;-28,32300;6141,02073
19,36000;-28,31966;6158,89207
19,40000;-28,31631;6176,99102
19,44000;-28,31296;6195,48485
19,48000;-28,30961;6212,93262
19,52000;-28,30632;6230,29396
19,56000;-28,30286;6249,50454
19,60000;-28,29957;6268,35600
19,64000;-28,29628;6284,57591
19,68000;-28,29299;6302,93787
19,72000;-28,28958;6321,25363
19,76000;-28,28623;6339,52469
19,80000;-28,28295;6356,90019
19,84000;-28,27960;6374,41128
19,88000;-28,27619;6392,74642
19,92000;-28,27302;6408,88214
19,96000;-28,26967;6426,38281
20,00000;-28,26620;6445,30356
20,04000;-28,26291;6463,49117
20,08000;-28,25963;6478,73282
20,12000;-28,25628;6496,86903
20,16000;-28,25293;6515,42544
20,20000;-28,24964;6531,78468
20,24000;-28,24635;6548,97392
20,28000;-28,24300;6567,66444
20,32000;-28,23960;6584,29861
20,36000;-28,23631;6599,82488
20,40000;-28,23296;6618,06911
20,44000;-28,22961;6635,67260
20,48000;-28,22632;6652,20395
20,52000;-28,22298;6669,07281
20,56000;-28,21969;6685,40895
20,60000;-28,21634;6703,05714
20,64000;-28,21299;6720,21210
20,68000;-28,20988;6737,26127
20,72000;-28,20623;6756,79967
20,76000;-28,20295;6774,69596
20,80000;-28,19972;6791,36068
20,84000;-28,19631;6808,74661
20,88000;-28,19296;6826,55424
20,92000;-28,18979;6842,86878
20,96000;-28,18627;6860,52665
21,00000;-28,18292;6880,15521
21,04000;-28,17963;6897,08441
21,08000;-28,17634;6912,84984
21,12000;-28,17281;6932,52385
21,16000;-28,16959;6952,42211
21,20000;-28,16624;6967,10274
21,24000;-28,16295;6983,61173
21,28000;-28,15966;6999,98587
21,32000;-28,15631;7015,17984
21,36000;-28,15296;7033,14319
21,40000;-28,14961;7050,74668
21,44000;-28,14627;7069,89542
21,48000;-28,14292;7085,81805
21,52000;-28,13963;7102,21827
21,56000;-28,13622;7118,65872
21,60000;-28,13293;7137,28368
21,64000;-28,12959;7153,69359
21,68000;-28,12624;7170,28454
21,72000;-28,12289;7188,28961
21,76000;-28,11954;7205,32835
21,80000;-28,11625;7221,11389
21,84000;-28,11296;7237,62512
21,88000;-28,10956;7257,29764
21,92000;-28,10633;7272,52141
21,96000;-28,10304;7288,67725
22,00000;-28,09963;7306,54374
22,04000;-28,09634;7324,92730
22,08000;-28,09305;7341,37297
22,12000;-28,08971;7358,37668
22,16000;-28,08630;7378,00151
22,20000;-28,08301;7394,58650
22,24000;-28,07978;7410,75054
22,28000;-28,07619;7432,18139
22,32000;-28,07291;7452,36203
22,36000;-28,06955;7468,99620
22,40000;-28,06627;7485,03432
22,44000;-28,06292;7501,80781
22,48000;-28,05963;7520,39999
22,52000;-28,05628;7537,21595
22,56000;-28,05311;7554,45138
22,60000;-28,04953;7575,53652
22,64000;-28,04624;7595,65532
22,68000;-28,04307;7610,90443
22,72000;-28,03966;7626,91870
22,76000;-28,03631;7645,06757
22,80000;-28,03308;7661,78146
22,84000;-28,02968;7679,56972
22,88000;-28,02627;7699,28992
22,92000;-28,02304;7716,54695
22,96000;-28,01969;7733,19975
23,00000;-28,01628;7752,87896
23,04000;-28,01300;7772,33467
23,08000;-28,00971;7789,58946
23,12000;-28,00630;7806,63863
23,16000;-28,00301;7825,53554
23,20000;-27,99966;7841,76290
23,24000;-27,99637;7859,11381
23,28000;-27,99303;7878,70362
23,32000;-27,98968;7896,14916
23,36000;-27,98639;7913,24750
23,40000;-27,98292;7931,31590
23,44000;-27,97963;7951,34157
23,48000;-27,97629;7967,06155
23,52000;-27,97294;7985,03086
23,56000;-27,96965;8003,03146
23,60000;-27,96630;8020,43304
23,64000;-27,96289;8037,38609
23,68000;-27,95966;8054,88974
23,72000;-27,95632;8072,49844
23,76000;-27,95291;8090,03264
23,80000;-27,94974;8107,28073
23,84000;-27,94633;8125,24259
23,88000;-27,94292;8143,60604
23,92000;-27,93969;8160,63732
23,96000;-27,93635;8176,10323
24,00000;-27,93294;8195,32871
24,04000;-27,92959;8213,05290
24,08000;-27,92636;8229,20054
24,12000;-27,92295;8246,41585
24,16000;-27,91960;8265,97214
24,20000;-27,91638;8281,51181
24,24000;-27,91297;8298,35981
24,28000;-27,90962;8317,19339
24,32000;-27,90627;8333,68003
24,36000;-27,90304;8349,74647
24,40000;-27,89957;8368,74172
24,44000;-27,89629;8385,72457
24,48000;-27,89294;8402,66198
24,52000;-27,88965;8419,06741
24,56000;-27,88630;8437,79147
24,60000;-27,88295;8453,50549
24,64000;-27,87960;8470,48685
24,68000;-27,87638;8486,92507
24,72000;-27,87297;8504,09269
24,76000;-27,86962;8522,23337
24,80000;-27,86633;8540,04771
24,84000;-27,86299;8558,09897
24,88000;-27,85963;8575,69203
24,92000;-27,85635;8592,81197
24,96000;-27,85300;8608,21679
25,00000;-27,84959;8625,46638
25,04000;-27,84630;8642,11395
25,08000;-27,84307;8657,83244
25,12000;-27,83966;8675,26457
25,16000;-27,83632;8693,10424
25,20000;-27,83303;8709,86953
25,24000;-27,82968;8725,70649
25,28000;-27,82627;8743,28017
25,32000;-27,82304;8760,08496
25,36000;-27,81970;8775,72745
25,40000;-27,81635;8792,46742
25,44000;-27,81306;8809,82503
25,48000;-27,80971;8826,25878
25,52000;-27,80636;8842,46901
25,56000;-27,80301;8859,33861
25,60000;-27,79961;8877,90099
25,64000;-27,79632;8893,70292
25,68000;-27,79303;8910,25066
25,72000;-27,78962;8925,56235
25,76000;-27,78627;8943,31187
25,80000;-27,78298;8959,62194
25,84000;-27,77964;8976,91026
25,88000;-27,77629;8994,10099
25,92000;-27,77294;9011,13302
25,96000;-27,76965;9025,54691
26,00000;-27,76636;9043,84479
26,04000;-27,76302;9059,29208
26,08000;-27,75967;9077,90512
26,12000;-27,75626;9095,09957
26,16000;-27,75297;9112,74776
26,20000;-27,74962;9128,99375
26,24000;-27,74657;9143,17295
26,28000;-27,74287;9162,60779
26,32000;-27,73952;9180,53165
26,36000;-27,73623;9195,17279
26,40000;-27,73288;9210,73034
26,44000;-27,72953;9227,90766
26,48000;-27,72630;9243,79602
26,52000;-27,72284;9261,60216
26,56000;-27,71961;9278,21323
26,60000;-27,71626;9293,78793
26,64000;-27,71285;9309,74782
26,68000;-27,70962;9325,57136
26,72000;-27,70622;9342,35081
26,76000;-27,70281;9361,67985
26,80000;-27,69964;9375,85533
26,84000;-27,69629;9390,82801
26,88000;-27,69288;9408,99476
26,92000;-27,68954;9424,16862
26,96000;-27,68636;9438,88053
27,00000;-27,68284;9456,57864
27,04000;-27,67949;9473,10776
27,08000;-27,67626;9487,79583
27,12000;-27,67291;9503,86077
27,16000;-27,66957;9521,60507
27,20000;-27,66628;9536,63364
27,24000;-27,66305;9551,58621
27,28000;-27,65964;9568,75607
27,32000;-27,65629;9585,25911
27,36000;-27,65294;9600,81592
27,40000;-27,64966;9615,87504
27,44000;-27,64637;9632,18212
27,48000;-27,64296;9650,05830
27,52000;-27,63955;9667,19538
27,56000;-27,63632;9681,49602
27,60000;-27,63297;9695,45618
27,64000;-27,62957;9712,47479
27,68000;-27,62640;9726,01250
27,72000;-27,62311;9740,31612
27,76000;-27,61958;9758,72874
27,80000;-27,61635;9775,28170
27,84000;-27,61300;9788,44315
27,88000;-27,60960;9804,33151
27,92000;-27,60631;9820,52609
27,96000;-27,60302;9833,36270
28,00000;-27,59973;9847,97180
28,04000;-27,59626;9865,16699
28,08000;-27,59297;9879,60622
28,12000;-27,58963;9893,88227
28,16000;-27,58634;9908,78940
28,20000;-27,58293;9925,91679
28,24000;-27,57964;9939,59531
28,28000;-27,57629;9952,83350
28,32000;-27,57300;9968,09825
28,36000;-27,56966;9984,19076
28,40000;-27,56667;9998,74100
28,44000;-27,56290;10017,21323
28,48000;-27,55961;10033,91296
28,52000;-27,55626;10046,61098
28,56000;-27,55303;10060,14124
28,60000;-27,54963;10074,27573
28,64000;-27,54628;10090,07320
28,68000;-27,54305;10103,41272
28,72000;-27,53982;10117,60235
28,76000;-27,53617;10137,57288
28,80000;-27,53295;10151,26482
28,84000;-27,52960;10164,64382
28,88000;-27,52625;10177,79186
28,92000;-27,52296;10192,32422
28,96000;-27,51955;10205,22639
29,00000;-27,51620;10214,88830
29,04000;-27,51285;10234,54368
29,08000;-27,50963;10247,76325
29,12000;-27,50628;10261,58258
29,16000;-27,50293;10276,49418
29,20000;-27,49964;10290,71361
29,24000;-27,49630;10305,18040
29,28000;-27,49295;10319,79397
29,32000;-27,48966;10336,74851
29,36000;-27,48631;10349,30050
29,40000;-27,48296;10362,55956
29,44000;-27,47973;10376,07566
29,48000;-27,47633;10389,97248
29,52000;-27,47298;10404,44672
29,56000;-27,46975;10418,58420
29,60000;-27,46628;10433,27898
29,64000;-27,46293;10449,63971
29,68000;-27,45964;10461,93466
29,72000;-27,45636;10475,19743
29,76000;-27,45295;10489,77226
29,80000;-27,44966;10502,77427
29,84000;-27,44637;10515,66973
29,88000;-27,44302;10529,31845
29,92000;-27,43967;10545,54582
29,96000;-27,43639;10558,43532
30,00000;-27,43304;10571,84860
30,04000;-27,42963;10587,16178
30,08000;-27,42634;10601,40282
30,12000;-27,42299;10615,11487
30,16000;-27,41965;10629,33728
30,20000;-27,41629;10642,56057
30,24000;-27,41301;10656,70401
30,28000;-27,40972;10669,49144
30,32000;-27,40631;10685,45133
30,36000;-27,40296;10699,75197
30,40000;-27,39968;10711,81521
30,44000;-27,39639;10724,58625
30,48000;-27,39298;10738,52628
30,52000;-27,38969;10752,71443
30,56000;-27,38646;10765,21128
30,60000;-27,38305;10778,58433
30,64000;-27,37965;10793,78352
30,68000;-27,37642;10807,05151
30,72000;-27,37307;10818,99777
30,76000;-27,36966;10832,91471
30,80000;-27,36637;10846,57162
30,84000;-27,36302;10858,52534
30,88000;-27,35961;10872,60097
30,92000;-27,35627;10887,53566
30,96000;-27,35298;10899,16900
31,00000;-27,34963;10912,79835
31,04000;-27,34622;10926,19598
31,08000;-27,34299;10939,21587
31,12000;-27,33971;10952,01373
31,16000;-27,33630;10965,18114
31,20000;-27,33301;10979,52053
31,24000;-27,32966;10991,07862
31,28000;-27,32631;11003,37654
31,32000;-27,32296;11017,72785
31,36000;-27,31962;11030,84534
31,40000;-27,31627;11043,00320
31,44000;-27,31298;11057,92373
31,48000;-27,30957;11071,50912
31,52000;-27,30622;11083,96873
31,56000;-27,30299;11094,82124
31,60000;-27,29959;11108,11681
31,64000;-27,29624;11120,89232
31,68000;-27,29295;11133,70657
31,72000;-27,28966;11145,60887
31,76000;-27,28625;11158,63547
31,80000;-27,28297;11170,61675
31,84000;-27,27968;11181,85893
31,88000;-27,27633;11195,12171
31,92000;-27,27298;11209,47301
31,96000;-27,26969;11220,55501
32,00000;-27,26634;11233,84312
32,04000;-27,26288;11247,86437
32,08000;-27,25965;11259,61617
32,12000;-27,25630;11270,53946
32,16000;-27,25289;11283,91623
32,20000;-27,24960;11296,53752
32,24000;-27,24625;11308,25579
32,28000;-27,24291;11320,55596
32,32000;-27,23962;11333,27782
32,36000;-27,23627;11345,91997
32,40000;-27,23292;11357,93701
32,44000;-27,22963;11369,98236
32,48000;-27,22629;11382,13649
32,52000;-27,22300;11394,04997
32,56000;-27,21971;11406,08415
32,60000;-27,21636;11418,65924
32,64000;-27,21295;11431,61505
32,68000;-27,20966;11444,81152
32,72000;-27,20632;11456,20346
32,76000;-27,20297;11467,81072
32,80000;-27,19962;11479,59530
32,84000;-27,19639;11489,90691
32,88000;-27,19298;11502,34714
32,92000;-27,18963;11514,67115
32,96000;-27,18629;11525,65181
33,00000;-27,18294;11538,02946
33,04000;-27,17953;11549,87365
33,08000;-27,17630;11560,19196
33,12000;-27,17301;11570,35828
33,16000;-27,16961;11582,23674
33,20000;-27,16632;11594,71199
33,24000;-27,16297;11606,30882
33,28000;-27,15956;11617,53237
33,32000;-27,15627;11628,72836
33,36000;-27,15298;11639,00644
33,40000;-27,14964;11649,60042
33,44000;-27,14635;11660,80832
33,48000;-27,14300;11671,82699
33,52000;-27,13965;11683,78815
33,56000;-27,13636;11695,68598
33,60000;-27,13295;11706,07656
33,64000;-27,12961;11718,70977
33,68000;-27,12632;11729,65094
33,72000;-27,12303;11739,43579
33,76000;-27,11962;11751,39770
33,80000;-27,11627;11765,26174
33,84000;-27,11298;11773,78520
33,88000;-27,10964;11784,05359
33,92000;-27,10623;11795,68544
33,96000;-27,10300;11805,88752
34,00000;-27,09971;11816,41072
34,04000;-27,09630;11828,28397
34,08000;-27,09301;11839,44941
34,12000;-27,08967;11849,62541
34,16000;-27,08626;11860,57553
34,20000;-27,08291;11872,73562
34,24000;-27,07962;11882,75814
34,28000;-27,07627;11892,62271
34,32000;-27,07293;11904,51682
34,36000;-27,06958;11915,03629
34,40000;-27,06617;11924,46053
34,44000;-27,06294;11933,98163
34,48000;-27,05953;11943,46771
34,52000;-27,05618;11953,95291
34,56000;-27,05296;11964,03578
34,60000;-27,04961;11974,42561
34,64000;-27,04620;11986,16773
34,68000;-27,04291;11995,75216
34,72000;-27,03962;12004,43357
34,76000;-27,03627;12014,85991
34,80000;-27,03293;12025,27955
34,84000;-27,02970;12034,59501
34,88000;-27,02629;12043,97455
34,92000;-27,02294;12055,34413
34,96000;-27,01959;12063,66196
35,00000;-27,01630;12072,42534
35,04000;-27,01296;12083,39855
35,08000;-27,00967;12093,95453
35,12000;-27,00638;12101,70835
35,16000;-27,00297;12111,74950
35,20000;-26,99968;12124,02135
35,24000;-26,99628;12132,03222
35,28000;-26,99292;12140,48788
35,32000;-26,98970;12148,13516
35,36000;-26,98629;12155,99775
35,40000;-26,98294;12165,04872
35,44000;-26,97983;12171,87345
35,48000;-26,97619;12182,50841
35,52000;-26,97284;12192,15244
35,56000;-26,96961;12197,40734
35,60000;-26,96626;12200,87558
35,64000;-26,96291;12208,48486
35,68000;-26,95957;12215,20528
35,72000;-26,95658;12217,81969
35,76000;-26,95293;12226,26567
35,80000;-26,94958;12233,42419
35,84000;-26,94629;12233,80864
35,88000;-26,94300;12235,13633
35,92000;-26,93960;12236,86188
35,96000;-26,93631;12238,97561
36,00000;-26,93302;12211,05903
36,04000;-26,92961;12177,47182
36,08000;-26,92632;12142,48091
36,12000;-26,92291;12088,76371
36,16000;-26,91992;11809,50850
36,19400;-26,91496;2205,48958