File: SU - Suspension/05 - Essais/Excels essais Optimus/collage alu carbone 05_02_19/collage2.is_tens_RawData/Specimen_RawData_1.csv
Temps;Déplacement;Charge
(sec);(mm);(N)
0,00000;-0,12640;43,49116
0,04000;-0,12592;43,86879
0,08000;-0,12382;47,72495
0,12000;-0,12072;60,61695
0,16000;-0,11713;75,85587
0,20000;-0,11318;94,36582
0,24000;-0,10935;113,91668
0,28000;-0,10565;131,09948
0,32000;-0,10194;148,30474
0,36000;-0,09841;164,75880
0,40000;-0,09489;180,81286
0,44000;-0,09136;196,70685
0,48000;-0,08795;212,35601
0,52000;-0,08448;228,42770
0,56000;-0,08107;243,60879
0,60000;-0,07773;259,65380
0,64000;-0,07438;275,27206
0,68000;-0,07103;291,78618
0,72000;-0,06774;308,12067
0,76000;-0,06433;325,13714
0,80000;-0,06093;342,48885
0,84000;-0,05764;359,15505
0,88000;-0,05423;376,04847
0,92000;-0,05088;392,97654
0,96000;-0,04759;410,21421
1,00000;-0,04430;426,18522
1,04000;-0,04096;442,99117
1,08000;-0,03755;459,61658
1,12000;-0,03432;475,56157
1,16000;-0,03091;491,45157
1,20000;-0,02750;508,47260
1,24000;-0,02433;523,84930
1,28000;-0,02099;539,61393
1,32000;-0,01758;556,12493
1,36000;-0,01429;572,73908
1,40000;-0,01094;588,74120
1,44000;-0,00759;603,21419
1,48000;-0,00430;619,84584
1,52000;-0,00096;635,62244
1,56000;0,00233;650,18386
1,60000;0,00562;666,15772
1,64000;0,00903;682,33358
1,68000;0,01232;697,86487
1,72000;0,01561;713,71621
1,76000;0,01901;730,32696
1,80000;0,02236;746,54985
1,84000;0,02565;762,24706
1,88000;0,02894;777,49677
1,92000;0,03235;794,43902
1,96000;0,03569;810,04305
2,00000;0,03898;825,62454
2,04000;0,04239;841,40832
2,08000;0,04574;856,58757
2,12000;0,04897;872,09688
2,16000;0,05238;887,62334
2,20000;0,05572;902,78033
2,24000;0,05901;919,56826
2,28000;0,06242;934,97932
2,32000;0,06583;951,67719
2,36000;0,06906;968,34535
2,40000;0,07241;982,44185
2,44000;0,07575;998,51610
2,48000;0,07898;1013,83794
2,52000;0,08239;1028,40597
2,56000;0,08574;1043,96380
2,60000;0,08903;1058,46841
2,64000;0,09237;1073,18573
2,68000;0,09566;1088,32922
2,72000;0,09901;1104,09390
2,76000;0,10236;1118,48721
2,80000;0,10571;1134,01124
2,84000;0,10906;1149,54924
2,88000;0,11234;1164,05338
2,92000;0,11575;1178,89363
2,96000;0,11910;1193,20834
3,00000;0,12239;1207,94307
3,04000;0,12574;1222,79776
3,08000;0,12915;1237,09384
3,12000;0,13237;1250,72422
3,16000;0,13566;1263,50941
3,20000;0,13907;1277,98235
3,24000;0,14230;1292,13911
3,28000;0,14565;1305,37078
3,32000;0,14900;1318,64343
3,36000;0,15234;1332,98198
3,40000;0,15563;1346,56327
3,44000;0,15898;1359,28923
3,48000;0,16233;1372,23620
3,52000;0,16568;1384,77888
3,56000;0,16902;1398,17484
3,60000;0,17231;1410,25335
3,64000;0,17578;1422,45600
3,68000;0,17907;1434,09465
3,72000;0,18236;1444,72886
3,76000;0,18571;1455,58184
3,80000;0,18899;1466,67538
3,84000;0,19234;1477,10219
3,88000;0,19557;1486,80508
3,92000;0,19898;1498,49989
3,96000;0,20233;1509,55832
4,00000;0,20562;1519,33022
4,04000;0,20890;1529,18268
4,08000;0,21231;1539,22662
4,12000;0,21560;1548,58865
4,16000;0,21865;1557,23505
4,20000;0,22242;1568,72924
4,24000;0,22565;1578,63777
4,28000;0,22899;1586,11666
4,32000;0,23228;1595,18253
4,36000;0,23563;1604,23890
4,40000;0,23898;1612,36823
4,44000;0,24209;1620,72517
4,48000;0,24568;1630,94979
4,52000;0,24902;1638,86901
4,56000;0,25231;1646,20895
4,60000;0,25560;1653,12830
4,64000;0,25895;1661,35374
4,68000;0,26230;1668,64805
4,72000;0,26558;1675,54133
4,76000;0,26881;1684,31811
4,80000;0,27234;1693,65332
4,84000;0,27575;1701,89422
4,88000;0,27898;1708,12905
4,92000;0,28233;1716,03430
4,96000;0,28573;1723,13768
5,00000;0,28896;1730,37797
5,04000;0,29237;1738,65501
5,08000;0,29572;1747,60353
5,12000;0,29895;1754,51208
5,16000;0,30230;1760,43324
5,20000;0,30564;1769,38698
5,24000;0,30893;1776,94838
5,28000;0,31228;1784,29000
5,32000;0,31569;1792,21332
5,36000;0,31904;1801,53362
5,40000;0,32233;1807,74052
5,44000;0,32567;1814,90649
5,48000;0,32902;1822,40400
5,52000;0,33237;1829,40811
5,56000;0,33566;1836,68546
5,60000;0,33901;1843,86857
5,64000;0,34235;1851,82691
5,68000;0,34564;1859,42277
5,72000;0,34899;1866,04802
5,76000;0,35228;1873,56938
5,80000;0,35563;1880,19145
5,84000;0,35898;1886,83327
5,88000;0,36226;1894,53550
5,92000;0,36567;1901,78920
5,96000;0,36902;1909,22171
6,00000;0,37225;1916,55997
6,04000;0,37560;1924,10182
6,08000;0,37901;1931,64013
6,12000;0,38223;1938,59842
6,16000;0,38564;1945,72099
6,20000;0,38905;1954,39719
6,24000;0,39234;1962,22216
6,28000;0,39563;1968,55925
6,32000;0,39898;1975,56186
6,36000;0,40226;1983,28122
6,40000;0,40549;1990,26521
6,44000;0,40896;1999,04349
6,48000;0,41231;2006,82506
6,52000;0,41560;2014,24211
6,56000;0,41894;2021,42261
6,60000;0,42229;2028,59212
6,64000;0,42558;2034,97838
6,68000;0,42893;2042,57499
6,72000;0,43228;2048,99013
6,76000;0,43557;2056,86502
6,80000;0,43897;2063,61003
6,84000;0,44232;2070,73074
6,88000;0,44561;2077,46569
6,92000;0,44896;2084,12800
6,96000;0,45231;2090,84172
7,00000;0,45554;2097,30174
7,04000;0,45894;2105,07158
7,08000;0,46235;2112,02279
7,12000;0,46558;2118,90992
7,16000;0,46893;2124,40006
7,20000;0,47228;2130,52165
7,24000;0,47563;2137,39332
7,28000;0,47891;2142,20919
7,32000;0,48232;2148,50362
7,36000;0,48567;2155,26149
7,40000;0,48902;2160,69389
7,44000;0,49225;2167,00565
7,48000;0,49571;2172,60830
7,52000;0,49906;2178,83084
7,56000;0,50229;2183,91977
7,60000;0,50570;2189,62915
7,64000;0,50905;2196,43302
7,68000;0,51246;2201,62068
7,72000;0,51574;2206,87669
7,76000;0,51903;2211,05982
7,80000;0,52244;2216,03308
7,84000;0,52573;2220,64722
7,88000;0,52896;2225,78328
7,92000;0,53231;2230,43282
7,96000;0,53553;2234,87616
8,00000;0,53900;2240,58386
8,04000;0,54235;2246,87215
8,08000;0,54576;2252,73594
8,12000;0,54905;2257,04275
8,16000;0,55228;2260,80175
8,20000;0,55574;2267,82411
8,24000;0,55909;2272,91770
8,28000;0,56238;2276,29580
8,32000;0,56555;2280,20996
8,36000;0,56914;2285,78560
8,40000;0,57236;2291,08967
8,44000;0,57565;2294,23288
8,48000;0,57906;2299,99516
8,52000;0,58235;2306,43824
8,56000;0,58570;2311,20605
8,60000;0,58887;2314,90638
8,64000;0,59233;2320,36896
8,68000;0,59568;2326,41939
8,72000;0,59903;2330,89887
8,76000;0,60232;2336,07795
8,80000;0,60573;2341,23003
8,84000;0,60908;2347,06644
8,88000;0,61230;2351,66866
8,92000;0,61571;2357,28249
8,96000;0,61906;2362,10264
9,00000;0,62229;2367,97258
9,04000;0,62558;2372,18477
9,08000;0,62905;2379,28126
9,12000;0,63233;2385,29276
9,16000;0,63562;2389,87040
9,20000;0,63897;2394,65106
9,24000;0,64232;2400,76110
9,28000;0,64567;2405,62670
9,32000;0,64890;2410,36471
9,36000;0,65236;2415,62556
9,40000;0,65571;2421,64508
9,44000;0,65906;2426,06159
9,48000;0,66235;2430,43397
9,52000;0,66570;2436,11354
9,56000;0,66898;2441,51540
9,60000;0,67233;2445,94421
9,64000;0,67562;2451,52172
9,68000;0,67903;2457,91879
9,72000;0,68238;2462,55361
9,76000;0,68555;2467,61050
9,80000;0,68901;2472,73855
9,84000;0,69236;2478,02213
9,88000;0,69559;2482,99781
9,92000;0,69900;2487,45233
9,96000;0,70235;2493,98388
10,00000;0,70570;2499,98346
10,04000;0,70898;2504,42438
10,08000;0,71245;2510,71285
10,12000;0,71574;2516,19630
10,16000;0,71909;2520,99056
10,20000;0,72238;2526,15120
10,24000;0,72584;2531,04679
10,28000;0,72907;2537,58393
10,32000;0,73236;2542,68795
10,36000;0,73571;2547,75546
10,40000;0,73900;2551,24271
10,44000;0,74235;2556,00736
10,48000;0,74569;2560,48776
10,52000;0,74898;2566,22192
10,56000;0,75239;2572,75458
10,60000;0,75574;2578,03332
10,64000;0,75897;2582,56346
10,68000;0,76238;2587,56317
10,72000;0,76572;2592,68843
10,76000;0,76901;2598,09587
10,80000;0,77242;2603,19021
10,84000;0,77571;2609,89238
10,88000;0,77900;2613,87359
10,92000;0,78229;2619,12681
10,96000;0,78569;2623,85421
11,00000;0,78898;2628,99194
11,04000;0,79233;2633,56417
11,08000;0,79556;2638,26046
11,12000;0,79897;2645,75463
11,16000;0,80226;2650,35219
11,20000;0,80554;2654,68229
11,24000;0,80889;2659,25769
11,28000;0,81218;2664,17954
11,32000;0,81559;2667,61370
11,36000;0,81894;2672,88052
11,40000;0,82228;2677,79734
11,44000;0,82563;2683,15002
11,48000;0,82892;2688,00613
11,52000;0,83233;2693,86861
11,56000;0,83562;2698,95550
11,60000;0,83903;2703,49570
11,64000;0,84219;2707,58923
11,68000;0,84560;2712,98848
11,72000;0,84895;2717,83434
11,76000;0,85224;2722,92383
11,80000;0,85559;2727,25113
11,84000;0,85894;2732,82882
11,88000;0,86222;2737,55156
11,92000;0,86557;2741,67061
11,96000;0,86904;2747,41780
12,00000;0,87227;2753,16928
12,04000;0,87556;2755,99714
12,08000;0,87897;2762,17666
12,12000;0,88231;2766,93683
12,16000;0,88560;2770,30431
12,20000;0,88901;2775,59943
12,24000;0,89236;2782,44950
12,28000;0,89571;2786,88278
12,32000;0,89899;2791,69753
12,36000;0,90234;2797,66880
12,40000;0,90563;2803,29864
12,44000;0,90898;2809,20919
12,48000;0,91233;2815,28309
12,52000;0,91562;2822,50363
12,56000;0,91902;2829,54816
12,60000;0,92231;2836,31291
12,64000;0,92560;2842,37619
12,68000;0,92901;2849,00665
12,72000;0,93236;2855,10775
12,76000;0,93565;2861,83637
12,80000;0,93905;2868,19395
12,84000;0,94240;2874,08996
12,88000;0,94563;2879,75576
12,92000;0,94898;2884,96502
12,96000;0,95233;2892,00395
13,00000;0,95562;2897,53582
13,04000;0,95890;2903,58569
13,08000;0,96237;2911,18305
13,12000;0,96572;2917,96047
13,16000;0,96895;2924,67624
13,20000;0,97230;2930,94832
13,24000;0,97564;2938,01688
13,28000;0,97887;2943,86428
13,32000;0,98228;2950,34517
13,36000;0,98569;2958,40316
13,40000;0,98904;2965,79506
13,44000;0,99239;2971,73820
13,48000;0,99567;2977,75269
13,52000;0,99902;2984,23171
13,56000;1,00231;2991,04620
13,60000;1,00566;2997,05379
13,64000;1,00895;3004,54255
13,68000;1,01236;3010,64122
13,72000;1,01564;3017,19997
13,76000;1,01893;3023,23923
13,80000;1,02228;3028,47121
13,84000;1,02563;3035,35741
13,88000;1,02892;3041,90777
13,92000;1,03227;3048,08505
13,96000;1,03567;3054,45679
14,00000;1,03902;3061,07942
14,04000;1,04231;3065,86307
14,08000;1,04572;3071,46553
14,12000;1,04907;3077,75680
14,16000;1,05229;3083,16853
14,20000;1,05564;3090,71783
14,24000;1,05899;3100,79623
14,28000;1,06228;3111,38257
14,32000;1,06563;3121,93502
14,36000;1,06898;3132,86260
14,40000;1,07226;3144,99550
14,44000;1,07561;3157,49459
14,48000;1,07896;3169,30152
14,52000;1,08225;3181,95261
14,56000;1,08566;3194,74451
14,60000;1,08895;3207,95365
14,64000;1,09229;3221,50849
14,68000;1,09570;3234,89532
14,72000;1,09899;3248,53063
14,76000;1,10228;3261,87871
14,80000;1,10563;3275,69917
14,84000;1,10898;3290,84843
14,88000;1,11226;3304,88384
14,92000;1,11561;3318,32357
14,96000;1,11902;3332,36940
15,00000;1,12231;3346,96695
15,04000;1,12560;3360,17311
15,08000;1,12895;3375,09625
15,12000;1,13235;3389,46246
15,16000;1,13564;3403,98774
15,20000;1,13905;3418,68848
15,24000;1,14240;3433,25846
15,28000;1,14569;3447,28008
15,32000;1,14897;3461,30021
15,36000;1,15232;3476,35001
15,40000;1,15561;3490,32059
15,44000;1,15896;3504,42156
15,48000;1,16231;3518,36756
15,52000;1,16566;3533,56414
15,56000;1,16900;3547,29183
15,60000;1,17229;3561,00984
15,64000;1,17558;3576,16059
15,68000;1,17899;3590,06785
15,72000;1,18240;3604,19601
15,76000;1,18563;3618,42588
15,80000;1,18903;3632,32419
15,84000;1,19238;3646,94893
15,88000;1,19567;3660,32533
15,92000;1,19896;3673,08520
15,96000;1,20237;3687,68498
16,00000;1,20571;3701,79713
16,04000;1,20900;3714,87699
16,08000;1,21235;3728,54173
16,12000;1,21576;3742,87330
16,16000;1,21905;3755,81831
16,20000;1,22234;3769,57208
16,24000;1,22574;3783,10271
16,28000;1,22903;3797,75763
16,32000;1,23238;3810,13379
16,36000;1,23567;3824,03471
16,40000;1,23902;3838,05819
16,44000;1,24237;3851,10155
16,48000;1,24565;3864,42728
16,52000;1,24894;3878,60835
16,56000;1,25235;3892,86093
16,60000;1,25564;3905,11267
16,64000;1,25893;3917,99696
16,68000;1,26234;3931,37112
16,72000;1,26568;3944,75758
16,76000;1,26897;3957,61803
16,80000;1,27232;3970,79475
16,84000;1,27573;3985,19188
16,88000;1,27902;3998,93858
16,92000;1,28231;4011,38030
16,96000;1,28559;4024,48922
17,00000;1,28906;4038,01948
17,04000;1,29223;4051,24202
17,08000;1,29552;4065,04273
17,12000;1,29905;4081,44817
17,16000;1,30227;4094,69642
17,20000;1,30556;4106,03434
17,24000;1,30891;4118,61464
17,28000;1,31226;4132,84041
17,32000;1,31561;4145,46728
17,36000;1,31884;4158,35045
17,40000;1,32236;4173,23634
17,44000;1,32571;4188,29620
17,48000;1,32906;4201,89574
17,52000;1,33229;4215,11196
17,56000;1,33570;4229,54448
17,60000;1,33899;4242,68506
17,64000;1,34215;4256,34310
17,68000;1,34568;4272,63752
17,72000;1,34897;4288,40630
17,76000;1,35226;4302,22414
17,80000;1,35561;4315,93955
17,84000;1,35890;4330,33258
17,88000;1,36230;4344,77068
17,92000;1,36565;4361,03679
17,96000;1,36900;4375,48310
18,00000;1,37241;4389,75245
18,04000;1,37570;4404,10040
18,08000;1,37898;4419,10997
18,12000;1,38239;4433,78016
18,16000;1,38562;4448,88175
18,20000;1,38897;4463,06169
18,24000;1,39232;4477,71959
18,28000;1,39561;4492,49819
18,32000;1,39895;4507,91419
18,36000;1,40230;4522,29492
18,40000;1,40559;4537,20950
18,44000;1,40894;4551,65505
18,48000;1,41229;4565,96017
18,52000;1,41558;4581,32923
18,56000;1,41904;4597,70076
18,60000;1,42239;4613,10744
18,64000;1,42568;4627,60516
18,68000;1,42897;4641,25052
18,72000;1,43232;4656,17515
18,76000;1,43567;4671,91674
18,80000;1,43895;4686,83951
18,84000;1,44242;4702,66379
18,88000;1,44571;4719,43133
18,92000;1,44894;4733,17355
18,96000;1,45229;4747,02828
19,00000;1,45563;4762,08553
19,04000;1,45892;4776,57579
19,08000;1,46227;4791,32719
19,12000;1,46568;4806,92536
19,16000;1,46897;4823,64707
19,20000;1,47226;4838,06618
19,24000;1,47566;4854,17843
19,28000;1,47895;4870,07685
19,32000;1,48230;4884,33875
19,36000;1,48553;4900,27480
19,40000;1,48900;4916,96335
19,44000;1,49235;4932,94522
19,48000;1,49569;4947,63665
19,52000;1,49892;4962,75648
19,56000;1,50227;4977,05676
19,60000;1,50562;4992,26414
19,64000;1,50891;5006,40869
19,68000;1,51226;5021,56727
19,72000;1,51566;5037,39640
19,76000;1,51889;5052,92229
19,80000;1,52224;5067,82532
19,84000;1,52565;5084,19797
19,88000;1,52900;5099,23436
19,92000;1,53223;5114,36537
19,96000;1,53563;5130,48321
20,00000;1,53904;5146,36040
20,04000;1,54221;5161,40871
20,08000;1,54556;5175,82074
20,12000;1,54897;5191,99781
20,16000;1,55225;5207,82806
20,20000;1,55560;5221,13927
20,24000;1,55901;5236,72327
20,28000;1,56230;5254,09915
20,32000;1,56559;5268,60356
20,36000;1,56894;5283,56172
20,40000;1,57222;5300,44846
20,44000;1,57563;5315,26171
20,48000;1,57892;5331,11803
20,52000;1,58227;5347,27350
20,56000;1,58562;5362,53937
20,60000;1,58897;5377,55303
20,64000;1,59225;5394,38017
20,68000;1,59560;5409,22508
20,72000;1,59901;5425,16783
20,76000;1,60218;5440,65535
20,80000;1,60565;5457,92058
20,84000;1,60905;5474,23661
20,88000;1,61234;5489,34788
20,92000;1,61563;5503,64219
20,96000;1,61898;5519,42736
21,00000;1,62239;5534,73346
21,04000;1,62562;5549,22335
21,08000;1,62896;5564,06155
21,12000;1,63231;5581,29922
21,16000;1,63566;5595,53988
21,20000;1,63895;5610,20039
21,24000;1,64236;5626,28023
21,28000;1,64565;5641,14265
21,32000;1,64893;5656,68270
21,36000;1,65234;5672,30769
21,40000;1,65569;5690,25613
21,44000;1,65910;5705,47618
21,48000;1,66233;5720,32072
21,52000;1,66574;5735,95129
21,56000;1,66908;5751,22982
21,60000;1,67237;5765,09945
21,64000;1,67566;5780,29975
21,68000;1,67901;5796,19743
21,72000;1,68230;5811,14963
21,76000;1,68570;5826,23594
21,80000;1,68893;5840,40992
21,84000;1,69234;5855,89744
21,88000;1,69569;5871,94972
21,92000;1,69886;5886,41018
21,96000;1,70233;5901,42459
22,00000;1,70567;5918,46257
22,04000;1,70902;5934,36211
22,08000;1,71237;5948,69256
22,12000;1,71572;5964,76309
22,16000;1,71901;5979,52008
22,20000;1,72230;5993,55213
22,24000;1,72558;6008,23723
22,28000;1,72893;6023,52582
22,32000;1,73222;6038,74363
22,36000;1,73563;6055,63670
22,40000;1,73892;6070,91375
22,44000;1,74233;6085,97398
22,48000;1,74561;6101,11058
22,52000;1,74872;6114,91427
22,56000;1,75225;6132,13852
22,60000;1,75566;6147,49752
22,64000;1,75901;6161,95165
22,68000;1,76230;6176,62668
22,72000;1,76570;6191,51331
22,76000;1,76899;6206,95688
22,80000;1,77222;6220,96434
22,84000;1,77563;6237,21071
22,88000;1,77904;6253,49954
22,92000;1,78227;6267,75250
22,96000;1,78561;6282,41748
23,00000;1,78908;6298,33490
23,04000;1,79231;6314,99887
23,08000;1,79560;6328,76158
23,12000;1,79901;6343,95108
23,16000;1,80229;6358,85671
23,20000;1,80564;6372,80717
23,24000;1,80905;6387,42447
23,28000;1,81234;6403,98115
23,32000;1,81575;6417,56281
23,36000;1,81904;6431,12138
23,40000;1,82232;6446,33994
23,44000;1,82567;6462,49130
23,48000;1,82902;6476,80685
23,52000;1,83231;6490,60085
23,56000;1,83572;6506,00791
23,60000;1,83906;6521,99686
23,64000;1,84235;6537,10142
23,68000;1,84564;6550,38208
23,72000;1,84905;6566,60870
23,76000;1,85240;6581,28634
23,80000;1,85569;6594,38595
23,84000;1,85897;6608,99282
23,88000;1,86238;6623,01183
23,92000;1,86567;6637,48309
23,96000;1,86890;6651,81428
24,00000;1,87237;6666,65807
24,04000;1,87572;6681,49740
24,08000;1,87900;6695,16996
24,12000;1,88235;6709,32159
24,16000;1,88570;6724,48948
24,20000;1,88899;6738,30882
24,24000;1,89234;6751,89495
24,28000;1,89563;6765,67107
24,32000;1,89897;6779,92031
24,36000;1,90226;6794,41169
24,40000;1,90567;6808,94628
24,44000;1,90896;6824,07022
24,48000;1,91231;6837,30245
24,52000;1,91566;6851,85120
24,56000;1,91894;6865,70257
24,60000;1,92235;6882,99239
24,64000;1,92564;6897,34668
24,68000;1,92893;6911,28150
24,72000;1,93234;6925,16342
24,76000;1,93568;6939,84851
24,80000;1,93891;6953,21485
24,84000;1,94226;6966,23176
24,88000;1,94573;6982,05680
24,92000;1,94896;6997,17700
24,96000;1,95225;7009,72974
25,00000;1,95565;7023,65935
25,04000;1,95894;7037,93541
25,08000;1,96229;7051,60350
25,12000;1,96564;7065,15014
25,16000;1,96899;7079,47090
25,20000;1,97234;7094,05467
25,24000;1,97562;7107,30255
25,28000;1,97897;7122,10760
25,32000;1,98226;7135,18783
25,36000;1,98561;7149,63749
25,40000;1,98896;7163,49483
25,44000;1,99225;7175,35615
25,48000;1,99565;7192,64075
25,52000;1,99900;7207,18727
25,56000;2,00229;7220,96562
25,60000;2,00564;7233,90058
25,64000;2,00899;7247,15441
25,68000;2,01228;7260,36802
25,72000;2,01562;7273,92808
25,76000;2,01897;7287,99030
25,80000;2,02232;7301,85583
25,84000;2,02561;7315,77054
25,88000;2,02908;7331,49275
25,92000;2,03230;7344,52456
25,96000;2,03565;7358,00564
26,00000;2,03906;7371,98219
26,04000;2,04235;7385,36492
26,08000;2,04570;7398,24921
26,12000;2,04899;7411,53210
26,16000;2,05227;7423,59161
26,20000;2,05562;7436,98999
26,24000;2,05903;7450,31908
26,28000;2,06232;7464,88124
26,32000;2,06567;7477,63291
26,36000;2,06902;7491,20489
26,40000;2,07230;7503,95283
26,44000;2,07565;7517,55461
26,48000;2,07894;7530,86805
26,52000;2,08223;7544,52720
26,56000;2,08564;7558,83455
26,60000;2,08898;7573,18661
26,64000;2,09233;7586,18489
26,68000;2,09562;7598,87919
26,72000;2,09897;7612,20679
26,76000;2,10232;7626,57151
26,80000;2,10561;7638,56694
26,84000;2,10889;7651,96308
26,88000;2,11230;7664,38991
26,92000;2,11559;7678,00435
26,96000;2,11888;7690,99146
27,00000;2,12229;7704,24530
27,04000;2,12558;7718,24718
27,08000;2,12892;7730,39013
27,12000;2,13227;7744,38530
27,16000;2,13562;7759,14341
27,20000;2,13897;7772,26985
27,24000;2,14232;7785,12061
27,28000;2,14561;7798,20457
27,32000;2,14901;7810,24098
27,36000;2,15230;7823,91503
27,40000;2,15559;7836,73748
27,44000;2,15894;7850,07253
27,48000;2,16229;7863,18183
27,52000;2,16558;7875,82099
27,56000;2,16886;7887,73820
27,60000;2,17227;7901,11348
27,64000;2,17562;7914,77636
27,68000;2,17891;7926,42981
27,72000;2,18232;7939,75368
27,76000;2,18572;7954,25400
27,80000;2,18895;7966,41409
27,84000;2,19230;7977,70172
27,88000;2,19571;7991,12841
27,92000;2,19894;8003,68711
27,96000;2,20229;8016,10500
28,00000;2,20563;8029,71721
28,04000;2,20892;8042,43386
28,08000;2,21227;8053,69690
28,12000;2,21562;8066,20941
28,16000;2,21897;8078,77854
28,20000;2,22226;8091,63153
28,24000;2,22560;8104,72816
28,28000;2,22895;8117,42097
28,32000;2,23230;8130,16817
28,36000;2,23565;8142,74251
28,40000;2,23900;8155,16934
28,44000;2,24229;8167,40692
28,48000;2,24563;8180,18541
28,52000;2,24898;8192,66438
28,56000;2,25233;8204,86024
28,60000;2,25568;8218,60805
28,64000;2,25903;8230,49769
28,68000;2,26231;8242,73825
28,72000;2,26566;8254,82309
28,76000;2,26901;8267,69397
28,80000;2,27224;8278,77223
28,84000;2,27565;8291,05824
28,88000;2,27906;8304,62798
28,92000;2,28234;8316,80745
28,96000;2,28569;8328,34542
29,00000;2,28904;8341,16861
29,04000;2,29239;8353,43301
29,08000;2,29562;8364,81005
29,12000;2,29897;8377,27040
29,16000;2,30231;8390,73882
29,20000;2,30566;8402,76405
29,24000;2,30901;8415,04112
29,28000;2,31236;8428,08634
29,32000;2,31571;8439,83963
29,36000;2,31905;8450,94100
29,40000;2,32234;8462,79413
29,44000;2,32563;8475,28800
29,48000;2,32904;8487,80647
29,52000;2,33239;8499,72591
29,56000;2,33568;8512,79572
29,60000;2,33902;8524,17201
29,64000;2,34237;8536,00875
29,68000;2,34560;8547,30159
29,72000;2,34895;8558,71961
29,76000;2,35230;8572,82430
29,80000;2,35565;8585,22877
29,84000;2,35899;8597,14672
29,88000;2,36234;8608,98271
29,92000;2,36569;8621,05936
29,96000;2,36898;8630,98726
30,00000;2,37233;8643,72328
30,04000;2,37562;8656,23802
30,08000;2,37902;8667,62996
30,12000;2,38231;8678,80657
30,16000;2,38566;8690,76774
30,20000;2,38901;8702,93900
30,24000;2,39230;8714,65281
30,28000;2,39559;8726,07082
30,32000;2,39893;8737,87254
30,36000;2,40234;8749,78453
30,40000;2,40563;8761,07737
30,44000;2,40892;8773,49228
30,48000;2,41239;8785,81628
30,52000;2,41573;8797,44589
30,56000;2,41896;8807,73216
30,60000;2,42237;8819,95335
30,64000;2,42572;8832,12164
30,68000;2,42895;8843,16564
30,72000;2,43236;8853,44520
30,76000;2,43576;8865,11207
30,80000;2,43899;8877,62979
30,84000;2,44228;8887,62921
30,88000;2,44569;8899,38399
30,92000;2,44898;8911,33919
30,96000;2,45233;8921,67687
31,00000;2,45567;8932,13600
31,04000;2,45896;8944,27076
31,08000;2,46231;8955,35946
31,12000;2,46560;8966,48839
31,16000;2,46907;8978,26925
31,20000;2,47241;8990,77579
31,24000;2,47570;9001,35636
31,28000;2,47899;9012,14555
31,32000;2,48240;9024,57163
31,36000;2,48569;9035,44426
31,40000;2,48898;9046,27964
31,44000;2,49232;9057,74757
31,48000;2,49567;9069,36005
31,52000;2,49902;9079,81172
31,56000;2,50225;9089,96165
31,60000;2,50566;9100,99596
31,64000;2,50901;9113,16276
31,68000;2,51229;9124,30212
31,72000;2,51570;9133,66675
31,76000;2,51911;9148,00316
31,80000;2,52240;9157,69115
31,84000;2,52569;9167,52592
31,88000;2,52904;9177,83156
31,92000;2,53238;9188,71462
31,96000;2,53567;9198,79973
32,00000;2,53896;9209,70067
32,04000;2,54237;9222,56410
32,08000;2,54566;9232,71701
32,12000;2,54901;9243,15229
32,16000;2,55229;9252,85891
32,20000;2,55564;9263,61382
32,24000;2,55899;9274,21302
32,28000;2,56210;9285,92309
32,32000;2,56569;9298,32757
32,36000;2,56903;9309,58688
32,40000;2,57238;9320,39991
32,44000;2,57567;9330,56623
32,48000;2,57902;9340,01431
32,52000;2,58237;9350,99572
32,56000;2,58560;9359,46256
32,60000;2,58900;9370,75093
32,64000;2,59241;9383,32751
32,68000;2,59558;9392,98272
32,72000;2,59887;9402,65357
32,76000;2,60234;9415,47453
32,80000;2,60563;9426,02605
32,84000;2,60897;9435,59483
32,88000;2,61232;9445,83863
32,92000;2,61567;9456,38716
32,96000;2,61896;9466,20107
33,00000;2,62231;9476,18335
33,04000;2,62572;9486,44578
33,08000;2,62900;9498,17225
33,12000;2,63229;9507,93028
33,16000;2,63570;9517,86190
33,20000;2,63899;9527,62514
33,24000;2,64234;9538,08650
33,28000;2,64569;9547,82814
33,32000;2,64891;9557,82086
33,36000;2,65226;9568,48264
33,40000;2,65561;9578,22874
33,44000;2,65896;9589,88816
33,48000;2,66231;9601,74054
33,52000;2,66565;9612,16241
33,56000;2,66888;9620,85277
33,60000;2,67229;9631,09732
33,64000;2,67564;9641,27332
33,68000;2,67887;9651,84867
33,72000;2,68228;9661,44204
33,76000;2,68568;9672,90848
33,80000;2,68897;9683,47490
33,84000;2,69226;9692,03040
33,88000;2,69561;9701,63047
33,92000;2,69896;9711,98827
33,96000;2,70225;9721,34769
34,00000;2,70547;9730,63335
34,04000;2,70900;9740,76241
34,08000;2,71229;9751,59109
34,12000;2,71558;9760,24941
34,16000;2,71899;9770,71300
34,20000;2,72234;9781,12891
34,24000;2,72562;9791,09481
34,28000;2,72897;9800,26647
34,32000;2,73226;9809,60652
34,36000;2,73567;9819,90397
34,40000;2,73896;9830,32659
34,44000;2,74224;9840,02650
34,48000;2,74565;9851,07645
34,52000;2,74900;9860,72123
34,56000;2,75223;9869,65001
34,60000;2,75564;9879,73958
34,64000;2,75899;9890,15996
34,68000;2,76227;9899,53503
34,72000;2,76562;9908,21049
34,76000;2,76897;9918,63012
34,80000;2,77232;9927,78763
34,84000;2,77561;9937,34449
34,88000;2,77896;9947,02056
34,92000;2,78236;9958,26945
34,96000;2,78565;9967,97904
35,00000;2,78900;9976,87355
35,04000;2,79235;9986,89383
35,08000;2,79570;9995,29511
35,12000;2,79899;10005,49495
35,16000;2,80239;10016,63357
35,20000;2,80568;10026,30889
35,24000;2,80903;10035,49844
35,28000;2,81238;10044,30726
35,32000;2,81567;10053,61825
35,36000;2,81901;10062,64910
35,40000;2,82236;10072,59116
35,44000;2,82559;10081,56016
35,48000;2,82900;10090,81751
35,52000;2,83235;10100,31328
35,56000;2,83558;10109,80904
35,60000;2,83898;10118,17977
35,64000;2,84227;10128,15908
35,68000;2,84550;10137,72711
35,72000;2,84891;10147,84500
35,76000;2,85232;10158,67367
35,80000;2,85567;10168,22830
35,84000;2,85895;10176,28387
35,88000;2,86230;10186,51426
35,92000;2,86571;10196,65003
35,96000;2,86888;10204,94998
36,00000;2,87229;10214,56271
36,04000;2,87564;10225,69388
36,08000;2,87898;10234,95570
36,12000;2,88227;10244,17356
36,16000;2,88562;10253,08818
36,20000;2,88897;10263,35508
36,24000;2,89232;10272,69959
36,28000;2,89560;10280,75591
36,32000;2,89895;10290,85144
36,36000;2,90236;10301,68906
36,40000;2,90565;10310,76610
36,44000;2,90906;10321,49494
36,48000;2,91241;10330,90353
36,52000;2,91575;10338,71174
36,56000;2,91898;10347,49299
36,60000;2,92227;10355,52472
36,64000;2,92568;10364,59431
36,68000;2,92891;10374,15937
36,72000;2,93232;10384,62147
36,76000;2,93566;10394,47784
36,80000;2,93907;10404,11890
36,84000;2,94224;10412,32571
36,88000;2,94571;10421,18743
36,92000;2,94906;10433,36168
36,96000;2,95241;10441,69739
37,00000;2,95569;10449,71570
37,04000;2,95910;10458,20415
37,08000;2,96245;10468,77280
37,12000;2,96562;10477,49892
37,16000;2,96909;10487,24055
37,20000;2,97237;10496,98666
37,24000;2,97572;10505,44679
37,28000;2,97907;10514,18781
37,32000;2,98236;10523,47422
37,36000;2,98571;10532,88877
37,40000;2,98906;10541,41000
37,44000;2,99228;10550,29705
37,48000;2,99563;10558,00244
37,52000;2,99904;10568,17621
37,56000;3,00233;10577,50657
37,60000;3,00568;10585,44591
37,64000;3,00909;10594,78894
37,68000;3,01237;10605,69286
37,72000;3,01566;10612,06087
37,76000;3,01901;10620,96730
37,80000;3,02236;10631,42568
37,84000;3,02565;10637,79220
37,88000;3,02894;10645,44022
37,92000;3,03234;10656,42461
37,96000;3,03563;10665,07325
38,00000;3,03892;10673,03121
38,04000;3,04233;10680,78503
38,08000;3,04568;10690,41342
38,12000;3,04897;10698,83928
38,16000;3,05231;10706,61098
38,20000;3,05560;10715,28271
38,24000;3,05895;10723,98648
38,28000;3,06224;10731,65163
38,32000;3,06553;10739,61705
38,36000;3,06893;10748,53092
38,40000;3,07234;10758,65477
38,44000;3,07551;10767,00389
38,48000;3,07898;10775,08256
38,52000;3,08233;10784,79141
38,56000;3,08562;10793,27539
38,60000;3,08890;10800,39889
38,64000;3,09237;10810,48027
38,68000;3,09566;10819,29728
38,72000;3,09883;10826,04155
38,76000;3,10242;10835,98956
38,80000;3,10571;10844,40425
38,84000;3,10899;10851,97777
38,88000;3,11234;10860,89462
38,92000;3,11575;10869,15061
38,96000;3,11898;10879,53895
39,00000;3,12233;10887,48500
39,04000;3,12573;10894,32910
39,08000;3,12902;10902,45917
39,12000;3,13231;10910,36871
39,16000;3,13572;10917,95564
39,20000;3,13895;10926,72572
39,24000;3,14242;10936,25352
39,28000;3,14576;10944,97517
39,32000;3,14893;10952,39595
39,36000;3,15234;10959,51572
39,40000;3,15575;10968,10624
39,44000;3,15898;10976,10220
39,48000;3,16233;10983,41644
39,52000;3,16573;10992,78256
39,56000;3,16902;11001,45355
39,60000;3,17225;11008,57854
39,64000;3,17572;11017,30764
39,68000;3,17901;11025,30211
39,72000;3,18236;11032,74301
39,76000;3,18546;11040,97441
39,80000;3,18911;11051,51027
39,84000;3,19240;11059,19108
39,88000;3,19575;11067,34425
39,92000;3,19904;11074,60335
39,96000;3,20233;11082,29384
40,00000;3,20567;11089,12453
40,04000;3,20896;11096,51774
40,08000;3,21225;11105,70505
40,12000;3,21566;11113,58777
40,16000;3,21901;11122,46588
40,20000;3,22229;11129,52903
40,24000;3,22570;11137,70530
40,28000;3,22905;11146,48879
40,32000;3,23228;11153,98109
40,36000;3,23569;11160,65085
40,40000;3,23904;11168,84574
40,44000;3,24226;11175,30614
40,48000;3,24561;11182,80813
40,52000;3,24902;11192,52890
40,56000;3,25231;11199,71201
40,60000;3,25560;11207,18345
40,64000;3,25895;11214,91790
40,68000;3,26229;11223,28863
40,72000;3,26558;11230,86214
40,76000;3,26893;11238,50122
40,80000;3,27228;11246,19767
40,84000;3,27557;11254,12211
40,88000;3,27892;11261,40431
40,92000;3,28232;11271,12955
40,96000;3,28561;11279,17916
41,00000;3,28896;11286,39653
41,04000;3,29237;11294,64358
41,08000;3,29560;11303,48668
41,12000;3,29900;11310,36580
41,16000;3,30229;11317,23225
41,20000;3,30558;11325,77658
41,24000;3,30899;11332,70636
41,28000;3,31228;11339,87233
41,32000;3,31551;11347,14559
41,36000;3,31897;11355,69289
41,40000;3,32232;11363,32154
41,44000;3,32555;11370,29156
41,48000;3,32896;11377,15802
41,52000;3,33231;11385,83273
41,56000;3,33566;11393,13504
41,60000;3,33894;11399,00908
41,64000;3,34229;11407,18833
41,68000;3,34570;11415,65666
41,72000;3,34899;11422,42923
41,76000;3,35234;11430,92737
41,80000;3,35574;11439,52385
41,84000;3,35897;11445,72198
41,88000;3,36232;11451,58410
41,92000;3,36567;11460,83400
41,96000;3,36896;11467,48364
42,00000;3,37225;11474,07666
42,04000;3,37565;11482,56138
42,08000;3,37900;11491,47823
42,12000;3,38235;11498,59205
42,16000;3,38564;11505,25138
42,20000;3,38899;11511,98149
42,24000;3,39240;11519,92232
42,28000;3,39568;11527,74841
42,32000;3,39897;11535,36513
42,36000;3,40238;11542,91555
42,40000;3,40573;11550,06438
42,44000;3,40902;11556,54490
42,48000;3,41237;11563,53578
42,52000;3,41571;11571,84318
42,56000;3,41906;11579,09855
42,60000;3,42229;11586,61246
42,64000;3,42570;11594,19268
42,68000;3,42905;11602,67293
42,72000;3,43234;11609,11098
42,76000;3,43568;11615,36947
42,80000;3,43903;11623,37363
42,84000;3,44232;11630,53364
42,88000;3,44561;11636,57010
42,92000;3,44902;11644,52881
42,96000;3,45231;11651,75736
43,00000;3,45565;11658,59848
43,04000;3,45900;11665,69293
43,08000;3,46223;11672,94607
43,12000;3,46564;11680,07478
43,16000;3,46893;11686,92186
43,20000;3,47222;11694,28974
43,24000;3,47562;11701,51383
43,28000;3,47891;11708,27150
43,32000;3,48226;11715,48516
43,36000;3,48561;11721,41284
43,40000;3,48896;11728,09675
43,44000;3,49224;11734,84251
43,48000;3,49553;11741,41616
43,52000;3,49894;11749,27801
43,56000;3,50229;11756,26218
43,60000;3,50558;11762,82912
43,64000;3,50905;11770,66937
43,68000;3,51239;11777,93145
43,72000;3,51562;11783,94482
43,76000;3,51903;11790,07739
43,80000;3,52238;11797,70082
43,84000;3,52567;11804,88989
43,88000;3,52901;11811,25641
43,92000;3,53242;11818,11839
43,96000;3,53565;11824,96995
44,00000;3,53894;11830,62270
44,04000;3,54229;11837,22317
44,08000;3,54558;11844,72591
44,12000;3,54904;11850,72288
44,16000;3,55233;11857,62212
44,20000;3,55568;11864,91400
44,24000;3,55909;11871,85869
44,28000;3,56238;11878,93450
44,32000;3,56573;11884,67517
44,36000;3,56907;11892,40590
44,40000;3,57242;11899,23659
44,44000;3,57577;11904,77386
44,48000;3,57906;11910,11891
44,52000;3,58241;11917,52404
44,56000;3,58576;11923,91217
44,60000;3,58892;11929,68786
44,64000;3,59233;11937,12205
44,68000;3,59574;11943,86408
44,72000;3,59897;11949,87595
44,76000;3,60232;11956,02193
44,80000;3,60572;11962,72448
44,84000;3,60901;11969,38232
44,88000;3,61230;11974,99260
44,92000;3,61571;11981,02012
44,96000;3,61906;11989,01758
45,00000;3,62241;11995,08756
45,04000;3,62575;12000,91243
45,08000;3,62904;12006,75964
45,12000;3,63239;12012,27456
45,16000;3,63568;12018,57403
45,20000;3,63891;12024,92118
45,24000;3,64232;12032,20487
45,28000;3,64560;12039,04822
45,32000;3,64895;12045,48851
45,36000;3,65224;12051,07868
45,40000;3,65565;12057,60092
45,44000;3,65900;12063,91975
45,48000;3,66223;12069,20147
45,52000;3,66563;12074,62624
45,56000;3,66904;12082,37261
45,60000;3,67233;12087,66773
45,64000;3,67568;12093,00384
45,68000;3,67909;12101,92591
45,72000;3,68232;12107,53992
45,76000;3,68560;12113,13382
45,80000;3,68907;12120,83399
45,84000;3,69236;12127,54473
45,88000;3,69565;12131,70737
45,92000;3,69894;12136,76259
45,96000;3,70228;12143,18722
46,00000;3,70563;12150,00227
46,04000;3,70892;12155,24748
46,08000;3,71227;12161,26978
46,12000;3,71562;12166,80855
46,16000;3,71897;12174,04380
46,20000;3,72237;12179,59374
46,24000;3,72572;12186,79994
46,28000;3,72901;12192,16734
46,32000;3,73236;12197,65246
46,36000;3,73559;12201,17658
46,40000;3,73906;12208,22260
46,44000;3,74240;12216,14480
46,48000;3,74569;12219,92597
46,52000;3,74898;12223,82933
46,56000;3,75239;12228,46359
46,60000;3,75538;12233,07550
46,64000;3,75903;12240,77418
46,68000;3,76243;12246,26899
46,72000;3,76572;12250,49123
46,76000;3,76907;12255,04354
46,80000;3,77248;12259,86853
46,84000;3,77571;12263,36211
46,88000;3,77900;12267,43311
46,92000;3,78234;12271,83342
46,96000;3,78563;12276,84841
47,00000;3,78904;12281,12504
47,04000;3,79239;12285,72279
47,08000;3,79562;12288,74624
47,12000;3,79902;12291,91944
47,16000;3,80237;12294,72756
47,20000;3,80566;12296,84949
47,24000;3,80901;12299,34767
47,28000;3,81236;12302,93438
47,32000;3,81571;12304,25611
47,36000;3,81899;12303,74053
47,40000;3,82228;12303,89699
47,44000;3,82569;12303,87837
47,48000;3,82892;12301,55453
47,52000;3,83233;12298,79111
47,56000;3,83573;12298,51320
47,60000;3,83902;12290,24529
47,64000;3,84237;12278,06211
47,68000;3,84572;12259,44385
47,72000;3,84901;12224,65932
47,76000;3,85230;10877,68227
47,79800;3,85732;2254,70848