File: SU - Suspension/05 - Essais/Excels essais Optimus/Test_Rotules_31_01_19/K7_3.is_tens_RawData/Specimen_RawData_1.csv
Temps;Déplacement;Charge
(sec);(mm);(N)
0,00000;-0,10367;72,57628
0,06000;-0,10302;72,55464
0,12000;-0,10122;82,76294
0,18000;-0,09901;93,38044
0,24000;-0,09656;106,21169
0,30000;-0,09429;117,62709
0,36000;-0,09208;127,95579
0,42000;-0,09004;138,73503
0,48000;-0,08795;148,00491
0,54000;-0,08592;158,06279
0,60000;-0,08388;167,11972
0,66000;-0,08179;176,85306
0,72000;-0,07988;186,24795
0,78000;-0,07797;194,32642
0,84000;-0,07587;198,53818
0,90000;-0,07378;194,23020
0,96000;-0,07175;196,19903
1,02000;-0,06977;200,85366
1,08000;-0,06792;204,10288
1,14000;-0,06583;209,74597
1,20000;-0,06386;215,53184
1,26000;-0,06188;221,04487
1,32000;-0,05979;227,95903
1,38000;-0,05794;230,39177
1,44000;-0,05584;235,69730
1,50000;-0,05387;236,71272
1,56000;-0,05184;234,13829
1,62000;-0,04974;229,06796
1,68000;-0,04789;223,22666
1,74000;-0,04586;220,11232
1,80000;-0,04383;216,87951
1,86000;-0,04185;213,31059
1,92000;-0,03982;209,96314
1,98000;-0,03791;207,37674
2,04000;-0,03593;205,63803
2,10000;-0,03384;205,21272
2,16000;-0,03187;203,11559
2,22000;-0,02983;202,28883
2,28000;-0,02780;201,77013
2,34000;-0,02595;199,77451
2,40000;-0,02386;201,59872
2,46000;-0,02182;200,17729
2,52000;-0,01985;200,60085
2,58000;-0,01776;200,64809
2,64000;-0,01590;199,75370
2,70000;-0,01387;199,98290
2,76000;-0,01184;198,85504
2,82000;-0,00981;198,37490
2,88000;-0,00783;197,56735
2,94000;-0,00592;196,65842
3,00000;-0,00383;197,00264
3,06000;-0,00179;194,88011
3,12000;0,00018;195,61017
3,18000;0,00215;195,08542
3,24000;0,00407;192,59485
3,30000;0,00604;191,86601
3,36000;0,00807;192,00194
3,42000;0,01010;190,78413
3,48000;0,01208;189,13675
3,54000;0,01411;187,99277
3,60000;0,01596;185,83296
3,66000;0,01812;185,53354
3,72000;0,02015;183,60696
3,78000;0,02218;181,96595
3,84000;0,02421;181,08296
3,90000;0,02607;180,43559
3,96000;0,02816;180,02057
4,02000;0,03013;178,82307
4,08000;0,03211;179,38063
4,14000;0,03420;179,62600
4,20000;0,03605;178,46690
4,26000;0,03809;178,22697
4,32000;0,04018;178,71246
4,38000;0,04221;179,49194
4,44000;0,04424;178,32877
4,50000;0,04616;178,90636
4,56000;0,04807;178,30429
4,62000;0,05016;179,76668
4,68000;0,05220;179,52131
4,74000;0,05417;179,38740
4,80000;0,05620;180,29433
4,86000;0,05800;179,59976
4,92000;0,06015;180,78550
4,98000;0,06212;180,74191
5,04000;0,06415;180,08902
5,10000;0,06619;181,03438
5,16000;0,06804;179,27272
5,22000;0,07019;180,91442
5,28000;0,07217;180,20340
5,34000;0,07420;180,00411
5,40000;0,07623;179,74013
5,46000;0,07814;178,78066
5,52000;0,08012;177,79235
5,58000;0,08215;177,38183
5,64000;0,08418;176,45096
5,70000;0,08616;174,60875
5,76000;0,08813;174,57177
5,82000;0,09010;173,38549
5,88000;0,09220;173,97841
5,94000;0,09423;172,95245
6,00000;0,09626;171,87492
6,06000;0,09829;171,21071
6,12000;0,10009;170,72492
6,18000;0,10218;171,51361
6,24000;0,10415;170,69525
6,30000;0,10619;171,45034
6,36000;0,10822;171,54122
6,42000;0,11007;170,02467
6,48000;0,11217;170,79812
6,54000;0,11414;169,35909
6,60000;0,11617;168,76407
6,66000;0,11820;168,58979
6,72000;0,12012;168,19122
6,78000;0,12215;168,29660
6,84000;0,12418;167,74344
6,90000;0,12616;167,38521
6,96000;0,12819;166,81756
7,02000;0,13010;167,35480
7,08000;0,13207;168,10113
7,14000;0,13411;169,03097
7,20000;0,13614;168,29312
7,26000;0,13823;168,06582
7,32000;0,14021;168,42645
7,38000;0,14212;166,73524
7,44000;0,14421;167,38290
7,50000;0,14625;166,59604
7,56000;0,14822;165,87933
7,62000;0,15019;166,46305
7,68000;0,15204;164,64546
7,74000;0,15420;165,58692
7,80000;0,15617;163,23345
7,86000;0,15814;163,81844
7,92000;0,16024;162,25865
7,98000;0,16209;162,91641
8,04000;0,16412;162,16116
8,10000;0,16615;162,04586
8,16000;0,16819;161,16967
8,22000;0,17022;161,35559
8,28000;0,17207;159,98932
8,34000;0,17405;160,91432
8,40000;0,17608;161,10337
8,46000;0,17811;160,17554
8,52000;0,18015;160,31621
8,58000;0,18218;160,46428
8,64000;0,18403;159,55495
8,70000;0,18612;161,86028
8,76000;0,18816;161,19328
8,82000;0,19019;160,95956
8,88000;0,19228;160,99932
8,94000;0,19408;159,09115
9,00000;0,19617;160,26965
9,06000;0,19814;160,06355
9,12000;0,20018;159,90706
9,18000;0,20221;159,57586
9,24000;0,20406;159,35164
9,30000;0,20615;160,52652
9,36000;0,20819;159,75321
9,42000;0,21016;159,58952
9,48000;0,21219;159,29329
9,54000;0,21417;158,42562
9,60000;0,21614;158,18824
9,66000;0,21817;158,61741
9,72000;0,22014;158,06651
9,78000;0,22218;158,67421
9,84000;0,22415;157,74755
9,90000;0,22606;156,95445
9,96000;0,22816;156,49658
10,02000;0,23013;155,73748
10,08000;0,23210;155,66751
10,14000;0,23420;155,91116
10,20000;0,23605;155,44060
10,26000;0,23814;154,71176
10,32000;0,24017;154,33013
10,38000;0,24221;155,06754
10,44000;0,24424;154,29776
10,50000;0,24609;153,06345
10,56000;0,24819;153,58502
10,62000;0,25016;152,52326
10,68000;0,25213;151,97578
10,74000;0,25422;151,80465
10,80000;0,25608;151,53240
10,86000;0,25805;151,07164
10,92000;0,26014;152,02205
10,98000;0,26218;151,14328
11,04000;0,26427;150,62626
11,10000;0,26612;151,06460
11,16000;0,26810;150,87407
11,22000;0,27013;151,23435
11,28000;0,27216;150,74328
11,34000;0,27419;151,36328
11,40000;0,27623;152,50539
11,46000;0,27802;150,90433
11,52000;0,28011;151,56751
11,58000;0,28209;151,92854
11,64000;0,28412;151,14699
11,70000;0,28621;151,43702
11,76000;0,28807;150,41605
11,82000;0,29016;151,62455
11,88000;0,29213;150,98512
11,94000;0,29416;150,82109
12,00000;0,29626;150,68623
12,06000;0,29811;149,25362
12,12000;0,30020;149,94221
12,18000;0,30218;148,85538
12,24000;0,30415;148,59205
12,30000;0,30618;148,68141
12,36000;0,30810;147,86188
12,42000;0,31013;148,18026
12,48000;0,31216;147,13249
12,54000;0,31413;147,00891
12,60000;0,31623;147,17054
12,66000;0,31820;146,89394
12,72000;0,32017;145,84701
12,78000;0,32221;147,01018
12,84000;0,32424;145,26653
12,90000;0,32627;145,40452
12,96000;0,32824;145,25130
13,02000;0,33004;144,17475
13,08000;0,33213;145,59245
13,14000;0,33416;144,25055
13,20000;0,33620;145,12095
13,26000;0,33823;144,77361
13,32000;0,34008;144,02693
13,38000;0,34218;145,00864
13,44000;0,34421;144,65227
13,50000;0,34624;145,41735
13,56000;0,34827;145,07620
13,62000;0,35007;144,39226
13,68000;0,35210;145,12375
13,74000;0,35407;144,74476
13,80000;0,35611;144,56545
13,86000;0,35820;144,57696
13,92000;0,36011;144,45841
13,98000;0,36209;144,13882
14,04000;0,36418;143,53483
14,10000;0,36621;144,02047
14,16000;0,36818;144,38370
14,22000;0,37022;143,78661
14,28000;0,37213;143,19036
14,34000;0,37416;143,07529
14,40000;0,37614;142,17948
14,46000;0,37817;142,50720
14,52000;0,38020;141,83691
14,58000;0,38211;140,53136
14,64000;0,38415;141,48246
14,70000;0,38618;140,10703
14,76000;0,38815;140,31586
14,82000;0,39019;139,65454
14,88000;0,39210;139,49776
14,94000;0,39419;139,86264
15,00000;0,39617;138,22917
15,06000;0,39820;138,26446
15,12000;0,40017;138,16003
15,18000;0,40208;137,91079
15,24000;0,40412;138,92755
15,30000;0,40615;138,35946
15,36000;0,40818;137,52696
15,42000;0,41022;137,89195
15,48000;0,41213;137,93004
15,54000;0,41410;137,67282
15,60000;0,41613;138,20635
15,66000;0,41817;138,01960
15,72000;0,42020;138,31275
15,78000;0,42223;138,00770
15,84000;0,42403;137,85557
15,90000;0,42612;138,53451
15,96000;0,42821;137,95363
16,02000;0,43019;137,85938
16,08000;0,43222;138,09681
16,14000;0,43407;137,03584
16,20000;0,43616;138,05162
16,26000;0,43820;137,45900
16,32000;0,44017;137,79720
16,38000;0,44226;137,58224
16,44000;0,44412;136,59579
16,50000;0,44615;136,59735
16,56000;0,44812;135,69248
16,62000;0,45010;136,07945
16,68000;0,45213;136,28921
16,74000;0,45410;135,91541
16,80000;0,45607;135,06337
16,86000;0,45811;134,83079
16,92000;0,46014;134,19483
16,98000;0,46217;133,58673
17,04000;0,46415;132,52316
17,10000;0,46612;132,72940
17,16000;0,46815;132,59823
17,22000;0,47012;132,10123
17,28000;0,47210;131,86394
17,34000;0,47413;132,35232
17,40000;0,47604;131,58043
17,46000;0,47820;131,44823
17,52000;0,48017;131,27211
17,58000;0,48220;132,87492
17,64000;0,48424;132,07758
17,70000;0,48609;132,35736
17,76000;0,48806;132,66770
17,82000;0,49015;133,07534
17,88000;0,49219;132,06607
17,94000;0,49416;132,68200
18,00000;0,49607;132,52600
18,06000;0,49805;133,14697
18,12000;0,50014;132,86979
18,18000;0,50217;132,84642
18,24000;0,50420;132,14505
18,30000;0,50618;132,66584
18,36000;0,50803;131,62935
18,42000;0,51018;132,43296
18,48000;0,51216;131,66690
18,54000;0,51413;131,13858
18,60000;0,51622;132,10725
18,66000;0,51802;130,12249
18,72000;0,52017;130,69540
18,78000;0,52214;130,20035
18,84000;0,52417;130,02962
18,90000;0,52627;129,90686
18,96000;0,52812;128,53617
19,02000;0,53021;127,89993
19,08000;0,53219;127,41571
19,14000;0,53416;127,76017
19,20000;0,53625;127,81956
19,26000;0,53817;127,30343
19,32000;0,54020;127,59849
19,38000;0,54217;127,17342
19,44000;0,54420;127,28609
19,50000;0,54618;127,84249
19,56000;0,54815;127,39685
19,62000;0,55012;126,89565
19,68000;0,55216;127,34965
19,74000;0,55419;127,03887
19,80000;0,55616;127,16843
19,86000;0,55813;126,81230
19,92000;0,56005;127,21946
19,98000;0,56214;127,66896
20,04000;0,56417;127,38809
20,10000;0,56621;127,06717
20,16000;0,56818;128,47659
20,22000;0,57009;128,13814
20,28000;0,57219;128,66260
20,34000;0,57428;128,88407
20,40000;0,57625;126,83660
20,46000;0,57822;126,81495
20,52000;0,58002;125,89711
20,58000;0,58211;127,52964
20,64000;0,58414;125,91649
20,70000;0,58612;126,67682
20,76000;0,58815;125,86992
20,82000;0,59006;125,03292
20,88000;0,59216;126,53561
20,94000;0,59413;126,51940
21,00000;0,59622;126,17302
21,06000;0,59825;125,12752
21,12000;0,60017;125,34340
21,18000;0,60208;124,40328
21,24000;0,60411;124,44332
21,30000;0,60621;125,01656
21,36000;0,60818;123,46809
21,42000;0,61015;123,83268
21,48000;0,61206;123,29974
21,54000;0,61416;124,79852
21,60000;0,61613;123,81334
21,66000;0,61816;123,61939
21,72000;0,62026;124,19067
21,78000;0,62211;123,16543
21,84000;0,62420;123,11676
21,90000;0,62618;123,20627
21,96000;0,62821;123,56034
22,02000;0,63018;123,58022
22,08000;0,63209;123,65415
22,14000;0,63407;123,29142
22,20000;0,63610;123,93855
22,26000;0,63813;123,86814
22,32000;0,63981;123,74773
22,38000;0,64220;126,27996
22,44000;0,64417;123,83969
22,50000;0,64620;124,23268
22,56000;0,64824;123,82700
22,62000;0,65021;123,35047
22,68000;0,65212;122,98353
22,74000;0,65398;123,62002
22,80000;0,65613;124,38158
22,86000;0,65816;123,83645
22,92000;0,66014;123,69724
22,98000;0,66217;123,27879
23,04000;0,66402;122,44692
23,10000;0,66611;124,71724
23,16000;0,66815;122,46744
23,22000;0,67024;123,78617
23,28000;0,67227;121,85205
23,34000;0,67407;121,16305
23,40000;0,67610;122,32348
23,46000;0,67813;122,06724
23,52000;0,68017;121,96726
23,58000;0,68214;122,05456
23,64000;0,68411;121,13774
23,70000;0,68608;121,14694
23,76000;0,68812;120,84625
23,82000;0,69015;119,82581
23,88000;0,69218;120,48009
23,94000;0,69416;120,73877
24,00000;0,69607;119,66305
24,06000;0,69816;120,16397
24,12000;0,70019;120,08215
24,18000;0,70217;120,00380
24,24000;0,70420;120,79126
24,30000;0,70605;119,58887
24,36000;0,70815;119,94127
24,42000;0,71018;120,39053
24,48000;0,71215;120,62375
24,54000;0,71425;120,94800
24,60000;0,71610;120,41306
24,66000;0,71819;120,43313
24,72000;0,72016;120,92876
24,78000;0,72214;120,65069
24,84000;0,72423;120,88214
24,90000;0,72608;121,06331
24,96000;0,72818;120,85560
25,02000;0,73015;120,68716
25,08000;0,73218;119,84452
25,14000;0,73421;120,53811
25,20000;0,73613;120,35347
25,26000;0,73804;120,13547
25,32000;0,74019;121,70818
25,38000;0,74217;120,57367
25,44000;0,74420;120,29882
25,50000;0,74611;119,75605
25,56000;0,74803;119,63060
25,62000;0,75018;120,56632
25,68000;0,75215;119,46509
25,74000;0,75424;118,97221
25,80000;0,75628;119,09173
25,86000;0,75807;117,55364
25,92000;0,76016;118,05445
25,98000;0,76220;118,07713
26,04000;0,76423;117,42623
26,10000;0,76626;118,21026
26,16000;0,76812;117,55932
26,22000;0,77015;118,82487
26,28000;0,77212;117,89218
26,34000;0,77415;118,14039
26,40000;0,77619;117,94771
26,46000;0,77810;118,69296
26,52000;0,78013;118,53999
26,58000;0,78217;118,57667
26,64000;0,78420;119,66521
26,70000;0,78617;118,64884
26,76000;0,78815;118,80000
26,82000;0,79012;118,53245
26,88000;0,79215;119,07700
26,94000;0,79412;118,61427
27,00000;0,79616;118,74016
27,06000;0,79819;118,79755
27,12000;0,80004;117,49307
27,18000;0,80214;118,78541
27,24000;0,80423;118,09872
27,30000;0,80620;119,09786
27,36000;0,80823;118,81292
27,42000;0,81009;117,33442
27,48000;0,81224;118,83491
27,54000;0,81421;117,57225
27,60000;0,81619;117,55569
27,66000;0,81822;116,98118
27,72000;0,82007;116,68416
27,78000;0,82211;116,91592
27,84000;0,82414;116,51558
27,90000;0,82617;116,20484
27,96000;0,82820;116,26938
28,02000;0,83006;115,89763
28,08000;0,83203;115,36416
28,14000;0,83412;116,10143
28,20000;0,83610;114,07182
28,26000;0,83819;114,80743
28,32000;0,84016;114,09224
28,38000;0,84202;114,23948
28,44000;0,84411;115,48970
28,50000;0,84620;115,34625
28,56000;0,84823;114,56995
28,62000;0,85027;115,25125
28,68000;0,85206;113,79160
28,74000;0,85415;115,94974
28,80000;0,85613;115,96932
28,86000;0,85822;116,43160
28,92000;0,86025;115,84226
28,98000;0,86204;115,68220
29,04000;0,86420;115,75050
29,10000;0,86617;115,24229
29,16000;0,86826;115,69978
29,22000;0,87024;116,26977
29,28000;0,87215;115,05274
29,34000;0,87418;115,12693
29,40000;0,87616;115,71348
29,46000;0,87813;115,10454
29,52000;0,88022;116,37721
29,58000;0,88207;114,98150
29,64000;0,88411;114,38500
29,70000;0,88614;115,72033
29,76000;0,88817;115,39677
29,82000;0,89021;114,51642
29,88000;0,89218;114,93155
29,94000;0,89409;114,00445
30,00000;0,89612;114,63008
30,06000;0,89816;114,33433
30,12000;0,90013;113,83023
30,18000;0,90216;113,60773
30,24000;0,90402;113,03606
30,30000;0,90611;113,45589
30,36000;0,90814;113,26541
30,42000;0,91012;113,02769
30,48000;0,91221;113,34352
30,54000;0,91412;113,29387
30,60000;0,91615;113,17807
30,66000;0,91819;113,01726
30,72000;0,92022;113,46162
30,78000;0,92225;113,75605
30,84000;0,92411;112,22222
30,90000;0,92608;112,04017
30,96000;0,92811;112,81117
31,02000;0,93015;113,74361
31,08000;0,93212;113,34547
31,14000;0,93415;113,89668
31,20000;0,93600;113,71316
31,26000;0,93816;114,04867
31,32000;0,94019;113,13057
31,38000;0,94222;112,88007
31,44000;0,94426;113,43063
31,50000;0,94605;112,28034
31,56000;0,94814;114,51702
31,62000;0,95006;113,32447
31,68000;0,95215;113,87097
31,74000;0,95418;113,36076
31,80000;0,95603;112,50881
31,86000;0,95819;113,76177
31,92000;0,96016;113,27497
31,98000;0,96219;112,54793
32,04000;0,96423;112,75025
32,10000;0,96614;112,96531
32,16000;0,96823;112,73072
32,22000;0,97020;113,46568
32,28000;0,97224;111,99928
32,34000;0,97421;112,73567
32,40000;0,97612;111,67763
32,46000;0,97816;110,82127
32,52000;0,98013;110,99353
32,58000;0,98216;110,80751
32,64000;0,98425;110,81075
32,70000;0,98623;110,49733
32,76000;0,98814;109,56503
32,82000;0,98999;110,19452
32,88000;0,99227;111,01875
32,94000;0,99424;110,56254
33,00000;0,99615;110,42642
33,06000;0,99807;109,23265
33,12000;1,00010;110,91974
33,18000;1,00213;110,45756
33,24000;1,00416;110,87572
33,30000;1,00620;110,90192
33,36000;1,00805;110,83900
33,42000;1,01014;111,54547
33,48000;1,01218;110,35415
33,54000;1,01421;111,64238
33,60000;1,01624;111,17500
33,66000;1,01810;110,99941
33,72000;1,02019;110,90892
33,78000;1,02204;111,21343
33,84000;1,02419;112,49289
33,90000;1,02617;111,49504
33,96000;1,02808;111,90728
34,02000;1,03017;111,53842
34,08000;1,03215;110,22934
34,14000;1,03418;110,55735
34,20000;1,03621;110,56225
34,26000;1,03824;110,57057
34,32000;1,04016;109,80529
34,38000;1,04219;109,91865
34,44000;1,04422;109,57188
34,50000;1,04620;109,05745
34,56000;1,04823;109,26243
34,62000;1,05008;109,01759
34,68000;1,05218;109,44844
34,74000;1,05421;108,45156
34,80000;1,05618;108,09998
34,86000;1,05827;108,83916
34,92000;1,06013;108,12712
34,98000;1,06216;108,83329
35,04000;1,06419;107,92710
35,10000;1,06617;108,47962
35,16000;1,06820;108,43516
35,22000;1,07011;108,77169
35,28000;1,07209;108,42193
35,34000;1,07412;109,50891
35,40000;1,07621;109,62207
35,46000;1,07824;109,09467
35,52000;1,08016;109,24445
35,58000;1,08213;108,75788
35,64000;1,08416;109,26732
35,70000;1,08620;108,60169
35,76000;1,08823;108,48652
35,82000;1,09020;108,94381
35,88000;1,09206;108,39358
35,94000;1,09415;109,68759
36,00000;1,09612;109,02474
36,06000;1,09815;109,37499
36,12000;1,10025;110,25582
36,18000;1,10204;107,20736
36,24000;1,10413;108,88025
36,30000;1,10611;107,70313
36,36000;1,10814;107,84772
36,42000;1,11017;107,86011
36,48000;1,11208;108,08354
36,54000;1,11412;106,83938
36,60000;1,11615;106,26487
36,66000;1,11812;106,34586
36,72000;1,12016;105,99737
36,78000;1,12213;106,07822
36,84000;1,12410;106,34229
36,90000;1,12614;105,96521
36,96000;1,12817;107,21029
37,02000;1,13014;105,30167
37,08000;1,13217;106,10162
37,14000;1,13409;106,00021
37,20000;1,13612;106,10451
37,26000;1,13821;106,30076
37,32000;1,14019;105,32950
37,38000;1,14222;106,08336
37,44000;1,14407;106,57272
37,50000;1,14616;107,21500
37,56000;1,14826;106,63951
37,62000;1,15023;107,18341
37,68000;1,15226;107,32380
37,74000;1,15406;106,79042
37,80000;1,15591;107,49717
37,86000;1,15818;109,15250
37,92000;1,16016;107,25622
37,98000;1,16225;107,70631
38,04000;1,16410;105,97837
38,10000;1,16613;107,63580
38,16000;1,16817;106,55215
38,22000;1,17014;106,76574
38,28000;1,17217;107,19429
38,34000;1,17415;107,54336
38,40000;1,17606;106,02352
38,46000;1,17815;107,01619
38,52000;1,18018;106,17184
38,58000;1,18216;104,77604
38,64000;1,18413;105,44637
38,70000;1,18604;103,91092
38,76000;1,18814;104,61245
38,82000;1,19017;104,01091
38,88000;1,19220;104,20834
38,94000;1,19430;104,15374
39,00000;1,19609;103,54354
39,06000;1,19818;103,75776
39,12000;1,20015;102,49559
39,18000;1,20219;103,15442
39,24000;1,20422;103,35429
39,30000;1,20607;101,94649
39,36000;1,20823;103,68814
39,42000;1,21020;102,76563
39,48000;1,21217;103,54957
39,54000;1,21420;104,04660
39,60000;1,21612;104,21202
39,66000;1,21815;104,38887
39,72000;1,22018;104,64761
39,78000;1,22222;104,40312
39,84000;1,22419;104,51868
39,90000;1,22616;104,36102
39,96000;1,22808;103,96243
40,02000;1,23017;105,01206
40,08000;1,23214;104,79416
40,14000;1,23423;104,50433
40,20000;1,23621;103,99260
40,26000;1,23806;104,06213
40,32000;1,24015;105,04099
40,38000;1,24219;104,29285
40,44000;1,24428;105,15121
40,50000;1,24625;104,19174
40,56000;1,24811;102,30129
40,62000;1,25020;103,24891
40,68000;1,25217;103,38000
40,74000;1,25414;102,37880
40,80000;1,25618;102,04613
40,86000;1,25809;101,77037
40,92000;1,26012;101,48553
40,98000;1,26216;101,56266
41,04000;1,26419;100,22047
41,10000;1,26616;100,18169
41,16000;1,26814;100,43450
41,22000;1,27011;99,70766
41,28000;1,27214;100,21146
41,34000;1,27411;100,23736
41,40000;1,27615;100,06104
41,46000;1,27818;100,95089
41,52000;1,28009;100,46941
41,58000;1,28213;101,13103
41,64000;1,28416;100,62625
41,70000;1,28613;100,98296
41,76000;1,28822;101,80866
41,82000;1,29008;100,75336
41,88000;1,29217;101,88152
41,94000;1,29414;101,52216
42,00000;1,29618;101,59547
42,06000;1,29821;101,34266
42,12000;1,30000;101,41546
42,18000;1,30216;101,69246
42,24000;1,30419;100,96014
42,30000;1,30616;100,53596
42,36000;1,30819;101,12628
42,42000;1,31005;100,02912
42,48000;1,31214;100,85487
42,54000;1,31417;99,68509
42,60000;1,31621;100,08581
42,66000;1,31818;100,33906
42,72000;1,32015;100,10178
42,78000;1,32201;99,26790
42,84000;1,32410;100,18707
42,90000;1,32613;99,31060
42,96000;1,32816;99,04717
43,02000;1,33020;98,50131
43,08000;1,33199;97,49547
43,14000;1,33414;99,03032
43,20000;1,33618;98,69756
43,26000;1,33821;98,42844
43,32000;1,34024;98,13769
43,38000;1,34203;97,16701
43,44000;1,34413;97,75321
43,50000;1,34610;97,43485
43,56000;1,34813;97,25176
43,62000;1,35017;97,59056
43,68000;1,35208;97,95226
43,74000;1,35411;97,22586
43,80000;1,35615;98,11487
43,86000;1,35812;98,13455
43,92000;1,36015;98,37595
43,98000;1,36212;98,34658
44,04000;1,36404;97,58370
44,10000;1,36613;98,25110
44,16000;1,36816;97,70959
44,22000;1,37014;98,60452
44,28000;1,37217;98,43202
44,34000;1,37402;97,35998
44,40000;1,37611;97,00391
44,46000;1,37815;97,64074
44,52000;1,38012;96,89638
44,58000;1,38221;98,29702
44,64000;1,38401;96,60342
44,70000;1,38616;97,73294
44,76000;1,38819;97,19521
44,82000;1,39017;96,60356
44,88000;1,39226;96,78146
44,94000;1,39405;95,92290
45,00000;1,39608;97,22317
45,06000;1,39818;95,83300
45,12000;1,40021;96,21679
45,18000;1,40224;96,40457
45,24000;1,40410;95,90655
45,30000;1,40607;95,54519
45,36000;1,40816;95,53221
45,42000;1,41019;94,72326
45,48000;1,41223;94,96113
45,54000;1,41420;93,72011
45,60000;1,41611;94,50536
45,66000;1,41821;94,32184
45,72000;1,42018;93,88831
45,78000;1,42221;94,17950
45,84000;1,42425;93,72598
45,90000;1,42604;92,49608
45,96000;1,42813;94,17759
46,02000;1,43016;93,96352
46,08000;1,43214;93,51352
46,14000;1,43423;93,36183
46,20000;1,43608;94,06463
46,26000;1,43818;94,21735
46,32000;1,44015;93,79777
46,38000;1,44218;93,59241
46,44000;1,44422;93,42064
46,50000;1,44613;93,68887
46,56000;1,44816;93,55225
46,62000;1,45013;93,62546
46,68000;1,45217;93,11485
46,74000;1,45420;93,31477
46,80000;1,45611;93,32516
46,86000;1,45809;92,58774
46,92000;1,46012;93,12131
46,98000;1,46221;92,89333
47,04000;1,46418;92,11121
47,10000;1,46622;93,11671
47,16000;1,46813;92,56385
47,22000;1,47016;93,04199
47,28000;1,47220;92,92526
47,34000;1,47417;92,95023
47,40000;1,47620;91,96397
47,46000;1,47812;91,50752
47,52000;1,48015;92,44432
47,58000;1,48218;92,05955
47,64000;1,48421;91,88984
47,70000;1,48625;91,78819
47,76000;1,48810;91,54135
47,82000;1,49013;92,14495
47,88000;1,49217;92,02298
47,94000;1,49420;91,64012
48,00000;1,49623;91,30466
48,06000;1,49809;90,44689
48,12000;1,50006;90,31909
48,18000;1,50209;91,06913
48,24000;1,50412;91,68948
48,30000;1,50616;91,07016
48,36000;1,50819;90,90040
48,42000;1,51004;89,81568
48,48000;1,51214;90,98134
48,54000;1,51417;90,48028
48,60000;1,51620;89,80123
48,66000;1,51823;89,84564
48,72000;1,52003;88,93788
48,78000;1,52218;90,32325
48,84000;1,52409;90,27938
48,90000;1,52619;89,75702
48,96000;1,52822;90,03499
49,02000;1,53007;89,14324
49,08000;1,53217;89,58715
49,14000;1,53414;89,56541
49,20000;1,53617;89,80021
49,26000;1,53820;89,98637
49,32000;1,54012;89,87331
49,38000;1,54215;89,69752
49,44000;1,54412;89,57756
49,50000;1,54616;89,65341
49,56000;1,54813;89,63593
49,62000;1,55010;89,27368
49,68000;1,55202;88,63557
49,74000;1,55411;88,26901
49,80000;1,55614;88,10444
49,86000;1,55817;87,95799
49,92000;1,56015;88,16349
49,98000;1,56206;87,77814
50,04000;1,56415;88,30202
50,10000;1,56619;87,56622
50,16000;1,56816;87,76463
50,22000;1,57019;87,54184
50,28000;1,57205;87,04871
50,34000;1,57414;87,61082
50,40000;1,57617;86,65557
50,46000;1,57820;87,25554
50,52000;1,58030;86,66232
50,58000;1,58209;85,86111
50,64000;1,58412;85,92260
50,70000;1,58616;86,20381
50,76000;1,58825;87,31605
50,82000;1,59028;86,69024
50,88000;1,59213;85,71676
50,94000;1,59411;85,42179
51,00000;1,59608;86,43366
51,06000;1,59811;86,33964
51,12000;1,60015;86,86391
51,18000;1,60212;86,31643
51,24000;1,60409;86,35629
51,30000;1,60613;86,88761
51,36000;1,60816;86,57810
51,42000;1,61013;86,36995
51,48000;1,61222;87,23360
51,54000;1,61408;85,26427
51,60000;1,61623;86,20254
51,66000;1,61820;86,44511
51,72000;1,62018;86,09443
51,78000;1,62221;86,41770
51,84000;1,62406;85,04941
51,90000;1,62621;85,40211
51,96000;1,62819;85,22549
52,02000;1,63022;85,30814
52,08000;1,63231;84,79905
52,14000;1,63417;84,19571
52,20000;1,63620;84,90790
52,26000;1,63817;83,96537
52,32000;1,64021;84,56363
52,38000;1,64224;84,31748
52,44000;1,64415;83,29940
52,50000;1,64606;83,00135
52,56000;1,64816;83,39111
52,62000;1,65019;83,99294
52,68000;1,65222;83,93981
52,74000;1,65420;83,37588
52,80000;1,65611;83,21204
52,86000;1,65814;83,23212
52,92000;1,66017;84,22528
52,98000;1,66215;83,88115
53,04000;1,66418;83,34293
53,10000;1,66603;82,14578
53,16000;1,66813;83,85569
53,22000;1,67016;83,72955
53,28000;1,67219;83,92885
53,34000;1,67429;83,98236
53,40000;1,67614;83,12425
53,46000;1,67817;83,74425
53,52000;1,68014;82,98837
53,58000;1,68218;83,55774
53,64000;1,68421;83,61189
53,70000;1,68618;83,77113
53,76000;1,68816;83,11695
53,82000;1,69019;83,00169
53,88000;1,69216;82,16282
53,94000;1,69414;82,80328
54,00000;1,69617;82,94078
54,06000;1,69808;81,51775
54,12000;1,70017;82,06097
54,18000;1,70221;82,10470
54,24000;1,70418;81,65300
54,30000;1,70621;81,82849
54,36000;1,70807;81,31107
54,42000;1,71016;81,86213
54,48000;1,71213;80,84463
54,54000;1,71416;80,89663
54,60000;1,71620;80,75100
54,66000;1,71811;80,60230
54,72000;1,72020;80,52273
54,78000;1,72224;81,07511
54,84000;1,72421;80,64774
54,90000;1,72624;80,80345
54,96000;1,72810;80,02245
55,02000;1,73013;80,31659
55,08000;1,73210;80,62561
55,14000;1,73413;81,09866
55,20000;1,73617;80,19413
55,26000;1,73808;80,89350
55,32000;1,74005;80,91181
55,38000;1,74197;80,65156
55,44000;1,74424;81,33678
55,50000;1,74621;80,22806
55,56000;1,74813;79,90230
55,62000;1,75004;79,15215
55,68000;1,75213;80,46745
55,74000;1,75416;80,10755
55,80000;1,75614;79,63798
55,86000;1,75817;80,10026
55,92000;1,76002;78,99776
55,98000;1,76212;80,44600
56,04000;1,76415;79,51033
56,10000;1,76618;78,86693
56,16000;1,76827;79,89030
56,22000;1,77013;78,54170
56,28000;1,77216;78,28894
56,34000;1,77419;78,11600
56,40000;1,77617;77,47862
56,46000;1,77820;77,38745
56,52000;1,78011;77,02486
56,58000;1,78209;77,20515
56,64000;1,78412;77,21348
56,70000;1,78615;77,81471
56,76000;1,78812;77,13959
56,82000;1,79016;77,91690
56,88000;1,79207;77,71908
56,94000;1,79416;77,76550
57,00000;1,79620;76,73792
57,06000;1,79799;76,29293
57,12000;1,80020;77,07270
57,18000;1,80206;75,89323
57,24000;1,80415;76,97359
57,30000;1,80618;76,84109
57,36000;1,80815;77,03196
57,42000;1,81019;77,58815
57,48000;1,81204;76,61649
57,54000;1,81413;76,84031
57,60000;1,81617;76,87213
57,66000;1,81820;76,88227
57,72000;1,82023;77,01081
57,78000;1,82214;76,03136
57,84000;1,82412;75,46297
57,90000;1,82615;76,25062
57,96000;1,82812;76,01490
58,02000;1,82992;75,98102
58,08000;1,83213;76,93128
58,14000;1,83410;75,93529
58,20000;1,83620;75,48304
58,26000;1,83817;75,18093
58,32000;1,84020;75,58675
58,38000;1,84217;75,79760
58,44000;1,84415;74,30191
58,50000;1,84618;74,63472
58,56000;1,84815;73,64235
58,62000;1,85019;74,69980
58,68000;1,85222;74,25970
58,74000;1,85407;73,70737
58,80000;1,85616;74,37262
58,86000;1,85814;73,44874
58,92000;1,86023;73,93271
58,98000;1,86226;74,66939
59,04000;1,86418;74,26700
59,10000;1,86627;74,54100
59,16000;1,86818;73,07959
59,22000;1,87022;73,31888
59,28000;1,87219;73,92816
59,34000;1,87404;73,50172
59,40000;1,87613;73,86719
59,46000;1,87817;72,97535
59,52000;1,88020;73,13287
59,58000;1,88217;72,46278
59,64000;1,88415;73,33651
59,70000;1,88606;73,04874
59,76000;1,88815;73,47714
59,82000;1,89018;73,31208
59,88000;1,89222;73,14794
59,94000;1,89419;73,60719
60,00000;1,89598;71,71591
60,06000;1,89814;73,31076
60,12000;1,90017;72,78404
60,18000;1,90214;71,23703
60,24000;1,90418;72,65002
60,30000;1,90609;72,34472
60,36000;1,90818;72,64801
60,42000;1,91015;72,48055
60,48000;1,91219;71,97327
60,54000;1,91428;72,24528
60,60000;1,91613;71,60216
60,66000;1,91817;71,18954
60,72000;1,92014;71,08568
60,78000;1,92217;71,32728
60,84000;1,92421;71,15110
60,90000;1,92612;70,59701
60,96000;1,92809;70,12842
61,02000;1,93012;70,45477
61,08000;1,93216;70,16999
61,14000;1,93419;70,07666
61,20000;1,93616;70,41060
61,26000;1,93808;69,89960
61,32000;1,94017;70,72187
61,38000;1,94214;70,18056
61,44000;1,94412;70,25127
61,50000;1,94621;69,51934
61,56000;1,94800;68,23410
61,62000;1,95009;69,70678
61,68000;1,95213;69,17565
61,74000;1,95416;68,65368
61,80000;1,95619;69,08448
61,86000;1,95811;68,90242
61,92000;1,96014;68,93940
61,98000;1,96211;68,05528
62,04000;1,96420;69,17893
62,10000;1,96624;68,73673
62,16000;1,96809;68,19277
62,22000;1,97012;68,04201
62,28000;1,97216;67,92038
62,34000;1,97413;68,49768
62,40000;1,97616;68,34451
62,46000;1,97814;68,59620
62,52000;1,98005;67,37711
62,58000;1,98214;68,31097
62,64000;1,98417;67,50300
62,70000;1,98621;68,23317
62,76000;1,98824;68,17970
62,82000;1,99003;67,24941
62,88000;1,99213;67,92601
62,94000;1,99416;67,50888
63,00000;1,99613;67,45629
63,06000;1,99822;67,08126
63,12000;2,00008;66,83340
63,18000;2,00217;67,23384
63,24000;2,00420;67,17900
63,30000;2,00618;66,96610
63,36000;2,00821;67,38010
63,42000;2,01012;65,89973
63,48000;2,01216;66,07224
63,54000;2,01419;65,63919
63,60000;2,01622;65,99316
63,66000;2,01825;65,49758
63,72000;2,02011;65,78139
63,78000;2,02214;64,69084
63,84000;2,02417;65,31725
63,90000;2,02621;64,27992
63,96000;2,02818;64,69916
64,02000;2,03021;65,06733
64,08000;2,03207;63,72196
64,14000;2,03416;64,41658
64,20000;2,03613;63,61189
64,26000;2,03816;63,78655
64,32000;2,04020;64,51021
64,38000;2,04205;63,06088
64,44000;2,04420;64,55094
64,50000;2,04618;64,21015
64,56000;2,04815;63,84819
64,62000;2,05018;64,07691
64,68000;2,05203;64,13875
64,74000;2,05419;64,90545
64,80000;2,05622;64,63100
64,86000;2,05819;65,43652
64,92000;2,06023;65,24595
64,98000;2,06214;64,80967
65,04000;2,06417;63,95234
65,10001;2,06615;63,98153
65,16000;2,06818;63,54500
65,22000;2,07021;63,27668
65,28001;2,07212;63,23789
65,34000;2,07410;61,97738
65,40000;2,07613;63,31354
65,46001;2,07816;63,27437
65,52000;2,08020;62,86860
65,58000;2,08217;62,37086
65,64000;2,08408;61,81315
65,70001;2,08612;61,78989
65,76000;2,08815;60,88855
65,82000;2,09018;60,98256
65,88001;2,09221;60,77426
65,94000;2,09407;60,35840
66,00000;2,09616;60,71614
66,06001;2,09813;59,31103
66,12000;2,10017;60,08655
66,18000;2,10220;60,61449
66,24001;2,10411;59,59650
66,30000;2,10614;60,00242
66,36000;2,10818;58,75744
66,42001;2,11021;59,58661
66,48000;2,11224;59,27010
66,54000;2,11416;59,64596
66,60001;2,11613;59,47389
66,66000;2,11816;59,43311
66,72000;2,12020;59,48349
66,78001;2,12217;59,12365
66,84001;2,12420;60,25019
66,90000;2,12605;58,87877
66,96001;2,12815;60,38881
67,02001;2,13018;59,53584
67,08000;2,13215;60,25371
67,14000;2,13425;60,48257
67,20001;2,13604;59,43374
67,26000;2,13819;59,94729
67,32000;2,14022;59,15621
67,38001;2,14220;58,83632
67,44000;2,14423;59,36519
67,50000;2,14608;57,79772
67,56001;2,14812;58,21104
67,62000;2,15015;58,03334
67,68000;2,15218;57,26689
67,74001;2,15422;57,23257
67,80000;2,15613;57,24828
67,86000;2,15810;56,60841
67,92001;2,16025;57,80291
67,98000;2,16223;56,01367
68,04000;2,16426;56,43913
68,10001;2,16617;56,15646
68,16000;2,16809;55,05944
68,22000;2,17012;55,26960
68,28001;2,17215;55,97078
68,34001;2,17419;55,13260
68,40000;2,17616;55,22548
68,46001;2,17801;54,23948
68,52001;2,18016;55,07403
68,58000;2,18220;55,66808
68,64001;2,18423;55,07575
68,70001;2,18626;56,53217
68,76000;2,18812;54,75988
68,82000;2,19021;55,37948
68,88001;2,19218;54,43705
68,94000;2,19415;54,76624
69,00000;2,19619;55,67043
69,06001;2,19804;55,21305
69,12000;2,20013;56,32842
69,18000;2,20217;54,66924
69,24001;2,20420;55,36352
69,30000;2,20623;55,49641
69,36000;2,20815;56,28705
69,42001;2,21018;55,12300
69,48000;2,21215;54,31909
69,54000;2,21418;53,82944
69,60001;2,21622;53,64371
69,66000;2,21813;53,57218
69,72000;2,22010;52,24742
69,74001;2,22082;52,33914