File: SU - Suspension/05 - Essais/Excels essais Optimus/Collage_alu_alu_31_01_19/collage4.is_tens_RawData/Specimen_RawData_1.csv
Temps;Déplacement;Charge
(sec);(mm);(N)
0,00000;-37,73465;54,25104
0,04000;-37,73411;54,20372
0,08000;-37,73190;61,00759
0,12000;-37,72861;78,44937
0,16000;-37,72484;99,79322
0,20000;-37,72102;121,14877
0,24000;-37,71719;142,84027
0,28000;-37,71336;163,12202
0,32000;-37,70972;183,03972
0,36000;-37,70619;201,68270
0,40000;-37,70266;221,02734
0,44000;-37,69919;238,28996
0,48000;-37,69567;254,70930
0,52000;-37,69226;269,78266
0,56000;-37,68891;283,76740
0,60000;-37,68550;296,33367
0,64000;-37,68209;309,70110
0,68000;-37,67881;323,78177
0,72000;-37,67546;337,63535
0,76000;-37,67205;351,16393
0,80000;-37,66876;365,53687
0,84000;-37,66541;379,58554
0,88000;-37,66201;393,81455
0,92000;-37,65878;407,81233
0,96000;-37,65543;420,88209
1,00000;-37,65208;433,99553
1,04000;-37,64879;447,55093
1,08000;-37,64538;458,67683
1,12000;-37,64204;470,69974
1,16000;-37,63875;482,63147
1,20000;-37,63540;493,33666
1,24000;-37,63211;502,48820
1,28000;-37,62876;511,30950
1,32000;-37,62541;519,55413
1,36000;-37,62213;527,14893
1,40000;-37,61872;534,38372
1,44000;-37,61537;540,71425
1,48000;-37,61208;546,86493
1,52000;-37,60867;551,63298
1,56000;-37,60539;556,25830
1,60000;-37,60204;558,76141
1,64000;-37,59869;562,18095
1,68000;-37,59534;564,01379
1,72000;-37,59199;563,85132
1,76000;-37,58870;561,88214
1,80000;-37,58535;557,37626
1,84000;-37,58200;551,74353
1,88000;-37,57866;544,15725
1,92000;-37,57543;538,08354
1,96000;-37,57190;532,38478
2,00000;-37,56861;526,97188
2,04000;-37,56538;519,18407
2,08000;-37,56210;513,58207
2,12000;-37,55875;509,63457
2,16000;-37,55534;504,89935
2,20000;-37,55205;500,71492
2,24000;-37,54864;500,27040
2,28000;-37,54530;500,91450
2,32000;-37,54201;502,05439
2,36000;-37,53866;511,38001
2,40000;-37,53531;530,95380
2,44000;-37,53202;552,43834
2,48000;-37,52879;571,60584
2,52000;-37,52532;587,10566
2,56000;-37,52210;599,05127
2,60000;-37,51875;609,74793
2,64000;-37,51540;620,62158
2,68000;-37,51211;631,81748
2,72000;-37,50876;641,42686
2,76000;-37,50542;651,92068
2,80000;-37,50213;661,26450
2,84000;-37,49872;670,39956
2,88000;-37,49537;680,04243
2,92000;-37,49209;689,30471
2,96000;-37,48873;699,01790
3,00000;-37,48539;706,93409
3,04000;-37,48210;715,58338
3,08000;-37,47875;723,78339
3,12000;-37,47540;733,76396
3,16000;-37,47211;743,85675
3,20000;-37,46894;752,56303
3,24000;-37,46541;763,64344
3,28000;-37,46207;773,05790
3,32000;-37,45878;782,13066
3,36000;-37,45543;792,41954
3,40000;-37,45214;802,01821
3,44000;-37,44874;812,91040
3,48000;-37,44545;821,81878
3,52000;-37,44210;831,33895
3,56000;-37,43887;840,99267
3,60000;-37,43546;850,41812
3,64000;-37,43217;861,17014
3,68000;-37,42883;871,12430
3,72000;-37,42542;881,27302
3,76000;-37,42207;890,67211
3,80000;-37,41878;900,24890
3,84000;-37,41537;909,18690
3,88000;-37,41220;918,71247
3,92000;-37,40873;929,90408
3,96000;-37,40539;938,33385
4,00000;-37,40204;947,46742
4,04000;-37,39869;956,22027
4,08000;-37,39534;963,09744
4,12000;-37,39200;972,37928
4,16000;-37,38859;981,37129
4,20000;-37,38536;988,32883
4,24000;-37,38201;997,09099
4,28000;-37,37866;1006,52110
4,32000;-37,37543;1014,10635
4,36000;-37,37208;1021,40428
4,40000;-37,36868;1032,50789
4,44000;-37,36539;1039,86887
4,48000;-37,36210;1048,50046
4,52000;-37,35869;1056,62271
4,56000;-37,35540;1065,48592
4,60000;-37,35211;1072,89692
4,64000;-37,34865;1081,62612
4,68000;-37,34536;1090,31554
4,72000;-37,34201;1096,80351
4,76000;-37,33866;1104,21488
4,80000;-37,33538;1113,56694
4,84000;-37,33203;1121,32737
4,88000;-37,32874;1129,25693
4,92000;-37,32533;1139,72435
4,96000;-37,32198;1151,37380
5,00000;-37,31864;1163,84244
5,04000;-37,31535;1175,61463
5,08000;-37,31212;1187,71447
5,12000;-37,30895;1200,37599
5,16000;-37,30530;1215,25079
5,20000;-37,30207;1226,76836
5,24000;-37,29872;1238,38577
5,28000;-37,29537;1251,66886
5,32000;-37,29209;1264,61228
5,36000;-37,28868;1277,32763
5,40000;-37,28539;1291,87535
5,44000;-37,28210;1304,77203
5,48000;-37,27870;1316,28839
5,52000;-37,27541;1328,15363
5,56000;-37,27212;1340,43470
5,60000;-37,26871;1354,28440
5,64000;-37,26542;1366,89246
5,68000;-37,26207;1381,32954
5,72000;-37,25878;1393,66584
5,76000;-37,25544;1405,77899
5,80000;-37,25209;1417,77173
5,84000;-37,24874;1428,82401
5,88000;-37,24539;1440,06601
5,92000;-37,24234;1449,72736
5,96000;-37,23869;1460,63510
6,00000;-37,23541;1470,14940
6,04000;-37,23206;1476,78610
6,08000;-37,22883;1481,34753
6,12000;-37,22536;1486,36308
6,16000;-37,22195;1491,92708
6,20000;-37,21873;1492,39153
6,24000;-37,21544;1491,42966
6,28000;-37,21197;1491,42118
6,32000;-37,20874;1488,27648
6,36000;-37,20533;1484,27077
6,40000;-37,20204;1480,59223
6,44000;-37,19870;1478,91399
6,48000;-37,19541;1476,18074
6,52000;-37,19224;1473,87050
6,56000;-37,18871;1472,55687
6,60000;-37,18530;1470,89502
6,64000;-37,18201;1467,60494
6,68000;-37,17873;1465,13786
6,72000;-37,17532;1464,85996
6,76000;-37,17197;1462,23251
6,80000;-37,16868;1460,41084
6,84000;-37,16539;1458,23890
6,88000;-37,16193;1457,36067
6,92000;-37,15864;1455,19366
6,96000;-37,15541;1452,71290
7,00000;-37,15194;1452,20738
7,04000;-37,14865;1449,86566
7,08000;-37,14536;1446,64925
7,12000;-37,14208;1443,23055
7,16000;-37,13861;1442,14565
7,20000;-37,13538;1439,41864
7,24000;-37,13191;1437,79088
7,28000;-37,12862;1438,22059
7,32000;-37,12539;1432,86297
7,36000;-37,12204;1429,69871
7,40000;-37,11870;1427,06614
7,44000;-37,11541;1426,02473
7,48000;-37,11200;1425,01649
7,52000;-37,10871;1424,68447
7,56000;-37,10543;1426,28364
7,60000;-37,10202;1430,66896
7,64000;-37,09867;1435,71431
7,68000;-37,09544;1440,90308
7,72000;-37,09209;1447,07235
7,76000;-37,08874;1454,36497
7,80000;-37,08533;1462,42054
7,84000;-37,08204;1473,18114
7,88000;-37,07870;1479,29257
7,92000;-37,07535;1484,97541
7,96000;-37,07206;1490,82225
8,00000;-37,06871;1497,62332
8,04000;-37,06536;1504,73109
8,08000;-37,06202;1510,90268
8,12000;-37,05879;1519,05771
8,16000;-37,05526;1529,31707
8,20000;-37,05203;1534,31548
8,24000;-37,04875;1541,18445
8,28000;-37,04540;1547,98552
8,32000;-37,04211;1556,80357
8,36000;-37,03876;1564,04097
8,40000;-37,03547;1571,67166
8,44000;-37,03224;1580,04966
8,48000;-37,02872;1588,75547
8,52000;-37,02543;1595,42151
8,56000;-37,02208;1601,99720
8,60000;-37,01879;1610,11517
8,64000;-37,01544;1618,67831
8,68000;-37,01215;1626,55115
8,72000;-37,00881;1633,57258
8,76000;-37,00546;1642,52333
8,80000;-37,00205;1653,96705
8,84000;-36,99870;1661,51375
8,88000;-36,99541;1669,65872
8,92000;-36,99207;1677,46600
8,96000;-36,98878;1684,01971
9,00000;-36,98543;1691,57665
9,04000;-36,98208;1699,13955
9,08000;-36,97903;1705,11957
9,12000;-36,97538;1716,48301
9,16000;-36,97203;1725,26482
9,20000;-36,96874;1732,57887
9,24000;-36,96546;1739,99630
9,28000;-36,96205;1748,74384
9,32000;-36,95876;1756,51480
9,36000;-36,95541;1764,01157
9,40000;-36,95206;1771,89894
9,44000;-36,94872;1781,15554
9,48000;-36,94537;1788,33250
9,52000;-36,94208;1796,07477
9,56000;-36,93879;1803,08335
9,60000;-36,93538;1812,05869
9,64000;-36,93203;1819,34778
9,68000;-36,92875;1827,27594
9,72000;-36,92540;1834,99865
9,76000;-36,92205;1842,45761
9,80000;-36,91882;1849,19853
9,84000;-36,91547;1857,42863
9,88000;-36,91212;1865,03045
9,92000;-36,90877;1872,98357
9,96000;-36,90555;1879,57976
10,00000;-36,90208;1888,04045
10,04000;-36,89873;1896,04983
10,08000;-36,89544;1903,11372
10,12000;-36,89210;1909,10473
10,16000;-36,88869;1915,53216
10,20000;-36,88540;1921,21323
10,24000;-36,88211;1926,68736
10,28000;-36,87870;1932,93951
10,32000;-36,87541;1938,63641
10,36000;-36,87207;1942,26597
10,40000;-36,86878;1945,12643
10,44000;-36,86543;1949,11677
10,48000;-36,86208;1951,94874
10,52000;-36,85873;1954,02019
10,56000;-36,85544;1957,15856
10,60000;-36,85209;1957,52122
10,64000;-36,84881;1957,44019
10,68000;-36,84546;1957,46738
10,72000;-36,84211;1957,77696
10,76000;-36,83876;1957,57914
10,80000;-36,83542;1957,12633
10,84000;-36,83213;1955,68297
10,88000;-36,82872;1955,40488
10,92000;-36,82537;1952,88323
10,96000;-36,82208;1951,41677
11,00000;-36,81873;1950,00917
11,04000;-36,81533;1948,73083
11,08000;-36,81210;1947,09450
11,12000;-36,80875;1945,11507
11,16000;-36,80540;1944,20032
11,20000;-36,80211;1941,33464
11,24000;-36,79876;1939,91102
11,28000;-36,79541;1939,18403
11,32000;-36,79207;1938,42426
11,36000;-36,78878;1936,28538
11,40000;-36,78543;1935,70331
11,44000;-36,78208;1936,00506
11,48000;-36,77874;1933,07791
11,52000;-36,77539;1932,12051
11,56000;-36,77204;1929,86820
11,60000;-36,76875;1927,57193
11,64000;-36,76546;1924,88432
11,68000;-36,76211;1923,71141
11,72000;-36,75882;1921,45668
11,76000;-36,75542;1920,45625
11,80000;-36,75207;1917,84054
11,84000;-36,74872;1915,95163
11,88000;-36,74537;1913,93215
11,92000;-36,74202;1911,36543
11,96000;-36,73892;1908,85346
12,00000;-36,73539;1908,90282
12,04000;-36,73198;1907,83553
12,08000;-36,72869;1904,50735
12,12000;-36,72534;1902,40517
12,16000;-36,72193;1899,90997
12,20000;-36,71865;1896,01872
12,24000;-36,71536;1891,61971
12,28000;-36,71207;1888,43068
12,32000;-36,70878;1885,45305
12,36000;-36,70543;1881,34667
12,40000;-36,70203;1878,52569
12,44000;-36,69868;1876,24581
12,48000;-36,69533;1877,29206
12,52000;-36,69204;1882,24148
12,56000;-36,68869;1890,30860
12,60000;-36,68534;1898,45134
12,64000;-36,68199;1906,34672
12,68000;-36,67865;1913,70919
12,72000;-36,67536;1920,52368
12,76000;-36,67195;1929,63853
12,80000;-36,66860;1936,52883
12,84000;-36,66543;1941,77572
12,88000;-36,66203;1950,28279
12,92000;-36,65868;1958,16029
12,96000;-36,65551;1963,20973
13,00000;-36,65204;1970,82385
13,04000;-36,64863;1978,30591
13,08000;-36,64540;1984,37497
13,12000;-36,64206;1989,68984
13,16000;-36,63871;1996,13534
13,20000;-36,63536;2003,91151
13,24000;-36,63201;2008,99094
13,28000;-36,62866;2015,41726
13,32000;-36,62531;2021,80836
13,36000;-36,62203;2026,59089
13,40000;-36,61868;2032,27904
13,44000;-36,61539;2039,75644
13,48000;-36,61198;2045,69455
13,52000;-36,60869;2053,06970
13,56000;-36,60535;2060,20307
13,60000;-36,60200;2066,95441
13,64000;-36,59865;2073,70315
13,68000;-36,59536;2079,95400
13,72000;-36,59207;2086,05994
13,76000;-36,58867;2093,52970
13,80000;-36,58538;2098,77305
13,84000;-36,58227;2104,61635
13,88000;-36,57868;2112,81627
13,92000;-36,57539;2118,45096
13,96000;-36,57216;2123,70642
14,00000;-36,56875;2129,86935
14,04000;-36,56534;2135,98926
14,08000;-36,56206;2141,87391
14,12000;-36,55877;2147,22939
14,16000;-36,55536;2155,32221
14,20000;-36,55207;2160,96621
14,24000;-36,54879;2166,40793
14,28000;-36,54544;2173,33212
14,32000;-36,54197;2180,84045
14,36000;-36,53862;2189,68764
14,40000;-36,53539;2193,89126
14,44000;-36,53204;2199,32701
14,48000;-36,52875;2205,41451
14,52000;-36,52541;2212,59668
14,56000;-36,52212;2220,07241
14,60000;-36,51877;2228,87713
14,64000;-36,51536;2237,70589
14,68000;-36,51201;2245,14846
14,72000;-36,50866;2255,44162
14,76000;-36,50538;2267,51156
14,80000;-36,50197;2274,79786
14,84000;-36,49874;2282,88341
14,88000;-36,49539;2292,10500
14,92000;-36,49198;2301,44132
14,96000;-36,48876;2310,39859
15,00000;-36,48541;2318,97384
15,04000;-36,48206;2328,53778
15,08000;-36,47871;2340,80330
15,12000;-36,47542;2350,06306
15,16000;-36,47207;2358,67631
15,20000;-36,46879;2369,75979
15,24000;-36,46538;2382,26056
15,28000;-36,46209;2395,26834
15,32000;-36,45880;2410,76723
15,36000;-36,45539;2426,05936
15,40000;-36,45204;2440,56247
15,44000;-36,44876;2455,36435
15,48000;-36,44529;2471,86814
15,52000;-36,44200;2490,46087
15,56000;-36,43871;2504,88520
15,60000;-36,43543;2520,13262
15,64000;-36,43207;2537,34812
15,68000;-36,42873;2554,48781
15,72000;-36,42550;2570,86717
15,76000;-36,42209;2588,95196
15,80000;-36,41856;2608,77833
15,84000;-36,41545;2628,70993
15,88000;-36,41210;2645,47579
15,92000;-36,40876;2662,41431
15,96000;-36,40553;2680,25957
16,00000;-36,40212;2698,03442
16,04000;-36,39871;2718,24896
16,08000;-36,39542;2736,06814
16,12000;-36,39214;2753,80630
16,16000;-36,38873;2773,28808
16,20000;-36,38544;2791,95663
16,24000;-36,38209;2808,90744
16,28000;-36,37904;2826,80281
16,32000;-36,37539;2848,37652
16,36000;-36,37210;2867,95739
16,40000;-36,36882;2884,79906
16,44000;-36,36547;2902,85982
16,48000;-36,36212;2921,72022
16,52000;-36,35883;2938,98135
16,56000;-36,35548;2957,68641
16,60000;-36,35214;2976,23277
16,64000;-36,34873;2996,29588
16,68000;-36,34550;3015,04061
16,72000;-36,34209;3035,00779
16,76000;-36,33868;3053,88290
16,80000;-36,33534;3073,10373
16,84000;-36,33217;3090,43285
16,88000;-36,32882;3109,17348
16,92000;-36,32541;3129,29042
16,96000;-36,32218;3147,93587
17,00000;-36,31883;3166,63496
17,04000;-36,31542;3187,25072
17,08000;-36,31214;3205,57766
17,12000;-36,30879;3222,78440
17,16000;-36,30544;3243,15093
17,20000;-36,30209;3262,41739
17,24000;-36,29880;3280,42023
17,28000;-36,29545;3298,74791
17,32000;-36,29205;3319,13456
17,36000;-36,28870;3337,56618
17,40000;-36,28547;3355,74411
17,44000;-36,28206;3374,67380
17,48000;-36,27878;3393,35464
17,52000;-36,27543;3411,50090
17,56000;-36,27208;3430,06216
17,60000;-36,26879;3448,68191
17,64000;-36,26544;3466,87436
17,68000;-36,26209;3485,29629
17,72000;-36,25874;3506,82251
17,76000;-36,25540;3525,70936
17,80000;-36,25199;3545,46830
17,84000;-36,24876;3562,91384
17,88000;-36,24541;3581,56487
17,92000;-36,24200;3600,93564
17,96000;-36,23877;3619,42649
18,00000;-36,23543;3637,96018
18,04000;-36,23202;3657,79996
18,08000;-36,22873;3676,14105
18,12000;-36,22544;3695,14003
18,16000;-36,22204;3714,78125
18,20000;-36,21875;3735,19622
18,24000;-36,21546;3752,17982
18,28000;-36,21211;3773,00829
18,32000;-36,20870;3792,71582
18,36000;-36,20541;3811,68425
18,40000;-36,20212;3830,10879
18,44000;-36,19872;3849,98433
18,48000;-36,19543;3868,59626
18,52000;-36,19214;3886,77344
18,56000;-36,18879;3905,79961
18,60000;-36,18544;3926,10058
18,64000;-36,18209;3945,18673
18,68000;-36,17875;3964,39061
18,72000;-36,17558;3983,68165
18,76000;-36,17205;4005,40046
18,80000;-36,16870;4024,53914
18,84000;-36,16547;4042,66268
18,88000;-36,16213;4061,58939
18,92000;-36,15872;4081,56291
18,96000;-36,15543;4100,64645
19,00000;-36,15208;4118,50922
19,04000;-36,14873;4138,81876
19,08000;-36,14538;4157,49997
19,12000;-36,14210;4174,51486
19,16000;-36,13887;4193,40134
19,20000;-36,13540;4214,39484
19,24000;-36,13211;4234,01147
19,28000;-36,12876;4253,44333
19,32000;-36,12535;4273,51967
19,36000;-36,12207;4293,77407
19,40000;-36,11884;4312,20829
19,44000;-36,11537;4333,40110
19,48000;-36,11208;4354,78054
19,52000;-36,10874;4374,64602
19,56000;-36,10539;4392,53189
19,60000;-36,10210;4412,32771
19,64000;-36,09863;4434,30133
19,68000;-36,09534;4455,10000
19,72000;-36,09211;4474,39291
19,76000;-36,08870;4495,07795
19,80000;-36,08536;4516,01334
19,84000;-36,08213;4535,09390
19,88000;-36,07890;4554,32236
19,92000;-36,07531;4577,32864
19,96000;-36,07202;4598,08409
20,00000;-36,06873;4617,19893
20,04000;-36,06532;4636,90497
20,08000;-36,06198;4658,28404
20,12000;-36,05869;4678,40396
20,16000;-36,05546;4697,84327
20,20000;-36,05193;4720,21475
20,24000;-36,04865;4739,76061
20,28000;-36,04536;4759,37538
20,32000;-36,04207;4781,07370
20,36000;-36,03866;4802,72546
20,40000;-36,03531;4824,51990
20,44000;-36,03202;4844,00056
20,48000;-36,02867;4864,91024
20,52000;-36,02533;4886,57542
20,56000;-36,02198;4906,53813
20,60000;-36,01875;4925,90554
20,64000;-36,01534;4947,73500
20,68000;-36,01193;4967,95215
20,72000;-36,00870;4987,15416
20,76000;-36,00536;5006,39640
20,80000;-36,00201;5029,95178
20,84000;-35,99878;5048,57674
20,88000;-35,99543;5067,06424
20,92000;-35,99209;5088,89742
20,96000;-35,98874;5110,20012
21,00000;-35,98557;5129,71655
21,04000;-35,98210;5151,94535
21,08000;-35,97875;5172,46351
21,12000;-35,97546;5191,30901
21,16000;-35,97217;5211,06198
21,20000;-35,96877;5232,30061
21,24000;-35,96542;5252,96293
21,28000;-35,96225;5273,55783
21,32000;-35,95872;5296,36145
21,36000;-35,95543;5317,66638
21,40000;-35,95209;5337,81834
21,44000;-35,94874;5357,75051
21,48000;-35,94551;5378,58568
21,52000;-35,94210;5400,09551
21,56000;-35,93863;5422,39472
21,60000;-35,93541;5447,53969
21,64000;-35,93205;5467,40144
21,68000;-35,92877;5486,72304
21,72000;-35,92548;5507,18792
21,76000;-35,92213;5526,51398
21,80000;-35,91878;5547,89677
21,84000;-35,91543;5569,13204
21,88000;-35,91214;5589,48740
21,92000;-35,90862;5612,27724
21,96000;-35,90539;5637,01391
22,00000;-35,90204;5655,01489
22,04000;-35,89869;5675,31288
22,08000;-35,89540;5696,25609
22,12000;-35,89212;5714,66237
22,16000;-35,88883;5735,48116
22,20000;-35,88536;5757,17390
22,24000;-35,88207;5779,69328
22,28000;-35,87878;5798,26608
22,32000;-35,87537;5818,47914
22,36000;-35,87209;5837,51313
22,40000;-35,86874;5858,34607
22,44000;-35,86539;5878,96332
22,48000;-35,86210;5898,09939
22,52000;-35,85869;5921,27368
22,56000;-35,85534;5939,42329
22,60000;-35,85205;5957,86534
22,64000;-35,84871;5977,86605
22,68000;-35,84530;5998,64572
22,72000;-35,84207;6017,80713
22,76000;-35,83878;6036,97821
22,80000;-35,83538;6057,87858
22,84000;-35,83209;6077,71687
22,88000;-35,82880;6095,55580
22,92000;-35,82533;6115,93761
22,96000;-35,82204;6138,26886
23,00000;-35,81875;6155,42196
23,04000;-35,81541;6174,52897
23,08000;-35,81212;6193,12488
23,12000;-35,80877;6210,19192
23,16000;-35,80548;6228,94093
23,20000;-35,80213;6247,50629
23,24000;-35,79872;6266,00087
23,28000;-35,79543;6284,28385
23,32000;-35,79209;6301,51778
23,36000;-35,78874;6322,46509
23,40000;-35,78545;6339,58280
23,44000;-35,78216;6356,26093
23,48000;-35,77881;6374,51559
23,52000;-35,77541;6392,74269
23,56000;-35,77206;6408,94398
23,60000;-35,76883;6425,31440
23,64000;-35,76542;6442,96333
23,68000;-35,76207;6460,13543
23,72000;-35,75885;6476,91712
23,76000;-35,75549;6492,47989
23,80000;-35,75209;6510,68389
23,84000;-35,74880;6527,77776
23,88000;-35,74545;6542,34961
23,92000;-35,74204;6559,54555
23,96000;-35,73875;6576,91658
24,00000;-35,73547;6590,95421
24,04000;-35,73206;6606,03791
24,08000;-35,72871;6622,35543
24,12000;-35,72542;6635,83651
24,16000;-35,72213;6650,14759
24,20000;-35,71873;6665,42426
24,24000;-35,71544;6679,18921
24,28000;-35,71209;6692,49594
24,32000;-35,70874;6706,26089
24,36000;-35,70539;6721,48019
24,40000;-35,70210;6733,49723
24,44000;-35,69881;6745,53737
24,48000;-35,69553;6758,01635
24,52000;-35,69206;6770,06990
24,56000;-35,68877;6781,58402
24,60000;-35,68548;6793,89238
24,64000;-35,68207;6806,42128
24,68000;-35,67867;6818,46663
24,72000;-35,67544;6827,99146
24,76000;-35,67209;6836,62817
24,80000;-35,66874;6847,26089
24,84000;-35,66545;6857,17762
24,88000;-35,66211;6866,32842
24,92000;-35,65876;6876,85981
24,96000;-35,65541;6885,49429
25,00000;-35,65212;6891,96289
25,04000;-35,64877;6899,39708
25,08000;-35,64537;6907,88180
25,12000;-35,64213;6914,07546
25,16000;-35,63879;6920,53437
25,20000;-35,63532;6928,13993
25,24000;-35,63197;6932,41060
25,28000;-35,62868;6935,84308
25,32000;-35,62527;6938,18480
25,36000;-35,62199;6939,80008
25,40000;-35,61864;6939,77326
25,44000;-35,61535;6938,57819
25,48000;-35,61212;6936,46148
25,52000;-35,60872;6932,72650
25,56000;-35,60537;6927,57145
25,60000;-35,60208;6918,77529
25,64000;-35,59879;6904,96564
25,68000;-35,59538;6890,01232
25,72000;-35,59209;6869,00392
25,76000;-35,58874;6840,76920
25,80000;-35,58533;6809,97893
25,84000;-35,58199;6768,81820
25,88000;-35,57864;6716,47862
25,92000;-35,57529;6653,98762
25,96000;-35,57194;6579,18081
26,00000;-35,56865;6489,36480
26,04000;-35,56531;6387,44608
26,08000;-35,56196;6277,74894
26,12000;-35,55867;6163,00926
26,16000;-35,55526;6052,75556
26,20000;-35,55191;5952,64733
26,24000;-35,54863;5861,10726
26,28000;-35,54534;5778,28363
26,32000;-35,54193;5705,18821
26,36000;-35,53864;5638,36247
26,40000;-35,53529;5575,08580
26,44000;-35,53194;5517,24322
26,48000;-35,52860;5463,42582
26,52000;-35,52525;5410,11319
26,56000;-35,52196;5357,19618
26,60000;-35,51873;5302,09094
26,64000;-35,51538;5244,54191
26,68000;-35,51197;5181,38483
26,72000;-35,50875;5110,04962
26,76000;-35,50534;5025,12716
26,80000;-35,50193;4915,83273
26,84000;-35,49864;4724,97866
26,88000;-35,49529;4322,32320
26,92000;-35,49183;3854,95164
26,96000;-35,48848;3593,27160
27,00000;-35,48519;3459,33922
27,04000;-35,48184;3368,63734
27,08000;-35,47849;3297,89780
27,12000;-35,47520;3239,27291
27,16000;-35,47197;3188,84365
27,20000;-35,46851;3146,23974
27,24000;-35,46528;3106,90813
27,28000;-35,46199;3070,96541
27,32000;-35,45864;3038,75580
27,36000;-35,45535;3009,92113
27,40000;-35,45194;2982,74662
27,44000;-35,44866;2957,32636
27,48000;-35,44537;2933,83431
27,52000;-35,44196;2912,85440
27,56000;-35,43861;2892,85947
27,60000;-35,43532;2873,30411
27,64000;-35,43198;2855,70938
27,68000;-35,42863;2839,22590
27,72000;-35,42540;2823,44054
27,76000;-35,42205;2807,47246
27,80000;-35,41870;2794,54663
27,84000;-35,41529;2779,63225
27,88000;-35,41200;2764,94063
27,92000;-35,40866;2750,26206
27,96000;-35,40525;2738,18821
28,00000;-35,40196;2725,25605
28,04000;-35,39873;2711,70754
28,08000;-35,39532;2700,25805
28,12000;-35,39204;2688,84487
28,16000;-35,38863;2676,83584
28,20000;-35,38534;2663,44603
28,24000;-35,38205;2651,62867
28,28000;-35,37864;2640,79086
28,32000;-35,37536;2629,76456
28,36000;-35,37207;2617,08479
28,40000;-35,36866;2606,35093
28,44000;-35,36531;2595,17115
28,48000;-35,36208;2582,37049
28,52000;-35,35873;2571,37511
28,56000;-35,35527;2563,02338
28,60000;-35,35204;2552,32044
28,64000;-35,34869;2540,95010
28,68000;-35,34534;2532,29905
28,72000;-35,34199;2522,36053
28,76000;-35,33876;2510,97400
28,80000;-35,33530;2501,47581
28,84000;-35,33195;2496,54669
28,88000;-35,32872;2485,73571
28,92000;-35,32537;2476,41634
28,96000;-35,32202;2469,84661
29,00000;-35,31873;2463,97536
29,04000;-35,31544;2457,24693
29,08000;-35,31210;2450,72674
29,12000;-35,30869;2447,93259
29,16000;-35,30534;2440,62133
29,20000;-35,30199;2433,43692
29,24000;-35,29870;2428,43255
29,28000;-35,29530;2422,29309
29,32000;-35,29201;2416,14114
29,36000;-35,28896;2410,44518
29,40000;-35,28531;2407,06392
29,44000;-35,28202;2403,60927
29,48000;-35,27874;2398,10087
29,52000;-35,27539;2393,44873
29,56000;-35,27204;2390,21052
29,60000;-35,26875;2386,51168
29,64000;-35,26540;2381,88729
29,68000;-35,26205;2378,52018
29,72000;-35,25871;2375,03070
29,76000;-35,25542;2369,26228
29,80000;-35,25201;2366,83208
29,84000;-35,24860;2366,54188
29,88000;-35,24537;2359,85350
29,92000;-35,24202;2354,34510
29,96000;-35,23868;2349,85165
30,00000;-35,23539;2345,90080
30,04000;-35,23210;2342,18445
30,08000;-35,22893;2340,38271
30,12000;-35,22534;2339,84124
30,16000;-35,22206;2336,99810
30,20000;-35,21877;2331,12387
30,24000;-35,21548;2328,07230
30,28000;-35,21207;2326,25231
30,32000;-35,20878;2323,35441
30,36000;-35,20549;2321,94662
30,40000;-35,20203;2321,36361
30,44000;-35,19874;2320,20374
30,48000;-35,19539;2318,89263
30,52000;-35,19204;2317,39152
30,56000;-35,18863;2315,60860
30,60000;-35,18540;2312,79563
30,64000;-35,18205;2310,69885
30,68000;-35,17865;2312,72485
30,72000;-35,17536;2311,82277
30,76000;-35,17207;2307,66665
30,80000;-35,16878;2304,95054
30,84000;-35,16538;2302,86922
30,88000;-35,16209;2301,28504
30,92000;-35,15874;2299,09364
30,96000;-35,15533;2298,02858
31,00000;-35,15204;2296,79812
31,04000;-35,14869;2294,84569
31,08000;-35,14535;2294,98129
31,12000;-35,14206;2293,72084
31,16000;-35,13865;2291,16678
31,20000;-35,13536;2289,51070
31,24000;-35,13207;2288,69487
31,28000;-35,12866;2287,00396
31,32000;-35,12543;2284,90606
31,36000;-35,12209;2283,47871
31,40000;-35,11874;2282,03181
31,44000;-35,11539;2279,57219
31,48000;-35,11204;2277,32230
31,52000;-35,10870;2275,85509
31,56000;-35,10535;2273,97382
31,60000;-35,10206;2272,35053
31,64000;-35,09871;2272,52785
31,68000;-35,09536;2270,91946
31,72000;-35,09207;2269,05867
31,76000;-35,08878;2267,35901
31,80000;-35,08538;2265,98699
31,84000;-35,08197;2265,62452
31,88000;-35,07886;2262,98664
31,92000;-35,07539;2262,50216
31,96000;-35,07204;2261,76158
32,00000;-35,06875;2259,30326
32,04000;-35,06547;2256,08051
32,08000;-35,06218;2255,50700
32,12000;-35,05871;2255,70574
32,16000;-35,05542;2252,15610
32,20000;-35,05208;2249,84940
32,24000;-35,04879;2247,35923
32,28000;-35,04544;2245,04303
32,32000;-35,04221;2241,74447
32,36000;-35,03880;2239,58921
32,40000;-35,03545;2237,72898
32,44000;-35,03204;2235,78978
32,48000;-35,02876;2233,17929
32,52000;-35,02541;2231,10523
32,56000;-35,02206;2229,04440
32,60000;-35,01883;2227,73105
32,64000;-35,01548;2227,07409
32,68000;-35,01207;2225,72386
32,72000;-35,00873;2223,96422
32,76000;-35,00550;2219,95711
32,80000;-35,00209;2218,98649
32,84000;-34,99868;2217,67500
32,88000;-34,99545;2215,09971
32,92000;-34,99211;2212,42532
32,96000;-34,98870;2211,05572
33,00000;-34,98541;2209,83252
33,04000;-34,98212;2206,86775
33,08000;-34,97865;2205,63076
33,12000;-34,97536;2204,80692
33,16000;-34,97201;2201,07250
33,20000;-34,96872;2198,40258
33,24000;-34,96538;2197,78214
33,28000;-34,96203;2195,67306
33,32000;-34,95868;2192,54494
33,36000;-34,95533;2190,04992
33,40000;-34,95198;2187,18909
33,44000;-34,94864;2184,88555
33,48000;-34,94535;2182,99776
33,52000;-34,94206;2179,22777
33,56000;-34,93895;2177,92206
33,60000;-34,93531;2178,73380
33,64000;-34,93202;2178,24392
33,68000;-34,92861;2175,14317
33,72000;-34,92526;2173,43997
33,76000;-34,92203;2170,37741
33,80000;-34,91862;2168,69134
33,84000;-34,91527;2168,66396
33,88000;-34,91199;2166,12518
33,92000;-34,90858;2164,44358
33,96000;-34,90523;2166,57221
34,00000;-34,90200;2164,03753
34,04000;-34,89871;2160,71606
34,08000;-34,89536;2159,43642
34,12000;-34,89208;2158,31790
34,16000;-34,88867;2156,38820
34,20000;-34,88538;2154,99699
34,24000;-34,88221;2153,82781
34,28000;-34,87863;2155,35611
34,32000;-34,87534;2153,25449
34,36000;-34,87211;2150,43221
34,40000;-34,86870;2148,19945
34,44000;-34,86535;2146,72294
34,48000;-34,86206;2144,79528
34,52000;-34,85871;2142,75103
34,56000;-34,85531;2143,03378
34,60000;-34,85202;2141,21640
34,64000;-34,84885;2139,45974
34,68000;-34,84538;2140,95619
34,72000;-34,84203;2139,78924
34,76000;-34,83881;2137,79174
34,80000;-34,83546;2136,66745
34,84000;-34,83199;2137,62075
34,88000;-34,82876;2137,46224
34,92000;-34,82547;2135,68658
34,96000;-34,82206;2135,45933
35,00000;-34,81878;2136,75387
35,04000;-34,81537;2136,16416
35,08000;-34,81202;2135,55731
35,12000;-34,80879;2135,72532
35,16000;-34,80532;2137,18452
35,20000;-34,80203;2137,17110
35,24000;-34,79880;2137,40487
35,28000;-34,79534;2139,16488
35,32000;-34,79205;2140,36349
35,36000;-34,78882;2139,90211
35,40000;-34,78541;2141,16257
35,44000;-34,78206;2142,80821
35,48000;-34,77872;2142,64635
35,52000;-34,77543;2142,24979
35,56000;-34,77208;2143,76822
35,60000;-34,76867;2145,92498
35,64000;-34,76544;2146,23548
35,68000;-34,76209;2148,78879
35,72000;-34,75863;2152,27678
35,76000;-34,75534;2153,13062
35,80000;-34,75211;2154,38325
35,84000;-34,74858;2157,42979
35,88000;-34,74529;2163,22318
35,92000;-34,74200;2164,18039
35,96000;-34,73871;2165,37174
36,00000;-34,73537;2166,74637
36,04000;-34,73202;2168,07406
36,08000;-34,72867;2169,58225
36,12000;-34,72538;2171,48904
36,16000;-34,72198;2174,79765
36,20000;-34,71863;2178,18208
36,24000;-34,71540;2180,11700
36,28000;-34,71199;2186,51015
36,32000;-34,70864;2187,61861
36,36000;-34,70535;2187,22355
36,40000;-34,70195;2187,14159
36,44000;-34,69872;2188,85355
36,48000;-34,69537;2189,51739
36,52000;-34,69220;2190,71284
36,56000;-34,68867;2195,43148
36,60000;-34,68538;2195,76471
36,64000;-34,68203;2193,85140
36,68000;-34,67875;2194,84009
36,72000;-34,67534;2195,99567
36,76000;-34,67211;2198,35844
36,80000;-34,66876;2199,59281
36,84000;-34,66554;2200,61578
36,88000;-34,66207;2203,54367
36,92000;-34,65872;2204,03727
36,96000;-34,65537;2202,91540
37,00000;-34,65214;2203,88882
37,04000;-34,64873;2204,07434
37,08000;-34,64544;2205,66522
37,12000;-34,64215;2206,65354
37,16000;-34,63869;2208,82595
37,20000;-34,63540;2210,55076
37,24000;-34,63205;2211,41204
37,28000;-34,62870;2211,75011
37,32000;-34,62541;2212,43203
37,36000;-34,62207;2213,16125
37,40000;-34,61872;2215,13957
37,44000;-34,61543;2218,12893
37,48000;-34,61208;2218,68381
37,52000;-34,60879;2219,17015
37,56000;-34,60539;2221,27158
37,60000;-34,60204;2222,76207
37,64000;-34,59881;2223,49167
37,68000;-34,59546;2224,48837
37,72000;-34,59199;2226,28433
37,76000;-34,58882;2227,38311
37,80000;-34,58547;2228,12351
37,84000;-34,58207;2230,63603
37,88000;-34,57878;2232,95670
37,92000;-34,57543;2233,42534
37,96000;-34,57214;2233,63750
38,00000;-34,56879;2235,88049
38,04000;-34,56545;2235,57111
38,08000;-34,56216;2236,19770
38,12000;-34,55881;2238,35949
38,16000;-34,55540;2239,73598
38,20000;-34,55211;2241,24733
38,24000;-34,54883;2243,27501
38,28000;-34,54542;2244,42706
38,32000;-34,54207;2245,88513
38,36000;-34,53872;2246,99862
38,40000;-34,53537;2247,08021
38,44000;-34,53203;2249,43478
38,48000;-34,52868;2250,06528
38,52000;-34,52539;2248,77615
38,56000;-34,52204;2248,98830
38,60000;-34,51869;2250,28209
38,64000;-34,51546;2250,10030
38,68000;-34,51211;2250,23944
38,72000;-34,50871;2252,02031
38,76000;-34,50542;2252,72402
38,80000;-34,50213;2251,82809
38,84000;-34,49872;2252,54651
38,88000;-34,49538;2254,52781
38,92000;-34,49209;2253,10400
38,96000;-34,48868;2253,70638
39,00000;-34,48533;2254,81354
39,04000;-34,48198;2254,14038
39,08000;-34,47869;2253,10083
39,12000;-34,47535;2252,13729
39,16000;-34,47199;2251,77668
39,20000;-34,46870;2250,61532
39,24000;-34,46536;2250,33313
39,28000;-34,46207;2250,24857
39,32000;-34,45872;2249,30644
39,36000;-34,45537;2248,47980
39,40000;-34,45209;2247,74312
39,44000;-34,44874;2247,76510
39,48000;-34,44539;2248,25069
39,52000;-34,44210;2247,20351
39,56000;-34,43875;2246,38265
39,60000;-34,43534;2245,19223
39,64000;-34,43212;2243,11668
39,68000;-34,42877;2242,07100
39,72000;-34,42536;2241,42764
39,76000;-34,42213;2240,67178
39,80000;-34,41878;2238,14491
39,84000;-34,41537;2238,53420
39,88000;-34,41209;2238,18738
39,92000;-34,40880;2235,99225
39,96000;-34,40539;2234,71951
40,00000;-34,40210;2234,30861
40,04000;-34,39875;2232,77435
40,08000;-34,39547;2230,18937
40,12000;-34,39212;2230,39240
40,16000;-34,38877;2230,22383
40,20000;-34,38548;2229,70434
40,24000;-34,38207;2227,70236
40,28000;-34,37873;2227,51107
40,32000;-34,37538;2227,09030
40,36000;-34,37209;2226,10906
40,40000;-34,36880;2225,73876
40,44000;-34,36539;2227,48704
40,48000;-34,36204;2228,23787
40,52000;-34,35875;2227,62171
40,56000;-34,35534;2228,62158
40,60000;-34,35200;2228,79648
40,64000;-34,34877;2228,51131
40,68000;-34,34542;2228,13226
40,72000;-34,34201;2231,46193
40,76000;-34,33873;2231,63366
40,80000;-34,33538;2230,31361
40,84000;-34,33197;2231,09573
40,88000;-34,32868;2231,33974
40,92000;-34,32539;2229,87216
40,96000;-34,32204;2229,72594
41,00000;-34,31870;2231,90244
41,04000;-34,31535;2232,05052
41,08000;-34,31200;2232,27181
41,12000;-34,30865;2232,73672
41,16000;-34,30530;2232,73020
41,20000;-34,30201;2233,45272
41,24000;-34,29872;2233,72690
41,28000;-34,29538;2235,40068
41,32000;-34,29197;2237,47324
41,36000;-34,28862;2237,74277
41,40000;-34,28539;2236,86863
41,44000;-34,28198;2237,60363
41,48000;-34,27864;2239,48620
41,52000;-34,27541;2238,72028
41,56000;-34,27206;2239,49328
41,60000;-34,26865;2241,54629
41,64000;-34,26543;2243,01405
41,68000;-34,26202;2243,19454
41,72000;-34,25861;2245,24736
41,76000;-34,25532;2246,15894
41,80000;-34,25203;2244,19236
41,84000;-34,24868;2245,12201
41,88000;-34,24533;2246,11629
41,92000;-34,24198;2246,85427
41,96000;-34,23870;2245,53254
42,00000;-34,23535;2246,17384
42,04000;-34,23200;2246,67769
42,08000;-34,22871;2246,86228
42,12000;-34,22536;2247,43672
42,16000;-34,22202;2249,39212
42,20000;-34,21867;2248,71356
42,24000;-34,21538;2249,09019
42,28000;-34,21203;2250,13178
42,32000;-34,20868;2251,05677
42,36000;-34,20534;2250,74254
42,40000;-34,20210;2251,28755
42,44000;-34,19864;2252,50535
42,48000;-34,19529;2252,53422
42,52000;-34,19218;2251,14021
42,56000;-34,18865;2251,95456
42,60000;-34,18536;2253,90419
42,64000;-34,18214;2253,52272
42,68000;-34,17879;2252,44612
42,72000;-34,17538;2254,16869
42,76000;-34,17209;2255,71468
42,80000;-34,16874;2254,54271
42,84000;-34,16546;2254,28473
42,88000;-34,16211;2256,05275
42,92000;-34,15876;2255,91566
42,96000;-34,15571;2255,89573
43,00000;-34,15194;2259,09036
43,04000;-34,14866;2258,66828
43,08000;-34,14531;2255,81080
43,12000;-34,14202;2253,85688
43,16000;-34,13873;2253,30107
43,20000;-34,13538;2254,00254
43,24000;-34,13203;2251,93128
43,28000;-34,12892;2251,68616
43,32000;-34,12527;2255,00464
43,36000;-34,12199;2255,14751
43,40000;-34,11882;2252,49305
43,44000;-34,11541;2252,38670
43,48000;-34,11206;2252,64281
43,52000;-34,10878;2252,49007
43,56000;-34,10537;2253,55290
43,60000;-34,10196;2258,50753
43,64000;-34,09867;2257,83251
43,68000;-34,09532;2256,89653
43,72000;-34,09203;2255,69047
43,76000;-34,08869;2256,55660
43,80000;-34,08540;2255,32576
43,84000;-34,08211;2254,25866
43,88000;-34,07876;2256,51022
43,92000;-34,07541;2258,09719
43,96000;-34,07236;2257,42385
44,00000;-34,06877;2260,37875
44,04000;-34,06543;2260,48324
44,08000;-34,06208;2258,38218
44,12000;-34,05873;2257,27223
44,16000;-34,05544;2257,14501
44,20000;-34,05204;2257,68257
44,24000;-34,04869;2257,45607
44,28000;-34,04546;2256,88647
44,32000;-34,04211;2257,07516
44,36000;-34,03864;2260,33833
44,40000;-34,03541;2259,60240
44,44000;-34,03201;2258,83368
44,48000;-34,02872;2260,02801
44,52000;-34,02543;2260,20962
44,56000;-34,02208;2260,02783
44,60000;-34,01873;2260,91072
44,60400;-34,01843;2260,83547