File: SU - Suspension/05 - Essais/Excels essais Optimus/collage alu carbone 05_02_19/collage9.is_tens_RawData/Specimen_RawData_1.csv
Temps;Déplacement;Charge
(sec);(mm);(N)
0,00000;0,01268;38,67560
0,04000;0,01327;38,21958
0,08000;0,01561;42,09303
0,12000;0,01889;53,67153
0,16000;0,02260;66,99237
0,20000;0,02655;81,64863
0,24000;0,03043;95,06609
0,28000;0,03414;107,09829
0,32000;0,03773;119,01669
0,36000;0,04137;130,00924
0,40000;0,04478;139,55652
0,44000;0,04831;148,20816
0,48000;0,05178;157,41767
0,52000;0,05513;165,89392
0,56000;0,05853;173,37801
0,60000;0,06194;181,80215
0,64000;0,06529;190,71077
0,68000;0,06864;198,41399
0,72000;0,07205;206,56602
0,76000;0,07539;214,48089
0,80000;0,07874;224,00504
0,84000;0,08209;232,94454
0,88000;0,08550;241,39371
0,92000;0,08879;250,68824
0,96000;0,09208;259,61217
1,00000;0,09542;267,46807
1,04000;0,09877;276,27752
1,08000;0,10212;284,74883
1,12000;0,10541;293,40095
1,16000;0,10870;301,36586
1,20000;0,11211;310,57610
1,24000;0,11545;319,52427
1,28000;0,11874;328,46835
1,32000;0,12215;338,21750
1,36000;0,12550;346,27067
1,40000;0,12867;352,24280
1,44000;0,13202;312,54492
1,48000;0,13536;302,59313
1,52000;0,13859;319,99983
1,56000;0,14194;334,36129
1,60000;0,14529;350,09682
1,64000;0,14864;363,92524
1,68000;0,15198;376,23434
1,72000;0,15527;389,92476
1,76000;0,15868;402,75543
1,80000;0,16197;413,90136
1,84000;0,16526;426,16106
1,88000;0,16867;438,92758
1,92000;0,17201;450,24962
1,96000;0,17530;462,02904
2,00000;0,17871;473,71020
2,04000;0,18200;486,25921
2,08000;0,18535;497,10874
2,12000;0,18870;509,30893
2,16000;0,19198;520,51716
2,20000;0,19539;531,93830
2,24000;0,19874;543,79138
2,28000;0,20203;555,07771
2,32000;0,20544;565,72547
2,36000;0,20878;576,52951
2,40000;0,21201;586,99255
2,44000;0,21536;595,83276
2,48000;0,21871;606,74185
2,52000;0,22206;616,63110
2,56000;0,22541;626,73474
2,60000;0,22875;635,66086
2,64000;0,23210;645,59630
2,68000;0,23539;653,28339
2,72000;0,23868;661,79670
2,76000;0,24209;670,74834
2,80000;0,24532;679,08010
2,84000;0,24872;686,27219
2,88000;0,25213;695,90299
2,92000;0,25542;703,64238
2,96000;0,25877;710,43237
3,00000;0,26200;719,04892
3,04000;0,26541;727,18761
3,08000;0,26881;734,59861
3,12000;0,27210;741,86195
3,16000;0,27539;748,85818
3,20000;0,27880;756,68450
3,24000;0,28209;763,49722
3,28000;0,28532;771,58110
3,32000;0,28872;780,06741
3,36000;0,29207;786,86569
3,40000;0,29536;794,71571
3,44000;0,29865;800,99758
3,48000;0,30212;809,99034
3,52000;0,30546;817,61228
3,56000;0,30869;823,86127
3,60000;0,31204;830,52116
3,64000;0,31539;838,42427
3,68000;0,31874;845,29407
3,72000;0,32209;851,68304
3,76000;0,32549;859,58960
3,80000;0,32878;866,91482
3,84000;0,33201;874,00908
3,88000;0,33542;880,26021
3,92000;0,33877;888,30134
3,96000;0,34206;895,69017
4,00000;0,34546;901,84277
4,04000;0,34875;908,99942
4,08000;0,35210;916,54612
4,12000;0,35545;922,02034
4,16000;0,35868;929,80741
4,20000;0,36209;936,20736
4,24000;0,36549;943,47671
4,28000;0,36878;949,66022
4,32000;0,37207;955,81571
4,36000;0,37542;962,78088
4,40000;0,37871;969,81861
4,44000;0,38194;974,87969
4,48000;0,38540;982,61628
4,52000;0,38869;989,33671
4,56000;0,39204;995,81154
4,60000;0,39533;1002,30062
4,64000;0,39874;1009,41230
4,68000;0,40202;1015,82427
4,72000;0,40537;1022,22199
4,76000;0,40872;1029,10157
4,80000;0,41201;1035,53394
4,84000;0,41536;1041,75592
4,88000;0,41871;1048,17105
4,92000;0,42205;1056,72302
4,96000;0,42540;1063,17028
5,00000;0,42875;1069,18225
5,04000;0,43168;1076,10570
5,08000;0,43545;1083,78706
5,12000;0,43874;1090,19922
5,16000;0,44196;1096,93771
5,20000;0,44537;1102,87275
5,24000;0,44872;1110,16808
5,28000;0,45201;1116,93265
5,32000;0,45530;1122,72156
5,36000;0,45870;1130,75059
5,40000;0,46205;1137,94385
5,44000;0,46534;1145,25976
5,48000;0,46875;1152,47825
5,52000;0,47210;1160,83035
5,56000;0,47539;1167,18318
5,60000;0,47873;1173,98435
5,64000;0,48208;1180,99172
5,68000;0,48531;1187,93380
5,72000;0,48854;1194,69371
5,76000;0,49201;1204,09140
5,80000;0,49536;1211,84941
5,84000;0,49864;1218,09468
5,88000;0,50205;1225,27806
5,92000;0,50534;1232,57255
5,96000;0,50869;1240,41783
6,00000;0,51210;1248,85319
6,04000;0,51533;1256,37539
6,08000;0,51873;1264,66332
6,12000;0,52208;1271,74314
6,16000;0,52537;1279,21328
6,20000;0,52872;1286,39312
6,24000;0,53207;1294,75938
6,28000;0,53536;1304,51676
6,32000;0,53852;1311,43546
6,36000;0,54211;1320,34821
6,40000;0,54534;1328,81701
6,44000;0,54875;1336,21115
6,48000;0,55210;1344,34784
6,52000;0,55538;1352,99787
6,56000;0,55873;1361,31281
6,60000;0,56202;1368,99948
6,64000;0,56549;1377,12117
6,68000;0,56872;1387,01368
6,72000;0,57207;1394,05541
6,76000;0,57541;1403,33008
6,80000;0,57870;1412,02826
6,84000;0,58205;1420,07116
6,88000;0,58540;1428,75146
6,92000;0,58869;1437,26012
6,96000;0,59204;1445,06022
7,00000;0,59532;1453,94308
7,04000;0,59867;1463,70940
7,08000;0,60202;1471,82969
7,12000;0,60537;1481,23251
7,16000;0,60860;1489,60594
7,20000;0,61201;1498,35870
7,24000;0,61535;1507,82671
7,28000;0,61864;1516,09061
7,32000;0,62193;1524,64025
7,36000;0,62534;1534,51879
7,40000;0,62869;1543,75890
7,44000;0,63197;1553,13350
7,48000;0,63532;1561,50647
7,52000;0,63873;1571,51856
7,56000;0,64202;1581,05101
7,60000;0,64537;1589,50258
7,64000;0,64878;1598,43732
7,68000;0,65200;1607,55254
7,72000;0,65529;1616,28891
7,76000;0,65864;1626,16242
7,80000;0,66193;1635,89362
7,84000;0,66534;1645,00363
7,88000;0,66863;1653,35461
7,92000;0,67197;1662,82505
7,96000;0,67532;1672,12114
8,00000;0,67867;1682,08908
8,04000;0,68190;1690,90740
8,08000;0,68531;1699,10267
8,12000;0,68866;1708,75993
8,16000;0,69194;1717,71310
8,20000;0,69535;1727,06805
8,24000;0,69876;1736,33974
8,28000;0,70205;1746,20934
8,32000;0,70534;1754,15780
8,36000;0,70868;1763,18511
8,40000;0,71197;1773,20484
8,44000;0,71526;1780,52187
8,48000;0,71867;1790,85266
8,52000;0,72202;1799,91927
8,56000;0,72531;1808,46322
8,60000;0,72865;1816,75386
8,64000;0,73200;1826,66630
8,68000;0,73529;1835,81822
8,72000;0,73864;1844,20832
8,76000;0,74205;1853,81249
8,80000;0,74540;1862,89195
8,84000;0,74868;1871,77286
8,88000;0,75209;1880,38722
8,92000;0,75532;1889,64326
8,96000;0,75873;1897,90912
9,00000;0,76202;1906,92265
9,04000;0,76525;1916,65683
9,08000;0,76865;1925,27231
9,12000;0,77200;1934,77422
9,16000;0,77529;1943,80544
9,20000;0,77864;1953,08849
9,24000;0,78205;1964,87345
9,28000;0,78533;1976,61128
9,32000;0,78862;1989,53860
9,36000;0,79203;2004,80148
9,40000;0,79544;2019,29472
9,44000;0,79873;2034,20091
9,48000;0,80208;2049,35744
9,52000;0,80548;2064,60431
9,56000;0,80865;2080,42488
9,60000;0,81194;2095,61493
9,64000;0,81535;2111,32541
9,68000;0,81864;2127,59003
9,72000;0,82199;2142,85888
9,76000;0,82539;2159,93803
9,80000;0,82868;2177,03804
9,84000;0,83203;2192,30633
9,88000;0,83532;2208,20289
9,92000;0,83867;2225,89392
9,96000;0,84202;2243,49033
10,00000;0,84536;2259,32803
10,04000;0,84871;2276,67689
10,08000;0,85206;2293,18831
10,12000;0,85541;2310,92889
10,16000;0,85870;2327,62750
10,20000;0,86204;2344,74596
10,24000;0,86539;2362,82554
10,28000;0,86868;2380,74232
10,32000;0,87197;2397,00451
10,36000;0,87538;2414,93806
10,40000;0,87873;2432,76134
10,44000;0,88195;2450,16869
10,48000;0,88536;2467,84333
10,52000;0,88877;2486,03318
10,56000;0,89206;2503,46530
10,60000;0,89541;2520,23041
10,64000;0,89876;2537,77020
10,68000;0,90204;2555,84009
10,72000;0,90539;2572,98071
10,76000;0,90868;2590,35192
10,80000;0,91197;2608,27709
10,84000;0,91538;2626,92533
10,88000;0,91867;2644,72067
10,92000;0,92201;2662,81329
10,96000;0,92536;2680,97520
11,00000;0,92871;2698,00257
11,04000;0,93194;2714,85206
11,08000;0,93535;2732,38439
11,12000;0,93870;2750,49508
11,16000;0,94198;2768,03002
11,20000;0,94533;2784,16704
11,24000;0,94874;2801,90241
11,28000;0,95203;2819,61374
11,32000;0,95532;2836,08548
11,36000;0,95866;2854,30923
11,40000;0,96207;2872,41321
11,44000;0,96536;2889,45772
11,48000;0,96871;2907,23406
11,52000;0,97212;2925,27955
11,56000;0,97541;2942,72192
11,60000;0,97863;2960,12480
11,64000;0,98210;2977,71096
11,68000;0,98539;2995,92894
11,72000;0,98874;3012,09278
11,76000;0,99209;3029,66461
11,80000;0,99538;3048,98024
11,84000;0,99872;3065,49948
11,88000;1,00195;3082,18542
11,92000;1,00536;3101,13132
11,96000;1,00877;3117,48907
12,00000;1,01206;3134,49204
12,04000;1,01535;3152,55746
12,08000;1,01875;3170,22763
12,12000;1,02210;3188,55569
12,16000;1,02545;3206,13198
12,20000;1,02880;3224,21715
12,24000;1,03215;3243,67806
12,28000;1,03543;3260,69370
12,32000;1,03872;3277,18332
12,36000;1,04201;3293,49823
12,40000;1,04536;3310,33021
12,44000;1,04865;3327,50753
12,48000;1,05182;3344,21508
12,52000;1,05540;3363,34966
12,56000;1,05863;3381,07720
12,60000;1,06204;3397,29413
12,64000;1,06527;3414,10227
12,68000;1,06868;3432,79280
12,72000;1,07203;3450,05728
12,76000;1,07531;3467,85299
12,80000;1,07860;3485,51832
12,84000;1,08207;3504,24275
12,88000;1,08536;3520,85792
12,92000;1,08865;3537,95178
12,96000;1,09200;3554,11321
13,00000;1,09528;3571,10910
13,04000;1,09845;3588,41494
13,08000;1,10198;3606,33247
13,12000;1,10533;3625,40632
13,16000;1,10868;3643,57084
13,20000;1,11191;3660,02619
13,24000;1,11525;3677,87592
13,28000;1,11866;3695,29687
13,32000;1,12195;3711,23701
13,36000;1,12506;3727,71919
13,40000;1,12883;3746,59896
13,44000;1,13205;3764,71207
13,48000;1,13534;3780,49947
13,52000;1,13869;3798,56266
13,56000;1,14198;3815,41066
13,60000;1,14533;3832,63342
13,64000;1,14862;3850,04245
13,68000;1,15196;3867,88398
13,72000;1,15537;3884,66939
13,76000;1,15860;3900,87590
13,80000;1,16183;3917,45009
13,84000;1,16536;3934,94926
13,88000;1,16865;3951,66017
13,92000;1,17193;3967,93000
13,96000;1,17534;3984,63681
14,00000;1,17869;4002,38484
14,04000;1,18192;4019,18963
14,08000;1,18539;4037,30497
14,12000;1,18873;4054,55269
14,16000;1,19208;4071,27216
14,20000;1,19531;4087,24323
14,24000;1,19872;4105,32579
14,28000;1,20207;4123,78237
14,32000;1,20512;4138,46113
14,36000;1,20870;4155,28826
14,40000;1,21205;4174,08049
14,44000;1,21528;4190,18567
14,48000;1,21863;4206,80605
14,52000;1,22204;4224,59692
14,56000;1,22533;4241,95454
14,60000;1,22867;4258,24784
14,64000;1,23202;4275,52350
14,68000;1,23537;4293,05732
14,72000;1,23872;4309,99584
14,76000;1,24207;4326,66279
14,80000;1,24536;4342,75568
14,84000;1,24870;4359,24865
14,88000;1,25205;4375,84557
14,92000;1,25528;4392,81575
14,96000;1,25863;4408,89969
15,00000;1,26198;4425,60054
15,04000;1,26532;4442,36062
15,08000;1,26861;4458,66995
15,12000;1,27202;4476,23245
15,16000;1,27537;4492,95379
15,20000;1,27860;4508,89580
15,24000;1,28201;4525,68978
15,28000;1,28541;4543,48922
15,32000;1,28858;4559,03038
15,36000;1,29199;4576,19540
15,40000;1,29540;4593,07022
15,44000;1,29863;4610,89052
15,48000;1,30198;4626,04128
15,52000;1,30532;4643,65594
15,56000;1,30861;4661,05491
15,60000;1,31190;4678,10333
15,64000;1,31531;4696,60349
15,68000;1,31860;4714,87455
15,72000;1,32201;4731,40553
15,76000;1,32529;4749,18708
15,80000;1,32858;4765,67075
15,84000;1,33199;4781,95660
15,88000;1,33528;4799,01545
15,92000;1,33863;4816,86592
15,96000;1,34198;4834,65530
16,00000;1,34532;4852,82950
16,04000;1,34867;4869,94237
16,08000;1,35196;4887,12937
16,12000;1,35537;4904,04516
16,16000;1,35866;4920,95388
16,20000;1,36194;4937,71918
16,24000;1,36535;4956,13590
16,28000;1,36876;4973,10460
16,32000;1,37199;4989,85946
16,36000;1,37534;5006,46979
16,40000;1,37869;5023,91793
16,44000;1,38197;5041,51992
16,48000;1,38526;5058,56797
16,52000;1,38867;5076,95153
16,56000;1,39196;5095,64877
16,60000;1,39531;5111,23873
16,64000;1,39872;5128,84669
16,68000;1,40200;5147,27794
16,72000;1,40541;5164,80319
16,76000;1,40852;5181,28797
16,80000;1,41211;5200,94149
16,84000;1,41546;5219,12649
16,88000;1,41874;5236,24122
16,92000;1,42209;5253,17453
16,96000;1,42544;5270,10635
17,00000;1,42879;5287,26019
17,04000;1,43208;5304,79066
17,08000;1,43531;5321,02399
17,12000;1,43871;5338,79660
17,16000;1,44200;5356,04097
17,20000;1,44535;5375,24894
17,24000;1,44876;5393,13219
17,28000;1,45211;5411,69941
17,32000;1,45534;5428,79738
17,36000;1,45868;5445,34028
17,40000;1,46209;5464,55160
17,44000;1,46538;5482,84501
17,48000;1,46867;5498,23008
17,52000;1,47214;5517,76886
17,56000;1,47543;5535,49156
17,60000;1,47865;5551,69359
17,64000;1,48200;5569,57945
17,68000;1,48535;5587,27570
17,72000;1,48870;5605,40929
17,76000;1,49205;5622,25245
17,80000;1,49534;5638,96671
17,84000;1,49868;5658,95662
17,88000;1,50203;5676,46250
17,92000;1,50532;5693,39059
17,96000;1,50867;5710,72027
18,00000;1,51208;5729,50393
18,04000;1,51542;5746,71663
18,08000;1,51871;5763,85222
18,12000;1,52206;5781,33725
18,16000;1,52541;5798,06305
18,20000;1,52858;5813,60944
18,24000;1,53199;5831,73670
18,28000;1,53539;5850,06736
18,32000;1,53868;5867,45963
18,36000;1,54197;5884,14259
18,40000;1,54538;5901,71814
18,44000;1,54867;5919,35329
18,48000;1,55202;5935,40519
18,52000;1,55530;5952,24388
18,56000;1,55871;5970,75373
18,60000;1,56206;5987,37672
18,64000;1,56535;6003,90099
18,68000;1,56870;6020,79034
18,72000;1,57205;6038,94591
18,76000;1,57533;6055,25188
18,80000;1,57862;6071,46770
18,84000;1,58203;6089,98910
18,88000;1,58538;6107,35491
18,92000;1,58861;6123,39154
18,96000;1,59196;6139,56973
19,00000;1,59536;6156,46392
19,04000;1,59865;6173,52873
19,08000;1,60194;6188,46901
19,12000;1,60535;6205,33675
19,16000;1,60876;6222,34419
19,20000;1,61198;6238,69486
19,24000;1,61545;6256,84038
19,28000;1,61880;6275,71866
19,32000;1,62209;6292,22319
19,36000;1,62538;6308,10410
19,40000;1,62861;6325,27098
19,44000;1,63213;6343,96523
19,48000;1,63542;6361,10678
19,52000;1,63871;6376,83198
19,56000;1,64206;6392,66968
19,60000;1,64535;6407,76828
19,64000;1,64870;6424,70047
19,68000;1,65198;6440,49793
19,72000;1,65533;6457,63129
19,76000;1,65874;6476,93053
19,80000;1,66203;6493,43580
19,84000;1,66538;6509,25934
19,88000;1,66872;6526,31745
19,92000;1,67201;6542,99110
19,96000;1,67506;6558,76920
20,00000;1,67877;6577,07676
20,04000;1,68206;6594,63853
20,08000;1,68529;6609,72893
20,12000;1,68863;6626,70210
20,16000;1,69204;6642,74991
20,20000;1,69527;6659,12256
20,24000;1,69862;6674,78368
20,28000;1,70203;6692,10032
20,32000;1,70532;6710,60011
20,36000;1,70860;6726,75893
20,40000;1,71195;6742,41483
20,44000;1,71524;6758,84485
20,48000;1,71859;6773,94494
20,52000;1,72194;6790,13655
20,56000;1,72529;6806,83330
20,60000;1,72869;6824,04637
20,64000;1,73198;6840,51886
20,68000;1,73533;6858,18642
20,72000;1,73868;6875,88379
20,76000;1,74197;6891,51809
20,80000;1,74532;6908,45028
20,84000;1,74860;6924,52639
20,88000;1,75195;6942,04494
20,92000;1,75530;6958,40865
20,96000;1,75859;6974,16738
21,00000;1,76200;6989,77187
21,04000;1,76528;7006,32334
21,08000;1,76857;7022,01575
21,12000;1,77198;7037,17396
21,16000;1,77539;7055,36753
21,20000;1,77862;7070,87740
21,24000;1,78197;7086,50351
21,28000;1,78537;7102,80389
21,32000;1,78860;7119,75172
21,36000;1,79195;7135,02020
21,40000;1,79536;7151,98368
21,44000;1,79871;7169,41282
21,48000;1,80206;7183,75966
21,52000;1,80534;7200,03769
21,56000;1,80869;7215,65858
21,60000;1,81204;7230,55974
21,64000;1,81527;7245,77978
21,68000;1,81868;7261,22037
21,72000;1,82202;7277,99609
21,76000;1,82537;7293,33758
21,80000;1,82866;7308,43619
21,84000;1,83201;7324,67845
21,88000;1,83536;7341,68664
21,92000;1,83871;7357,41258
21,96000;1,84205;7372,83453
22,00000;1,84540;7389,36514
22,04000;1,84875;7404,39221
22,08000;1,85198;7419,65100
22,12000;1,85539;7434,62369
22,16000;1,85874;7450,05831
22,20000;1,86196;7465,99063
22,24000;1,86531;7481,13245
22,28000;1,86872;7497,31213
22,32000;1,87201;7512,38838
22,36000;1,87530;7527,02132
22,40000;1,87865;7542,68840
22,44000;1,88199;7558,04181
22,48000;1,88528;7572,88933
22,52000;1,88863;7588,89094
22,56000;1,89204;7605,68082
22,60000;1,89539;7621,09756
22,64000;1,89873;7635,40715
22,68000;1,90202;7649,83445
22,72000;1,90537;7664,26697
22,76000;1,90866;7679,58239
22,80000;1,91201;7694,98274
22,84000;1,91536;7710,66025
22,88000;1,91870;7725,70968
22,92000;1,92199;7740,88129
22,96000;1,92522;7756,13636
23,00000;1,92869;7770,79388
23,04000;1,93198;7786,38721
23,08000;1,93521;7801,46196
23,12000;1,93867;7816,94949
23,16000;1,94208;7833,48307
23,20000;1,94531;7848,15624
23,24000;1,94872;7862,50234
23,28000;1,95207;7877,07493
23,32000;1,95536;7892,63844
23,36000;1,95864;7906,56060
23,40000;1,96199;7922,64938
23,44000;1,96534;7938,10636
23,48000;1,96863;7953,04179
23,52000;1,97198;7968,18808
23,56000;1,97533;7983,23601
23,60000;1,97861;7997,15444
23,64000;1,98196;8011,53705
23,68000;1,98531;8026,27951
23,72000;1,98866;8041,29019
23,76000;1,99201;8056,36197
23,80000;1,99535;8069,97642
23,84000;1,99864;8084,70324
23,88000;2,00205;8100,08049
23,92000;2,00540;8114,19114
23,96000;2,00863;8128,17514
24,00000;2,01198;8143,32366
24,04000;2,01538;8158,41258
24,08000;2,01861;8173,18708
24,12000;2,02202;8188,04502
24,16000;2,02543;8202,03871
24,20000;2,02860;8216,44291
24,24000;2,03195;8229,88600
24,28000;2,03535;8245,06432
24,32000;2,03864;8259,42382
24,36000;2,04199;8272,53759
24,40000;2,04540;8286,99246
24,44000;2,04875;8302,40846
24,48000;2,05198;8315,75543
24,52000;2,05532;8329,45481
24,56000;2,05867;8343,95513
24,60000;2,06208;8358,46290
24,64000;2,06531;8372,58324
24,68000;2,06872;8386,38917
24,72000;2,07206;8401,44530
24,76000;2,07535;8414,83548
24,80000;2,07870;8428,72038
24,84000;2,08199;8443,40920
24,88000;2,08540;8458,39456
24,92000;2,08875;8472,24370
24,96000;2,09197;8485,27700
25,00000;2,09544;8499,82277
25,04000;2,09879;8514,40281
25,08000;2,10196;8527,37948
25,12000;2,10537;8540,39639
25,16000;2,10878;8555,60601
25,20000;2,11200;8569,00290
25,24000;2,11535;8582,49143
25,28000;2,11876;8597,46188
25,32000;2,12211;8611,35423
25,36000;2,12540;8624,16849
25,40000;2,12874;8637,54898
25,44000;2,13209;8652,21322
25,48000;2,13538;8665,07217
25,52000;2,13873;8677,77765
25,56000;2,14208;8690,86161
25,60000;2,14537;8704,55205
25,64000;2,14871;8717,99439
25,68000;2,15200;8731,17298
25,72000;2,15535;8745,34845
25,76000;2,15870;8758,92863
25,80000;2,16205;8772,15862
25,84000;2,16528;8786,01372
25,88000;2,16868;8799,92396
25,92000;2,17209;8814,05920
25,96000;2,17526;8826,88835
26,00000;2,17867;8840,08259
26,04000;2,18208;8854,68051
26,08000;2,18531;8868,33817
26,12000;2,18865;8879,07222
26,16000;2,19188;8892,32084
26,20000;2,19535;8907,40380
26,24000;2,19858;8919,25916
26,28000;2,20193;8931,50568
26,32000;2,20534;8945,66178
26,36000;2,20868;8957,91203
26,40000;2,21185;8970,43049
26,44000;2,21538;8984,30869
26,48000;2,21867;8998,27853
26,52000;2,22202;9010,55112
26,56000;2,22536;9024,65358
26,60000;2,22871;9037,91413
26,64000;2,23212;9052,25649
26,68000;2,23541;9064,24820
26,72000;2,23870;9076,43959
26,76000;2,24205;9088,10794
26,80000;2,24539;9100,01397
26,84000;2,24868;9112,81630
26,88000;2,25203;9126,78912
26,92000;2,25538;9138,54763
26,96000;2,25861;9152,12557
27,00000;2,26190;9162,74711
27,04000;2,26536;9177,03733
27,08000;2,26865;9189,80315
27,12000;2,27188;9201,72632
27,16000;2,27547;9216,73551
27,20000;2,27876;9230,56677
27,24000;2,28205;9241,53924
27,28000;2,28539;9252,73672
27,32000;2,28874;9264,77239
27,36000;2,29203;9276,15091
27,40000;2,29526;9288,59785
27,44000;2,29873;9302,34045
27,48000;2,30202;9315,52947
27,52000;2,30536;9326,65616
27,56000;2,30871;9338,66352
27,60000;2,31200;9351,32802
27,64000;2,31535;9363,30408
27,68000;2,31870;9375,15423
27,72000;2,32204;9387,96774
27,76000;2,32539;9401,59038
27,80000;2,32874;9412,87726
27,84000;2,33203;9425,06492
27,88000;2,33538;9435,97704
27,92000;2,33873;9447,58281
27,96000;2,34172;9460,15269
28,00000;2,34542;9472,95427
28,04000;2,34877;9486,29156
28,08000;2,35206;9497,87498
28,12000;2,35529;9508,44511
28,16000;2,35870;9520,03226
28,20000;2,36204;9531,77661
28,24000;2,36527;9542,65371
28,28000;2,36856;9554,90023
28,32000;2,37203;9568,40515
28,36000;2,37532;9581,61503
28,40000;2,37867;9592,97419
28,44000;2,38207;9606,22355
28,48000;2,38536;9619,42151
28,52000;2,38865;9631,82673
28,56000;2,39206;9645,35773
28,60000;2,39541;9660,23728
28,64000;2,39869;9672,83696
28,68000;2,40204;9683,86084
28,72000;2,40527;9695,92035
28,76000;2,40868;9708,20040
28,80000;2,41203;9719,63480
28,84000;2,41526;9730,96266
28,88000;2,41860;9742,62729
28,92000;2,42201;9755,17258
28,96000;2,42524;9766,68894
29,00000;2,42865;9778,10100
29,04000;2,43200;9790,63958
29,08000;2,43529;9802,98668
29,12000;2,43863;9813,43985
29,16000;2,44198;9825,92627
29,20000;2,44533;9838,99981
29,24000;2,44856;9849,47383
29,28000;2,45197;9861,31802
29,32000;2,45537;9873,63458
29,36000;2,45866;9885,94070
29,40000;2,46195;9896,41026
29,44000;2,46542;9908,70520
29,48000;2,46865;9919,96974
29,52000;2,47200;9931,02416
29,56000;2,47540;9943,80116
29,60000;2,47869;9955,91879
29,64000;2,48192;9967,11403
29,68000;2,48539;9978,72949
29,72000;2,48862;9992,21429
29,76000;2,49203;10003,39910
29,80000;2,49537;10014,27770
29,84000;2,49866;10025,75979
29,88000;2,50201;10037,70903
29,92000;2,50542;10049,54576
29,96000;2,50865;10062,58279
30,00000;2,51206;10074,02316
30,04000;2,51540;10085,87033
30,08000;2,51869;10096,82864
30,12000;2,52198;10106,61870
30,16000;2,52539;10118,08217
30,20000;2,52880;10130,12156
30,24000;2,53203;10143,45288
30,28000;2,53537;10154,35159
30,32000;2,53872;10165,57068
30,36000;2,54201;10176,73239
30,40000;2,54530;10187,16395
30,44000;2,54871;10198,91128
30,48000;2,55205;10211,48041
30,52000;2,55534;10221,90154
30,56000;2,55869;10234,92217
30,60000;2,56204;10246,11369
30,64000;2,56545;10257,91168
30,68000;2,56874;10268,98772
30,72000;2,57202;10280,76857
30,76000;2,57543;10291,79543
30,80000;2,57872;10302,13311
30,84000;2,58201;10313,77241
30,88000;2,58536;10324,89017
30,92000;2,58871;10336,27987
30,96000;2,59199;10346,73750
31,00000;2,59534;10357,84334
31,04000;2,59869;10368,93874
31,08000;2,60204;10380,27555
31,12000;2,60527;10390,64974
31,16000;2,60868;10403,06240
31,20000;2,61202;10415,79917
31,24000;2,61537;10425,97815
31,28000;2,61872;10437,72548
31,32000;2,62207;10449,01833
31,36000;2,62536;10459,58102
31,40000;2,62864;10470,15041
31,44000;2,63199;10480,57303
31,48000;2,63498;10491,49260
31,52000;2,63869;10504,54080
31,56000;2,64204;10517,08162
31,60000;2,64533;10526,91042
31,64000;2,64867;10538,19582
31,68000;2,65196;10548,31594
31,72000;2,65507;10559,03435
31,76000;2,65866;10571,79272
31,80000;2,66207;10583,21446
31,84000;2,66530;10593,90381
31,88000;2,66870;10603,17308
31,92000;2,67205;10615,34286
31,96000;2,67534;10625,83849
32,00000;2,67863;10637,12910
32,04000;2,68204;10649,41287
32,08000;2,68533;10660,45687
32,12000;2,68867;10670,30579
32,16000;2,69202;10681,06815
32,20000;2,69543;10693,00473
32,24000;2,69872;10705,29819
32,28000;2,70201;10714,62333
32,32000;2,70541;10726,38482
32,36000;2,70870;10735,23164
32,40000;2,71199;10745,66841
32,44000;2,71546;10756,70347
32,48000;2,71881;10768,29433
32,52000;2,72210;10778,17976
32,56000;2,72544;10788,52788
32,60000;2,72873;10800,76769
32,64000;2,73208;10811,01522
32,68000;2,73543;10821,27988
32,72000;2,73872;10831,49686
32,76000;2,74213;10842,79120
32,80000;2,74547;10854,17196
32,84000;2,74864;10864,51858
32,88000;2,75205;10874,38837
32,92000;2,75546;10886,27726
32,96000;2,75875;10896,21484
33,00000;2,76198;10904,43805
33,04000;2,76544;10915,17061
33,08000;2,76873;10926,59011
33,12000;2,77202;10936,14995
33,16000;2,77537;10945,66062
33,20000;2,77878;10957,85052
33,24000;2,78206;10967,90433
33,28000;2,78535;10977,41872
33,32000;2,78876;10987,84730
33,36000;2,79205;10998,33027
33,40000;2,79534;11007,95269
33,44000;2,79869;11017,73754
33,48000;2,80197;11027,88821
33,52000;2,80538;11038,33020
33,56000;2,80861;11048,19551
33,60000;2,81202;11059,29688
33,64000;2,81537;11071,38172
33,68000;2,81872;11080,18383
33,72000;2,82188;11089,68332
33,76000;2,82541;11100,76383
33,80000;2,82870;11113,50879
33,84000;2,83199;11123,65872
33,88000;2,83534;11131,92439
33,92000;2,83875;11142,46920
33,96000;2,84203;11152,56771
34,00000;2,84532;11159,91920
34,04000;2,84855;11169,88435
34,08000;2,85208;11183,19854
34,12000;2,85537;11192,69431
34,16000;2,85866;11201,12166
34,20000;2,86200;11211,74246
34,24000;2,86535;11221,41778
34,28000;2,86870;11230,48142
34,32000;2,87187;11240,12619
34,36000;2,87540;11252,52247
34,40000;2,87868;11262,42578
34,44000;2,88203;11272,23819
34,48000;2,88532;11281,79580
34,52000;2,88873;11290,35130
34,56000;2,89208;11300,56828
34,60000;2,89531;11310,16463
34,64000;2,89865;11319,66785
34,68000;2,90200;11330,03384
34,72000;2,90535;11341,45260
34,76000;2,90870;11350,60936
34,80000;2,91205;11359,26694
34,84000;2,91534;11368,80666
34,88000;2,91868;11377,12672
34,92000;2,92203;11386,93616
34,96000;2,92532;11396,96538
35,00000;2,92867;11405,56261
35,04000;2,93208;11416,26686
35,08000;2,93542;11428,20790
35,12000;2,93871;11436,77607
35,16000;2,94206;11444,87187
35,20000;2,94547;11454,82436
35,24000;2,94876;11464,44008
35,28000;2,95211;11473,68327
35,32000;2,95539;11482,58448
35,36000;2,95868;11491,64513
35,40000;2,96203;11500,31537
35,44000;2,96538;11510,58301
35,48000;2,96867;11519,79417
35,52000;2,97202;11529,04555
35,56000;2,97536;11538,43328
35,60000;2,97865;11548,21217
35,64000;2,98200;11556,19100
35,68000;2,98529;11566,15019
35,72000;2,98858;11575,01638
35,76000;2,99199;11585,15438
35,80000;2,99533;11595,23651
35,84000;2,99868;11604,43872
35,88000;3,00197;11613,41667
35,92000;3,00538;11622,51085
35,96000;3,00867;11631,91795
36,00000;3,01196;11640,32519
36,04000;3,01530;11649,01182
36,08000;3,01871;11658,70577
36,12000;3,02194;11667,75823
36,16000;3,02529;11676,73022
36,20000;3,02870;11686,34593
36,24000;3,03198;11696,20752
36,28000;3,03527;11704,97835
36,32000;3,03868;11713,94885
36,36000;3,04197;11724,01905
36,40000;3,04538;11733,16166
36,44000;3,04873;11742,15525
36,48000;3,05195;11750,85530
36,52000;3,05536;11760,31232
36,56000;3,05865;11769,31188
36,60000;3,06194;11777,28921
36,64000;3,06529;11786,38116
36,68000;3,06864;11795,84041
36,72000;3,07192;11803,87661
36,76000;3,07527;11812,52524
36,80000;3,07868;11821,77514
36,84000;3,08197;11831,32753
36,88000;3,08532;11840,18999
36,92000;3,08873;11849,93312
36,96000;3,09207;11859,31191
37,00000;3,09530;11866,98899
37,04000;3,09871;11875,24274
37,08000;3,10212;11885,11997
37,12000;3,10535;11893,51827
37,16000;3,10869;11901,99852
37,20000;3,11204;11910,72017
37,24000;3,11527;11919,38445
37,28000;3,11862;11927,04588
37,32000;3,12203;11936,21233
37,36000;3,12532;11945,27447
37,40000;3,12866;11953,62136
37,44000;3,13201;11962,60750
37,48000;3,13530;11971,23975
37,52000;3,13871;11979,07254
37,56000;3,14200;11987,35088
37,60000;3,14529;11995,74918
37,64000;3,14869;12003,75706
37,68000;3,15198;12013,07252
37,72000;3,15533;12021,46113
37,76000;3,15868;12030,07698
37,80000;3,16203;12038,81651
37,84000;3,16538;12047,33849
37,88000;3,16866;12055,85673
37,92000;3,17201;12064,49643
37,96000;3,17542;12073,49971
38,00000;3,17865;12080,79085
38,04000;3,18206;12089,81425
38,08000;3,18546;12100,03868
38,12000;3,18869;12107,69638
38,16000;3,19210;12116,01645
38,20000;3,19545;12125,49508
38,24000;3,19868;12133,74212
38,28000;3,20203;12140,19731
38,32000;3,20537;12149,13800
38,36000;3,20866;12158,99438
38,40000;3,21201;12166,66698
38,44000;3,21542;12175,59651
38,48000;3,21871;12184,24141
38,52000;3,22206;12191,90285
38,56000;3,22534;12198,74173
38,60000;3,22869;12207,09160
38,64000;3,23204;12215,94214
38,68000;3,23539;12223,18485
38,72000;3,23874;12231,63530
38,76000;3,24209;12239,90694
38,80000;3,24543;12248,51012
38,84000;3,24872;12256,63051
38,88000;3,25195;12263,67205
38,92000;3,25536;12271,36701
38,96000;3,25871;12281,56835
39,00000;3,26200;12288,91909
39,04000;3,26534;12296,55743
39,08000;3,26875;12305,82818
39,12000;3,27198;12313,36594
39,16000;3,27533;12320,10201
39,20000;3,27874;12329,38468
39,24000;3,28202;12338,13837
39,28000;3,28537;12345,33340
39,32000;3,28872;12352,78994
39,36000;3,29201;12362,31476
39,40000;3,29536;12368,99570
39,44000;3,29865;12376,38518
39,48000;3,30193;12383,84098
39,52000;3,30534;12392,44789
39,56000;3,30863;12400,62639
39,60000;3,31198;12407,69997
39,64000;3,31539;12415,67060
39,68000;3,31874;12424,98904
39,72000;3,32202;12430,92790
39,76000;3,32537;12438,21755
39,80000;3,32872;12446,75815
39,84000;3,33207;12454,69302
39,88000;3,33536;12462,06239
39,92000;3,33870;12469,99949
39,96000;3,34211;12478,16905
40,00000;3,34534;12485,26871
40,04000;3,34869;12491,97721
40,08000;3,35210;12500,58115
40,12000;3,35533;12508,51005
40,16000;3,35867;12515,46741
40,20000;3,36208;12522,54993
40,24000;3,36531;12530,50268
40,28000;3,36866;12537,34678
40,32000;3,37201;12544,64537
40,36000;3,37536;12553,25675
40,40000;3,37870;12559,73279
40,44000;3,38193;12566,41299
40,48000;3,38540;12575,68151
40,52000;3,38875;12582,18288
40,56000;3,39204;12588,79751
40,60000;3,39533;12595,66844
40,64000;3,39873;12603,97285
40,68000;3,40202;12611,01067
40,72000;3,40537;12617,71768
40,76000;3,40866;12623,71242
40,80000;3,41207;12632,69335
40,84000;3,41541;12640,72657
40,88000;3,41852;12647,10128
40,92000;3,42211;12655,68584
40,96000;3,42546;12664,04241
41,00000;3,42875;12670,00586
41,04000;3,43210;12676,46402
41,08000;3,43544;12684,61049
41,12000;3,43873;12692,34121
41,16000;3,44196;12698,59225
41,20000;3,44549;12707,10230
41,24000;3,44872;12716,56752
41,28000;3,45207;12722,43112
41,32000;3,45535;12729,14261
41,36000;3,45870;12736,63640
41,40000;3,46205;12744,63832
41,44000;3,46534;12752,17384
41,48000;3,46875;12761,09070
41,52000;3,47210;12769,67973
41,56000;3,47544;12776,97533
41,60000;3,47873;12784,06829
41,64000;3,48202;12790,07196
41,68000;3,48543;12797,24538
41,72000;3,48872;12804,12823
41,76000;3,49183;12809,46285
41,80000;3,49541;12818,21132
41,84000;3,49876;12826,99704
41,88000;3,50193;12833,31364
41,92000;3,50534;12840,23374
41,96000;3,50875;12848,39809
42,00000;3,51197;12855,55214
42,04000;3,51532;12862,78218
42,08000;3,51879;12871,48595
42,12000;3,52202;12880,38939
42,16000;3,52537;12886,84458
42,20000;3,52872;12893,16416
42,24000;3,53200;12901,11095
42,28000;3,53535;12907,57805
42,32000;3,53846;12915,60531
42,36000;3,54205;12925,33726
42,40000;3,54540;12933,92926
42,44000;3,54869;12940,45597
42,48000;3,55203;12947,88867
42,52000;3,55532;12954,30064
42,56000;3,55867;12962,57228
42,60000;3,56196;12969,88428
42,64000;3,56531;12977,73421
42,68000;3,56872;12986,24575
42,72000;3,57206;12994,31622
42,76000;3,57529;13001,06049
42,80000;3,57870;13008,61239
42,84000;3,58205;13015,35070
42,88000;3,58522;13022,07708
42,92000;3,58869;13030,96712
42,96000;3,59209;13039,90334
43,00000;3,59532;13045,65817
43,04000;3,59861;13052,06120
43,08000;3,60202;13060,23449
43,12000;3,60531;13067,75808
43,16000;3,60859;13074,12833
43,20000;3,61194;13081,09909
43,24000;3,61535;13090,53004
43,28000;3,61870;13095,91979
43,32000;3,62205;13103,59836
43,36000;3,62540;13111,58389
43,40000;3,62868;13118,79009
43,44000;3,63203;13125,13947
43,48000;3,63532;13131,49035
43,52000;3,63867;13138,49837
43,56000;3,64202;13147,23492
43,60000;3,64531;13153,16856
43,64000;3,64865;13160,31665
43,68000;3,65206;13167,80597
43,72000;3,65541;13175,08668
43,76000;3,65864;13180,81319
43,80000;3,66205;13187,22069
43,84000;3,66539;13194,86350
43,88000;3,66862;13201,53922
43,92000;3,67203;13207,91394
43,96000;3,67544;13216,03656
44,00000;3,67861;13222,48280
44,04000;3,68202;13228,20336
44,08000;3,68536;13236,24402
44,12000;3,68871;13243,56645
44,16000;3,69200;13250,24962
44,20000;3,69535;13256,51407
44,24000;3,69870;13263,64577
44,28000;3,70187;13269,08767
44,32000;3,70539;13277,53365
44,36000;3,70868;13285,46107
44,40000;3,71209;13290,31140
44,44000;3,71538;13296,20779
44,48000;3,71873;13302,65105
44,52000;3,72202;13308,44760
44,56000;3,72536;13314,98325
44,60000;3,72871;13322,04193
44,64000;3,73200;13327,27075
44,68000;3,73535;13334,52314
44,72000;3,73864;13340,56258
44,76000;3,74193;13345,75117
44,80000;3,74527;13352,26744
44,84000;3,74862;13358,95956
44,88000;3,75191;13364,63839
44,92000;3,75532;13371,27388
44,96000;3,75873;13378,71999
45,00000;3,76196;13384,27961
45,04000;3,76536;13389,93460
45,08000;3,76871;13397,54313
45,12000;3,77200;13403,19365
45,16000;3,77517;13407,50754
45,20000;3,77870;13413,64384
45,24000;3,78198;13420,93498
45,28000;3,78539;13425,73613
45,32000;3,78862;13431,42390
45,36000;3,79203;13437,02227
45,40000;3,79538;13443,67415
45,44000;3,79867;13449,74935
45,48000;3,80201;13454,43428
45,52000;3,80536;13460,66445
45,56000;3,80877;13467,85575
45,60000;3,81218;13474,74456
45,64000;3,81547;13481,99248
45,68000;3,81881;13487,31369
45,72000;3,82216;13492,66320
45,76000;3,82539;13497,29002
45,80000;3,82868;13501,95110
45,84000;3,83203;13508,79520
45,88000;3,83538;13514,41592
45,92000;3,83872;13523,00942
45,96000;3,84213;13529,31857
46,00000;3,84542;13535,21645
46,04000;3,84865;13539,39474
46,08000;3,85206;13545,62044
46,12000;3,85541;13552,12927
46,16000;3,85857;13557,28209
46,20000;3,86216;13563,30067
46,24000;3,86545;13570,94198
46,28000;3,86880;13576,47628
46,32000;3,87209;13581,33256
46,36000;3,87544;13587,27962
46,40000;3,87872;13593,78248
46,44000;3,88213;13598,50019
46,48000;3,88530;13603,46973
46,52000;3,88877;13610,64911
46,56000;3,89212;13616,76604
46,60000;3,89541;13621,53292
46,64000;3,89863;13625,96154
46,68000;3,90204;13632,05314
46,72000;3,90545;13638,71694
46,76000;3,90868;13643,79674
46,80000;3,91191;13648,38034
46,84000;3,91549;13655,47925
46,88000;3,91872;13660,84367
46,92000;3,92201;13664,63453
46,96000;3,92542;13670,47727
47,00000;3,92871;13676,09054
47,04000;3,93200;13679,71897
47,08000;3,93534;13684,98057
47,12000;3,93863;13692,36410
47,16000;3,94198;13696,31588
47,20000;3,94527;13700,32579
47,24000;3,94862;13705,52480
47,28000;3,95203;13711,38841
47,32000;3,95537;13716,04502
47,36000;3,95866;13720,50345
47,40000;3,96201;13724,65342
47,44000;3,96530;13729,64829
47,48000;3,96859;13734,09480
47,52000;3,97194;13738,22242
47,56000;3,97534;13744,50177
47,60000;3,97875;13749,51303
47,64000;3,98198;13753,98487
47,68000;3,98539;13759,68903
47,72000;3,98874;13764,46486
47,76000;3,99196;13767,82656
47,80000;3,99531;13770,40893
47,84000;3,99878;13775,39039
47,88000;4,00201;13779,58506
47,92000;4,00536;13781,90517
47,96000;4,00877;13787,44543
48,00000;4,01199;13790,21853
48,04000;4,01540;13791,75335
48,08000;4,01839;13792,90074
48,12000;4,02204;13796,99409
48,16000;4,02539;13798,91783
48,20000;4,02874;13799,09813
48,24000;4,03208;13798,35457
48,28000;4,03543;13796,30119
48,32000;4,03878;13791,34357
48,36000;4,04207;13785,68411
48,40000;4,04524;13775,43062
48,44000;4,04876;13763,99249
48,48000;4,05211;13741,00149
48,52000;4,05534;13697,18611
48,56000;4,05875;13606,46039
48,60000;4,06341;6240,52025
48,61400;4,06527;2480,33162