File: SU - Suspension/05 - Essais/Excels essais Optimus/collage alu carbone 05_02_19/collage5.is_tens_RawData/Specimen_RawData_1.csv
Temps;Déplacement;Charge
(sec);(mm);(N)
0,00000;0,06912;22,57089
0,04000;0,06942;21,62834
0,08000;0,07067;22,48912
0,12000;0,07348;27,90793
0,16000;0,07689;36,41793
0,20000;0,08048;43,78694
0,24000;0,08418;49,58399
0,28000;0,08789;55,73222
0,32000;0,09154;60,29592
0,36000;0,09513;65,65641
0,40000;0,09871;71,24247
0,44000;0,10212;78,10474
0,48000;0,10559;83,64232
0,52000;0,10900;89,27869
0,56000;0,11234;96,90063
0,60000;0,11575;103,83513
0,64000;0,11916;109,26437
0,68000;0,12251;117,63958
0,72000;0,12580;124,54547
0,76000;0,12915;132,46184
0,80000;0,13255;142,00557
0,84000;0,13584;149,57591
0,88000;0,13919;158,31793
0,92000;0,14260;168,75684
0,96000;0,14583;180,15762
1,00000;0,14917;192,82148
1,04000;0,15252;207,07226
1,08000;0,15581;218,41081
1,12000;0,15916;231,85872
1,16000;0,16251;244,48736
1,20000;0,16580;258,95215
1,24000;0,16920;272,39402
1,28000;0,17249;285,23318
1,32000;0,17578;296,94748
1,36000;0,17919;309,08182
1,40000;0,18254;320,16963
1,44000;0,18583;332,35499
1,48000;0,18917;345,45478
1,52000;0,19258;358,67020
1,56000;0,19587;369,85730
1,60000;0,19916;381,11745
1,64000;0,20251;394,36086
1,68000;0,20586;409,27473
1,72000;0,20914;424,57990
1,76000;0,21249;438,56362
1,80000;0,21584;452,88745
1,84000;0,21907;466,45431
1,88000;0,22248;480,64780
1,92000;0,22582;494,65541
1,96000;0,22911;509,69692
2,00000;0,23246;523,87477
2,04000;0,23587;538,62617
2,08000;0,23916;553,31481
2,12000;0,24251;567,13168
2,16000;0,24585;581,55558
2,20000;0,24914;596,25204
2,24000;0,25249;610,85671
2,28000;0,25578;623,60242
2,32000;0,25907;639,15360
2,36000;0,26242;654,69649
2,40000;0,26576;669,18391
2,44000;0,26911;683,61075
2,48000;0,27246;699,55452
2,52000;0,27581;715,30393
2,56000;0,27910;730,94335
2,60000;0,28245;746,28661
2,64000;0,28585;761,81744
2,68000;0,28920;777,47763
2,72000;0,29249;791,75485
2,76000;0,29590;805,12054
2,80000;0,29925;819,78105
2,84000;0,30248;832,34198
2,88000;0,30582;846,01585
2,92000;0,30917;859,58717
2,96000;0,31246;872,41502
3,00000;0,31575;885,23692
3,04000;0,31916;897,13708
3,08000;0,32250;909,75920
3,12000;0,32579;920,90080
3,16000;0,32914;933,23318
3,20000;0,33243;946,10779
3,24000;0,33584;959,47357
3,28000;0,33913;972,45332
3,32000;0,34247;986,15605
3,36000;0,34588;999,93842
3,40000;0,34923;1013,44604
3,44000;0,35252;1026,74561
3,48000;0,35581;1041,55233
3,52000;0,35922;1056,08804
3,56000;0,36250;1069,14714
3,60000;0,36579;1082,98380
3,64000;0,36920;1097,21627
3,68000;0,37255;1110,70815
3,72000;0,37578;1124,75129
3,76000;0,37913;1138,41193
3,80000;0,38253;1152,87593
3,84000;0,38588;1167,15319
3,88000;0,38917;1179,71720
3,92000;0,39252;1192,47846
3,96000;0,39587;1206,20653
4,00000;0,39921;1219,42433
4,04000;0,40250;1231,52882
4,08000;0,40579;1244,13557
4,12000;0,40920;1257,64934
4,16000;0,41249;1270,13559
4,20000;0,41584;1283,06523
4,24000;0,41918;1295,54756
4,28000;0,42253;1308,68051
4,32000;0,42576;1320,54482
4,36000;0,42917;1333,17700
4,40000;0,43252;1346,93570
4,44000;0,43587;1359,00304
4,48000;0,43915;1370,58273
4,52000;0,44256;1382,50999
4,56000;0,44585;1395,28112
4,60000;0,44914;1406,70547
4,64000;0,45249;1419,40368
4,68000;0,45589;1431,95856
4,72000;0,45918;1444,27978
4,76000;0,46253;1455,84904
4,80000;0,46594;1468,59130
4,84000;0,46923;1480,15805
4,88000;0,47252;1492,02822
4,92000;0,47592;1503,36223
4,96000;0,47921;1515,70905
5,00000;0,48256;1526,90541
5,04000;0,48579;1538,38359
5,08000;0,48920;1549,94037
5,12000;0,49249;1560,76690
5,16000;0,49571;1572,17961
5,20000;0,49918;1584,88899
5,24000;0,50253;1595,55171
5,28000;0,50588;1605,82438
5,32000;0,50911;1616,21906
5,36000;0,51258;1627,34948
5,40000;0,51586;1638,76377
5,44000;0,51921;1648,14722
5,48000;0,52244;1658,29882
5,52000;0,52597;1669,61737
5,56000;0,52926;1679,29418
5,60000;0,53254;1687,99553
5,64000;0,53583;1697,03644
5,68000;0,53918;1706,37108
5,72000;0,54247;1715,75751
5,76000;0,54558;1723,48395
5,80000;0,54929;1733,93823
5,84000;0,55245;1743,46156
5,88000;0,55580;1750,61636
5,92000;0,55909;1758,66615
5,96000;0,56244;1767,79423
6,00000;0,56579;1775,81292
6,04000;0,56914;1783,92585
6,08000;0,57248;1791,55599
6,12000;0,57589;1800,93199
6,16000;0,57924;1807,74126
6,20000;0,58247;1814,23202
6,24000;0,58582;1820,33349
6,28000;0,58911;1826,56348
6,32000;0,59239;1832,13037
6,36000;0,59574;1839,67911
6,40000;0,59915;1847,97794
6,44000;0,60250;1853,66198
6,48000;0,60573;1859,65076
6,52000;0,60908;1865,91521
6,56000;0,61248;1872,64960
6,60000;0,61571;1878,67433
6,64000;0,61906;1883,25047
6,68000;0,62259;1890,64983
6,72000;0,62582;1897,58874
6,76000;0,62916;1902,39046
6,80000;0,63251;1908,15311
6,84000;0,63580;1914,07688
6,88000;0,63915;1919,35915
6,92000;0,64220;1925,29820
6,96000;0,64585;1933,10529
7,00000;0,64919;1939,37086
7,04000;0,65248;1943,24255
7,08000;0,65577;1950,43832
7,12000;0,65912;1958,11447
7,16000;0,66241;1967,33698
7,20000;0,66576;1977,20435
7,24000;0,66916;1987,03893
7,28000;0,67251;1997,50103
7,32000;0,67574;2008,13841
7,36000;0,67921;2019,41598
7,40000;0,68250;2029,48246
7,44000;0,68585;2038,00201
7,48000;0,68913;2046,45321
7,52000;0,69254;2054,61644
7,56000;0,69589;2062,67145
7,60000;0,69906;2069,27434
7,64000;0,70253;2076,66866
7,68000;0,70581;2084,32116
7,72000;0,70910;2089,88674
7,76000;0,71245;2096,58183
7,80000;0,71592;2104,13877
7,84000;0,71915;2109,99884
7,88000;0,72250;2115,03077
7,92000;0,72584;2120,90723
7,96000;0,72919;2127,11580
8,00000;0,73254;2131,73702
8,04000;0,73583;2137,10461
8,08000;0,73918;2142,01305
8,12000;0,74253;2146,76112
8,16000;0,74581;2152,77988
8,20000;0,74910;2159,12666
8,24000;0,75245;2166,85049
8,28000;0,75580;2175,51291
8,32000;0,75915;2184,22785
8,36000;0,76244;2194,00395
8,40000;0,76584;2203,99648
8,44000;0,76919;2214,29933
8,48000;0,77242;2224,46453
8,52000;0,77577;2236,16716
8,56000;0,77918;2247,37283
8,60000;0,78241;2257,90348
8,64000;0,78581;2269,43083
8,68000;0,78922;2283,12034
8,72000;0,79245;2295,69804
8,76000;0,79580;2308,36961
8,80000;0,79915;2321,34052
8,84000;0,80243;2334,40567
8,88000;0,80572;2346,90290
8,92000;0,80907;2361,85417
8,96000;0,81242;2374,82600
9,00000;0,81577;2387,89897
9,04000;0,81912;2399,97730
9,08000;0,82240;2411,67825
9,12000;0,82575;2424,11271
9,16000;0,82904;2436,17296
9,20000;0,83245;2448,37571
9,24000;0,83574;2460,18078
9,28000;0,83915;2472,36528
9,32000;0,84249;2483,59088
9,36000;0,84578;2494,80717
9,40000;0,84913;2505,54569
9,44000;0,85248;2516,48724
9,48000;0,85577;2529,42257
9,52000;0,85912;2541,43346
9,56000;0,86252;2552,38134
9,60000;0,86575;2564,35573
9,64000;0,86916;2575,25556
9,68000;0,87251;2587,48475
9,72000;0,87574;2598,65578
9,76000;0,87914;2610,10807
9,80000;0,88249;2622,26555
9,84000;0,88578;2633,64967
9,88000;0,88913;2643,45910
9,92000;0,89248;2654,75065
9,96000;0,89589;2666,74068
10,00000;0,89923;2676,26774
10,04000;0,90252;2685,81137
10,08000;0,90593;2697,48997
10,12000;0,90922;2707,86006
10,16000;0,91257;2717,06600
10,20000;0,91592;2726,96931
10,24000;0,91920;2735,92453
10,28000;0,92261;2745,55199
10,32000;0,92584;2754,56011
10,36000;0,92913;2762,88763
10,40000;0,93248;2771,29691
10,44000;0,93588;2780,97037
10,48000;0,93917;2791,85660
10,52000;0,94252;2800,77960
10,56000;0,94593;2809,82945
10,60000;0,94910;2817,55775
10,64000;0,95257;2826,07526
10,68000;0,95591;2837,00358
10,72000;0,95920;2845,46800
10,76000;0,96249;2854,55342
10,80000;0,96578;2865,17590
10,84000;0,96919;2879,24800
10,88000;0,97248;2890,83421
10,92000;0,97576;2903,19454
10,96000;0,97911;2917,95861
11,00000;0,98246;2932,06275
11,04000;0,98581;2944,64864
11,08000;0,98898;2957,87919
11,12000;0,99251;2973,23652
11,16000;0,99579;2987,37306
11,20000;0,99914;3000,24468
11,24000;1,00243;3013,94258
11,28000;1,00590;3027,39497
11,32000;1,00925;3042,08975
11,36000;1,01248;3055,15341
11,40000;1,01588;3069,33168
11,44000;1,01923;3083,33430
11,48000;1,02240;3095,88928
11,52000;1,02581;3109,71923
11,56000;1,02922;3124,59860
11,60000;1,03244;3137,74794
11,64000;1,03579;3150,91424
11,68000;1,03914;3164,40687
11,72000;1,04249;3179,08488
11,76000;1,04584;3192,61625
11,80000;1,04907;3205,88350
11,84000;1,05253;3220,85433
11,88000;1,05588;3234,70943
11,92000;1,05917;3246,73355
11,96000;1,06252;3261,24616
12,00000;1,06587;3274,89860
12,04000;1,06916;3287,70615
12,08000;1,07244;3300,93950
12,12000;1,07585;3313,71315
12,16000;1,07920;3327,07725
12,20000;1,08243;3339,42473
12,24000;1,08578;3352,92034
12,28000;1,08913;3365,86572
12,32000;1,09247;3379,29092
12,36000;1,09576;3391,59183
12,40000;1,09917;3404,43328
12,44000;1,10258;3419,19400
12,48000;1,10581;3432,62367
12,52000;1,10921;3446,40985
12,56000;1,11256;3462,14063
12,60000;1,11585;3475,13109
12,64000;1,11920;3487,73710
12,68000;1,12237;3500,42470
12,72000;1,12596;3516,76680
12,76000;1,12924;3530,46060
12,80000;1,13253;3542,37445
12,84000;1,13582;3556,11295
12,88000;1,13917;3569,51691
12,92000;1,14252;3582,45075
12,96000;1,14581;3595,77537
13,00000;1,14903;3609,77761
13,04000;1,15256;3625,65704
13,08000;1,15585;3639,88914
13,12000;1,15914;3652,25673
13,16000;1,16249;3666,22321
13,20000;1,16584;3679,62979
13,24000;1,16912;3693,05089
13,28000;1,17253;3706,70706
13,32000;1,17588;3723,23208
13,36000;1,17911;3735,60749
13,40000;1,18246;3748,12186
13,44000;1,18580;3762,27163
13,48000;1,18909;3775,73669
13,52000;1,19244;3789,01549
13,56000;1,19585;3803,50985
13,60000;1,19908;3819,43360
13,64000;1,20243;3831,98150
13,68000;1,20571;3845,18541
13,72000;1,20906;3860,07279
13,76000;1,21235;3872,04550
13,80000;1,21576;3885,40141
13,84000;1,21911;3899,44203
13,88000;1,22252;3914,17481
13,92000;1,22580;3927,76020
13,96000;1,22909;3940,70558
14,00000;1,23244;3953,81153
14,04000;1,23579;3967,47366
14,08000;1,23914;3981,30342
14,12000;1,24243;3993,77197
14,16000;1,24577;4008,65376
14,20000;1,24912;4022,60646
14,24000;1,25241;4036,37215
14,28000;1,25576;4049,19237
14,32000;1,25911;4063,09366
14,36000;1,26240;4075,97125
14,40000;1,26574;4089,84162
14,44000;1,26921;4105,24271
14,48000;1,27244;4117,93403
14,52000;1,27579;4129,88737
14,56000;1,27914;4143,66163
14,60000;1,28242;4157,87548
14,64000;1,28577;4170,16596
14,68000;1,28918;4184,91215
14,72000;1,29247;4199,53279
14,76000;1,29582;4212,00581
14,80000;1,29911;4225,69029
14,84000;1,30245;4240,39289
14,88000;1,30580;4253,02349
14,92000;1,30909;4267,04623
14,96000;1,31244;4281,54767
15,00000;1,31579;4296,62094
15,04000;1,31914;4310,65075
15,08000;1,32248;4324,47270
15,12000;1,32577;4340,05335
15,16000;1,32918;4353,61862
15,20000;1,33253;4367,58250
15,24000;1,33582;4382,07835
15,28000;1,33922;4396,44866
15,32000;1,34257;4410,28252
15,36000;1,34574;4424,50829
15,40000;1,34915;4437,84669
15,44000;1,35250;4452,48336
15,48000;1,35573;4466,97809
15,52000;1,35913;4481,20460
15,56000;1,36254;4496,31251
15,60000;1,36583;4510,36654
15,64000;1,36912;4523,05451
15,68000;1,37247;4536,34597
15,72000;1,37576;4550,98450
15,76000;1,37904;4564,28491
15,80000;1,38245;4578,22531
15,84000;1,38586;4592,94952
15,88000;1,38921;4607,17231
15,92000;1,39250;4620,02009
15,96000;1,39585;4632,44691
16,00000;1,39919;4646,47152
16,04000;1,40248;4660,58031
16,08000;1,40583;4674,79751
16,12000;1,40912;4689,39580
16,16000;1,41247;4702,88508
16,20000;1,41582;4715,75484
16,24000;1,41904;4729,72579
16,28000;1,42245;4744,47533
16,32000;1,42574;4758,46753
16,36000;1,42903;4772,03429
16,40000;1,43244;4786,34834
16,44000;1,43590;4801,17090
16,48000;1,43913;4815,02041
16,52000;1,44248;4827,89688
16,56000;1,44589;4842,88000
16,60000;1,44918;4857,30246
16,64000;1,45247;4869,53296
16,68000;1,45581;4883,79374
16,72000;1,45910;4898,43898
16,76000;1,46245;4911,60490
16,80000;1,46580;4924,89822
16,84000;1,46915;4937,42116
16,88000;1,47244;4950,89963
16,92000;1,47578;4964,19854
16,96000;1,47913;4976,39626
17,00000;1,48242;4989,88591
17,04000;1,48583;5004,01556
17,08000;1,48918;5017,27723
17,12000;1,49247;5030,00133
17,16000;1,49587;5042,91393
17,20000;1,49916;5056,50230
17,24000;1,50239;5069,88429
17,28000;1,50580;5083,65929
17,32000;1,50915;5098,68525
17,36000;1,51243;5111,19813
17,40000;1,51584;5124,68107
17,44000;1,51919;5138,20164
17,48000;1,52242;5151,12393
17,52000;1,52577;5163,64276
17,56000;1,52912;5177,20990
17,60000;1,53246;5191,13466
17,64000;1,53581;5204,49802
17,68000;1,53922;5218,08267
17,72000;1,54257;5232,28161
17,76000;1,54580;5244,22787
17,80000;1,54915;5256,79290
17,84000;1,55249;5271,32414
17,88000;1,55584;5285,60616
17,92000;1,55907;5298,37571
17,96000;1,56254;5311,85791
18,00000;1,56583;5325,85420
18,04000;1,56918;5338,80889
18,08000;1,57246;5351,42422
18,12000;1,57575;5365,96514
18,16000;1,57916;5379,68911
18,20000;1,58257;5392,96530
18,24000;1,58574;5406,69598
18,28000;1,58920;5419,92635
18,32000;1,59255;5435,17582
18,36000;1,59578;5446,63258
18,40000;1,59913;5460,35916
18,44000;1,60254;5474,89598
18,48000;1,60583;5488,44226
18,52000;1,60917;5501,35709
18,56000;1,61252;5516,32680
18,60000;1,61587;5530,23107
18,64000;1,61916;5543,09599
18,68000;1,62251;5555,94452
18,72000;1,62586;5571,25881
18,76000;1,62920;5584,16247
18,80000;1,63255;5596,08079
18,84000;1,63584;5609,28620
18,88000;1,63919;5623,05860
18,92000;1,64254;5636,18466
18,96000;1,64583;5649,40311
19,00000;1,64911;5663,98613
19,04000;1,65252;5678,18135
19,08000;1,65587;5691,58047
19,12000;1,65910;5705,39609
19,16000;1,66251;5719,18227
19,20000;1,66585;5733,36519
19,24000;1,66908;5746,56166
19,28000;1,67249;5759,69070
19,32000;1,67590;5774,29347
19,36000;1,67913;5788,01110
19,40000;1,68242;5799,88509
19,44000;1,68576;5813,41796
19,48000;1,68911;5827,55953
19,52000;1,69240;5839,43762
19,56000;1,69575;5853,17984
19,60000;1,69916;5869,72572
19,64000;1,70245;5881,74537
19,68000;1,70573;5893,92819
19,72000;1,70902;5907,69947
19,76000;1,71249;5922,19718
19,80000;1,71578;5935,47821
19,84000;1,71913;5948,86355
19,88000;1,72254;5963,64439
19,92000;1,72588;5979,14793
19,96000;1,72923;5991,13964
20,00000;1,73246;6003,82835
20,04000;1,73581;6016,82886
20,08000;1,73916;6029,30076
20,12000;1,74245;6042,91968
20,16000;1,74579;6057,40659
20,20000;1,74914;6071,16930
20,24000;1,75243;6084,17206
20,28000;1,75578;6096,97662
20,32000;1,75913;6111,81371
20,36000;1,76241;6125,39090
20,40000;1,76582;6138,76618
20,44000;1,76923;6154,81362
20,48000;1,77252;6168,94625
20,52000;1,77587;6182,11366
20,56000;1,77922;6194,95213
20,60000;1,78250;6207,41844
20,64000;1,78579;6219,72792
20,68000;1,78908;6233,41016
20,72000;1,79249;6248,51435
20,76000;1,79584;6263,51312
20,80000;1,79919;6276,59485
20,84000;1,80247;6290,20706
20,88000;1,80576;6303,84013
20,92000;1,80911;6317,18040
20,96000;1,81252;6331,14204
21,00000;1,81587;6345,00682
21,04000;1,81921;6360,20899
21,08000;1,82256;6373,95605
21,12000;1,82579;6386,06474
21,16000;1,82914;6398,32169
21,20000;1,83249;6412,50014
21,24000;1,83578;6425,11994
21,28000;1,83912;6438,26872
21,32000;1,84259;6455,38419
21,36000;1,84582;6468,23347
21,40000;1,84911;6480,65135
21,44000;1,85246;6493,00367
21,48000;1,85581;6506,79022
21,52000;1,85909;6519,53816
21,56000;1,86244;6532,91494
21,60000;1,86591;6548,19012
21,64000;1,86914;6563,47796
21,68000;1,87249;6575,98078
21,72000;1,87584;6589,03271
21,76000;1,87912;6602,62629
21,80000;1,88247;6615,59179
21,84000;1,88582;6628,92461
21,88000;1,88917;6643,30721
21,92000;1,89252;6657,17125
21,96000;1,89581;6670,61880
22,00000;1,89903;6682,49428
22,04000;1,90250;6696,05881
22,08000;1,90579;6709,43707
22,12000;1,90902;6721,71339
22,16000;1,91243;6735,46195
22,20000;1,91577;6748,38945
22,24000;1,91900;6760,98689
22,28000;1,92241;6774,60805
22,32000;1,92582;6788,48848
22,36000;1,92911;6801,02780
22,40000;1,93240;6813,27805
22,44000;1,93574;6827,20542
22,48000;1,93915;6841,39505
22,52000;1,94238;6852,89651
22,56000;1,94579;6866,80228
22,60000;1,94920;6881,07535
22,64000;1,95243;6893,28089
22,68000;1,95577;6905,83214
22,72000;1,95918;6919,70959
22,76000;1,96247;6932,84944
22,80000;1,96576;6945,66518
22,84000;1,96917;6959,67227
22,88000;1,97246;6972,91642
22,92000;1,97580;6985,89608
22,96000;1,97915;6998,89138
23,00000;1,98238;7012,76362
23,04000;1,98579;7025,16213
23,08000;1,98914;7037,68507
23,12000;1,99242;7051,72271
23,16000;1,99583;7064,06981
23,20000;1,99918;7076,88034
23,24000;2,00235;7089,48299
23,28000;2,00588;7102,79942
23,32000;2,00923;7117,95464
23,36000;2,01251;7130,52452
23,40000;2,01580;7142,20852
23,44000;2,01915;7155,06226
23,48000;2,02256;7168,93151
23,52000;2,02585;7182,08700
23,56000;2,02914;7195,83407
23,60000;2,03254;7208,71016
23,64000;2,03583;7220,94700
23,68000;2,03912;7233,04003
23,72000;2,04253;7245,78947
23,76000;2,04582;7258,72815
23,80000;2,04911;7271,12666
23,84000;2,05251;7284,96462
23,88000;2,05586;7299,29283
23,92000;2,05921;7311,50582
23,96000;2,06256;7323,10042
24,00000;2,06585;7337,20362
24,04000;2,06919;7350,06779
24,08000;2,07248;7362,57583
24,12000;2,07583;7375,15688
24,16000;2,07918;7388,44797
24,20000;2,08253;7402,31052
24,24000;2,08582;7413,88574
24,28000;2,08910;7426,28425
24,32000;2,09251;7439,34065
24,36000;2,09586;7452,00440
24,40000;2,09909;7463,70777
24,44000;2,10250;7477,66048
24,48000;2,10585;7491,53420
24,52000;2,10913;7503,44470
24,56000;2,11248;7516,02650
24,60000;2,11589;7529,44127
24,64000;2,11912;7541,85542
24,68000;2,12247;7554,33142
24,72000;2,12576;7566,11899
24,76000;2,12886;7578,69408
24,80000;2,13245;7592,22060
24,84000;2,13580;7606,57042
24,88000;2,13909;7619,14402
24,92000;2,14244;7630,44357
24,96000;2,14573;7643,48954
25,00000;2,14901;7655,86346
25,04000;2,15242;7668,00344
25,08000;2,15583;7681,15595
25,12000;2,15912;7693,37416
25,16000;2,16253;7708,19262
25,20000;2,16587;7719,86097
25,24000;2,16916;7732,18796
25,28000;2,17245;7744,03587
25,32000;2,17580;7757,37762
25,36000;2,17915;7769,66363
25,40000;2,18244;7781,60989
25,44000;2,18584;7795,34355
25,48000;2,18925;7810,11358
25,52000;2,19248;7822,05388
25,56000;2,19577;7833,25434
25,60000;2,19918;7845,77206
25,64000;2,20247;7857,41881
25,68000;2,20575;7869,57368
25,72000;2,20928;7882,86328
25,76000;2,21257;7896,26539
25,80000;2,21586;7908,70264
25,84000;2,21915;7919,83232
25,88000;2,22255;7933,79322
25,92000;2,22584;7946,91741
25,96000;2,22919;7957,85338
26,00000;2,23248;7970,28989
26,04000;2,23589;7983,90135
26,08000;2,23924;7996,91677
26,12000;2,24246;8008,83099
26,16000;2,24587;8020,74224
26,20000;2,24928;8033,67794
26,24000;2,25251;8046,41694
26,28000;2,25580;8056,81869
26,32000;2,25921;8068,68449
26,36000;2,26255;8081,08523
26,40000;2,26584;8092,48835
26,44000;2,26913;8104,79522
26,48000;2,27254;8118,82690
26,52000;2,27589;8131,63817
26,56000;2,27918;8143,16571
26,60000;2,28252;8155,95314
26,64000;2,28581;8168,51109
26,68000;2,28916;8180,23756
26,72000;2,29251;8191,48794
26,76000;2,29574;8204,18373
26,80000;2,29915;8216,76180
26,84000;2,30237;8228,20067
26,88000;2,30578;8242,00511
26,92000;2,30919;8254,86556
26,96000;2,31248;8266,07719
27,00000;2,31571;8278,31551
27,04000;2,31917;8291,10816
27,08000;2,32252;8305,22925
27,12000;2,32581;8317,21127
27,16000;2,32916;8328,66877
27,20000;2,33251;8340,59566
27,24000;2,33580;8352,87794
27,28000;2,33914;8364,14769
27,32000;2,34225;8376,49256
27,36000;2,34590;8391,09719
27,40000;2,34913;8402,63590
27,44000;2,35242;8415,04559
27,48000;2,35583;8427,29360
27,52000;2,35917;8439,23390
27,56000;2,36246;8451,41634
27,60000;2,36581;8462,94537
27,64000;2,36916;8476,02636
27,68000;2,37251;8488,32875
27,72000;2,37586;8501,10576
27,76000;2,37908;8513,20773
27,80000;2,38249;8524,23236
27,84000;2,38578;8536,37904
27,88000;2,38883;8548,01014
27,92000;2,39254;8560,93019
27,96000;2,39582;8575,52513
28,00000;2,39911;8588,02572
28,04000;2,40246;8599,54506
28,08000;2,40581;8611,85715
28,12000;2,40910;8623,58734
28,16000;2,41245;8635,15288
28,20000;2,41579;8647,11106
28,24000;2,41914;8660,86259
28,28000;2,42249;8672,31488
28,32000;2,42584;8684,36098
28,36000;2,42919;8696,67903
28,40000;2,43242;8707,40339
28,44000;2,43588;8721,50809
28,48000;2,43923;8733,15185
28,52000;2,44252;8744,91856
28,56000;2,44587;8757,17551
28,60000;2,44922;8767,35672
28,64000;2,45245;8779,57866
28,68000;2,45579;8791,79761
28,72000;2,45920;8804,73629
28,76000;2,46249;8816,73247
28,80000;2,46584;8828,50513
28,84000;2,46913;8839,95295
28,88000;2,47241;8852,13986
28,92000;2,47582;8864,17627
28,96000;2,47911;8875,35214
29,00000;2,48240;8887,28946
29,04000;2,48581;8898,86767
29,08000;2,48916;8911,76537
29,12000;2,49250;8923,44490
29,16000;2,49579;8934,26165
29,20000;2,49914;8946,31818
29,24000;2,50249;8958,48125
29,28000;2,50572;8969,07076
29,32000;2,50913;8981,33814
29,36000;2,51247;8993,68078
29,40000;2,51570;9004,77171
29,44000;2,51905;9016,57715
29,48000;2,52246;9029,15820
29,52000;2,52575;9041,33394
29,56000;2,52910;9052,64914
29,60000;2,53250;9064,89566
29,64000;2,53579;9078,59430
29,68000;2,53920;9089,35741
29,72000;2,54249;9100,09667
29,76000;2,54578;9111,23604
29,80000;2,54918;9122,98337
29,84000;2,55247;9134,64576
29,88000;2,55570;9145,99076
29,92000;2,55911;9157,95863
29,96000;2,56246;9170,25730
30,00000;2,56569;9181,48533
30,04000;2,56903;9193,03894
30,08000;2,57244;9205,29887
30,12000;2,57573;9217,23694
30,16000;2,57908;9229,15563
30,20000;2,58249;9240,68689
30,24000;2,58584;9252,97290
30,28000;2,58912;9263,43128
30,32000;2,59247;9274,48347
30,36000;2,59588;9286,43346
30,40000;2,59911;9297,94386
30,44000;2,60246;9309,37752
30,48000;2,60587;9321,57263
30,52000;2,60909;9333,30357
30,56000;2,61244;9344,88922
30,60000;2,61579;9356,33630
30,64000;2,61908;9368,98440
30,68000;2,62243;9379,78998
30,72000;2,62577;9392,38220
30,76000;2,62906;9404,70845
30,80000;2,63247;9416,05568
30,84000;2,63582;9427,44315
30,88000;2,63911;9439,33204
30,92000;2,64252;9450,03331
30,96000;2,64580;9461,87153
31,00000;2,64915;9473,28657
31,04000;2,65250;9484,91693
31,08000;2,65585;9496,80507
31,12000;2,65914;9507,58159
31,16000;2,66249;9518,97129
31,20000;2,66583;9530,21348
31,24000;2,66918;9541,54953
31,28000;2,67241;9551,81792
31,32000;2,67582;9563,17708
31,36000;2,67923;9575,70001
31,40000;2,68252;9586,86098
31,44000;2,68586;9597,53767
31,48000;2,68927;9609,58377
31,52000;2,69250;9620,55400
31,56000;2,69579;9630,36790
31,60000;2,69914;9642,51533
31,64000;2,70249;9654,19337
31,68000;2,70583;9665,73507
31,72000;2,70918;9676,88262
31,76000;2,71247;9688,51894
31,80000;2,71588;9698,44535
31,84000;2,71917;9707,75783
31,88000;2,72245;9718,67070
31,92000;2,72580;9729,55376
31,96000;2,72915;9740,81308
32,00000;2,73250;9751,17236
32,04000;2,73585;9762,11727
32,08000;2,73920;9772,71721
32,12000;2,74248;9782,95505
32,16000;2,74577;9792,88295
32,20000;2,74912;9804,79792
32,24000;2,75253;9816,41263
32,28000;2,75582;9826,85536
32,32000;2,75917;9836,72738
32,36000;2,76257;9848,69823
32,40000;2,76580;9857,92875
32,44000;2,76915;9868,20385
32,48000;2,77250;9880,20003
32,52000;2,77579;9890,95792
32,56000;2,77919;9901,01919
32,60000;2,78248;9911,08045
32,64000;2,78577;9922,62289
32,68000;2,78918;9932,84360
32,72000;2,79241;9942,41610
32,76000;2,79576;9952,65990
32,80000;2,79910;9962,96704
32,84000;2,80245;9973,96559
32,88000;2,80580;9983,69530
32,92000;2,80915;9994,26171
32,96000;2,81250;10005,23195
33,00000;2,81585;10014,68450
33,04000;2,81913;10024,06925
33,08000;2,82254;10035,49322
33,12000;2,82589;10045,66103
33,16000;2,82918;10055,86386
33,20000;2,83253;10065,21359
33,24000;2,83588;10075,65483
33,28000;2,83910;10085,26608
33,32000;2,84245;10094,78122
33,36000;2,84592;10105,85949
33,40000;2,84915;10115,68755
33,44000;2,85250;10125,15649
33,48000;2,85585;10134,82735
33,52000;2,85907;10145,07189
33,56000;2,86242;10154,19215
33,60000;2,86577;10164,99177
33,64000;2,86912;10175,97243
33,68000;2,87253;10185,78038
33,72000;2,87587;10195,53691
33,76000;2,87916;10205,10569
33,80000;2,88251;10215,77865
33,84000;2,88586;10224,97192
33,88000;2,88915;10235,01903
33,92000;2,89250;10246,91537
33,96000;2,89584;10256,10641
34,00000;2,89919;10265,19462
34,04000;2,90242;10274,47358
34,08000;2,90583;10284,51994
34,12000;2,90918;10294,82633
34,16000;2,91241;10304,55902
34,20000;2,91587;10315,36534
34,24000;2,91928;10325,95038
34,28000;2,92257;10333,40693
34,32000;2,92586;10342,88332
34,36000;2,92921;10352,10416
34,40000;2,93249;10362,42843
34,44000;2,93584;10371,15082
34,48000;2,93925;10381,69339
34,52000;2,94254;10393,51448
34,56000;2,94583;10401,52460
34,60000;2,94912;10410,42358
34,64000;2,95241;10420,05271
34,68000;2,95581;10431,10937
34,72000;2,95916;10440,74073
34,76000;2,96245;10449,94444
34,80000;2,96586;10462,15594
34,84000;2,96921;10472,41464
34,88000;2,97255;10481,58482
34,92000;2,97584;10489,05700
34,96000;2,97925;10498,35458
35,00000;2,98254;10507,07251
35,04000;2,98577;10515,39630
35,08000;2,98918;10525,25118
35,12000;2,99252;10536,17746
35,16000;2,99575;10543,59004
35,20000;2,99910;10552,96734
35,24000;3,00257;10565,56553
35,28000;3,00580;10574,17318
35,32000;3,00909;10582,68398
35,36000;3,01249;10591,74240
35,40000;3,01578;10600,44691
35,44000;3,01913;10609,38984
35,48000;3,02242;10617,94832
35,52000;3,02583;10627,85760
35,56000;3,02912;10639,04762
35,60000;3,03246;10648,22227
35,64000;3,03581;10657,17861
35,68000;3,03916;10666,43298
35,72000;3,04245;10675,86392
35,76000;3,04580;10684,58036
35,80000;3,04908;10693,40631
35,84000;3,05225;10702,21514
35,88000;3,05578;10713,82985
35,92000;3,05913;10723,46792
35,96000;3,06248;10732,38254
36,00000;3,06583;10740,83373
36,04000;3,06911;10749,88842
36,08000;3,07246;10759,18451
36,12000;3,07581;10768,49550
36,16000;3,07898;10777,40565
36,20000;3,08245;10787,44307
36,24000;3,08586;10797,94839
36,28000;3,08914;10806,73784
36,32000;3,09237;10815,74932
36,36000;3,09578;10825,62134
36,40000;3,09907;10835,50975
36,44000;3,10242;10844,57934
36,48000;3,10577;10854,59813
36,52000;3,10911;10865,10867
36,56000;3,11246;10873,43022
36,60000;3,11581;10882,73004
36,64000;3,11916;10893,20108
36,68000;3,12251;10902,48376
36,72000;3,12585;10911,53473
36,76000;3,12914;10920,70416
36,80000;3,13249;10930,10306
36,84000;3,13584;10939,32465
36,88000;3,13913;10949,33823
36,92000;3,14248;10958,98151
36,96000;3,14582;10968,74997
37,00000;3,14917;10977,72419
37,04000;3,15240;10986,86531
37,08000;3,15581;10996,89603
37,12000;3,15922;11007,09662
37,16000;3,16239;11015,44350
37,20000;3,16579;11024,47659
37,24000;3,16920;11035,28589
37,28000;3,17243;11044,04330
37,32000;3,17578;11053,06819
37,36000;3,17919;11063,76797
37,40000;3,18248;11073,67724
37,44000;3,18582;11082,30799
37,48000;3,18911;11090,87616
37,52000;3,19252;11100,97542
37,56000;3,19563;11110,11654
37,60000;3,19922;11119,31577
37,64000;3,20250;11129,69071
37,68000;3,20585;11137,90125
37,72000;3,20920;11146,50369
37,76000;3,21249;11155,83107
37,80000;3,21584;11163,86279
37,84000;3,21919;11173,70427
37,88000;3,22253;11182,84091
37,92000;3,22576;11191,28317
37,96000;3,22917;11200,34009
38,00000;3,23246;11209,79786
38,04000;3,23575;11218,08961
38,08000;3,23910;11227,42817
38,12000;3,24244;11236,39494
38,16000;3,24567;11245,15235
38,20000;3,24914;11254,82693
38,24000;3,25255;11264,72130
38,28000;3,25578;11273,52938
38,32000;3,25912;11282,13480
38,36000;3,26253;11292,64683
38,40000;3,26582;11300,49601
38,44000;3,26893;11307,98608
38,48000;3,27246;11318,31184
38,52000;3,27581;11328,67709
38,56000;3,27915;11336,74979
38,60000;3,28238;11345,59363
38,64000;3,28579;11354,67291
38,68000;3,28914;11362,63087
38,72000;3,29243;11371,63937
38,76000;3,29578;11380,03767
38,80000;3,29912;11389,52598
38,84000;3,30253;11398,55906
38,88000;3,30594;11408,10773
38,92000;3,30923;11418,63018
38,96000;3,31258;11427,12608
39,00000;3,31593;11435,45359
39,04000;3,31915;11443,08746
39,08000;3,32250;11451,04170
39,12000;3,32579;11459,35357
39,16000;3,32914;11469,55565
39,20000;3,33249;11480,40891
39,24000;3,33590;11489,44497
39,28000;3,33918;11498,31340
39,32000;3,34229;11505,10013
39,36000;3,34588;11515,99288
39,40000;3,34917;11525,71514
39,44000;3,35252;11533,08377
39,48000;3,35586;11541,56327
39,52000;3,35927;11550,99422
39,56000;3,36262;11559,86637
39,60000;3,36591;11568,63943
39,64000;3,36920;11576,97886
39,68000;3,37255;11585,78619
39,72000;3,37589;11594,87069
39,76000;3,37906;11603,06856
39,80000;3,38253;11612,40712
39,84000;3,38594;11622,33800
39,88000;3,38923;11630,72586
39,92000;3,39246;11639,11298
39,96000;3,39586;11648,53126
40,00000;3,39921;11658,38838
40,04000;3,40250;11666,84851
40,08000;3,40573;11675,42785
40,12000;3,40926;11685,65154
40,16000;3,41249;11694,52444
40,20000;3,41577;11701,48402
40,24000;3,41918;11711,25099
40,28000;3,42247;11719,79681
40,32000;3,42582;11726,31159
40,36000;3,42917;11734,97066
40,40000;3,43245;11744,73614
40,44000;3,43580;11752,83045
40,48000;3,43909;11760,77574
40,52000;3,44250;11769,99733
40,56000;3,44585;11778,35912
40,60000;3,44914;11785,43717
40,64000;3,45242;11793,57991
40,68000;3,45583;11802,19874
40,72000;3,45912;11810,32509
40,76000;3,46241;11817,97534
40,80000;3,46570;11826,23431
40,84000;3,46917;11835,70772
40,88000;3,47251;11844,32730
40,92000;3,47574;11852,29123
40,96000;3,47921;11861,69833
41,00000;3,48256;11871,14865
41,04000;3,48579;11878,50758
41,08000;3,48908;11885,30996
41,12000;3,49254;11894,44885
41,16000;3,49583;11902,64672
41,20000;3,49912;11909,39397
41,24000;3,50253;11918,95381
41,28000;3,50582;11927,11145
41,32000;3,50916;11934,17832
41,36000;3,51233;11941,12301
41,40000;3,51586;11950,85868
41,44000;3,51921;11959,35011
41,48000;3,52256;11966,68446
41,52000;3,52591;11974,57612
41,56000;3,52919;11982,05873
41,60000;3,53254;11989,17031
41,64000;3,53589;11996,57544
41,68000;3,53900;12004,18100
41,72000;3,54259;12014,16031
41,76000;3,54594;12022,89015
41,80000;3,54910;12029,02570
41,84000;3,55251;12037,45455
41,88000;3,55586;12045,68371
41,92000;3,55915;12053,71618
41,96000;3,56250;12060,23470
42,00000;3,56590;12071,03655
42,04000;3,56913;12078,72182
42,08000;3,57248;12086,21413
42,12000;3,57589;12095,16302
42,16000;3,57912;12104,22069
42,20000;3,58253;12110,98060
42,24000;3,58587;12118,42224
42,28000;3,58922;12128,47605
42,32000;3,59251;12136,93246
42,36000;3,59586;12144,32418
42,40000;3,59921;12151,31506
42,44000;3,60244;12158,75000
42,48000;3,60578;12166,36896
42,52000;3,60907;12173,09758
42,56000;3,61242;12180,93708
42,60000;3,61577;12189,44937
42,64000;3,61918;12198,44669
42,68000;3,62247;12205,63650
42,72000;3,62587;12214,96835
42,76000;3,62916;12223,05596
42,80000;3,63245;12228,89200
42,84000;3,63586;12237,22845
42,88000;3,63921;12244,82208
42,92000;3,64244;12251,53506
42,96000;3,64578;12258,38885
43,00000;3,64919;12267,02407
43,04000;3,65242;12273,66328
43,08000;3,65571;12281,94535
43,12000;3,65912;12289,93312
43,16000;3,66241;12298,57132
43,20000;3,66569;12305,15540
43,24000;3,66916;12313,75188
43,28000;3,67245;12321,93783
43,32000;3,67574;12328,89444
43,36000;3,67909;12336,76299
43,40000;3,68249;12346,14477
43,44000;3,68578;12353,61993
43,48000;3,68913;12361,03103
43,52000;3,69254;12369,39654
43,56000;3,69577;12376,41573
43,60000;3,69918;12383,38351
43,64000;3,70252;12391,81310
43,68000;3,70581;12399,28678
43,72000;3,70910;12406,81261
43,76000;3,71245;12413,81317
43,80000;3,71574;12420,59320
43,84000;3,71915;12429,62778
43,88000;3,72249;12437,48888
43,92000;3,72572;12444,16162
43,96000;3,72913;12451,87670
44,00000;3,73248;12460,10065
44,04000;3,73577;12466,95220
44,08000;3,73912;12474,15096
44,12000;3,74252;12482,01504
44,16000;3,74581;12490,74712
44,20000;3,74910;12497,77675
44,24000;3,75251;12505,86659
44,28000;3,75586;12513,97580
44,32000;3,75914;12520,85716
44,36000;3,76249;12527,01730
44,40000;3,76584;12535,40367
44,44000;3,76913;12541,77243
44,48000;3,77242;12548,45709
44,52000;3,77583;12557,38288
44,56000;3,77917;12565,84972
44,60000;3,78252;12571,69545
44,64000;3,78581;12578,40842
44,68000;3,78916;12585,42240
44,72000;3,79251;12593,10544
44,76000;3,79586;12601,11481
44,80000;3,79914;12608,30909
44,84000;3,80255;12615,78053
44,88000;3,80584;12622,69169
44,92000;3,80913;12630,17952
44,96000;3,81254;12637,18903
45,00000;3,81583;12644,71859
45,04000;3,81911;12654,19573
45,08000;3,82246;12662,40180
45,12000;3,82581;12670,72409
45,16000;3,82916;12679,98517
45,20000;3,83245;12686,85311
45,24000;3,83579;12694,00865
45,28000;3,83914;12703,07153
45,32000;3,84243;12710,40142
45,36000;3,84578;12717,24701
45,40000;3,84913;12725,66319
45,44000;3,85242;12734,51447
45,48000;3,85576;12741,72366
45,52000;3,85911;12749,85671
45,56000;3,86240;12758,35782
45,60000;3,86575;12766,84403
45,64000;3,86910;12775,44349
45,68000;3,87239;12783,69278
45,72000;3,87579;12793,57970
45,76000;3,87914;12801,82153
45,80000;3,88243;12810,17363
45,84000;3,88578;12818,97724
45,88000;3,88913;12827,60948
45,92000;3,89236;12836,56210
45,96000;3,89576;12845,63690
46,00000;3,89911;12855,52531
46,04000;3,90240;12865,29452
46,08000;3,90581;12874,68821
46,12000;3,90922;12885,43344
46,16000;3,91250;12894,22363
46,20000;3,91579;12902,32241
46,24000;3,91920;12913,02741
46,28000;3,92255;12923,08420
46,32000;3,92584;12931,55402
46,36000;3,92919;12940,45895
46,40000;3,93253;12949,92268
46,44000;3,93582;12958,88871
46,48000;3,93911;12966,69841
46,52000;3,94252;12976,14723
46,56000;3,94575;12985,96114
46,60000;3,94916;12995,22072
46,64000;3,95250;13003,14963
46,68000;3,95579;13012,86370
46,72000;3,95920;13022,67760
46,76000;3,96249;13030,60353
46,80000;3,96584;13040,37273
46,84000;3,96924;13049,90202
46,88000;3,97259;13058,84272
46,92000;3,97582;13066,82080
46,96000;3,97923;13074,40698
47,00000;3,98258;13084,61726
47,04000;3,98581;13093,07218
47,08000;3,98915;13100,24410
47,12000;3,99250;13109,75403
47,16000;3,99585;13120,45157
47,20000;3,99914;13127,09600
47,24000;4,00249;13135,93835
47,28000;4,00590;13146,19184
47,32000;4,00918;13155,51847
47,36000;4,01247;13162,46390
47,40000;4,01588;13171,78011
47,44000;4,01923;13181,24086
47,48000;4,02258;13189,27556
47,52000;4,02593;13197,44587
47,56000;4,02921;13205,98871
47,60000;4,03256;13214,65969
47,64000;4,03579;13222,41873
47,68000;4,03908;13230,80063
47,72000;4,04249;13240,70841
47,76000;4,04584;13250,12445
47,80000;4,04906;13257,85667
47,84000;4,05241;13265,52480
47,88000;4,05588;13274,27179
47,92000;4,05911;13283,08880
47,96000;4,06240;13289,00605
48,00000;4,06580;13297,75602
48,04000;4,06921;13307,52373
48,08000;4,07250;13313,34859
48,12000;4,07585;13322,43681
48,16000;4,07920;13331,88862
48,20000;4,08249;13338,93836
48,24000;4,08583;13347,20999
48,28000;4,08918;13357,46497
48,32000;4,09247;13364,76058
48,36000;4,09576;13371,63150
48,40000;4,09917;13379,28921
48,44000;4,10246;13388,11666
48,48000;4,10580;13396,47621
48,52000;4,10897;13404,08623
48,56000;4,11250;13413,20276
48,60000;4,11585;13421,67109
48,64000;4,11920;13428,79832
48,68000;4,12249;13436,42324
48,72000;4,12583;13444,02432
48,76000;4,12918;13450,88482
48,80000;4,13223;13458,34881
48,84000;4,13594;13466,70389
48,88000;4,13923;13476,24063
48,92000;4,14245;13481,77791
48,96000;4,14580;13487,73390
49,00000;4,14915;13493,73013
49,04000;4,15250;13502,32810
49,08000;4,15579;13507,78192
49,12000;4,15908;13515,01793
49,16000;4,16254;13524,23579
49,20000;4,16589;13530,72971
49,24000;4,16924;13536,59928
49,28000;4,17259;13542,12612
49,32000;4,17582;13547,36388
49,36000;4,17917;13553,34371
49,40000;4,18257;13560,33087
49,44000;4,18586;13568,53992
49,48000;4,18915;13574,54956
49,52000;4,19250;13580,10322
49,56000;4,19579;13586,55393
49,60000;4,19920;13592,60678
49,64000;4,20248;13598,58066
49,68000;4,20565;13604,75719
49,72000;4,20918;13611,14979
49,76000;4,21253;13618,35897
49,80000;4,21576;13623,79938
49,84000;4,21911;13628,66163
49,88000;4,22251;13635,00655
49,92000;4,22580;13640,47229
49,96000;4,22891;13645,88290
50,00000;4,23256;13654,72823
50,04000;4,23591;13662,66310
50,08000;4,23919;13666,39137
50,12000;4,24254;13670,85129
50,16000;4,24589;13676,98610
50,20000;4,24912;13681,91391
50,24000;4,25241;13687,25896
50,28000;4,25588;13694,47410
50,32000;4,25916;13701,72352
50,36000;4,26251;13706,18194
50,40000;4,26586;13711,62832
50,44000;4,26915;13716,99572
50,48000;4,27250;13721,08012
50,52000;4,27579;13726,27914
50,56000;4,27907;13731,80896
50,60000;4,28248;13737,98549
50,64000;4,28583;13742,94609
50,68000;4,28906;13747,66976
50,72000;4,29253;13754,00722
50,76000;4,29587;13759,48638
50,80000;4,29910;13763,62145
50,84000;4,30251;13767,15899
50,88000;4,30592;13772,43996
50,92000;4,30915;13776,36939
50,96000;4,31244;13778,99945
51,00000;4,31584;13784,41602
51,04000;4,31913;13788,93405
51,08000;4,32242;13791,54921
51,12000;4,32577;13794,44599
51,16000;4,32912;13799,34549
51,20000;4,33241;13803,62660
51,24000;4,33575;13806,88399
51,28000;4,33916;13811,17254
51,32000;4,34245;13814,74882
51,36000;4,34574;13816,90204
51,40000;4,34921;13820,10579
51,44000;4,35250;13823,31550
51,48000;4,35584;13824,31686
51,52000;4,35913;13826,48349
51,56000;4,36248;13828,35507
51,60000;4,36583;13829,33855
51,64000;4,36906;13829,40710
51,68000;4,37241;13829,16421
51,72000;4,37575;13828,24630
51,76000;4,37916;13828,54730
51,80000;4,38239;13825,76376
51,84000;4,38574;13821,42454
51,88000;4,38915;13815,79041
51,92000;4,39232;13808,56782
51,96000;4,39578;13799,06535
52,00000;4,39919;13787,08482
52,04000;4,40254;13768,54181
52,08000;4,40583;13741,02682
52,12000;4,40918;13705,09267
52,16000;4,41258;13652,61674
52,20000;4,41575;13561,60939
52,24000;4,42077;4716,79755
52,24800;4,42179;2483,13658