File: SU - Suspension/05 - Essais/Excels essais Optimus/Collage_alu_alu_31_01_19/collage3.is_tens_RawData/Specimen_RawData_1.csv
Temps;Déplacement;Charge
(sec);(mm);(N)
0,00000;-40,00408;12,35025
0,04000;-40,00378;12,53480
0,08000;-40,00240;13,05260
0,12000;-39,99983;15,49533
0,16000;-39,99631;18,23311
0,20000;-39,99272;21,12455
0,24000;-39,98901;26,44249
0,28000;-39,98531;36,75212
0,32000;-39,98166;46,93403
0,36000;-39,97807;56,18767
0,40000;-39,97460;66,68348
0,44000;-39,97108;76,86430
0,48000;-39,96767;88,77285
0,52000;-39,96426;101,56499
0,56000;-39,96079;116,64245
0,60000;-39,95745;131,66921
0,64000;-39,95421;147,14019
0,68000;-39,95080;164,93861
0,72000;-39,94740;181,34105
0,76000;-39,94417;197,84602
0,80000;-39,94082;213,90433
0,84000;-39,93736;229,61576
0,88000;-39,93419;247,88261
0,92000;-39,93084;266,83202
0,96000;-39,92743;287,81185
1,00000;-39,92414;307,68274
1,04000;-39,92085;326,60111
1,08000;-39,91744;346,04212
1,12000;-39,91410;365,42160
1,16000;-39,91075;383,71491
1,20000;-39,90746;401,51249
1,24000;-39,90417;419,17837
1,28000;-39,90083;436,42013
1,32000;-39,89748;452,44857
1,36000;-39,89412;468,41162
1,40000;-39,89078;485,19415
1,44000;-39,88749;500,83939
1,48000;-39,88408;517,21558
1,52000;-39,88085;533,06501
1,56000;-39,87744;548,88949
1,60000;-39,87416;564,73743
1,64000;-39,87087;580,54212
1,68000;-39,86752;595,49115
1,72000;-39,86411;610,45978
1,76000;-39,86101;624,68997
1,80000;-39,85748;639,26941
1,84000;-39,85407;653,67185
1,88000;-39,85084;667,14692
1,92000;-39,84749;679,54049
1,96000;-39,84408;693,77320
2,00000;-39,84074;705,29301
2,04000;-39,83744;715,20545
2,08000;-39,83410;725,74369
2,12000;-39,83069;736,71113
2,16000;-39,82740;747,15693
2,20000;-39,82411;754,48458
2,24000;-39,82076;762,35435
2,28000;-39,81736;770,28139
2,32000;-39,81407;776,55716
2,36000;-39,81072;782,92517
2,40000;-39,80743;789,43074
2,44000;-39,80414;796,48998
2,48000;-39,80080;804,50689
2,52000;-39,79739;811,79300
2,56000;-39,79404;819,54449
2,60000;-39,79069;825,05355
2,64000;-39,78740;831,23697
2,68000;-39,78406;836,67636
2,72000;-39,78071;841,83915
2,76000;-39,77760;846,43355
2,80000;-39,77407;851,68425
2,84000;-39,77072;855,46048
2,88000;-39,76737;858,84482
2,92000;-39,76414;863,66674
2,96000;-39,76068;876,88332
3,00000;-39,75739;892,72354
3,04000;-39,75416;905,57570
3,08000;-39,75081;920,68026
3,12000;-39,74740;938,49618
3,16000;-39,74406;954,95014
3,20000;-39,74077;970,62457
3,24000;-39,73736;987,48924
3,28000;-39,73407;1004,26357
3,32000;-39,73072;1020,03710
3,36000;-39,72738;1036,01711
3,40000;-39,72414;1051,76335
3,44000;-39,72080;1068,67319
3,48000;-39,71739;1085,61656
3,52000;-39,71410;1101,61845
3,56000;-39,71075;1118,04968
3,60000;-39,70740;1134,20412
3,64000;-39,70424;1149,05247
3,68000;-39,70077;1166,23323
3,72000;-39,69742;1182,74186
3,76000;-39,69437;1198,00242
3,80000;-39,69066;1215,23896
3,84000;-39,68738;1232,06200
3,88000;-39,68409;1246,84609
3,92000;-39,68074;1261,80639
3,96000;-39,67745;1278,44336
4,00000;-39,67410;1294,80166
4,04000;-39,67076;1309,66362
4,08000;-39,66746;1324,08775
4,12000;-39,66399;1341,15238
4,16000;-39,66077;1357,22058
4,20000;-39,65742;1371,29100
4,24000;-39,65407;1385,54703
4,28000;-39,65072;1399,95357
4,32000;-39,64738;1414,72006
4,36000;-39,64409;1428,29129
4,40000;-39,64074;1442,70016
4,44000;-39,63733;1459,24781
4,48000;-39,63404;1472,61964
4,52000;-39,63076;1485,62472
4,56000;-39,62735;1500,72714
4,60000;-39,62400;1514,79617
4,64000;-39,62089;1527,71380
4,68000;-39,61736;1542,80625
4,72000;-39,61402;1558,17112
4,76000;-39,61078;1570,38439
4,80000;-39,60756;1582,89243
4,84000;-39,60403;1597,33556
4,88000;-39,60074;1610,71792
4,92000;-39,59739;1622,35424
4,96000;-39,59410;1634,91443
5,00000;-39,59076;1647,65567
5,04000;-39,58741;1659,55555
5,08000;-39,58412;1671,26227
5,12000;-39,58071;1684,50810
5,16000;-39,57736;1697,91635
5,20000;-39,57408;1708,87709
5,24000;-39,57079;1719,43698
5,28000;-39,56738;1730,84680
5,32000;-39,56409;1742,31827
5,36000;-39,56074;1752,82229
5,40000;-39,55751;1762,45682
5,44000;-39,55404;1774,30902
5,48000;-39,55069;1785,12894
5,52000;-39,54747;1794,03089
5,56000;-39,54406;1804,70049
5,60000;-39,54065;1816,48638
5,64000;-39,53742;1825,05436
5,68000;-39,53413;1833,43105
5,72000;-39,53061;1845,18918
5,76000;-39,52738;1856,04170
5,80000;-39,52409;1862,14279
5,84000;-39,52074;1871,46217
5,88000;-39,51739;1880,96333
5,92000;-39,51405;1889,50729
5,96000;-39,51075;1896,65630
6,00000;-39,50741;1904,84282
6,04000;-39,50406;1912,56534
6,08000;-39,50077;1919,82687
6,12000;-39,49748;1927,78390
6,16000;-39,49414;1936,19076
6,20000;-39,49073;1943,57969
6,24000;-39,48744;1949,69010
6,28000;-39,48403;1956,84787
6,32000;-39,48074;1966,14936
6,36000;-39,47739;1972,42387
6,40000;-39,47417;1978,35173
6,44000;-39,47076;1985,05949
6,48000;-39,46741;1991,49661
6,52000;-39,46412;1995,73934
6,56000;-39,46077;2001,85236
6,60000;-39,45737;2008,70465
6,64000;-39,45432;2014,10558
6,68000;-39,45073;2021,18251
6,72000;-39,44744;2027,87053
6,76000;-39,44415;2032,04136
6,80000;-39,44080;2035,78491
6,84000;-39,43746;2041,57270
6,88000;-39,43416;2047,61215
6,92000;-39,43082;2052,49507
6,96000;-39,42759;2057,74438
7,00000;-39,42412;2064,27500
7,04000;-39,42083;2070,28538
7,08000;-39,41743;2074,44746
7,12000;-39,41408;2079,88936
7,16000;-39,41079;2084,61098
7,20000;-39,40744;2089,75039
7,24000;-39,40409;2094,09874
7,28000;-39,40086;2098,39232
7,32000;-39,39745;2104,47349
7,36000;-39,39411;2111,86763
7,40000;-39,39082;2115,03226
7,44000;-39,38747;2119,37111
7,48000;-39,38406;2124,40640
7,52000;-39,38084;2128,33546
7,56000;-39,37743;2132,67431
7,60000;-39,37414;2136,11964
7,64000;-39,37097;2140,83679
7,68000;-39,36738;2147,43689
7,72000;-39,36397;2153,05835
7,76000;-39,36074;2157,11202
7,80000;-39,35740;2161,01371
7,84000;-39,35405;2164,21075
7,88000;-39,35076;2168,82359
7,92000;-39,34741;2171,48475
7,96000;-39,34412;2175,91431
8,00000;-39,34071;2181,40073
8,04000;-39,33743;2186,00705
8,08000;-39,33414;2190,88774
8,12000;-39,33079;2196,58855
8,16000;-39,32744;2203,33580
8,20000;-39,32409;2208,81123
8,24000;-39,32075;2213,70999
8,28000;-39,31740;2220,15195
8,32000;-39,31405;2226,69709
8,36000;-39,31076;2232,08517
8,40000;-39,30747;2238,65118
8,44000;-39,30406;2246,09077
8,48000;-39,30072;2252,08625
8,52000;-39,29749;2257,26720
8,56000;-39,29408;2264,54921
8,60000;-39,29067;2271,24151
8,64000;-39,28744;2276,28294
8,68000;-39,28415;2280,85276
8,72000;-39,28075;2288,30781
8,76000;-39,27746;2293,86557
8,80000;-39,27417;2299,75339
8,84000;-39,27076;2306,46394
8,88000;-39,26741;2313,16444
8,92000;-39,26407;2319,34320
8,96000;-39,26078;2323,86477
9,00000;-39,25743;2328,58174
9,04000;-39,25414;2332,89655
9,08000;-39,25079;2338,91532
9,12000;-39,24738;2344,77501
9,16000;-39,24410;2349,74157
9,20000;-39,24081;2353,61792
9,24000;-39,23746;2356,57822
9,28000;-39,23417;2361,80741
9,32000;-39,23082;2366,57001
9,36000;-39,22747;2371,71352
9,40000;-39,22413;2377,05633
9,44000;-39,22078;2381,32123
9,48000;-39,21737;2386,23563
9,52000;-39,21414;2390,00022
9,56000;-39,21079;2394,09413
9,60000;-39,20744;2398,46110
9,64000;-39,20416;2402,34714
9,68000;-39,20081;2405,71517
9,72000;-39,19746;2411,20402
9,76000;-39,19411;2416,17486
9,80000;-39,19082;2419,75170
9,84000;-39,18742;2425,66001
9,88000;-39,18407;2430,56379
9,92000;-39,18078;2433,54030
9,96000;-39,17749;2437,37418
10,00000;-39,17408;2443,29479
10,04000;-39,17073;2447,08620
10,08000;-39,16745;2451,41331
10,12000;-39,16404;2455,89465
10,16000;-39,16075;2460,01855
10,20000;-39,15746;2463,33107
10,24000;-39,15405;2468,47440
10,28000;-39,15082;2473,64882
10,32000;-39,14741;2479,13748
10,36000;-39,14407;2483,07157
10,40000;-39,14078;2487,90178
10,44000;-39,13737;2492,80538
10,48000;-39,13402;2495,68727
10,52000;-39,13085;2499,39915
10,56000;-39,12739;2506,32185
10,60000;-39,12404;2511,17609
10,64000;-39,12075;2514,88239
10,68000;-39,11740;2518,37466
10,72000;-39,11399;2523,75193
10,76000;-39,11071;2528,13119
10,80000;-39,10742;2531,62645
10,84000;-39,10413;2536,70104
10,88000;-39,10072;2542,94351
10,92000;-39,09743;2547,25795
10,96000;-39,09408;2551,11884
11,00000;-39,09067;2557,08657
11,04000;-39,08733;2562,52680
11,08000;-39,08410;2566,53782
11,12000;-39,08069;2571,74112
11,16000;-39,07740;2578,40753
11,20000;-39,07399;2582,62400
11,24000;-39,07070;2586,85611
11,28000;-39,06748;2591,80609
11,32000;-39,06395;2598,60847
11,36000;-39,06072;2603,79985
11,40000;-39,05743;2607,89748
11,44000;-39,05408;2613,82777
11,48000;-39,05067;2620,20640
11,52000;-39,04745;2625,11615
11,56000;-39,04410;2629,72862
11,60000;-39,04075;2635,52070
11,64000;-39,03740;2641,34519
11,68000;-39,03411;2644,90694
11,72000;-39,03071;2650,31625
11,76000;-39,02736;2657,66736
11,80000;-39,02401;2661,03782
11,84000;-39,02072;2666,48401
11,88000;-39,01731;2672,97588
11,92000;-39,01402;2679,10380
11,96000;-39,01074;2683,17740
12,00000;-39,00745;2688,34829
12,04000;-39,00410;2694,53861
12,08000;-39,00075;2700,65442
12,12000;-38,99740;2705,41329
12,16000;-38,99411;2710,67843
12,20000;-38,99076;2717,12597
12,24000;-38,98748;2722,17654
12,28000;-38,98419;2726,97173
12,32000;-38,98072;2733,82142
12,36000;-38,97737;2740,28443
12,40000;-38,97415;2746,51423
12,44000;-38,97074;2751,77713
12,48000;-38,96733;2761,06391
12,52000;-38,96410;2765,27852
12,56000;-38,96075;2770,77686
12,60000;-38,95740;2777,18939
12,64000;-38,95412;2782,51208
12,68000;-38,95095;2787,93667
12,72000;-38,94742;2795,47311
12,76000;-38,94407;2801,91991
12,80000;-38,94078;2806,67674
12,84000;-38,93749;2813,16526
12,88000;-38,93397;2821,69171
12,92000;-38,93068;2827,89096
12,96000;-38,92739;2832,38925
13,00000;-38,92404;2837,64359
13,04000;-38,92069;2842,21414
13,08000;-38,91741;2848,47319
13,12000;-38,91406;2854,42993
13,16000;-38,91071;2861,25615
13,20000;-38,90730;2868,10547
13,24000;-38,90401;2875,21984
13,28000;-38,90079;2878,51971
13,32000;-38,89738;2883,39965
13,36000;-38,89403;2889,02465
13,40000;-38,89104;2894,92495
13,44000;-38,88727;2902,21497
13,48000;-38,88398;2909,08236
13,52000;-38,88069;2913,16882
13,56000;-38,87740;2916,86058
13,60000;-38,87406;2921,81633
13,64000;-38,87071;2926,86615
13,68000;-38,86742;2930,77976
13,72000;-38,86407;2937,87289
13,76000;-38,86060;2945,34657
13,80000;-38,85738;2952,22644
13,84000;-38,85409;2956,28626
13,88000;-38,85074;2961,40425
13,92000;-38,84745;2967,20620
13,96000;-38,84410;2972,18263
14,00000;-38,84081;2977,06705
14,04000;-38,83735;2985,76411
14,08000;-38,83406;2993,50414
14,12000;-38,83071;2998,46809
14,16000;-38,82748;3003,07553
14,20000;-38,82407;3008,75828
14,24000;-38,82078;3014,11618
14,28000;-38,81756;3019,38988
14,32000;-38,81415;3026,31278
14,36000;-38,81062;3035,75173
14,40000;-38,80751;3042,52841
14,44000;-38,80417;3045,55483
14,48000;-38,80076;3052,43824
14,52000;-38,79753;3057,66258
14,56000;-38,79424;3062,66323
14,60000;-38,79083;3069,38402
14,64000;-38,78748;3076,44829
14,68000;-38,78419;3080,57275
14,72000;-38,78084;3086,68409
14,76000;-38,77744;3093,89178
14,80000;-38,77415;3099,07813
14,84000;-38,77104;3104,22927
14,88000;-38,76739;3112,60726
14,92000;-38,76410;3119,36382
14,96000;-38,76082;3123,14574
15,00000;-38,75747;3129,44800
15,04000;-38,75418;3135,07020
15,08000;-38,75077;3140,02372
15,12000;-38,74742;3145,94246
15,16000;-38,74414;3152,56305
15,20000;-38,74073;3157,17757
15,24000;-38,73738;3164,86172
15,28000;-38,73415;3170,69255
15,32000;-38,73080;3175,18115
15,36000;-38,72745;3180,73742
15,40000;-38,72416;3186,20801
15,44000;-38,72082;3190,65563
15,48000;-38,71741;3198,12968
15,52000;-38,71412;3203,69080
15,56000;-38,71077;3207,90447
15,60000;-38,70742;3215,07975
15,64000;-38,70402;3220,56822
15,68000;-38,70073;3224,58893
15,72000;-38,69738;3230,20294
15,76000;-38,69397;3236,76877
15,80000;-38,69068;3240,29662
15,84000;-38,68740;3245,04189
15,88000;-38,68399;3251,43673
15,92000;-38,68070;3255,80128
15,96000;-38,67741;3260,15316
16,00000;-38,67406;3266,14156
16,04000;-38,67071;3271,91465
16,08000;-38,66737;3275,86718
16,12000;-38,66408;3279,67219
16,16000;-38,66073;3287,79630
16,20000;-38,65738;3291,34166
16,24000;-38,65409;3295,26104
16,28000;-38,65074;3301,14514
16,32000;-38,64739;3307,18830
16,36000;-38,64399;3312,06471
16,40000;-38,64076;3316,20649
16,44000;-38,63741;3319,97536
16,48000;-38,63406;3325,70300
16,52000;-38,63078;3331,21158
16,56000;-38,62743;3336,51341
16,60000;-38,62414;3342,22242
16,64000;-38,62073;3348,74429
16,68000;-38,61750;3354,34936
16,72000;-38,61409;3360,65218
16,76000;-38,61074;3368,12921
16,80000;-38,60746;3375,35180
16,84000;-38,60417;3381,79544
16,88000;-38,60076;3389,07577
16,92000;-38,59747;3396,90894
16,96000;-38,59412;3403,83388
17,00000;-38,59071;3411,44614
17,04000;-38,58743;3417,25051
17,08000;-38,58408;3423,03514
17,12000;-38,58079;3428,93712
17,16000;-38,57744;3435,62812
17,20000;-38,57415;3441,38891
17,24000;-38,57081;3446,85018
17,28000;-38,56763;3452,33418
17,32000;-38,56411;3459,01027
17,36000;-38,56076;3466,47352
17,40000;-38,55747;3470,60710
17,44000;-38,55412;3475,06814
17,48000;-38,55078;3481,92416
17,52000;-38,54749;3487,37985
17,56000;-38,54414;3492,10650
17,60000;-38,54073;3498,07441
17,64000;-38,53732;3504,71810
17,68000;-38,53409;3508,43482
17,72000;-38,53075;3513,47029
17,76000;-38,52740;3519,17334
17,80000;-38,52411;3524,42376
17,84000;-38,52076;3531,62326
17,88000;-38,51735;3535,43684
17,92000;-38,51413;3540,55390
17,96000;-38,51078;3543,66340
18,00000;-38,50749;3548,58600
18,04000;-38,50402;3555,29673
18,08000;-38,50067;3560,54604
18,12000;-38,49738;3562,55621
18,16000;-38,49410;3564,96088
18,20000;-38,49069;3568,82326
18,24000;-38,48734;3573,00900
18,28000;-38,48405;3578,62525
18,32000;-38,48070;3581,69563
18,36000;-38,47735;3583,76727
18,40000;-38,47401;3586,86969
18,44000;-38,47072;3588,41717
18,48000;-38,46731;3591,23126
18,52000;-38,46396;3596,23693
18,56000;-38,46074;3595,32535
18,60000;-38,45738;3597,34483
18,64000;-38,45404;3600,54038
18,68000;-38,45075;3602,66529
18,72000;-38,44758;3603,96691
18,76000;-38,44393;3609,30637
18,80000;-38,44070;3612,72581
18,84000;-38,43741;3613,37028
18,88000;-38,43406;3618,82038
18,92000;-38,43072;3624,07900
18,96000;-38,42737;3627,08941
19,00000;-38,42408;3631,80004
19,04000;-38,42073;3638,67432
19,08000;-38,41733;3645,56611
19,12000;-38,41404;3652,39456
19,16000;-38,41081;3659,37054
19,20000;-38,40740;3669,70487
19,24000;-38,40399;3679,95873
19,28000;-38,40070;3689,15796
19,32000;-38,39741;3698,96367
19,36000;-38,39407;3710,26285
19,40000;-38,39072;3722,11933
19,44000;-38,38749;3732,45999
19,48000;-38,38420;3745,44971
19,52000;-38,38067;3760,77667
19,56000;-38,37744;3773,24782
19,60000;-38,37410;3786,95503
19,64000;-38,37069;3802,70332
19,68000;-38,36740;3816,04098
19,72000;-38,36411;3829,06422
19,76000;-38,36071;3841,00601
19,80000;-38,35742;3856,52930
19,84000;-38,35413;3868,34703
19,88000;-38,35078;3880,18005
19,92000;-38,34749;3893,60338
19,96000;-38,34414;3905,49228
20,00000;-38,34079;3917,92431
20,04000;-38,33762;3931,04367
20,08000;-38,33404;3946,62395
20,12000;-38,33075;3955,20367
20,16000;-38,32746;3968,61695
20,20000;-38,32411;3982,52383
20,24000;-38,32076;3996,36365
20,28000;-38,31742;4009,34629
20,32000;-38,31413;4021,96981
20,36000;-38,31072;4036,78566
20,40000;-38,30737;4051,34708
20,44000;-38,30414;4063,97507
20,48000;-38,30068;4082,36235
20,52000;-38,29739;4097,23669
20,56000;-38,29410;4110,50320
20,60000;-38,29075;4127,62985
20,64000;-38,28740;4144,10532
20,68000;-38,28418;4159,33728
20,72000;-38,28082;4175,73899
20,76000;-38,27736;4195,16936
20,80000;-38,27413;4213,64829
20,84000;-38,27078;4228,74168
20,88000;-38,26737;4245,38516
20,92000;-38,26408;4260,77768
20,96000;-38,26074;4277,36491
21,00000;-38,25739;4293,95176
21,04000;-38,25410;4309,80548
21,08000;-38,25075;4327,15304
21,12000;-38,24740;4341,79008
21,16000;-38,24412;4356,90321
21,20000;-38,24077;4371,62220
21,24000;-38,23742;4389,39258
21,28000;-38,23413;4403,90781
21,32000;-38,23090;4420,21228
21,36000;-38,22737;4439,14235
21,40000;-38,22409;4456,72013
21,44000;-38,22080;4471,78967
21,48000;-38,21745;4486,43379
21,52000;-38,21404;4504,12780
21,56000;-38,21075;4520,91433
21,60000;-38,20752;4536,76172
21,64000;-38,20405;4555,64186
21,68000;-38,20077;4572,13409
21,72000;-38,19742;4587,66595
21,76000;-38,19413;4604,67786
21,80000;-38,19078;4622,17182
21,84000;-38,18749;4638,45953
21,88000;-38,18415;4654,34678
21,92000;-38,18086;4670,18336
21,96000;-38,17751;4686,87154
22,00000;-38,17416;4702,52968
22,04000;-38,17087;4719,21600
22,08000;-38,16746;4736,26889
22,12000;-38,16412;4753,22902
22,16000;-38,16083;4768,82756
22,20000;-38,15748;4784,12956
22,24000;-38,15407;4801,74311
22,28000;-38,15078;4817,59869
22,32000;-38,14750;4832,34897
22,36000;-38,14409;4849,29755
22,40000;-38,14074;4866,42346
22,44000;-38,13751;4881,62488
22,48000;-38,13416;4897,34374
22,52000;-38,13076;4914,14368
22,56000;-38,12753;4929,28140
22,60000;-38,12412;4943,81078
22,64000;-38,12077;4960,68597
22,68000;-38,11748;4977,00647
22,72000;-38,11419;4993,02931
22,76000;-38,11084;5009,72345
22,80000;-38,10749;5027,17979
22,84000;-38,10415;5042,21842
22,88000;-38,10080;5060,02419
22,92000;-38,09751;5078,22186
22,96000;-38,09410;5094,54459
23,00000;-38,09088;5111,03161
23,04000;-38,08753;5127,71979
23,08000;-38,08412;5144,21463
23,12000;-38,08083;5160,81415
23,16000;-38,07748;5178,19375
23,20000;-38,07413;5196,40297
23,24000;-38,07073;5212,93096
23,28000;-38,06738;5229,02086
23,32000;-38,06409;5244,61046
23,36000;-38,06074;5261,63802
23,40000;-38,05739;5278,43088
23,44000;-38,05410;5295,34854
23,48000;-38,05076;5312,29377
23,52000;-38,04735;5329,10489
23,56000;-38,04412;5344,42812
23,60000;-38,04077;5360,34107
23,64000;-38,03736;5378,07234
23,68000;-38,03407;5395,01533
23,72000;-38,03079;5409,88520
23,76000;-38,02738;5428,03034
23,80000;-38,02409;5445,65208
23,84000;-38,02080;5461,07516
23,88000;-38,01740;5478,04534
23,92000;-38,01411;5494,83597
23,96000;-38,01076;5510,01579
24,00000;-38,00747;5527,18118
24,04000;-38,00412;5543,95691
24,08000;-38,00077;5561,34991
24,12000;-37,99742;5578,53319
24,16000;-37,99408;5594,93676
24,20000;-37,99072;5611,52101
24,24000;-37,98738;5628,30791
24,28000;-37,98409;5644,40936
24,32000;-37,98080;5660,66094
24,36000;-37,97739;5679,33246
24,40000;-37,97405;5696,68896
24,44000;-37,97082;5712,29905
24,48000;-37,96747;5728,03132
24,52000;-37,96406;5744,62526
24,56000;-37,96083;5760,56577
24,60000;-37,95749;5775,60775
24,64000;-37,95408;5791,80121
24,68000;-37,95079;5808,72335
24,72000;-37,94744;5824,49026
24,76000;-37,94403;5841,21943
24,80000;-37,94074;5857,99515
24,84000;-37,93739;5872,23992
24,88000;-37,93404;5887,32995
24,92000;-37,93076;5903,97604
24,96000;-37,92735;5919,72582
25,00000;-37,92406;5935,63914
25,04000;-37,92071;5951,14231
25,08000;-37,91737;5966,54862
25,12000;-37,91414;5981,34734
25,16000;-37,91079;5996,02871
25,20000;-37,90756;6010,72721
25,24000;-37,90415;6026,68338
25,28000;-37,90081;6042,70883
25,32000;-37,89752;6057,56417
25,36000;-37,89411;6073,79302
25,40000;-37,89076;6090,27594
25,44000;-37,88753;6104,27223
25,48000;-37,88412;6120,11738
25,52000;-37,88071;6136,17375
25,56000;-37,87742;6153,60215
25,60000;-37,87408;6165,78162
25,64000;-37,87073;6181,38909
25,68000;-37,86744;6195,81416
25,72000;-37,86415;6209,14996
25,76000;-37,86081;6223,73298
25,80000;-37,85752;6240,06577
25,84000;-37,85417;6254,05535
25,88000;-37,85082;6267,43510
25,92000;-37,84747;6283,35997
25,96000;-37,84406;6298,63217
26,00000;-37,84077;6312,43438
26,04000;-37,83743;6326,92128
26,08000;-37,83408;6342,36708
26,12000;-37,83073;6356,79588
26,16000;-37,82738;6370,43044
26,20000;-37,82403;6383,07631
26,24000;-37,82068;6398,23005
26,28000;-37,81734;6410,75596
26,32000;-37,81411;6425,18103
26,36000;-37,81076;6439,86538
26,40000;-37,80735;6453,91792
26,44000;-37,80412;6466,77017
26,48000;-37,80078;6480,27658
26,52000;-37,79737;6495,03544
26,56000;-37,79414;6508,71471
26,60000;-37,79085;6521,57739
26,64000;-37,78738;6536,92037
26,68000;-37,78409;6551,57045
26,72000;-37,78075;6564,56128
26,76000;-37,77752;6577,56627
26,80000;-37,77399;6593,02473
26,84000;-37,77070;6607,56677
26,88000;-37,76741;6619,87066
26,92000;-37,76406;6633,68031
26,96000;-37,76072;6649,34441
27,00000;-37,75737;6663,52212
27,04000;-37,75402;6673,21235
27,08000;-37,75079;6679,83145
27,12000;-37,74738;6696,26296
27,16000;-37,74410;6712,66541
27,20000;-37,74081;6725,11756
27,24000;-37,73740;6739,38319
27,28000;-37,73399;6754,11597
27,32000;-37,73076;6766,26042
27,36000;-37,72736;6780,04548
27,40000;-37,72401;6796,89720
27,44000;-37,72078;6808,35769
27,48000;-37,71743;6819,89715
27,52000;-37,71432;6834,06591
27,56000;-37,71067;6849,91181
27,60000;-37,70738;6863,80416
27,64000;-37,70410;6874,62837
27,68000;-37,70081;6887,87103
27,72000;-37,69746;6899,52001
27,76000;-37,69435;6913,01972
27,80000;-37,69076;6928,17420
27,84000;-37,68748;6942,22599
27,88000;-37,68413;6956,55271
27,92000;-37,68084;6969,55323
27,96000;-37,67743;6982,71915
28,00000;-37,67414;6995,13853
28,04000;-37,67103;7007,85667
28,08000;-37,66744;7024,72627
28,12000;-37,66410;7039,89789
28,16000;-37,66075;7052,30758
28,20000;-37,65752;7064,35442
28,24000;-37,65411;7078,31532
28,28000;-37,65076;7092,31794
28,32000;-37,64748;7105,05024
28,36000;-37,64413;7118,14985
28,40000;-37,64084;7132,60770
28,44000;-37,63743;7149,29178
28,48000;-37,63408;7161,61504
28,52000;-37,63074;7174,21845
28,56000;-37,62751;7186,68848
28,60000;-37,62416;7199,56309
28,64000;-37,62081;7213,60594
28,68000;-37,61734;7229,54944
28,72000;-37,61405;7245,66579
28,76000;-37,61076;7256,90573
28,80000;-37,60742;7270,47026
28,84000;-37,60407;7281,74672
28,88000;-37,60072;7295,39171
28,92000;-37,59743;7309,01510
28,96000;-37,59408;7323,69572
29,00000;-37,59073;7336,69400
29,04000;-37,58739;7350,20116
29,08000;-37,58410;7364,36844
29,12000;-37,58069;7379,10345
29,16000;-37,57740;7392,56963
29,20000;-37,57429;7404,35421
29,24000;-37,57071;7420,60617
29,28000;-37,56736;7434,78611
29,32000;-37,56413;7447,27850
29,36000;-37,56078;7459,86104
29,40000;-37,55737;7473,98362
29,44000;-37,55414;7488,59420
29,48000;-37,55080;7500,33408
29,52000;-37,54739;7515,18458
29,56000;-37,54404;7530,63634
29,60000;-37,54069;7542,35908
29,64000;-37,53740;7554,71289
29,68000;-37,53405;7568,75500
29,72000;-37,53071;7581,34797
29,76000;-37,52748;7593,32255
29,80000;-37,52413;7607,84671
29,84000;-37,52078;7621,01561
29,88000;-37,51749;7634,18004
29,92000;-37,51409;7647,88687
29,96000;-37,51080;7661,14146
30,00000;-37,50745;7674,73429
30,04000;-37,50410;7687,72736
30,08000;-37,50081;7701,19727
30,12000;-37,49740;7715,05088
30,16000;-37,49417;7728,63254
30,20000;-37,49083;7741,50342
30,24000;-37,48742;7755,44122
30,28000;-37,48407;7769,03555
30,32000;-37,48084;7780,61077
30,36000;-37,47749;7793,76179
30,40000;-37,47415;7807,76963
30,44000;-37,47086;7821,04433
30,48000;-37,46763;7832,92204
30,52000;-37,46410;7848,76347
30,56000;-37,46081;7861,65223
30,60000;-37,45752;7873,30866
30,64000;-37,45418;7887,29563
30,68000;-37,45077;7900,91157
30,72000;-37,44748;7912,60377
30,76000;-37,44419;7924,06052
30,80000;-37,44072;7940,83104
30,84000;-37,43744;7952,45990
30,88000;-37,43408;7964,83979
30,92000;-37,43074;7977,13324
30,96000;-37,42751;7989,79327
31,00000;-37,42410;8003,43379
31,04000;-37,42075;8014,85851
31,08000;-37,41753;8027,72120
31,12000;-37,41412;8040,49745
31,16000;-37,41095;8052,37964
31,20000;-37,40748;8065,50011
31,24000;-37,40408;8079,52210
31,28000;-37,40072;8091,94893
31,32000;-37,39750;8103,22762
31,36000;-37,39409;8116,97468
31,40000;-37,39068;8131,16506
31,44000;-37,38745;8143,44287
31,48000;-37,38410;8154,36617
31,52000;-37,38075;8169,14514
31,56000;-37,37747;8181,39985
31,60000;-37,37418;8192,99147
31,64000;-37,37071;8206,61485
31,68000;-37,36742;8220,34702
31,72000;-37,36407;8231,49979
31,76000;-37,36079;8243,20540
31,80000;-37,35738;8255,77006
31,84000;-37,35409;8268,63199
31,88000;-37,35074;8280,88298
31,92000;-37,34733;8293,53407
31,96000;-37,34411;8306,22986
32,00000;-37,34070;8318,29682
32,04000;-37,33741;8329,67833
32,08000;-37,33412;8342,05523
32,12000;-37,33071;8355,14814
32,16000;-37,32736;8368,06446
32,20000;-37,32407;8381,81749
32,24000;-37,32072;8394,53712
32,28000;-37,31738;8406,66741
32,32000;-37,31433;8417,16528
32,36000;-37,31068;8430,62997
32,40000;-37,30739;8446,18157
32,44000;-37,30405;8456,99608
32,48000;-37,30076;8466,68556
32,52000;-37,29741;8479,64957
32,56000;-37,29406;8492,90937
32,60000;-37,29083;8503,66578
32,64000;-37,28736;8516,76911
32,68000;-37,28407;8530,87977
32,72000;-37,28073;8541,13922
32,76000;-37,27744;8553,41032
32,80000;-37,27409;8564,82387
32,84000;-37,27074;8576,43187
32,88000;-37,26739;8588,89595
32,92000;-37,26410;8599,74846
32,96000;-37,26082;8612,73631
33,00000;-37,25747;8623,49570
33,04000;-37,25412;8635,42706
33,08000;-37,25083;8648,06101
33,12000;-37,24743;8660,02515
33,16000;-37,24408;8671,87679
33,20000;-37,24085;8683,14058
33,24000;-37,23744;8697,46581
33,28000;-37,23409;8708,73928
33,32000;-37,23086;8719,33624
33,36000;-37,22752;8729,22465
33,40000;-37,22405;8742,94341
33,44000;-37,22076;8755,61908
33,48000;-37,21747;8765,52537
33,52000;-37,21406;8776,81822
33,56000;-37,21071;8789,54530
33,60000;-37,20736;8800,12959
33,64000;-37,20414;8811,25554
33,68000;-37,20073;8822,67207
33,72000;-37,19738;8834,37321
33,76000;-37,19409;8845,42018
33,80000;-37,19087;8855,77500
33,84000;-37,18740;8869,03033
33,88000;-37,18405;8880,30306
33,92000;-37,18076;8890,65415
33,96000;-37,17741;8901,81884
34,00000;-37,17388;8908,92893
34,04000;-37,17066;8911,88830
34,08000;-37,16743;8923,26087
34,12000;-37,16408;8936,69650
34,16000;-37,16067;8950,83174
34,20000;-37,15744;8962,03741
34,24000;-37,15409;8972,66194
34,28000;-37,15068;8987,30233
34,32000;-37,14746;8998,39476
34,36000;-37,14411;9007,74077
34,40000;-37,14076;9018,72888
34,44000;-37,13735;9030,80106
34,48000;-37,13412;9044,37676
34,52000;-37,13078;9052,91215
34,56000;-37,12743;9063,90622
34,60000;-37,12408;9073,92502
34,64000;-37,12079;9082,95587
34,68000;-37,11744;9092,79436
34,72000;-37,11403;9106,49747
34,76000;-37,11069;9115,29288
34,80000;-37,10740;9124,26338
34,84000;-37,10405;9131,56494
34,88000;-37,10064;9139,56314
34,92000;-37,09735;9147,49876
34,96000;-37,09412;9154,05974
35,00000;-37,09113;9160,25862
35,04000;-37,08731;9168,79401
35,08000;-37,08420;9175,08602
35,12000;-37,08073;9178,46560
35,16000;-37,07738;9182,17227
35,20000;-37,07415;9178,76959
35,24000;-37,07075;9169,47573
35,28000;-37,06740;9134,94602
35,32000;-37,06411;9020,01783
35,36000;-37,06064;8780,63664
35,40000;-37,05706;7862,77279
35,43400;-37,05329;1701,02455